Workbook

Sheet ToImport
A1: Data | B1: DataPIM_BR | C1: DataPIM_US
A2: 27395 | B2: 40.694754 | C2: 42.2035 | D2: =LN(B2) -> 3.7060992 | E2: =LN(C2) -> 3.7425032 | F2: =D2-D1 -> 3.7060992 | G2: =E2-E1 -> 3.7425032
A3: 27426 | B3: 38.18129 | C3: 42.02 | D3: =LN(B3) -> 3.6423456 | E3: =LN(C3) -> 3.7381457 | F3: =D3-D2 -> -0.063753568 | G3: =E3-E2 -> -0.0043574606
A4: 27454 | B4: 41.35231 | C4: 41.6022 | D4: =LN(B4) -> 3.7221283 | E4: =LN(C4) -> 3.7281531 | F4: =D4-D3 -> 0.079782673 | G4: =E4-E3 -> -0.0099926449
A5: 27485 | B5: 43.570795 | C5: 41.7066 | D5: =LN(B5) -> 3.7743871 | E5: =LN(C5) -> 3.7306594 | F5: =D5-D4 -> 0.052258796 | G5: =E5-E4 -> 0.0025063392
A6: 27515 | B6: 43.724429 | C6: 41.4999 | D6: =LN(B6) -> 3.777907 | E6: =LN(C6) -> 3.725691 | F6: =D6-D5 -> 0.003519891 | G6: =E6-E5 -> -0.0049683721
A7: 27546 | B7: 45.174741 | C7: 42.7036 | D7: =LN(B7) -> 3.8105381 | E7: =LN(C7) -> 3.7542832 | F7: =D7-D6 -> 0.032631127 | G7: =E7-E6 -> 0.028592208
A8: 27576 | B8: 46.877013 | C8: 40.9055 | D8: =LN(B8) -> 3.8475274 | E8: =LN(C8) -> 3.7112645 | F8: =D8-D7 -> 0.036989329 | G8: =E8-E7 -> -0.043018697
A9: 27607 | B9: 46.022804 | C9: 42.5577 | D9: =LN(B9) -> 3.829137 | E9: =LN(C9) -> 3.7508608 | F9: =D9-D8 -> -0.01839041 | G9: =E9-E8 -> 0.039596274
A10: 27638 | B10: 47.178137 | C10: 43.9232 | D10: =LN(B10) -> 3.8539306 | E10: =LN(C10) -> 3.7824427 | F10: =D10-D9 -> 0.024793569 | G10: =E10-E9 -> 0.031581852
A11: 27668 | B11: 48.81281 | C11: 44.1579 | D11: =LN(B11) -> 3.8879928 | E11: =LN(C11) -> 3.7877718 | F11: =D11-D10 -> 0.034062192 | G11: =E11-E10 -> 0.0053291922
A12: 27699 | B12: 45.752407 | C12: 43.6988 | D12: =LN(B12) -> 3.8232444 | E12: =LN(C12) -> 3.7773206 | F12: =D12-D11 -> -0.064748372 | G12: =E12-E11 -> -0.010451205
A13: 27729 | B13: 44.394277 | C13: 43.4423 | D13: =LN(B13) -> 3.7931106 | E13: =LN(C13) -> 3.7714336 | F13: =D13-D12 -> -0.03013385 | G13: =E13-E12 -> -0.005887021
... A349: 37956 | B349: 77.9 | C349: 94.6425 | D349: =LN(B349) -> 4.355426 | E349: =LN(C349) -> 4.5501066 | F349: =D349-D348 -> -0.082508314 | G349: =E349-E348 -> -0.0055549786
A350: 37987 | B350: 76.8 | C350: 94.4102 | D350: =LN(B350) -> 4.3412046 | E350: =LN(C350) -> 4.5476491 | F350: =D350-D349 -> -0.014221313 | G350: =E350-E349 -> -0.0024575171 | H350: <<<< | I350: INICIO | J350: <<<< | K350: INICIO | L350: <<<< | M350: INICIO | N350: <<<< | O350: INICIO | P350: <<<< | Q350: INICIO
A351: 38018 | B351: 74 | C351: 96.2589 | D351: =LN(B351) -> 4.3040651 | E351: =LN(C351) -> 4.5670414 | F351: =D351-D350 -> -0.037139547 | G351: =E351-E350 -> 0.019392318
A352: 38047 | B352: 86.9 | C352: 96.6183 | D352: =LN(B352) -> 4.464758 | E352: =LN(C352) -> 4.5707682 | F352: =D352-D351 -> 0.16069294 | G352: =E352-E351 -> 0.0037267278
A353: 38078 | B353: 82.2 | C353: 94.8371 | D353: =LN(B353) -> 4.4091553 | E353: =LN(C353) -> 4.5521607 | F353: =D353-D352 -> -0.05560273 | G353: =E353-E352 -> -0.018607481
A354: 38108 | B354: 86.3 | C354: 96.3792 | D354: =LN(B354) -> 4.4578296 | E354: =LN(C354) -> 4.5682904 | F354: =D354-D353 -> 0.048674296 | G354: =E354-E353 -> 0.016129728
A355: 38139 | B355: 86.1 | C355: 98.5806 | D355: =LN(B355) -> 4.4555094 | E355: =LN(C355) -> 4.5908745 | F355: =D355-D354 -> -0.0023201867 | G355: =E355-E354 -> 0.022584077
A356: 38169 | B356: 90.1 | C356: 95.4028 | D356: =LN(B356) -> 4.5009202 | E356: =LN(C356) -> 4.5581079 | F356: =D356-D355 -> 0.045410753 | G356: =E356-E355 -> -0.03276656
A357: 38200 | B357: 92.1 | C357: 98.9902 | D357: =LN(B357) -> 4.5228749 | E357: =LN(C357) -> 4.5950209 | F357: =D357-D356 -> 0.021954779 | G357: =E357-E356 -> 0.036912927
A358: 38231 | B358: 92.1 | C358: 98.3802 | D358: =LN(B358) -> 4.5228749 | E358: =LN(C358) -> 4.5888396 | F358: =D358-D357 -> 0 | G358: =E358-E357 -> -0.006181291
A359: 38261 | B359: 93.5 | C359: 98.573 | D359: =LN(B359) -> 4.5379614 | E359: =LN(C359) -> 4.5907974 | F359: =D359-D358 -> 0.015086493 | G359: =E359-E358 -> 0.0019578261
A360: 38292 | B360: 91.8 | C360: 97.6279 | D360: =LN(B360) -> 4.5196123 | E360: =LN(C360) -> 4.5811633 | F360: =D360-D359 -> -0.018349139 | G360: =E360-E359 -> -0.0096340772
A361: 38322 | B361: 84.7 | C361: 98.0015 | D361: =LN(B361) -> 4.4391156 | E361: =LN(C361) -> 4.5849828 | F361: =D361-D360 -> -0.080496696 | G361: =E361-E360 -> 0.0038194715
A362: 38353 | B362: 81 | C362: 98.2289 | D362: =LN(B362) -> 4.3944492 | E362: =LN(C362) -> 4.5873005 | F362: =D362-D361 -> -0.044666447 | G362: =E362-E361 -> 0.0023176847
... A471: 41671 | B471: 92.3 | C471: 102.7889 | D471: =LN(B471) -> 4.5250441 | E471: =LN(C471) -> 4.6326774 | F471: =D471-D470 -> -0.0032450001 | G471: =E471-E470 -> 0.006055917
A472: =EOMONTH(A471,0)+1 -> 41699 | B472: 97.3 | C472: 104.2804 | D472: =LN(B472) -> 4.577799 | E472: =LN(C472) -> 4.6470834 | F472: =D472-D471 -> 0.052754848 | G472: =E472-E471 -> 0.014406054
A473: =EOMONTH(A472,0)+1 -> 41730 | B473: 96 | C473: 102.9064 | D473: =LN(B473) -> 4.5643482 | E473: =LN(C473) -> 4.6338198 | F473: =D473-D472 -> -0.013450798 | G473: =E473-E472 -> -0.013263588
A474: =EOMONTH(A473,0)+1 -> 41760 | B474: 101.7 | C474: 103.7271 | D474: =LN(B474) -> 4.6220273 | E474: =LN(C474) -> 4.6417634 | F474: =D474-D473 -> 0.057679112 | G474: =E474-E473 -> 0.0079435746
A475: =EOMONTH(A474,0)+1 -> 41791 | B475: 94.9 | C475: 106.8076 | D475: =LN(B475) -> 4.5528237 | E475: =LN(C475) -> 4.6710291 | F475: =D475-D474 -> -0.069203597 | G475: =E475-E474 -> 0.029265673
A476: =EOMONTH(A475,0)+1 -> 41821 | B476: 104.4 | C476: 104.8018 | D476: =LN(B476) -> 4.6482297 | E476: =LN(C476) -> 4.6520709 | F476: =D476-D475 -> 0.09540597 | G476: =E476-E475 -> -0.018958138
A477: =EOMONTH(A476,0)+1 -> 41852 | B477: 106.3 | C477: 107.4252 | D477: =LN(B477) -> 4.6662653 | E477: =LN(C477) -> 4.6767948 | F477: =D477-D476 -> 0.01803561 | G477: =E477-E476 -> 0.024723844
A478: =EOMONTH(A477,0)+1 -> 41883 | B478: 105.6 | C478: 106.6147 | D478: =LN(B478) -> 4.6596584 | E478: =LN(C478) -> 4.6692214 | F478: =D478-D477 -> -0.0066069141 | G478: =E478-E477 -> -0.0075733905
A479: =EOMONTH(A478,0)+1 -> 41913 | B479: 109.3 | C479: 105.4789 | D479: =LN(B479) -> 4.6940964 | E479: =LN(C479) -> 4.6585109 | F479: =D479-D478 -> 0.034438024 | G479: =E479-E478 -> -0.010710468
A480: =EOMONTH(A479,0)+1 -> 41944 | B480: 99.8 | C480: 105.915 | D480: =LN(B480) -> 4.6031682 | E480: =LN(C480) -> 4.6626369 | F480: =D480-D479 -> -0.090928212 | G480: =E480-E479 -> 0.0041259527
A481: =EOMONTH(A480,0)+1 -> 41974 | B481: 87.7 | C481: 105.777 | D481: =LN(B481) -> 4.4739219 | E481: =LN(C481) -> 4.6613331 | F481: =D481-D480 -> -0.12924628 | G481: =E481-E480 -> -0.0013037811
A482: =EOMONTH(A481,0)+1 -> 42005 | B482: 88.1 | C482: 105.3085 | D482: =LN(B482) -> 4.4784725 | E482: =LN(C482) -> 4.6568941 | F482: =D482-D481 -> 0.0045506336 | G482: =E482-E481 -> -0.0044389669
A483: =EOMONTH(A482,0)+1 -> 42036 | B483: 83.7 | C483: 105.3511 | D483: =LN(B483) -> 4.427239 | E483: =LN(C483) -> 4.6572986 | F483: =D483-D482 -> -0.051233555 | G483: =E483-E482 -> 0.00040444395
...

Sheet PIM_US
A1: Data | B1: PIM_US
A2: 27395 | B2: =FRED!B684 -> 42.2035
A3: 27426 | B3: =FRED!B685 -> 42.02
A4: 27454 | B4: =FRED!B686 -> 41.6022
A5: 27485 | B5: =FRED!B687 -> 41.7066
A6: 27515 | B6: =FRED!B688 -> 41.4999
A7: 27546 | B7: =FRED!B689 -> 42.7036
A8: 27576 | B8: =FRED!B690 -> 40.9055
A9: 27607 | B9: =FRED!B691 -> 42.5577
A10: 27638 | B10: =FRED!B692 -> 43.9232
A11: 27668 | B11: =FRED!B693 -> 44.1579
A12: 27699 | B12: =FRED!B694 -> 43.6988
A13: 27729 | B13: =FRED!B695 -> 43.4423
... A471: 41671 | B471: =FRED!B1153 -> 102.7889
A472: =EOMONTH(A471,0)+1 -> 41699 | B472: =FRED!B1154 -> 104.2804
A473: =EOMONTH(A472,0)+1 -> 41730 | B473: =FRED!B1155 -> 102.9064
A474: =EOMONTH(A473,0)+1 -> 41760 | B474: =FRED!B1156 -> 103.7271
A475: =EOMONTH(A474,0)+1 -> 41791 | B475: =FRED!B1157 -> 106.8076
A476: =EOMONTH(A475,0)+1 -> 41821 | B476: =FRED!B1158 -> 104.8018
A477: =EOMONTH(A476,0)+1 -> 41852 | B477: =FRED!B1159 -> 107.4252
A478: =EOMONTH(A477,0)+1 -> 41883 | B478: =FRED!B1160 -> 106.6147
A479: =EOMONTH(A478,0)+1 -> 41913 | B479: =FRED!B1161 -> 105.4789
A480: =EOMONTH(A479,0)+1 -> 41944 | B480: =FRED!B1162 -> 105.915
A481: =EOMONTH(A480,0)+1 -> 41974 | B481: =FRED!B1163 -> 105.777
A482: =EOMONTH(A481,0)+1 -> 42005 | B482: =FRED!B1164 -> 105.3085
A483: =EOMONTH(A482,0)+1 -> 42036 | B483: =FRED!B1165 -> 105.3511
... A505: =EOMONTH(A504,0)+1 -> 42705 | B505: =FRED!B1187 -> 103.513

Sheet PIM_BR
A1: Data | B1: PIM_BR | C1: PIM(2002=100) | D1: PIM(2012=100)
A2: 27395 | B2: =IF(ISBLANK(D2),B3/(C3/C2),D2) -> 40.694754 | C2: ='PIM(2002 = 100)'!B2 -> 51.008963
A3: 27426 | B3: =IF(ISBLANK(D3),B4/(C4/C3),D3) -> 38.18129 | C3: ='PIM(2002 = 100)'!B3 -> 47.858454
A4: 27454 | B4: =IF(ISBLANK(D4),B5/(C5/C4),D4) -> 41.35231 | C4: ='PIM(2002 = 100)'!B4 -> 51.833179
A5: 27485 | B5: =IF(ISBLANK(D5),B6/(C6/C5),D5) -> 43.570795 | C5: ='PIM(2002 = 100)'!B5 -> 54.613945
A6: 27515 | B6: =IF(ISBLANK(D6),B7/(C7/C6),D6) -> 43.724429 | C6: ='PIM(2002 = 100)'!B6 -> 54.806519
A7: 27546 | B7: =IF(ISBLANK(D7),B8/(C8/C7),D7) -> 45.174741 | C7: ='PIM(2002 = 100)'!B7 -> 56.624416
A8: 27576 | B8: =IF(ISBLANK(D8),B9/(C9/C8),D8) -> 46.877013 | C8: ='PIM(2002 = 100)'!B8 -> 58.758134
A9: 27607 | B9: =IF(ISBLANK(D9),B10/(C10/C9),D9) -> 46.022804 | C9: ='PIM(2002 = 100)'!B9 -> 57.687424
A10: 27638 | B10: =IF(ISBLANK(D10),B11/(C11/C10),D10) -> 47.178137 | C10: ='PIM(2002 = 100)'!B10 -> 59.135579
A11: 27668 | B11: =IF(ISBLANK(D11),B12/(C12/C11),D11) -> 48.81281 | C11: ='PIM(2002 = 100)'!B11 -> 61.184565
A12: 27699 | B12: =IF(ISBLANK(D12),B13/(C13/C12),D12) -> 45.752407 | C12: ='PIM(2002 = 100)'!B12 -> 57.348494
A13: 27729 | B13: =IF(ISBLANK(D13),B14/(C14/C13),D13) -> 44.394277 | C13: ='PIM(2002 = 100)'!B13 -> 55.646141
... A325: 37226 | B325: =IF(ISBLANK(D325),B326/(C326/C325),D325) -> 69.160948 | C325: ='PIM(2002 = 100)'!B325 -> 86.69
A326: 37257 | B326: =IF(ISBLANK(D326),B327/(C327/C326),D326) -> 72.4 | C326: ='PIM(2002 = 100)'!B326 -> 90.75 | D326: ='PIM(2012 = 100)'!B2 -> 72.4
A327: 37288 | B327: =IF(ISBLANK(D327),B328/(C328/C327),D327) -> 69.7 | C327: ='PIM(2002 = 100)'!B327 -> 87.85 | D327: ='PIM(2012 = 100)'!B3 -> 69.7
A328: 37316 | B328: =IF(ISBLANK(D328),B329/(C329/C328),D328) -> 77.4 | C328: ='PIM(2002 = 100)'!B328 -> 97.04 | D328: ='PIM(2012 = 100)'!B4 -> 77.4
A329: 37347 | B329: =IF(ISBLANK(D329),B330/(C330/C329),D329) -> 79.6 | C329: ='PIM(2002 = 100)'!B329 -> 100.11 | D329: ='PIM(2012 = 100)'!B5 -> 79.6
A330: 37377 | B330: =IF(ISBLANK(D330),B331/(C331/C330),D330) -> 80.4 | C330: ='PIM(2002 = 100)'!B330 -> 100.48 | D330: ='PIM(2012 = 100)'!B6 -> 80.4
A331: 37408 | B331: =IF(ISBLANK(D331),B332/(C332/C331),D331) -> 77.5 | C331: ='PIM(2002 = 100)'!B331 -> 96.8 | D331: ='PIM(2012 = 100)'!B7 -> 77.5
A332: 37438 | B332: =IF(ISBLANK(D332),B333/(C333/C332),D332) -> 83.3 | C332: ='PIM(2002 = 100)'!B332 -> 104.53 | D332: ='PIM(2012 = 100)'!B8 -> 83.3
A333: 37469 | B333: =IF(ISBLANK(D333),B334/(C334/C333),D333) -> 83.6 | C333: ='PIM(2002 = 100)'!B333 -> 105.34 | D333: ='PIM(2012 = 100)'!B9 -> 83.6
A334: 37500 | B334: =IF(ISBLANK(D334),B335/(C335/C334),D334) -> 82.1 | C334: ='PIM(2002 = 100)'!B334 -> 103.82 | D334: ='PIM(2012 = 100)'!B10 -> 82.1
A335: 37530 | B335: =IF(ISBLANK(D335),B336/(C336/C335),D335) -> 89.2 | C335: ='PIM(2002 = 100)'!B335 -> 113.18 | D335: ='PIM(2012 = 100)'!B11 -> 89.2
A336: 37561 | B336: =IF(ISBLANK(D336),B337/(C337/C336),D336) -> 83.9 | C336: ='PIM(2002 = 100)'!B336 -> 106.3 | D336: ='PIM(2012 = 100)'!B12 -> 83.9
A337: 37591 | B337: =IF(ISBLANK(D337),B338/(C338/C337),D337) -> 74.6 | C337: ='PIM(2002 = 100)'!B337 -> 93.75 | D337: ='PIM(2012 = 100)'!B13 -> 74.6
... A471: 41671 | B471: =IF(ISBLANK(D471),B472/(C472/C471),D471) -> 92.3 | C471: ='PIM(2002 = 100)'!B471 -> 117.91 | D471: ='PIM(2012 = 100)'!B147 -> 92.3
A472: =EOMONTH(A471,0)+1 -> 41699 | B472: =IF(ISBLANK(D472),B473/(C473/C472),D472) -> 97.3 | D472: ='PIM(2012 = 100)'!B148 -> 97.3
A473: =EOMONTH(A472,0)+1 -> 41730 | B473: =IF(ISBLANK(D473),B474/(C474/C473),D473) -> 96 | D473: ='PIM(2012 = 100)'!B149 -> 96
A474: =EOMONTH(A473,0)+1 -> 41760 | B474: =IF(ISBLANK(D474),B475/(C475/C474),D474) -> 101.7 | D474: ='PIM(2012 = 100)'!B150 -> 101.7
A475: =EOMONTH(A474,0)+1 -> 41791 | B475: =IF(ISBLANK(D475),B476/(C476/C475),D475) -> 94.9 | D475: ='PIM(2012 = 100)'!B151 -> 94.9
A476: =EOMONTH(A475,0)+1 -> 41821 | B476: =IF(ISBLANK(D476),B477/(C477/C476),D476) -> 104.4 | D476: ='PIM(2012 = 100)'!B152 -> 104.4
A477: =EOMONTH(A476,0)+1 -> 41852 | B477: =IF(ISBLANK(D477),B478/(C478/C477),D477) -> 106.3 | D477: ='PIM(2012 = 100)'!B153 -> 106.3
A478: =EOMONTH(A477,0)+1 -> 41883 | B478: =IF(ISBLANK(D478),B479/(C479/C478),D478) -> 105.6 | D478: ='PIM(2012 = 100)'!B154 -> 105.6
A479: =EOMONTH(A478,0)+1 -> 41913 | B479: =IF(ISBLANK(D479),B480/(C480/C479),D479) -> 109.3 | D479: ='PIM(2012 = 100)'!B155 -> 109.3
A480: =EOMONTH(A479,0)+1 -> 41944 | B480: =IF(ISBLANK(D480),B481/(C481/C480),D480) -> 99.8 | D480: ='PIM(2012 = 100)'!B156 -> 99.8
A481: =EOMONTH(A480,0)+1 -> 41974 | B481: =IF(ISBLANK(D481),B482/(C482/C481),D481) -> 87.7 | D481: ='PIM(2012 = 100)'!B157 -> 87.7
A482: =EOMONTH(A481,0)+1 -> 42005 | B482: =IF(ISBLANK(D482),B483/(C483/C482),D482) -> 88.1 | D482: ='PIM(2012 = 100)'!B158 -> 88.1
A483: =EOMONTH(A482,0)+1 -> 42036 | B483: =IF(ISBLANK(D483),B484/(C484/C483),D483) -> 83.7 | D483: ='PIM(2012 = 100)'!B159 -> 83.7
... A505: =EOMONTH(A504,0)+1 -> 42705 | B505: =IF(ISBLANK(D505),B506/(C506/C505),D505) -> 77.2 | D505: ='PIM(2012 = 100)'!B181 -> 77.2

Sheet 1
B1: ipg | C1: nfpsnominal | D1: nfpsreal | E1: Dnfpsreal | F1: pigeral1 | G1: pigeral2 | H1: SELIC | I1: txinflacao | J1: lnjurosreal | K1: lnjurosreal12 | L1: INDPRO_ADJUSTED | M1: INDPRO_notADJUSTED | N1: DLPIusaAdj | O1: DLPIusaNAdj | P1: PI-BRA | Q1: DLPI-BRA | R1: INFL | S1: Lnselic | T1: I:1997(11) | U1: I:1997(12) | V1: I:2002(11) | W1: I:2003(11) | X1: DLnselic | Y1: I:1996(7) | Z1: I:1998(9) | AA1: I:1998(10) | AB1: I:1999(2) | AC1: I:1999(3) | AD1: I:1999(4) | AE1: I:2000(2) | AF1: I:1996(4) | AG1: I:2000(7) | AH1: I:1981(3) | AI1: I:1985(5) | AJ1: I:1985(7) | AK1: I:1985(8) | AL1: I:1985(11) | AM1: I:1986(2) | AN1: I:1986(3) | AO1: I:1986(11) | AP1: I:1986(12) | AQ1: I:1987(1) | AR1: I:1987(2) | AS1: I:1987(3) | AT1: I:1987(4) | AU1: I:1987(5) | AV1: I:1987(6) | AW1: I:1987(7) | AX1: I:1987(8) | AY1: I:1987(10) | AZ1: I:1987(11) | BA1: I:1988(1) | BB1: I:1988(6) | BC1: I:1988(9) | BD1: I:1988(10) | BE1: I:1989(1) | BF1: I:1989(2) | BG1: I:1989(3) | BH1: I:1989(4) | BI1: I:1989(5) | BJ1: I:1989(6) | BK1: I:1989(7) | BL1: I:1989(8) | BM1: I:1989(10) | BN1: I:1989(11) | BO1: I:1989(12) | BP1: I:1990(1) | BQ1: I:1990(2) | BR1: I:1990(3) | BS1: I:1990(4) | BT1: I:1990(5) | BU1: I:1990(7) | BV1: I:1990(8) | BW1: I:1990(12) | BX1: I:1991(1) | BY1: I:1991(2) | BZ1: I:1991(4) | CA1: I:1991(9) | CB1: I:1991(10) | CC1: I:1991(11) | CD1: I:1991(12) | CE1: I:1992(2) | CF1: I:1992(5) | CG1: I:1992(7) | CH1: I:1993(1) | CI1: I:1994(3) | CJ1: I:1994(7) | CK1: I:1995(6) | CL1: I:1995(8) | CM1: I:1995(5) | CN1: I:1998(8) | CO1: I:1998(12) | CP1: I:2006(4) | CQ1: S1:1997(10) | CR1: S1:1997(12) | CS1: S1:1999(5) | CT1: I:2003(9)
A2: 1974(1) | B2: #N/A | C2: #N/A | D2: #N/A | E2: #N/A | F2: #N/A | G2: #N/A | H2: 1.46 | I2: #N/A | J2: #N/A | K2: #N/A | L2: 47.3282 | M2: 46.2745 | N2: #N/A | O2: #N/A | P2: #N/A | Q2: #N/A | R2: #N/A | S2: #N/A | T2: 0 | U2: 0 | V2: 0 | W2: 0 | X2: #N/A | Y2: 0 | Z2: 0 | AA2: 0 | AB2: 0 | AC2: 0 | AD2: 0 | AE2: 0 | AF2: 0 | AG2: 0 | AH2: 0 | AI2: 0 | AJ2: 0 | AK2: 0 | AL2: 0 | AM2: 0 | AN2: 0 | AO2: 0 | AP2: 0 | AQ2: 0 | AR2: 0 | AS2: 0 | AT2: 0 | AU2: 0 | AV2: 0 | AW2: 0 | AX2: 0 | AY2: 0 | AZ2: 0 | BA2: 0 | BB2: 0 | BC2: 0 | BD2: 0 | BE2: 0 | BF2: 0 | BG2: 0 | BH2: 0 | BI2: 0 | BJ2: 0 | BK2: 0 | BL2: 0 | BM2: 0 | BN2: 0 | BO2: 0 | BP2: 0 | BQ2: 0 | BR2: 0 | BS2: 0 | BT2: 0 | BU2: 0 | BV2: 0 | BW2: 0 | BX2: 0 | BY2: 0 | BZ2: 0 | CA2: 0 | CB2: 0 | CC2: 0 | CD2: 0 | CE2: 0 | CF2: 0 | CG2: 0 | CH2: 0 | CI2: 0 | CJ2: 0 | CK2: 0 | CL2: 0 | CM2: 0 | CN2: 0 | CO2: 0 | CP2: 0 | CQ2: 1 | CR2: 1 | CS2: 1 | CT2: 0
A3: 1974(2) | B3: #N/A | C3: #N/A | D3: #N/A | E3: #N/A | F3: #N/A | G3: #N/A | H3: 1.15 | I3: #N/A | J3: #N/A | K3: #N/A | L3: 47.1853 | M3: 47.0204 | N3: -0.0030239089 | O3: 0.015990497 | P3: #N/A | Q3: #N/A | R3: #N/A | S3: #N/A | T3: 0 | U3: 0 | V3: 0 | W3: 0 | X3: #N/A | Y3: 0 | Z3: 0 | AA3: 0 | AB3: 0 | AC3: 0 | AD3: 0 | AE3: 0 | AF3: 0 | AG3: 0 | AH3: 0 | AI3: 0 | AJ3: 0 | AK3: 0 | AL3: 0 | AM3: 0 | AN3: 0 | AO3: 0 | AP3: 0 | AQ3: 0 | AR3: 0 | AS3: 0 | AT3: 0 | AU3: 0 | AV3: 0 | AW3: 0 | AX3: 0 | AY3: 0 | AZ3: 0 | BA3: 0 | BB3: 0 | BC3: 0 | BD3: 0 | BE3: 0 | BF3: 0 | BG3: 0 | BH3: 0 | BI3: 0 | BJ3: 0 | BK3: 0 | BL3: 0 | BM3: 0 | BN3: 0 | BO3: 0 | BP3: 0 | BQ3: 0 | BR3: 0 | BS3: 0 | BT3: 0 | BU3: 0 | BV3: 0 | BW3: 0 | BX3: 0 | BY3: 0 | BZ3: 0 | CA3: 0 | CB3: 0 | CC3: 0 | CD3: 0 | CE3: 0 | CF3: 0 | CG3: 0 | CH3: 0 | CI3: 0 | CJ3: 0 | CK3: 0 | CL3: 0 | CM3: 0 | CN3: 0 | CO3: 0 | CP3: 0 | CQ3: 1 | CR3: 1 | CS3: 1 | CT3: 0
A4: 1974(3) | B4: #N/A | C4: #N/A | D4: #N/A | E4: #N/A | F4: #N/A | G4: #N/A | H4: 1.16 | I4: #N/A | J4: #N/A | K4: #N/A | L4: 47.1963 | M4: 47.2636 | N4: 0.00023309628 | O4: 0.0051588931 | P4: #N/A | Q4: #N/A | R4: #N/A | S4: #N/A | T4: 0 | U4: 0 | V4: 0 | W4: 0 | X4: #N/A | Y4: 0 | Z4: 0 | AA4: 0 | AB4: 0 | AC4: 0 | AD4: 0 | AE4: 0 | AF4: 0 | AG4: 0 | AH4: 0 | AI4: 0 | AJ4: 0 | AK4: 0 | AL4: 0 | AM4: 0 | AN4: 0 | AO4: 0 | AP4: 0 | AQ4: 0 | AR4: 0 | AS4: 0 | AT4: 0 | AU4: 0 | AV4: 0 | AW4: 0 | AX4: 0 | AY4: 0 | AZ4: 0 | BA4: 0 | BB4: 0 | BC4: 0 | BD4: 0 | BE4: 0 | BF4: 0 | BG4: 0 | BH4: 0 | BI4: 0 | BJ4: 0 | BK4: 0 | BL4: 0 | BM4: 0 | BN4: 0 | BO4: 0 | BP4: 0 | BQ4: 0 | BR4: 0 | BS4: 0 | BT4: 0 | BU4: 0 | BV4: 0 | BW4: 0 | BX4: 0 | BY4: 0 | BZ4: 0 | CA4: 0 | CB4: 0 | CC4: 0 | CD4: 0 | CE4: 0 | CF4: 0 | CG4: 0 | CH4: 0 | CI4: 0 | CJ4: 0 | CK4: 0 | CL4: 0 | CM4: 0 | CN4: 0 | CO4: 0 | CP4: 0 | CQ4: 1 | CR4: 1 | CS4: 1 | CT4: 0
A5: 1974(4) | B5: #N/A | C5: #N/A | D5: #N/A | E5: #N/A | F5: #N/A | G5: #N/A | H5: 1.21 | I5: #N/A | J5: #N/A | K5: #N/A | L5: 47.0514 | M5: 46.6531 | N5: -0.0030748785 | O5: -0.013001066 | P5: #N/A | Q5: #N/A | R5: #N/A | S5: #N/A | T5: 0 | U5: 0 | V5: 0 | W5: 0 | X5: #N/A | Y5: 0 | Z5: 0 | AA5: 0 | AB5: 0 | AC5: 0 | AD5: 0 | AE5: 0 | AF5: 0 | AG5: 0 | AH5: 0 | AI5: 0 | AJ5: 0 | AK5: 0 | AL5: 0 | AM5: 0 | AN5: 0 | AO5: 0 | AP5: 0 | AQ5: 0 | AR5: 0 | AS5: 0 | AT5: 0 | AU5: 0 | AV5: 0 | AW5: 0 | AX5: 0 | AY5: 0 | AZ5: 0 | BA5: 0 | BB5: 0 | BC5: 0 | BD5: 0 | BE5: 0 | BF5: 0 | BG5: 0 | BH5: 0 | BI5: 0 | BJ5: 0 | BK5: 0 | BL5: 0 | BM5: 0 | BN5: 0 | BO5: 0 | BP5: 0 | BQ5: 0 | BR5: 0 | BS5: 0 | BT5: 0 | BU5: 0 | BV5: 0 | BW5: 0 | BX5: 0 | BY5: 0 | BZ5: 0 | CA5: 0 | CB5: 0 | CC5: 0 | CD5: 0 | CE5: 0 | CF5: 0 | CG5: 0 | CH5: 0 | CI5: 0 | CJ5: 0 | CK5: 0 | CL5: 0 | CM5: 0 | CN5: 0 | CO5: 0 | CP5: 0 | CQ5: 1 | CR5: 1 | CS5: 1 | CT5: 0
A6: 1974(5) | B6: #N/A | C6: #N/A | D6: #N/A | E6: #N/A | F6: #N/A | G6: #N/A | H6: 1.24 | I6: #N/A | J6: #N/A | K6: #N/A | L6: 47.4078 | M6: 47.5165 | N6: 0.007546151 | O6: 0.018337642 | P6: #N/A | Q6: #N/A | R6: #N/A | S6: #N/A | T6: 0 | U6: 0 | V6: 0 | W6: 0 | X6: #N/A | Y6: 0 | Z6: 0 | AA6: 0 | AB6: 0 | AC6: 0 | AD6: 0 | AE6: 0 | AF6: 0 | AG6: 0 | AH6: 0 | AI6: 0 | AJ6: 0 | AK6: 0 | AL6: 0 | AM6: 0 | AN6: 0 | AO6: 0 | AP6: 0 | AQ6: 0 | AR6: 0 | AS6: 0 | AT6: 0 | AU6: 0 | AV6: 0 | AW6: 0 | AX6: 0 | AY6: 0 | AZ6: 0 | BA6: 0 | BB6: 0 | BC6: 0 | BD6: 0 | BE6: 0 | BF6: 0 | BG6: 0 | BH6: 0 | BI6: 0 | BJ6: 0 | BK6: 0 | BL6: 0 | BM6: 0 | BN6: 0 | BO6: 0 | BP6: 0 | BQ6: 0 | BR6: 0 | BS6: 0 | BT6: 0 | BU6: 0 | BV6: 0 | BW6: 0 | BX6: 0 | BY6: 0 | BZ6: 0 | CA6: 0 | CB6: 0 | CC6: 0 | CD6: 0 | CE6: 0 | CF6: 0 | CG6: 0 | CH6: 0 | CI6: 0 | CJ6: 0 | CK6: 0 | CL6: 0 | CM6: 0 | CN6: 0 | CO6: 0 | CP6: 0 | CQ6: 1 | CR6: 1 | CS6: 1 | CT6: 0
A7: 1974(6) | B7: #N/A | C7: #N/A | D7: #N/A | E7: #N/A | F7: #N/A | G7: #N/A | H7: 1.51 | I7: #N/A | J7: #N/A | K7: #N/A | L7: 47.3559 | M7: 48.455 | N7: -0.0010953562 | O7: 0.019558513 | P7: #N/A | Q7: #N/A | R7: #N/A | S7: #N/A | T7: 0 | U7: 0 | V7: 0 | W7: 0 | X7: #N/A | Y7: 0 | Z7: 0 | AA7: 0 | AB7: 0 | AC7: 0 | AD7: 0 | AE7: 0 | AF7: 0 | AG7: 0 | AH7: 0 | AI7: 0 | AJ7: 0 | AK7: 0 | AL7: 0 | AM7: 0 | AN7: 0 | AO7: 0 | AP7: 0 | AQ7: 0 | AR7: 0 | AS7: 0 | AT7: 0 | AU7: 0 | AV7: 0 | AW7: 0 | AX7: 0 | AY7: 0 | AZ7: 0 | BA7: 0 | BB7: 0 | BC7: 0 | BD7: 0 | BE7: 0 | BF7: 0 | BG7: 0 | BH7: 0 | BI7: 0 | BJ7: 0 | BK7: 0 | BL7: 0 | BM7: 0 | BN7: 0 | BO7: 0 | BP7: 0 | BQ7: 0 | BR7: 0 | BS7: 0 | BT7: 0 | BU7: 0 | BV7: 0 | BW7: 0 | BX7: 0 | BY7: 0 | BZ7: 0 | CA7: 0 | CB7: 0 | CC7: 0 | CD7: 0 | CE7: 0 | CF7: 0 | CG7: 0 | CH7: 0 | CI7: 0 | CJ7: 0 | CK7: 0 | CL7: 0 | CM7: 0 | CN7: 0 | CO7: 0 | CP7: 0 | CQ7: 1 | CR7: 1 | CS7: 1 | CT7: 0
A8: 1974(7) | B8: #N/A | C8: #N/A | D8: #N/A | E8: #N/A | F8: #N/A | G8: #N/A | H8: 1.62 | I8: #N/A | J8: #N/A | K8: #N/A | L8: 47.3768 | M8: 46.1372 | N8: 0.00044124152 | O8: -0.049015966 | P8: #N/A | Q8: #N/A | R8: #N/A | S8: #N/A | T8: 0 | U8: 0 | V8: 0 | W8: 0 | X8: #N/A | Y8: 0 | Z8: 0 | AA8: 0 | AB8: 0 | AC8: 0 | AD8: 0 | AE8: 0 | AF8: 0 | AG8: 0 | AH8: 0 | AI8: 0 | AJ8: 0 | AK8: 0 | AL8: 0 | AM8: 0 | AN8: 0 | AO8: 0 | AP8: 0 | AQ8: 0 | AR8: 0 | AS8: 0 | AT8: 0 | AU8: 0 | AV8: 0 | AW8: 0 | AX8: 0 | AY8: 0 | AZ8: 0 | BA8: 0 | BB8: 0 | BC8: 0 | BD8: 0 | BE8: 0 | BF8: 0 | BG8: 0 | BH8: 0 | BI8: 0 | BJ8: 0 | BK8: 0 | BL8: 0 | BM8: 0 | BN8: 0 | BO8: 0 | BP8: 0 | BQ8: 0 | BR8: 0 | BS8: 0 | BT8: 0 | BU8: 0 | BV8: 0 | BW8: 0 | BX8: 0 | BY8: 0 | BZ8: 0 | CA8: 0 | CB8: 0 | CC8: 0 | CD8: 0 | CE8: 0 | CF8: 0 | CG8: 0 | CH8: 0 | CI8: 0 | CJ8: 0 | CK8: 0 | CL8: 0 | CM8: 0 | CN8: 0 | CO8: 0 | CP8: 0 | CQ8: 1 | CR8: 1 | CS8: 1 | CT8: 0
A9: 1974(8) | B9: #N/A | C9: #N/A | D9: #N/A | E9: #N/A | F9: #N/A | G9: #N/A | H9: 1 | I9: #N/A | J9: #N/A | K9: #N/A | L9: 46.913 | M9: 46.6709 | N9: -0.0098378349 | O9: 0.011501278 | P9: #N/A | Q9: #N/A | R9: #N/A | S9: #N/A | T9: 0 | U9: 0 | V9: 0 | W9: 0 | X9: #N/A | Y9: 0 | Z9: 0 | AA9: 0 | AB9: 0 | AC9: 0 | AD9: 0 | AE9: 0 | AF9: 0 | AG9: 0 | AH9: 0 | AI9: 0 | AJ9: 0 | AK9: 0 | AL9: 0 | AM9: 0 | AN9: 0 | AO9: 0 | AP9: 0 | AQ9: 0 | AR9: 0 | AS9: 0 | AT9: 0 | AU9: 0 | AV9: 0 | AW9: 0 | AX9: 0 | AY9: 0 | AZ9: 0 | BA9: 0 | BB9: 0 | BC9: 0 | BD9: 0 | BE9: 0 | BF9: 0 | BG9: 0 | BH9: 0 | BI9: 0 | BJ9: 0 | BK9: 0 | BL9: 0 | BM9: 0 | BN9: 0 | BO9: 0 | BP9: 0 | BQ9: 0 | BR9: 0 | BS9: 0 | BT9: 0 | BU9: 0 | BV9: 0 | BW9: 0 | BX9: 0 | BY9: 0 | BZ9: 0 | CA9: 0 | CB9: 0 | CC9: 0 | CD9: 0 | CE9: 0 | CF9: 0 | CG9: 0 | CH9: 0 | CI9: 0 | CJ9: 0 | CK9: 0 | CL9: 0 | CM9: 0 | CN9: 0 | CO9: 0 | CP9: 0 | CQ9: 1 | CR9: 1 | CS9: 1 | CT9: 0
A10: 1974(9) | B10: #N/A | C10: #N/A | D10: #N/A | E10: #N/A | F10: #N/A | G10: #N/A | H10: 1.38 | I10: #N/A | J10: #N/A | K10: #N/A | L10: 46.9406 | M10: 47.8221 | N10: 0.00058815007 | O10: 0.024367032 | P10: #N/A | Q10: #N/A | R10: #N/A | S10: #N/A | T10: 0 | U10: 0 | V10: 0 | W10: 0 | X10: #N/A | Y10: 0 | Z10: 0 | AA10: 0 | AB10: 0 | AC10: 0 | AD10: 0 | AE10: 0 | AF10: 0 | AG10: 0 | AH10: 0 | AI10: 0 | AJ10: 0 | AK10: 0 | AL10: 0 | AM10: 0 | AN10: 0 | AO10: 0 | AP10: 0 | AQ10: 0 | AR10: 0 | AS10: 0 | AT10: 0 | AU10: 0 | AV10: 0 | AW10: 0 | AX10: 0 | AY10: 0 | AZ10: 0 | BA10: 0 | BB10: 0 | BC10: 0 | BD10: 0 | BE10: 0 | BF10: 0 | BG10: 0 | BH10: 0 | BI10: 0 | BJ10: 0 | BK10: 0 | BL10: 0 | BM10: 0 | BN10: 0 | BO10: 0 | BP10: 0 | BQ10: 0 | BR10: 0 | BS10: 0 | BT10: 0 | BU10: 0 | BV10: 0 | BW10: 0 | BX10: 0 | BY10: 0 | BZ10: 0 | CA10: 0 | CB10: 0 | CC10: 0 | CD10: 0 | CE10: 0 | CF10: 0 | CG10: 0 | CH10: 0 | CI10: 0 | CJ10: 0 | CK10: 0 | CL10: 0 | CM10: 0 | CN10: 0 | CO10: 0 | CP10: 0 | CQ10: 1 | CR10: 1 | CS10: 1 | CT10: 0
A11: 1974(10) | B11: #N/A | C11: #N/A | D11: #N/A | E11: #N/A | F11: #N/A | G11: #N/A | H11: 1.12 | I11: #N/A | J11: #N/A | K11: #N/A | L11: 46.7581 | M11: 47.7994 | N11: -0.0038954699 | O11: -0.00047478863 | P11: #N/A | Q11: #N/A | R11: #N/A | S11: #N/A | T11: 0 | U11: 0 | V11: 0 | W11: 0 | X11: #N/A | Y11: 0 | Z11: 0 | AA11: 0 | AB11: 0 | AC11: 0 | AD11: 0 | AE11: 0 | AF11: 0 | AG11: 0 | AH11: 0 | AI11: 0 | AJ11: 0 | AK11: 0 | AL11: 0 | AM11: 0 | AN11: 0 | AO11: 0 | AP11: 0 | AQ11: 0 | AR11: 0 | AS11: 0 | AT11: 0 | AU11: 0 | AV11: 0 | AW11: 0 | AX11: 0 | AY11: 0 | AZ11: 0 | BA11: 0 | BB11: 0 | BC11: 0 | BD11: 0 | BE11: 0 | BF11: 0 | BG11: 0 | BH11: 0 | BI11: 0 | BJ11: 0 | BK11: 0 | BL11: 0 | BM11: 0 | BN11: 0 | BO11: 0 | BP11: 0 | BQ11: 0 | BR11: 0 | BS11: 0 | BT11: 0 | BU11: 0 | BV11: 0 | BW11: 0 | BX11: 0 | BY11: 0 | BZ11: 0 | CA11: 0 | CB11: 0 | CC11: 0 | CD11: 0 | CE11: 0 | CF11: 0 | CG11: 0 | CH11: 0 | CI11: 0 | CJ11: 0 | CK11: 0 | CL11: 0 | CM11: 0 | CN11: 0 | CO11: 0 | CP11: 0 | CQ11: 1 | CR11: 1 | CS11: 1 | CT11: 0
A12: 1974(11) | B12: #N/A | C12: #N/A | D12: #N/A | E12: #N/A | F12: #N/A | G12: #N/A | H12: 1.46 | I12: #N/A | J12: #N/A | K12: #N/A | L12: 45.2208 | M12: 45.5796 | N12: -0.033430345 | O12: -0.047552839 | P12: #N/A | Q12: #N/A | R12: #N/A | S12: #N/A | T12: 0 | U12: 0 | V12: 0 | W12: 0 | X12: #N/A | Y12: 0 | Z12: 0 | AA12: 0 | AB12: 0 | AC12: 0 | AD12: 0 | AE12: 0 | AF12: 0 | AG12: 0 | AH12: 0 | AI12: 0 | AJ12: 0 | AK12: 0 | AL12: 0 | AM12: 0 | AN12: 0 | AO12: 0 | AP12: 0 | AQ12: 0 | AR12: 0 | AS12: 0 | AT12: 0 | AU12: 0 | AV12: 0 | AW12: 0 | AX12: 0 | AY12: 0 | AZ12: 0 | BA12: 0 | BB12: 0 | BC12: 0 | BD12: 0 | BE12: 0 | BF12: 0 | BG12: 0 | BH12: 0 | BI12: 0 | BJ12: 0 | BK12: 0 | BL12: 0 | BM12: 0 | BN12: 0 | BO12: 0 | BP12: 0 | BQ12: 0 | BR12: 0 | BS12: 0 | BT12: 0 | BU12: 0 | BV12: 0 | BW12: 0 | BX12: 0 | BY12: 0 | BZ12: 0 | CA12: 0 | CB12: 0 | CC12: 0 | CD12: 0 | CE12: 0 | CF12: 0 | CG12: 0 | CH12: 0 | CI12: 0 | CJ12: 0 | CK12: 0 | CL12: 0 | CM12: 0 | CN12: 0 | CO12: 0 | CP12: 0 | CQ12: 1 | CR12: 1 | CS12: 1 | CT12: 0
A13: 1974(12) | B13: #N/A | C13: #N/A | D13: #N/A | E13: #N/A | F13: #N/A | G13: #N/A | H13: 1.73 | I13: #N/A | J13: #N/A | K13: #N/A | L13: 43.6268 | M13: 43.1688 | N13: -0.035885518 | O13: -0.054342236 | P13: #N/A | Q13: #N/A | R13: #N/A | S13: #N/A | T13: 0 | U13: 0 | V13: 0 | W13: 0 | X13: #N/A | Y13: 0 | Z13: 0 | AA13: 0 | AB13: 0 | AC13: 0 | AD13: 0 | AE13: 0 | AF13: 0 | AG13: 0 | AH13: 0 | AI13: 0 | AJ13: 0 | AK13: 0 | AL13: 0 | AM13: 0 | AN13: 0 | AO13: 0 | AP13: 0 | AQ13: 0 | AR13: 0 | AS13: 0 | AT13: 0 | AU13: 0 | AV13: 0 | AW13: 0 | AX13: 0 | AY13: 0 | AZ13: 0 | BA13: 0 | BB13: 0 | BC13: 0 | BD13: 0 | BE13: 0 | BF13: 0 | BG13: 0 | BH13: 0 | BI13: 0 | BJ13: 0 | BK13: 0 | BL13: 0 | BM13: 0 | BN13: 0 | BO13: 0 | BP13: 0 | BQ13: 0 | BR13: 0 | BS13: 0 | BT13: 0 | BU13: 0 | BV13: 0 | BW13: 0 | BX13: 0 | BY13: 0 | BZ13: 0 | CA13: 0 | CB13: 0 | CC13: 0 | CD13: 0 | CE13: 0 | CF13: 0 | CG13: 0 | CH13: 0 | CI13: 0 | CJ13: 0 | CK13: 0 | CL13: 0 | CM13: 0 | CN13: 0 | CO13: 0 | CP13: 0 | CQ13: 1 | CR13: 1 | CS13: 1 | CT13: 0
A14: 1975(1) | B14: #N/A | C14: #N/A | D14: #N/A | E14: #N/A | F14: #N/A | G14: 51.008963 | H14: 1.79 | I14: #N/A | J14: #N/A | K14: #N/A | L14: 43.023 | M14: 42.2035 | N14: -0.013936784 | O14: -0.022614856 | P14: 40.694754 | Q14: #N/A | R14: #N/A | S14: 0.017741681 | T14: 0 | U14: 0 | V14: 0 | W14: 0 | X14: #N/A | Y14: 0 | Z14: 0 | AA14: 0 | AB14: 0 | AC14: 0 | AD14: 0 | AE14: 0 | AF14: 0 | AG14: 0 | AH14: 0 | AI14: 0 | AJ14: 0 | AK14: 0 | AL14: 0 | AM14: 0 | AN14: 0 | AO14: 0 | AP14: 0 | AQ14: 0 | AR14: 0 | AS14: 0 | AT14: 0 | AU14: 0 | AV14: 0 | AW14: 0 | AX14: 0 | AY14: 0 | AZ14: 0 | BA14: 0 | BB14: 0 | BC14: 0 | BD14: 0 | BE14: 0 | BF14: 0 | BG14: 0 | BH14: 0 | BI14: 0 | BJ14: 0 | BK14: 0 | BL14: 0 | BM14: 0 | BN14: 0 | BO14: 0 | BP14: 0 | BQ14: 0 | BR14: 0 | BS14: 0 | BT14: 0 | BU14: 0 | BV14: 0 | BW14: 0 | BX14: 0 | BY14: 0 | BZ14: 0 | CA14: 0 | CB14: 0 | CC14: 0 | CD14: 0 | CE14: 0 | CF14: 0 | CG14: 0 | CH14: 0 | CI14: 0 | CJ14: 0 | CK14: 0 | CL14: 0 | CM14: 0 | CN14: 0 | CO14: 0 | CP14: 0 | CQ14: 1 | CR14: 1 | CS14: 1 | CT14: 0
A15: 1975(2) | B15: #N/A | C15: #N/A | D15: #N/A | E15: #N/A | F15: #N/A | G15: 47.858454 | H15: 1.6 | I15: #N/A | J15: #N/A | K15: #N/A | L15: 42.0254 | M15: 42.02 | N15: -0.023460659 | O15: -0.0043574606 | P15: 38.18129 | Q15: -0.063753568 | R15: #N/A | S15: 0.015873349 | T15: 0 | U15: 0 | V15: 0 | W15: 0 | X15: -0.0018683323 | Y15: 0 | Z15: 0 | AA15: 0 | AB15: 0 | AC15: 0 | AD15: 0 | AE15: 0 | AF15: 0 | AG15: 0 | AH15: 0 | AI15: 0 | AJ15: 0 | AK15: 0 | AL15: 0 | AM15: 0 | AN15: 0 | AO15: 0 | AP15: 0 | AQ15: 0 | AR15: 0 | AS15: 0 | AT15: 0 | AU15: 0 | AV15: 0 | AW15: 0 | AX15: 0 | AY15: 0 | AZ15: 0 | BA15: 0 | BB15: 0 | BC15: 0 | BD15: 0 | BE15: 0 | BF15: 0 | BG15: 0 | BH15: 0 | BI15: 0 | BJ15: 0 | BK15: 0 | BL15: 0 | BM15: 0 | BN15: 0 | BO15: 0 | BP15: 0 | BQ15: 0 | BR15: 0 | BS15: 0 | BT15: 0 | BU15: 0 | BV15: 0 | BW15: 0 | BX15: 0 | BY15: 0 | BZ15: 0 | CA15: 0 | CB15: 0 | CC15: 0 | CD15: 0 | CE15: 0 | CF15: 0 | CG15: 0 | CH15: 0 | CI15: 0 | CJ15: 0 | CK15: 0 | CL15: 0 | CM15: 0 | CN15: 0 | CO15: 0 | CP15: 0 | CQ15: 1 | CR15: 1 | CS15: 1 | CT15: 0
A16: 1975(3) | B16: #N/A | C16: #N/A | D16: #N/A | E16: #N/A | F16: #N/A | G16: 51.833179 | H16: 1.03 | I16: #N/A | J16: #N/A | K16: #N/A | L16: 41.5778 | M16: 41.6022 | N16: -0.010707826 | O16: -0.0099926449 | P16: 41.35231 | Q16: 0.079782673 | R16: #N/A | S16: 0.010247316 | T16: 0 | U16: 0 | V16: 0 | W16: 0 | X16: -0.0056260327 | Y16: 0 | Z16: 0 | AA16: 0 | AB16: 0 | AC16: 0 | AD16: 0 | AE16: 0 | AF16: 0 | AG16: 0 | AH16: 0 | AI16: 0 | AJ16: 0 | AK16: 0 | AL16: 0 | AM16: 0 | AN16: 0 | AO16: 0 | AP16: 0 | AQ16: 0 | AR16: 0 | AS16: 0 | AT16: 0 | AU16: 0 | AV16: 0 | AW16: 0 | AX16: 0 | AY16: 0 | AZ16: 0 | BA16: 0 | BB16: 0 | BC16: 0 | BD16: 0 | BE16: 0 | BF16: 0 | BG16: 0 | BH16: 0 | BI16: 0 | BJ16: 0 | BK16: 0 | BL16: 0 | BM16: 0 | BN16: 0 | BO16: 0 | BP16: 0 | BQ16: 0 | BR16: 0 | BS16: 0 | BT16: 0 | BU16: 0 | BV16: 0 | BW16: 0 | BX16: 0 | BY16: 0 | BZ16: 0 | CA16: 0 | CB16: 0 | CC16: 0 | CD16: 0 | CE16: 0 | CF16: 0 | CG16: 0 | CH16: 0 | CI16: 0 | CJ16: 0 | CK16: 0 | CL16: 0 | CM16: 0 | CN16: 0 | CO16: 0 | CP16: 0 | CQ16: 1 | CR16: 1 | CS16: 1 | CT16: 0
A17: 1975(4) | B17: #N/A | C17: #N/A | D17: #N/A | E17: #N/A | F17: #N/A | G17: 54.613945 | H17: 1.19 | I17: #N/A | J17: #N/A | K17: #N/A | L17: 41.6247 | M17: 41.7066 | N17: 0.0011273701 | O17: 0.0025063392 | P17: 43.570795 | Q17: 0.052258796 | R17: #N/A | S17: 0.011829752 | T17: 0 | U17: 0 | V17: 0 | W17: 0 | X17: 0.0015824353 | Y17: 0 | Z17: 0 | AA17: 0 | AB17: 0 | AC17: 0 | AD17: 0 | AE17: 0 | AF17: 0 | AG17: 0 | AH17: 0 | AI17: 0 | AJ17: 0 | AK17: 0 | AL17: 0 | AM17: 0 | AN17: 0 | AO17: 0 | AP17: 0 | AQ17: 0 | AR17: 0 | AS17: 0 | AT17: 0 | AU17: 0 | AV17: 0 | AW17: 0 | AX17: 0 | AY17: 0 | AZ17: 0 | BA17: 0 | BB17: 0 | BC17: 0 | BD17: 0 | BE17: 0 | BF17: 0 | BG17: 0 | BH17: 0 | BI17: 0 | BJ17: 0 | BK17: 0 | BL17: 0 | BM17: 0 | BN17: 0 | BO17: 0 | BP17: 0 | BQ17: 0 | BR17: 0 | BS17: 0 | BT17: 0 | BU17: 0 | BV17: 0 | BW17: 0 | BX17: 0 | BY17: 0 | BZ17: 0 | CA17: 0 | CB17: 0 | CC17: 0 | CD17: 0 | CE17: 0 | CF17: 0 | CG17: 0 | CH17: 0 | CI17: 0 | CJ17: 0 | CK17: 0 | CL17: 0 | CM17: 0 | CN17: 0 | CO17: 0 | CP17: 0 | CQ17: 1 | CR17: 1 | CS17: 1 | CT17: 0
A18: 1975(5) | B18: #N/A | C18: #N/A | D18: #N/A | E18: #N/A | F18: #N/A | G18: 54.806519 | H18: 1.46 | I18: #N/A | J18: #N/A | K18: #N/A | L18: 41.5252 | M18: 41.4999 | N18: -0.0023932692 | O18: -0.0049683721 | P18: 43.724429 | Q18: 0.003519891 | R18: #N/A | S18: 0.014494446 | T18: 0 | U18: 0 | V18: 0 | W18: 0 | X18: 0.0026646944 | Y18: 0 | Z18: 0 | AA18: 0 | AB18: 0 | AC18: 0 | AD18: 0 | AE18: 0 | AF18: 0 | AG18: 0 | AH18: 0 | AI18: 0 | AJ18: 0 | AK18: 0 | AL18: 0 | AM18: 0 | AN18: 0 | AO18: 0 | AP18: 0 | AQ18: 0 | AR18: 0 | AS18: 0 | AT18: 0 | AU18: 0 | AV18: 0 | AW18: 0 | AX18: 0 | AY18: 0 | AZ18: 0 | BA18: 0 | BB18: 0 | BC18: 0 | BD18: 0 | BE18: 0 | BF18: 0 | BG18: 0 | BH18: 0 | BI18: 0 | BJ18: 0 | BK18: 0 | BL18: 0 | BM18: 0 | BN18: 0 | BO18: 0 | BP18: 0 | BQ18: 0 | BR18: 0 | BS18: 0 | BT18: 0 | BU18: 0 | BV18: 0 | BW18: 0 | BX18: 0 | BY18: 0 | BZ18: 0 | CA18: 0 | CB18: 0 | CC18: 0 | CD18: 0 | CE18: 0 | CF18: 0 | CG18: 0 | CH18: 0 | CI18: 0 | CJ18: 0 | CK18: 0 | CL18: 0 | CM18: 0 | CN18: 0 | CO18: 0 | CP18: 0 | CQ18: 1 | CR18: 1 | CS18: 1 | CT18: 0
A19: 1975(6) | B19: #N/A | C19: #N/A | D19: #N/A | E19: #N/A | F19: #N/A | G19: 56.624416 | H19: 1.76 | I19: #N/A | J19: #N/A | K19: #N/A | L19: 41.8018 | M19: 42.7036 | N19: 0.0066389289 | O19: 0.028592208 | P19: 45.174741 | Q19: 0.032631127 | R19: #N/A | S19: 0.017446914 | T19: 0 | U19: 0 | V19: 0 | W19: 0 | X19: 0.0029524675 | Y19: 0 | Z19: 0 | AA19: 0 | AB19: 0 | AC19: 0 | AD19: 0 | AE19: 0 | AF19: 0 | AG19: 0 | AH19: 0 | AI19: 0 | AJ19: 0 | AK19: 0 | AL19: 0 | AM19: 0 | AN19: 0 | AO19: 0 | AP19: 0 | AQ19: 0 | AR19: 0 | AS19: 0 | AT19: 0 | AU19: 0 | AV19: 0 | AW19: 0 | AX19: 0 | AY19: 0 | AZ19: 0 | BA19: 0 | BB19: 0 | BC19: 0 | BD19: 0 | BE19: 0 | BF19: 0 | BG19: 0 | BH19: 0 | BI19: 0 | BJ19: 0 | BK19: 0 | BL19: 0 | BM19: 0 | BN19: 0 | BO19: 0 | BP19: 0 | BQ19: 0 | BR19: 0 | BS19: 0 | BT19: 0 | BU19: 0 | BV19: 0 | BW19: 0 | BX19: 0 | BY19: 0 | BZ19: 0 | CA19: 0 | CB19: 0 | CC19: 0 | CD19: 0 | CE19: 0 | CF19: 0 | CG19: 0 | CH19: 0 | CI19: 0 | CJ19: 0 | CK19: 0 | CL19: 0 | CM19: 0 | CN19: 0 | CO19: 0 | CP19: 0 | CQ19: 1 | CR19: 1 | CS19: 1 | CT19: 0
A20: 1975(7) | B20: #N/A | C20: #N/A | D20: #N/A | E20: #N/A | F20: #N/A | G20: 58.758134 | H20: 1.65 | I20: #N/A | J20: #N/A | K20: #N/A | L20: 42.1962 | M20: 40.9055 | N20: 0.0093907688 | O20: -0.043018697 | P20: 46.877013 | Q20: 0.036989329 | R20: #N/A | S20: 0.016365354 | T20: 0 | U20: 0 | V20: 0 | W20: 0 | X20: -0.0010815595 | Y20: 0 | Z20: 0 | AA20: 0 | AB20: 0 | AC20: 0 | AD20: 0 | AE20: 0 | AF20: 0 | AG20: 0 | AH20: 0 | AI20: 0 | AJ20: 0 | AK20: 0 | AL20: 0 | AM20: 0 | AN20: 0 | AO20: 0 | AP20: 0 | AQ20: 0 | AR20: 0 | AS20: 0 | AT20: 0 | AU20: 0 | AV20: 0 | AW20: 0 | AX20: 0 | AY20: 0 | AZ20: 0 | BA20: 0 | BB20: 0 | BC20: 0 | BD20: 0 | BE20: 0 | BF20: 0 | BG20: 0 | BH20: 0 | BI20: 0 | BJ20: 0 | BK20: 0 | BL20: 0 | BM20: 0 | BN20: 0 | BO20: 0 | BP20: 0 | BQ20: 0 | BR20: 0 | BS20: 0 | BT20: 0 | BU20: 0 | BV20: 0 | BW20: 0 | BX20: 0 | BY20: 0 | BZ20: 0 | CA20: 0 | CB20: 0 | CC20: 0 | CD20: 0 | CE20: 0 | CF20: 0 | CG20: 0 | CH20: 0 | CI20: 0 | CJ20: 0 | CK20: 0 | CL20: 0 | CM20: 0 | CN20: 0 | CO20: 0 | CP20: 0 | CQ20: 1 | CR20: 1 | CS20: 1 | CT20: 0
A21: 1975(8) | B21: #N/A | C21: #N/A | D21: #N/A | E21: #N/A | F21: #N/A | G21: 57.687424 | H21: 1.6 | I21: #N/A | J21: #N/A | K21: #N/A | L21: 42.6469 | M21: 42.5577 | N21: 0.010624417 | O21: 0.039596274 | P21: 46.022804 | Q21: -0.01839041 | R21: #N/A | S21: 0.015873349 | T21: 0 | U21: 0 | V21: 0 | W21: 0 | X21: -0.00049200493 | Y21: 0 | Z21: 0 | AA21: 0 | AB21: 0 | AC21: 0 | AD21: 0 | AE21: 0 | AF21: 0 | AG21: 0 | AH21: 0 | AI21: 0 | AJ21: 0 | AK21: 0 | AL21: 0 | AM21: 0 | AN21: 0 | AO21: 0 | AP21: 0 | AQ21: 0 | AR21: 0 | AS21: 0 | AT21: 0 | AU21: 0 | AV21: 0 | AW21: 0 | AX21: 0 | AY21: 0 | AZ21: 0 | BA21: 0 | BB21: 0 | BC21: 0 | BD21: 0 | BE21: 0 | BF21: 0 | BG21: 0 | BH21: 0 | BI21: 0 | BJ21: 0 | BK21: 0 | BL21: 0 | BM21: 0 | BN21: 0 | BO21: 0 | BP21: 0 | BQ21: 0 | BR21: 0 | BS21: 0 | BT21: 0 | BU21: 0 | BV21: 0 | BW21: 0 | BX21: 0 | BY21: 0 | BZ21: 0 | CA21: 0 | CB21: 0 | CC21: 0 | CD21: 0 | CE21: 0 | CF21: 0 | CG21: 0 | CH21: 0 | CI21: 0 | CJ21: 0 | CK21: 0 | CL21: 0 | CM21: 0 | CN21: 0 | CO21: 0 | CP21: 0 | CQ21: 1 | CR21: 1 | CS21: 1 | CT21: 0
A22: 1975(9) | B22: #N/A | C22: #N/A | D22: #N/A | E22: #N/A | F22: #N/A | G22: 59.135579 | H22: 1.57 | I22: #N/A | J22: #N/A | K22: #N/A | L22: 43.175 | M22: 43.9232 | N22: 0.012307037 | O22: 0.031581852 | P22: 47.178137 | Q22: 0.024793569 | R22: #N/A | S22: 0.01557803 | T22: 0 | U22: 0 | V22: 0 | W22: 0 | X22: -0.00029531919 | Y22: 0 | Z22: 0 | AA22: 0 | AB22: 0 | AC22: 0 | AD22: 0 | AE22: 0 | AF22: 0 | AG22: 0 | AH22: 0 | AI22: 0 | AJ22: 0 | AK22: 0 | AL22: 0 | AM22: 0 | AN22: 0 | AO22: 0 | AP22: 0 | AQ22: 0 | AR22: 0 | AS22: 0 | AT22: 0 | AU22: 0 | AV22: 0 | AW22: 0 | AX22: 0 | AY22: 0 | AZ22: 0 | BA22: 0 | BB22: 0 | BC22: 0 | BD22: 0 | BE22: 0 | BF22: 0 | BG22: 0 | BH22: 0 | BI22: 0 | BJ22: 0 | BK22: 0 | BL22: 0 | BM22: 0 | BN22: 0 | BO22: 0 | BP22: 0 | BQ22: 0 | BR22: 0 | BS22: 0 | BT22: 0 | BU22: 0 | BV22: 0 | BW22: 0 | BX22: 0 | BY22: 0 | BZ22: 0 | CA22: 0 | CB22: 0 | CC22: 0 | CD22: 0 | CE22: 0 | CF22: 0 | CG22: 0 | CH22: 0 | CI22: 0 | CJ22: 0 | CK22: 0 | CL22: 0 | CM22: 0 | CN22: 0 | CO22: 0 | CP22: 0 | CQ22: 1 | CR22: 1 | CS22: 1 | CT22: 0
A23: 1975(10) | B23: #N/A | C23: #N/A | D23: #N/A | E23: #N/A | F23: #N/A | G23: 61.184565 | H23: 1.95 | I23: #N/A | J23: #N/A | K23: #N/A | L23: 43.3625 | M23: 44.1579 | N23: 0.0043333883 | O23: 0.0053291922 | P23: 48.81281 | Q23: 0.034062192 | R23: #N/A | S23: 0.019312311 | T23: 0 | U23: 0 | V23: 0 | W23: 0 | X23: 0.0037342811 | Y23: 0 | Z23: 0 | AA23: 0 | AB23: 0 | AC23: 0 | AD23: 0 | AE23: 0 | AF23: 0 | AG23: 0 | AH23: 0 | AI23: 0 | AJ23: 0 | AK23: 0 | AL23: 0 | AM23: 0 | AN23: 0 | AO23: 0 | AP23: 0 | AQ23: 0 | AR23: 0 | AS23: 0 | AT23: 0 | AU23: 0 | AV23: 0 | AW23: 0 | AX23: 0 | AY23: 0 | AZ23: 0 | BA23: 0 | BB23: 0 | BC23: 0 | BD23: 0 | BE23: 0 | BF23: 0 | BG23: 0 | BH23: 0 | BI23: 0 | BJ23: 0 | BK23: 0 | BL23: 0 | BM23: 0 | BN23: 0 | BO23: 0 | BP23: 0 | BQ23: 0 | BR23: 0 | BS23: 0 | BT23: 0 | BU23: 0 | BV23: 0 | BW23: 0 | BX23: 0 | BY23: 0 | BZ23: 0 | CA23: 0 | CB23: 0 | CC23: 0 | CD23: 0 | CE23: 0 | CF23: 0 | CG23: 0 | CH23: 0 | CI23: 0 | CJ23: 0 | CK23: 0 | CL23: 0 | CM23: 0 | CN23: 0 | CO23: 0 | CP23: 0 | CQ23: 1 | CR23: 1 | CS23: 1 | CT23: 0
A24: 1975(11) | B24: #N/A | C24: #N/A | D24: #N/A | E24: #N/A | F24: #N/A | G24: 57.348494 | H24: 2.35 | I24: #N/A | J24: #N/A | K24: #N/A | L24: 43.4591 | M24: 43.6988 | N24: 0.0022252536 | O24: -0.010451205 | P24: 45.752407 | Q24: -0.064748372 | R24: #N/A | S24: 0.023228126 | T24: 0 | U24: 0 | V24: 0 | W24: 0 | X24: 0.0039158151 | Y24: 0 | Z24: 0 | AA24: 0 | AB24: 0 | AC24: 0 | AD24: 0 | AE24: 0 | AF24: 0 | AG24: 0 | AH24: 0 | AI24: 0 | AJ24: 0 | AK24: 0 | AL24: 0 | AM24: 0 | AN24: 0 | AO24: 0 | AP24: 0 | AQ24: 0 | AR24: 0 | AS24: 0 | AT24: 0 | AU24: 0 | AV24: 0 | AW24: 0 | AX24: 0 | AY24: 0 | AZ24: 0 | BA24: 0 | BB24: 0 | BC24: 0 | BD24: 0 | BE24: 0 | BF24: 0 | BG24: 0 | BH24: 0 | BI24: 0 | BJ24: 0 | BK24: 0 | BL24: 0 | BM24: 0 | BN24: 0 | BO24: 0 | BP24: 0 | BQ24: 0 | BR24: 0 | BS24: 0 | BT24: 0 | BU24: 0 | BV24: 0 | BW24: 0 | BX24: 0 | BY24: 0 | BZ24: 0 | CA24: 0 | CB24: 0 | CC24: 0 | CD24: 0 | CE24: 0 | CF24: 0 | CG24: 0 | CH24: 0 | CI24: 0 | CJ24: 0 | CK24: 0 | CL24: 0 | CM24: 0 | CN24: 0 | CO24: 0 | CP24: 0 | CQ24: 1 | CR24: 1 | CS24: 1 | CT24: 0
A25: 1975(12) | B25: #N/A | C25: #N/A | D25: #N/A | E25: #N/A | F25: #N/A | G25: 55.646141 | H25: 1.99 | I25: #N/A | J25: #N/A | K25: #N/A | L25: 44.0037 | M25: 43.4423 | N25: 0.012453455 | O25: -0.005887021 | P25: 44.394277 | Q25: -0.03013385 | R25: #N/A | S25: 0.019704583 | T25: 0 | U25: 0 | V25: 0 | W25: 0 | X25: -0.0035235428 | Y25: 0 | Z25: 0 | AA25: 0 | AB25: 0 | AC25: 0 | AD25: 0 | AE25: 0 | AF25: 0 | AG25: 0 | AH25: 0 | AI25: 0 | AJ25: 0 | AK25: 0 | AL25: 0 | AM25: 0 | AN25: 0 | AO25: 0 | AP25: 0 | AQ25: 0 | AR25: 0 | AS25: 0 | AT25: 0 | AU25: 0 | AV25: 0 | AW25: 0 | AX25: 0 | AY25: 0 | AZ25: 0 | BA25: 0 | BB25: 0 | BC25: 0 | BD25: 0 | BE25: 0 | BF25: 0 | BG25: 0 | BH25: 0 | BI25: 0 | BJ25: 0 | BK25: 0 | BL25: 0 | BM25: 0 | BN25: 0 | BO25: 0 | BP25: 0 | BQ25: 0 | BR25: 0 | BS25: 0 | BT25: 0 | BU25: 0 | BV25: 0 | BW25: 0 | BX25: 0 | BY25: 0 | BZ25: 0 | CA25: 0 | CB25: 0 | CC25: 0 | CD25: 0 | CE25: 0 | CF25: 0 | CG25: 0 | CH25: 0 | CI25: 0 | CJ25: 0 | CK25: 0 | CL25: 0 | CM25: 0 | CN25: 0 | CO25: 0 | CP25: 0 | CQ25: 1 | CR25: 1 | CS25: 1 | CT25: 0
A26: 1976(1) | B26: #N/A | C26: #N/A | D26: #N/A | E26: #N/A | F26: #N/A | G26: 55.091528 | H26: 2.36 | I26: #N/A | J26: #N/A | K26: #N/A | L26: 44.6407 | M26: 43.8465 | N26: 0.014372278 | O26: 0.0092612773 | P26: 43.951809 | Q26: -0.010016778 | R26: #N/A | S26: 0.023325825 | T26: 0 | U26: 0 | V26: 0 | W26: 0 | X26: 0.003621242 | Y26: 0 | Z26: 0 | AA26: 0 | AB26: 0 | AC26: 0 | AD26: 0 | AE26: 0 | AF26: 0 | AG26: 0 | AH26: 0 | AI26: 0 | AJ26: 0 | AK26: 0 | AL26: 0 | AM26: 0 | AN26: 0 | AO26: 0 | AP26: 0 | AQ26: 0 | AR26: 0 | AS26: 0 | AT26: 0 | AU26: 0 | AV26: 0 | AW26: 0 | AX26: 0 | AY26: 0 | AZ26: 0 | BA26: 0 | BB26: 0 | BC26: 0 | BD26: 0 | BE26: 0 | BF26: 0 | BG26: 0 | BH26: 0 | BI26: 0 | BJ26: 0 | BK26: 0 | BL26: 0 | BM26: 0 | BN26: 0 | BO26: 0 | BP26: 0 | BQ26: 0 | BR26: 0 | BS26: 0 | BT26: 0 | BU26: 0 | BV26: 0 | BW26: 0 | BX26: 0 | BY26: 0 | BZ26: 0 | CA26: 0 | CB26: 0 | CC26: 0 | CD26: 0 | CE26: 0 | CF26: 0 | CG26: 0 | CH26: 0 | CI26: 0 | CJ26: 0 | CK26: 0 | CL26: 0 | CM26: 0 | CN26: 0 | CO26: 0 | CP26: 0 | CQ26: 1 | CR26: 1 | CS26: 1 | CT26: 0
... A73: 1979(12) | B73: #N/A | C73: #N/A | D73: #N/A | E73: #N/A | F73: #N/A | G73: 69.311182 | H73: 3.57 | I73: #N/A | J73: #N/A | K73: #N/A | L73: 53.7087 | M73: 53.203 | N73: 0.00091274534 | O73: -0.009141779 | P73: 55.296193 | Q73: -0.076874598 | R73: #N/A | S73: 0.035077527 | T73: 0 | U73: 0 | V73: 0 | W73: 0 | X73: 0.014490893 | Y73: 0 | Z73: 0 | AA73: 0 | AB73: 0 | AC73: 0 | AD73: 0 | AE73: 0 | AF73: 0 | AG73: 0 | AH73: 0 | AI73: 0 | AJ73: 0 | AK73: 0 | AL73: 0 | AM73: 0 | AN73: 0 | AO73: 0 | AP73: 0 | AQ73: 0 | AR73: 0 | AS73: 0 | AT73: 0 | AU73: 0 | AV73: 0 | AW73: 0 | AX73: 0 | AY73: 0 | AZ73: 0 | BA73: 0 | BB73: 0 | BC73: 0 | BD73: 0 | BE73: 0 | BF73: 0 | BG73: 0 | BH73: 0 | BI73: 0 | BJ73: 0 | BK73: 0 | BL73: 0 | BM73: 0 | BN73: 0 | BO73: 0 | BP73: 0 | BQ73: 0 | BR73: 0 | BS73: 0 | BT73: 0 | BU73: 0 | BV73: 0 | BW73: 0 | BX73: 0 | BY73: 0 | BZ73: 0 | CA73: 0 | CB73: 0 | CC73: 0 | CD73: 0 | CE73: 0 | CF73: 0 | CG73: 0 | CH73: 0 | CI73: 0 | CJ73: 0 | CK73: 0 | CL73: 0 | CM73: 0 | CN73: 0 | CO73: 0 | CP73: 0 | CQ73: 1 | CR73: 1 | CS73: 1 | CT73: 0
A74: 1980(1) | B74: #N/A | C74: #N/A | D74: #N/A | E74: #N/A | F74: #N/A | G74: 71.568147 | H74: 2.95 | I74: 6.6156492 | J74: -0.03498687 | K74: #N/A | L74: 53.9628 | M74: 53.2023 | N74: 0.0047199207 | O74: -1.3157239e-05 | P74: 57.096792 | Q74: 0.032043859 | R74: 0.064060118 | S74: 0.029073247 | T74: 0 | U74: 0 | V74: 0 | W74: 0 | X74: -0.0060042791 | Y74: 0 | Z74: 0 | AA74: 0 | AB74: 0 | AC74: 0 | AD74: 0 | AE74: 0 | AF74: 0 | AG74: 0 | AH74: 0 | AI74: 0 | AJ74: 0 | AK74: 0 | AL74: 0 | AM74: 0 | AN74: 0 | AO74: 0 | AP74: 0 | AQ74: 0 | AR74: 0 | AS74: 0 | AT74: 0 | AU74: 0 | AV74: 0 | AW74: 0 | AX74: 0 | AY74: 0 | AZ74: 0 | BA74: 0 | BB74: 0 | BC74: 0 | BD74: 0 | BE74: 0 | BF74: 0 | BG74: 0 | BH74: 0 | BI74: 0 | BJ74: 0 | BK74: 0 | BL74: 0 | BM74: 0 | BN74: 0 | BO74: 0 | BP74: 0 | BQ74: 0 | BR74: 0 | BS74: 0 | BT74: 0 | BU74: 0 | BV74: 0 | BW74: 0 | BX74: 0 | BY74: 0 | BZ74: 0 | CA74: 0 | CB74: 0 | CC74: 0 | CD74: 0 | CE74: 0 | CF74: 0 | CG74: 0 | CH74: 0 | CI74: 0 | CJ74: 0 | CK74: 0 | CL74: 0 | CM74: 0 | CN74: 0 | CO74: 0 | CP74: 0 | CQ74: 1 | CR74: 1 | CS74: 1 | CT74: 0
A75: 1980(2) | B75: #N/A | C75: #N/A | D75: #N/A | E75: #N/A | F75: #N/A | G75: 70.150804 | H75: 2.47 | I75: 4.6169189 | J75: -0.020735214 | K75: #N/A | L75: 53.9815 | M75: 54.2363 | N75: 0.00034647499 | O75: 0.019248797 | P75: 55.966041 | Q75: -0.020002841 | R75: 0.045135101 | S75: 0.024399887 | T75: 0 | U75: 0 | V75: 0 | W75: 0 | X75: -0.0046733607 | Y75: 0 | Z75: 0 | AA75: 0 | AB75: 0 | AC75: 0 | AD75: 0 | AE75: 0 | AF75: 0 | AG75: 0 | AH75: 0 | AI75: 0 | AJ75: 0 | AK75: 0 | AL75: 0 | AM75: 0 | AN75: 0 | AO75: 0 | AP75: 0 | AQ75: 0 | AR75: 0 | AS75: 0 | AT75: 0 | AU75: 0 | AV75: 0 | AW75: 0 | AX75: 0 | AY75: 0 | AZ75: 0 | BA75: 0 | BB75: 0 | BC75: 0 | BD75: 0 | BE75: 0 | BF75: 0 | BG75: 0 | BH75: 0 | BI75: 0 | BJ75: 0 | BK75: 0 | BL75: 0 | BM75: 0 | BN75: 0 | BO75: 0 | BP75: 0 | BQ75: 0 | BR75: 0 | BS75: 0 | BT75: 0 | BU75: 0 | BV75: 0 | BW75: 0 | BX75: 0 | BY75: 0 | BZ75: 0 | CA75: 0 | CB75: 0 | CC75: 0 | CD75: 0 | CE75: 0 | CF75: 0 | CG75: 0 | CH75: 0 | CI75: 0 | CJ75: 0 | CK75: 0 | CL75: 0 | CM75: 0 | CN75: 0 | CO75: 0 | CP75: 0 | CQ75: 1 | CR75: 1 | CS75: 1 | CT75: 0
A76: 1980(3) | B76: #N/A | C76: #N/A | D76: #N/A | E76: #N/A | F76: #N/A | G76: 77.460907 | H76: 3.57 | I76: 6.0383887 | J76: -0.023553473 | K76: #N/A | L76: 53.8006 | M76: 54.4618 | N76: -0.0033567758 | O76: 0.0041491125 | P76: 61.798013 | Q76: 0.099126123 | R76: 0.058631 | S76: 0.035077527 | T76: 0 | U76: 0 | V76: 0 | W76: 0 | X76: 0.01067764 | Y76: 0 | Z76: 0 | AA76: 0 | AB76: 0 | AC76: 0 | AD76: 0 | AE76: 0 | AF76: 0 | AG76: 0 | AH76: 0 | AI76: 0 | AJ76: 0 | AK76: 0 | AL76: 0 | AM76: 0 | AN76: 0 | AO76: 0 | AP76: 0 | AQ76: 0 | AR76: 0 | AS76: 0 | AT76: 0 | AU76: 0 | AV76: 0 | AW76: 0 | AX76: 0 | AY76: 0 | AZ76: 0 | BA76: 0 | BB76: 0 | BC76: 0 | BD76: 0 | BE76: 0 | BF76: 0 | BG76: 0 | BH76: 0 | BI76: 0 | BJ76: 0 | BK76: 0 | BL76: 0 | BM76: 0 | BN76: 0 | BO76: 0 | BP76: 0 | BQ76: 0 | BR76: 0 | BS76: 0 | BT76: 0 | BU76: 0 | BV76: 0 | BW76: 0 | BX76: 0 | BY76: 0 | BZ76: 0 | CA76: 0 | CB76: 0 | CC76: 0 | CD76: 0 | CE76: 0 | CF76: 0 | CG76: 0 | CH76: 0 | CI76: 0 | CJ76: 0 | CK76: 0 | CL76: 0 | CM76: 0 | CN76: 0 | CO76: 0 | CP76: 0 | CQ76: 1 | CR76: 1 | CS76: 1 | CT76: 0
A77: 1980(4) | B77: #N/A | C77: #N/A | D77: #N/A | E77: #N/A | F77: #N/A | G77: 72.061136 | H77: 1.95 | I77: 5.2861138 | J77: -0.032199041 | K77: #N/A | L77: 52.7031 | M77: 52.5917 | N77: -0.020610342 | O77: -0.034941226 | P77: 57.490097 | Q77: -0.072258512 | R77: 0.051511352 | S77: 0.019312311 | T77: 0 | U77: 0 | V77: 0 | W77: 0 | X77: -0.015765216 | Y77: 0 | Z77: 0 | AA77: 0 | AB77: 0 | AC77: 0 | AD77: 0 | AE77: 0 | AF77: 0 | AG77: 0 | AH77: 0 | AI77: 0 | AJ77: 0 | AK77: 0 | AL77: 0 | AM77: 0 | AN77: 0 | AO77: 0 | AP77: 0 | AQ77: 0 | AR77: 0 | AS77: 0 | AT77: 0 | AU77: 0 | AV77: 0 | AW77: 0 | AX77: 0 | AY77: 0 | AZ77: 0 | BA77: 0 | BB77: 0 | BC77: 0 | BD77: 0 | BE77: 0 | BF77: 0 | BG77: 0 | BH77: 0 | BI77: 0 | BJ77: 0 | BK77: 0 | BL77: 0 | BM77: 0 | BN77: 0 | BO77: 0 | BP77: 0 | BQ77: 0 | BR77: 0 | BS77: 0 | BT77: 0 | BU77: 0 | BV77: 0 | BW77: 0 | BX77: 0 | BY77: 0 | BZ77: 0 | CA77: 0 | CB77: 0 | CC77: 0 | CD77: 0 | CE77: 0 | CF77: 0 | CG77: 0 | CH77: 0 | CI77: 0 | CJ77: 0 | CK77: 0 | CL77: 0 | CM77: 0 | CN77: 0 | CO77: 0 | CP77: 0 | CQ77: 1 | CR77: 1 | CS77: 1 | CT77: 0
A78: 1980(5) | B78: #N/A | C78: #N/A | D78: #N/A | E78: #N/A | F78: #N/A | G78: 79.201775 | H78: 2.03 | I78: 5.7027207 | J78: -0.035363744 | K78: #N/A | L78: 51.4325 | M78: 51.2055 | N78: -0.024404009 | O78: -0.026711364 | P78: 63.18687 | Q78: 0.094483834 | R78: 0.055460446 | S78: 0.020096702 | T78: 0 | U78: 0 | V78: 0 | W78: 0 | X78: 0.00078439067 | Y78: 0 | Z78: 0 | AA78: 0 | AB78: 0 | AC78: 0 | AD78: 0 | AE78: 0 | AF78: 0 | AG78: 0 | AH78: 0 | AI78: 0 | AJ78: 0 | AK78: 0 | AL78: 0 | AM78: 0 | AN78: 0 | AO78: 0 | AP78: 0 | AQ78: 0 | AR78: 0 | AS78: 0 | AT78: 0 | AU78: 0 | AV78: 0 | AW78: 0 | AX78: 0 | AY78: 0 | AZ78: 0 | BA78: 0 | BB78: 0 | BC78: 0 | BD78: 0 | BE78: 0 | BF78: 0 | BG78: 0 | BH78: 0 | BI78: 0 | BJ78: 0 | BK78: 0 | BL78: 0 | BM78: 0 | BN78: 0 | BO78: 0 | BP78: 0 | BQ78: 0 | BR78: 0 | BS78: 0 | BT78: 0 | BU78: 0 | BV78: 0 | BW78: 0 | BX78: 0 | BY78: 0 | BZ78: 0 | CA78: 0 | CB78: 0 | CC78: 0 | CD78: 0 | CE78: 0 | CF78: 0 | CG78: 0 | CH78: 0 | CI78: 0 | CJ78: 0 | CK78: 0 | CL78: 0 | CM78: 0 | CN78: 0 | CO78: 0 | CP78: 0 | CQ78: 1 | CR78: 1 | CS78: 1 | CT78: 0
A79: 1980(6) | B79: #N/A | C79: #N/A | D79: #N/A | E79: #N/A | F79: #N/A | G79: 80.241674 | H79: 2.45 | I79: 5.3053043 | J79: -0.027488916 | K79: #N/A | L79: 50.8002 | M79: 51.5013 | N79: -0.012369977 | O79: 0.0057601019 | P79: 64.016498 | Q79: 0.013044293 | R79: 0.051693605 | S79: 0.024204689 | T79: 0 | U79: 0 | V79: 0 | W79: 0 | X79: 0.004107987 | Y79: 0 | Z79: 0 | AA79: 0 | AB79: 0 | AC79: 0 | AD79: 0 | AE79: 0 | AF79: 0 | AG79: 0 | AH79: 0 | AI79: 0 | AJ79: 0 | AK79: 0 | AL79: 0 | AM79: 0 | AN79: 0 | AO79: 0 | AP79: 0 | AQ79: 0 | AR79: 0 | AS79: 0 | AT79: 0 | AU79: 0 | AV79: 0 | AW79: 0 | AX79: 0 | AY79: 0 | AZ79: 0 | BA79: 0 | BB79: 0 | BC79: 0 | BD79: 0 | BE79: 0 | BF79: 0 | BG79: 0 | BH79: 0 | BI79: 0 | BJ79: 0 | BK79: 0 | BL79: 0 | BM79: 0 | BN79: 0 | BO79: 0 | BP79: 0 | BQ79: 0 | BR79: 0 | BS79: 0 | BT79: 0 | BU79: 0 | BV79: 0 | BW79: 0 | BX79: 0 | BY79: 0 | BZ79: 0 | CA79: 0 | CB79: 0 | CC79: 0 | CD79: 0 | CE79: 0 | CF79: 0 | CG79: 0 | CH79: 0 | CI79: 0 | CJ79: 0 | CK79: 0 | CL79: 0 | CM79: 0 | CN79: 0 | CO79: 0 | CP79: 0 | CQ79: 1 | CR79: 1 | CS79: 1 | CT79: 0
A80: 1980(7) | B80: #N/A | C80: #N/A | D80: #N/A | E80: #N/A | F80: #N/A | G80: 84.147071 | H80: 3.21 | I80: 5.5456121 | J80: -0.022377454 | K80: #N/A | L80: 50.4013 | M80: 49.0516 | N80: -0.0078833232 | O80: -0.048734245 | P80: 67.132209 | Q80: 0.047523117 | R80: 0.053973016 | S80: 0.031595562 | T80: 0 | U80: 0 | V80: 0 | W80: 0 | X80: 0.0073908729 | Y80: 0 | Z80: 0 | AA80: 0 | AB80: 0 | AC80: 0 | AD80: 0 | AE80: 0 | AF80: 0 | AG80: 0 | AH80: 0 | AI80: 0 | AJ80: 0 | AK80: 0 | AL80: 0 | AM80: 0 | AN80: 0 | AO80: 0 | AP80: 0 | AQ80: 0 | AR80: 0 | AS80: 0 | AT80: 0 | AU80: 0 | AV80: 0 | AW80: 0 | AX80: 0 | AY80: 0 | AZ80: 0 | BA80: 0 | BB80: 0 | BC80: 0 | BD80: 0 | BE80: 0 | BF80: 0 | BG80: 0 | BH80: 0 | BI80: 0 | BJ80: 0 | BK80: 0 | BL80: 0 | BM80: 0 | BN80: 0 | BO80: 0 | BP80: 0 | BQ80: 0 | BR80: 0 | BS80: 0 | BT80: 0 | BU80: 0 | BV80: 0 | BW80: 0 | BX80: 0 | BY80: 0 | BZ80: 0 | CA80: 0 | CB80: 0 | CC80: 0 | CD80: 0 | CE80: 0 | CF80: 0 | CG80: 0 | CH80: 0 | CI80: 0 | CJ80: 0 | CK80: 0 | CL80: 0 | CM80: 0 | CN80: 0 | CO80: 0 | CP80: 0 | CQ80: 1 | CR80: 1 | CS80: 1 | CT80: 0
A81: 1980(8) | B81: #N/A | C81: #N/A | D81: #N/A | E81: #N/A | F81: #N/A | G81: 83.222717 | H81: 3.04 | I81: 4.9455824 | J81: -0.018324691 | K81: #N/A | L81: 50.5944 | M81: 50.597 | N81: 0.0038239298 | O81: 0.031019481 | P81: 66.394763 | Q81: -0.011045768 | R81: 0.048271767 | S81: 0.029947076 | T81: 0 | U81: 0 | V81: 0 | W81: 0 | X81: -0.0016484852 | Y81: 0 | Z81: 0 | AA81: 0 | AB81: 0 | AC81: 0 | AD81: 0 | AE81: 0 | AF81: 0 | AG81: 0 | AH81: 0 | AI81: 0 | AJ81: 0 | AK81: 0 | AL81: 0 | AM81: 0 | AN81: 0 | AO81: 0 | AP81: 0 | AQ81: 0 | AR81: 0 | AS81: 0 | AT81: 0 | AU81: 0 | AV81: 0 | AW81: 0 | AX81: 0 | AY81: 0 | AZ81: 0 | BA81: 0 | BB81: 0 | BC81: 0 | BD81: 0 | BE81: 0 | BF81: 0 | BG81: 0 | BH81: 0 | BI81: 0 | BJ81: 0 | BK81: 0 | BL81: 0 | BM81: 0 | BN81: 0 | BO81: 0 | BP81: 0 | BQ81: 0 | BR81: 0 | BS81: 0 | BT81: 0 | BU81: 0 | BV81: 0 | BW81: 0 | BX81: 0 | BY81: 0 | BZ81: 0 | CA81: 0 | CB81: 0 | CC81: 0 | CD81: 0 | CE81: 0 | CF81: 0 | CG81: 0 | CH81: 0 | CI81: 0 | CJ81: 0 | CK81: 0 | CL81: 0 | CM81: 0 | CN81: 0 | CO81: 0 | CP81: 0 | CQ81: 1 | CR81: 1 | CS81: 1 | CT81: 0
A82: 1980(9) | B82: #N/A | C82: #N/A | D82: #N/A | E82: #N/A | F82: #N/A | G82: 85.348732 | H82: 3.43 | I82: 4.2303253 | J82: -0.0077080614 | K82: #N/A | L82: 51.4172 | M82: 52.0561 | N82: 0.016131849 | O82: 0.028429697 | P82: 68.090889 | Q82: 0.025225245 | R82: 0.041432931 | S82: 0.033724869 | T82: 0 | U82: 0 | V82: 0 | W82: 0 | X82: 0.003777793 | Y82: 0 | Z82: 0 | AA82: 0 | AB82: 0 | AC82: 0 | AD82: 0 | AE82: 0 | AF82: 0 | AG82: 0 | AH82: 0 | AI82: 0 | AJ82: 0 | AK82: 0 | AL82: 0 | AM82: 0 | AN82: 0 | AO82: 0 | AP82: 0 | AQ82: 0 | AR82: 0 | AS82: 0 | AT82: 0 | AU82: 0 | AV82: 0 | AW82: 0 | AX82: 0 | AY82: 0 | AZ82: 0 | BA82: 0 | BB82: 0 | BC82: 0 | BD82: 0 | BE82: 0 | BF82: 0 | BG82: 0 | BH82: 0 | BI82: 0 | BJ82: 0 | BK82: 0 | BL82: 0 | BM82: 0 | BN82: 0 | BO82: 0 | BP82: 0 | BQ82: 0 | BR82: 0 | BS82: 0 | BT82: 0 | BU82: 0 | BV82: 0 | BW82: 0 | BX82: 0 | BY82: 0 | BZ82: 0 | CA82: 0 | CB82: 0 | CC82: 0 | CD82: 0 | CE82: 0 | CF82: 0 | CG82: 0 | CH82: 0 | CI82: 0 | CJ82: 0 | CK82: 0 | CL82: 0 | CM82: 0 | CN82: 0 | CO82: 0 | CP82: 0 | CQ82: 1 | CR82: 1 | CS82: 1 | CT82: 0
A83: 1980(10) | B83: #N/A | C83: #N/A | D83: #N/A | E83: #N/A | F83: #N/A | G83: 86.95865 | H83: 3.96 | I83: 9.4805312 | J83: -0.051740526 | K83: #N/A | L83: 52.054 | M83: 52.6315 | N83: 0.012308894 | O83: 0.010992817 | P83: 69.375275 | Q83: 0.018687119 | R83: 0.09057655 | S83: 0.038836024 | T83: 0 | U83: 0 | V83: 0 | W83: 0 | X83: 0.0051111544 | Y83: 0 | Z83: 0 | AA83: 0 | AB83: 0 | AC83: 0 | AD83: 0 | AE83: 0 | AF83: 0 | AG83: 0 | AH83: 0 | AI83: 0 | AJ83: 0 | AK83: 0 | AL83: 0 | AM83: 0 | AN83: 0 | AO83: 0 | AP83: 0 | AQ83: 0 | AR83: 0 | AS83: 0 | AT83: 0 | AU83: 0 | AV83: 0 | AW83: 0 | AX83: 0 | AY83: 0 | AZ83: 0 | BA83: 0 | BB83: 0 | BC83: 0 | BD83: 0 | BE83: 0 | BF83: 0 | BG83: 0 | BH83: 0 | BI83: 0 | BJ83: 0 | BK83: 0 | BL83: 0 | BM83: 0 | BN83: 0 | BO83: 0 | BP83: 0 | BQ83: 0 | BR83: 0 | BS83: 0 | BT83: 0 | BU83: 0 | BV83: 0 | BW83: 0 | BX83: 0 | BY83: 0 | BZ83: 0 | CA83: 0 | CB83: 0 | CC83: 0 | CD83: 0 | CE83: 0 | CF83: 0 | CG83: 0 | CH83: 0 | CI83: 0 | CJ83: 0 | CK83: 0 | CL83: 0 | CM83: 0 | CN83: 0 | CO83: 0 | CP83: 0 | CQ83: 1 | CR83: 1 | CS83: 1 | CT83: 0
A84: 1980(11) | B84: #N/A | C84: #N/A | D84: #N/A | E84: #N/A | F84: #N/A | G84: 80.64993 | H84: 4.04 | I84: 6.6733598 | J84: -0.024996012 | K84: #N/A | L84: 52.9626 | M84: 52.9546 | N84: 0.017304363 | O84: 0.0061201429 | P84: 64.342203 | Q84: -0.075314775 | R84: 0.064601267 | S84: 0.039605255 | T84: 0 | U84: 0 | V84: 0 | W84: 0 | X84: 0.00076923081 | Y84: 0 | Z84: 0 | AA84: 0 | AB84: 0 | AC84: 0 | AD84: 0 | AE84: 0 | AF84: 0 | AG84: 0 | AH84: 0 | AI84: 0 | AJ84: 0 | AK84: 0 | AL84: 0 | AM84: 0 | AN84: 0 | AO84: 0 | AP84: 0 | AQ84: 0 | AR84: 0 | AS84: 0 | AT84: 0 | AU84: 0 | AV84: 0 | AW84: 0 | AX84: 0 | AY84: 0 | AZ84: 0 | BA84: 0 | BB84: 0 | BC84: 0 | BD84: 0 | BE84: 0 | BF84: 0 | BG84: 0 | BH84: 0 | BI84: 0 | BJ84: 0 | BK84: 0 | BL84: 0 | BM84: 0 | BN84: 0 | BO84: 0 | BP84: 0 | BQ84: 0 | BR84: 0 | BS84: 0 | BT84: 0 | BU84: 0 | BV84: 0 | BW84: 0 | BX84: 0 | BY84: 0 | BZ84: 0 | CA84: 0 | CB84: 0 | CC84: 0 | CD84: 0 | CE84: 0 | CF84: 0 | CG84: 0 | CH84: 0 | CI84: 0 | CJ84: 0 | CK84: 0 | CL84: 0 | CM84: 0 | CN84: 0 | CO84: 0 | CP84: 0 | CQ84: 1 | CR84: 1 | CS84: 1 | CT84: 0
A85: 1980(12) | B85: #N/A | C85: #N/A | D85: #N/A | E85: #N/A | F85: #N/A | G85: 73.424559 | H85: 5.65 | I85: 6.6140836 | J85: -0.0090838756 | K85: -0.30855788 | L85: 53.2684 | M85: 52.8888 | N85: 0.0057572807 | O85: -0.0012433465 | P85: 58.57783 | Q85: -0.093859466 | R85: 0.064045434 | S85: 0.054961558 | T85: 0 | U85: 0 | V85: 0 | W85: 0 | X85: 0.015356303 | Y85: 0 | Z85: 0 | AA85: 0 | AB85: 0 | AC85: 0 | AD85: 0 | AE85: 0 | AF85: 0 | AG85: 0 | AH85: 0 | AI85: 0 | AJ85: 0 | AK85: 0 | AL85: 0 | AM85: 0 | AN85: 0 | AO85: 0 | AP85: 0 | AQ85: 0 | AR85: 0 | AS85: 0 | AT85: 0 | AU85: 0 | AV85: 0 | AW85: 0 | AX85: 0 | AY85: 0 | AZ85: 0 | BA85: 0 | BB85: 0 | BC85: 0 | BD85: 0 | BE85: 0 | BF85: 0 | BG85: 0 | BH85: 0 | BI85: 0 | BJ85: 0 | BK85: 0 | BL85: 0 | BM85: 0 | BN85: 0 | BO85: 0 | BP85: 0 | BQ85: 0 | BR85: 0 | BS85: 0 | BT85: 0 | BU85: 0 | BV85: 0 | BW85: 0 | BX85: 0 | BY85: 0 | BZ85: 0 | CA85: 0 | CB85: 0 | CC85: 0 | CD85: 0 | CE85: 0 | CF85: 0 | CG85: 0 | CH85: 0 | CI85: 0 | CJ85: 0 | CK85: 0 | CL85: 0 | CM85: 0 | CN85: 0 | CO85: 0 | CP85: 0 | CQ85: 1 | CR85: 1 | CS85: 1 | CT85: 0
A86: 1981(1) | B86: #N/A | C86: #N/A | D86: #N/A | E86: #N/A | F86: #N/A | G86: 71.683692 | H86: 5.29 | I86: 6.8375111 | J86: -0.014590645 | K86: -0.28816165 | L86: 52.9637 | M86: 52.5263 | N86: -0.0057365116 | O86: -0.0068775997 | P86: 57.188973 | Q86: -0.023995206 | R86: 0.066138907 | S86: 0.051548262 | T86: 0 | U86: 0 | V86: 0 | W86: 0 | X86: -0.0034132962 | Y86: 0 | Z86: 0 | AA86: 0 | AB86: 0 | AC86: 0 | AD86: 0 | AE86: 0 | AF86: 0 | AG86: 0 | AH86: 0 | AI86: 0 | AJ86: 0 | AK86: 0 | AL86: 0 | AM86: 0 | AN86: 0 | AO86: 0 | AP86: 0 | AQ86: 0 | AR86: 0 | AS86: 0 | AT86: 0 | AU86: 0 | AV86: 0 | AW86: 0 | AX86: 0 | AY86: 0 | AZ86: 0 | BA86: 0 | BB86: 0 | BC86: 0 | BD86: 0 | BE86: 0 | BF86: 0 | BG86: 0 | BH86: 0 | BI86: 0 | BJ86: 0 | BK86: 0 | BL86: 0 | BM86: 0 | BN86: 0 | BO86: 0 | BP86: 0 | BQ86: 0 | BR86: 0 | BS86: 0 | BT86: 0 | BU86: 0 | BV86: 0 | BW86: 0 | BX86: 0 | BY86: 0 | BZ86: 0 | CA86: 0 | CB86: 0 | CC86: 0 | CD86: 0 | CE86: 0 | CF86: 0 | CG86: 0 | CH86: 0 | CI86: 0 | CJ86: 0 | CK86: 0 | CL86: 0 | CM86: 0 | CN86: 0 | CO86: 0 | CP86: 0 | CQ86: 1 | CR86: 1 | CS86: 1 | CT86: 0
...

Sheet PIM(2012 = 100)
A1: Data | B1: Produção industrial - indústria geral - quantum - índice (média 2012 = 100) - - - Instituto Brasileiro de Geografia e Estatística, Pesquisa Industrial Mensal - Produção Física (IBGE/PIM-PF) - PIMPFN12_QIIGN12
A2: 2002.01 | B2: 72.4 | C2: ='1'!P338 -> 72.4 | D2: =EXACT(B2,C2) -> TRUE
A3: 2002.02 | B3: 69.7 | C3: ='1'!P339 -> 69.7 | D3: =EXACT(B3,C3) -> TRUE
A4: 2002.03 | B4: 77.4 | C4: ='1'!P340 -> 77.4 | D4: =EXACT(B4,C4) -> TRUE
A5: 2002.04 | B5: 79.6 | C5: ='1'!P341 -> 79.6 | D5: =EXACT(B5,C5) -> TRUE
A6: 2002.05 | B6: 80.4 | C6: ='1'!P342 -> 80.4 | D6: =EXACT(B6,C6) -> TRUE
A7: 2002.06 | B7: 77.5 | C7: ='1'!P343 -> 77.5 | D7: =EXACT(B7,C7) -> TRUE
A8: 2002.07 | B8: 83.3 | C8: ='1'!P344 -> 83.3 | D8: =EXACT(B8,C8) -> TRUE
A9: 2002.08 | B9: 83.6 | C9: ='1'!P345 -> 83.6 | D9: =EXACT(B9,C9) -> TRUE
A10: 2002.09 | B10: 82.1 | C10: ='1'!P346 -> 82.1 | D10: =EXACT(B10,C10) -> TRUE
A11: 2002.10 | B11: 89.2 | C11: ='1'!P347 -> 89.2 | D11: =EXACT(B11,C11) -> TRUE
A12: 2002.11 | B12: 83.9 | C12: ='1'!P348 -> 83.9 | D12: =EXACT(B12,C12) -> TRUE
A13: 2002.12 | B13: 74.6 | C13: ='1'!P349 -> 74.6 | D13: =EXACT(B13,C13) -> TRUE
... A148: 2014.03 | B148: 97.3 | C148: ='1'!P484 -> 97.3 | D148: =EXACT(B148,C148) -> TRUE
A149: 2014.04 | B149: 96 | C149: ='1'!P485 -> 96 | D149: =EXACT(B149,C149) -> TRUE | K149: 2014.07 | L149: 104.4
A150: 2014.05 | B150: 101.7 | C150: ='1'!P486 -> 101.7 | D150: =EXACT(B150,C150) -> TRUE | K150: 2014.08 | L150: 106.3
A151: 2014.06 | B151: 94.9 | C151: ='1'!P487 -> 94.8 | D151: =EXACT(B151,C151) -> FALSE | K151: 2014.09 | L151: 105.6
A152: 2014.07 | B152: 104.4 | C152: ='1'!P488 -> 104.4 | D152: =EXACT(B152,C152) -> TRUE | F152: =EXACT(L149,B152) -> TRUE | K152: 2014.1 | L152: 109.3
A153: 2014.08 | B153: 106.3 | C153: ='1'!P489 -> 106.3 | D153: =EXACT(B153,C153) -> TRUE | F153: =EXACT(L150,B153) -> TRUE | K153: 2014.11 | L153: 99.8
A154: 2014.09 | B154: 105.6 | C154: ='1'!P490 -> 105.5 | D154: =EXACT(B154,C154) -> FALSE | F154: =EXACT(L151,B154) -> TRUE | H154: 2015.07 | I154: 95.5 | K154: 2014.12 | L154: 87.7
A155: 2014.10 | B155: 109.3 | C155: ='1'!P491 -> 109.1 | D155: =EXACT(B155,C155) -> FALSE | F155: =EXACT(L152,B155) -> TRUE | H155: 2015.08 | I155: 97.6 | K155: 2015.01 | L155: 88.1
A156: 2014.11 | B156: 99.8 | C156: ='1'!P492 -> 99.8 | D156: =EXACT(B156,C156) -> TRUE | F156: =EXACT(L153,B156) -> TRUE | H156: 2015.09 | I156: 94.3 | K156: 2015.02 | L156: 83.7
A157: 2014.12 | B157: 87.7 | C157: ='1'!P493 -> 87.7 | D157: =EXACT(B157,C157) -> TRUE | F157: =EXACT(L154,B157) -> TRUE | H157: 2015.1 | I157: 97.2 | K157: 2015.03 | L157: 94.3
A158: 2015.01 | B158: 88.1 | C158: ='1'!P494 -> 88 | D158: =EXACT(B158,C158) -> FALSE | F158: =EXACT(L155,B158) -> TRUE | H158: 2015.11 | I158: 87.6 | K158: 2015.04 | L158: 88.8
A159: 2015.02 | B159: 83.7 | C159: ='1'!P495 -> 83.7 | D159: =EXACT(B159,C159) -> TRUE | F159: =EXACT(L156,B159) -> TRUE | H159: 2015.12 | I159: 77.2 | K159: 2015.05 | L159: 93.1
A160: 2015.03 | B160: 94.3 | C160: ='1'!P496 -> 94.2 | D160: =EXACT(B160,C160) -> FALSE | F160: =EXACT(L157,B160) -> TRUE | H160: 2016.01 | I160: 76.3 | K160: 2015.06 | L160: 92.5
A161: 2015.04 | B161: 88.8 | C161: ='1'!P497 -> 88.6 | D161: =EXACT(B161,C161) -> FALSE | F161: =EXACT(L158,B161) -> TRUE | H161: 2016.02 | I161: 75.8 | K161: 2015.07 | L161: 95.5
A162: 2015.05 | B162: 93.1 | C162: ='1'!P498 -> 92.8 | D162: =EXACT(B162,C162) -> FALSE | F162: =EXACT(L159,B162) -> TRUE | H162: 2016.03 | I162: 83.6 | K162: 2015.08 | L162: 97.6
A163: 2015.06 | B163: 92.5 | C163: ='1'!P499 -> 92.1 | D163: =EXACT(B163,C163) -> FALSE | F163: =EXACT(L160,B163) -> TRUE | H163: 2016.04 | I163: 82.9 | K163: 2015.09 | L163: 94.3
A164: 2015.07 | B164: 95.5 | C164: ='1'!P500 -> 95 | D164: =EXACT(B164,C164) -> FALSE | F164: =EXACT(L161,B164) -> TRUE | H164: 2016.05 | I164: 86.2 | K164: 2015.1 | L164: 97.2
A165: 2015.08 | B165: 97.6 | C165: ='1'!P501 -> 97 | D165: =EXACT(B165,C165) -> FALSE | F165: =EXACT(L162,B165) -> TRUE | H165: 2016.06 | I165: 87.4 | K165: 2015.11 | L165: 87.6
