Workbook

Sheet conditional forecasts_8
A1: GVAR Conditional Forecasts
A2: Last in-sample estimation date: | B2: 2016M12
A3: Last forecast date: | B3: 2024M12
D4: =DATE(LEFT(D5,4),SUBSTITUTE(RIGHT(D5,2),"M",""),1) -> 42736 | E4: =DATE(LEFT(E5,4),SUBSTITUTE(RIGHT(E5,2),"M",""),1) -> 42767 | F4: =DATE(LEFT(F5,4),SUBSTITUTE(RIGHT(F5,2),"M",""),1) -> 42795 | G4: =DATE(LEFT(G5,4),SUBSTITUTE(RIGHT(G5,2),"M",""),1) -> 42826 | H4: =DATE(LEFT(H5,4),SUBSTITUTE(RIGHT(H5,2),"M",""),1) -> 42856 | I4: =DATE(LEFT(I5,4),SUBSTITUTE(RIGHT(I5,2),"M",""),1) -> 42887 | J4: =DATE(LEFT(J5,4),SUBSTITUTE(RIGHT(J5,2),"M",""),1) -> 42917 | K4: =DATE(LEFT(K5,4),SUBSTITUTE(RIGHT(K5,2),"M",""),1) -> 42948 | ... CU4: =DATE(LEFT(CU5,4),SUBSTITUTE(RIGHT(CU5,2),"M",""),1) -> 45627
D5: 2017M1 | E5: 2017M2 | F5: 2017M3 | G5: 2017M4 | H5: 2017M5 | I5: 2017M6 | J5: 2017M7 | K5: 2017M8 | L5: 2017M9 | M5: 2017M10 | N5: 2017M11 | O5: 2017M12 | P5: 2018M1 | Q5: 2018M2 | R5: 2018M3 | S5: 2018M4 | T5: 2018M5 | U5: 2018M6 | V5: 2018M7 | W5: 2018M8 | X5: 2018M9 | Y5: 2018M10 | Z5: 2018M11 | AA5: 2018M12 | AB5: 2019M1 | AC5: 2019M2 | AD5: 2019M3 | AE5: 2019M4 | AF5: 2019M5 | AG5: 2019M6 | AH5: 2019M7 | AI5: 2019M8 | AJ5: 2019M9 | AK5: 2019M10 | AL5: 2019M11 | AM5: 2019M12 | AN5: 2020M1 | AO5: 2020M2 | AP5: 2020M3 | AQ5: 2020M4 | AR5: 2020M5 | AS5: 2020M6 | AT5: 2020M7 | AU5: 2020M8 | AV5: 2020M9 | AW5: 2020M10 | AX5: 2020M11 | AY5: 2020M12 | AZ5: 2021M1 | BA5: 2021M2 | BB5: 2021M3 | BC5: 2021M4 | BD5: 2021M5 | BE5: 2021M6 | BF5: 2021M7 | BG5: 2021M8 | BH5: 2021M9 | BI5: 2021M10 | BJ5: 2021M11 | BK5: 2021M12 | BL5: 2022M1 | BM5: 2022M2 | BN5: 2022M3 | BO5: 2022M4 | BP5: 2022M5 | BQ5: 2022M6 | BR5: 2022M7 | BS5: 2022M8 | BT5: 2022M9 | BU5: 2022M10 | BV5: 2022M11 | BW5: 2022M12 | BX5: 2023M1 | BY5: 2023M2 | BZ5: 2023M3 | CA5: 2023M4 | CB5: 2023M5 | CC5: 2023M6 | CD5: 2023M7 | CE5: 2023M8 | CF5: 2023M9 | CG5: 2023M10 | CH5: 2023M11 | CI5: 2023M12 | CJ5: 2024M1 | CK5: 2024M2 | CL5: 2024M3 | CM5: 2024M4 | CN5: 2024M5 | CO5: 2024M6 | CP5: 2024M7 | CQ5: 2024M8 | CR5: 2024M9 | CS5: 2024M10 | CT5: 2024M11 | CU5: 2024M12 | CV5: Serie | CW5: Meso
A6: Ro1101 | B6: adm | C6: Forecast | D6: 3115.6169 | E6: 3366.9532 | F6: 3895.1536 | G6: 4031.024 | H6: 4157.4622 | I6: 4381.114 | J6: 4326.4124 | K6: 4376.2513 | L6: 4224.1857 | M6: 3751.245 | N6: 3580.8344 | O6: 3078.0567 | P6: 3906.863 | Q6: 4229.2565 | R6: 4883.0082 | S6: 5027.9508 | T6: 5176.0149 | U6: 5378.6777 | V6: 5292.7516 | W6: 5321.9414 | X6: 5167.1529 | Y6: 4722.4168 | Z6: 4603.9021 | AA6: 4163.5286 | AB6: 5052.5194 | AC6: 5422.0336 | AD6: 6105.4342 | AE6: 6264.675 | AF6: 6417.4864 | AG6: 6621.9488 | AH6: 6540.077 | AI6: 6578.3516 | AJ6: 6438.218 | AK6: 6012.8067 | AL6: 5916.7409 | AM6: 5500.3101 | AN6: 6413.305 | AO6: 6805.736 | AP6: 7510.1488 | AQ6: 7688.081 | AR6: 7857.304 | AS6: 8076.3748 | AT6: 8008.0884 | AU6: 8059.7894 | AV6: 7933.6367 | AW6: 7523.1566 | AX6: 7443.0004 | AY6: 7043.1849 | AZ6: 7973.0683 | BA6: 8382.2238 | BB6: 9102.8713 | BC6: 9296.3858 | BD6: 9480.5287 | BE6: 9713.95 | BF6: 9659.5799 | BG6: 9724.891 | BH6: 9612.1366 | BI6: 9214.9012 | BJ6: 9147.8714 | BK6: 8761.0954 | BL6: 9703.974 | BM6: 10126.138 | BN6: 10859.87 | BO6: 11066.584 | BP6: 11264.035 | BQ6: 11510.785 | BR6: 11469.593 | BS6: 11547.687 | BT6: 11447.056 | BU6: 11061.07 | BV6: 11004.332 | BW6: 10627.001 | BX6: 11578.819 | BY6: 12009.951 | BZ6: 12753.316 | CA6: 12970.923 | CB6: 13180.887 | CC6: 13441.745 | CD6: 13415.716 | CE6: 13508.993 | CF6: 13422.144 | CG6: 13047.061 | CH6: 12997.241 | CI6: 12622.413 | CJ6: 13573.284 | CK6: 14002.38 | CL6: 14744.81 | CM6: 14967.396 | CN6: 15190.192 | CO6: 15469.204 | CP6: 15479.614 | CQ6: 15593.266 | CR6: 15539.161 | CS6: 15256.277 | CT6: 15089.362 | CU6: 14800.144 | CV6: 1 | CW6: 1101
C7: Actual | CV7: 0 | CW7: 0
A8: Ro1101 | B8: desl | C8: Forecast | D8: 3253.3177 | E8: 3322.7997 | F8: 3689.5561 | G8: 3784.8754 | H8: 4118.6782 | I8: 4077.4937 | J8: 4281.4478 | K8: 4355.4509 | L8: 4261.6488 | M8: 4504.442 | N8: 4375.9852 | O8: 4250.2461 | P8: 4278.9371 | Q8: 4263.8889 | R8: 4663.4829 | S8: 4710.7249 | T8: 5051.614 | U8: 4991.2221 | V8: 5176.3678 | W8: 5233.3342 | X8: 5134.6359 | Y8: 5391.2624 | Z8: 5296.3924 | AA8: 5218.2797 | AB8: 5299.9512 | AC8: 5334.6652 | AD8: 5775.3243 | AE8: 5853.3125 | AF8: 6216.4852 | AG8: 6173.5599 | AH8: 6375.1032 | AI8: 6450.1278 | AJ8: 6372.4688 | AK8: 6653.2325 | AL8: 6584.9897 | AM8: 6535.0816 | AN8: 6645.5842 | AO8: 6708.898 | AP8: 7177.2252 | AQ8: 7281.464 | AR8: 7669.2557 | AS8: 7649.4052 | AT8: 7872.8332 | AU8: 7969.0675 | AV8: 7912.4723 | AW8: 8214.5567 | AX8: 8168.0824 | AY8: 8140.3599 | AZ8: 8273.2689 | BA8: 8358.9388 | BB8: 8849.3163 | BC8: 8975.1204 | BD8: 9383.9121 | BE8: 9384.5027 | BF8: 9627.8756 | BG8: 9743.6431 | BH8: 9706.2498 | BI8: 10027.268 | BJ8: 9999.5044 | BK8: 9990.3021 | BL8: 10141.569 | BM8: 10245.464 | BN8: 10753.962 | BO8: 10897.801 | BP8: 11324.54 | BQ8: 11342.954 | BR8: 11603.943 | BS8: 11737.002 | BT8: 11716.435 | BU8: 12053.691 | BV8: 12041.507 | BW8: 12047.252 | BX8: 12212.98 | BY8: 12331.105 | BZ8: 12853.935 | CA8: 13012.543 | CB8: 13454.736 | CC8: 13489.352 | CD8: 13767.107 | CE8: 13917.024 | CF8: 13912.714 | CG8: 14264.824 | CH8: 14265.362 | CI8: 14281.373 | CJ8: 14455.085 | CK8: 14579.653 | CL8: 15109.385 | CM8: 15276.252 | CN8: 15730.728 | CO8: 15783.736 | CP8: 16078.434 | CQ8: 16256.336 | CR8: 16281.149 | CS8: 16611.416 | CT8: 16702.961 | CU8: 16661.897 | CV8: -1 | CW8: 1101
C9: Actual | CV9: 0 | CW9: 0
A10: Ro1102 | B10: adm | C10: Forecast | D10: 4980.5079 | E10: 5358.7058 | F10: 6017.9881 | G10: 5995.5157 | H10: 5938.4682 | I10: 5977.6758 | J10: 5666.6636 | K10: 5667.5644 | L10: 5460.688 | M10: 5054.6123 | N10: 5240.0048 | O10: 4766.9749 | P10: 5837.8326 | Q10: 6007.6322 | R10: 6596.7262 | S10: 6488.734 | T10: 6381.7847 | U10: 6365.4825 | V10: 6021.1826 | W10: 6013.1366 | X10: 5825.9551 | Y10: 5472.1003 | Z10: 5725.1927 | AA10: 5317.0714 | AB10: 6436.1899 | AC10: 6630.3071 | AD10: 7222.3022 | AE10: 7105.12 | AF10: 6987.5456 | AG10: 6967.2639 | AH10: 6629.2824 | AI10: 6637.3016 | AJ10: 6472.8557 | AK10: 6144.6977 | AL10: 6423.3914 | AM10: 6038.8825 | AN10: 7178.7897 | AO10: 7390.7267 | AP10: 7997.8222 | AQ10: 7893.5353 | AR10: 7787.3874 | AS10: 7777.9558 | AT10: 7451.1471 | AU10: 7471.3652 | AV10: 7320.4785 | AW10: 7007.1438 | AX10: 7301.4754 | AY10: 6932.7963 | AZ10: 8088.1374 | BA10: 8314.7168 | BB10: 8935.5244 | BC10: 8844.1063 | BD10: 8750.2065 | BE10: 8752.6556 | BF10: 8437.5652 | BG10: 8469.4593 | BH10: 8330.2469 | BI10: 8028.5774 | BJ10: 8334.5469 | BK10: 7977.4793 | BL10: 9144.4337 | BM10: 9382.6732 | BN10: 10015.221 | BO10: 9935.6108 | BP10: 9853.4963 | BQ10: 9867.5336 | BR10: 9563.5943 | BS10: 9605.9518 | BT10: 9476.3311 | BU10: 9183.3474 | BV10: 9497.2701 | BW10: 9147.8151 | BX10: 10322.598 | BY10: 10569.49 | BZ10: 11212.015 | CA10: 11143.943 | CB10: 11074.765 | CC10: 11102.521 | CD10: 10812.03 | CE10: 10866.236 | CF10: 10745.49 | CG10: 10457.404 | CH10: 10771.995 | CI10: 10419.808 | CJ10: 11590.723 | CK10: 11836.092 | CL10: 12481.947 | CM10: 12426.972 | CN10: 12379.7 | CO10: 12435.145 | CP10: 12180.291 | CQ10: 12248.762 | CR10: 12135.286 | CS10: 11914.819 | CT10: 12048.529 | CU10: 11840.049 | CV10: 1 | CW10: 1102
C11: Actual | CV11: 0 | CW11: 0
A12: Ro1102 | B12: desl | C12: Forecast | D12: 5215.2238 | E12: 5235.7516 | F12: 5791.0833 | G12: 5428.1316 | H12: 5728.3708 | I12: 5271.3767 | J12: 5364.2558 | K12: 5594.3975 | L12: 5112.4405 | M12: 5936.4177 | N12: 5937.62 | O12: 5604.9358 | P12: 5817.9876 | Q12: 5559.5054 | R12: 6148.0127 | S12: 5740.7253 | T12: 6003.3656 | U12: 5552.1936 | V12: 5637.2482 | W12: 5878.0917 | X12: 5425.7438 | Y12: 6289.9413 | Z12: 6336.386 | AA12: 6043.146 | AB12: 6283.3761 | AC12: 6040.0062 | AD12: 6636.0887 | AE12: 6234.8554 | AF12: 6506.9281 | AG12: 6070.8294 | AH12: 6176.2329 | AI12: 6440.7897 | AJ12: 6013.2714 | AK12: 6901.6924 | AL12: 6970.9049 | AM12: 6698.8293 | AN12: 6958.8017 | AO12: 6733.9924 | AP12: 7347.6648 | AQ12: 6963.2689 | AR12: 7251.7118 | AS12: 6831.8668 | AT12: 6953.7459 | AU12: 7235.22 | AV12: 6825.0899 | AW12: 7731.2071 | AX12: 7818.1396 | AY12: 7563.5096 | AZ12: 7840.4338 | BA12: 7631.9901 | BB12: 8261.4705 | BC12: 7892.4304 | BD12: 8195.9044 | BE12: 7790.8719 | BF12: 7927.411 | BG12: 8223.4218 | BH12: 7827.7138 | BI12: 8748.1441 | BJ12: 8849.2937 | BK12: 8608.8041 | BL12: 8899.8078 | BM12: 8705.3794 | BN12: 9348.774 | BO12: 8993.469 | BP12: 9310.3853 | BQ12: 8918.3728 | BR12: 9067.3999 | BS12: 9375.3189 | BT12: 8990.9903 | BU12: 9922.438 | BV12: 10034.511 | BW12: 9805.1669 | BX12: 10107.824 | BY12: 9925.7192 | BZ12: 10582.078 | CA12: 10240.119 | CB12: 10570.294 | CC12: 10190.842 | CD12: 10351.105 | CE12: 10668.414 | CF12: 10291.415 | CG12: 11228.328 | CH12: 11344.678 | CI12: 11119.768 | CJ12: 11428.789 | CK12: 11255.867 | CL12: 11927.053 | CM12: 11603.231 | CN12: 11954.281 | CO12: 11600.711 | CP12: 11766.283 | CQ12: 12092.494 | CR12: 11749.491 | CS12: 12510.017 | CT12: 12847.979 | CU12: 12472.469 | CV12: -1 | CW12: 1102
C13: Actual | CV13: 0 | CW13: 0
A14: Ac1201 | B14: adm | C14: Forecast | D14: 129.28288 | E14: 127.28931 | F14: 177.02006 | G14: 209.95592 | H14: 230.05114 | I14: 246.67733 | J14: 231.02716 | K14: 222.21148 | L14: 205.02928 | M14: 174.22828 | N14: 169.41673 | O14: 143.90467 | P14: 173.11489 | Q14: 176.16274 | R14: 212.17861 | S14: 239.62245 | T14: 256.20238 | U14: 267.27595 | V14: 245.98566 | W14: 231.49701 | X14: 210.24501 | Y14: 178.56907 | Z14: 176.31746 | AA14: 156.24246 | AB14: 192.20924 | AC14: 201.55697 | AD14: 242.12817 | AE14: 271.84451 | AF14: 288.65425 | AG14: 298.68633 | AH14: 275.99584 | AI14: 260.48649 | AJ14: 239.00119 | AK14: 207.95519 | AL14: 207.04004 | AM14: 188.74538 | AN14: 226.66608 | AO14: 237.9181 | AP14: 280.18806 | AQ14: 311.31048 | AR14: 329.21095 | AS14: 340.05389 | AT14: 317.97641 | AU14: 302.9912 | AV14: 282.05105 | AW14: 251.65618 | AX14: 251.54049 | AY14: 234.18924 | AZ14: 273.15574 | BA14: 285.49551 | BB14: 328.83575 | BC14: 360.96781 | BD14: 379.79701 | BE14: 391.48907 | BF14: 370.19691 | BG14: 355.9549 | BH14: 335.73599 | BI14: 306.05501 | BJ14: 306.65416 | BK14: 290.02248 | BL14: 329.71523 | BM14: 342.79039 | BN14: 386.87899 | BO14: 419.77654 | BP14: 439.39036 | BQ14: 451.88263 | BR14: 431.39462 | BS14: 417.94023 | BT14: 398.46568 | BU14: 369.4584 | BV14: 370.64078 | BW14: 354.4981 | BX14: 394.60435 | BY14: 408.06034 | BZ14: 452.55903 | CA14: 485.96514 | CB14: 506.2451 | CC14: 519.59094 | CD14: 500.12696 | CE14: 487.7946 | CF14: 469.41389 | CG14: 441.31501 | CH14: 443.06247 | CI14: 427.03594 | CJ14: 466.79894 | CK14: 479.59078 | CL14: 523.31672 | CM14: 556.28016 | CN14: 576.70634 | CO14: 591.14029 | CP14: 573.77022 | CQ14: 564.07651 | CR14: 548.15813 | CS14: 526.73694 | CT14: 523.85305 | CU14: 517.82064 | CV14: 1 | CW14: 1201
C15: Actual | CV15: 0 | CW15: 0
A16: Ac1201 | B16: desl | C16: Forecast | D16: 194.57113 | E16: 160.17272 | F16: 162.62916 | G16: 155.30179 | H16: 173.75641 | I16: 171.52241 | J16: 190.16659 | K16: 202.07626 | L16: 195.6393 | M16: 233.98995 | N16: 232.97433 | O16: 227.65978 | P16: 221.46624 | Q16: 194.35189 | R16: 193.15444 | S16: 179.65028 | T16: 197.97286 | U16: 196.28604 | V16: 215.82088 | W16: 228.87548 | X16: 222.33679 | Y16: 259.67196 | Z16: 257.45519 | AA16: 251.47417 | AB16: 245.5843 | AC16: 219.74563 | AD16: 220.4966 | AE16: 209.1856 | AF16: 229.57871 | AG16: 229.64308 | AH16: 250.58524 | AI16: 264.79024 | AJ16: 259.26412 | AK16: 297.5695 | AL16: 296.3351 | AM16: 291.3719 | AN16: 286.54507 | AO16: 261.82168 | AP16: 263.74399 | AQ16: 253.65492 | AR16: 275.30141 | AS16: 276.62011 | AT16: 298.78437 | AU16: 314.15408 | AV16: 309.72569 | AW16: 349.06899 | AX16: 348.83162 | AY16: 344.84707 | AZ16: 340.99891 | BA16: 317.264 | BB16: 320.18526 | BC16: 311.09975 | BD16: 333.7458 | BE16: 336.05224 | BF16: 359.1874 | BG16: 375.50944 | BH16: 372.0156 | BI16: 412.27781 | BJ16: 412.94579 | BK16: 409.85413 | BL16: 406.88601 | BM16: 384.01653 | BN16: 387.78611 | BO16: 379.52966 | BP16: 402.98504 | BQ16: 406.08325 | BR16: 429.99787 | BS16: 447.09475 | BT16: 444.37956 | BU16: 485.43086 | BV16: 486.9006 | BW16: 484.61909 | BX16: 482.45809 | BY16: 460.3755 | BZ16: 464.89211 | CA16: 457.32569 | CB16: 481.40502 | CC16: 485.0649 | CD16: 509.49863 | CE16: 527.10647 | CF16: 524.93997 | CG16: 566.62248 | CH16: 568.83549 | CI16: 567.42169 | CJ16: 566.21106 | CK16: 545.07166 | CL16: 550.48886 | CM16: 543.54084 | CN16: 567.98377 | CO16: 571.90381 | CP16: 595.55716 | CQ16: 613.87422 | CR16: 611.59118 | CS16: 648.40546 | CT16: 659.83404 | CU16: 652.5949 | CV16: -1 | CW16: 1201
C17: Actual | CV17: 0 | CW17: 0
A18: Ac1202 | B18: adm | C18: Forecast | D18: 1631.3306 | E18: 1721.5021 | F18: 1893.8196 | G18: 1956.8734 | H18: 1949.5672 | I18: 1978.9168 | J18: 1924.7042 | K18: 1923.8549 | L18: 1858.2958 | M18: 1728.1868 | N18: 1753.4649 | O18: 1541.7077 | P18: 1853.6069 | Q18: 1945.144 | R18: 2147.9136 | S18: 2157.4975 | T18: 2143.2747 | U18: 2154.9152 | V18: 2088.076 | W18: 2084.4676 | X18: 2020.9065 | Y18: 1902.5902 | Z18: 1945.291 | AA18: 1752.7924 | AB18: 2082.6978 | AC18: 2187.6506 | AD18: 2398.0857 | AE18: 2410.4631 | AF18: 2396.1687 | AG18: 2407.235 | AH18: 2341.2253 | AI18: 2340.8258 | AJ18: 2282.8983 | AK18: 2172.0426 | AL18: 2223.1586 | AM18: 2039.2003 | AN18: 2377.165 | AO18: 2489.3557 | AP18: 2706.1012 | AQ18: 2723.9339 | AR18: 2714.4326 | AS18: 2729.8919 | AT18: 2668.1551 | AU18: 2672.1552 | AV18: 2618.9207 | AW18: 2513.1117 | AX18: 2569.5809 | AY18: 2391.156 | AZ18: 2734.674 | BA18: 2852.2912 | BB18: 3074.2372 | BC18: 3097.0069 | BD18: 3092.1965 | BE18: 3112.1533 | BF18: 3054.7849 | BG18: 3063.0817 | BH18: 3014.1125 | BI18: 2912.5594 | BJ18: 2973.2846 | BK18: 2799.1188 | BL18: 3146.9012 | BM18: 3268.7905 | BN18: 3495.016 | BO18: 3522.0628 | BP18: 3521.5023 | BQ18: 3545.6388 | BR18: 3492.3228 | BS18: 3504.4838 | BT18: 3459.1441 | BU18: 3360.9729 | BV18: 3424.8689 | BW18: 3253.7543 | BX18: 3604.6045 | BY18: 3729.7325 | BZ18: 3959.5011 | CA18: 3990.4662 | CB18: 3994.1707 | CC18: 4022.7757 | CD18: 3973.8766 | CE18: 3990.078 | CF18: 3948.0641 | CG18: 3852.2573 | CH18: 3917.464 | CI18: 3746.7913 | CJ18: 4097.6611 | CK18: 4223.2543 | CL18: 4454.417 | CM18: 4488.991 | CN18: 4498.4223 | CO18: 4534.6024 | CP18: 4494.0916 | CQ18: 4518.481 | CR18: 4473.9175 | CS18: 4403.3006 | CT18: 4419.4225 | CU18: 4289.4679 | CV18: 1 | CW18: 1202
C19: Actual | CV19: 0 | CW19: 0
A20: Ac1202 | B20: desl | C20: Forecast | D20: 1769.317 | E20: 1703.0219 | F20: 1883.9633 | G20: 1719.809 | H20: 1905.4268 | I20: 1735.212 | J20: 1784.0269 | K20: 1872.1527 | L20: 1717.7498 | M20: 2080.3847 | N20: 2074.9243 | O20: 2069.6951 | P20: 2067.5215 | Q20: 1865.3161 | R20: 2032.2053 | S20: 1864.5393 | T20: 2029.3143 | U20: 1861.5335 | V20: 1908.306 | W20: 1999.8855 | X20: 1855.9582 | Y20: 2231.5647 | Z20: 2241.341 | AA20: 2250.2938 | AB20: 2258.9645 | AC20: 2064.2612 | AD20: 2236.2889 | AE20: 2072.8927 | AF20: 2242.4382 | AG20: 2080.6485 | AH20: 2134.6868 | AI20: 2234.4587 | AJ20: 2099.1693 | AK20: 2483.4469 | AL20: 2501.6819 | AM20: 2518.7766 | AN20: 2535.2372 | AO20: 2347.96 | AP20: 2527.054 | AQ20: 2370.3996 | AR20: 2546.4433 | AS20: 2391.0253 | AT20: 2451.4314 | AU20: 2557.6583 | AV20: 2428.9445 | AW20: 2819.8911 | AX20: 2844.818 | AY20: 2868.5444 | AZ20: 2891.5067 | BA20: 2710.5624 | BB20: 2895.8133 | BC20: 2745.1557 | BD20: 2927.0623 | BE20: 2777.399 | BF20: 2843.4713 | BG20: 2955.2898 | BH20: 2832.1046 | BI20: 3228.5287 | BJ20: 3258.8964 | BK20: 3288.0415 | BL20: 3316.4111 | BM20: 3140.8633 | BN20: 3331.4857 | BO20: 3186.1421 | BP20: 3373.2572 | BQ20: 3228.6414 | BR20: 3299.5519 | BS20: 3415.9742 | BT20: 3297.1733 | BU20: 3697.8238 | BV20: 3732.3645 | BW20: 3765.7565 | BX20: 3798.5672 | BY20: 3627.7307 | BZ20: 3823.3359 | CA20: 3683.1563 | CB20: 3875.4378 | CC20: 3735.7469 | CD20: 3811.0813 | CE20: 3931.2 | CF20: 3815.2578 | CG20: 4217.9873 | CH20: 4254.0822 | CI20: 4289.0144 | CJ20: 4324.1091 | CK20: 4156.6205 | CL20: 4357.8226 | CM20: 4224.7204 | CN20: 4424.8978 | CO20: 4295.6812 | CP20: 4374.337 | CQ20: 4494.8381 | CR20: 4400.0035 | CS20: 4726.7486 | CT20: 4858.0776 | CU20: 4823.9144 | CV20: -1 | CW20: 1202
C21: Actual | CV21: 0 | CW21: 0
A22: Am1301 | B22: adm | C22: Forecast | D22: 26.557922 | E22: 16.017332 | F22: 24.009068 | G22: 18.191291 | H22: 15.401722 | I22: 22.969178 | J22: 11.282975 | K22: 14.762628 | L22: 18.243871 | M22: 4.3148319 | N22: 20.26132 | O22: 15.869947 | P22: 34.143157 | Q22: 19.313991 | R22: 20.304048 | S22: 15.913067 | T22: 12.206519 | U22: 19.195481 | V22: 8.0817066 | W22: 11.230621 | X22: 14.695638 | Y22: 0.81246232 | Z22: 16.772126 | AA22: 12.513428 | AB22: 30.947386 | AC22: 16.243552 | AD22: 17.310297 | AE22: 12.94412 | AF22: 9.2252023 | AG22: 16.190091 | AH22: 5.0623475 | AI22: 8.2177824 | AJ22: 11.710824 | AK22: -2.1287125 | AL22: 13.881428 | AM22: 9.6733015 | AN22: 28.154473 | AO22: 13.493304 | AP22: 14.598139 | AQ22: 10.265725 | AR22: 6.5764785 | AS22: 13.567491 | AT22: 2.4634395 | AU22: 5.6417466 | AV22: 9.158562 | AW22: -4.6549959 | AX22: 11.383802 | AY22: 7.2065777 | AZ22: 25.719831 | BA22: 11.090669 | BB22: 12.22642 | BC22: 7.9232818 | BD22: 4.2616081 | BE22: 11.278745 | BF22: 0.19973634 | BG22: 3.4023137 | BH22: 6.9428179 | BI22: -6.8475214 | BJ22: 9.2141484 | BK22: 5.0596703 | BL22: 23.595885 | BM22: 8.9903058 | BN22: 10.150597 | BO22: 5.8730712 | BP22: 2.2378412 | BQ22: 9.2816165 | BR22: -1.7715173 | BS22: 1.4550845 | BT22: 5.0168138 | BU22: -8.7556336 | BV22: 7.3206911 | BW22: 3.1784739 | BX22: 21.726126 | BY22: 7.133321 | BZ22: 8.3101455 | CA22: 4.0550916 | CB22: 0.44948358 | CC22: 7.5295819 | CD22: -3.4835413 | CE22: -0.21854567 | CF22: 3.3722942 | CG22: -10.386809 | CH22: 5.6835486 | CI22: 1.5142307 | CJ22: 20.025969 | CK22: 5.4103014 | CL22: 6.5577472 | CM22: 2.350612 | CN22: -1.2297676 | CO22: 5.8354092 | CP22: -4.8380552 | CQ22: -2.1029098 | CR22: 1.437249 | CS22: -9.2037732 | CT22: -0.40192512 | CU22: 4.7806808 | CV22: 1 | CW22: 1301
C23: Actual | CV23: 0 | CW23: 0
A24: Am1301 | B24: desl | C24: Forecast | D24: 17.838627 | E24: 25.415515 | F24: 17.811334 | G24: 17.782937 | H24: 19.896878 | I24: 10.996796 | J24: 14.936565 | K24: 14.581896 | L24: 10.59873 | M24: 26.734261 | N24: 22.242291 | O24: 35.006846 | P24: 15.667755 | Q24: 19.288042 | R24: 12.630537 | S24: 12.383325 | T24: 14.000385 | U24: 5.6660048 | V24: 9.3956107 | W24: 9.2688327 | X24: 5.5023533 | Y24: 21.658929 | Z24: 17.15363 | AA24: 29.828493 | AB24: 10.363303 | AC24: 13.900769 | AD24: 7.226674 | AE24: 7.0204382 | AF24: 8.7102389 | AG24: 0.44916847 | AH24: 4.2307807 | AI24: 4.1294712 | AJ24: 0.36822729 | AK24: 16.520415 | AL24: 12.010513 | AM24: 24.685163 | AN24: 5.2241736 | AO24: 8.7684514 | AP24: 2.1023762 | AQ24: 1.9052396 | AR24: 3.6060002 | AS24: -4.6416274 | AT24: -0.84445625 | AU24: -0.92948028 | AV24: -4.6755154 | AW24: 11.489401 | AX24: 6.9893114 | AY24: 19.671448 | AZ24: 0.21684984 | BA24: 3.767698 | BB24: -2.8907837 | BC24: -3.0790976 | BD24: -1.3686222 | BE24: -9.6062472 | BF24: -5.7993512 | BG24: -5.8752426 | BH24: -9.6127298 | BI24: 6.5604217 | BJ24: 2.0686585 | BK24: 14.759586 | BL24: -4.6855564 | BM24: -1.1246536 | BN24: -7.7728521 | BO24: -7.9512758 | BP24: -6.2320374 | BQ24: -14.462663 | BR24: -10.650832 | BS24: -10.723631 | BT24: -14.459051 | BU24: 1.7164615 | BV24: -2.7710997 | BW24: 9.9272585 | BX24: -9.5064111 | BY24: -5.9301132 | BZ24: -12.560202 | CA24: -12.720087 | CB24: -10.984936 | CC24: -19.205731 | CD24: -15.392875 | CE24: -15.475171 | CF24: -19.229037 | CG24: -3.076825 | CH24: -7.5862287 | CI24: 5.1020318 | CJ24: -14.315669 | CK24: -10.711594 | CL24: -17.257678 | CM24: -17.364756 | CN24: -15.571585 | CO24: -23.66411 | CP24: -20.086945 | CQ24: -20.252557 | CR24: -22.847778 | CS24: -11.064691 | CT24: -8.449302 | CU24: -2.5193421 | CV24: -1 | CW24: 1301
C25: Actual | CV25: 0 | CW25: 0
A26: Am1302 | B26: adm | C26: Forecast | D26: 27.941897 | E26: 25.585754 | F26: 30.092035 | G26: 29.908072 | H26: 29.558493 | I26: 32.122741 | J26: 28.836753 | K26: 30.206445 | L26: 30.539159 | M26: 25.043933 | N26: 29.069202 | O26: 25.187936 | P26: 31.99874 | Q26: 30.596576 | R26: 34.081346 | S26: 34.119022 | T26: 33.558415 | U26: 35.850439 | V26: 32.502759 | W26: 33.699988 | X26: 34.058854 | Y26: 28.802813 | Z26: 33.203998 | AA26: 29.759441 | AB26: 36.949639 | AC26: 35.789621 | AD26: 39.369643 | AE26: 39.39885 | AF26: 38.793268 | AG26: 41.064386 | AH26: 37.753589 | AI26: 39.048925 | AJ26: 39.550404 | AK26: 34.458025 | AL26: 39.024052 | AM26: 35.733905 | AN26: 43.06391 | AO26: 42.029053 | AP26: 45.720911 | AQ26: 45.850228 | AR26: 45.335202 | AS26: 47.690658 | AT26: 44.462406 | AU26: 45.843045 | AV26: 46.4359 | AW26: 41.442032 | AX26: 46.112331 | AY26: 42.929128 | AZ26: 50.365165 | BA26: 49.432531 | BB26: 53.2213 | BC26: 53.442193 | BD26: 53.014441 | BE26: 55.454335 | BF26: 52.309025 | BG26: 53.772002 | BH26: 54.446988 | BI26: 49.535082 | BJ26: 54.287062 | BK26: 51.185172 | BL26: 58.70218 | BM26: 57.850297 | BN26: 61.71972 | BO26: 62.021149 | BP26: 61.673511 | BQ26: 64.192437 | BR26: 61.12409 | BS26: 62.660833 | BT26: 63.405433 | BU26: 58.558597 | BV26: 63.371604 | BW26: 60.328235 | BX26: 67.903686 | BY26: 67.112998 | BZ26: 71.048874 | CA26: 71.423398 | CB26: 71.155128 | CC26: 73.757291 | CD26: 70.771727 | CE26: 72.385315 | CF26: 73.194878 | CG26: 68.396513 | CH26: 73.239832 | CI26: 70.208419 | CJ26: 77.786613 | CK26: 77.003709 | CL26: 80.954378 | CM26: 81.396156 | CN26: 81.231749 | CO26: 83.937065 | CP26: 81.272423 | CQ26: 82.751758 | CR26: 83.744769 | CS26: 79.82204 | CT26: 82.312321 | CU26: 81.926074 | CV26: 1 | CW26: 1302
C27: Actual | CV27: 0 | CW27: 0
A28: Am1302 | B28: desl | C28: Forecast | D28: 31.380551 | E28: 26.150817 | F28: 29.742052 | G28: 26.680523 | H28: 28.356021 | I28: 28.988406 | J28: 29.087755 | K28: 31.077767 | L28: 33.000939 | M28: 31.141555 | N28: 31.58534 | O28: 27.995519 | P28: 30.375136 | Q28: 26.360933 | R28: 29.950733 | S28: 27.318496 | T28: 29.099974 | U28: 30.059511 | V28: 30.201876 | W28: 32.09975 | X28: 33.971593 | Y28: 32.031355 | Z28: 32.42099 | AA28: 28.840478 | AB28: 31.276566 | AC28: 27.354418 | AD28: 31.058484 | AE28: 28.545484 | AF28: 30.439393 | AG28: 31.498711 | AH28: 31.725468 | AI28: 33.691849 | AJ28: 35.617981 | AK28: 33.721557 | AL28: 34.150102 | AM28: 30.609612 | AN28: 33.091556 | AO28: 29.22354 | AP28: 32.989867 | AQ28: 30.544864 | AR28: 32.508882 | AS28: 33.636811 | AT28: 33.928092 | AU28: 35.953799 | AV28: 37.934347 | AW28: 36.088651 | AX28: 36.565826 | AY28: 33.07333 | AZ28: 35.603656 | BA28: 31.784898 | BB28: 35.601374 | BC28: 33.207104 | BD28: 35.221985 | BE28: 36.400455 | BF28: 36.741605 | BG28: 38.816305 | BH28: 40.844898 | BI28: 39.046307 | BJ28: 39.569654 | BK28: 36.12234 | BL28: 38.696725 | BM28: 34.920728 | BN28: 38.778554 | BO28: 36.424286 | BP28: 38.478141 | BQ28: 39.695158 | BR28: 40.075199 | BS28: 42.189895 | BT28: 44.260101 | BU28: 42.504785 | BV28: 43.072519 | BW28: 39.669564 | BX28: 42.28669 | BY28: 38.550056 | BZ28: 42.442338 | CA28: 40.116733 | CB28: 42.193743 | CC28: 43.430181 | CD28: 43.829442 | CE28: 45.967716 | CF28: 48.071101 | CG28: 46.361878 | CH28: 46.990006 | CI28: 43.654737 | CJ28: 46.343703 | CK28: 42.667027 | CL28: 46.597281 | CM28: 44.276006 | CN28: 46.359173 | CO28: 47.508244 | CP28: 48.01672 | CQ28: 49.850785 | CR28: 52.052361 | CS28: 51.110862 | CT28: 50.705921 | CU28: 49.656763 | CV28: -1 | CW28: 1302
C29: Actual | CV29: 0 | CW29: 0
A30: Am1303 | B30: adm | C30: Forecast | D30: 11388.339 | E30: 11972.454 | F30: 13808.242 | G30: 13892.995 | H30: 13895.892 | I30: 14560.565 | J30: 14034.345 | K30: 14641.946 | L30: 14510.623 | M30: 13109.052 | N30: 13298.686 | O30: 10839.834 | P30: 13609.005 | Q30: 14194.683 | R30: 16325.923 | S30: 16431.731 | T30: 16361.834 | U30: 16929.126 | V30: 16341.894 | W30: 16977.127 | X30: 16966.719 | Y30: 15760.366 | Z30: 16147.305 | AA30: 13825.841 | AB30: 16646.42 | AC30: 17202.147 | AD30: 19253.665 | AE30: 19272.151 | AF30: 19140.185 | AG30: 19685.372 | AH30: 19113.577 | AI30: 19788.918 | AJ30: 19828.207 | AK30: 18669.574 | AL30: 19096.004 | AM30: 16803.961 | AN30: 19644.528 | AO30: 20212.317 | AP30: 22269.72 | AQ30: 22289.982 | AR30: 22158.219 | AS30: 22704.814 | AT30: 22138.034 | AU30: 22823.334 | AV30: 22877.414 | AW30: 21736.976 | AX30: 22182.847 | AY30: 19909.363 | AZ30: 22766.136 | BA30: 23347.26 | BB30: 25415.466 | BC30: 25444.865 | BD30: 25321.548 | BE30: 25876.665 | BF30: 25318.89 | BG30: 26013.745 | BH30: 26077.78 | BI30: 24947.492 | BJ30: 25403.58 | BK30: 23140.388 | BL30: 26007.668 | BM30: 26599.705 | BN30: 28679.365 | BO30: 28720.711 | BP30: 28609.519 | BQ30: 29176.346 | BR30: 28629.09 | BS30: 29332.518 | BT30: 29402.704 | BU30: 28276.216 | BV30: 28734.511 | BW30: 26473.352 | BX30: 29344.327 | BY30: 29943.541 | BZ30: 32035.147 | CA30: 32093.477 | CB30: 32003.254 | CC30: 32592.61 | CD30: 32065.9 | CE30: 32783.812 | CF30: 32858.614 | CG30: 31724.574 | CH30: 32163.472 | CI30: 29874.506 | CJ30: 32717.606 | CK30: 33300.115 | CL30: 35392.841 | CM30: 35486.062 | CN30: 35459.245 | CO30: 36122.345 | CP30: 35709.908 | CQ30: 36426.657 | CR30: 36508.109 | CS30: 35609.133 | CT30: 35395.928 | CU30: 33549.447 | CV30: 1 | CW30: 1303
C31: Actual | CV31: 0 | CW31: 0
A32: Am1303 | B32: desl | C32: Forecast | D32: 12403.217 | E32: 12754.232 | F32: 13999.875 | G32: 13473.188 | H32: 14433.634 | I32: 12993.679 | J32: 13352.826 | K32: 13998.239 | L32: 12802.86 | M32: 15580.094 | N32: 15836.438 | O32: 15393.752 | P32: 15012.756 | Q32: 14229.462 | R32: 15518.562 | S32: 14728.403 | T32: 15587.193 | U32: 14157.315 | V32: 14460.065 | W32: 15129.351 | X32: 14032.805 | Y32: 16962.618 | Z32: 17395.793 | AA32: 17103.428 | AB32: 16814.244 | AC32: 16060.788 | AD32: 17336.654 | AE32: 16518.82 | AF32: 17361.138 | AG32: 15940.346 | AH32: 16279.235 | AI32: 17004.421 | AJ32: 15973.055 | AK32: 18968.238 | AL32: 19461.589 | AM32: 19222.304 | AN32: 18979.252 | AO32: 18265.895 | AP32: 19576.912 | AQ32: 18790.533 | AR32: 19662.193 | AS32: 18270.504 | AT32: 18640.07 | AU32: 19398.746 | AV32: 18403.985 | AW32: 21438.206 | AX32: 21971.667 | AY32: 21772.037 | AZ32: 21566.978 | BA32: 20889.345 | BB32: 22233.844 | BC32: 21479.169 | BD32: 22381.398 | BE32: 21019.724 | BF32: 21419.134 | BG32: 22207.655 | BH32: 21242.765 | BI32: 24306.849 | BJ32: 24870.148 | BK32: 24700.368 | BL32: 24525.228 | BM32: 23877.62 | BN32: 25252.187 | BO32: 24527.408 | BP32: 25458.971 | BQ32: 24125.556 | BR32: 24551.623 | BS32: 25364.831 | BT32: 24422.619 | BU32: 27507.797 | BV32: 28091.501 | BW32: 27942.668 | BX32: 27790.323 | BY32: 27168.373 | BZ32: 28571.842 | CA32: 27878.716 | CB32: 28843.244 | CC32: 27541.851 | CD32: 27996.297 | CE32: 28831.54 | CF32: 27903.153 | CG32: 30993.507 | CH32: 31575.221 | CI32: 31421.906 | CJ32: 31269.563 | CK32: 30657.035 | CL32: 32091.576 | CM32: 31446.866 | CN32: 32476.197 | CO32: 31266.819 | CP32: 31740.782 | CQ32: 32625.689 | CR32: 31814.241 | CS32: 34296.093 | CT32: 35633.204 | CU32: 34898.813 | CV32: -1 | CW32: 1303
C33: Actual | CV33: 0 | CW33: 0
A34: Am1304 | B34: adm | C34: Forecast | D34: 96.04359 | E34: 91.572248 | F34: 101.59855 | G34: 93.177487 | H34: 90.774641 | I34: 90.951577 | J34: 85.081269 | K34: 86.726904 | L34: 82.510594 | M34: 76.470534 | N34: 82.333365 | O34: 69.885936 | P34: 99.147147 | Q34: 96.766372 | R34: 108.93567 | S34: 100.3346 | T34: 97.433607 | U34: 96.74383 | V34: 90.556328 | W34: 92.207951 | X34: 88.368198 | Y34: 83.092935 | Z34: 89.791597 | AA34: 78.066273 | AB34: 107.84427 | AC34: 105.74271 | AD34: 118.02537 | AE34: 109.49161 | AF34: 106.7121 | AG34: 106.2523 | AH34: 100.40939 | AI34: 102.49186 | AJ34: 99.12884 | AK34: 94.340436 | AL34: 101.51172 | AM34: 90.232114 | AN34: 120.4246 | AO34: 118.70642 | AP34: 131.34434 | AQ34: 123.14357 | AR34: 120.68334 | AS34: 120.53914 | AT34: 115.0173 | AU34: 117.43223 | AV34: 114.41419 | AW34: 109.97992 | AX34: 117.50822 | AY34: 106.5817 | AZ34: 137.11801 | BA34: 135.73173 | BB34: 148.68963 | BC34: 140.79879 | BD34: 138.64102 | BE34: 138.79418 | BF34: 133.56617 | BG34: 136.27212 | BH34: 133.54246 | BI34: 129.39397 | BJ34: 137.20567 | BK34: 126.5607 | BL34: 157.37745 | BM34: 156.27113 | BN34: 169.50854 | BO34: 161.89586 | BP34: 160.01285 | BQ34: 160.43434 | BR34: 155.46487 | BS34: 158.41681 | BT34: 155.91951 | BU34: 151.99121 | BV34: 160.01524 | BW34: 149.58143 | BX34: 180.61598 | BY34: 179.74116 | BZ34: 193.22804 | CA34: 185.8825 | CB34: 184.27821 | CC34: 184.97824 | CD34: 180.27063 | CE34: 183.44967 | CF34: 181.12864 | CG34: 177.31884 | CH34: 185.40945 | CI34: 175.01414 | CJ34: 206.09664 | CK34: 205.33835 | CL34: 219.02296 | CM34: 212.01874 | CN34: 210.85865 | CO34: 211.99954 | CP34: 207.72704 | CQ34: 211.11403 | CR34: 208.30027 | CS34: 206.29975 | CT34: 210.03714 | CU34: 203.9606 | CV34: 1 | CW34: 1304
C35: Actual | CV35: 0 | CW35: 0
A36: Am1304 | B36: desl | C36: Forecast | D36: 84.798367 | E36: 78.580887 | F36: 80.596767 | G36: 78.528469 | H36: 79.393456 | I36: 73.919093 | J36: 73.941072 | K36: 75.499869 | L36: 74.408127 | M36: 84.849754 | N36: 86.697735 | O36: 88.505448 | P36: 83.594244 | Q36: 83.374288 | R36: 85.327886 | S36: 83.42983 | T36: 83.000745 | U36: 77.345456 | V36: 77.1253 | W36: 78.744205 | X36: 78.099974 | Y36: 89.125784 | Z36: 91.654865 | AA36: 94.112412 | AB36: 89.709861 | AC36: 89.848112 | AD36: 92.047133 | AE36: 90.348134 | AF36: 90.138409 | AG36: 84.765671 | AH36: 84.90412 | AI36: 86.947388 | AJ36: 86.770091 | AK36: 98.279626 | AL36: 101.28818 | AM36: 104.20715 | AN36: 100.24071 | AO36: 100.78775 | AP36: 103.37032 | AQ36: 102.03487 | AR36: 102.17607 | AS36: 97.149762 | AT36: 97.637204 | AU36: 100.03646 | AV36: 100.22315 | AW36: 112.10241 | AX36: 115.48208 | AY36: 118.76858 | AZ36: 115.16201 | BA36: 116.05889 | BB36: 118.98082 | BC36: 117.9753 | BD36: 118.43888 | BE36: 113.72939 | BF36: 114.52971 | BG36: 117.23894 | BH36: 117.7332 | BI36: 129.91775 | BJ36: 133.60036 | BK36: 137.18735 | BL36: 133.87867 | BM36: 135.07062 | BN36: 138.28436 | BO36: 137.56663 | BP36: 138.3129 | BQ36: 133.87974 | BR36: 134.94887 | BS36: 137.91881 | BT36: 138.66601 | BU36: 151.09725 | BV36: 155.02287 | BW36: 158.85242 | BX36: 155.789 | BY36: 157.23111 | BZ36: 160.7004 | CA36: 160.24191 | CB36: 161.24709 | CC36: 157.06649 | CD36: 158.3748 | CE36: 161.56339 | CF36: 162.50408 | CG36: 175.10288 | CH36: 179.17527 | CI36: 183.14507 | CJ36: 180.23544 | CK36: 181.85667 | CL36: 185.57212 | CM36: 185.3877 | CN36: 186.71728 | CO36: 182.91267 | CP36: 184.33415 | CQ36: 187.71021 | CR36: 188.93905 | CS36: 199.96928 | CT36: 206.95744 | CU36: 209.60235 | CV36: -1 | CW36: 1304
C37: Actual | CV37: 0 | CW37: 0
A38: Rr1401 | B38: adm | C38: Forecast | D38: 1628.9781 | E38: 1629.7498 | F38: 1749.1998 | G38: 1752.899 | H38: 1742.2199 | I38: 1814.7726 | J38: 1756.9953 | K38: 1783.2222 | L38: 1798.0092 | M38: 1659.7158 | N38: 1728.4397 | O38: 1605.0541 | P38: 1824.3101 | Q38: 1834.652 | R38: 1940.3038 | S38: 1944.2278 | T38: 1923.7768 | U38: 1988.1201 | V38: 1927.7146 | W38: 1955.5072 | X38: 1976.0121 | Y38: 1847.5638 | Z38: 1926.0461 | AA38: 1810.0284 | AB38: 2032.9893 | AC38: 2043.3214 | AD38: 2146.4753 | AE38: 2147.2673 | AF38: 2124.5517 | AG38: 2188.2766 | AH38: 2128.9367 | AI38: 2159.0166 | AJ38: 2182.408 | AK38: 2056.9178 | AL38: 2138.0897 | AM38: 2024.3374 | AN38: 2249.1099 | AO38: 2260.8351 | AP38: 2365.0341 | AQ38: 2366.6252 | AR38: 2344.5935 | AS38: 2409.0296 | AT38: 2350.5522 | AU38: 2381.7181 | AV38: 2406.4223 | AW38: 2282.4118 | AX38: 2365.1335 | AY38: 2252.901 | AZ38: 2479.0896 | BA38: 2492.0952 | BB38: 2597.4465 | BC38: 2600.0958 | BD38: 2579.0716 | BE38: 2644.5012 | BF38: 2587.0259 | BG38: 2619.2103 | BH38: 2644.9466 | BI38: 2521.9751 | BJ38: 2605.7376 | BK38: 2494.5475 | BL38: 2721.7853 | BM38: 2735.8541 | BN38: 2842.2875 | BO38: 2846.0348 | BP38: 2826.1093 | BQ38: 2892.611 | BR38: 2836.145 | BS38: 2869.2403 | BT38: 2895.7669 | BU38: 2773.4682 | BV38: 2857.8221 | BW38: 2747.2101 | BX38: 2975.1008 | BY38: 2989.9845 | BZ38: 3097.455 | CA38: 3102.4729 | CB38: 3083.9977 | CC38: 3152.0128 | CD38: 3096.9557 | CE38: 3131.1704 | CF38: 3158.354 | CG38: 3036.1531 | CH38: 3120.0654 | CI38: 3008.6138 | CJ38: 3235.6379 | CK38: 3250.2402 | CL38: 3358.0804 | CM38: 3365.1954 | CN38: 3350.226 | CO38: 3421.7341 | CP38: 3374.0611 | CQ38: 3408.1858 | CR38: 3432.3907 | CS38: 3338.7577 | CT38: 3356.6747 | CU38: 3300.3564 | CV38: 1 | CW38: 1401
C39: Actual | CV39: 0 | CW39: 0
A40: Rr1401 | B40: desl | C40: Forecast | D40: 1830.653 | E40: 1650.3935 | F40: 1864.9591 | G40: 1717.2252 | H40: 1822.2261 | I40: 1742.3945 | J40: 1738.7411 | K40: 1800.4879 | L40: 1686.9631 | M40: 1800.8774 | N40: 1813.804 | O40: 1711.8609 | P40: 1927.5504 | Q40: 1791.2198 | R40: 1998.4343 | S40: 1847.2047 | T40: 1944.7079 | U40: 1865.9235 | V40: 1856.9972 | W40: 1921.7626 | X40: 1814.8411 | Y40: 1939.2015 | Z40: 1962.3986 | AA40: 1868.3356 | AB40: 2087.8458 | AC40: 1951.6262 | AD40: 2156.7134 | AE40: 2002.9872 | AF40: 2099.0205 | AG40: 2020.4641 | AH40: 2013.377 | AI40: 2081.0711 | AJ40: 1977.5414 | AK40: 2105.2614 | AL40: 2131.5038 | AM40: 2040.0698 | AN40: 2261.7887 | AO40: 2127.3949 | AP40: 2333.9858 | AQ40: 2181.5314 | AR40: 2278.7258 | AS40: 2201.3564 | AT40: 2195.6012 | AU40: 2264.8405 | AV40: 2163.0689 | AW40: 2292.6975 | AX40: 2320.9016 | AY40: 2231.3849 | AZ40: 2454.9075 | BA40: 2322.1766 | BB40: 2530.3009 | BC40: 2379.2858 | BD40: 2477.8678 | BE40: 2401.8694 | BF40: 2397.4899 | BG40: 2468.1168 | BH40: 2367.743 | BI40: 2498.7747 | BJ40: 2528.3835 | BK40: 2440.2733 | BL40: 2665.2069 | BM40: 2533.8945 | BN40: 2743.4434 | BO40: 2593.8499 | BP40: 2693.8316 | BQ40: 2619.1843 | BR40: 2616.0781 | BS40: 2687.8779 | BT40: 2588.5698 | BU40: 2720.5774 | BV40: 2751.1165 | BW40: 2663.9561 | BX40: 2889.933 | BY40: 2759.8211 | BZ40: 2970.7613 | CA40: 2822.7368 | CB40: 2924.3963 | CC40: 2851.4131 | CD40: 2849.8006 | CE40: 2922.7586 | CF40: 2824.1489 | CG40: 2956.3572 | CH40: 2986.6872 | CI40: 2899.1324 | CJ40: 3124.975 | CK40: 2995.25 | CL40: 3207.668 | CM40: 3062.3852 | CN40: 3167.7007 | CO40: 3099.6279 | CP40: 3102.501 | CQ40: 3173.9936 | CR40: 3087.1105 | CS40: 3195.723 | CT40: 3240.3753 | CU40: 3152.8794 | CV40: -1 | CW40: 1401
...

Sheet Adm
B2: Mesoregiao | C2: 2017M1 | D2: 2017M2 | E2: 2017M3 | F2: 2017M4 | G2: 2017M5 | H2: 2017M6 | I2: 2017M7 | J2: 2017M8 | K2: 2017M9 | L2: 2017M10 | M2: 2017M11 | N2: 2017M12 | O2: 2018M1 | P2: 2018M2 | Q2: 2018M3 | R2: 2018M4 | S2: 2018M5 | T2: 2018M6 | U2: 2018M7 | V2: 2018M8 | W2: 2018M9 | X2: 2018M10 | Y2: 2018M11 | Z2: 2018M12 | AA2: 2019M1 | AB2: 2019M2 | AC2: 2019M3 | AD2: 2019M4 | AE2: 2019M5 | AF2: 2019M6 | AG2: 2019M7 | AH2: 2019M8 | AI2: 2019M9 | AJ2: 2019M10 | AK2: 2019M11 | AL2: 2019M12 | AM2: 2020M1 | AN2: 2020M2 | AO2: 2020M3 | AP2: 2020M4 | AQ2: 2020M5 | AR2: 2020M6 | AS2: 2020M7 | AT2: 2020M8 | AU2: 2020M9 | AV2: 2020M10 | AW2: 2020M11 | AX2: 2020M12 | AY2: 2021M1 | AZ2: 2021M2 | BA2: 2021M3 | BB2: 2021M4 | BC2: 2021M5 | BD2: 2021M6 | BE2: 2021M7 | BF2: 2021M8 | BG2: 2021M9 | BH2: 2021M10 | BI2: 2021M11 | BJ2: 2021M12 | BK2: 2022M1 | BL2: 2022M2 | BM2: 2022M3 | BN2: 2022M4 | BO2: 2022M5 | BP2: 2022M6 | BQ2: 2022M7 | BR2: 2022M8 | BS2: 2022M9 | BT2: 2022M10 | BU2: 2022M11 | BV2: 2022M12 | BW2: 2023M1 | BX2: 2023M2 | BY2: 2023M3 | BZ2: 2023M4 | CA2: 2023M5 | CB2: 2023M6 | CC2: 2023M7 | CD2: 2023M8 | CE2: 2023M9 | CF2: 2023M10 | CG2: 2023M11 | CH2: 2023M12 | CI2: 2024M1 | CJ2: 2024M2 | CK2: 2024M3 | CL2: 2024M4 | CM2: 2024M5 | CN2: 2024M6 | CO2: 2024M7 | CP2: 2024M8 | CQ2: 2024M9 | CR2: 2024M10 | CS2: 2024M11 | CT2: 2024M12
B3: 1102 | C3: =SUMIFS('conditional forecasts_8'!D$6:D$553,'conditional forecasts_8'!$CW$6:$CW$553,$B3,'conditional forecasts_8'!$B$6:$B$553,"adm") -> 4980.5079 | D3: =SUMIFS('conditional forecasts_8'!E$6:E$553,'conditional forecasts_8'!$CW$6:$CW$553,$B3,'conditional forecasts_8'!$B$6:$B$553,"adm") -> 5358.7058 | E3: =SUMIFS('conditional forecasts_8'!F$6:F$553,'conditional forecasts_8'!$CW$6:$CW$553,$B3,'conditional forecasts_8'!$B$6:$B$553,"adm") -> 6017.9881 | F3: =SUMIFS('conditional forecasts_8'!G$6:G$553,'conditional forecasts_8'!$CW$6:$CW$553,$B3,'conditional forecasts_8'!$B$6:$B$553,"adm") -> 5995.5157 | G3: =SUMIFS('conditional forecasts_8'!H$6:H$553,'conditional forecasts_8'!$CW$6:$CW$553,$B3,'conditional forecasts_8'!$B$6:$B$553,"adm") -> 5938.4682 | H3: =SUMIFS('conditional forecasts_8'!I$6:I$553,'conditional forecasts_8'!$CW$6:$CW$553,$B3,'conditional forecasts_8'!$B$6:$B$553,"adm") -> 5977.6758 | I3: =SUMIFS('conditional forecasts_8'!J$6:J$553,'conditional forecasts_8'!$CW$6:$CW$553,$B3,'conditional forecasts_8'!$B$6:$B$553,"adm") -> 5666.6636 | J3: =SUMIFS('conditional forecasts_8'!K$6:K$553,'conditional forecasts_8'!$CW$6:$CW$553,$B3,'conditional forecasts_8'!$B$6:$B$553,"adm") -> 5667.5644 | ... CT3: =SUMIFS('conditional forecasts_8'!CU$6:CU$553,'conditional forecasts_8'!$CW$6:$CW$553,$B3,'conditional forecasts_8'!$B$6:$B$553,"adm") -> 11840.049
B4: 1101 | C4: =SUMIFS('conditional forecasts_8'!D$6:D$553,'conditional forecasts_8'!$CW$6:$CW$553,$B4,'conditional forecasts_8'!$B$6:$B$553,"adm") -> 3115.6169 | D4: =SUMIFS('conditional forecasts_8'!E$6:E$553,'conditional forecasts_8'!$CW$6:$CW$553,$B4,'conditional forecasts_8'!$B$6:$B$553,"adm") -> 3366.9532 | E4: =SUMIFS('conditional forecasts_8'!F$6:F$553,'conditional forecasts_8'!$CW$6:$CW$553,$B4,'conditional forecasts_8'!$B$6:$B$553,"adm") -> 3895.1536 | F4: =SUMIFS('conditional forecasts_8'!G$6:G$553,'conditional forecasts_8'!$CW$6:$CW$553,$B4,'conditional forecasts_8'!$B$6:$B$553,"adm") -> 4031.024 | G4: =SUMIFS('conditional forecasts_8'!H$6:H$553,'conditional forecasts_8'!$CW$6:$CW$553,$B4,'conditional forecasts_8'!$B$6:$B$553,"adm") -> 4157.4622 | H4: =SUMIFS('conditional forecasts_8'!I$6:I$553,'conditional forecasts_8'!$CW$6:$CW$553,$B4,'conditional forecasts_8'!$B$6:$B$553,"adm") -> 4381.114 | I4: =SUMIFS('conditional forecasts_8'!J$6:J$553,'conditional forecasts_8'!$CW$6:$CW$553,$B4,'conditional forecasts_8'!$B$6:$B$553,"adm") -> 4326.4124 | J4: =SUMIFS('conditional forecasts_8'!K$6:K$553,'conditional forecasts_8'!$CW$6:$CW$553,$B4,'conditional forecasts_8'!$B$6:$B$553,"adm") -> 4376.2513 | ... CT4: =SUMIFS('conditional forecasts_8'!CU$6:CU$553,'conditional forecasts_8'!$CW$6:$CW$553,$B4,'conditional forecasts_8'!$B$6:$B$553,"adm") -> 14800.144
B5: 1100 | C5: =SUMIFS('conditional forecasts_8'!D$6:D$553,'conditional forecasts_8'!$CW$6:$CW$553,$B5,'conditional forecasts_8'!$B$6:$B$553,"adm") -> 0 | D5: =SUMIFS('conditional forecasts_8'!E$6:E$553,'conditional forecasts_8'!$CW$6:$CW$553,$B5,'conditional forecasts_8'!$B$6:$B$553,"adm") -> 0 | E5: =SUMIFS('conditional forecasts_8'!F$6:F$553,'conditional forecasts_8'!$CW$6:$CW$553,$B5,'conditional forecasts_8'!$B$6:$B$553,"adm") -> 0 | F5: =SUMIFS('conditional forecasts_8'!G$6:G$553,'conditional forecasts_8'!$CW$6:$CW$553,$B5,'conditional forecasts_8'!$B$6:$B$553,"adm") -> 0 | G5: =SUMIFS('conditional forecasts_8'!H$6:H$553,'conditional forecasts_8'!$CW$6:$CW$553,$B5,'conditional forecasts_8'!$B$6:$B$553,"adm") -> 0 | H5: =SUMIFS('conditional forecasts_8'!I$6:I$553,'conditional forecasts_8'!$CW$6:$CW$553,$B5,'conditional forecasts_8'!$B$6:$B$553,"adm") -> 0 | I5: =SUMIFS('conditional forecasts_8'!J$6:J$553,'conditional forecasts_8'!$CW$6:$CW$553,$B5,'conditional forecasts_8'!$B$6:$B$553,"adm") -> 0 | J5: =SUMIFS('conditional forecasts_8'!K$6:K$553,'conditional forecasts_8'!$CW$6:$CW$553,$B5,'conditional forecasts_8'!$B$6:$B$553,"adm") -> 0 | ... CT5: =SUMIFS('conditional forecasts_8'!CU$6:CU$553,'conditional forecasts_8'!$CW$6:$CW$553,$B5,'conditional forecasts_8'!$B$6:$B$553,"adm") -> 0
B6: 1202 | C6: =SUMIFS('conditional forecasts_8'!D$6:D$553,'conditional forecasts_8'!$CW$6:$CW$553,$B6,'conditional forecasts_8'!$B$6:$B$553,"adm") -> 1631.3306 | D6: =SUMIFS('conditional forecasts_8'!E$6:E$553,'conditional forecasts_8'!$CW$6:$CW$553,$B6,'conditional forecasts_8'!$B$6:$B$553,"adm") -> 1721.5021 | E6: =SUMIFS('conditional forecasts_8'!F$6:F$553,'conditional forecasts_8'!$CW$6:$CW$553,$B6,'conditional forecasts_8'!$B$6:$B$553,"adm") -> 1893.8196 | F6: =SUMIFS('conditional forecasts_8'!G$6:G$553,'conditional forecasts_8'!$CW$6:$CW$553,$B6,'conditional forecasts_8'!$B$6:$B$553,"adm") -> 1956.8734 | G6: =SUMIFS('conditional forecasts_8'!H$6:H$553,'conditional forecasts_8'!$CW$6:$CW$553,$B6,'conditional forecasts_8'!$B$6:$B$553,"adm") -> 1949.5672 | H6: =SUMIFS('conditional forecasts_8'!I$6:I$553,'conditional forecasts_8'!$CW$6:$CW$553,$B6,'conditional forecasts_8'!$B$6:$B$553,"adm") -> 1978.9168 | I6: =SUMIFS('conditional forecasts_8'!J$6:J$553,'conditional forecasts_8'!$CW$6:$CW$553,$B6,'conditional forecasts_8'!$B$6:$B$553,"adm") -> 1924.7042 | J6: =SUMIFS('conditional forecasts_8'!K$6:K$553,'conditional forecasts_8'!$CW$6:$CW$553,$B6,'conditional forecasts_8'!$B$6:$B$553,"adm") -> 1923.8549 | ... CT6: =SUMIFS('conditional forecasts_8'!CU$6:CU$553,'conditional forecasts_8'!$CW$6:$CW$553,$B6,'conditional forecasts_8'!$B$6:$B$553,"adm") -> 4289.4679
B7: 1201 | C7: =SUMIFS('conditional forecasts_8'!D$6:D$553,'conditional forecasts_8'!$CW$6:$CW$553,$B7,'conditional forecasts_8'!$B$6:$B$553,"adm") -> 129.28288 | D7: =SUMIFS('conditional forecasts_8'!E$6:E$553,'conditional forecasts_8'!$CW$6:$CW$553,$B7,'conditional forecasts_8'!$B$6:$B$553,"adm") -> 127.28931 | E7: =SUMIFS('conditional forecasts_8'!F$6:F$553,'conditional forecasts_8'!$CW$6:$CW$553,$B7,'conditional forecasts_8'!$B$6:$B$553,"adm") -> 177.02006 | F7: =SUMIFS('conditional forecasts_8'!G$6:G$553,'conditional forecasts_8'!$CW$6:$CW$553,$B7,'conditional forecasts_8'!$B$6:$B$553,"adm") -> 209.95592 | G7: =SUMIFS('conditional forecasts_8'!H$6:H$553,'conditional forecasts_8'!$CW$6:$CW$553,$B7,'conditional forecasts_8'!$B$6:$B$553,"adm") -> 230.05114 | H7: =SUMIFS('conditional forecasts_8'!I$6:I$553,'conditional forecasts_8'!$CW$6:$CW$553,$B7,'conditional forecasts_8'!$B$6:$B$553,"adm") -> 246.67733 | I7: =SUMIFS('conditional forecasts_8'!J$6:J$553,'conditional forecasts_8'!$CW$6:$CW$553,$B7,'conditional forecasts_8'!$B$6:$B$553,"adm") -> 231.02716 | J7: =SUMIFS('conditional forecasts_8'!K$6:K$553,'conditional forecasts_8'!$CW$6:$CW$553,$B7,'conditional forecasts_8'!$B$6:$B$553,"adm") -> 222.21148 | ... CT7: =SUMIFS('conditional forecasts_8'!CU$6:CU$553,'conditional forecasts_8'!$CW$6:$CW$553,$B7,'conditional forecasts_8'!$B$6:$B$553,"adm") -> 517.82064
B8: 1303 | C8: =SUMIFS('conditional forecasts_8'!D$6:D$553,'conditional forecasts_8'!$CW$6:$CW$553,$B8,'conditional forecasts_8'!$B$6:$B$553,"adm") -> 11388.339 | D8: =SUMIFS('conditional forecasts_8'!E$6:E$553,'conditional forecasts_8'!$CW$6:$CW$553,$B8,'conditional forecasts_8'!$B$6:$B$553,"adm") -> 11972.454 | E8: =SUMIFS('conditional forecasts_8'!F$6:F$553,'conditional forecasts_8'!$CW$6:$CW$553,$B8,'conditional forecasts_8'!$B$6:$B$553,"adm") -> 13808.242 | F8: =SUMIFS('conditional forecasts_8'!G$6:G$553,'conditional forecasts_8'!$CW$6:$CW$553,$B8,'conditional forecasts_8'!$B$6:$B$553,"adm") -> 13892.995 | G8: =SUMIFS('conditional forecasts_8'!H$6:H$553,'conditional forecasts_8'!$CW$6:$CW$553,$B8,'conditional forecasts_8'!$B$6:$B$553,"adm") -> 13895.892 | H8: =SUMIFS('conditional forecasts_8'!I$6:I$553,'conditional forecasts_8'!$CW$6:$CW$553,$B8,'conditional forecasts_8'!$B$6:$B$553,"adm") -> 14560.565 | I8: =SUMIFS('conditional forecasts_8'!J$6:J$553,'conditional forecasts_8'!$CW$6:$CW$553,$B8,'conditional forecasts_8'!$B$6:$B$553,"adm") -> 14034.345 | J8: =SUMIFS('conditional forecasts_8'!K$6:K$553,'conditional forecasts_8'!$CW$6:$CW$553,$B8,'conditional forecasts_8'!$B$6:$B$553,"adm") -> 14641.946 | ... CT8: =SUMIFS('conditional forecasts_8'!CU$6:CU$553,'conditional forecasts_8'!$CW$6:$CW$553,$B8,'conditional forecasts_8'!$B$6:$B$553,"adm") -> 33549.447
B9: 1302 | C9: =SUMIFS('conditional forecasts_8'!D$6:D$553,'conditional forecasts_8'!$CW$6:$CW$553,$B9,'conditional forecasts_8'!$B$6:$B$553,"adm") -> 27.941897 | D9: =SUMIFS('conditional forecasts_8'!E$6:E$553,'conditional forecasts_8'!$CW$6:$CW$553,$B9,'conditional forecasts_8'!$B$6:$B$553,"adm") -> 25.585754 | E9: =SUMIFS('conditional forecasts_8'!F$6:F$553,'conditional forecasts_8'!$CW$6:$CW$553,$B9,'conditional forecasts_8'!$B$6:$B$553,"adm") -> 30.092035 | F9: =SUMIFS('conditional forecasts_8'!G$6:G$553,'conditional forecasts_8'!$CW$6:$CW$553,$B9,'conditional forecasts_8'!$B$6:$B$553,"adm") -> 29.908072 | G9: =SUMIFS('conditional forecasts_8'!H$6:H$553,'conditional forecasts_8'!$CW$6:$CW$553,$B9,'conditional forecasts_8'!$B$6:$B$553,"adm") -> 29.558493 | H9: =SUMIFS('conditional forecasts_8'!I$6:I$553,'conditional forecasts_8'!$CW$6:$CW$553,$B9,'conditional forecasts_8'!$B$6:$B$553,"adm") -> 32.122741 | I9: =SUMIFS('conditional forecasts_8'!J$6:J$553,'conditional forecasts_8'!$CW$6:$CW$553,$B9,'conditional forecasts_8'!$B$6:$B$553,"adm") -> 28.836753 | J9: =SUMIFS('conditional forecasts_8'!K$6:K$553,'conditional forecasts_8'!$CW$6:$CW$553,$B9,'conditional forecasts_8'!$B$6:$B$553,"adm") -> 30.206445 | ... CT9: =SUMIFS('conditional forecasts_8'!CU$6:CU$553,'conditional forecasts_8'!$CW$6:$CW$553,$B9,'conditional forecasts_8'!$B$6:$B$553,"adm") -> 81.926074
B10: 1304 | C10: =SUMIFS('conditional forecasts_8'!D$6:D$553,'conditional forecasts_8'!$CW$6:$CW$553,$B10,'conditional forecasts_8'!$B$6:$B$553,"adm") -> 96.04359 | D10: =SUMIFS('conditional forecasts_8'!E$6:E$553,'conditional forecasts_8'!$CW$6:$CW$553,$B10,'conditional forecasts_8'!$B$6:$B$553,"adm") -> 91.572248 | E10: =SUMIFS('conditional forecasts_8'!F$6:F$553,'conditional forecasts_8'!$CW$6:$CW$553,$B10,'conditional forecasts_8'!$B$6:$B$553,"adm") -> 101.59855 | F10: =SUMIFS('conditional forecasts_8'!G$6:G$553,'conditional forecasts_8'!$CW$6:$CW$553,$B10,'conditional forecasts_8'!$B$6:$B$553,"adm") -> 93.177487 | G10: =SUMIFS('conditional forecasts_8'!H$6:H$553,'conditional forecasts_8'!$CW$6:$CW$553,$B10,'conditional forecasts_8'!$B$6:$B$553,"adm") -> 90.774641 | H10: =SUMIFS('conditional forecasts_8'!I$6:I$553,'conditional forecasts_8'!$CW$6:$CW$553,$B10,'conditional forecasts_8'!$B$6:$B$553,"adm") -> 90.951577 | I10: =SUMIFS('conditional forecasts_8'!J$6:J$553,'conditional forecasts_8'!$CW$6:$CW$553,$B10,'conditional forecasts_8'!$B$6:$B$553,"adm") -> 85.081269 | J10: =SUMIFS('conditional forecasts_8'!K$6:K$553,'conditional forecasts_8'!$CW$6:$CW$553,$B10,'conditional forecasts_8'!$B$6:$B$553,"adm") -> 86.726904 | ... CT10: =SUMIFS('conditional forecasts_8'!CU$6:CU$553,'conditional forecasts_8'!$CW$6:$CW$553,$B10,'conditional forecasts_8'!$B$6:$B$553,"adm") -> 203.9606
B11: 1301 | C11: =SUMIFS('conditional forecasts_8'!D$6:D$553,'conditional forecasts_8'!$CW$6:$CW$553,$B11,'conditional forecasts_8'!$B$6:$B$553,"adm") -> 26.557922 | D11: =SUMIFS('conditional forecasts_8'!E$6:E$553,'conditional forecasts_8'!$CW$6:$CW$553,$B11,'conditional forecasts_8'!$B$6:$B$553,"adm") -> 16.017332 | E11: =SUMIFS('conditional forecasts_8'!F$6:F$553,'conditional forecasts_8'!$CW$6:$CW$553,$B11,'conditional forecasts_8'!$B$6:$B$553,"adm") -> 24.009068 | F11: =SUMIFS('conditional forecasts_8'!G$6:G$553,'conditional forecasts_8'!$CW$6:$CW$553,$B11,'conditional forecasts_8'!$B$6:$B$553,"adm") -> 18.191291 | G11: =SUMIFS('conditional forecasts_8'!H$6:H$553,'conditional forecasts_8'!$CW$6:$CW$553,$B11,'conditional forecasts_8'!$B$6:$B$553,"adm") -> 15.401722 | H11: =SUMIFS('conditional forecasts_8'!I$6:I$553,'conditional forecasts_8'!$CW$6:$CW$553,$B11,'conditional forecasts_8'!$B$6:$B$553,"adm") -> 22.969178 | I11: =SUMIFS('conditional forecasts_8'!J$6:J$553,'conditional forecasts_8'!$CW$6:$CW$553,$B11,'conditional forecasts_8'!$B$6:$B$553,"adm") -> 11.282975 | J11: =SUMIFS('conditional forecasts_8'!K$6:K$553,'conditional forecasts_8'!$CW$6:$CW$553,$B11,'conditional forecasts_8'!$B$6:$B$553,"adm") -> 14.762628 | ... CT11: =SUMIFS('conditional forecasts_8'!CU$6:CU$553,'conditional forecasts_8'!$CW$6:$CW$553,$B11,'conditional forecasts_8'!$B$6:$B$553,"adm") -> 4.7806808
B12: 1401 | C12: =SUMIFS('conditional forecasts_8'!D$6:D$553,'conditional forecasts_8'!$CW$6:$CW$553,$B12,'conditional forecasts_8'!$B$6:$B$553,"adm") -> 1628.9781 | D12: =SUMIFS('conditional forecasts_8'!E$6:E$553,'conditional forecasts_8'!$CW$6:$CW$553,$B12,'conditional forecasts_8'!$B$6:$B$553,"adm") -> 1629.7498 | E12: =SUMIFS('conditional forecasts_8'!F$6:F$553,'conditional forecasts_8'!$CW$6:$CW$553,$B12,'conditional forecasts_8'!$B$6:$B$553,"adm") -> 1749.1998 | F12: =SUMIFS('conditional forecasts_8'!G$6:G$553,'conditional forecasts_8'!$CW$6:$CW$553,$B12,'conditional forecasts_8'!$B$6:$B$553,"adm") -> 1752.899 | G12: =SUMIFS('conditional forecasts_8'!H$6:H$553,'conditional forecasts_8'!$CW$6:$CW$553,$B12,'conditional forecasts_8'!$B$6:$B$553,"adm") -> 1742.2199 | H12: =SUMIFS('conditional forecasts_8'!I$6:I$553,'conditional forecasts_8'!$CW$6:$CW$553,$B12,'conditional forecasts_8'!$B$6:$B$553,"adm") -> 1814.7726 | I12: =SUMIFS('conditional forecasts_8'!J$6:J$553,'conditional forecasts_8'!$CW$6:$CW$553,$B12,'conditional forecasts_8'!$B$6:$B$553,"adm") -> 1756.9953 | J12: =SUMIFS('conditional forecasts_8'!K$6:K$553,'conditional forecasts_8'!$CW$6:$CW$553,$B12,'conditional forecasts_8'!$B$6:$B$553,"adm") -> 1783.2222 | ... CT12: =SUMIFS('conditional forecasts_8'!CU$6:CU$553,'conditional forecasts_8'!$CW$6:$CW$553,$B12,'conditional forecasts_8'!$B$6:$B$553,"adm") -> 3300.3564
B13: 1402 | C13: =SUMIFS('conditional forecasts_8'!D$6:D$553,'conditional forecasts_8'!$CW$6:$CW$553,$B13,'conditional forecasts_8'!$B$6:$B$553,"adm") -> 85.08853 | D13: =SUMIFS('conditional forecasts_8'!E$6:E$553,'conditional forecasts_8'!$CW$6:$CW$553,$B13,'conditional forecasts_8'!$B$6:$B$553,"adm") -> 75.347942 | E13: =SUMIFS('conditional forecasts_8'!F$6:F$553,'conditional forecasts_8'!$CW$6:$CW$553,$B13,'conditional forecasts_8'!$B$6:$B$553,"adm") -> 82.171626 | F13: =SUMIFS('conditional forecasts_8'!G$6:G$553,'conditional forecasts_8'!$CW$6:$CW$553,$B13,'conditional forecasts_8'!$B$6:$B$553,"adm") -> 79.157025 | G13: =SUMIFS('conditional forecasts_8'!H$6:H$553,'conditional forecasts_8'!$CW$6:$CW$553,$B13,'conditional forecasts_8'!$B$6:$B$553,"adm") -> 76.611669 | H13: =SUMIFS('conditional forecasts_8'!I$6:I$553,'conditional forecasts_8'!$CW$6:$CW$553,$B13,'conditional forecasts_8'!$B$6:$B$553,"adm") -> 77.716972 | I13: =SUMIFS('conditional forecasts_8'!J$6:J$553,'conditional forecasts_8'!$CW$6:$CW$553,$B13,'conditional forecasts_8'!$B$6:$B$553,"adm") -> 71.697849 | J13: =SUMIFS('conditional forecasts_8'!K$6:K$553,'conditional forecasts_8'!$CW$6:$CW$553,$B13,'conditional forecasts_8'!$B$6:$B$553,"adm") -> 69.952822 | ... CT13: =SUMIFS('conditional forecasts_8'!CU$6:CU$553,'conditional forecasts_8'!$CW$6:$CW$553,$B13,'conditional forecasts_8'!$B$6:$B$553,"adm") -> 169.03319
B14: 1504 | C14: =SUMIFS('conditional forecasts_8'!D$6:D$553,'conditional forecasts_8'!$CW$6:$CW$553,$B14,'conditional forecasts_8'!$B$6:$B$553,"adm") -> 1705.7568 | D14: =SUMIFS('conditional forecasts_8'!E$6:E$553,'conditional forecasts_8'!$CW$6:$CW$553,$B14,'conditional forecasts_8'!$B$6:$B$553,"adm") -> 1744.0076 | E14: =SUMIFS('conditional forecasts_8'!F$6:F$553,'conditional forecasts_8'!$CW$6:$CW$553,$B14,'conditional forecasts_8'!$B$6:$B$553,"adm") -> 1934.0426 | F14: =SUMIFS('conditional forecasts_8'!G$6:G$553,'conditional forecasts_8'!$CW$6:$CW$553,$B14,'conditional forecasts_8'!$B$6:$B$553,"adm") -> 1919.1726 | G14: =SUMIFS('conditional forecasts_8'!H$6:H$553,'conditional forecasts_8'!$CW$6:$CW$553,$B14,'conditional forecasts_8'!$B$6:$B$553,"adm") -> 1856.4918 | H14: =SUMIFS('conditional forecasts_8'!I$6:I$553,'conditional forecasts_8'!$CW$6:$CW$553,$B14,'conditional forecasts_8'!$B$6:$B$553,"adm") -> 1904.0561 | I14: =SUMIFS('conditional forecasts_8'!J$6:J$553,'conditional forecasts_8'!$CW$6:$CW$553,$B14,'conditional forecasts_8'!$B$6:$B$553,"adm") -> 1749.5847 | J14: =SUMIFS('conditional forecasts_8'!K$6:K$553,'conditional forecasts_8'!$CW$6:$CW$553,$B14,'conditional forecasts_8'!$B$6:$B$553,"adm") -> 1857.4758 | ... CT14: =SUMIFS('conditional forecasts_8'!CU$6:CU$553,'conditional forecasts_8'!$CW$6:$CW$553,$B14,'conditional forecasts_8'!$B$6:$B$553,"adm") -> 4974.5326
... B154: 5301 | C154: =SUMIFS('conditional forecasts_8'!D$6:D$553,'conditional forecasts_8'!$CW$6:$CW$553,$B154,'conditional forecasts_8'!$B$6:$B$553,"adm") -> 22957.337 | D154: =SUMIFS('conditional forecasts_8'!E$6:E$553,'conditional forecasts_8'!$CW$6:$CW$553,$B154,'conditional forecasts_8'!$B$6:$B$553,"adm") -> 24058.5 | E154: =SUMIFS('conditional forecasts_8'!F$6:F$553,'conditional forecasts_8'!$CW$6:$CW$553,$B154,'conditional forecasts_8'!$B$6:$B$553,"adm") -> 25932.158 | F154: =SUMIFS('conditional forecasts_8'!G$6:G$553,'conditional forecasts_8'!$CW$6:$CW$553,$B154,'conditional forecasts_8'!$B$6:$B$553,"adm") -> 26053.857 | G154: =SUMIFS('conditional forecasts_8'!H$6:H$553,'conditional forecasts_8'!$CW$6:$CW$553,$B154,'conditional forecasts_8'!$B$6:$B$553,"adm") -> 25585.595 | H154: =SUMIFS('conditional forecasts_8'!I$6:I$553,'conditional forecasts_8'!$CW$6:$CW$553,$B154,'conditional forecasts_8'!$B$6:$B$553,"adm") -> 25719.131 | I154: =SUMIFS('conditional forecasts_8'!J$6:J$553,'conditional forecasts_8'!$CW$6:$CW$553,$B154,'conditional forecasts_8'!$B$6:$B$553,"adm") -> 24255.455 | J154: =SUMIFS('conditional forecasts_8'!K$6:K$553,'conditional forecasts_8'!$CW$6:$CW$553,$B154,'conditional forecasts_8'!$B$6:$B$553,"adm") -> 24177.04 | ... CT154: =SUMIFS('conditional forecasts_8'!CU$6:CU$553,'conditional forecasts_8'!$CW$6:$CW$553,$B154,'conditional forecasts_8'!$B$6:$B$553,"adm") -> 57447.24

Sheet Des
B2: Mesoregiao | C2: 2017M1 | D2: 2017M2 | E2: 2017M3 | F2: 2017M4 | G2: 2017M5 | H2: 2017M6 | I2: 2017M7 | J2: 2017M8 | K2: 2017M9 | L2: 2017M10 | M2: 2017M11 | N2: 2017M12 | O2: 2018M1 | P2: 2018M2 | Q2: 2018M3 | R2: 2018M4 | S2: 2018M5 | T2: 2018M6 | U2: 2018M7 | V2: 2018M8 | W2: 2018M9 | X2: 2018M10 | Y2: 2018M11 | Z2: 2018M12 | AA2: 2019M1 | AB2: 2019M2 | AC2: 2019M3 | AD2: 2019M4 | AE2: 2019M5 | AF2: 2019M6 | AG2: 2019M7 | AH2: 2019M8 | AI2: 2019M9 | AJ2: 2019M10 | AK2: 2019M11 | AL2: 2019M12 | AM2: 2020M1 | AN2: 2020M2 | AO2: 2020M3 | AP2: 2020M4 | AQ2: 2020M5 | AR2: 2020M6 | AS2: 2020M7 | AT2: 2020M8 | AU2: 2020M9 | AV2: 2020M10 | AW2: 2020M11 | AX2: 2020M12 | AY2: 2021M1 | AZ2: 2021M2 | BA2: 2021M3 | BB2: 2021M4 | BC2: 2021M5 | BD2: 2021M6 | BE2: 2021M7 | BF2: 2021M8 | BG2: 2021M9 | BH2: 2021M10 | BI2: 2021M11 | BJ2: 2021M12 | BK2: 2022M1 | BL2: 2022M2 | BM2: 2022M3 | BN2: 2022M4 | BO2: 2022M5 | BP2: 2022M6 | BQ2: 2022M7 | BR2: 2022M8 | BS2: 2022M9 | BT2: 2022M10 | BU2: 2022M11 | BV2: 2022M12 | BW2: 2023M1 | BX2: 2023M2 | BY2: 2023M3 | BZ2: 2023M4 | CA2: 2023M5 | CB2: 2023M6 | CC2: 2023M7 | CD2: 2023M8 | CE2: 2023M9 | CF2: 2023M10 | CG2: 2023M11 | CH2: 2023M12 | CI2: 2024M1 | CJ2: 2024M2 | CK2: 2024M3 | CL2: 2024M4 | CM2: 2024M5 | CN2: 2024M6 | CO2: 2024M7 | CP2: 2024M8 | CQ2: 2024M9 | CR2: 2024M10 | CS2: 2024M11 | CT2: 2024M12
B3: 1102 | C3: =SUMIFS('conditional forecasts_8'!D$6:D$553,'conditional forecasts_8'!$CW$6:$CW$553,$B3,'conditional forecasts_8'!$B$6:$B$553,"desl") -> 5215.2238 | D3: =SUMIFS('conditional forecasts_8'!E$6:E$553,'conditional forecasts_8'!$CW$6:$CW$553,$B3,'conditional forecasts_8'!$B$6:$B$553,"desl") -> 5235.7516 | E3: =SUMIFS('conditional forecasts_8'!F$6:F$553,'conditional forecasts_8'!$CW$6:$CW$553,$B3,'conditional forecasts_8'!$B$6:$B$553,"desl") -> 5791.0833 | F3: =SUMIFS('conditional forecasts_8'!G$6:G$553,'conditional forecasts_8'!$CW$6:$CW$553,$B3,'conditional forecasts_8'!$B$6:$B$553,"desl") -> 5428.1316 | G3: =SUMIFS('conditional forecasts_8'!H$6:H$553,'conditional forecasts_8'!$CW$6:$CW$553,$B3,'conditional forecasts_8'!$B$6:$B$553,"desl") -> 5728.3708 | H3: =SUMIFS('conditional forecasts_8'!I$6:I$553,'conditional forecasts_8'!$CW$6:$CW$553,$B3,'conditional forecasts_8'!$B$6:$B$553,"desl") -> 5271.3767 | I3: =SUMIFS('conditional forecasts_8'!J$6:J$553,'conditional forecasts_8'!$CW$6:$CW$553,$B3,'conditional forecasts_8'!$B$6:$B$553,"desl") -> 5364.2558 | J3: =SUMIFS('conditional forecasts_8'!K$6:K$553,'conditional forecasts_8'!$CW$6:$CW$553,$B3,'conditional forecasts_8'!$B$6:$B$553,"desl") -> 5594.3975 | ... CT3: =SUMIFS('conditional forecasts_8'!CU$6:CU$553,'conditional forecasts_8'!$CW$6:$CW$553,$B3,'conditional forecasts_8'!$B$6:$B$553,"desl") -> 12472.469
B4: 1101 | C4: =SUMIFS('conditional forecasts_8'!D$6:D$553,'conditional forecasts_8'!$CW$6:$CW$553,$B4,'conditional forecasts_8'!$B$6:$B$553,"desl") -> 3253.3177 | D4: =SUMIFS('conditional forecasts_8'!E$6:E$553,'conditional forecasts_8'!$CW$6:$CW$553,$B4,'conditional forecasts_8'!$B$6:$B$553,"desl") -> 3322.7997 | E4: =SUMIFS('conditional forecasts_8'!F$6:F$553,'conditional forecasts_8'!$CW$6:$CW$553,$B4,'conditional forecasts_8'!$B$6:$B$553,"desl") -> 3689.5561 | F4: =SUMIFS('conditional forecasts_8'!G$6:G$553,'conditional forecasts_8'!$CW$6:$CW$553,$B4,'conditional forecasts_8'!$B$6:$B$553,"desl") -> 3784.8754 | G4: =SUMIFS('conditional forecasts_8'!H$6:H$553,'conditional forecasts_8'!$CW$6:$CW$553,$B4,'conditional forecasts_8'!$B$6:$B$553,"desl") -> 4118.6782 | H4: =SUMIFS('conditional forecasts_8'!I$6:I$553,'conditional forecasts_8'!$CW$6:$CW$553,$B4,'conditional forecasts_8'!$B$6:$B$553,"desl") -> 4077.4937 | I4: =SUMIFS('conditional forecasts_8'!J$6:J$553,'conditional forecasts_8'!$CW$6:$CW$553,$B4,'conditional forecasts_8'!$B$6:$B$553,"desl") -> 4281.4478 | J4: =SUMIFS('conditional forecasts_8'!K$6:K$553,'conditional forecasts_8'!$CW$6:$CW$553,$B4,'conditional forecasts_8'!$B$6:$B$553,"desl") -> 4355.4509 | ... CT4: =SUMIFS('conditional forecasts_8'!CU$6:CU$553,'conditional forecasts_8'!$CW$6:$CW$553,$B4,'conditional forecasts_8'!$B$6:$B$553,"desl") -> 16661.897
B5: 1100 | C5: =SUMIFS('conditional forecasts_8'!D$6:D$553,'conditional forecasts_8'!$CW$6:$CW$553,$B5,'conditional forecasts_8'!$B$6:$B$553,"desl") -> 0 | D5: =SUMIFS('conditional forecasts_8'!E$6:E$553,'conditional forecasts_8'!$CW$6:$CW$553,$B5,'conditional forecasts_8'!$B$6:$B$553,"desl") -> 0 | E5: =SUMIFS('conditional forecasts_8'!F$6:F$553,'conditional forecasts_8'!$CW$6:$CW$553,$B5,'conditional forecasts_8'!$B$6:$B$553,"desl") -> 0 | F5: =SUMIFS('conditional forecasts_8'!G$6:G$553,'conditional forecasts_8'!$CW$6:$CW$553,$B5,'conditional forecasts_8'!$B$6:$B$553,"desl") -> 0 | G5: =SUMIFS('conditional forecasts_8'!H$6:H$553,'conditional forecasts_8'!$CW$6:$CW$553,$B5,'conditional forecasts_8'!$B$6:$B$553,"desl") -> 0 | H5: =SUMIFS('conditional forecasts_8'!I$6:I$553,'conditional forecasts_8'!$CW$6:$CW$553,$B5,'conditional forecasts_8'!$B$6:$B$553,"desl") -> 0 | I5: =SUMIFS('conditional forecasts_8'!J$6:J$553,'conditional forecasts_8'!$CW$6:$CW$553,$B5,'conditional forecasts_8'!$B$6:$B$553,"desl") -> 0 | J5: =SUMIFS('conditional forecasts_8'!K$6:K$553,'conditional forecasts_8'!$CW$6:$CW$553,$B5,'conditional forecasts_8'!$B$6:$B$553,"desl") -> 0 | ... CT5: =SUMIFS('conditional forecasts_8'!CU$6:CU$553,'conditional forecasts_8'!$CW$6:$CW$553,$B5,'conditional forecasts_8'!$B$6:$B$553,"desl") -> 0
