Workbook

Sheet conditional forecasts_4
A1: GVAR Conditional Forecasts
A2: Last in-sample estimation date: | B2: 2016M12
A3: Last forecast date: | B3: 2024M12
D4: =DATE(LEFT(D5,4),SUBSTITUTE(RIGHT(D5,2),"M",""),1) -> 42736 | E4: =DATE(LEFT(E5,4),SUBSTITUTE(RIGHT(E5,2),"M",""),1) -> 42767 | F4: =DATE(LEFT(F5,4),SUBSTITUTE(RIGHT(F5,2),"M",""),1) -> 42795 | G4: =DATE(LEFT(G5,4),SUBSTITUTE(RIGHT(G5,2),"M",""),1) -> 42826 | H4: =DATE(LEFT(H5,4),SUBSTITUTE(RIGHT(H5,2),"M",""),1) -> 42856 | I4: =DATE(LEFT(I5,4),SUBSTITUTE(RIGHT(I5,2),"M",""),1) -> 42887 | J4: =DATE(LEFT(J5,4),SUBSTITUTE(RIGHT(J5,2),"M",""),1) -> 42917 | K4: =DATE(LEFT(K5,4),SUBSTITUTE(RIGHT(K5,2),"M",""),1) -> 42948 | ... CU4: =DATE(LEFT(CU5,4),SUBSTITUTE(RIGHT(CU5,2),"M",""),1) -> 45627
D5: 2017M1 | E5: 2017M2 | F5: 2017M3 | G5: 2017M4 | H5: 2017M5 | I5: 2017M6 | J5: 2017M7 | K5: 2017M8 | L5: 2017M9 | M5: 2017M10 | N5: 2017M11 | O5: 2017M12 | P5: 2018M1 | Q5: 2018M2 | R5: 2018M3 | S5: 2018M4 | T5: 2018M5 | U5: 2018M6 | V5: 2018M7 | W5: 2018M8 | X5: 2018M9 | Y5: 2018M10 | Z5: 2018M11 | AA5: 2018M12 | AB5: 2019M1 | AC5: 2019M2 | AD5: 2019M3 | AE5: 2019M4 | AF5: 2019M5 | AG5: 2019M6 | AH5: 2019M7 | AI5: 2019M8 | AJ5: 2019M9 | AK5: 2019M10 | AL5: 2019M11 | AM5: 2019M12 | AN5: 2020M1 | AO5: 2020M2 | AP5: 2020M3 | AQ5: 2020M4 | AR5: 2020M5 | AS5: 2020M6 | AT5: 2020M7 | AU5: 2020M8 | AV5: 2020M9 | AW5: 2020M10 | AX5: 2020M11 | AY5: 2020M12 | AZ5: 2021M1 | BA5: 2021M2 | BB5: 2021M3 | BC5: 2021M4 | BD5: 2021M5 | BE5: 2021M6 | BF5: 2021M7 | BG5: 2021M8 | BH5: 2021M9 | BI5: 2021M10 | BJ5: 2021M11 | BK5: 2021M12 | BL5: 2022M1 | BM5: 2022M2 | BN5: 2022M3 | BO5: 2022M4 | BP5: 2022M5 | BQ5: 2022M6 | BR5: 2022M7 | BS5: 2022M8 | BT5: 2022M9 | BU5: 2022M10 | BV5: 2022M11 | BW5: 2022M12 | BX5: 2023M1 | BY5: 2023M2 | BZ5: 2023M3 | CA5: 2023M4 | CB5: 2023M5 | CC5: 2023M6 | CD5: 2023M7 | CE5: 2023M8 | CF5: 2023M9 | CG5: 2023M10 | CH5: 2023M11 | CI5: 2023M12 | CJ5: 2024M1 | CK5: 2024M2 | CL5: 2024M3 | CM5: 2024M4 | CN5: 2024M5 | CO5: 2024M6 | CP5: 2024M7 | CQ5: 2024M8 | CR5: 2024M9 | CS5: 2024M10 | CT5: 2024M11 | CU5: 2024M12 | CV5: Serie | CW5: Meso
A6: Ro1101 | B6: adm | C6: Forecast | D6: 2825.5893 | E6: 3101.2583 | F6: 3682.3295 | G6: 3778.1559 | H6: 3895.3444 | I6: 4095.0617 | J6: 4005.7696 | K6: 4011.3179 | L6: 3802.1037 | M6: 3349.4518 | N6: 3054.3983 | O6: 2447.4152 | P6: 3066.0483 | Q6: 3393.087 | R6: 4069.0224 | S6: 4196.3705 | T6: 4338.0658 | U6: 4516.986 | V6: 4391.6904 | W6: 4361.5762 | X6: 4129.0336 | Y6: 3680.227 | Z6: 3413.1122 | AA6: 2848.1789 | AB6: 3511.4962 | AC6: 3875.1506 | AD6: 4574.0663 | AE6: 4711.0598 | AF6: 4853.1414 | AG6: 5028.5274 | AH6: 4900.3381 | AI6: 4870.6907 | AJ6: 4642.8762 | AK6: 4202.7364 | AL6: 3947.3028 | AM6: 3395.9698 | AN6: 4073.7416 | AO6: 4451.7225 | AP6: 5163.9879 | AQ6: 5312.7487 | AR6: 5464.7726 | AS6: 5648.4528 | AT6: 5527.4426 | AU6: 5504.5761 | AV6: 5283.8245 | AW6: 4851.4893 | AX6: 4604.7537 | AY6: 4062.8784 | AZ6: 4750.5533 | BA6: 5138.5194 | BB6: 5860.552 | BC6: 6018.6842 | BD6: 6179.6336 | BE6: 6371.8363 | BF6: 6259.0333 | BG6: 6244.1471 | BH6: 6031.2137 | BI6: 5606.5701 | BJ6: 5367.4164 | BK6: 4833.0299 | BL6: 5528.1341 | BM6: 5923.5297 | BN6: 6653.0747 | BO6: 6818.8886 | BP6: 6987.749 | BQ6: 7188.0903 | BR6: 7083.5596 | BS6: 7076.8836 | BT6: 6871.8199 | BU6: 6454.4006 | BV6: 6221.5794 | BW6: 5692.5431 | BX6: 6392.1597 | BY6: 6791.6396 | BZ6: 7525.4723 | CA6: 7696.507 | CB6: 7872.157 | CC6: 8081.1849 | CD6: 7987.0813 | CE6: 7991.8584 | CF6: 7798.0582 | CG6: 7390.2163 | CH6: 7163.8009 | CI6: 6636.958 | CJ6: 7334.4744 | CK6: 7728.3331 | CL6: 8455.1889 | CM6: 8622.0901 | CN6: 8798.292 | CO6: 9016.7793 | CP6: 8944.4648 | CQ6: 8970.3811 | CR6: 8822.9592 | CS6: 8433.1566 | CT6: 8183.4914 | CU6: 7830.6053 | CV6: 1 | CW6: 1101
C7: Actual | CV7: 0 | CW7: 0
A8: Ro1101 | B8: desl | C8: Forecast | D8: 3176.4667 | E8: 3195.7408 | F8: 3504.4765 | G8: 3566.9715 | H8: 3860.0017 | I8: 3789.1297 | J8: 3947.532 | K8: 3980.7296 | L8: 3850.9945 | M8: 4010.8214 | N8: 3877.3752 | O8: 3732.2366 | P8: 3635.9394 | Q8: 3574.7262 | R8: 3893.81 | S8: 3914.7687 | T8: 4207.2865 | U8: 4115.2016 | V8: 4247.9128 | W8: 4251.8225 | X8: 4100.0046 | Y8: 4252.8423 | Z8: 4130.6517 | AA8: 4011.6913 | AB8: 3949.4054 | AC8: 3922.2221 | AD8: 4269.6578 | AE8: 4310.8405 | AF8: 4616.2167 | AG8: 4532.271 | AH8: 4671.4605 | AI8: 4682.6038 | AJ8: 4540.113 | AK8: 4704.7352 | AL8: 4596.5355 | AM8: 4493.2305 | AN8: 4447.6238 | AO8: 4437.4889 | AP8: 4801.7194 | AQ8: 4858.9149 | AR8: 5179.1734 | AS8: 5108.8848 | AT8: 5260.677 | AU8: 5283.742 | AV8: 5152.9443 | AW8: 5329.4266 | AX8: 5233.4934 | AY8: 5142.9102 | AZ8: 5110.3679 | BA8: 5113.4362 | BB8: 5490.7927 | BC8: 5560.8675 | BD8: 5893.6646 | BE8: 5835.5518 | BF8: 5999.1861 | BG8: 6033.8118 | BH8: 5914.3471 | BI8: 6101.9775 | BJ8: 6017.038 | BK8: 5937.3169 | BL8: 5915.5286 | BM8: 5929.2733 | BN8: 6317.2667 | BO8: 6397.9803 | BP8: 6741.4493 | BQ8: 6694.0474 | BR8: 6868.3951 | BS8: 6913.6491 | BT8: 6804.593 | BU8: 7002.2525 | BV8: 6926.8172 | BW8: 6855.9944 | BX8: 6842.5302 | BY8: 6864.1966 | BZ8: 7260.0145 | CA8: 7348.8403 | CB8: 7701.0836 | CC8: 7663.3662 | CD8: 7848.3246 | CE8: 7904.8314 | CF8: 7807.0975 | CG8: 8015.3672 | CH8: 7949.0206 | CI8: 7885.1332 | CJ8: 7876.1239 | CK8: 7900.0913 | CL8: 8297.0782 | CM8: 8387.0334 | CN8: 8743.2355 | CO8: 8712.8596 | CP8: 8909.6411 | CQ8: 8988.4242 | CR8: 8905.1556 | CS8: 9133.7397 | CT8: 9116.2113 | CU8: 8968.148 | CV8: -1 | CW8: 1101
C9: Actual | CV9: 0 | CW9: 0
A10: Ro1102 | B10: adm | C10: Forecast | D10: 4626.3708 | E10: 5091.6645 | F10: 5832.3454 | G10: 5783.8094 | H10: 5732.4579 | I10: 5752.2769 | J10: 5410.2786 | K10: 5368.0792 | L10: 5105.313 | M10: 4732.7277 | N10: 4790.4612 | O10: 4302.7018 | P10: 5199.8116 | Q10: 5433.2651 | R10: 6090.9441 | S10: 5986.1007 | T10: 5886.0864 | U10: 5843.3865 | V10: 5453.5291 | W10: 5380.4244 | X10: 5113.3021 | Y10: 4769.8295 | Z10: 4877.3912 | AA10: 4443.4925 | AB10: 5383.9137 | AC10: 5640.9853 | AD10: 6302.4239 | AE10: 6188.3118 | AF10: 6075.123 | AG10: 6022.9549 | AH10: 5631.3935 | AI10: 5564.7168 | AJ10: 5310.1225 | AK10: 4982.4587 | AL10: 5106.6479 | AM10: 4688.5739 | AN10: 5643.1729 | AO10: 5912.4155 | AP10: 6583.9293 | AQ10: 6477.9316 | AR10: 6371.2909 | AS10: 6324.7546 | AT10: 5938.7019 | AU10: 5878.1458 | AV10: 5630.757 | AW10: 5311.4798 | AX10: 5444.9763 | AY10: 5036.6483 | AZ10: 6000.9132 | BA10: 6279.3459 | BB10: 6959.3836 | BC10: 6861.2546 | BD10: 6761.9733 | BE10: 6722.4794 | BF10: 6343.3173 | BG10: 6289.6002 | BH10: 6049.0335 | BI10: 5736.5554 | BJ10: 5876.8142 | BK10: 5475.2176 | BL10: 6446.2213 | BM10: 6731.4647 | BN10: 7418.4554 | BO10: 7327.467 | BP10: 7235.5009 | BQ10: 7203.3992 | BR10: 6831.5165 | BS10: 6784.7033 | BT10: 6550.3809 | BU10: 6243.2653 | BV10: 6387.9415 | BW10: 5989.9956 | BX10: 6964.3339 | BY10: 7253.268 | BZ10: 7945.0545 | CA10: 7860.5743 | CB10: 7777.0549 | CC10: 7755.0075 | CD10: 7393.8611 | CE10: 7357.102 | CF10: 7130.6499 | CG10: 6827.9814 | CH10: 6973.0189 | CI10: 6571.596 | CJ10: 7539.8898 | CK10: 7822.2199 | CL10: 8509.6541 | CM10: 8427.1021 | CN10: 8352.1092 | CO10: 8349.0364 | CP10: 8017.0807 | CQ10: 8009.1716 | CR10: 7822.2017 | CS10: 7522.0378 | CT10: 7609.0297 | CU10: 7360.9872 | CV10: 1 | CW10: 1102
C11: Actual | CV11: 0 | CW11: 0
A12: Ro1102 | B12: desl | C12: Forecast | D12: 5091.5863 | E12: 5086.7267 | F12: 5628.7039 | G12: 5277.8379 | H12: 5535.1614 | I12: 5065.7142 | J12: 5120.8829 | K12: 5307.2963 | L12: 4837.4561 | M12: 5512.366 | N12: 5596.2241 | O12: 5400.4178 | P12: 5398.2953 | Q12: 5159.3899 | R12: 5722.5356 | S12: 5320.576 | T12: 5537.4502 | U12: 5056.3414 | V12: 5090.0909 | W12: 5270.7322 | X12: 4813.1606 | Y12: 5513.8184 | Z12: 5631.2875 | AA12: 5466.5102 | AB12: 5485.6045 | AC12: 5256.8267 | AD12: 5822.2572 | AE12: 5419.9088 | AF12: 5638.3525 | AG12: 5163.2614 | AH12: 5207.6034 | AI12: 5402.0348 | AJ12: 4959.6308 | AK12: 5675.3708 | AL12: 5807.082 | AM12: 5655.5313 | AN12: 5686.9153 | AO12: 5469.5863 | AP12: 6045.677 | AQ12: 5653.2711 | AR12: 5881.1127 | AS12: 5415.1678 | AT12: 5468.7449 | AU12: 5672.7748 | AV12: 5240.4476 | AW12: 5966.6698 | AX12: 6109.0555 | AY12: 5968.1116 | AZ12: 6009.8197 | BA12: 5802.4176 | BB12: 6388.0303 | BC12: 6004.8084 | BD12: 6241.5904 | BE12: 5784.4241 | BF12: 5846.6686 | BG12: 6059.2759 | BH12: 5635.4429 | BI12: 6370.0855 | BJ12: 6520.8395 | BK12: 6388.2454 | BL12: 6438.3202 | BM12: 6239.3237 | BN12: 6833.3743 | BO12: 6458.5774 | BP12: 6703.6857 | BQ12: 6254.628 | BR12: 6324.6319 | BS12: 6544.5359 | BT12: 6127.4801 | BU12: 6868.4202 | BV12: 7025.155 | BW12: 6898.5099 | BX12: 6954.8653 | BY12: 6762.8348 | BZ12: 7364.7618 | CA12: 6998.7263 | CB12: 7253.1346 | CC12: 6813.2689 | CD12: 6891.5474 | CE12: 7118.0454 | CF12: 6705.4525 | CG12: 7448.7372 | CH12: 7606.3034 | CI12: 7480.0853 | CJ12: 7537.6512 | CK12: 7348.9514 | CL12: 7958.0653 | CM12: 7601.9543 | CN12: 7871.5231 | CO12: 7449.352 | CP12: 7542.409 | CQ12: 7795.952 | CR12: 7377.4345 | CS12: 8090.7194 | CT12: 8363.1788 | CU12: 7901.6318 | CV12: -1 | CW12: 1102
C13: Actual | CV13: 0 | CW13: 0
A14: Ac1201 | B14: adm | C14: Forecast | D14: 123.37411 | E14: 126.37728 | F14: 171.90629 | G14: 202.49704 | H14: 225.21623 | I14: 241.6723 | J14: 225.40562 | K14: 214.64485 | L14: 193.80928 | M14: 163.04864 | N14: 151.27533 | O14: 123.84906 | P14: 147.76367 | Q14: 151.19886 | R14: 186.28378 | S14: 213.74445 | T14: 234.95663 | U14: 248.316 | V14: 227.731 | W14: 211.40802 | X14: 185.55259 | Y14: 152.06782 | Z14: 140.62934 | AA14: 116.50159 | AB14: 145.50132 | AC14: 154.22631 | AD14: 193.49282 | AE14: 223.31524 | AF14: 245.06318 | AG14: 257.66444 | AH14: 235.77011 | AI14: 218.24683 | AJ14: 191.71436 | AK14: 158.2168 | AL14: 147.36566 | AM14: 124.2554 | AN14: 154.50654 | AO14: 164.53933 | AP14: 205.02917 | AQ14: 235.89142 | AR14: 258.44195 | AS14: 271.60364 | AT14: 250.07013 | AU14: 232.78681 | AV14: 206.46747 | AW14: 173.2405 | AX14: 162.77144 | AY14: 140.16905 | AZ14: 171.03202 | BA14: 181.73614 | BB14: 222.90687 | BC14: 254.41882 | BD14: 277.56447 | BE14: 291.26144 | BF14: 270.21167 | BG14: 253.3754 | BH14: 227.48148 | BI14: 194.6696 | BJ14: 184.61172 | BK14: 162.41939 | BL14: 193.69288 | BM14: 204.81068 | BN14: 246.40341 | BO14: 278.35309 | BP14: 301.95974 | BQ14: 316.1454 | BR14: 295.60941 | BS14: 279.29951 | BT14: 253.92145 | BU14: 221.58404 | BV14: 211.92733 | BW14: 190.03957 | BX14: 221.51681 | BY14: 232.76029 | BZ14: 274.45222 | CA14: 306.54812 | CB14: 330.42751 | CC14: 345.07552 | CD14: 325.21475 | CE14: 309.75981 | CF14: 285.32168 | CG14: 253.86493 | CH14: 244.86075 | CI14: 223.24918 | CJ14: 254.53747 | CK14: 265.13932 | CL14: 305.86849 | CM14: 336.98564 | CN14: 360.13998 | CO14: 374.8073 | CP14: 355.93365 | CQ14: 342.53156 | CR14: 321.2322 | CS14: 292.93799 | CT14: 283.93196 | CU14: 272.11767 | CV14: 1 | CW14: 1201
C15: Actual | CV15: 0 | CW15: 0
A16: Ac1201 | B16: desl | C16: Forecast | D16: 193.47965 | E16: 158.79748 | F16: 157.11027 | G16: 145.79736 | H16: 161.55703 | I16: 158.13603 | J16: 175.12194 | K16: 186.71331 | L16: 180.56866 | M16: 213.13048 | N16: 216.10033 | O16: 213.94957 | P16: 202.15628 | Q16: 176.22767 | R16: 170.08492 | S16: 151.54993 | T16: 166.08329 | U16: 162.6293 | V16: 180.28743 | W16: 192.83278 | X16: 186.58095 | Y16: 218.03612 | Z16: 219.49356 | AA16: 216.14012 | AB16: 203.92904 | AC16: 178.45767 | AD16: 173.44063 | AE16: 156.34122 | AF16: 172.28633 | AG16: 170.02263 | AH16: 188.60308 | AI16: 201.85961 | AJ16: 196.19838 | AK16: 228.19736 | AL16: 230.19262 | AM16: 227.3881 | AN16: 215.7471 | AO16: 190.87964 | AP16: 186.5138 | AQ16: 170.11872 | AR16: 186.81261 | AS16: 185.31891 | AT16: 204.66008 | AU16: 218.64098 | AV16: 213.65298 | AW16: 246.27467 | AX16: 248.85519 | AY16: 246.61717 | AZ16: 235.54099 | BA16: 211.24726 | BB16: 207.46683 | BC16: 191.66538 | BD16: 208.95458 | BE16: 208.05129 | BF16: 227.97337 | BG16: 242.5238 | BH16: 238.09439 | BI16: 271.2655 | BJ16: 274.38834 | BK16: 272.68687 | BL16: 262.14145 | BM16: 238.37115 | BN16: 235.10398 | BO16: 219.80233 | BP16: 237.57531 | BQ16: 237.13935 | BR16: 257.51507 | BS16: 272.51174 | BT16: 268.53019 | BU16: 302.16057 | BV16: 305.76162 | BW16: 304.55934 | BX16: 294.52835 | BY16: 271.27349 | BZ16: 268.50209 | CA16: 253.65378 | CB16: 271.81944 | CC16: 271.7085 | CD16: 292.35069 | CE16: 307.58128 | CF16: 303.84104 | CG16: 337.76571 | CH16: 341.75824 | CI16: 341.07316 | CJ16: 331.67555 | CK16: 309.14646 | CL16: 307.12473 | CM16: 292.88348 | CN16: 311.54301 | CO16: 311.56229 | CP16: 331.86776 | CQ16: 347.13617 | CR16: 341.63675 | CS16: 375.97545 | CT16: 383.50523 | CU16: 371.34175 | CV16: -1 | CW16: 1201
C17: Actual | CV17: 0 | CW17: 0
A18: Ac1202 | B18: adm | C18: Forecast | D18: 1499.8732 | E18: 1616.3859 | F18: 1828.2258 | G18: 1869.129 | H18: 1864.3748 | I18: 1889.3188 | J18: 1819.8285 | K18: 1808.5062 | L18: 1722.6622 | M18: 1597.7641 | N18: 1589.3109 | O18: 1369.924 | P18: 1608.8938 | Q18: 1709.1285 | R18: 1937.5255 | S18: 1945.2645 | T18: 1932.4929 | U18: 1939.1126 | V18: 1855.6874 | W18: 1835.699 | X18: 1745.2245 | Y18: 1624.7047 | Z18: 1626.9086 | AA18: 1421.5646 | AB18: 1674.9756 | AC18: 1786.6588 | AD18: 2021.8228 | AE18: 2031.8261 | AF18: 2018.2344 | AG18: 2022.9174 | AH18: 1938.2033 | AI18: 1918.636 | AJ18: 1830.5652 | AK18: 1714.1108 | AL18: 1721.4184 | AM18: 1521.5613 | AN18: 1780.3199 | AO18: 1896.8699 | AP18: 2136.25 | AQ18: 2149.7895 | AR18: 2139.1376 | AS18: 2146.3304 | AT18: 2063.9134 | AU18: 2046.6525 | AV18: 1961.0776 | AW18: 1847.4083 | AX18: 1857.7956 | AY18: 1661.2368 | AZ18: 1923.3892 | BA18: 2043.3003 | BB18: 2285.9099 | BC18: 2302.4966 | BD18: 2294.7058 | BE18: 2304.6046 | BF18: 2224.7836 | BG18: 2210.0527 | BH18: 2126.9741 | BI18: 2015.7866 | BJ18: 2028.6511 | BK18: 1834.5717 | BL18: 2099.2137 | BM18: 2221.6359 | BN18: 2466.7893 | BO18: 2485.9579 | BP18: 2480.78 | BQ18: 2493.297 | BR18: 2416.0535 | BS18: 2403.7969 | BT18: 2323.0225 | BU18: 2213.9154 | BV18: 2228.6184 | BW18: 2036.1714 | BX18: 2302.34 | BY18: 2426.3381 | BZ18: 2673.2989 | CA18: 2694.6664 | CB18: 2692.1581 | CC18: 2707.7647 | CD18: 2633.8291 | CE18: 2624.7742 | CF18: 2546.7085 | CG18: 2439.4711 | CH18: 2454.9934 | CI18: 2262.3574 | CJ18: 2527.6168 | CK18: 2650.5248 | CL18: 2896.8377 | CM18: 2919.0928 | CN18: 2919.0079 | CO18: 2939.3902 | CP18: 2872.5743 | CQ18: 2871.611 | CR18: 2800.8439 | CS18: 2701.3921 | CT18: 2696.8242 | CU18: 2548.181 | CV18: 1 | CW18: 1202
C19: Actual | CV19: 0 | CW19: 0
A20: Ac1202 | B20: desl | C20: Forecast | D20: 1766.6444 | E20: 1683.7622 | F20: 1824.8577 | G20: 1663.9323 | H20: 1826.5158 | I20: 1649.6846 | J20: 1686.3847 | K20: 1753.6265 | L20: 1607.4582 | M20: 1911.1752 | N20: 1936.5825 | O20: 1979.194 | P20: 1928.8274 | Q20: 1740.5164 | R20: 1865.2027 | S20: 1691.2437 | T20: 1834.9729 | U20: 1654.8827 | V20: 1684.573 | W20: 1750.0804 | X20: 1608.2787 | Y20: 1919.6901 | Z20: 1955.726 | AA20: 2008.8099 | AB20: 1966.4138 | AC20: 1783.1374 | AD20: 1910.5636 | AE20: 1738.2846 | AF20: 1883.8677 | AG20: 1706.5345 | AH20: 1740.032 | AI20: 1810.1698 | AJ20: 1673.456 | AK20: 1990.0868 | AL20: 2031.2791 | AM20: 2089.3709 | AN20: 2051.7915 | AO20: 1873.1016 | AP20: 2004.8471 | AQ20: 1836.6104 | AR20: 1985.9992 | AS20: 1812.3249 | AT20: 1849.4476 | AU20: 1923.2755 | AV20: 1790.3701 | AW20: 2110.9253 | AX20: 2156.1103 | AY20: 2218.1951 | AZ20: 2184.5463 | BA20: 2009.6843 | BB20: 2145.1414 | BC20: 1980.5068 | BD20: 2133.4042 | BE20: 1963.1616 | BF20: 2003.6508 | BG20: 2080.7877 | BH20: 1951.1409 | BI20: 2274.9146 | BJ20: 2323.2937 | BK20: 2388.5671 | BL20: 2358.12 | BM20: 2186.4848 | BN20: 2325.1932 | BO20: 2163.8168 | BP20: 2319.9445 | BQ20: 2152.8543 | BR20: 2196.3618 | BS20: 2276.333 | BT20: 2149.3088 | BU20: 2475.5045 | BV20: 2526.1662 | BW20: 2593.6944 | BX20: 2565.6201 | BY20: 2396.6212 | BZ20: 2538.3277 | CA20: 2380.3143 | CB20: 2540.0471 | CC20: 2376.56 | CD20: 2423.351 | CE20: 2505.9726 | CF20: 2380.7626 | CG20: 2707.9073 | CH20: 2758.8524 | CI20: 2826.4144 | CJ20: 2798.6093 | CK20: 2630.6314 | CL20: 2774.9249 | CM20: 2620.6524 | CN20: 2786.2484 | CO20: 2630.077 | CP20: 2682.4394 | CQ20: 2775.5686 | CR20: 2651.6346 | CS20: 2959.9103 | CT20: 3065.1145 | CU20: 2997.6689 | CV20: -1 | CW20: 1202
C21: Actual | CV21: 0 | CW21: 0
A22: Am1301 | B22: adm | C22: Forecast | D22: 25.057669 | E22: 21.335398 | F22: 25.754117 | G22: 19.667795 | H22: 17.841272 | I22: 24.35841 | J22: 13.166062 | K22: 16.208252 | L22: 18.926433 | M22: 8.1661972 | N22: 19.416697 | O22: 16.384902 | P22: 36.35954 | Q22: 23.81884 | R22: 24.101609 | S22: 18.980245 | T22: 15.942087 | U22: 22.171723 | V22: 11.375473 | W22: 14.135985 | X22: 16.804332 | Y22: 6.0285622 | Z22: 17.257883 | AA22: 14.313449 | AB22: 34.41718 | AC22: 21.987815 | AD22: 22.342289 | AE22: 17.246346 | AF22: 14.196645 | AG22: 20.39893 | AH22: 9.5796831 | AI22: 12.332357 | AJ22: 15.010611 | AK22: 4.2586003 | AL22: 15.518583 | AM22: 12.606195 | AN22: 32.740538 | AO22: 20.339345 | AP22: 20.719341 | AQ22: 15.646069 | AR22: 12.615824 | AS22: 18.83424 | AT22: 8.0283474 | AU22: 10.792834 | AV22: 13.482961 | AW22: 2.7443124 | AX22: 14.019927 | AY22: 11.125385 | AZ22: 31.279065 | BA22: 18.897675 | BB22: 19.297019 | BC22: 14.242064 | BD22: 11.228933 | BE22: 17.463385 | BF22: 6.6726901 | BG22: 9.4517506 | BH22: 12.155944 | BI22: 1.4308911 | BJ22: 12.719655 | BK22: 9.8379135 | BL22: 30.004271 | BM22: 17.635807 | BN22: 18.048777 | BO22: 13.008579 | BP22: 10.011575 | BQ22: 16.263388 | BR22: 5.4906612 | BS22: 8.2871743 | BT22: 11.006879 | BU22: 0.29404925 | BV22: 11.590983 | BW22: 8.7136199 | BX22: 28.882045 | BY22: 16.51582 | BZ22: 16.934091 | CA22: 11.904772 | CB22: 8.9256097 | CC22: 15.201988 | CD22: 4.4585452 | CE22: 7.2858592 | CF22: 10.033563 | CG22: -0.65859123 | CH22: 10.645801 | CI22: 7.7585085 | CJ22: 27.901302 | CK22: 15.490368 | CL22: 15.854148 | CM22: 10.811971 | CN22: 7.8082477 | CO22: 14.168322 | CP22: 3.5492094 | CQ22: 6.2304414 | CR22: 9.6923501 | CS22: -1.553982 | CT22: 7.5747494 | CU22: 12.700656 | CV22: 1 | CW22: 1301
C23: Actual | CV23: 0 | CW23: 0
A24: Am1301 | B24: desl | C24: Forecast | D24: 24.918337 | E24: 27.485703 | F24: 19.805134 | G24: 20.962994 | H24: 22.155499 | I24: 13.652888 | J24: 17.448986 | K24: 16.743325 | L24: 14.110511 | M24: 27.183702 | N24: 25.946476 | O24: 39.776559 | P24: 22.479494 | Q24: 24.581742 | R24: 17.562879 | S24: 17.86794 | T24: 18.890987 | U24: 10.774709 | V24: 14.386685 | W24: 13.892124 | X24: 11.468032 | Y24: 24.597271 | Z24: 23.36656 | AA24: 37.122833 | AB24: 19.707699 | AC24: 21.718861 | AD24: 14.665884 | AE24: 14.991508 | AF24: 16.068853 | AG24: 8.0126208 | AH24: 11.669113 | AI24: 11.196941 | AJ24: 8.7774401 | AK24: 21.902331 | AL24: 20.66656 | AM24: 34.421097 | AN24: 17.007417 | AO24: 19.021427 | AP24: 11.971417 | AQ24: 12.300248 | AR24: 13.382209 | AS24: 5.3330924 | AT24: 8.9992866 | AU24: 8.5383159 | AV24: 6.1297851 | AW24: 19.263859 | AX24: 18.034753 | AY24: 31.793706 | AZ24: 14.383178 | BA24: 16.400247 | BB24: 9.3540657 | BC24: 9.6878068 | BD24: 10.775544 | BE24: 2.7325561 | BF24: 6.4046958 | BG24: 5.9491451 | BH24: 3.5454509 | BI24: 16.68398 | BJ24: 15.459309 | BK24: 29.22307 | BL24: 11.818031 | BM24: 13.841386 | BN24: 6.8021559 | BO24: 7.1431004 | BP24: 8.237638 | BQ24: 0.20026418 | BR24: 3.8761144 | BS24: 3.421982 | BT24: 1.0176052 | BU24: 14.15427 | BV24: 12.928149 | BW24: 26.692839 | BX24: 9.2928883 | BY24: 11.326433 | BZ24: 4.3020455 | CA24: 4.6604257 | CB24: 5.7716607 | CC24: -2.2535685 | CD24: 1.4266878 | CE24: 0.96723683 | CF24: -1.4517296 | CG24: 11.663121 | CH24: 10.413081 | CI24: 24.158718 | CJ24: 6.7483888 | CK24: 8.78495 | CL24: 1.8010952 | CM24: 2.1984129 | CN24: 3.4167241 | CO24: -4.5342414 | CP24: -0.88190829 | CQ24: -1.0963565 | CR24: -3.8422541 | CS24: 8.358681 | CT24: 10.686386 | CU24: 16.239154 | CV24: -1 | CW24: 1301
C25: Actual | CV25: 0 | CW25: 0
A26: Am1302 | B26: adm | C26: Forecast | D26: 25.708676 | E26: 24.315895 | F26: 28.478181 | G26: 28.092005 | H26: 27.775274 | I26: 29.978109 | J26: 26.643056 | K26: 27.643738 | L26: 27.534534 | M26: 22.82442 | N26: 25.130772 | O26: 21.391571 | P26: 27.652405 | Q26: 26.292618 | R26: 29.771124 | S26: 29.678163 | T26: 29.129445 | U26: 31.088573 | V26: 27.600481 | W26: 28.334356 | X26: 28.115702 | Y26: 23.498052 | Z26: 26.057385 | AA26: 22.663462 | AB26: 29.249918 | AC26: 28.109752 | AD26: 31.676607 | AE26: 31.56858 | AF26: 30.95726 | AG26: 32.86174 | AH26: 29.361504 | AI26: 30.133776 | AJ26: 29.993173 | AK26: 25.474971 | AL26: 28.138912 | AM26: 24.845019 | AN26: 31.523148 | AO26: 30.465567 | AP26: 34.10583 | AQ26: 34.061838 | AR26: 33.505513 | AS26: 35.457736 | AT26: 32.001452 | AU26: 32.818203 | AV26: 32.726375 | AW26: 28.263221 | AX26: 30.988185 | AY26: 27.759123 | AZ26: 34.50288 | BA26: 33.508991 | BB26: 37.209329 | BC26: 37.221386 | BD26: 36.717679 | BE26: 38.720175 | BF26: 35.312885 | BG26: 36.178092 | BH26: 36.134518 | BI26: 31.71946 | BJ26: 34.49229 | BK26: 31.310842 | BL26: 38.102073 | BM26: 37.155754 | BN26: 40.90403 | BO26: 40.96458 | BP26: 40.509885 | BQ26: 42.561552 | BR26: 39.202867 | BS26: 40.115069 | BT26: 40.115692 | BU26: 35.740986 | BV26: 38.549799 | BW26: 35.400361 | BX26: 42.221181 | BY26: 41.304713 | BZ26: 45.086473 | CA26: 45.187342 | CB26: 44.781686 | CC26: 46.890588 | CD26: 43.593864 | CE26: 44.566749 | CF26: 44.619438 | CG26: 40.281738 | CH26: 43.108508 | CI26: 39.958399 | CJ26: 46.767187 | CK26: 45.832843 | CL26: 49.602277 | CM26: 49.72108 | CN26: 49.343015 | CO26: 51.534956 | CP26: 48.387955 | CQ26: 49.390123 | CR26: 49.911254 | CS26: 45.363595 | CT26: 47.593547 | CU26: 46.906741 | CV26: 1 | CW26: 1302
C27: Actual | CV27: 0 | CW27: 0
A28: Am1302 | B28: desl | C28: Forecast | D28: 30.945641 | E28: 26.414724 | F28: 28.774995 | G28: 26.221877 | H28: 27.741506 | I28: 28.206216 | J28: 28.424196 | K28: 30.238549 | L28: 32.032511 | M28: 31.084393 | N28: 30.925754 | O28: 27.458701 | P28: 29.311958 | Q28: 25.495982 | R28: 28.376774 | S28: 25.982689 | T28: 27.54243 | U28: 28.325196 | V28: 28.597081 | W28: 30.340722 | X28: 32.085508 | Y28: 31.057008 | Z28: 30.829243 | AA28: 27.338235 | AB28: 29.206168 | AC28: 25.436091 | AD28: 28.384636 | AE28: 26.067287 | AF28: 27.703159 | AG28: 28.555981 | AH28: 28.888287 | AI28: 30.680551 | AJ28: 32.461688 | AK28: 31.458887 | AL28: 31.25009 | AM28: 27.776475 | AN28: 29.664969 | AO28: 25.921766 | AP28: 28.904451 | AQ28: 26.627267 | AR28: 28.306615 | AS28: 29.20311 | AT28: 29.576753 | AU28: 31.406621 | AV28: 33.221434 | AW28: 32.249098 | AX28: 32.068729 | AY28: 28.622706 | AZ28: 30.53889 | BA28: 26.824013 | BB28: 29.835813 | BC28: 27.588403 | BD28: 29.297891 | BE28: 30.224566 | BF28: 30.62815 | BG28: 32.487541 | BH28: 34.33139 | BI28: 33.387608 | BJ28: 33.235336 | BK28: 29.816931 | BL28: 31.760141 | BM28: 28.071482 | BN28: 31.108433 | BO28: 28.8849 | BP28: 30.616983 | BQ28: 31.565274 | BR28: 31.990162 | BS28: 33.871502 | BT28: 35.738956 | BU28: 34.821167 | BV28: 34.697359 | BW28: 31.309092 | BX28: 33.28244 | BY28: 29.621702 | BZ28: 32.682182 | CA28: 30.476352 | CB28: 32.22021 | CC28: 33.175737 | CD28: 33.606023 | CE28: 35.4944 | CF28: 37.374484 | CG28: 36.478083 | CH28: 36.387032 | CI28: 33.042994 | CJ28: 35.072098 | CK28: 31.466879 | CL28: 34.579334 | CM28: 32.410904 | CN28: 34.160125 | CO28: 35.059621 | CP28: 35.467516 | CQ28: 37.177024 | CR28: 39.283864 | CS28: 38.038224 | CT28: 37.427703 | CU28: 36.104263 | CV28: -1 | CW28: 1302
C29: Actual | CV29: 0 | CW29: 0
A30: Am1303 | B30: adm | C30: Forecast | D30: 10126.067 | E30: 10698.564 | F30: 12695.821 | G30: 12669.033 | H30: 12653.724 | I30: 13265.739 | J30: 12684.63 | K30: 13179.848 | L30: 12904.34 | M30: 11726.46 | N30: 11556.343 | O30: 9000.7356 | P30: 11036.452 | Q30: 11581.162 | R30: 13843.914 | S30: 13912.392 | T30: 13834.81 | U30: 14314.395 | V30: 13624.622 | W30: 14086.267 | X30: 13874.042 | Y30: 12848.605 | Z30: 12856.141 | AA30: 10440.645 | AB30: 12545.185 | AC30: 13082.805 | AD30: 15285.346 | AE30: 15276.716 | AF30: 15136.314 | AG30: 15583.771 | AH30: 14893.628 | AI30: 15377.617 | AJ30: 15198.479 | AK30: 14207.24 | AL30: 14244.61 | AM30: 11852.592 | AN30: 13974.113 | AO30: 14522.599 | AP30: 16730.412 | AQ30: 16722.415 | AR30: 16579.742 | AS30: 17024.43 | AT30: 16333.512 | AU30: 16820.519 | AV30: 16648.738 | AW30: 15668.43 | AX30: 15718.634 | AY30: 13339.463 | AZ30: 15472.362 | BA30: 16030.039 | BB30: 18244.919 | BC30: 18242.464 | BD30: 18104.587 | BE30: 18553.985 | BF30: 17868.067 | BG30: 18360.443 | BH30: 18194.282 | BI30: 17219.666 | BJ30: 17275.52 | BK30: 14901.978 | BL30: 17040.642 | BM30: 17604.466 | BN30: 19826.118 | BO30: 19831.188 | BP30: 19701.503 | BQ30: 20159.39 | BR30: 19481.607 | BS30: 19980.921 | BT30: 19819.661 | BU30: 18847.338 | BV30: 18902.879 | BW30: 16527.207 | BX30: 18663.546 | BY30: 19227.064 | BZ30: 21452.701 | CA30: 21467.654 | CB30: 21353.945 | CC30: 21832.218 | CD30: 21175.719 | CE30: 21692.586 | CF30: 21540.561 | CG30: 20565.963 | CH30: 20606.819 | CI30: 18206.196 | CJ30: 20312.72 | CK30: 20848.035 | CL30: 23056.088 | CM30: 23076.571 | CN30: 22988.335 | CO30: 23523.378 | CP30: 22956.635 | CQ30: 23542.728 | CR30: 23530.216 | CS30: 22515.493 | CT30: 22299.644 | CU30: 20488.506 | CV30: 1 | CW30: 1303
C31: Actual | CV31: 0 | CW31: 0
A32: Am1303 | B32: desl | C32: Forecast | D32: 12272.658 | E32: 12371.878 | F32: 13485.689 | G32: 12920.26 | H32: 13726.331 | I32: 12251.542 | J32: 12473.626 | K32: 12984.452 | L32: 11845.181 | M32: 14112.628 | N32: 14668.641 | O32: 14694.802 | P32: 13869.785 | Q32: 12990.437 | R32: 14106.858 | S32: 13298.321 | T32: 14003.348 | U32: 12491.108 | V32: 12621.189 | W32: 13099.78 | X32: 12000.381 | Y32: 14372.584 | Z32: 15071.18 | AA32: 15229.734 | AB32: 14491.454 | AC32: 13642.99 | AD32: 14746.768 | AE32: 13905.88 | AF32: 14582.473 | AG32: 13060.604 | AH32: 13203.493 | AI32: 13712.689 | AJ32: 12653.546 | AK32: 15068.155 | AL32: 15806.672 | AM32: 16000.83 | AN32: 15293.573 | AO32: 14471.767 | AP32: 15598.096 | AQ32: 14776.105 | AR32: 15468.887 | AS32: 13962.011 | AT32: 14120.457 | AU32: 14647.249 | AV32: 13608.462 | AW32: 16045.969 | AX32: 16808.958 | AY32: 17027.868 | AZ32: 16344.494 | BA32: 15545.007 | BB32: 16691.942 | BC32: 15889.115 | BD32: 16600.09 | BE32: 15110.897 | BF32: 15286.828 | BG32: 15831.054 | BH32: 14809.675 | BI32: 17264.554 | BJ32: 18044.898 | BK32: 18281.222 | BL32: 17615.443 | BM32: 16833.851 | BN32: 17999.034 | BO32: 17214.732 | BP32: 17944.274 | BQ32: 16473.279 | BR32: 16666.504 | BS32: 17226.557 | BT32: 16219.109 | BU32: 18685.914 | BV32: 19476.56 | BW32: 19722.514 | BX32: 19067.122 | BY32: 18298.291 | BZ32: 19479.939 | CA32: 18716.307 | CB32: 19469.963 | CC32: 18024.408 | CD32: 18241.283 | CE32: 18819.814 | CF32: 17823.055 | CG32: 20291.646 | CH32: 21076.287 | CI32: 21311.796 | CJ32: 20645.632 | CK32: 19871.408 | CL32: 21060.99 | CM32: 20317.065 | CN32: 21112.496 | CO32: 19725.454 | CP32: 19999.304 | CQ32: 20690.075 | CR32: 19677.723 | CS32: 22065.318 | CT32: 23255.832 | CU32: 22316.531 | CV32: -1 | CW32: 1303
C33: Actual | CV33: 0 | CW33: 0
A34: Am1304 | B34: adm | C34: Forecast | D34: 87.719224 | E34: 88.106625 | F34: 100.02389 | G34: 90.726183 | H34: 88.447943 | I34: 88.026827 | J34: 81.379997 | K34: 82.287049 | L34: 76.817707 | M34: 71.793676 | N34: 75.069914 | O34: 62.879379 | P34: 87.630105 | Q34: 88.383717 | R34: 102.10639 | S34: 93.161714 | T34: 90.18392 | U34: 88.663735 | V34: 81.38605 | W34: 81.930038 | X34: 76.475972 | Y34: 71.88117 | Z34: 75.735027 | AA34: 64.08363 | AB34: 89.221912 | AC34: 90.15707 | AD34: 103.89784 | AE34: 94.905157 | AF34: 91.904224 | AG34: 90.441295 | AH34: 83.315346 | AI34: 84.088065 | AJ34: 78.909525 | AK34: 74.608856 | AL34: 78.755399 | AM34: 67.383788 | AN34: 92.783309 | AO34: 93.958274 | AP34: 107.91651 | AQ34: 99.120846 | AR34: 96.301839 | AS34: 95.013866 | AT34: 88.064712 | AU34: 89.022945 | AV34: 84.041661 | AW34: 79.948716 | AX34: 84.308966 | AY34: 73.151313 | AZ34: 98.760042 | BA34: 100.13648 | BB34: 114.28775 | BC34: 105.67772 | BD34: 103.03883 | BE34: 101.92724 | BF34: 95.151956 | BG34: 96.282067 | BH34: 91.470742 | BI34: 87.545816 | BJ34: 92.072349 | BK34: 81.07983 | BL34: 106.85347 | BM34: 108.39562 | BN34: 122.71416 | BO34: 114.27303 | BP34: 111.80368 | BQ34: 110.8601 | BR34: 104.24805 | BS34: 105.53288 | BT34: 100.86448 | BU34: 97.069139 | BV34: 101.71326 | BW34: 90.831217 | BX34: 116.71628 | BY34: 118.38046 | BZ34: 132.84029 | CA34: 124.5643 | CB34: 122.28183 | CC34: 121.53711 | CD34: 115.11967 | CE34: 116.57598 | CF34: 112.03859 | CG34: 108.32305 | CH34: 112.99378 | CI34: 102.09633 | CJ34: 127.94751 | CK34: 129.59402 | CL34: 144.08582 | CM34: 135.95822 | CN34: 133.91752 | CO34: 133.54435 | CP34: 127.63738 | CQ34: 129.51032 | CR34: 125.28653 | CS34: 121.66462 | CT34: 124.37699 | CU34: 117.20398 | CV34: 1 | CW34: 1304
C35: Actual | CV35: 0 | CW35: 0
A36: Am1304 | B36: desl | C36: Forecast | D36: 86.590137 | E36: 78.356262 | F36: 79.022544 | G36: 77.61528 | H36: 77.707643 | I36: 71.713457 | J36: 71.135162 | K36: 71.823377 | L36: 70.491487 | M36: 79.290253 | N36: 82.473074 | O36: 85.59363 | P36: 80.145796 | Q36: 78.917554 | R36: 80.294797 | S36: 78.468438 | T36: 77.334823 | U36: 70.882519 | V36: 69.758907 | W36: 70.194402 | X36: 68.963026 | Y36: 78.043905 | Z36: 81.650833 | AA36: 85.213747 | AB36: 80.114898 | AC36: 79.110683 | AD36: 80.605125 | AE36: 78.839931 | AF36: 77.76898 | AG36: 71.4224 | AH36: 70.464789 | AI36: 71.123489 | AJ36: 70.157073 | AK36: 79.525289 | AL36: 83.424991 | AM36: 87.273924 | AN36: 82.446528 | AO36: 81.695049 | AP36: 83.422557 | AQ36: 81.872852 | AR36: 81.00461 | AS36: 74.85448 | AT36: 74.093692 | AU36: 74.954654 | AV36: 74.198262 | AW36: 83.783598 | AX36: 87.90454 | AY36: 91.974808 | AZ36: 87.365095 | BA36: 86.82511 | BB36: 88.756943 | BC36: 87.404765 | BD36: 86.728457 | BE36: 80.766128 | BF36: 80.190291 | BG36: 81.234254 | BH36: 80.659427 | BI36: 90.425139 | BJ36: 94.725387 | BK36: 98.973983 | BL36: 94.541704 | BM36: 94.178294 | BN36: 96.285726 | BO36: 95.10779 | BP36: 94.603642 | BQ36: 88.810301 | BR36: 88.398943 | BS36: 89.601558 | BT36: 89.178683 | BU36: 99.089703 | BV36: 103.53002 | BW36: 107.9163 | BX36: 103.62327 | BY36: 103.40476 | BZ36: 105.66567 | CA36: 104.65017 | CB36: 104.31449 | CC36: 98.689504 | CD36: 98.438247 | CE36: 99.784575 | CF36: 99.483513 | CG36: 109.49264 | CH36: 114.01099 | CI36: 118.46354 | CJ36: 114.23477 | CK36: 114.09374 | CL36: 116.46767 | CM36: 115.59067 | CN36: 115.47174 | CO36: 110.09068 | CP36: 110.08042 | CQ36: 111.83876 | CR36: 111.50075 | CS36: 121.24746 | CT36: 126.66952 | CU36: 127.60411 | CV36: -1 | CW36: 1304
C37: Actual | CV37: 0 | CW37: 0
A38: Rr1401 | B38: adm | C38: Forecast | D38: 1555.2627 | E38: 1575.8867 | F38: 1701.3357 | G38: 1697.3431 | H38: 1687.8081 | I38: 1755.2833 | J38: 1695.7315 | K38: 1716.6338 | L38: 1718.5323 | M38: 1603.1783 | N38: 1635.0987 | O38: 1505.5394 | P38: 1695.1293 | Q38: 1712.1323 | R38: 1826.348 | S38: 1826.0464 | T38: 1806.9501 | U38: 1864.7202 | V38: 1799.8089 | W38: 1819.0138 | X38: 1823.5867 | Y38: 1715.4845 | Z38: 1755.7211 | AA38: 1633.1175 | AB38: 1826.7372 | AC38: 1844.404 | AD38: 1956.7302 | AE38: 1953.5332 | AF38: 1931.926 | AG38: 1988.3903 | AH38: 1923.554 | AI38: 1943.9216 | AJ38: 1950.2735 | AK38: 1844.1435 | AL38: 1886.2593 | AM38: 1765.2934 | AN38: 1960.252 | AO38: 1978.9443 | AP38: 2091.9942 | AQ38: 2089.2647 | AR38: 2067.9569 | AS38: 2124.6727 | AT38: 2060.1635 | AU38: 2081.025 | AV38: 2088.0706 | AW38: 1982.8057 | AX38: 2025.8859 | AY38: 1905.8974 | AZ38: 2101.7745 | BA38: 2121.2872 | BB38: 2235.0548 | BC38: 2232.9623 | BD38: 2212.2437 | BE38: 2269.5313 | BF38: 2205.5965 | BG38: 2227.0421 | BH38: 2234.6793 | BI38: 2130.0078 | BJ38: 2173.6793 | BK38: 2054.281 | BL38: 2250.7545 | BM38: 2270.88 | BN38: 2385.2871 | BO38: 2383.8655 | BP38: 2363.8438 | BQ38: 2421.8364 | BR38: 2358.5844 | BS38: 2380.6522 | BT38: 2388.8129 | BU38: 2284.5409 | BV38: 2328.4878 | BW38: 2209.2767 | BX38: 2405.9232 | BY38: 2426.3102 | BZ38: 2541.1746 | CA38: 2540.4849 | CB38: 2521.4836 | CC38: 2580.7093 | CD38: 2518.7367 | CE38: 2541.9065 | CF38: 2550.7653 | CG38: 2446.6335 | CH38: 2490.1214 | CI38: 2369.9681 | CJ38: 2565.4769 | CK38: 2584.8292 | CL38: 2699.1169 | CM38: 2699.1348 | CN38: 2681.5528 | CO38: 2743.5659 | CP38: 2686.3071 | CQ38: 2711.6923 | CR38: 2729.5635 | CS38: 2625.9678 | CT38: 2643.3739 | CU38: 2587.8733 | CV38: 1 | CW38: 1401
C39: Actual | CV39: 0 | CW39: 0
A40: Rr1401 | B40: desl | C40: Forecast | D40: 1784.5331 | E40: 1639.6598 | F40: 1836.2581 | G40: 1690.9562 | H40: 1790.8448 | I40: 1709.1508 | J40: 1700.8089 | K40: 1753.3931 | L40: 1642.5324 | M40: 1742.8074 | N40: 1751.996 | O40: 1676.3098 | P40: 1837.2866 | Q40: 1736.0825 | R40: 1930.8138 | S40: 1783.2142 | T40: 1875.627 | U40: 1792.1886 | V40: 1776.7927 | W40: 1828.6254 | X40: 1721.1232 | Y40: 1829.2044 | Z40: 1847.114 | AA40: 1778.7315 | AB40: 1943.6909 | AC40: 1843.0372 | AD40: 2035.9627 | AE40: 1885.7973 | AF40: 1976.2027 | AG40: 1892.0431 | AH40: 1877.2717 | AI40: 1930.7168 | AJ40: 1825.3281 | AK40: 1935.6206 | AL40: 1955.5999 | AM40: 1889.0445 | AN40: 2055.5555 | AO40: 1956.1675 | AP40: 2150.0781 | AQ40: 2000.6547 | AR40: 2091.6405 | AS40: 2008.0164 | AT40: 1993.8561 | AU40: 2048.0759 | AV40: 1943.6541 | AW40: 2055.0739 | AX40: 2076.2669 | AY40: 2010.9263 | AZ40: 2178.585 | BA40: 2080.2422 | BB40: 2275.0948 | BC40: 2126.533 | BD40: 2218.3325 | BE40: 2135.503 | BF40: 2122.1367 | BG40: 2177.1569 | BH40: 2073.5415 | BI40: 2185.7702 | BJ40: 2207.7727 | BK40: 2143.2442 | BL40: 2311.7231 | BM40: 2214.2157 | BN40: 2409.924 | BO40: 2262.2374 | BP40: 2354.9213 | BQ40: 2272.9649 | BR40: 2260.4305 | BS40: 2316.2083 | BT40: 2213.2487 | BU40: 2326.0211 | BV40: 2348.4726 | BW40: 2284.3482 | BX40: 2453.2639 | BY40: 2356.3163 | BZ40: 2552.7846 | CA40: 2406.0936 | CB40: 2499.9795 | CC40: 2419.3291 | CD40: 2408.0447 | CE40: 2464.8309 | CF40: 2362.4794 | CG40: 2475.3703 | CH40: 2497.4691 | CI40: 2432.6671 | CJ40: 2600.835 | CK40: 2503.3459 | CL40: 2700.0135 | CM40: 2554.3337 | CN40: 2650.2894 | CO40: 2573.0938 | CP40: 2565.6336 | CQ40: 2627.31 | CR40: 2530.6203 | CS40: 2632.8275 | CT40: 2673.1397 | CU40: 2577.4293 | CV40: -1 | CW40: 1401
...

Sheet Adm
B2: Mesoregiao | C2: 2017M1 | D2: 2017M2 | E2: 2017M3 | F2: 2017M4 | G2: 2017M5 | H2: 2017M6 | I2: 2017M7 | J2: 2017M8 | K2: 2017M9 | L2: 2017M10 | M2: 2017M11 | N2: 2017M12 | O2: 2018M1 | P2: 2018M2 | Q2: 2018M3 | R2: 2018M4 | S2: 2018M5 | T2: 2018M6 | U2: 2018M7 | V2: 2018M8 | W2: 2018M9 | X2: 2018M10 | Y2: 2018M11 | Z2: 2018M12 | AA2: 2019M1 | AB2: 2019M2 | AC2: 2019M3 | AD2: 2019M4 | AE2: 2019M5 | AF2: 2019M6 | AG2: 2019M7 | AH2: 2019M8 | AI2: 2019M9 | AJ2: 2019M10 | AK2: 2019M11 | AL2: 2019M12 | AM2: 2020M1 | AN2: 2020M2 | AO2: 2020M3 | AP2: 2020M4 | AQ2: 2020M5 | AR2: 2020M6 | AS2: 2020M7 | AT2: 2020M8 | AU2: 2020M9 | AV2: 2020M10 | AW2: 2020M11 | AX2: 2020M12 | AY2: 2021M1 | AZ2: 2021M2 | BA2: 2021M3 | BB2: 2021M4 | BC2: 2021M5 | BD2: 2021M6 | BE2: 2021M7 | BF2: 2021M8 | BG2: 2021M9 | BH2: 2021M10 | BI2: 2021M11 | BJ2: 2021M12 | BK2: 2022M1 | BL2: 2022M2 | BM2: 2022M3 | BN2: 2022M4 | BO2: 2022M5 | BP2: 2022M6 | BQ2: 2022M7 | BR2: 2022M8 | BS2: 2022M9 | BT2: 2022M10 | BU2: 2022M11 | BV2: 2022M12 | BW2: 2023M1 | BX2: 2023M2 | BY2: 2023M3 | BZ2: 2023M4 | CA2: 2023M5 | CB2: 2023M6 | CC2: 2023M7 | CD2: 2023M8 | CE2: 2023M9 | CF2: 2023M10 | CG2: 2023M11 | CH2: 2023M12 | CI2: 2024M1 | CJ2: 2024M2 | CK2: 2024M3 | CL2: 2024M4 | CM2: 2024M5 | CN2: 2024M6 | CO2: 2024M7 | CP2: 2024M8 | CQ2: 2024M9 | CR2: 2024M10 | CS2: 2024M11 | CT2: 2024M12
B3: 1102 | C3: =SUMIFS('conditional forecasts_4'!D$6:D$553,'conditional forecasts_4'!$CW$6:$CW$553,$B3,'conditional forecasts_4'!$B$6:$B$553,"adm") -> 4626.3708 | D3: =SUMIFS('conditional forecasts_4'!E$6:E$553,'conditional forecasts_4'!$CW$6:$CW$553,$B3,'conditional forecasts_4'!$B$6:$B$553,"adm") -> 5091.6645 | E3: =SUMIFS('conditional forecasts_4'!F$6:F$553,'conditional forecasts_4'!$CW$6:$CW$553,$B3,'conditional forecasts_4'!$B$6:$B$553,"adm") -> 5832.3454 | F3: =SUMIFS('conditional forecasts_4'!G$6:G$553,'conditional forecasts_4'!$CW$6:$CW$553,$B3,'conditional forecasts_4'!$B$6:$B$553,"adm") -> 5783.8094 | G3: =SUMIFS('conditional forecasts_4'!H$6:H$553,'conditional forecasts_4'!$CW$6:$CW$553,$B3,'conditional forecasts_4'!$B$6:$B$553,"adm") -> 5732.4579 | H3: =SUMIFS('conditional forecasts_4'!I$6:I$553,'conditional forecasts_4'!$CW$6:$CW$553,$B3,'conditional forecasts_4'!$B$6:$B$553,"adm") -> 5752.2769 | I3: =SUMIFS('conditional forecasts_4'!J$6:J$553,'conditional forecasts_4'!$CW$6:$CW$553,$B3,'conditional forecasts_4'!$B$6:$B$553,"adm") -> 5410.2786 | J3: =SUMIFS('conditional forecasts_4'!K$6:K$553,'conditional forecasts_4'!$CW$6:$CW$553,$B3,'conditional forecasts_4'!$B$6:$B$553,"adm") -> 5368.0792 | ... CT3: =SUMIFS('conditional forecasts_4'!CU$6:CU$553,'conditional forecasts_4'!$CW$6:$CW$553,$B3,'conditional forecasts_4'!$B$6:$B$553,"adm") -> 7360.9872
B4: 1101 | C4: =SUMIFS('conditional forecasts_4'!D$6:D$553,'conditional forecasts_4'!$CW$6:$CW$553,$B4,'conditional forecasts_4'!$B$6:$B$553,"adm") -> 2825.5893 | D4: =SUMIFS('conditional forecasts_4'!E$6:E$553,'conditional forecasts_4'!$CW$6:$CW$553,$B4,'conditional forecasts_4'!$B$6:$B$553,"adm") -> 3101.2583 | E4: =SUMIFS('conditional forecasts_4'!F$6:F$553,'conditional forecasts_4'!$CW$6:$CW$553,$B4,'conditional forecasts_4'!$B$6:$B$553,"adm") -> 3682.3295 | F4: =SUMIFS('conditional forecasts_4'!G$6:G$553,'conditional forecasts_4'!$CW$6:$CW$553,$B4,'conditional forecasts_4'!$B$6:$B$553,"adm") -> 3778.1559 | G4: =SUMIFS('conditional forecasts_4'!H$6:H$553,'conditional forecasts_4'!$CW$6:$CW$553,$B4,'conditional forecasts_4'!$B$6:$B$553,"adm") -> 3895.3444 | H4: =SUMIFS('conditional forecasts_4'!I$6:I$553,'conditional forecasts_4'!$CW$6:$CW$553,$B4,'conditional forecasts_4'!$B$6:$B$553,"adm") -> 4095.0617 | I4: =SUMIFS('conditional forecasts_4'!J$6:J$553,'conditional forecasts_4'!$CW$6:$CW$553,$B4,'conditional forecasts_4'!$B$6:$B$553,"adm") -> 4005.7696 | J4: =SUMIFS('conditional forecasts_4'!K$6:K$553,'conditional forecasts_4'!$CW$6:$CW$553,$B4,'conditional forecasts_4'!$B$6:$B$553,"adm") -> 4011.3179 | ... CT4: =SUMIFS('conditional forecasts_4'!CU$6:CU$553,'conditional forecasts_4'!$CW$6:$CW$553,$B4,'conditional forecasts_4'!$B$6:$B$553,"adm") -> 7830.6053
B5: 1100 | C5: =SUMIFS('conditional forecasts_4'!D$6:D$553,'conditional forecasts_4'!$CW$6:$CW$553,$B5,'conditional forecasts_4'!$B$6:$B$553,"adm") -> 0 | D5: =SUMIFS('conditional forecasts_4'!E$6:E$553,'conditional forecasts_4'!$CW$6:$CW$553,$B5,'conditional forecasts_4'!$B$6:$B$553,"adm") -> 0 | E5: =SUMIFS('conditional forecasts_4'!F$6:F$553,'conditional forecasts_4'!$CW$6:$CW$553,$B5,'conditional forecasts_4'!$B$6:$B$553,"adm") -> 0 | F5: =SUMIFS('conditional forecasts_4'!G$6:G$553,'conditional forecasts_4'!$CW$6:$CW$553,$B5,'conditional forecasts_4'!$B$6:$B$553,"adm") -> 0 | G5: =SUMIFS('conditional forecasts_4'!H$6:H$553,'conditional forecasts_4'!$CW$6:$CW$553,$B5,'conditional forecasts_4'!$B$6:$B$553,"adm") -> 0 | H5: =SUMIFS('conditional forecasts_4'!I$6:I$553,'conditional forecasts_4'!$CW$6:$CW$553,$B5,'conditional forecasts_4'!$B$6:$B$553,"adm") -> 0 | I5: =SUMIFS('conditional forecasts_4'!J$6:J$553,'conditional forecasts_4'!$CW$6:$CW$553,$B5,'conditional forecasts_4'!$B$6:$B$553,"adm") -> 0 | J5: =SUMIFS('conditional forecasts_4'!K$6:K$553,'conditional forecasts_4'!$CW$6:$CW$553,$B5,'conditional forecasts_4'!$B$6:$B$553,"adm") -> 0 | ... CT5: =SUMIFS('conditional forecasts_4'!CU$6:CU$553,'conditional forecasts_4'!$CW$6:$CW$553,$B5,'conditional forecasts_4'!$B$6:$B$553,"adm") -> 0
B6: 1202 | C6: =SUMIFS('conditional forecasts_4'!D$6:D$553,'conditional forecasts_4'!$CW$6:$CW$553,$B6,'conditional forecasts_4'!$B$6:$B$553,"adm") -> 1499.8732 | D6: =SUMIFS('conditional forecasts_4'!E$6:E$553,'conditional forecasts_4'!$CW$6:$CW$553,$B6,'conditional forecasts_4'!$B$6:$B$553,"adm") -> 1616.3859 | E6: =SUMIFS('conditional forecasts_4'!F$6:F$553,'conditional forecasts_4'!$CW$6:$CW$553,$B6,'conditional forecasts_4'!$B$6:$B$553,"adm") -> 1828.2258 | F6: =SUMIFS('conditional forecasts_4'!G$6:G$553,'conditional forecasts_4'!$CW$6:$CW$553,$B6,'conditional forecasts_4'!$B$6:$B$553,"adm") -> 1869.129 | G6: =SUMIFS('conditional forecasts_4'!H$6:H$553,'conditional forecasts_4'!$CW$6:$CW$553,$B6,'conditional forecasts_4'!$B$6:$B$553,"adm") -> 1864.3748 | H6: =SUMIFS('conditional forecasts_4'!I$6:I$553,'conditional forecasts_4'!$CW$6:$CW$553,$B6,'conditional forecasts_4'!$B$6:$B$553,"adm") -> 1889.3188 | I6: =SUMIFS('conditional forecasts_4'!J$6:J$553,'conditional forecasts_4'!$CW$6:$CW$553,$B6,'conditional forecasts_4'!$B$6:$B$553,"adm") -> 1819.8285 | J6: =SUMIFS('conditional forecasts_4'!K$6:K$553,'conditional forecasts_4'!$CW$6:$CW$553,$B6,'conditional forecasts_4'!$B$6:$B$553,"adm") -> 1808.5062 | ... CT6: =SUMIFS('conditional forecasts_4'!CU$6:CU$553,'conditional forecasts_4'!$CW$6:$CW$553,$B6,'conditional forecasts_4'!$B$6:$B$553,"adm") -> 2548.181
B7: 1201 | C7: =SUMIFS('conditional forecasts_4'!D$6:D$553,'conditional forecasts_4'!$CW$6:$CW$553,$B7,'conditional forecasts_4'!$B$6:$B$553,"adm") -> 123.37411 | D7: =SUMIFS('conditional forecasts_4'!E$6:E$553,'conditional forecasts_4'!$CW$6:$CW$553,$B7,'conditional forecasts_4'!$B$6:$B$553,"adm") -> 126.37728 | E7: =SUMIFS('conditional forecasts_4'!F$6:F$553,'conditional forecasts_4'!$CW$6:$CW$553,$B7,'conditional forecasts_4'!$B$6:$B$553,"adm") -> 171.90629 | F7: =SUMIFS('conditional forecasts_4'!G$6:G$553,'conditional forecasts_4'!$CW$6:$CW$553,$B7,'conditional forecasts_4'!$B$6:$B$553,"adm") -> 202.49704 | G7: =SUMIFS('conditional forecasts_4'!H$6:H$553,'conditional forecasts_4'!$CW$6:$CW$553,$B7,'conditional forecasts_4'!$B$6:$B$553,"adm") -> 225.21623 | H7: =SUMIFS('conditional forecasts_4'!I$6:I$553,'conditional forecasts_4'!$CW$6:$CW$553,$B7,'conditional forecasts_4'!$B$6:$B$553,"adm") -> 241.6723 | I7: =SUMIFS('conditional forecasts_4'!J$6:J$553,'conditional forecasts_4'!$CW$6:$CW$553,$B7,'conditional forecasts_4'!$B$6:$B$553,"adm") -> 225.40562 | J7: =SUMIFS('conditional forecasts_4'!K$6:K$553,'conditional forecasts_4'!$CW$6:$CW$553,$B7,'conditional forecasts_4'!$B$6:$B$553,"adm") -> 214.64485 | ... CT7: =SUMIFS('conditional forecasts_4'!CU$6:CU$553,'conditional forecasts_4'!$CW$6:$CW$553,$B7,'conditional forecasts_4'!$B$6:$B$553,"adm") -> 272.11767
B8: 1303 | C8: =SUMIFS('conditional forecasts_4'!D$6:D$553,'conditional forecasts_4'!$CW$6:$CW$553,$B8,'conditional forecasts_4'!$B$6:$B$553,"adm") -> 10126.067 | D8: =SUMIFS('conditional forecasts_4'!E$6:E$553,'conditional forecasts_4'!$CW$6:$CW$553,$B8,'conditional forecasts_4'!$B$6:$B$553,"adm") -> 10698.564 | E8: =SUMIFS('conditional forecasts_4'!F$6:F$553,'conditional forecasts_4'!$CW$6:$CW$553,$B8,'conditional forecasts_4'!$B$6:$B$553,"adm") -> 12695.821 | F8: =SUMIFS('conditional forecasts_4'!G$6:G$553,'conditional forecasts_4'!$CW$6:$CW$553,$B8,'conditional forecasts_4'!$B$6:$B$553,"adm") -> 12669.033 | G8: =SUMIFS('conditional forecasts_4'!H$6:H$553,'conditional forecasts_4'!$CW$6:$CW$553,$B8,'conditional forecasts_4'!$B$6:$B$553,"adm") -> 12653.724 | H8: =SUMIFS('conditional forecasts_4'!I$6:I$553,'conditional forecasts_4'!$CW$6:$CW$553,$B8,'conditional forecasts_4'!$B$6:$B$553,"adm") -> 13265.739 | I8: =SUMIFS('conditional forecasts_4'!J$6:J$553,'conditional forecasts_4'!$CW$6:$CW$553,$B8,'conditional forecasts_4'!$B$6:$B$553,"adm") -> 12684.63 | J8: =SUMIFS('conditional forecasts_4'!K$6:K$553,'conditional forecasts_4'!$CW$6:$CW$553,$B8,'conditional forecasts_4'!$B$6:$B$553,"adm") -> 13179.848 | ... CT8: =SUMIFS('conditional forecasts_4'!CU$6:CU$553,'conditional forecasts_4'!$CW$6:$CW$553,$B8,'conditional forecasts_4'!$B$6:$B$553,"adm") -> 20488.506
B9: 1302 | C9: =SUMIFS('conditional forecasts_4'!D$6:D$553,'conditional forecasts_4'!$CW$6:$CW$553,$B9,'conditional forecasts_4'!$B$6:$B$553,"adm") -> 25.708676 | D9: =SUMIFS('conditional forecasts_4'!E$6:E$553,'conditional forecasts_4'!$CW$6:$CW$553,$B9,'conditional forecasts_4'!$B$6:$B$553,"adm") -> 24.315895 | E9: =SUMIFS('conditional forecasts_4'!F$6:F$553,'conditional forecasts_4'!$CW$6:$CW$553,$B9,'conditional forecasts_4'!$B$6:$B$553,"adm") -> 28.478181 | F9: =SUMIFS('conditional forecasts_4'!G$6:G$553,'conditional forecasts_4'!$CW$6:$CW$553,$B9,'conditional forecasts_4'!$B$6:$B$553,"adm") -> 28.092005 | G9: =SUMIFS('conditional forecasts_4'!H$6:H$553,'conditional forecasts_4'!$CW$6:$CW$553,$B9,'conditional forecasts_4'!$B$6:$B$553,"adm") -> 27.775274 | H9: =SUMIFS('conditional forecasts_4'!I$6:I$553,'conditional forecasts_4'!$CW$6:$CW$553,$B9,'conditional forecasts_4'!$B$6:$B$553,"adm") -> 29.978109 | I9: =SUMIFS('conditional forecasts_4'!J$6:J$553,'conditional forecasts_4'!$CW$6:$CW$553,$B9,'conditional forecasts_4'!$B$6:$B$553,"adm") -> 26.643056 | J9: =SUMIFS('conditional forecasts_4'!K$6:K$553,'conditional forecasts_4'!$CW$6:$CW$553,$B9,'conditional forecasts_4'!$B$6:$B$553,"adm") -> 27.643738 | ... CT9: =SUMIFS('conditional forecasts_4'!CU$6:CU$553,'conditional forecasts_4'!$CW$6:$CW$553,$B9,'conditional forecasts_4'!$B$6:$B$553,"adm") -> 46.906741
B10: 1304 | C10: =SUMIFS('conditional forecasts_4'!D$6:D$553,'conditional forecasts_4'!$CW$6:$CW$553,$B10,'conditional forecasts_4'!$B$6:$B$553,"adm") -> 87.719224 | D10: =SUMIFS('conditional forecasts_4'!E$6:E$553,'conditional forecasts_4'!$CW$6:$CW$553,$B10,'conditional forecasts_4'!$B$6:$B$553,"adm") -> 88.106625 | E10: =SUMIFS('conditional forecasts_4'!F$6:F$553,'conditional forecasts_4'!$CW$6:$CW$553,$B10,'conditional forecasts_4'!$B$6:$B$553,"adm") -> 100.02389 | F10: =SUMIFS('conditional forecasts_4'!G$6:G$553,'conditional forecasts_4'!$CW$6:$CW$553,$B10,'conditional forecasts_4'!$B$6:$B$553,"adm") -> 90.726183 | G10: =SUMIFS('conditional forecasts_4'!H$6:H$553,'conditional forecasts_4'!$CW$6:$CW$553,$B10,'conditional forecasts_4'!$B$6:$B$553,"adm") -> 88.447943 | H10: =SUMIFS('conditional forecasts_4'!I$6:I$553,'conditional forecasts_4'!$CW$6:$CW$553,$B10,'conditional forecasts_4'!$B$6:$B$553,"adm") -> 88.026827 | I10: =SUMIFS('conditional forecasts_4'!J$6:J$553,'conditional forecasts_4'!$CW$6:$CW$553,$B10,'conditional forecasts_4'!$B$6:$B$553,"adm") -> 81.379997 | J10: =SUMIFS('conditional forecasts_4'!K$6:K$553,'conditional forecasts_4'!$CW$6:$CW$553,$B10,'conditional forecasts_4'!$B$6:$B$553,"adm") -> 82.287049 | ... CT10: =SUMIFS('conditional forecasts_4'!CU$6:CU$553,'conditional forecasts_4'!$CW$6:$CW$553,$B10,'conditional forecasts_4'!$B$6:$B$553,"adm") -> 117.20398
B11: 1301 | C11: =SUMIFS('conditional forecasts_4'!D$6:D$553,'conditional forecasts_4'!$CW$6:$CW$553,$B11,'conditional forecasts_4'!$B$6:$B$553,"adm") -> 25.057669 | D11: =SUMIFS('conditional forecasts_4'!E$6:E$553,'conditional forecasts_4'!$CW$6:$CW$553,$B11,'conditional forecasts_4'!$B$6:$B$553,"adm") -> 21.335398 | E11: =SUMIFS('conditional forecasts_4'!F$6:F$553,'conditional forecasts_4'!$CW$6:$CW$553,$B11,'conditional forecasts_4'!$B$6:$B$553,"adm") -> 25.754117 | F11: =SUMIFS('conditional forecasts_4'!G$6:G$553,'conditional forecasts_4'!$CW$6:$CW$553,$B11,'conditional forecasts_4'!$B$6:$B$553,"adm") -> 19.667795 | G11: =SUMIFS('conditional forecasts_4'!H$6:H$553,'conditional forecasts_4'!$CW$6:$CW$553,$B11,'conditional forecasts_4'!$B$6:$B$553,"adm") -> 17.841272 | H11: =SUMIFS('conditional forecasts_4'!I$6:I$553,'conditional forecasts_4'!$CW$6:$CW$553,$B11,'conditional forecasts_4'!$B$6:$B$553,"adm") -> 24.35841 | I11: =SUMIFS('conditional forecasts_4'!J$6:J$553,'conditional forecasts_4'!$CW$6:$CW$553,$B11,'conditional forecasts_4'!$B$6:$B$553,"adm") -> 13.166062 | J11: =SUMIFS('conditional forecasts_4'!K$6:K$553,'conditional forecasts_4'!$CW$6:$CW$553,$B11,'conditional forecasts_4'!$B$6:$B$553,"adm") -> 16.208252 | ... CT11: =SUMIFS('conditional forecasts_4'!CU$6:CU$553,'conditional forecasts_4'!$CW$6:$CW$553,$B11,'conditional forecasts_4'!$B$6:$B$553,"adm") -> 12.700656
B12: 1401 | C12: =SUMIFS('conditional forecasts_4'!D$6:D$553,'conditional forecasts_4'!$CW$6:$CW$553,$B12,'conditional forecasts_4'!$B$6:$B$553,"adm") -> 1555.2627 | D12: =SUMIFS('conditional forecasts_4'!E$6:E$553,'conditional forecasts_4'!$CW$6:$CW$553,$B12,'conditional forecasts_4'!$B$6:$B$553,"adm") -> 1575.8867 | E12: =SUMIFS('conditional forecasts_4'!F$6:F$553,'conditional forecasts_4'!$CW$6:$CW$553,$B12,'conditional forecasts_4'!$B$6:$B$553,"adm") -> 1701.3357 | F12: =SUMIFS('conditional forecasts_4'!G$6:G$553,'conditional forecasts_4'!$CW$6:$CW$553,$B12,'conditional forecasts_4'!$B$6:$B$553,"adm") -> 1697.3431 | G12: =SUMIFS('conditional forecasts_4'!H$6:H$553,'conditional forecasts_4'!$CW$6:$CW$553,$B12,'conditional forecasts_4'!$B$6:$B$553,"adm") -> 1687.8081 | H12: =SUMIFS('conditional forecasts_4'!I$6:I$553,'conditional forecasts_4'!$CW$6:$CW$553,$B12,'conditional forecasts_4'!$B$6:$B$553,"adm") -> 1755.2833 | I12: =SUMIFS('conditional forecasts_4'!J$6:J$553,'conditional forecasts_4'!$CW$6:$CW$553,$B12,'conditional forecasts_4'!$B$6:$B$553,"adm") -> 1695.7315 | J12: =SUMIFS('conditional forecasts_4'!K$6:K$553,'conditional forecasts_4'!$CW$6:$CW$553,$B12,'conditional forecasts_4'!$B$6:$B$553,"adm") -> 1716.6338 | ... CT12: =SUMIFS('conditional forecasts_4'!CU$6:CU$553,'conditional forecasts_4'!$CW$6:$CW$553,$B12,'conditional forecasts_4'!$B$6:$B$553,"adm") -> 2587.8733
B13: 1402 | C13: =SUMIFS('conditional forecasts_4'!D$6:D$553,'conditional forecasts_4'!$CW$6:$CW$553,$B13,'conditional forecasts_4'!$B$6:$B$553,"adm") -> 82.546203 | D13: =SUMIFS('conditional forecasts_4'!E$6:E$553,'conditional forecasts_4'!$CW$6:$CW$553,$B13,'conditional forecasts_4'!$B$6:$B$553,"adm") -> 73.506802 | E13: =SUMIFS('conditional forecasts_4'!F$6:F$553,'conditional forecasts_4'!$CW$6:$CW$553,$B13,'conditional forecasts_4'!$B$6:$B$553,"adm") -> 80.16202 | F13: =SUMIFS('conditional forecasts_4'!G$6:G$553,'conditional forecasts_4'!$CW$6:$CW$553,$B13,'conditional forecasts_4'!$B$6:$B$553,"adm") -> 77.530003 | G13: =SUMIFS('conditional forecasts_4'!H$6:H$553,'conditional forecasts_4'!$CW$6:$CW$553,$B13,'conditional forecasts_4'!$B$6:$B$553,"adm") -> 74.843309 | H13: =SUMIFS('conditional forecasts_4'!I$6:I$553,'conditional forecasts_4'!$CW$6:$CW$553,$B13,'conditional forecasts_4'!$B$6:$B$553,"adm") -> 75.395112 | I13: =SUMIFS('conditional forecasts_4'!J$6:J$553,'conditional forecasts_4'!$CW$6:$CW$553,$B13,'conditional forecasts_4'!$B$6:$B$553,"adm") -> 69.24166 | J13: =SUMIFS('conditional forecasts_4'!K$6:K$553,'conditional forecasts_4'!$CW$6:$CW$553,$B13,'conditional forecasts_4'!$B$6:$B$553,"adm") -> 66.815067 | ... CT13: =SUMIFS('conditional forecasts_4'!CU$6:CU$553,'conditional forecasts_4'!$CW$6:$CW$553,$B13,'conditional forecasts_4'!$B$6:$B$553,"adm") -> 100.64303
B14: 1504 | C14: =SUMIFS('conditional forecasts_4'!D$6:D$553,'conditional forecasts_4'!$CW$6:$CW$553,$B14,'conditional forecasts_4'!$B$6:$B$553,"adm") -> 1562.5849 | D14: =SUMIFS('conditional forecasts_4'!E$6:E$553,'conditional forecasts_4'!$CW$6:$CW$553,$B14,'conditional forecasts_4'!$B$6:$B$553,"adm") -> 1593.5122 | E14: =SUMIFS('conditional forecasts_4'!F$6:F$553,'conditional forecasts_4'!$CW$6:$CW$553,$B14,'conditional forecasts_4'!$B$6:$B$553,"adm") -> 1785.1265 | F14: =SUMIFS('conditional forecasts_4'!G$6:G$553,'conditional forecasts_4'!$CW$6:$CW$553,$B14,'conditional forecasts_4'!$B$6:$B$553,"adm") -> 1776.2032 | G14: =SUMIFS('conditional forecasts_4'!H$6:H$553,'conditional forecasts_4'!$CW$6:$CW$553,$B14,'conditional forecasts_4'!$B$6:$B$553,"adm") -> 1710.0547 | H14: =SUMIFS('conditional forecasts_4'!I$6:I$553,'conditional forecasts_4'!$CW$6:$CW$553,$B14,'conditional forecasts_4'!$B$6:$B$553,"adm") -> 1743.4684 | I14: =SUMIFS('conditional forecasts_4'!J$6:J$553,'conditional forecasts_4'!$CW$6:$CW$553,$B14,'conditional forecasts_4'!$B$6:$B$553,"adm") -> 1580.3452 | J14: =SUMIFS('conditional forecasts_4'!K$6:K$553,'conditional forecasts_4'!$CW$6:$CW$553,$B14,'conditional forecasts_4'!$B$6:$B$553,"adm") -> 1666.4785 | ... CT14: =SUMIFS('conditional forecasts_4'!CU$6:CU$553,'conditional forecasts_4'!$CW$6:$CW$553,$B14,'conditional forecasts_4'!$B$6:$B$553,"adm") -> 2918.2676
... B154: 5301 | C154: =SUMIFS('conditional forecasts_4'!D$6:D$553,'conditional forecasts_4'!$CW$6:$CW$553,$B154,'conditional forecasts_4'!$B$6:$B$553,"adm") -> 21836.037 | D154: =SUMIFS('conditional forecasts_4'!E$6:E$553,'conditional forecasts_4'!$CW$6:$CW$553,$B154,'conditional forecasts_4'!$B$6:$B$553,"adm") -> 22998.398 | E154: =SUMIFS('conditional forecasts_4'!F$6:F$553,'conditional forecasts_4'!$CW$6:$CW$553,$B154,'conditional forecasts_4'!$B$6:$B$553,"adm") -> 25061.348 | F154: =SUMIFS('conditional forecasts_4'!G$6:G$553,'conditional forecasts_4'!$CW$6:$CW$553,$B154,'conditional forecasts_4'!$B$6:$B$553,"adm") -> 25060.1 | G154: =SUMIFS('conditional forecasts_4'!H$6:H$553,'conditional forecasts_4'!$CW$6:$CW$553,$B154,'conditional forecasts_4'!$B$6:$B$553,"adm") -> 24532.029 | H154: =SUMIFS('conditional forecasts_4'!I$6:I$553,'conditional forecasts_4'!$CW$6:$CW$553,$B154,'conditional forecasts_4'!$B$6:$B$553,"adm") -> 24534.84 | I154: =SUMIFS('conditional forecasts_4'!J$6:J$553,'conditional forecasts_4'!$CW$6:$CW$553,$B154,'conditional forecasts_4'!$B$6:$B$553,"adm") -> 22913.542 | J154: =SUMIFS('conditional forecasts_4'!K$6:K$553,'conditional forecasts_4'!$CW$6:$CW$553,$B154,'conditional forecasts_4'!$B$6:$B$553,"adm") -> 22603.017 | ... CT154: =SUMIFS('conditional forecasts_4'!CU$6:CU$553,'conditional forecasts_4'!$CW$6:$CW$553,$B154,'conditional forecasts_4'!$B$6:$B$553,"adm") -> 35187.535

Sheet Des
B2: Mesoregiao | C2: 2017M1 | D2: 2017M2 | E2: 2017M3 | F2: 2017M4 | G2: 2017M5 | H2: 2017M6 | I2: 2017M7 | J2: 2017M8 | K2: 2017M9 | L2: 2017M10 | M2: 2017M11 | N2: 2017M12 | O2: 2018M1 | P2: 2018M2 | Q2: 2018M3 | R2: 2018M4 | S2: 2018M5 | T2: 2018M6 | U2: 2018M7 | V2: 2018M8 | W2: 2018M9 | X2: 2018M10 | Y2: 2018M11 | Z2: 2018M12 | AA2: 2019M1 | AB2: 2019M2 | AC2: 2019M3 | AD2: 2019M4 | AE2: 2019M5 | AF2: 2019M6 | AG2: 2019M7 | AH2: 2019M8 | AI2: 2019M9 | AJ2: 2019M10 | AK2: 2019M11 | AL2: 2019M12 | AM2: 2020M1 | AN2: 2020M2 | AO2: 2020M3 | AP2: 2020M4 | AQ2: 2020M5 | AR2: 2020M6 | AS2: 2020M7 | AT2: 2020M8 | AU2: 2020M9 | AV2: 2020M10 | AW2: 2020M11 | AX2: 2020M12 | AY2: 2021M1 | AZ2: 2021M2 | BA2: 2021M3 | BB2: 2021M4 | BC2: 2021M5 | BD2: 2021M6 | BE2: 2021M7 | BF2: 2021M8 | BG2: 2021M9 | BH2: 2021M10 | BI2: 2021M11 | BJ2: 2021M12 | BK2: 2022M1 | BL2: 2022M2 | BM2: 2022M3 | BN2: 2022M4 | BO2: 2022M5 | BP2: 2022M6 | BQ2: 2022M7 | BR2: 2022M8 | BS2: 2022M9 | BT2: 2022M10 | BU2: 2022M11 | BV2: 2022M12 | BW2: 2023M1 | BX2: 2023M2 | BY2: 2023M3 | BZ2: 2023M4 | CA2: 2023M5 | CB2: 2023M6 | CC2: 2023M7 | CD2: 2023M8 | CE2: 2023M9 | CF2: 2023M10 | CG2: 2023M11 | CH2: 2023M12 | CI2: 2024M1 | CJ2: 2024M2 | CK2: 2024M3 | CL2: 2024M4 | CM2: 2024M5 | CN2: 2024M6 | CO2: 2024M7 | CP2: 2024M8 | CQ2: 2024M9 | CR2: 2024M10 | CS2: 2024M11 | CT2: 2024M12
B3: 1102 | C3: =SUMIFS('conditional forecasts_4'!D$6:D$553,'conditional forecasts_4'!$CW$6:$CW$553,$B3,'conditional forecasts_4'!$B$6:$B$553,"desl") -> 5091.5863 | D3: =SUMIFS('conditional forecasts_4'!E$6:E$553,'conditional forecasts_4'!$CW$6:$CW$553,$B3,'conditional forecasts_4'!$B$6:$B$553,"desl") -> 5086.7267 | E3: =SUMIFS('conditional forecasts_4'!F$6:F$553,'conditional forecasts_4'!$CW$6:$CW$553,$B3,'conditional forecasts_4'!$B$6:$B$553,"desl") -> 5628.7039 | F3: =SUMIFS('conditional forecasts_4'!G$6:G$553,'conditional forecasts_4'!$CW$6:$CW$553,$B3,'conditional forecasts_4'!$B$6:$B$553,"desl") -> 5277.8379 | G3: =SUMIFS('conditional forecasts_4'!H$6:H$553,'conditional forecasts_4'!$CW$6:$CW$553,$B3,'conditional forecasts_4'!$B$6:$B$553,"desl") -> 5535.1614 | H3: =SUMIFS('conditional forecasts_4'!I$6:I$553,'conditional forecasts_4'!$CW$6:$CW$553,$B3,'conditional forecasts_4'!$B$6:$B$553,"desl") -> 5065.7142 | I3: =SUMIFS('conditional forecasts_4'!J$6:J$553,'conditional forecasts_4'!$CW$6:$CW$553,$B3,'conditional forecasts_4'!$B$6:$B$553,"desl") -> 5120.8829 | J3: =SUMIFS('conditional forecasts_4'!K$6:K$553,'conditional forecasts_4'!$CW$6:$CW$553,$B3,'conditional forecasts_4'!$B$6:$B$553,"desl") -> 5307.2963 | ... CT3: =SUMIFS('conditional forecasts_4'!CU$6:CU$553,'conditional forecasts_4'!$CW$6:$CW$553,$B3,'conditional forecasts_4'!$B$6:$B$553,"desl") -> 7901.6318
B4: 1101 | C4: =SUMIFS('conditional forecasts_4'!D$6:D$553,'conditional forecasts_4'!$CW$6:$CW$553,$B4,'conditional forecasts_4'!$B$6:$B$553,"desl") -> 3176.4667 | D4: =SUMIFS('conditional forecasts_4'!E$6:E$553,'conditional forecasts_4'!$CW$6:$CW$553,$B4,'conditional forecasts_4'!$B$6:$B$553,"desl") -> 3195.7408 | E4: =SUMIFS('conditional forecasts_4'!F$6:F$553,'conditional forecasts_4'!$CW$6:$CW$553,$B4,'conditional forecasts_4'!$B$6:$B$553,"desl") -> 3504.4765 | F4: =SUMIFS('conditional forecasts_4'!G$6:G$553,'conditional forecasts_4'!$CW$6:$CW$553,$B4,'conditional forecasts_4'!$B$6:$B$553,"desl") -> 3566.9715 | G4: =SUMIFS('conditional forecasts_4'!H$6:H$553,'conditional forecasts_4'!$CW$6:$CW$553,$B4,'conditional forecasts_4'!$B$6:$B$553,"desl") -> 3860.0017 | H4: =SUMIFS('conditional forecasts_4'!I$6:I$553,'conditional forecasts_4'!$CW$6:$CW$553,$B4,'conditional forecasts_4'!$B$6:$B$553,"desl") -> 3789.1297 | I4: =SUMIFS('conditional forecasts_4'!J$6:J$553,'conditional forecasts_4'!$CW$6:$CW$553,$B4,'conditional forecasts_4'!$B$6:$B$553,"desl") -> 3947.532 | J4: =SUMIFS('conditional forecasts_4'!K$6:K$553,'conditional forecasts_4'!$CW$6:$CW$553,$B4,'conditional forecasts_4'!$B$6:$B$553,"desl") -> 3980.7296 | ... CT4: =SUMIFS('conditional forecasts_4'!CU$6:CU$553,'conditional forecasts_4'!$CW$6:$CW$553,$B4,'conditional forecasts_4'!$B$6:$B$553,"desl") -> 8968.148
B5: 1100 | C5: =SUMIFS('conditional forecasts_4'!D$6:D$553,'conditional forecasts_4'!$CW$6:$CW$553,$B5,'conditional forecasts_4'!$B$6:$B$553,"desl") -> 0 | D5: =SUMIFS('conditional forecasts_4'!E$6:E$553,'conditional forecasts_4'!$CW$6:$CW$553,$B5,'conditional forecasts_4'!$B$6:$B$553,"desl") -> 0 | E5: =SUMIFS('conditional forecasts_4'!F$6:F$553,'conditional forecasts_4'!$CW$6:$CW$553,$B5,'conditional forecasts_4'!$B$6:$B$553,"desl") -> 0 | F5: =SUMIFS('conditional forecasts_4'!G$6:G$553,'conditional forecasts_4'!$CW$6:$CW$553,$B5,'conditional forecasts_4'!$B$6:$B$553,"desl") -> 0 | G5: =SUMIFS('conditional forecasts_4'!H$6:H$553,'conditional forecasts_4'!$CW$6:$CW$553,$B5,'conditional forecasts_4'!$B$6:$B$553,"desl") -> 0 | H5: =SUMIFS('conditional forecasts_4'!I$6:I$553,'conditional forecasts_4'!$CW$6:$CW$553,$B5,'conditional forecasts_4'!$B$6:$B$553,"desl") -> 0 | I5: =SUMIFS('conditional forecasts_4'!J$6:J$553,'conditional forecasts_4'!$CW$6:$CW$553,$B5,'conditional forecasts_4'!$B$6:$B$553,"desl") -> 0 | J5: =SUMIFS('conditional forecasts_4'!K$6:K$553,'conditional forecasts_4'!$CW$6:$CW$553,$B5,'conditional forecasts_4'!$B$6:$B$553,"desl") -> 0 | ... CT5: =SUMIFS('conditional forecasts_4'!CU$6:CU$553,'conditional forecasts_4'!$CW$6:$CW$553,$B5,'conditional forecasts_4'!$B$6:$B$553,"desl") -> 0
