Workbook

Sheet conditional forecasts_0
A1: GVAR Conditional Forecasts
A2: Last in-sample estimation date: | B2: 2016M12
A3: Last forecast date: | B3: 2024M12
D4: =DATE(LEFT(D5,4),SUBSTITUTE(RIGHT(D5,2),"M",""),1) -> 42736 | E4: =DATE(LEFT(E5,4),SUBSTITUTE(RIGHT(E5,2),"M",""),1) -> 42767 | F4: =DATE(LEFT(F5,4),SUBSTITUTE(RIGHT(F5,2),"M",""),1) -> 42795 | G4: =DATE(LEFT(G5,4),SUBSTITUTE(RIGHT(G5,2),"M",""),1) -> 42826 | H4: =DATE(LEFT(H5,4),SUBSTITUTE(RIGHT(H5,2),"M",""),1) -> 42856 | I4: =DATE(LEFT(I5,4),SUBSTITUTE(RIGHT(I5,2),"M",""),1) -> 42887 | J4: =DATE(LEFT(J5,4),SUBSTITUTE(RIGHT(J5,2),"M",""),1) -> 42917 | K4: =DATE(LEFT(K5,4),SUBSTITUTE(RIGHT(K5,2),"M",""),1) -> 42948 | ... CU4: =DATE(LEFT(CU5,4),SUBSTITUTE(RIGHT(CU5,2),"M",""),1) -> 45627
D5: 2017M1 | E5: 2017M2 | F5: 2017M3 | G5: 2017M4 | H5: 2017M5 | I5: 2017M6 | J5: 2017M7 | K5: 2017M8 | L5: 2017M9 | M5: 2017M10 | N5: 2017M11 | O5: 2017M12 | P5: 2018M1 | Q5: 2018M2 | R5: 2018M3 | S5: 2018M4 | T5: 2018M5 | U5: 2018M6 | V5: 2018M7 | W5: 2018M8 | X5: 2018M9 | Y5: 2018M10 | Z5: 2018M11 | AA5: 2018M12 | AB5: 2019M1 | AC5: 2019M2 | AD5: 2019M3 | AE5: 2019M4 | AF5: 2019M5 | AG5: 2019M6 | AH5: 2019M7 | AI5: 2019M8 | AJ5: 2019M9 | AK5: 2019M10 | AL5: 2019M11 | AM5: 2019M12 | AN5: 2020M1 | AO5: 2020M2 | AP5: 2020M3 | AQ5: 2020M4 | AR5: 2020M5 | AS5: 2020M6 | AT5: 2020M7 | AU5: 2020M8 | AV5: 2020M9 | AW5: 2020M10 | AX5: 2020M11 | AY5: 2020M12 | AZ5: 2021M1 | BA5: 2021M2 | BB5: 2021M3 | BC5: 2021M4 | BD5: 2021M5 | BE5: 2021M6 | BF5: 2021M7 | BG5: 2021M8 | BH5: 2021M9 | BI5: 2021M10 | BJ5: 2021M11 | BK5: 2021M12 | BL5: 2022M1 | BM5: 2022M2 | BN5: 2022M3 | BO5: 2022M4 | BP5: 2022M5 | BQ5: 2022M6 | BR5: 2022M7 | BS5: 2022M8 | BT5: 2022M9 | BU5: 2022M10 | BV5: 2022M11 | BW5: 2022M12 | BX5: 2023M1 | BY5: 2023M2 | BZ5: 2023M3 | CA5: 2023M4 | CB5: 2023M5 | CC5: 2023M6 | CD5: 2023M7 | CE5: 2023M8 | CF5: 2023M9 | CG5: 2023M10 | CH5: 2023M11 | CI5: 2023M12 | CJ5: 2024M1 | CK5: 2024M2 | CL5: 2024M3 | CM5: 2024M4 | CN5: 2024M5 | CO5: 2024M6 | CP5: 2024M7 | CQ5: 2024M8 | CR5: 2024M9 | CS5: 2024M10 | CT5: 2024M11 | CU5: 2024M12 | CV5: Serie | CW5: Meso
A6: Ro1101 | B6: adm | C6: Forecast | D6: 2524.1851 | E6: 2825.1414 | F6: 3461.1573 | G6: 3515.3689 | H6: 3622.9448 | I6: 3797.7889 | J6: 3672.5493 | K6: 3632.0697 | L6: 3363.4653 | M6: 2931.898 | N6: 2507.3125 | O6: 1792.0365 | P6: 2192.2521 | Q6: 2524.1183 | R6: 3223.1074 | S6: 3332.1711 | T6: 3467.2478 | U6: 3621.494 | V6: 3455.2846 | W6: 3363.5401 | X6: 3050.1935 | Y6: 2597.1567 | Z6: 2175.613 | AA6: 1481.2339 | AB6: 1910.0256 | AC6: 2267.5904 | AD6: 2982.6296 | AE6: 3096.5032 | AF6: 3227.434 | AG6: 3372.6032 | AH6: 3196.2795 | AI6: 3096.0457 | AJ6: 2777.111 | AK6: 2321.6651 | AL6: 1900.6125 | AM6: 1209.0855 | AN6: 1642.4076 | AO6: 2005.3715 | AP6: 2725.7976 | AQ6: 2844.2426 | AR6: 2978.3928 | AS6: 3125.2942 | AT6: 2949.4921 | AU6: 2849.1332 | AV6: 2530.072 | AW6: 2075.0244 | AX6: 1655.1751 | AY6: 965.6677 | AZ6: 1401.6333 | BA6: 1767.5789 | BB6: 2491.0509 | BC6: 2612.413 | BD6: 2749.2591 | BE6: 2898.6264 | BF6: 2725.0983 | BG6: 2626.8691 | BH6: 2309.8272 | BI6: 1856.7003 | BJ6: 1438.6709 | BK6: 750.8839 | BL6: 1188.4945 | BM6: 1556.0716 | BN6: 2281.2659 | BO6: 2404.5744 | BP6: 2543.7232 | BQ6: 2695.8351 | BR6: 2525.482 | BS6: 2430.7108 | BT6: 2117.1177 | BU6: 1667.0317 | BV6: 1251.2209 | BW6: 564.52794 | BX6: 1002.0507 | BY6: 1368.6373 | BZ6: 2092.5635 | CA6: 2215.1995 | CB6: 2355.189 | CC6: 2510.3544 | CD6: 2345.5051 | CE6: 2258.3106 | CF6: 1953.3649 | CG6: 1511.4785 | CH6: 1101.541 | CI6: 416.72005 | CJ6: 850.94397 | CK6: 1208.1827 | CL6: 1918.8544 | CM6: 2027.8864 | CN6: 2155.6664 | CO6: 2311.2544 | CP6: 2152.9709 | CQ6: 2087.7099 | CR6: 1843.311 | CS6: 1342.3951 | CT6: 1006.7343 | CU6: 587.68306 | CV6: 1 | CW6: 1101
C7: Actual | CV7: 0 | CW7: 0
A8: Ro1101 | B8: desl | C8: Forecast | D8: 3096.6012 | E8: 3063.6978 | F8: 3312.137 | G8: 3340.5202 | H8: 3591.1785 | I8: 3489.4544 | J8: 3600.5181 | K8: 3591.3097 | L8: 3424.232 | M8: 3497.8382 | N8: 3359.207 | O8: 3193.9078 | P8: 2967.7198 | Q8: 2858.5307 | R8: 3093.9463 | S8: 3087.5907 | T8: 3329.8398 | U8: 3204.8187 | V8: 3283.0385 | W8: 3231.8106 | X8: 3024.7893 | Y8: 3069.7671 | Z8: 2919.1841 | AA8: 2757.7738 | AB8: 2545.8837 | AC8: 2454.3751 | AD8: 2704.9307 | AE8: 2707.8643 | AF8: 2953.1767 | AG8: 2826.6017 | AH8: 2900.9915 | AI8: 2845.7477 | AJ8: 2635.8822 | AK8: 2679.8071 | AL8: 2530.0831 | AM8: 2371.2868 | AN8: 2163.4472 | AO8: 2076.9825 | AP8: 2333.0331 | AQ8: 2341.34 | AR8: 2591.4164 | AS8: 2468.7111 | AT8: 2546.0575 | AU8: 2493.0832 | AV8: 2285.1724 | AW8: 2331.1257 | AX8: 2183.7936 | AY8: 2027.884 | AZ8: 1823.4004 | BA8: 1740.6271 | BB8: 2000.5292 | BC8: 2012.6888 | BD8: 2266.5104 | BE8: 2147.3914 | BF8: 2228.1592 | BG8: 2178.4602 | BH8: 1973.7049 | BI8: 2022.7152 | BJ8: 1878.3571 | BK8: 1725.3511 | BL8: 1523.7194 | BM8: 1443.7777 | BN8: 1706.54 | BO8: 1721.6516 | BP8: 1978.5841 | BQ8: 1862.7853 | BR8: 1947.0924 | BS8: 1901.0976 | BT8: 1700.0811 | BU8: 1752.6688 | BV8: 1611.5012 | BW8: 1461.1064 | BX8: 1261.4213 | BY8: 1182.8453 | BZ8: 1446.6694 | CA8: 1462.9758 | CB8: 1721.7412 | CC8: 1608.8527 | CD8: 1697.3744 | CE8: 1656.8073 | CF8: 1461.9845 | CG8: 1520.7724 | CH8: 1384.9169 | CI8: 1237.9976 | CJ8: 1039.0993 | CK8: 958.52048 | CL8: 1217.5546 | CM8: 1227.5814 | CN8: 1481.6552 | CO8: 1364.6246 | CP8: 1459.6489 | CQ8: 1435.4249 | CR8: 1239.8352 | CS8: 1362.7475 | CT8: 1231.8669 | CU8: 972.60755 | CV8: -1 | CW8: 1101
C9: Actual | CV9: 0 | CW9: 0
A10: Ro1102 | B10: adm | C10: Forecast | D10: 4258.3425 | E10: 4814.1484 | F10: 5639.4208 | G10: 5563.7988 | H10: 5518.3668 | I10: 5518.0367 | J10: 5143.8368 | K10: 5056.8465 | L10: 4735.9982 | M10: 4398.2171 | N10: 4323.284 | O10: 3820.2172 | P10: 4536.7638 | Q10: 4836.368 | R10: 5565.3225 | S10: 5463.7514 | T10: 5370.944 | U10: 5300.8109 | V10: 4863.6092 | W10: 4722.8936 | X10: 4372.6948 | Y10: 4040.0118 | Z10: 3996.3342 | AA10: 3535.647 | AB10: 4290.3613 | AC10: 4612.8568 | AD10: 5346.4629 | AE10: 5235.5412 | AF10: 5126.9101 | AG10: 5041.6049 | AH10: 4594.3619 | AI10: 4450.0591 | AJ10: 4101.7805 | AK10: 3774.6303 | AL10: 3738.2544 | AM10: 3285.2988 | AN10: 4047.3206 | AO10: 4376.1167 | AP10: 5114.5756 | AQ10: 5006.8001 | AR10: 4899.6473 | AS10: 4814.5509 | AT10: 4366.9302 | AU10: 4222.4314 | AV10: 3874.7553 | AW10: 3549.3025 | AX10: 3515.655 | AY10: 3066.1228 | AZ10: 3831.8165 | BA10: 4164.1364 | BB10: 4905.7275 | BC10: 4800.6244 | BD10: 4695.7506 | BE10: 4612.6685 | BF10: 4166.9213 | BG10: 4024.2349 | BH10: 3678.3383 | BI10: 3354.6276 | BJ10: 3322.6754 | BK10: 2874.8033 | BL10: 3642.17 | BM10: 3976.261 | BN10: 4719.8299 | BO10: 4617.0174 | BP10: 4514.8131 | BQ10: 4434.7627 | BR10: 3992.2715 | BS10: 3852.7897 | BT10: 3509.6586 | BU10: 3187.857 | BV10: 3156.6478 | BW10: 2708.3089 | BX10: 3474.3397 | BY10: 3806.9655 | BZ10: 4549.9454 | CA10: 4448.4139 | CB10: 4349.9899 | CC10: 4276.1865 | CD10: 3841.6128 | CE10: 3710.3202 | CF10: 3374.0162 | CG10: 3056.1922 | CH10: 3025.0258 | CI10: 2572.4355 | CJ10: 3330.1601 | CK10: 3650.9012 | CL10: 4381.5455 | CM10: 4270.3345 | CN10: 4166.5343 | CO10: 4102.6481 | CP10: 3690.5662 | CQ10: 3603.2813 | CR10: 3339.9342 | CS10: 2956.9475 | CT10: 2995.3883 | CU10: 2706.2312 | CV10: 1 | CW10: 1102
C11: Actual | CV11: 0 | CW11: 0
A12: Ro1102 | B12: desl | C12: Forecast | D12: 4963.0991 | E12: 4931.8561 | F12: 5459.9551 | G12: 5121.6489 | H12: 5334.3733 | I12: 4851.9846 | J12: 4867.9636 | K12: 5008.9333 | L12: 4551.6853 | M12: 5071.6806 | N12: 5241.4367 | O12: 5187.8774 | P12: 4962.1405 | Q12: 4743.5797 | R12: 5280.369 | S12: 4883.9462 | T12: 5053.259 | U12: 4541.0391 | V12: 4521.4711 | W12: 4639.5488 | X12: 4176.5485 | Y12: 4707.2516 | Z12: 4898.5312 | AA12: 4867.2556 | AB12: 4656.5399 | AC12: 4442.9265 | AD12: 4976.5026 | AE12: 4572.9955 | AF12: 4735.7065 | AG12: 4220.0936 | AH12: 4200.9789 | AI12: 4322.5341 | AJ12: 3864.6605 | AK12: 4400.9461 | AL12: 4597.6075 | AM12: 4571.3093 | AN12: 4365.1384 | AO12: 4155.5832 | AP12: 4692.6181 | AQ12: 4291.8879 | AR12: 4456.7512 | AS12: 3942.8979 | AT12: 3925.4939 | AU12: 4049.0419 | AV12: 3593.6468 | AW12: 4132.9176 | AX12: 4332.9316 | AY12: 4310.1332 | AZ12: 4107.3988 | BA12: 3901.0792 | BB12: 4441.1034 | BC12: 4043.1434 | BD12: 4210.6174 | BE12: 3699.2722 | BF12: 3684.3079 | BG12: 3810.2402 | BH12: 3357.179 | BI12: 3898.7462 | BJ12: 4101.0504 | BK12: 4080.5841 | BL12: 3880.2795 | BM12: 3676.5355 | BN12: 4219.3066 | BO12: 3824.2533 | BP12: 3994.7369 | BQ12: 3486.3964 | BR12: 3474.2773 | BS12: 3602.7138 | BT12: 3151.6471 | BU12: 3694.6068 | BV12: 3897.7556 | BW12: 3877.8378 | BX12: 3678.2304 | BY12: 3475.8845 | BZ12: 4021.2442 | CA12: 3630.1883 | CB12: 3805.8581 | CC12: 3303.2089 | CD12: 3296.2865 | CE12: 3428.411 | CF12: 2978.8282 | CG12: 3520.8896 | CH12: 3721.2889 | CI12: 3697.6343 | CJ12: 3493.8809 | CK12: 3288.7843 | CL12: 3833.3915 | CM12: 3443.7256 | CN12: 3628.6163 | CO12: 3135.1537 | CP12: 3152.8513 | CQ12: 3330.8758 | CR12: 2833.8822 | CS12: 3498.0723 | CT12: 3702.4602 | CU12: 3151.5013 | CV12: -1 | CW12: 1102
C13: Actual | CV13: 0 | CW13: 0
A14: Ac1201 | B14: adm | C14: Forecast | D14: 117.23356 | E14: 125.42947 | F14: 166.59193 | G14: 194.74557 | H14: 220.19168 | I14: 236.47094 | J14: 219.56357 | K14: 206.78142 | L14: 182.14917 | M14: 151.43048 | N14: 132.42233 | O14: 103.00676 | P14: 121.41803 | Q14: 125.25577 | R14: 159.37322 | S14: 186.85137 | T14: 212.87751 | U14: 228.61233 | V14: 208.7603 | W14: 190.53103 | X14: 159.89159 | Y14: 124.52704 | Z14: 103.54134 | AA14: 75.20187 | AB14: 96.961256 | AC14: 105.03908 | AD14: 142.94973 | AE14: 172.88238 | AF14: 199.76222 | AG14: 215.03343 | AH14: 193.96651 | AI14: 174.3503 | AJ14: 142.57269 | AK14: 106.5274 | AL14: 85.350523 | AM14: 57.23577 | AN14: 79.516505 | AO14: 88.282235 | AP14: 126.92213 | AQ14: 157.514 | AR14: 184.89699 | AS14: 200.46839 | AT14: 179.5002 | AU14: 159.82862 | AV14: 127.91908 | AW14: 91.748927 | AX14: 70.520386 | AY14: 42.460872 | AZ14: 64.90245 | BA14: 73.90676 | BB14: 112.82287 | BC14: 143.6904 | BD14: 171.3218 | BE14: 187.10234 | BF14: 166.30445 | BG14: 146.77216 | BH14: 114.98062 | BI14: 78.915032 | BJ14: 57.78209 | BK14: 29.810998 | BL14: 52.334979 | BM14: 61.418629 | BN14: 100.4176 | BO14: 131.38223 | BP14: 159.13834 | BQ14: 175.08381 | BR14: 154.49796 | BS14: 135.22053 | BT14: 103.7074 | BU14: 67.909234 | BV14: 46.988256 | BW14: 19.130063 | BX14: 41.639808 | BY14: 50.583994 | BZ14: 89.359073 | CA14: 120.09337 | CB14: 147.71337 | CC14: 163.71464 | CD14: 143.4415 | CE14: 124.7415 | CF14: 94.008343 | CG14: 59.062011 | CH14: 38.88446 | CI14: 11.468783 | CJ14: 33.949918 | CK14: 42.275877 | CL14: 79.890736 | CM14: 109.08918 | CN14: 135.07868 | CO14: 149.98853 | CP14: 129.55233 | CQ14: 112.29638 | CR14: 85.404974 | CS14: 49.968145 | CT14: 34.599839 | CU14: 16.776869 | CV14: 1 | CW14: 1201
C15: Actual | CV15: 0 | CW15: 0
A16: Ac1201 | B16: desl | C16: Forecast | D16: 192.34537 | E16: 157.3683 | F16: 151.37491 | G16: 135.92012 | H16: 148.87912 | I16: 144.22455 | J16: 159.48715 | K16: 170.74774 | L16: 164.90686 | M16: 191.45279 | N16: 198.56444 | O16: 199.70157 | P16: 182.08888 | Q16: 157.39252 | R16: 146.11049 | S16: 122.34733 | T16: 132.94283 | U16: 127.65236 | V16: 143.36015 | W16: 155.37628 | X16: 149.42257 | Y16: 174.7671 | Z16: 180.04287 | AA16: 179.42007 | AB16: 160.63984 | AC16: 135.55017 | AD16: 124.53887 | AE16: 101.424 | AF16: 112.74662 | AG16: 108.06354 | AH16: 124.18964 | AI16: 136.46049 | AJ16: 130.65886 | AK16: 156.10405 | AL16: 161.45567 | AM16: 160.8945 | AN16: 142.17204 | AO16: 117.15486 | AP16: 106.25422 | AQ16: 83.305765 | AR16: 94.852776 | AS16: 90.436377 | AT16: 106.84372 | AU16: 119.38133 | AV16: 113.81177 | AW16: 139.44818 | AX16: 144.95713 | AY16: 144.53415 | AZ16: 125.94642 | BA16: 101.07195 | BB16: 90.326946 | BC16: 67.546139 | BD16: 79.268356 | BE16: 75.029435 | BF16: 91.612396 | BG16: 104.32174 | BH16: 98.920038 | BI16: 124.7219 | BJ16: 130.3959 | BK16: 130.13914 | BL16: 111.71921 | BM16: 87.012754 | BN16: 76.432804 | BO16: 53.809594 | BP16: 65.677278 | BQ16: 61.568533 | BR16: 78.266538 | BS16: 91.080616 | BT16: 85.783028 | BU16: 111.7014 | BV16: 117.51736 | BW16: 117.43666 | BX16: 99.226955 | BY16: 74.753855 | BZ16: 64.408555 | CA16: 41.992733 | CB16: 54.012747 | CC16: 49.983073 | CD16: 66.685004 | CE16: 79.445084 | CF16: 74.069386 | CG16: 99.931904 | CH16: 105.77376 | CI16: 105.84599 | CJ16: 87.940246 | CK16: 63.966966 | CL16: 54.214514 | CM16: 32.393941 | CN16: 45.043212 | CO16: 41.008737 | CP16: 57.835 | CQ16: 69.935173 | CR16: 61.093198 | CS16: 92.859227 | CT16: 96.337278 | CU16: 79.056288 | CV16: -1 | CW16: 1201
C17: Actual | CV17: 0 | CW17: 0
A18: Ac1202 | B18: adm | C18: Forecast | D18: 1363.2593 | E18: 1507.1465 | F18: 1760.0591 | G18: 1777.9428 | H18: 1775.8408 | I18: 1796.2064 | J18: 1710.8391 | K18: 1688.6328 | L18: 1581.7083 | M18: 1462.2254 | N18: 1418.7179 | O18: 1191.402 | P18: 1354.5818 | Q18: 1463.8552 | R18: 1718.8847 | S18: 1724.7065 | T18: 1713.4432 | U18: 1714.845 | V18: 1614.1832 | W18: 1577.1723 | X18: 1458.7287 | Y18: 1335.9189 | Z18: 1296.0376 | AA18: 1077.3442 | AB18: 1251.2604 | AC18: 1369.9378 | AD18: 1630.8008 | AE18: 1638.3367 | AF18: 1625.4754 | AG18: 1623.5246 | AH18: 1519.3726 | AI18: 1479.8855 | AJ18: 1360.4891 | AK18: 1238.2163 | AL18: 1199.9972 | AM18: 983.61763 | AN18: 1160.0632 | AO18: 1281.1436 | AP18: 1544.046 | AQ18: 1553.1241 | AR18: 1541.2763 | AS18: 1539.8784 | AT18: 1435.9699 | AU18: 1396.6141 | AV18: 1277.4302 | AW18: 1155.5923 | AX18: 1118.0902 | AY18: 902.6862 | AZ18: 1080.2813 | BA18: 1202.5763 | BB18: 1466.66 | BC18: 1476.8211 | BD18: 1465.9331 | BE18: 1465.3793 | BF18: 1362.225 | BG18: 1323.5632 | BH18: 1205.0372 | BI18: 1083.8373 | BJ18: 1046.9639 | BK18: 832.18969 | BL18: 1010.4302 | BM18: 1133.4061 | BN18: 1398.2298 | BO18: 1409.2111 | BP18: 1399.2349 | BQ18: 1399.6766 | BR18: 1297.5669 | BS18: 1259.9349 | BT18: 1142.3358 | BU18: 1021.8639 | BV18: 985.44428 | BW18: 770.82822 | BX18: 948.99339 | BY18: 1071.8174 | BZ18: 1336.6448 | CA18: 1348.0382 | CB18: 1339.0733 | CC18: 1341.1715 | CD18: 1241.2175 | CE18: 1205.9156 | CF18: 1090.384 | CG18: 971.26761 | CH18: 935.15659 | CI18: 719.69563 | CJ18: 895.98651 | CK18: 1016.1041 | CL18: 1278.1615 | CM18: 1287.6144 | CN18: 1277.6402 | CO18: 1281.6049 | CP18: 1187.452 | CQ18: 1160.1416 | CR18: 1062.1431 | CS18: 932.72531 | CT18: 906.65602 | CU18: 738.59124 | CV18: 1 | CW18: 1202
C19: Actual | CV19: 0 | CW19: 0
A20: Ac1202 | B20: desl | C20: Forecast | D20: 1763.8669 | E20: 1663.7472 | F20: 1763.4336 | G20: 1605.8637 | H20: 1744.5096 | I20: 1560.8023 | J20: 1584.9124 | K20: 1630.4511 | L20: 1492.8403 | M20: 1735.3283 | N20: 1792.8142 | O20: 1885.143 | P20: 1784.693 | Q20: 1610.8214 | R20: 1691.6493 | S20: 1511.1504 | T20: 1633.0083 | U20: 1440.1258 | V20: 1452.0641 | W20: 1490.4766 | X20: 1350.8839 | Y20: 1595.582 | Z20: 1658.9076 | AA20: 1757.8537 | AB20: 1662.3876 | AC20: 1490.9865 | AD20: 1572.0616 | AE20: 1390.5513 | AF20: 1511.2321 | AG20: 1317.7458 | AH20: 1329.8966 | AI20: 1369.238 | AJ20: 1231.0438 | AK20: 1477.3742 | AL20: 1542.4246 | AM20: 1643.1215 | AN20: 1549.3823 | AO20: 1379.6166 | AP20: 1462.1563 | AQ20: 1281.883 | AR20: 1403.5714 | AS20: 1210.9247 | AT20: 1223.8505 | AU20: 1264.0087 | AV20: 1126.7472 | AW20: 1374.1499 | AX20: 1440.3877 | AY20: 1542.3355 | AZ20: 1449.8549 | BA20: 1281.3139 | BB20: 1365.0241 | BC20: 1185.864 | BD20: 1308.6144 | BE20: 1116.9853 | BF20: 1130.8878 | BG20: 1171.9828 | BH20: 1035.6209 | BI20: 1283.8945 | BJ20: 1350.9914 | BK20: 1453.8103 | BL20: 1362.2394 | BM20: 1194.6703 | BN20: 1279.4283 | BO20: 1101.3902 | BP20: 1225.315 | BQ20: 1034.8689 | BR20: 1049.8985 | BS20: 1091.9887 | BT20: 956.41862 | BU20: 1205.239 | BV20: 1272.6541 | BW20: 1375.6576 | BX20: 1284.3099 | BY20: 1117.2207 | BZ20: 1202.9143 | CA20: 1026.3676 | CB20: 1152.275 | CC20: 964.05819 | CD20: 981.18616 | CE20: 1024.8399 | CF20: 889.99868 | CG20: 1138.5936 | CH20: 1204.9714 | CI20: 1306.4432 | CJ20: 1213.2709 | CK20: 1044.7845 | CL20: 1129.9373 | CM20: 953.66402 | CN20: 1083.3222 | CO20: 899.1385 | CP20: 924.17621 | CQ20: 988.85991 | CR20: 834.68492 | CS20: 1123.7669 | CT20: 1201.8214 | CU20: 1099.788 | CV20: -1 | CW20: 1202
C21: Actual | CV21: 0 | CW21: 0
A22: Am1301 | B22: adm | C22: Forecast | D22: 23.498568 | E22: 26.862069 | F22: 27.567616 | G22: 21.202216 | H22: 20.376514 | I22: 25.802135 | J22: 15.123014 | K22: 17.710581 | L22: 19.635768 | M22: 12.168634 | N22: 18.538943 | O22: 16.920056 | P22: 38.662862 | Q22: 28.500394 | R22: 28.04813 | S22: 22.167734 | T22: 19.824184 | U22: 25.264709 | V22: 14.79844 | W22: 17.155314 | X22: 18.995741 | Y22: 11.449266 | Z22: 17.762693 | AA22: 16.184076 | AB22: 38.023078 | AC22: 27.9574 | AD22: 27.571664 | AE22: 21.717329 | AF22: 19.363096 | AG22: 24.772862 | AH22: 14.274214 | AI22: 16.608328 | AJ22: 18.439834 | AK22: 10.896459 | AL22: 17.219956 | AM22: 15.654132 | AN22: 37.506494 | AO22: 27.453926 | AP22: 27.080651 | AQ22: 21.237461 | AR22: 18.892066 | AS22: 24.30758 | AT22: 13.811542 | AU22: 16.145976 | AV22: 17.976986 | AW22: 10.433863 | AX22: 16.759456 | AY22: 15.19791 | AZ22: 37.056362 | BA22: 27.010915 | BB22: 26.644965 | BC22: 20.808703 | BD22: 18.469556 | BE22: 23.89062 | BF22: 13.399549 | BG22: 15.73848 | BH22: 17.573558 | BI22: 10.034029 | BJ22: 16.362667 | BK22: 14.803586 | BL22: 36.66403 | BM22: 26.620433 | BN22: 26.256767 | BO22: 20.423982 | BP22: 18.090238 | BQ22: 23.519023 | BR22: 13.037703 | BS22: 15.387257 | BT22: 17.231907 | BU22: 9.6987109 | BV22: 16.028778 | BW22: 14.465885 | BX22: 36.318659 | BY22: 26.266353 | BZ22: 25.896316 | CA22: 20.062361 | CB22: 17.734216 | CC22: 23.175349 | CD22: 12.712165 | CE22: 15.084629 | CF22: 16.956123 | CG22: 9.4512214 | CH22: 15.802701 | CI22: 14.247722 | CJ22: 36.085549 | CK22: 25.965831 | CL22: 25.515205 | CM22: 19.605231 | CN22: 17.200784 | CO22: 22.828097 | CP22: 12.265469 | CQ22: 14.890673 | CR22: 18.271262 | CS22: 6.3958764 | CT22: 15.864313 | CU22: 20.931297 | CV22: 1 | CW22: 1301
C23: Actual | CV23: 0 | CW23: 0
A24: Am1301 | B24: desl | C24: Forecast | D24: 32.275753 | E24: 29.637096 | F24: 21.877141 | G24: 24.26779 | H24: 24.502715 | I24: 16.413167 | J24: 20.059959 | K24: 18.989537 | L24: 17.760044 | M24: 27.650773 | N24: 29.795961 | O24: 44.733367 | P24: 29.558427 | Q24: 30.083091 | R24: 22.688694 | S24: 23.567692 | T24: 23.973426 | U24: 16.083804 | V24: 19.573537 | W24: 18.696766 | X24: 17.667718 | Y24: 27.650871 | Z24: 29.823196 | AA24: 44.703297 | AB24: 29.418634 | AC24: 29.843621 | AD24: 22.396902 | AE24: 23.275247 | AF24: 23.716113 | AG24: 15.872754 | AH24: 19.399217 | AI24: 18.541636 | AJ24: 17.516509 | AK24: 27.495356 | AL24: 29.662145 | AM24: 44.538928 | AN24: 29.252864 | AO24: 29.676582 | AP24: 22.227577 | AQ24: 23.103007 | AR24: 23.541894 | AS24: 15.699076 | AT24: 19.229156 | AU24: 18.377492 | AV24: 17.358929 | AW24: 27.343275 | AX24: 29.513457 | AY24: 44.391465 | AZ24: 29.105188 | BA24: 29.528314 | BB24: 22.079226 | BC24: 22.9555 | BD24: 23.396071 | BE24: 15.555356 | BF24: 19.087453 | BG24: 18.237351 | BH24: 17.219769 | BI24: 27.20464 | BJ24: 29.375214 | BK24: 44.253893 | BL24: 28.96898 | BM24: 29.394477 | BN24: 21.948877 | BO24: 22.829562 | BP24: 23.274894 | BQ24: 15.438352 | BR24: 18.972888 | BS24: 18.122465 | BT24: 17.101341 | BU24: 27.079958 | BV24: 29.24321 | BW24: 44.116059 | BX24: 28.829601 | BY24: 29.259877 | BZ24: 21.825724 | CA24: 22.722699 | CB24: 23.185544 | CC24: 15.363552 | CD24: 18.906008 | CE24: 18.054607 | CF24: 17.022903 | CG24: 26.981249 | CH24: 29.118424 | CI24: 43.962913 | CJ24: 28.638696 | CK24: 29.046257 | CL24: 21.607459 | CM24: 22.528957 | CN24: 23.14986 | CO24: 15.346007 | CP24: 19.076456 | CQ24: 18.811257 | CR24: 15.908772 | CS24: 28.543945 | CT24: 30.572682 | CU24: 35.733463 | CV24: -1 | CW24: 1301
C25: Actual | CV25: 0 | CW25: 0
A26: Am1302 | B26: adm | C26: Forecast | D26: 23.387857 | E26: 22.996226 | F26: 26.801023 | G26: 26.204703 | H26: 25.922107 | I26: 27.749353 | J26: 24.36331 | K26: 24.980507 | L26: 24.412051 | M26: 20.517846 | N26: 21.037856 | O26: 17.446292 | P26: 23.135583 | Q26: 21.819834 | R26: 25.291831 | S26: 25.06311 | T26: 24.526746 | U26: 26.13992 | V26: 22.505908 | W26: 22.758254 | X26: 21.939427 | Y26: 17.985209 | Z26: 18.630442 | AA26: 15.289139 | AB26: 21.24817 | AC26: 20.128635 | AD26: 23.681807 | AE26: 23.431162 | AF26: 22.813881 | AG26: 24.337341 | AH26: 20.640235 | AI26: 20.868925 | AJ26: 20.061054 | AK26: 16.139552 | AL26: 16.826797 | AM26: 13.529011 | AN26: 19.529693 | AO26: 18.448496 | AP26: 22.03514 | AQ26: 21.811042 | AR26: 21.211798 | AS26: 22.744971 | AT26: 19.051711 | AU26: 19.282455 | AV26: 18.479085 | AW26: 14.567464 | AX26: 15.270785 | AY26: 11.994066 | AZ26: 18.018388 | BA26: 16.960841 | BB26: 20.569278 | BC26: 20.364308 | BD26: 19.781668 | BE26: 21.329607 | BF26: 17.650063 | BG26: 17.894052 | BH26: 17.103731 | BI26: 13.205011 | BJ26: 13.921056 | BK26: 10.65693 | BL26: 16.693916 | BM26: 15.649456 | BN26: 19.271833 | BO26: 19.082056 | BP26: 18.516105 | BQ26: 20.082183 | BR26: 16.421772 | BS26: 16.684936 | BT26: 15.912398 | BU26: 12.02834 | BV26: 12.754345 | BW26: 9.4946761 | BX26: 15.531266 | BY26: 14.484084 | BZ26: 18.105683 | CA26: 17.922162 | CB26: 17.373732 | CC26: 18.970024 | CD26: 15.349935 | CE26: 15.656985 | CF26: 14.923111 | CG26: 11.064145 | CH26: 11.795266 | CI26: 8.5218044 | CJ26: 14.531007 | CK26: 13.439282 | CL26: 17.020373 | CM26: 16.803532 | CN26: 16.203429 | CO26: 17.861857 | CP26: 14.213576 | CQ26: 14.71986 | CR26: 14.750602 | CS26: 9.553499 | CT26: 11.51291 | CU26: 10.513754 | CV26: 1 | CW26: 1302
C27: Actual | CV27: 0 | CW27: 0
A28: Am1302 | B28: desl | C28: Forecast | D28: 30.493672 | E28: 26.688984 | F28: 27.770004 | G28: 25.745242 | H28: 27.102886 | I28: 27.393345 | J28: 27.734609 | K28: 29.366413 | L28: 31.026096 | M28: 31.02499 | N28: 30.240296 | O28: 26.900826 | P28: 28.207076 | Q28: 24.597104 | R28: 26.741076 | S28: 24.594485 | T28: 25.92379 | U28: 26.522851 | V28: 26.929337 | W28: 28.512697 | X28: 30.12544 | Y28: 30.04444 | Z28: 29.175059 | AA28: 25.777065 | AB28: 27.054559 | AC28: 23.442517 | AD28: 25.605905 | AE28: 23.491881 | AF28: 24.859595 | AG28: 25.497821 | AH28: 25.939815 | AI28: 27.551133 | AJ28: 29.181588 | AK28: 29.107462 | AL28: 28.236323 | AM28: 24.832207 | AN28: 26.103972 | AO28: 22.490478 | AP28: 24.658782 | AQ28: 22.556 | AR28: 23.939512 | AS28: 24.595495 | AT28: 25.054731 | AU28: 26.681077 | AV28: 28.323655 | AW28: 28.258938 | AX28: 27.39523 | AY28: 23.997503 | AZ28: 25.275455 | BA28: 21.668534 | BB28: 23.844095 | BC28: 21.749304 | BD28: 23.141421 | BE28: 23.806425 | BF28: 24.274891 | BG28: 25.910528 | BH28: 27.562386 | BI28: 27.506944 | BJ28: 26.65255 | BK28: 23.264189 | BL28: 24.551465 | BM28: 20.95357 | BN28: 23.137446 | BO28: 21.049778 | BP28: 22.447467 | BQ28: 23.116491 | BR28: 23.587986 | BS28: 25.226815 | BT28: 26.883565 | BU28: 26.836155 | BV28: 25.993678 | BW28: 22.620676 | BX28: 23.924994 | BY28: 20.343128 | BZ28: 22.53918 | CA28: 20.457821 | CB28: 21.855461 | CC28: 22.519056 | CD28: 22.981586 | CE28: 24.610262 | CF28: 26.258287 | CG28: 26.20659 | CH28: 25.368149 | CI28: 22.014999 | CJ28: 23.358359 | CK28: 19.827398 | CL28: 22.089975 | CM28: 20.080386 | CN28: 21.482562 | CO28: 22.122693 | CP28: 22.426061 | CQ28: 24.006128 | CR28: 26.014516 | CS28: 24.452803 | CT28: 23.62864 | CU28: 22.020158 | CV28: -1 | CW28: 1302
C29: Actual | CV29: 0 | CW29: 0
A30: Am1303 | B30: adm | C30: Forecast | D30: 8814.2814 | E30: 9374.7043 | F30: 11539.764 | G30: 11397.061 | H30: 11362.832 | I30: 11920.123 | J30: 11281.972 | K30: 11660.398 | L30: 11235.049 | M30: 10289.635 | N30: 9745.6558 | O30: 7089.4974 | P30: 8362.9885 | Q30: 8865.1235 | R30: 11264.548 | S30: 11294.23 | T30: 11208.662 | U30: 11597.1 | V30: 10800.764 | W30: 11082.011 | X30: 10660.052 | Y30: 9822.6294 | Z30: 9435.8804 | AA30: 6922.6632 | AB30: 8283.0776 | AC30: 8801.8797 | AD30: 11161.367 | AE30: 11124.557 | AF30: 10975.389 | AG30: 11321.283 | AH30: 10508.15 | AI30: 10793.281 | AJ30: 10387.147 | AK30: 9569.8698 | AL30: 9202.9178 | AM30: 6707.002 | AN30: 8081.2724 | AO30: 8609.699 | AP30: 10973.822 | AQ30: 10936.458 | AR30: 10782.446 | AS30: 11121.229 | AT30: 10301.304 | AU30: 10582.239 | AV30: 10175.739 | AW30: 9361.8414 | AX30: 9000.8581 | AY30: 6511.8562 | AZ30: 7892.4864 | BA30: 8425.7968 | BB30: 10793.103 | BC30: 10757.545 | BD30: 10604.537 | BE30: 10944.07 | BF30: 10124.982 | BG30: 10406.937 | BH30: 10001.55 | BI30: 9188.7105 | BJ30: 8828.6325 | BK30: 6340.4121 | BL30: 7721.8794 | BM30: 8256.3836 | BN30: 10625.596 | BO30: 10592.969 | BP30: 10444.066 | BQ30: 10788.74 | BR30: 9975.3083 | BS30: 10262.504 | BT30: 9860.718 | BU30: 9048.6072 | BV30: 8685.5955 | BW30: 6190.9189 | BX30: 7563.8062 | BY30: 8090.2259 | BZ30: 10455.153 | CA30: 10425.028 | CB30: 10286.912 | CC30: 10649.743 | CD30: 9858.3637 | CE30: 10166.3 | CF30: 9778.5511 | CG30: 8969.6487 | CH30: 8596.8497 | CI30: 6080.1897 | CJ30: 7421.2448 | CK30: 7907.5141 | CL30: 10235.418 | CM30: 10180.312 | CN30: 10028.246 | CO30: 10430.209 | CP30: 9703.1081 | CQ30: 10153.42 | CR30: 10043.258 | CS30: 8908.2471 | CT30: 8689.6511 | CU30: 6915.2416 | CV30: 1 | CW30: 1303
C31: Actual | CV31: 0 | CW31: 0
A32: Am1303 | B32: desl | C32: Forecast | D32: 12136.977 | E32: 11974.527 | F32: 12951.334 | G32: 12345.644 | H32: 12991.284 | I32: 11480.293 | J32: 11559.938 | K32: 11930.899 | L32: 10849.936 | M32: 12587.6 | N32: 13455.036 | O32: 13968.434 | P32: 12681.98 | Q32: 11702.81 | R32: 12639.78 | S32: 11812.144 | T32: 12357.376 | U32: 10759.543 | V32: 10710.182 | W32: 10990.598 | X32: 9888.2341 | Y32: 11680.955 | Z32: 12655.383 | AA32: 13282.543 | AB32: 12077.55 | AC32: 11130.353 | AD32: 12055.292 | AE32: 11190.446 | AF32: 11694.813 | AG32: 10067.904 | AH32: 10007.104 | AI32: 10291.838 | AJ32: 9203.8271 | AK32: 11015.088 | AL32: 12008.389 | AM32: 12652.991 | AN32: 11463.321 | AO32: 10528.812 | AP32: 11463.209 | AQ32: 10604.208 | AR32: 11111.096 | AS32: 9484.5149 | AT32: 9423.5598 | AU32: 9709.373 | AV32: 8624.8311 | AW32: 10442.218 | AX32: 11443.739 | AY32: 12097.606 | AZ32: 10917.155 | BA32: 9991.0338 | BB32: 10932.657 | BC32: 10079.787 | BD32: 10592.008 | BE32: 8970.2926 | BF32: 8913.9795 | BG32: 9204.3278 | BH32: 8124.2434 | BI32: 9946.0216 | BJ32: 10951.922 | BK32: 11610.282 | BL32: 10434.618 | BM32: 9513.7867 | BN32: 10461.371 | BO32: 9615.2122 | BP32: 10134.809 | BQ32: 8520.8366 | BR32: 8472.0859 | BS32: 8769.0553 | BT32: 7693.8113 | BU32: 9517.9877 | BV32: 10523.694 | BW32: 11179.92 | BX32: 10001.747 | BY32: 9080.2742 | BZ32: 10031.401 | CA32: 9194.4972 | CB32: 9729.01 | CC32: 8133.6385 | CD32: 8103.6239 | CE32: 8415.3728 | CF32: 7347.5593 | CG32: 9169.9985 | CH32: 10165.527 | CI32: 10805.111 | CJ32: 9604.972 | CK32: 8662.7086 | CL32: 9597.7238 | CM32: 8750.6927 | CN32: 9303.048 | CO32: 7731.3732 | CP32: 7797.2595 | CQ32: 8286.2795 | CR32: 7065.1438 | CS32: 9354.7839 | CT32: 10392.951 | CU32: 9240.7026 | CV32: -1 | CW32: 1303
C33: Actual | CV33: 0 | CW33: 0
A34: Am1304 | B34: adm | C34: Forecast | D34: 79.06833 | E34: 84.505061 | F34: 98.387473 | G34: 88.178726 | H34: 86.029979 | I34: 84.987352 | J34: 77.533541 | K34: 77.673038 | L34: 70.901514 | M34: 66.933367 | N34: 67.521551 | O34: 55.597986 | P34: 75.661301 | Q34: 79.672247 | R34: 95.009224 | S34: 85.707468 | T34: 82.649859 | U34: 80.266695 | V34: 71.856063 | W34: 71.248967 | X34: 64.117267 | Y34: 60.229617 | Z34: 61.12708 | AA34: 49.552509 | AB34: 69.869083 | AC34: 73.960073 | AD34: 89.216156 | AE34: 79.74654 | AF34: 76.515505 | AG34: 74.010093 | AH34: 65.550782 | AI34: 64.962367 | AJ34: 57.897097 | AK34: 54.103294 | AL34: 55.106453 | AM34: 43.639224 | AN34: 64.057775 | AO34: 68.239367 | AP34: 83.569712 | AQ34: 74.155812 | AR34: 70.963961 | AS34: 68.487352 | AT34: 60.054892 | AU34: 59.499292 | AV34: 52.477756 | AW34: 48.739525 | AX34: 49.807453 | AY34: 38.409597 | AZ34: 58.897458 | BA34: 63.144975 | BB34: 78.536428 | BC34: 69.179016 | BD34: 66.040128 | BE34: 63.61418 | BF34: 55.230922 | BG34: 54.723384 | BH34: 47.748736 | BI34: 44.056144 | BJ34: 45.16865 | BK34: 33.814949 | BL34: 54.347657 | BM34: 58.642163 | BN34: 74.084233 | BO34: 64.782158 | BP34: 61.703477 | BQ34: 59.341289 | BR34: 51.022228 | BS34: 50.574555 | BT34: 43.649892 | BU34: 39.992718 | BV34: 41.124348 | BW34: 29.776491 | BX34: 50.310083 | BY34: 54.612855 | BZ34: 70.083792 | CA34: 60.840863 | CB34: 57.853608 | CC34: 55.607456 | CD34: 47.413139 | CE34: 47.079137 | CF34: 40.238442 | CG34: 36.620875 | CH34: 37.737578 | CI34: 26.318266 | CJ34: 46.732933 | CK34: 50.878575 | CL34: 66.209231 | CM34: 56.914185 | CN34: 53.958317 | CO34: 52.011706 | CP34: 44.406171 | CQ34: 44.705666 | CR34: 39.016521 | CS34: 33.709634 | CT34: 35.356773 | CU34: 27.044281 | CV34: 1 | CW34: 1304
C35: Actual | CV35: 0 | CW35: 0
A36: Am1304 | B36: desl | C36: Forecast | D36: 88.452191 | E36: 78.122826 | F36: 77.386571 | G36: 76.666271 | H36: 75.955703 | I36: 69.421304 | J36: 68.219188 | K36: 68.002673 | L36: 66.421215 | M36: 73.512677 | N36: 78.082699 | O36: 82.567594 | P36: 76.56208 | Q36: 74.286002 | R36: 75.064283 | S36: 73.312432 | T36: 71.446653 | U36: 64.166069 | V36: 62.103564 | W36: 61.309229 | X36: 59.467676 | Y36: 66.527333 | Z36: 71.254387 | AA36: 75.966028 | AB36: 70.143566 | AC36: 67.952073 | AD36: 68.714298 | AE36: 66.880312 | AF36: 64.914353 | AG36: 57.555732 | AH36: 55.459068 | AI36: 54.67889 | AJ36: 52.8924 | AK36: 60.035302 | AL36: 64.861106 | AM36: 69.676483 | AN36: 63.954362 | AO36: 61.853425 | AP36: 62.692329 | AQ36: 60.919971 | AR36: 59.00269 | AS36: 51.684653 | AT36: 49.626673 | AU36: 48.888997 | AV36: 47.152534 | AW36: 54.35396 | AX36: 59.245257 | AY36: 64.130034 | AZ36: 58.477833 | BA36: 56.444619 | BB36: 57.347517 | BC36: 55.635086 | BD36: 53.774173 | BE36: 46.509859 | BF36: 44.503888 | BG36: 43.81726 | BH36: 42.131416 | BI36: 49.383406 | BJ36: 54.325521 | BK36: 59.261674 | BL36: 53.661725 | BM36: 51.681943 | BN36: 52.639672 | BO36: 50.983481 | BP36: 49.179862 | BQ36: 41.972989 | BR36: 40.023066 | BS36: 39.389031 | BT36: 37.750185 | BU36: 45.042133 | BV36: 50.017341 | BW36: 54.982193 | BX36: 49.411317 | BY36: 47.467047 | BZ36: 48.472163 | CA36: 46.877821 | CB36: 45.148691 | CC36: 38.02265 | CD36: 36.15065 | CE36: 35.582455 | CF36: 33.990928 | CG36: 41.308802 | CH36: 46.29061 | CI36: 51.244834 | CJ36: 45.64518 | CK36: 43.672779 | CL36: 44.652556 | CM36: 43.055804 | CN36: 41.431556 | CO36: 34.412219 | CP36: 32.914045 | CQ36: 32.991216 | CR36: 31.024884 | CS36: 39.437738 | CT36: 43.232269 | CU36: 42.389442 | CV36: -1 | CW36: 1304
C37: Actual | CV37: 0 | CW37: 0
A38: Rr1401 | B38: adm | C38: Forecast | D38: 1478.6558 | E38: 1519.9108 | F38: 1651.5941 | G38: 1639.608 | H38: 1631.2619 | I38: 1693.4605 | J38: 1632.0646 | K38: 1647.4335 | L38: 1635.9378 | M38: 1544.4232 | N38: 1538.0963 | O38: 1402.1212 | P38: 1560.8813 | Q38: 1584.8067 | R38: 1707.9222 | S38: 1703.2293 | T38: 1685.5408 | U38: 1736.4798 | V38: 1666.886 | W38: 1677.1663 | X38: 1665.1823 | Y38: 1578.2243 | Z38: 1578.7151 | AA38: 1449.2671 | AB38: 1612.3948 | AC38: 1637.684 | AD38: 1759.5423 | AE38: 1752.1997 | AF38: 1731.7445 | AG38: 1780.6634 | AH38: 1710.115 | AI38: 1720.3894 | AJ38: 1709.0333 | AK38: 1623.023 | AL38: 1624.5507 | AM38: 1496.0882 | AN38: 1660.0636 | AO38: 1685.9963 | AP38: 1808.2441 | AQ38: 1801.0246 | AR38: 1780.4692 | AS38: 1829.1617 | AT38: 1758.3841 | AU38: 1768.5371 | AV38: 1757.2313 | AW38: 1671.4474 | AX38: 1673.3312 | AY38: 1545.2823 | AZ38: 1709.6591 | BA38: 1735.934 | BB38: 1858.4481 | BC38: 1851.4276 | BD38: 1831.0267 | BE38: 1879.853 | BF38: 1809.2054 | BG38: 1819.4909 | BH38: 1808.319 | BI38: 1722.6653 | BJ38: 1724.6733 | BK38: 1596.7448 | BL38: 1761.2472 | BM38: 1787.667 | BN38: 1910.3607 | BO38: 1903.5673 | BP38: 1883.4457 | BQ38: 1932.5955 | BR38: 1862.2913 | BS38: 1872.8989 | BT38: 1861.9733 | BU38: 1776.4352 | BV38: 1778.3901 | BW38: 1650.2426 | BX38: 1814.4194 | BY38: 1840.5255 | BZ38: 1963.0738 | CA38: 1956.4527 | CB38: 1936.9045 | CC38: 1986.9962 | CD38: 1917.8368 | CE38: 1929.5284 | CF38: 1919.3435 | CG38: 1833.9897 | CH38: 1835.4676 | CI38: 1706.2713 | CJ38: 1869.0285 | CK38: 1893.317 | CL38: 2014.3053 | CM38: 2006.9475 | CN38: 1986.6505 | CO38: 2038.7962 | CP38: 1971.5757 | CQ38: 1987.8783 | CR38: 1999.1675 | CS38: 1885.2182 | CT38: 1902.0935 | CU38: 1847.4427 | CV38: 1 | CW38: 1401
C39: Actual | CV39: 0 | CW39: 0
A40: Rr1401 | B40: desl | C40: Forecast | D40: 1736.6042 | E40: 1628.5051 | F40: 1806.4313 | G40: 1663.6568 | H40: 1758.2326 | I40: 1674.6032 | J40: 1661.3888 | K40: 1704.451 | L40: 1596.3589 | M40: 1682.4595 | N40: 1687.7635 | O40: 1639.3641 | P40: 1743.4822 | Q40: 1678.7825 | R40: 1860.5407 | S40: 1716.7136 | T40: 1803.8364 | U40: 1715.5614 | V40: 1693.4421 | W40: 1731.8348 | X40: 1623.7291 | Y40: 1714.8925 | Z40: 1727.3073 | AA40: 1685.6126 | AB40: 1793.8815 | AC40: 1730.1887 | AD40: 1910.4755 | AE40: 1764.0105 | AF40: 1848.5673 | AG40: 1758.5848 | AH40: 1735.8275 | AI40: 1774.4648 | AJ40: 1667.1442 | AK40: 1759.3255 | AL40: 1772.796 | AM40: 1732.0951 | AN40: 1841.2327 | AO40: 1778.2237 | AP40: 1958.9566 | AQ40: 1812.683 | AR40: 1897.2166 | AS40: 1807.0925 | AT40: 1784.1975 | AU40: 1822.8085 | AV40: 1715.6327 | AW40: 1808.1295 | AX40: 1822.0364 | AY40: 1781.8201 | AZ40: 1891.4235 | BA40: 1828.8178 | BB40: 2009.8781 | BC40: 1863.8658 | BD40: 1948.6168 | BE40: 1858.6883 | BF40: 1835.9827 | BG40: 1874.7839 | BH40: 1767.7998 | BI40: 1860.4879 | BJ40: 1874.5858 | BK40: 1834.564 | BL40: 1944.3736 | BM40: 1881.9974 | BN40: 2063.3221 | BO40: 1917.6171 | BP40: 2002.7171 | BQ40: 1913.1649 | BR40: 1890.8325 | BS40: 1929.9597 | BT40: 1823.2054 | BU40: 1915.9881 | BV40: 1930.0348 | BW40: 1889.8499 | BX40: 1999.4662 | BY40: 1936.9839 | BZ40: 2118.4124 | CA40: 1973.1073 | CB40: 2058.9147 | CC40: 1970.2963 | CD40: 1948.9607 | CE40: 1988.9407 | CF40: 1882.7007 | CG40: 1975.5164 | CH40: 1989.0613 | CI40: 1947.9045 | CJ40: 2056.1354 | CK40: 1992.1467 | CL40: 2172.4459 | CM40: 2026.3535 | CN40: 2112.5823 | CO40: 2025.9062 | CP40: 2007.7073 | CQ40: 2059.1823 | CR40: 1952.3013 | CS40: 2047.8521 | CT40: 2083.6539 | CU40: 1979.4068 | CV40: -1 | CW40: 1401
...

Sheet Adm
B2: Mesoregiao | C2: 2017M1 | D2: 2017M2 | E2: 2017M3 | F2: 2017M4 | G2: 2017M5 | H2: 2017M6 | I2: 2017M7 | J2: 2017M8 | K2: 2017M9 | L2: 2017M10 | M2: 2017M11 | N2: 2017M12 | O2: 2018M1 | P2: 2018M2 | Q2: 2018M3 | R2: 2018M4 | S2: 2018M5 | T2: 2018M6 | U2: 2018M7 | V2: 2018M8 | W2: 2018M9 | X2: 2018M10 | Y2: 2018M11 | Z2: 2018M12 | AA2: 2019M1 | AB2: 2019M2 | AC2: 2019M3 | AD2: 2019M4 | AE2: 2019M5 | AF2: 2019M6 | AG2: 2019M7 | AH2: 2019M8 | AI2: 2019M9 | AJ2: 2019M10 | AK2: 2019M11 | AL2: 2019M12 | AM2: 2020M1 | AN2: 2020M2 | AO2: 2020M3 | AP2: 2020M4 | AQ2: 2020M5 | AR2: 2020M6 | AS2: 2020M7 | AT2: 2020M8 | AU2: 2020M9 | AV2: 2020M10 | AW2: 2020M11 | AX2: 2020M12 | AY2: 2021M1 | AZ2: 2021M2 | BA2: 2021M3 | BB2: 2021M4 | BC2: 2021M5 | BD2: 2021M6 | BE2: 2021M7 | BF2: 2021M8 | BG2: 2021M9 | BH2: 2021M10 | BI2: 2021M11 | BJ2: 2021M12 | BK2: 2022M1 | BL2: 2022M2 | BM2: 2022M3 | BN2: 2022M4 | BO2: 2022M5 | BP2: 2022M6 | BQ2: 2022M7 | BR2: 2022M8 | BS2: 2022M9 | BT2: 2022M10 | BU2: 2022M11 | BV2: 2022M12 | BW2: 2023M1 | BX2: 2023M2 | BY2: 2023M3 | BZ2: 2023M4 | CA2: 2023M5 | CB2: 2023M6 | CC2: 2023M7 | CD2: 2023M8 | CE2: 2023M9 | CF2: 2023M10 | CG2: 2023M11 | CH2: 2023M12 | CI2: 2024M1 | CJ2: 2024M2 | CK2: 2024M3 | CL2: 2024M4 | CM2: 2024M5 | CN2: 2024M6 | CO2: 2024M7 | CP2: 2024M8 | CQ2: 2024M9 | CR2: 2024M10 | CS2: 2024M11 | CT2: 2024M12
B3: 1102 | C3: =SUMIFS('conditional forecasts_0'!D$6:D$553,'conditional forecasts_0'!$CW$6:$CW$553,$B3,'conditional forecasts_0'!$B$6:$B$553,"adm") -> 4258.3425 | D3: =SUMIFS('conditional forecasts_0'!E$6:E$553,'conditional forecasts_0'!$CW$6:$CW$553,$B3,'conditional forecasts_0'!$B$6:$B$553,"adm") -> 4814.1484 | E3: =SUMIFS('conditional forecasts_0'!F$6:F$553,'conditional forecasts_0'!$CW$6:$CW$553,$B3,'conditional forecasts_0'!$B$6:$B$553,"adm") -> 5639.4208 | F3: =SUMIFS('conditional forecasts_0'!G$6:G$553,'conditional forecasts_0'!$CW$6:$CW$553,$B3,'conditional forecasts_0'!$B$6:$B$553,"adm") -> 5563.7988 | G3: =SUMIFS('conditional forecasts_0'!H$6:H$553,'conditional forecasts_0'!$CW$6:$CW$553,$B3,'conditional forecasts_0'!$B$6:$B$553,"adm") -> 5518.3668 | H3: =SUMIFS('conditional forecasts_0'!I$6:I$553,'conditional forecasts_0'!$CW$6:$CW$553,$B3,'conditional forecasts_0'!$B$6:$B$553,"adm") -> 5518.0367 | I3: =SUMIFS('conditional forecasts_0'!J$6:J$553,'conditional forecasts_0'!$CW$6:$CW$553,$B3,'conditional forecasts_0'!$B$6:$B$553,"adm") -> 5143.8368 | J3: =SUMIFS('conditional forecasts_0'!K$6:K$553,'conditional forecasts_0'!$CW$6:$CW$553,$B3,'conditional forecasts_0'!$B$6:$B$553,"adm") -> 5056.8465 | ... CT3: =SUMIFS('conditional forecasts_0'!CU$6:CU$553,'conditional forecasts_0'!$CW$6:$CW$553,$B3,'conditional forecasts_0'!$B$6:$B$553,"adm") -> 2706.2312
B4: 1101 | C4: =SUMIFS('conditional forecasts_0'!D$6:D$553,'conditional forecasts_0'!$CW$6:$CW$553,$B4,'conditional forecasts_0'!$B$6:$B$553,"adm") -> 2524.1851 | D4: =SUMIFS('conditional forecasts_0'!E$6:E$553,'conditional forecasts_0'!$CW$6:$CW$553,$B4,'conditional forecasts_0'!$B$6:$B$553,"adm") -> 2825.1414 | E4: =SUMIFS('conditional forecasts_0'!F$6:F$553,'conditional forecasts_0'!$CW$6:$CW$553,$B4,'conditional forecasts_0'!$B$6:$B$553,"adm") -> 3461.1573 | F4: =SUMIFS('conditional forecasts_0'!G$6:G$553,'conditional forecasts_0'!$CW$6:$CW$553,$B4,'conditional forecasts_0'!$B$6:$B$553,"adm") -> 3515.3689 | G4: =SUMIFS('conditional forecasts_0'!H$6:H$553,'conditional forecasts_0'!$CW$6:$CW$553,$B4,'conditional forecasts_0'!$B$6:$B$553,"adm") -> 3622.9448 | H4: =SUMIFS('conditional forecasts_0'!I$6:I$553,'conditional forecasts_0'!$CW$6:$CW$553,$B4,'conditional forecasts_0'!$B$6:$B$553,"adm") -> 3797.7889 | I4: =SUMIFS('conditional forecasts_0'!J$6:J$553,'conditional forecasts_0'!$CW$6:$CW$553,$B4,'conditional forecasts_0'!$B$6:$B$553,"adm") -> 3672.5493 | J4: =SUMIFS('conditional forecasts_0'!K$6:K$553,'conditional forecasts_0'!$CW$6:$CW$553,$B4,'conditional forecasts_0'!$B$6:$B$553,"adm") -> 3632.0697 | ... CT4: =SUMIFS('conditional forecasts_0'!CU$6:CU$553,'conditional forecasts_0'!$CW$6:$CW$553,$B4,'conditional forecasts_0'!$B$6:$B$553,"adm") -> 587.68306
B5: 1100 | C5: =SUMIFS('conditional forecasts_0'!D$6:D$553,'conditional forecasts_0'!$CW$6:$CW$553,$B5,'conditional forecasts_0'!$B$6:$B$553,"adm") -> 0 | D5: =SUMIFS('conditional forecasts_0'!E$6:E$553,'conditional forecasts_0'!$CW$6:$CW$553,$B5,'conditional forecasts_0'!$B$6:$B$553,"adm") -> 0 | E5: =SUMIFS('conditional forecasts_0'!F$6:F$553,'conditional forecasts_0'!$CW$6:$CW$553,$B5,'conditional forecasts_0'!$B$6:$B$553,"adm") -> 0 | F5: =SUMIFS('conditional forecasts_0'!G$6:G$553,'conditional forecasts_0'!$CW$6:$CW$553,$B5,'conditional forecasts_0'!$B$6:$B$553,"adm") -> 0 | G5: =SUMIFS('conditional forecasts_0'!H$6:H$553,'conditional forecasts_0'!$CW$6:$CW$553,$B5,'conditional forecasts_0'!$B$6:$B$553,"adm") -> 0 | H5: =SUMIFS('conditional forecasts_0'!I$6:I$553,'conditional forecasts_0'!$CW$6:$CW$553,$B5,'conditional forecasts_0'!$B$6:$B$553,"adm") -> 0 | I5: =SUMIFS('conditional forecasts_0'!J$6:J$553,'conditional forecasts_0'!$CW$6:$CW$553,$B5,'conditional forecasts_0'!$B$6:$B$553,"adm") -> 0 | J5: =SUMIFS('conditional forecasts_0'!K$6:K$553,'conditional forecasts_0'!$CW$6:$CW$553,$B5,'conditional forecasts_0'!$B$6:$B$553,"adm") -> 0 | ... CT5: =SUMIFS('conditional forecasts_0'!CU$6:CU$553,'conditional forecasts_0'!$CW$6:$CW$553,$B5,'conditional forecasts_0'!$B$6:$B$553,"adm") -> 0
B6: 1202 | C6: =SUMIFS('conditional forecasts_0'!D$6:D$553,'conditional forecasts_0'!$CW$6:$CW$553,$B6,'conditional forecasts_0'!$B$6:$B$553,"adm") -> 1363.2593 | D6: =SUMIFS('conditional forecasts_0'!E$6:E$553,'conditional forecasts_0'!$CW$6:$CW$553,$B6,'conditional forecasts_0'!$B$6:$B$553,"adm") -> 1507.1465 | E6: =SUMIFS('conditional forecasts_0'!F$6:F$553,'conditional forecasts_0'!$CW$6:$CW$553,$B6,'conditional forecasts_0'!$B$6:$B$553,"adm") -> 1760.0591 | F6: =SUMIFS('conditional forecasts_0'!G$6:G$553,'conditional forecasts_0'!$CW$6:$CW$553,$B6,'conditional forecasts_0'!$B$6:$B$553,"adm") -> 1777.9428 | G6: =SUMIFS('conditional forecasts_0'!H$6:H$553,'conditional forecasts_0'!$CW$6:$CW$553,$B6,'conditional forecasts_0'!$B$6:$B$553,"adm") -> 1775.8408 | H6: =SUMIFS('conditional forecasts_0'!I$6:I$553,'conditional forecasts_0'!$CW$6:$CW$553,$B6,'conditional forecasts_0'!$B$6:$B$553,"adm") -> 1796.2064 | I6: =SUMIFS('conditional forecasts_0'!J$6:J$553,'conditional forecasts_0'!$CW$6:$CW$553,$B6,'conditional forecasts_0'!$B$6:$B$553,"adm") -> 1710.8391 | J6: =SUMIFS('conditional forecasts_0'!K$6:K$553,'conditional forecasts_0'!$CW$6:$CW$553,$B6,'conditional forecasts_0'!$B$6:$B$553,"adm") -> 1688.6328 | ... CT6: =SUMIFS('conditional forecasts_0'!CU$6:CU$553,'conditional forecasts_0'!$CW$6:$CW$553,$B6,'conditional forecasts_0'!$B$6:$B$553,"adm") -> 738.59124
B7: 1201 | C7: =SUMIFS('conditional forecasts_0'!D$6:D$553,'conditional forecasts_0'!$CW$6:$CW$553,$B7,'conditional forecasts_0'!$B$6:$B$553,"adm") -> 117.23356 | D7: =SUMIFS('conditional forecasts_0'!E$6:E$553,'conditional forecasts_0'!$CW$6:$CW$553,$B7,'conditional forecasts_0'!$B$6:$B$553,"adm") -> 125.42947 | E7: =SUMIFS('conditional forecasts_0'!F$6:F$553,'conditional forecasts_0'!$CW$6:$CW$553,$B7,'conditional forecasts_0'!$B$6:$B$553,"adm") -> 166.59193 | F7: =SUMIFS('conditional forecasts_0'!G$6:G$553,'conditional forecasts_0'!$CW$6:$CW$553,$B7,'conditional forecasts_0'!$B$6:$B$553,"adm") -> 194.74557 | G7: =SUMIFS('conditional forecasts_0'!H$6:H$553,'conditional forecasts_0'!$CW$6:$CW$553,$B7,'conditional forecasts_0'!$B$6:$B$553,"adm") -> 220.19168 | H7: =SUMIFS('conditional forecasts_0'!I$6:I$553,'conditional forecasts_0'!$CW$6:$CW$553,$B7,'conditional forecasts_0'!$B$6:$B$553,"adm") -> 236.47094 | I7: =SUMIFS('conditional forecasts_0'!J$6:J$553,'conditional forecasts_0'!$CW$6:$CW$553,$B7,'conditional forecasts_0'!$B$6:$B$553,"adm") -> 219.56357 | J7: =SUMIFS('conditional forecasts_0'!K$6:K$553,'conditional forecasts_0'!$CW$6:$CW$553,$B7,'conditional forecasts_0'!$B$6:$B$553,"adm") -> 206.78142 | ... CT7: =SUMIFS('conditional forecasts_0'!CU$6:CU$553,'conditional forecasts_0'!$CW$6:$CW$553,$B7,'conditional forecasts_0'!$B$6:$B$553,"adm") -> 16.776869
B8: 1303 | C8: =SUMIFS('conditional forecasts_0'!D$6:D$553,'conditional forecasts_0'!$CW$6:$CW$553,$B8,'conditional forecasts_0'!$B$6:$B$553,"adm") -> 8814.2814 | D8: =SUMIFS('conditional forecasts_0'!E$6:E$553,'conditional forecasts_0'!$CW$6:$CW$553,$B8,'conditional forecasts_0'!$B$6:$B$553,"adm") -> 9374.7043 | E8: =SUMIFS('conditional forecasts_0'!F$6:F$553,'conditional forecasts_0'!$CW$6:$CW$553,$B8,'conditional forecasts_0'!$B$6:$B$553,"adm") -> 11539.764 | F8: =SUMIFS('conditional forecasts_0'!G$6:G$553,'conditional forecasts_0'!$CW$6:$CW$553,$B8,'conditional forecasts_0'!$B$6:$B$553,"adm") -> 11397.061 | G8: =SUMIFS('conditional forecasts_0'!H$6:H$553,'conditional forecasts_0'!$CW$6:$CW$553,$B8,'conditional forecasts_0'!$B$6:$B$553,"adm") -> 11362.832 | H8: =SUMIFS('conditional forecasts_0'!I$6:I$553,'conditional forecasts_0'!$CW$6:$CW$553,$B8,'conditional forecasts_0'!$B$6:$B$553,"adm") -> 11920.123 | I8: =SUMIFS('conditional forecasts_0'!J$6:J$553,'conditional forecasts_0'!$CW$6:$CW$553,$B8,'conditional forecasts_0'!$B$6:$B$553,"adm") -> 11281.972 | J8: =SUMIFS('conditional forecasts_0'!K$6:K$553,'conditional forecasts_0'!$CW$6:$CW$553,$B8,'conditional forecasts_0'!$B$6:$B$553,"adm") -> 11660.398 | ... CT8: =SUMIFS('conditional forecasts_0'!CU$6:CU$553,'conditional forecasts_0'!$CW$6:$CW$553,$B8,'conditional forecasts_0'!$B$6:$B$553,"adm") -> 6915.2416
B9: 1302 | C9: =SUMIFS('conditional forecasts_0'!D$6:D$553,'conditional forecasts_0'!$CW$6:$CW$553,$B9,'conditional forecasts_0'!$B$6:$B$553,"adm") -> 23.387857 | D9: =SUMIFS('conditional forecasts_0'!E$6:E$553,'conditional forecasts_0'!$CW$6:$CW$553,$B9,'conditional forecasts_0'!$B$6:$B$553,"adm") -> 22.996226 | E9: =SUMIFS('conditional forecasts_0'!F$6:F$553,'conditional forecasts_0'!$CW$6:$CW$553,$B9,'conditional forecasts_0'!$B$6:$B$553,"adm") -> 26.801023 | F9: =SUMIFS('conditional forecasts_0'!G$6:G$553,'conditional forecasts_0'!$CW$6:$CW$553,$B9,'conditional forecasts_0'!$B$6:$B$553,"adm") -> 26.204703 | G9: =SUMIFS('conditional forecasts_0'!H$6:H$553,'conditional forecasts_0'!$CW$6:$CW$553,$B9,'conditional forecasts_0'!$B$6:$B$553,"adm") -> 25.922107 | H9: =SUMIFS('conditional forecasts_0'!I$6:I$553,'conditional forecasts_0'!$CW$6:$CW$553,$B9,'conditional forecasts_0'!$B$6:$B$553,"adm") -> 27.749353 | I9: =SUMIFS('conditional forecasts_0'!J$6:J$553,'conditional forecasts_0'!$CW$6:$CW$553,$B9,'conditional forecasts_0'!$B$6:$B$553,"adm") -> 24.36331 | J9: =SUMIFS('conditional forecasts_0'!K$6:K$553,'conditional forecasts_0'!$CW$6:$CW$553,$B9,'conditional forecasts_0'!$B$6:$B$553,"adm") -> 24.980507 | ... CT9: =SUMIFS('conditional forecasts_0'!CU$6:CU$553,'conditional forecasts_0'!$CW$6:$CW$553,$B9,'conditional forecasts_0'!$B$6:$B$553,"adm") -> 10.513754
B10: 1304 | C10: =SUMIFS('conditional forecasts_0'!D$6:D$553,'conditional forecasts_0'!$CW$6:$CW$553,$B10,'conditional forecasts_0'!$B$6:$B$553,"adm") -> 79.06833 | D10: =SUMIFS('conditional forecasts_0'!E$6:E$553,'conditional forecasts_0'!$CW$6:$CW$553,$B10,'conditional forecasts_0'!$B$6:$B$553,"adm") -> 84.505061 | E10: =SUMIFS('conditional forecasts_0'!F$6:F$553,'conditional forecasts_0'!$CW$6:$CW$553,$B10,'conditional forecasts_0'!$B$6:$B$553,"adm") -> 98.387473 | F10: =SUMIFS('conditional forecasts_0'!G$6:G$553,'conditional forecasts_0'!$CW$6:$CW$553,$B10,'conditional forecasts_0'!$B$6:$B$553,"adm") -> 88.178726 | G10: =SUMIFS('conditional forecasts_0'!H$6:H$553,'conditional forecasts_0'!$CW$6:$CW$553,$B10,'conditional forecasts_0'!$B$6:$B$553,"adm") -> 86.029979 | H10: =SUMIFS('conditional forecasts_0'!I$6:I$553,'conditional forecasts_0'!$CW$6:$CW$553,$B10,'conditional forecasts_0'!$B$6:$B$553,"adm") -> 84.987352 | I10: =SUMIFS('conditional forecasts_0'!J$6:J$553,'conditional forecasts_0'!$CW$6:$CW$553,$B10,'conditional forecasts_0'!$B$6:$B$553,"adm") -> 77.533541 | J10: =SUMIFS('conditional forecasts_0'!K$6:K$553,'conditional forecasts_0'!$CW$6:$CW$553,$B10,'conditional forecasts_0'!$B$6:$B$553,"adm") -> 77.673038 | ... CT10: =SUMIFS('conditional forecasts_0'!CU$6:CU$553,'conditional forecasts_0'!$CW$6:$CW$553,$B10,'conditional forecasts_0'!$B$6:$B$553,"adm") -> 27.044281
B11: 1301 | C11: =SUMIFS('conditional forecasts_0'!D$6:D$553,'conditional forecasts_0'!$CW$6:$CW$553,$B11,'conditional forecasts_0'!$B$6:$B$553,"adm") -> 23.498568 | D11: =SUMIFS('conditional forecasts_0'!E$6:E$553,'conditional forecasts_0'!$CW$6:$CW$553,$B11,'conditional forecasts_0'!$B$6:$B$553,"adm") -> 26.862069 | E11: =SUMIFS('conditional forecasts_0'!F$6:F$553,'conditional forecasts_0'!$CW$6:$CW$553,$B11,'conditional forecasts_0'!$B$6:$B$553,"adm") -> 27.567616 | F11: =SUMIFS('conditional forecasts_0'!G$6:G$553,'conditional forecasts_0'!$CW$6:$CW$553,$B11,'conditional forecasts_0'!$B$6:$B$553,"adm") -> 21.202216 | G11: =SUMIFS('conditional forecasts_0'!H$6:H$553,'conditional forecasts_0'!$CW$6:$CW$553,$B11,'conditional forecasts_0'!$B$6:$B$553,"adm") -> 20.376514 | H11: =SUMIFS('conditional forecasts_0'!I$6:I$553,'conditional forecasts_0'!$CW$6:$CW$553,$B11,'conditional forecasts_0'!$B$6:$B$553,"adm") -> 25.802135 | I11: =SUMIFS('conditional forecasts_0'!J$6:J$553,'conditional forecasts_0'!$CW$6:$CW$553,$B11,'conditional forecasts_0'!$B$6:$B$553,"adm") -> 15.123014 | J11: =SUMIFS('conditional forecasts_0'!K$6:K$553,'conditional forecasts_0'!$CW$6:$CW$553,$B11,'conditional forecasts_0'!$B$6:$B$553,"adm") -> 17.710581 | ... CT11: =SUMIFS('conditional forecasts_0'!CU$6:CU$553,'conditional forecasts_0'!$CW$6:$CW$553,$B11,'conditional forecasts_0'!$B$6:$B$553,"adm") -> 20.931297
B12: 1401 | C12: =SUMIFS('conditional forecasts_0'!D$6:D$553,'conditional forecasts_0'!$CW$6:$CW$553,$B12,'conditional forecasts_0'!$B$6:$B$553,"adm") -> 1478.6558 | D12: =SUMIFS('conditional forecasts_0'!E$6:E$553,'conditional forecasts_0'!$CW$6:$CW$553,$B12,'conditional forecasts_0'!$B$6:$B$553,"adm") -> 1519.9108 | E12: =SUMIFS('conditional forecasts_0'!F$6:F$553,'conditional forecasts_0'!$CW$6:$CW$553,$B12,'conditional forecasts_0'!$B$6:$B$553,"adm") -> 1651.5941 | F12: =SUMIFS('conditional forecasts_0'!G$6:G$553,'conditional forecasts_0'!$CW$6:$CW$553,$B12,'conditional forecasts_0'!$B$6:$B$553,"adm") -> 1639.608 | G12: =SUMIFS('conditional forecasts_0'!H$6:H$553,'conditional forecasts_0'!$CW$6:$CW$553,$B12,'conditional forecasts_0'!$B$6:$B$553,"adm") -> 1631.2619 | H12: =SUMIFS('conditional forecasts_0'!I$6:I$553,'conditional forecasts_0'!$CW$6:$CW$553,$B12,'conditional forecasts_0'!$B$6:$B$553,"adm") -> 1693.4605 | I12: =SUMIFS('conditional forecasts_0'!J$6:J$553,'conditional forecasts_0'!$CW$6:$CW$553,$B12,'conditional forecasts_0'!$B$6:$B$553,"adm") -> 1632.0646 | J12: =SUMIFS('conditional forecasts_0'!K$6:K$553,'conditional forecasts_0'!$CW$6:$CW$553,$B12,'conditional forecasts_0'!$B$6:$B$553,"adm") -> 1647.4335 | ... CT12: =SUMIFS('conditional forecasts_0'!CU$6:CU$553,'conditional forecasts_0'!$CW$6:$CW$553,$B12,'conditional forecasts_0'!$B$6:$B$553,"adm") -> 1847.4427
B13: 1402 | C13: =SUMIFS('conditional forecasts_0'!D$6:D$553,'conditional forecasts_0'!$CW$6:$CW$553,$B13,'conditional forecasts_0'!$B$6:$B$553,"adm") -> 79.904152 | D13: =SUMIFS('conditional forecasts_0'!E$6:E$553,'conditional forecasts_0'!$CW$6:$CW$553,$B13,'conditional forecasts_0'!$B$6:$B$553,"adm") -> 71.593442 | E13: =SUMIFS('conditional forecasts_0'!F$6:F$553,'conditional forecasts_0'!$CW$6:$CW$553,$B13,'conditional forecasts_0'!$B$6:$B$553,"adm") -> 78.073587 | F13: =SUMIFS('conditional forecasts_0'!G$6:G$553,'conditional forecasts_0'!$CW$6:$CW$553,$B13,'conditional forecasts_0'!$B$6:$B$553,"adm") -> 75.839161 | G13: =SUMIFS('conditional forecasts_0'!H$6:H$553,'conditional forecasts_0'!$CW$6:$CW$553,$B13,'conditional forecasts_0'!$B$6:$B$553,"adm") -> 73.005585 | H13: =SUMIFS('conditional forecasts_0'!I$6:I$553,'conditional forecasts_0'!$CW$6:$CW$553,$B13,'conditional forecasts_0'!$B$6:$B$553,"adm") -> 72.982176 | I13: =SUMIFS('conditional forecasts_0'!J$6:J$553,'conditional forecasts_0'!$CW$6:$CW$553,$B13,'conditional forecasts_0'!$B$6:$B$553,"adm") -> 66.689126 | J13: =SUMIFS('conditional forecasts_0'!K$6:K$553,'conditional forecasts_0'!$CW$6:$CW$553,$B13,'conditional forecasts_0'!$B$6:$B$553,"adm") -> 63.554233 | ... CT13: =SUMIFS('conditional forecasts_0'!CU$6:CU$553,'conditional forecasts_0'!$CW$6:$CW$553,$B13,'conditional forecasts_0'!$B$6:$B$553,"adm") -> 29.570241
B14: 1504 | C14: =SUMIFS('conditional forecasts_0'!D$6:D$553,'conditional forecasts_0'!$CW$6:$CW$553,$B14,'conditional forecasts_0'!$B$6:$B$553,"adm") -> 1413.7969 | D14: =SUMIFS('conditional forecasts_0'!E$6:E$553,'conditional forecasts_0'!$CW$6:$CW$553,$B14,'conditional forecasts_0'!$B$6:$B$553,"adm") -> 1437.1135 | E14: =SUMIFS('conditional forecasts_0'!F$6:F$553,'conditional forecasts_0'!$CW$6:$CW$553,$B14,'conditional forecasts_0'!$B$6:$B$553,"adm") -> 1630.369 | F14: =SUMIFS('conditional forecasts_0'!G$6:G$553,'conditional forecasts_0'!$CW$6:$CW$553,$B14,'conditional forecasts_0'!$B$6:$B$553,"adm") -> 1627.6257 | G14: =SUMIFS('conditional forecasts_0'!H$6:H$553,'conditional forecasts_0'!$CW$6:$CW$553,$B14,'conditional forecasts_0'!$B$6:$B$553,"adm") -> 1557.8736 | H14: =SUMIFS('conditional forecasts_0'!I$6:I$553,'conditional forecasts_0'!$CW$6:$CW$553,$B14,'conditional forecasts_0'!$B$6:$B$553,"adm") -> 1576.5816 | I14: =SUMIFS('conditional forecasts_0'!J$6:J$553,'conditional forecasts_0'!$CW$6:$CW$553,$B14,'conditional forecasts_0'!$B$6:$B$553,"adm") -> 1404.4671 | J14: =SUMIFS('conditional forecasts_0'!K$6:K$553,'conditional forecasts_0'!$CW$6:$CW$553,$B14,'conditional forecasts_0'!$B$6:$B$553,"adm") -> 1467.9892 | ... CT14: =SUMIFS('conditional forecasts_0'!CU$6:CU$553,'conditional forecasts_0'!$CW$6:$CW$553,$B14,'conditional forecasts_0'!$B$6:$B$553,"adm") -> 781.34451
... B154: 5301 | C154: =SUMIFS('conditional forecasts_0'!D$6:D$553,'conditional forecasts_0'!$CW$6:$CW$553,$B154,'conditional forecasts_0'!$B$6:$B$553,"adm") -> 20670.754 | D154: =SUMIFS('conditional forecasts_0'!E$6:E$553,'conditional forecasts_0'!$CW$6:$CW$553,$B154,'conditional forecasts_0'!$B$6:$B$553,"adm") -> 21896.713 | E154: =SUMIFS('conditional forecasts_0'!F$6:F$553,'conditional forecasts_0'!$CW$6:$CW$553,$B154,'conditional forecasts_0'!$B$6:$B$553,"adm") -> 24156.379 | F154: =SUMIFS('conditional forecasts_0'!G$6:G$553,'conditional forecasts_0'!$CW$6:$CW$553,$B154,'conditional forecasts_0'!$B$6:$B$553,"adm") -> 24027.362 | G154: =SUMIFS('conditional forecasts_0'!H$6:H$553,'conditional forecasts_0'!$CW$6:$CW$553,$B154,'conditional forecasts_0'!$B$6:$B$553,"adm") -> 23437.136 | H154: =SUMIFS('conditional forecasts_0'!I$6:I$553,'conditional forecasts_0'!$CW$6:$CW$553,$B154,'conditional forecasts_0'!$B$6:$B$553,"adm") -> 23304.095 | I154: =SUMIFS('conditional forecasts_0'!J$6:J$553,'conditional forecasts_0'!$CW$6:$CW$553,$B154,'conditional forecasts_0'!$B$6:$B$553,"adm") -> 21518.991 | J154: =SUMIFS('conditional forecasts_0'!K$6:K$553,'conditional forecasts_0'!$CW$6:$CW$553,$B154,'conditional forecasts_0'!$B$6:$B$553,"adm") -> 20967.251 | ... CT154: =SUMIFS('conditional forecasts_0'!CU$6:CU$553,'conditional forecasts_0'!$CW$6:$CW$553,$B154,'conditional forecasts_0'!$B$6:$B$553,"adm") -> 12054.68

Sheet Des
B2: Mesoregiao | C2: 2017M1 | D2: 2017M2 | E2: 2017M3 | F2: 2017M4 | G2: 2017M5 | H2: 2017M6 | I2: 2017M7 | J2: 2017M8 | K2: 2017M9 | L2: 2017M10 | M2: 2017M11 | N2: 2017M12 | O2: 2018M1 | P2: 2018M2 | Q2: 2018M3 | R2: 2018M4 | S2: 2018M5 | T2: 2018M6 | U2: 2018M7 | V2: 2018M8 | W2: 2018M9 | X2: 2018M10 | Y2: 2018M11 | Z2: 2018M12 | AA2: 2019M1 | AB2: 2019M2 | AC2: 2019M3 | AD2: 2019M4 | AE2: 2019M5 | AF2: 2019M6 | AG2: 2019M7 | AH2: 2019M8 | AI2: 2019M9 | AJ2: 2019M10 | AK2: 2019M11 | AL2: 2019M12 | AM2: 2020M1 | AN2: 2020M2 | AO2: 2020M3 | AP2: 2020M4 | AQ2: 2020M5 | AR2: 2020M6 | AS2: 2020M7 | AT2: 2020M8 | AU2: 2020M9 | AV2: 2020M10 | AW2: 2020M11 | AX2: 2020M12 | AY2: 2021M1 | AZ2: 2021M2 | BA2: 2021M3 | BB2: 2021M4 | BC2: 2021M5 | BD2: 2021M6 | BE2: 2021M7 | BF2: 2021M8 | BG2: 2021M9 | BH2: 2021M10 | BI2: 2021M11 | BJ2: 2021M12 | BK2: 2022M1 | BL2: 2022M2 | BM2: 2022M3 | BN2: 2022M4 | BO2: 2022M5 | BP2: 2022M6 | BQ2: 2022M7 | BR2: 2022M8 | BS2: 2022M9 | BT2: 2022M10 | BU2: 2022M11 | BV2: 2022M12 | BW2: 2023M1 | BX2: 2023M2 | BY2: 2023M3 | BZ2: 2023M4 | CA2: 2023M5 | CB2: 2023M6 | CC2: 2023M7 | CD2: 2023M8 | CE2: 2023M9 | CF2: 2023M10 | CG2: 2023M11 | CH2: 2023M12 | CI2: 2024M1 | CJ2: 2024M2 | CK2: 2024M3 | CL2: 2024M4 | CM2: 2024M5 | CN2: 2024M6 | CO2: 2024M7 | CP2: 2024M8 | CQ2: 2024M9 | CR2: 2024M10 | CS2: 2024M11 | CT2: 2024M12
B3: 1102 | C3: =SUMIFS('conditional forecasts_0'!D$6:D$553,'conditional forecasts_0'!$CW$6:$CW$553,$B3,'conditional forecasts_0'!$B$6:$B$553,"desl") -> 4963.0991 | D3: =SUMIFS('conditional forecasts_0'!E$6:E$553,'conditional forecasts_0'!$CW$6:$CW$553,$B3,'conditional forecasts_0'!$B$6:$B$553,"desl") -> 4931.8561 | E3: =SUMIFS('conditional forecasts_0'!F$6:F$553,'conditional forecasts_0'!$CW$6:$CW$553,$B3,'conditional forecasts_0'!$B$6:$B$553,"desl") -> 5459.9551 | F3: =SUMIFS('conditional forecasts_0'!G$6:G$553,'conditional forecasts_0'!$CW$6:$CW$553,$B3,'conditional forecasts_0'!$B$6:$B$553,"desl") -> 5121.6489 | G3: =SUMIFS('conditional forecasts_0'!H$6:H$553,'conditional forecasts_0'!$CW$6:$CW$553,$B3,'conditional forecasts_0'!$B$6:$B$553,"desl") -> 5334.3733 | H3: =SUMIFS('conditional forecasts_0'!I$6:I$553,'conditional forecasts_0'!$CW$6:$CW$553,$B3,'conditional forecasts_0'!$B$6:$B$553,"desl") -> 4851.9846 | I3: =SUMIFS('conditional forecasts_0'!J$6:J$553,'conditional forecasts_0'!$CW$6:$CW$553,$B3,'conditional forecasts_0'!$B$6:$B$553,"desl") -> 4867.9636 | J3: =SUMIFS('conditional forecasts_0'!K$6:K$553,'conditional forecasts_0'!$CW$6:$CW$553,$B3,'conditional forecasts_0'!$B$6:$B$553,"desl") -> 5008.9333 | ... CT3: =SUMIFS('conditional forecasts_0'!CU$6:CU$553,'conditional forecasts_0'!$CW$6:$CW$553,$B3,'conditional forecasts_0'!$B$6:$B$553,"desl") -> 3151.5013
B4: 1101 | C4: =SUMIFS('conditional forecasts_0'!D$6:D$553,'conditional forecasts_0'!$CW$6:$CW$553,$B4,'conditional forecasts_0'!$B$6:$B$553,"desl") -> 3096.6012 | D4: =SUMIFS('conditional forecasts_0'!E$6:E$553,'conditional forecasts_0'!$CW$6:$CW$553,$B4,'conditional forecasts_0'!$B$6:$B$553,"desl") -> 3063.6978 | E4: =SUMIFS('conditional forecasts_0'!F$6:F$553,'conditional forecasts_0'!$CW$6:$CW$553,$B4,'conditional forecasts_0'!$B$6:$B$553,"desl") -> 3312.137 | F4: =SUMIFS('conditional forecasts_0'!G$6:G$553,'conditional forecasts_0'!$CW$6:$CW$553,$B4,'conditional forecasts_0'!$B$6:$B$553,"desl") -> 3340.5202 | G4: =SUMIFS('conditional forecasts_0'!H$6:H$553,'conditional forecasts_0'!$CW$6:$CW$553,$B4,'conditional forecasts_0'!$B$6:$B$553,"desl") -> 3591.1785 | H4: =SUMIFS('conditional forecasts_0'!I$6:I$553,'conditional forecasts_0'!$CW$6:$CW$553,$B4,'conditional forecasts_0'!$B$6:$B$553,"desl") -> 3489.4544 | I4: =SUMIFS('conditional forecasts_0'!J$6:J$553,'conditional forecasts_0'!$CW$6:$CW$553,$B4,'conditional forecasts_0'!$B$6:$B$553,"desl") -> 3600.5181 | J4: =SUMIFS('conditional forecasts_0'!K$6:K$553,'conditional forecasts_0'!$CW$6:$CW$553,$B4,'conditional forecasts_0'!$B$6:$B$553,"desl") -> 3591.3097 | ... CT4: =SUMIFS('conditional forecasts_0'!CU$6:CU$553,'conditional forecasts_0'!$CW$6:$CW$553,$B4,'conditional forecasts_0'!$B$6:$B$553,"desl") -> 972.60755
B5: 1100 | C5: =SUMIFS('conditional forecasts_0'!D$6:D$553,'conditional forecasts_0'!$CW$6:$CW$553,$B5,'conditional forecasts_0'!$B$6:$B$553,"desl") -> 0 | D5: =SUMIFS('conditional forecasts_0'!E$6:E$553,'conditional forecasts_0'!$CW$6:$CW$553,$B5,'conditional forecasts_0'!$B$6:$B$553,"desl") -> 0 | E5: =SUMIFS('conditional forecasts_0'!F$6:F$553,'conditional forecasts_0'!$CW$6:$CW$553,$B5,'conditional forecasts_0'!$B$6:$B$553,"desl") -> 0 | F5: =SUMIFS('conditional forecasts_0'!G$6:G$553,'conditional forecasts_0'!$CW$6:$CW$553,$B5,'conditional forecasts_0'!$B$6:$B$553,"desl") -> 0 | G5: =SUMIFS('conditional forecasts_0'!H$6:H$553,'conditional forecasts_0'!$CW$6:$CW$553,$B5,'conditional forecasts_0'!$B$6:$B$553,"desl") -> 0 | H5: =SUMIFS('conditional forecasts_0'!I$6:I$553,'conditional forecasts_0'!$CW$6:$CW$553,$B5,'conditional forecasts_0'!$B$6:$B$553,"desl") -> 0 | I5: =SUMIFS('conditional forecasts_0'!J$6:J$553,'conditional forecasts_0'!$CW$6:$CW$553,$B5,'conditional forecasts_0'!$B$6:$B$553,"desl") -> 0 | J5: =SUMIFS('conditional forecasts_0'!K$6:K$553,'conditional forecasts_0'!$CW$6:$CW$553,$B5,'conditional forecasts_0'!$B$6:$B$553,"desl") -> 0 | ... CT5: =SUMIFS('conditional forecasts_0'!CU$6:CU$553,'conditional forecasts_0'!$CW$6:$CW$553,$B5,'conditional forecasts_0'!$B$6:$B$553,"desl") -> 0
