Workbook

Sheet forecasts (2)
A1: GVAR Forecasts
A2: Last in-sample estimation date: | B2: 2016M12
A3: Last forecast date: | B3: 2024M12
D5: 2017M1 | E5: 2017M2 | F5: 2017M3 | G5: 2017M4 | H5: 2017M5 | I5: 2017M6 | J5: 2017M7 | K5: 2017M8 | L5: 2017M9 | M5: 2017M10 | N5: 2017M11 | O5: 2017M12 | P5: 2018M1 | Q5: 2018M2 | R5: 2018M3 | S5: 2018M4 | T5: 2018M5 | U5: 2018M6 | V5: 2018M7 | W5: 2018M8 | X5: 2018M9 | Y5: 2018M10 | Z5: 2018M11 | AA5: 2018M12 | AB5: 2019M1 | AC5: 2019M2 | AD5: 2019M3 | AE5: 2019M4 | AF5: 2019M5 | AG5: 2019M6 | AH5: 2019M7 | AI5: 2019M8 | AJ5: 2019M9 | AK5: 2019M10 | AL5: 2019M11 | AM5: 2019M12 | AN5: 2020M1 | AO5: 2020M2 | AP5: 2020M3 | AQ5: 2020M4 | AR5: 2020M5 | AS5: 2020M6 | AT5: 2020M7 | AU5: 2020M8 | AV5: 2020M9 | AW5: 2020M10 | AX5: 2020M11 | AY5: 2020M12 | AZ5: 2021M1 | BA5: 2021M2 | BB5: 2021M3 | BC5: 2021M4 | BD5: 2021M5 | BE5: 2021M6 | BF5: 2021M7 | BG5: 2021M8 | BH5: 2021M9 | BI5: 2021M10 | BJ5: 2021M11 | BK5: 2021M12 | BL5: 2022M1 | BM5: 2022M2 | BN5: 2022M3 | BO5: 2022M4 | BP5: 2022M5 | BQ5: 2022M6 | BR5: 2022M7 | BS5: 2022M8 | BT5: 2022M9 | BU5: 2022M10 | BV5: 2022M11 | BW5: 2022M12 | BX5: 2023M1 | BY5: 2023M2 | BZ5: 2023M3 | CA5: 2023M4 | CB5: 2023M5 | CC5: 2023M6 | CD5: 2023M7 | CE5: 2023M8 | CF5: 2023M9 | CG5: 2023M10 | CH5: 2023M11 | CI5: 2023M12 | CJ5: 2024M1 | CK5: 2024M2 | CL5: 2024M3 | CM5: 2024M4 | CN5: 2024M5 | CO5: 2024M6 | CP5: 2024M7 | CQ5: 2024M8 | CR5: 2024M9 | CS5: 2024M10 | CT5: 2024M11 | CU5: 2024M12
A6: Ro1101 | B6: adm | C6: Forecast | D6: 2336.9808 | E6: 2312.3801 | F6: 2657.806 | G6: 2863.4845 | H6: 2929.8957 | I6: 2932.1209 | J6: 2722.6753 | K6: 2533.8324 | L6: 2267.0652 | M6: 2069.9615 | N6: 1943.9223 | O6: 1881.0981 | P6: 1905.1517 | Q6: 1947.7631 | R6: 2016.3741 | S6: 2065.4142 | T6: 2086.708 | U6: 2079.0643 | V6: 2038.9515 | W6: 1987.4013 | X6: 1929.4789 | Y6: 1881.6535 | Z6: 1850.2302 | AA6: 1837.4009 | AB6: 1843.2285 | AC6: 1859.8933 | AD6: 1882.0422 | AE6: 1901.8471 | AF6: 1914.9245 | AG6: 1919.5119 | AH6: 1915.9575 | AI6: 1907.6058 | AJ6: 1897.7589 | AK6: 1890.1217 | AL6: 1886.9702 | AM6: 1889.1262 | AN6: 1896.1482 | AO6: 1906.3751 | AP6: 1917.9433 | AQ6: 1928.9859 | AR6: 1938.2634 | AS6: 1945.2694 | AT6: 1950.1712 | AU6: 1953.7006 | AV6: 1956.7748 | AW6: 1960.3005 | AX6: 1964.9103 | AY6: 1970.8715 | AZ6: 1978.094 | BA6: 1986.2009 | BB6: 1994.6927 | BC6: 2003.0766 | BD6: 2010.9946 | BE6: 2018.2818 | BF6: 2024.9663 | BG6: 2031.2278 | BH6: 2037.3166 | BI6: 2043.4797 | BJ6: 2049.897 | BK6: 2056.6493 | BL6: 2063.7177 | BM6: 2071.007 | BN6: 2078.3845 | BO6: 2085.7193 | BP6: 2092.9142 | BQ6: 2099.9224 | BR6: 2106.7487 | BS6: 2113.4378 | BT6: 2120.0552 | BU6: 2126.6669 | BV6: 2133.3228 | BW6: 2140.0476 | BX6: 2146.8394 | BY6: 2153.6756 | BZ6: 2160.5221 | CA6: 2167.3444 | CB6: 2174.116 | CC6: 2180.8235 | CD6: 2187.4673 | CE6: 2194.0589 | CF6: 2200.6161 | CG6: 2207.1569 | CH6: 2213.6957 | CI6: 2220.2402 | CJ6: 2226.7906 | CK6: 2233.342 | CL6: 2239.8857 | CM6: 2246.4129 | CN6: 2252.9167 | CO6: 2259.3936 | CP6: 2265.8438 | CQ6: 2272.2704 | CR6: 2278.6783 | CS6: 2285.0727 | CT6: 2291.4578 | CU6: 2297.8361 | CV6: 1 | CW6: 1
C7: Actual | CV7: 0 | CW7: 0
A8: Ro1101 | B8: desl | C8: Forecast | D8: 3171.6865 | E8: 3043.8417 | F8: 3116.1931 | G8: 3065.1451 | H8: 3169.497 | I8: 3103.7389 | J8: 3063.4059 | K8: 2947.4825 | L8: 2780.9638 | M8: 2634.6895 | N8: 2467.2418 | O8: 2364.64 | P8: 2288.1828 | Q8: 2256.2625 | R8: 2252.0299 | S8: 2248.9762 | T8: 2248.137 | U8: 2226.0539 | V8: 2191.5499 | W8: 2143.0077 | X8: 2087.8574 | Y8: 2035.4439 | Z8: 1987.8242 | AA8: 1951.5844 | AB8: 1925.0338 | AC8: 1908.0051 | AD8: 1897.5939 | AE8: 1889.9574 | AF8: 1882.8145 | AG8: 1873.1463 | AH8: 1860.4555 | AI8: 1844.6843 | AJ8: 1827.0799 | AK8: 1809.5083 | AL8: 1793.4999 | AM8: 1780.4554 | AN8: 1770.7296 | AO8: 1764.1112 | AP8: 1759.7735 | AQ8: 1756.6334 | AR8: 1753.7581 | AS8: 1750.4382 | AT8: 1746.4344 | AU8: 1741.8373 | AV8: 1737.0084 | AW8: 1732.417 | AX8: 1728.4772 | AY8: 1725.4835 | AZ8: 1723.532 | BA8: 1722.5535 | BB8: 1722.3474 | BC8: 1722.6523 | BD8: 1723.2192 | BE8: 1723.8583 | BF8: 1724.4765 | BG8: 1725.0741 | BH8: 1725.7265 | BI8: 1726.5477 | BJ8: 1727.6505 | BK8: 1729.1169 | BL8: 1730.9787 | BM8: 1733.2179 | BN8: 1735.7777 | BO8: 1738.5823 | BP8: 1741.5578 | BQ8: 1744.6478 | BR8: 1747.8225 | BS8: 1751.0782 | BT8: 1754.4315 | BU8: 1757.9092 | BV8: 1761.5382 | BW8: 1765.3371 | BX8: 1769.3123 | BY8: 1773.4571 | BZ8: 1777.755 | CA8: 1782.1842 | CB8: 1786.7229 | CC8: 1791.3532 | CD8: 1796.0644 | CE8: 1800.8524 | CF8: 1805.719 | CG8: 1810.6691 | CH8: 1815.7081 | CI8: 1820.8396 | CJ8: 1826.0638 | CK8: 1831.3776 | CL8: 1836.7753 | CM8: 1842.2494 | CN8: 1847.7927 | CO8: 1853.3987 | CP8: 1859.063 | CQ8: 1864.7831 | CR8: 1870.5582 | CS8: 1876.3881 | CT8: 1882.2732 | CU8: 1888.2132 | CV8: -1 | CW8: 1
C9: Actual | CV9: 0 | CW9: 0
A10: Ro1102 | B10: adm | C10: Forecast | D10: 4137.5519 | E10: 4444.5537 | F10: 5010.4524 | G10: 5191.2041 | H10: 5154.9613 | I10: 5075.0248 | J10: 4758.7789 | K10: 4580.7946 | L10: 4351.9333 | M10: 4251.2794 | N10: 4238.3129 | O10: 4269.8338 | P10: 4372.4476 | Q10: 4442.5826 | R10: 4507.4578 | S10: 4517.8557 | T10: 4483.2062 | U10: 4419.6918 | V10: 4331.3627 | W10: 4252.5203 | X10: 4184.8822 | Y10: 4143.3702 | Z10: 4125.8544 | AA10: 4125.7486 | AB10: 4137.6964 | AC10: 4149.0379 | AD10: 4155.3258 | AE10: 4150.7121 | AF10: 4135.0917 | AG10: 4111.0759 | AH10: 4082.0784 | AI10: 4053.5659 | AJ10: 4028.8044 | AK10: 4010.5231 | AL10: 3999.0752 | AM10: 3993.216 | AN10: 3990.8947 | AO10: 3989.4078 | AP10: 3986.7774 | AQ10: 3981.636 | AR10: 3973.7276 | AS10: 3963.6517 | AT10: 3952.492 | AU10: 3941.5596 | AV10: 3931.8848 | AW10: 3924.1209 | AX10: 3918.3927 | AY10: 3914.3907 | AZ10: 3911.5419 | BA10: 3909.1731 | BB10: 3906.7224 | BC10: 3903.8274 | BD10: 3900.3855 | BE10: 3896.5214 | BF10: 3892.5063 | BG10: 3888.6668 | BH10: 3885.2843 | BI10: 3882.5373 | BJ10: 3880.4715 | BK10: 3879.0132 | BL10: 3878.0092 | BM10: 3877.2768 | BN10: 3876.6547 | BO10: 3876.036 | BP10: 3875.3823 | BQ10: 3874.7183 | BR10: 3874.1109 | BS10: 3873.6432 | BT10: 3873.3883 | BU10: 3873.3924 | BV10: 3873.6669 | BW10: 3874.1912 | BX10: 3874.9229 | BY10: 3875.8111 | BZ10: 3876.8093 | CA10: 3877.8852 | CB10: 3879.0243 | CC10: 3880.2289 | CD10: 3881.5134 | CE10: 3882.897 | CF10: 3884.3974 | CG10: 3886.0252 | CH10: 3887.7824 | CI10: 3889.6621 | CJ10: 3891.6515 | CK10: 3893.7352 | CL10: 3895.8988 | CM10: 3898.1315 | CN10: 3900.4272 | CO10: 3902.7845 | CP10: 3905.2054 | CQ10: 3907.6934 | CR10: 3910.2518 | CS10: 3912.8823 | CT10: 3915.584 | CU10: 3918.354 | CV10: 1 | CW10: 1
C11: Actual | CV11: 0 | CW11: 0
A12: Ro1102 | B12: desl | C12: Forecast | D12: 5184.4937 | E12: 5069.5182 | F12: 5288.3821 | G12: 5045.6956 | H12: 5145.1068 | I12: 4969.0827 | J12: 4867.0074 | K12: 4829.8545 | L12: 4688.2598 | M12: 4682.2469 | N12: 4608.8389 | O12: 4611.118 | P12: 4607.9062 | Q12: 4589.6876 | R12: 4581.2162 | S12: 4527.0458 | T12: 4478.1086 | U12: 4409.0183 | V12: 4345.4879 | W12: 4294.0142 | X12: 4249.7012 | Y12: 4223.2032 | Z12: 4199.7286 | AA12: 4182.3558 | AB12: 4163.8526 | AC12: 4142.3055 | AD12: 4118.9745 | AE12: 4091.6344 | AF12: 4063.8673 | AG12: 4035.2449 | AH12: 4007.8111 | AI12: 3982.5532 | AJ12: 3959.7141 | AK12: 3940.1412 | AL12: 3922.9989 | AM12: 3907.994 | AN12: 3894.0468 | AO12: 3880.3084 | AP12: 3866.2975 | AQ12: 3851.6823 | AR12: 3836.7818 | AS12: 3821.9481 | AT12: 3807.7321 | AU12: 3794.5459 | AV12: 3782.5806 | AW12: 3771.8658 | AX12: 3762.1985 | AY12: 3753.3371 | AZ12: 3745.0056 | BA12: 3736.9946 | BB12: 3729.1884 | BC12: 3721.5492 | BD12: 3714.1261 | BE12: 3707.0007 | BF12: 3700.2734 | BG12: 3694.027 | BH12: 3688.3083 | BI12: 3683.1239 | BJ12: 3678.436 | BK12: 3674.1811 | BL12: 3670.283 | BM12: 3666.6725 | BN12: 3663.3011 | BO12: 3660.1458 | BP12: 3657.2087 | BQ12: 3654.5077 | BR12: 3652.0671 | BS12: 3649.9068 | BT12: 3648.0358 | BU12: 3646.4499 | BV12: 3645.1334 | BW12: 3644.063 | BX12: 3643.2136 | BY12: 3642.5625 | BZ12: 3642.093 | CA12: 3641.795 | CB12: 3641.6644 | CC12: 3641.7017 | CD12: 3641.9087 | CE12: 3642.2868 | CF12: 3642.835 | CG12: 3643.5494 | CH12: 3644.423 | CI12: 3645.4468 | CJ12: 3646.6113 | CK12: 3647.9072 | CL12: 3649.327 | CM12: 3650.8649 | CN12: 3652.5172 | CO12: 3654.2813 | CP12: 3656.1554 | CQ12: 3658.1376 | CR12: 3660.2254 | CS12: 3662.4157 | CT12: 3664.7045 | CU12: 3667.0874 | CV12: -1 | CW12: 1
C13: Actual | CV13: 0 | CW13: 0
A14: Ac1201 | B14: adm | C14: Forecast | D14: 115.87824 | E14: 122.22568 | F14: 159.99944 | G14: 189.92608 | H14: 210.50288 | I14: 226.23131 | J14: 218.50408 | K14: 205.81668 | L14: 181.40742 | M14: 158.0026 | N14: 138.97397 | O14: 125.71312 | P14: 122.84775 | Q14: 125.51348 | R14: 133.57703 | S14: 141.99013 | T14: 148.14426 | U14: 150.63869 | V14: 148.30071 | W14: 142.84803 | X14: 135.28814 | Y14: 127.7757 | Z14: 121.66734 | AA14: 117.66068 | AB14: 116.03535 | AC14: 116.13942 | AD14: 117.33725 | AE14: 118.70458 | AF14: 119.56194 | AG14: 119.50974 | AH14: 118.40103 | AI14: 116.45363 | AJ14: 113.99433 | AK14: 111.46699 | AL14: 109.24536 | AM14: 107.57015 | AN14: 106.52701 | AO14: 106.02251 | AP14: 105.87051 | AQ14: 105.83219 | AR14: 105.69973 | AS14: 105.33967 | AT14: 104.70869 | AU14: 103.85308 | AV14: 102.87155 | AW14: 101.8845 | AX14: 100.99608 | AY14: 100.27196 | AZ14: 99.731655 | BA14: 99.351461 | BB14: 99.08057 | BC14: 98.857533 | BD14: 98.627801 | BE14: 98.355183 | BF14: 98.026585 | BG14: 97.650811 | BH14: 97.251603 | BI14: 96.859044 | BJ14: 96.500626 | BK14: 96.194829 | BL14: 95.948143 | BM14: 95.755511 | BN14: 95.603725 | BO14: 95.476077 | BP14: 95.357097 | BQ14: 95.236017 | BR14: 95.108388 | BS14: 94.975818 | BT14: 94.844219 | BU14: 94.721368 | BV14: 94.61447 | BW14: 94.52838 | BX14: 94.464764 | BY14: 94.422213 | BZ14: 94.397113 | CA14: 94.384868 | CB14: 94.381135 | CC14: 94.38275 | CD14: 94.388186 | CE14: 94.397522 | CF14: 94.412026 | CG14: 94.43353 | CH14: 94.463796 | CI14: 94.504015 | CJ14: 94.554559 | CK14: 94.614978 | CL14: 94.684206 | CM14: 94.760887 | CN14: 94.843704 | CO14: 94.931637 | CP14: 95.024109 | CQ14: 95.120976 | CR14: 95.222433 | CS14: 95.328844 | CT14: 95.44057 | CU14: 95.557835 | CV14: 1 | CW14: 1
C15: Actual | CV15: 0 | CW15: 0
A16: Ac1201 | B16: desl | C16: Forecast | D16: 204.3715 | E16: 170.28649 | F16: 161.97532 | G16: 145.91385 | H16: 145.94902 | I16: 145.11911 | J16: 150.91298 | K16: 157.89436 | L16: 159.75952 | M16: 161.99066 | N16: 157.72249 | O16: 152.39984 | P16: 145.0417 | Q16: 137.75736 | R16: 132.59744 | S16: 128.57336 | T16: 126.9994 | U16: 126.21613 | V16: 126.07451 | W16: 125.82973 | X16: 124.87459 | Y16: 123.39798 | Z16: 121.13125 | AA16: 118.52404 | AB16: 115.71102 | AC16: 112.97752 | AD16: 110.58109 | AE16: 108.5705 | AF16: 107.04709 | AG16: 105.88467 | AH16: 104.97474 | AI16: 104.14976 | AJ16: 103.25629 | AK16: 102.22397 | AL16: 101.01646 | AM16: 99.689833 | AN16: 98.319508 | AO16: 96.996808 | AP16: 95.79619 | AQ16: 94.751355 | AR16: 93.867019 | AS16: 93.111718 | AT16: 92.442649 | AU16: 91.81393 | AV16: 91.189101 | AW16: 90.549071 | AX16: 89.889629 | AY16: 89.221697 | AZ16: 88.563275 | BA16: 87.934657 | BB16: 87.352776 | BC16: 86.827188 | BD16: 86.359531 | BE16: 85.943634 | BF16: 85.568631 | BG16: 85.221994 | BH16: 84.892769 | BI16: 84.573915 | BJ16: 84.262989 | BK16: 83.961829 | BL16: 83.674941 | BM16: 83.407677 | BN16: 83.164502 | BO16: 82.947833 | BP16: 82.757708 | BQ16: 82.592062 | BR16: 82.447536 | BS16: 82.320412 | BT16: 82.207447 | BU16: 82.106432 | BV16: 82.016374 | BW16: 81.937365 | BX16: 81.87021 | BY16: 81.815967 | BZ16: 81.775525 | CA16: 81.749298 | CB16: 81.73711 | CC16: 81.738238 | CD16: 81.751592 | CE16: 81.775957 | CF16: 81.810217 | CG16: 81.853521 | CH16: 81.905353 | CI16: 81.965505 | CJ16: 82.033989 | CK16: 82.110902 | CL16: 82.196313 | CM16: 82.29017 | CN16: 82.39227 | CO16: 82.502265 | CP16: 82.619712 | CQ16: 82.744138 | CR16: 82.875096 | CS16: 83.012217 | CT16: 83.155221 | CU16: 83.303916 | CV16: -1 | CW16: 1
C17: Actual | CV17: 0 | CW17: 0
A18: Ac1202 | B18: adm | C18: Forecast | D18: 1346.32 | E18: 1379.2961 | F18: 1523.3626 | G18: 1628.7088 | H18: 1634.9611 | I18: 1628.978 | J18: 1538.0996 | K18: 1470.9891 | L18: 1388.7794 | M18: 1335.1077 | N18: 1314.4614 | O18: 1308.902 | P18: 1330.1977 | Q18: 1349.1277 | R18: 1370.5834 | S18: 1381.8493 | T18: 1380.4775 | U18: 1370.1813 | V18: 1349.2702 | W18: 1326.6261 | X18: 1303.7347 | Y18: 1285.6809 | Z18: 1274.3994 | AA18: 1269.3067 | AB18: 1270.0246 | AC18: 1273.0605 | AD18: 1276.4329 | AE18: 1277.6826 | AF18: 1275.6965 | AG18: 1270.6203 | AH18: 1263.0616 | AI18: 1254.591 | AJ18: 1246.4259 | AK18: 1239.6864 | AL18: 1234.8911 | AM18: 1231.9775 | AN18: 1230.5615 | AO18: 1229.9264 | AP18: 1229.4268 | AQ18: 1228.5131 | AR18: 1226.8964 | AS18: 1224.5594 | AT18: 1221.6776 | AU18: 1218.5796 | AV18: 1215.6 | AW18: 1213.022 | AX18: 1211.0043 | AY18: 1209.5644 | AZ18: 1208.6059 | BA18: 1207.9539 | BB18: 1207.4207 | BC18: 1206.8493 | BD18: 1206.1481 | BE18: 1205.3008 | BF18: 1204.3526 | BG18: 1203.3883 | BH18: 1202.5001 | BI18: 1201.7634 | BJ18: 1201.2207 | BK18: 1200.8765 | BL18: 1200.7039 | BM18: 1200.6563 | BN18: 1200.6827 | BO18: 1200.7402 | BP18: 1200.8022 | BQ18: 1200.8614 | BR18: 1200.927 | BS18: 1201.0188 | BT18: 1201.1598 | BU18: 1201.3693 | BV18: 1201.6585 | BW18: 1202.0288 | BX18: 1202.4729 | BY18: 1202.978 | BZ18: 1203.5294 | CA18: 1204.1143 | CB18: 1204.7243 | CC18: 1205.356 | CD18: 1206.0108 | CE18: 1206.693 | CF18: 1207.4081 | CG18: 1208.1605 | CH18: 1208.9527 | CI18: 1209.7847 | CJ18: 1210.6539 | CK18: 1211.5565 | CL18: 1212.4879 | CM18: 1213.4442 | CN18: 1214.4223 | CO18: 1215.4208 | CP18: 1216.4394 | CQ18: 1217.4787 | CR18: 1218.5396 | CS18: 1219.6228 | CT18: 1220.7286 | CU18: 1221.8566 | CV18: 1 | CW18: 1
C19: Actual | CV19: 0 | CW19: 0
A20: Ac1202 | B20: desl | C20: Forecast | D20: 1851.9404 | E20: 1770.2276 | F20: 1801.1693 | G20: 1630.3924 | H20: 1670.5878 | I20: 1596.3179 | J20: 1585.1338 | K20: 1583.7567 | L20: 1538.2506 | M20: 1542.7769 | N20: 1503.8192 | O20: 1497.6911 | P20: 1483.9862 | Q20: 1471.3549 | R20: 1466.9974 | S20: 1447.9043 | T20: 1435.3893 | U20: 1414.0148 | V20: 1395.5055 | W20: 1379.4823 | X20: 1364.6289 | Y20: 1355.4971 | Z20: 1346.0305 | AA20: 1338.7289 | AB20: 1330.4955 | AC20: 1321.4853 | AD20: 1312.3682 | AE20: 1302.4208 | AF20: 1293.1615 | AG20: 1283.984 | AH20: 1275.4874 | AI20: 1267.5831 | AJ20: 1260.1413 | AK20: 1253.409 | AL20: 1247.1025 | AM20: 1241.3499 | AN20: 1235.925 | AO20: 1230.7126 | AP20: 1225.6237 | AQ20: 1220.5406 | AR20: 1215.5376 | AS20: 1210.6451 | AT20: 1205.986 | AU20: 1201.6371 | AV20: 1197.6308 | AW20: 1193.9708 | AX20: 1190.597 | AY20: 1187.4572 | AZ20: 1184.4887 | BA20: 1181.6535 | BB20: 1178.9357 | BC20: 1176.3321 | BD20: 1173.8567 | BE20: 1171.5212 | BF20: 1169.3398 | BG20: 1167.3202 | BH20: 1165.4645 | BI20: 1163.7693 | BJ20: 1162.2247 | BK20: 1160.818 | BL20: 1159.5341 | BM20: 1158.3593 | BN20: 1157.2833 | BO20: 1156.3002 | BP20: 1155.4088 | BQ20: 1154.6105 | BR20: 1153.9081 | BS20: 1153.3036 | BT20: 1152.7966 | BU20: 1152.3842 | BV20: 1152.0616 | BW20: 1151.8227 | BX20: 1151.6613 | BY20: 1151.5723 | BZ20: 1151.5515 | CA20: 1151.5961 | CB20: 1151.7046 | CC20: 1151.8758 | CD20: 1152.109 | CE20: 1152.403 | CF20: 1152.7565 | CG20: 1153.1676 | CH20: 1153.6339 | CI20: 1154.1528 | CJ20: 1154.7216 | CK20: 1155.338 | CL20: 1155.9996 | CM20: 1156.7048 | CN20: 1157.4519 | CO20: 1158.24 | CP20: 1159.0678 | CQ20: 1159.9343 | CR20: 1160.8384 | CS20: 1161.7787 | CT20: 1162.7539 | CU20: 1163.7625 | CV20: -1 | CW20: 1
C21: Actual | CV21: 0 | CW21: 0
A22: Am1301 | B22: adm | C22: Forecast | D22: 20.57114 | E22: 27.653351 | F22: 33.591843 | G22: 30.158634 | H22: 26.779868 | I22: 28.438469 | J22: 24.279521 | K22: 26.136799 | L22: 25.028429 | M22: 25.367057 | N22: 25.860524 | O22: 24.953484 | P22: 25.352419 | Q22: 24.520757 | R22: 24.51491 | S22: 24.217185 | T22: 23.85015 | U22: 23.717568 | V22: 23.221395 | W22: 22.999849 | X22: 22.634648 | Y22: 22.408494 | Z22: 22.271379 | AA22: 22.122016 | AB22: 22.057999 | AC22: 21.905742 | AD22: 21.754442 | AE22: 21.552719 | AF22: 21.330705 | AG22: 21.127338 | AH22: 20.926516 | AI22: 20.766072 | AJ22: 20.61969 | AK22: 20.492911 | AL22: 20.375691 | AM22: 20.258607 | AN22: 20.146251 | AO22: 20.030415 | AP22: 19.916331 | AQ22: 19.801317 | AR22: 19.686505 | AS22: 19.574055 | AT22: 19.464066 | AU22: 19.360134 | AV22: 19.262492 | AW22: 19.172208 | AX22: 19.088399 | AY22: 19.009192 | AZ22: 18.933055 | BA22: 18.858051 | BB22: 18.783666 | BC22: 18.709793 | BD22: 18.637095 | BE22: 18.566502 | BF22: 18.498686 | BG22: 18.434169 | BH22: 18.372949 | BI22: 18.31482 | BJ22: 18.259367 | BK22: 18.206127 | BL22: 18.154724 | BM22: 18.104844 | BN22: 18.056328 | BO22: 18.009115 | BP22: 17.963247 | BQ22: 17.91883 | BR22: 17.87598 | BS22: 17.834797 | BT22: 17.795311 | BU22: 17.757484 | BV22: 17.721209 | BW22: 17.686334 | BX22: 17.652704 | BY22: 17.620186 | BZ22: 17.588691 | CA22: 17.558179 | CB22: 17.528646 | CC22: 17.500108 | CD22: 17.472582 | CE22: 17.446074 | CF22: 17.420567 | CG22: 17.396027 | CH22: 17.372402 | CI22: 17.349636 | CJ22: 17.327672 | CK22: 17.306462 | CL22: 17.285965 | CM22: 17.266155 | CN22: 17.247012 | CO22: 17.228524 | CP22: 17.21068 | CQ22: 17.193469 | CR22: 17.176874 | CS22: 17.160874 | CT22: 17.145446 | CU22: 17.130562 | CV22: 1 | CW22: 1
C23: Actual | CV23: 0 | CW23: 0
A24: Am1301 | B24: desl | C24: Forecast | D24: 36.580924 | E24: 38.527885 | F24: 32.243856 | G24: 30.42985 | H24: 31.397536 | I24: 28.674524 | J24: 31.353747 | K24: 30.590702 | L24: 31.637135 | M24: 31.903292 | N24: 31.258334 | O24: 31.427053 | P24: 30.382727 | Q24: 30.094884 | R24: 29.342084 | S24: 28.759256 | T24: 28.413671 | U24: 27.962448 | V24: 27.890834 | W24: 27.730514 | X24: 27.721589 | Y24: 27.676499 | Z24: 27.540386 | AA24: 27.375396 | AB24: 27.077842 | AC24: 26.778955 | AD24: 26.452761 | AE24: 26.162644 | AF24: 25.93048 | AG24: 25.739803 | AH24: 25.605761 | AI24: 25.487779 | AJ24: 25.382414 | AK24: 25.269152 | AL24: 25.1399 | AM24: 24.997934 | AN24: 24.840939 | AO24: 24.68054 | AP24: 24.520715 | AQ24: 24.369493 | AR24: 24.231548 | AS24: 24.107618 | AT24: 23.998037 | AU24: 23.898398 | AV24: 23.805088 | AW24: 23.713499 | AX24: 23.620475 | AY24: 23.524914 | AZ24: 23.426961 | BA24: 23.328653 | BB24: 23.232145 | BC24: 23.139637 | BD24: 23.052509 | BE24: 22.971104 | BF24: 22.894999 | BG24: 22.823053 | BH24: 22.754017 | BI24: 22.686718 | BJ24: 22.620366 | BK24: 22.554635 | BL24: 22.489591 | BM24: 22.425623 | BN24: 22.36323 | BO24: 22.302889 | BP24: 22.244924 | BQ24: 22.189436 | BR24: 22.136314 | BS24: 22.085276 | BT24: 22.035963 | BU24: 21.988024 | BV24: 21.94119 | BW24: 21.895314 | BX24: 21.850372 | BY24: 21.806434 | BZ24: 21.763614 | CA24: 21.722024 | CB24: 21.681731 | CC24: 21.642744 | CD24: 21.605009 | CE24: 21.568429 | CF24: 21.532885 | CG24: 21.498263 | CH24: 21.464472 | CI24: 21.431454 | CJ24: 21.399181 | CK24: 21.367651 | CL24: 21.336876 | CM24: 21.306867 | CN24: 21.277628 | CO24: 21.249147 | CP24: 21.221397 | CQ24: 21.194338 | CR24: 21.167928 | CS24: 21.14212 | CT24: 21.116878 | CU24: 21.092172 | CV24: -1 | CW24: 1
C25: Actual | CV25: 0 | CW25: 0
A26: Am1302 | B26: adm | C26: Forecast | D26: 21.5856 | E26: 21.047007 | F26: 23.625159 | G26: 23.80825 | H26: 22.935351 | I26: 22.97805 | J26: 20.90142 | K26: 20.28191 | L26: 19.016717 | M26: 18.308703 | N26: 18.12814 | O26: 17.933537 | P26: 18.408916 | Q26: 18.681242 | R26: 19.110556 | S26: 19.310713 | T26: 19.245105 | U26: 19.04507 | V26: 18.608063 | W26: 18.205893 | X26: 17.815909 | Y26: 17.557222 | Z26: 17.441096 | AA26: 17.418193 | AB26: 17.484196 | AC26: 17.550587 | AD26: 17.603162 | AE26: 17.604653 | AF26: 17.549972 | AG26: 17.454025 | AH26: 17.325194 | AI26: 17.193264 | AJ26: 17.071361 | AK26: 16.976037 | AL26: 16.913057 | AM26: 16.879108 | AN26: 16.868271 | AO26: 16.867112 | AP26: 16.865529 | AQ26: 16.854249 | AR26: 16.829311 | AS26: 16.79191 | AT26: 16.746138 | AU26: 16.698829 | AV26: 16.655788 | AW26: 16.621445 | AX26: 16.597483 | AY26: 16.583026 | AZ26: 16.575623 | BA26: 16.571859 | BB26: 16.568714 | BC26: 16.563978 | BD26: 16.556704 | BE26: 16.547141 | BF26: 16.536362 | BG26: 16.525903 | BH26: 16.517224 | BI26: 16.511414 | BJ26: 16.508965 | BK26: 16.509755 | BL26: 16.51319 | BM26: 16.518413 | BN26: 16.524568 | BO26: 16.530992 | BP26: 16.537342 | BQ26: 16.543609 | BR26: 16.550047 | BS26: 16.55705 | BT26: 16.565014 | BU26: 16.574231 | BV26: 16.584829 | BW26: 16.596763 | BX26: 16.609858 | BY26: 16.62387 | BZ26: 16.638552 | CA26: 16.653714 | CB26: 16.669246 | CC26: 16.685129 | CD26: 16.70141 | CE26: 16.718176 | CF26: 16.735518 | CG26: 16.753504 | CH26: 16.772159 | CI26: 16.791467 | CJ26: 16.811374 | CK26: 16.831808 | CL26: 16.852691 | CM26: 16.873962 | CN26: 16.895579 | CO26: 16.917526 | CP26: 16.939805 | CQ26: 16.962432 | CR26: 16.985421 | CS26: 17.008786 | CT26: 17.032525 | CU26: 17.05663 | CV26: 1 | CW26: 1
C27: Actual | CV27: 0 | CW27: 0
A28: Am1302 | B28: desl | C28: Forecast | D28: 30.184879 | E28: 27.172164 | F28: 28.005691 | G28: 26.551151 | H28: 27.606337 | I28: 27.513428 | J28: 27.824184 | K28: 28.501935 | L28: 28.203672 | M28: 28.374024 | N28: 27.798229 | O28: 27.408673 | P28: 26.94631 | Q28: 26.467676 | R28: 26.270197 | S28: 26.033283 | T28: 26.024342 | U28: 26.007799 | V28: 26.021 | W28: 26.032489 | X28: 25.961624 | Y28: 25.876675 | Z28: 25.718356 | AA28: 25.547568 | AB28: 25.367613 | AC28: 25.19747 | AD28: 25.06487 | AE28: 24.958249 | AF28: 24.88976 | AG28: 24.840029 | AH28: 24.800692 | AI28: 24.760355 | AJ28: 24.707759 | AK28: 24.643769 | AL28: 24.5667 | AM28: 24.483914 | AN28: 24.400925 | AO28: 24.323449 | AP28: 24.256039 | AQ28: 24.199084 | AR28: 24.152319 | AS28: 24.112586 | AT28: 24.076801 | AU28: 24.041967 | AV28: 24.005809 | AW28: 23.967646 | AX28: 23.927583 | AY28: 23.886882 | AZ28: 23.847044 | BA28: 23.809544 | BB28: 23.77547 | BC28: 23.745197 | BD28: 23.718563 | BE28: 23.694861 | BF28: 23.673197 | BG28: 23.652695 | BH28: 23.6327 | BI28: 23.612913 | BJ28: 23.593349 | BK28: 23.574288 | BL28: 23.556122 | BM28: 23.539233 | BN28: 23.523888 | BO28: 23.51018 | BP28: 23.498042 | BQ28: 23.487276 | BR28: 23.477625 | BS28: 23.468837 | BT28: 23.460719 | BU28: 23.453163 | BV28: 23.44615 | BW28: 23.439727 | BX28: 23.433978 | BY28: 23.428989 | BZ28: 23.424819 | CA28: 23.421483 | CB28: 23.418952 | CC28: 23.417165 | CD28: 23.41604 | CE28: 23.415497 | CF28: 23.415467 | CG28: 23.41591 | CH28: 23.416805 | CI28: 23.418154 | CJ28: 23.419967 | CK28: 23.422257 | CL28: 23.425031 | CM28: 23.428284 | CN28: 23.431999 | CO28: 23.436153 | CP28: 23.440715 | CQ28: 23.445655 | CR28: 23.450947 | CS28: 23.456572 | CT28: 23.462516 | CU28: 23.468772 | CV28: -1 | CW28: 1
C29: Actual | CV29: 0 | CW29: 0
A30: Am1303 | B30: adm | C30: Forecast | D30: 8134.5837 | E30: 7418.0982 | F30: 8015.1295 | G30: 8167.6662 | H30: 7984.3458 | I30: 7956.2369 | J30: 7260.9462 | K30: 7037.5045 | L30: 6633.1164 | M30: 6583.8764 | N30: 6805.3284 | O30: 7128.641 | P30: 7647.7099 | Q30: 8015.782 | R30: 8327.5498 | S30: 8454.4497 | T30: 8445.616 | U30: 8380.4505 | V30: 8273.5072 | W30: 8226.6457 | X30: 8225.1329 | Y30: 8293.1036 | Z30: 8410.2758 | AA30: 8549.6061 | AB30: 8700.497 | AC30: 8832.9636 | AD30: 8944.0251 | AE30: 9023.4263 | AF30: 9074.0011 | AG30: 9104.1357 | AH30: 9121.8228 | AI30: 9141.176 | AJ30: 9169.4759 | AK30: 9212.9446 | AL30: 9271.2546 | AM30: 9339.6841 | AN30: 9411.982 | AO30: 9480.5944 | AP30: 9540.9329 | AQ30: 9590.6022 | AR30: 9630.4375 | AS30: 9663.3573 | AT30: 9692.9229 | AU30: 9722.6742 | AV30: 9754.8201 | AW30: 9790.3477 | AX30: 9828.8995 | AY30: 9869.23 | AZ30: 9909.7514 | BA30: 9948.8844 | BB30: 9985.5233 | BC30: 10019.125 | BD30: 10049.781 | BE30: 10078.074 | BF30: 10104.855 | BG30: 10131.017 | BH30: 10157.253 | BI30: 10183.94 | BJ30: 10211.101 | BK30: 10238.464 | BL30: 10265.603 | BM30: 10292.07 | BN30: 10317.532 | BO30: 10341.831 | BP30: 10364.997 | BQ30: 10387.207 | BR30: 10408.715 | BS30: 10429.775 | BT30: 10450.582 | BU30: 10471.244 | BV30: 10491.774 | BW30: 10512.113 | BX30: 10532.161 | BY30: 10551.812 | BZ30: 10570.989 | CA30: 10589.654 | CB30: 10607.818 | CC30: 10625.529 | CD30: 10642.856 | CE30: 10659.875 | CF30: 10676.645 | CG30: 10693.207 | CH30: 10709.572 | CI30: 10725.733 | CJ30: 10741.67 | CK30: 10757.359 | CL30: 10772.782 | CM30: 10787.935 | CN30: 10802.823 | CO30: 10817.464 | CP30: 10831.881 | CQ30: 10846.098 | CR30: 10860.136 | CS30: 10874.009 | CT30: 10887.725 | CU30: 10901.287 | CV30: 1 | CW30: 1
C31: Actual | CV31: 0 | CW31: 0
A32: Am1303 | B32: desl | C32: Forecast | D32: 12971.077 | E32: 12691.969 | F32: 12666.568 | G32: 11770.487 | H32: 11825.135 | I32: 11184.618 | J32: 10950.693 | K32: 10789.858 | L32: 10475.456 | M32: 10480.665 | N32: 10341.393 | O32: 10456.424 | P32: 10557.926 | Q32: 10662.642 | R32: 10754.088 | S32: 10702.064 | T32: 10622.359 | U32: 10455.602 | V32: 10299.135 | W32: 10173.633 | X32: 10090.109 | Y32: 10070.848 | Z32: 10074.278 | AA32: 10099.807 | AB32: 10117.266 | AC32: 10119.899 | AD32: 10106.843 | AE32: 10075.253 | AF32: 10036.241 | AG32: 9990.9817 | AH32: 9947.5056 | AI32: 9909.1818 | AJ32: 9878.4053 | AK32: 9857.6889 | AL32: 9845.117 | AM32: 9839.4255 | AN32: 9836.5266 | AO32: 9832.9988 | AP32: 9826.2387 | AQ32: 9814.8127 | AR32: 9799.5712 | AS32: 9782.0793 | AT32: 9764.7838 | AU32: 9749.6669 | AV32: 9737.907 | AW32: 9729.7922 | AX32: 9724.6551 | AY32: 9721.4914 | AZ32: 9719.1378 | BA32: 9716.7 | BB32: 9713.6655 | BC32: 9709.9031 | BD32: 9705.6363 | BE32: 9701.2573 | BF32: 9697.2397 | BG32: 9693.9923 | BH32: 9691.7855 | BI32: 9690.7148 | BJ32: 9690.6929 | BK32: 9691.5065 | BL32: 9692.8751 | BM32: 9694.5326 | BN32: 9696.2878 | BO32: 9698.0562 | BP32: 9699.862 | BQ32: 9701.8059 | BR32: 9704.0225 | BS32: 9706.6344 | BT32: 9709.7194 | BU32: 9713.2972 | BV32: 9717.3335 | BW32: 9721.7579 | BX32: 9726.4866 | BY32: 9731.4435 | BZ32: 9736.575 | CA32: 9741.8558 | CB32: 9747.2871 | CC32: 9752.8885 | CD32: 9758.6879 | CE32: 9764.711 | CF32: 9770.9743 | CG32: 9777.4803 | CH32: 9784.2185 | CI32: 9791.1683 | CJ32: 9798.3043 | CK32: 9805.6021 | CL32: 9813.0427 | CM32: 9820.6144 | CN32: 9828.3133 | CO32: 9836.1411 | CP32: 9844.1024 | CQ32: 9852.2017 | CR32: 9860.4408 | CS32: 9868.818 | CT32: 9877.328 | CU32: 9885.9627 | CV32: -1 | CW32: 1
C33: Actual | CV33: 0 | CW33: 0
A34: Am1304 | B34: adm | C34: Forecast | D34: 76.509959 | E34: 76.932964 | F34: 87.608128 | G34: 87.179251 | H34: 85.411625 | I34: 83.563693 | J34: 76.965281 | K34: 75.218056 | L34: 71.148448 | M34: 70.390024 | N34: 70.334194 | O34: 70.495264 | P34: 71.661145 | Q34: 71.487157 | R34: 71.533324 | S34: 70.556131 | T34: 69.233803 | U34: 67.759559 | V34: 66.048304 | W34: 64.730546 | X34: 63.517299 | Y34: 62.719336 | Z34: 62.180017 | AA34: 61.820398 | AB34: 61.603812 | AC34: 61.319198 | AD34: 60.976343 | AE34: 60.475764 | AF34: 59.855728 | AG34: 59.162657 | AH34: 58.444215 | AI34: 57.785953 | AJ34: 57.210427 | AK34: 56.747984 | AL34: 56.382188 | AM34: 56.084659 | AN34: 55.823986 | AO34: 55.562924 | AP34: 55.28484 | AQ34: 54.978459 | AR34: 54.64931 | AS34: 54.309882 | AT34: 53.975137 | AU34: 53.660992 | AV34: 53.376547 | AW34: 53.126592 | AX34: 52.908859 | AY34: 52.716848 | AZ34: 52.542031 | BA34: 52.375563 | BB34: 52.211265 | BC34: 52.045792 | BD34: 51.879386 | BE34: 51.714816 | BF34: 51.556117 | BG34: 51.407382 | BH34: 51.271432 | BI34: 51.149448 | BJ34: 51.040805 | BK34: 50.943574 | BL34: 50.855202 | BM34: 50.773178 | BN34: 50.695627 | BO34: 50.621541 | BP34: 50.550817 | BQ34: 50.484032 | BR34: 50.422103 | BS34: 50.365957 | BT34: 50.316241 | BU34: 50.273178 | BV34: 50.236545 | BW34: 50.205772 | BX34: 50.180104 | BY34: 50.15878 | BZ34: 50.141184 | CA34: 50.126926 | CB34: 50.115863 | CC34: 50.108046 | CD34: 50.103634 | CE34: 50.102803 | CF34: 50.105665 | CG34: 50.112217 | CH34: 50.122341 | CI34: 50.135822 | CJ34: 50.152397 | CK34: 50.171798 | CL34: 50.193797 | CM34: 50.21823 | CN34: 50.244997 | CO34: 50.274055 | CP34: 50.305393 | CQ34: 50.339006 | CR34: 50.374877 | CS34: 50.412963 | CT34: 50.453189 | CU34: 50.495459 | CV34: 1 | CW34: 1
C35: Actual | CV35: 0 | CW35: 0
A36: Am1304 | B36: desl | C36: Forecast | D36: 93.330606 | E36: 85.334356 | F36: 83.450497 | G36: 80.753707 | H36: 80.510628 | I36: 77.580658 | J36: 75.738476 | K36: 73.915937 | L36: 71.922704 | M36: 70.894525 | N36: 69.595973 | O36: 69.133061 | P36: 68.594854 | Q36: 68.071704 | R36: 67.418488 | S36: 66.328922 | T36: 65.137032 | U36: 63.697278 | V36: 62.330131 | W36: 61.092562 | X36: 60.045509 | Y36: 59.24166 | Z36: 58.560161 | AA36: 57.988277 | AB36: 57.422057 | AC36: 56.83412 | AD36: 56.20814 | AE36: 55.534576 | AF36: 54.845795 | AG36: 54.150983 | AH36: 53.481715 | AI36: 52.853241 | AJ36: 52.277297 | AK36: 51.76081 | AL36: 51.295759 | AM36: 50.873867 | AN36: 50.478112 | AO36: 50.094714 | AP36: 49.713338 | AQ36: 49.329078 | AR36: 48.944764 | AS36: 48.56614 | AT36: 48.201744 | AU36: 47.858379 | AV36: 47.540028 | AW36: 47.247304 | AX36: 46.977463 | AY36: 46.726331 | AZ36: 46.489098 | BA36: 46.261858 | BB36: 46.042097 | BC36: 45.828839 | BD36: 45.622525 | BE36: 45.424375 | BF36: 45.235972 | BG36: 45.058669 | BH36: 44.893261 | BI36: 44.739826 | BJ36: 44.59772 | BK36: 44.46581 | BL36: 44.342725 | BM36: 44.227182 | BN36: 44.118211 | BO36: 44.015272 | BP36: 43.918249 | BQ36: 43.827324 | BR36: 43.74281 | BS36: 43.664982 | BT36: 43.593952 | BU36: 43.529616 | BV36: 43.47167 | BW36: 43.419675 | BX36: 43.373145 | BY36: 43.331626 | BZ36: 43.294756 | CA36: 43.262289 | CB36: 43.234088 | CC36: 43.210096 | CD36: 43.190295 | CE36: 43.174662 | CF36: 43.163142 | CG36: 43.155629 | CH36: 43.151971 | CI36: 43.151979 | CJ36: 43.155451 | CK36: 43.162191 | CL36: 43.17203 | CM36: 43.184831 | CN36: 43.200488 | CO36: 43.218923 | CP36: 43.240072 | CQ36: 43.263871 | CR36: 43.290252 | CS36: 43.319134 | CT36: 43.350425 | CU36: 43.384026 | CV36: -1 | CW36: 1
C37: Actual | CV37: 0 | CW37: 0
A38: Rr1401 | B38: adm | C38: Forecast | D38: 1424.4297 | E38: 1414.1964 | F38: 1490.2375 | G38: 1510.0924 | H38: 1494.7052 | I38: 1503.1948 | J38: 1457.2995 | K38: 1449.9142 | L38: 1429.8314 | M38: 1429.9534 | N38: 1447.4094 | O38: 1464.8265 | P38: 1495.8355 | Q38: 1516.01 | R38: 1535.1771 | S38: 1545.3093 | T38: 1548.125 | U38: 1549.1014 | V38: 1546.6223 | W38: 1547.4622 | X38: 1550.0092 | Y38: 1556.166 | Z38: 1565.3393 | AA38: 1575.8716 | AB38: 1587.6303 | AC38: 1598.5237 | AD38: 1608.4357 | AE38: 1616.6358 | AF38: 1623.2007 | AG38: 1628.698 | AH38: 1633.507 | AI38: 1638.5036 | AJ38: 1644.0427 | AK38: 1650.4626 | AL38: 1657.7409 | AM38: 1665.5991 | AN38: 1673.7325 | AO38: 1681.7306 | AP38: 1689.3651 | AQ38: 1696.4999 | AR38: 1703.1629 | AS38: 1709.4965 | AT38: 1715.6715 | AU38: 1721.8759 | AV38: 1728.2297 | AW38: 1734.7958 | AX38: 1741.5654 | AY38: 1748.4765 | AZ38: 1755.4456 | BA38: 1762.3831 | BB38: 1769.2242 | BC38: 1775.9337 | BD38: 1782.5122 | BE38: 1788.9891 | BF38: 1795.4089 | BG38: 1801.8195 | BH38: 1808.2581 | BI38: 1814.745 | BJ38: 1821.2814 | BK38: 1827.8529 | BL38: 1834.4363 | BM38: 1841.0071 | BN38: 1847.5465 | BO38: 1854.0446 | BP38: 1860.5015 | BQ38: 1866.9251 | BR38: 1873.3277 | BS38: 1879.7223 | BT38: 1886.1191 | BU38: 1892.5236 | BV38: 1898.9367 | BW38: 1905.3548 | BX38: 1911.7724 | BY38: 1918.1832 | BZ38: 1924.5823 | CA38: 1930.967 | CB38: 1937.3371 | CC38: 1943.6948 | CD38: 1950.0431 | CE38: 1956.3856 | CF38: 1962.7254 | CG38: 1969.0641 | CH38: 1975.4023 | CI38: 1981.7392 | CJ38: 1988.0734 | CK38: 1994.4034 | CL38: 2000.7278 | CM38: 2007.0461 | CN38: 2013.3581 | CO38: 2019.6646 | CP38: 2025.9663 | CQ38: 2032.2644 | CR38: 2038.5596 | CS38: 2044.8527 | CT38: 2051.1437 | CU38: 2057.4326 | CV38: 1 | CW38: 1
C39: Actual | CV39: 0 | CW39: 0
A40: Rr1401 | B40: desl | C40: Forecast | D40: 1746.6035 | E40: 1605.4167 | F40: 1729.492 | G40: 1645.3701 | H40: 1680.8135 | I40: 1640.1107 | J40: 1610.9518 | K40: 1615.7356 | L40: 1581.6277 | M40: 1601.5431 | N40: 1600.358 | O40: 1621.6711 | P40: 1642.8762 | Q40: 1654.9517 | R40: 1671.5832 | S40: 1671.5565 | T40: 1673.0812 | U40: 1668.0254 | V40: 1663.4616 | W40: 1662.6998 | X40: 1663.0161 | Y40: 1668.9604 | Z40: 1675.7642 | AA40: 1684.6002 | AB40: 1693.3452 | AC40: 1700.868 | AD40: 1707.599 | AE40: 1712.4394 | AF40: 1716.5464 | AG40: 1719.8403 | AH40: 1723.0607 | AI40: 1726.7478 | AJ40: 1731.0252 | AK40: 1736.2544 | AL40: 1742.1434 | AM40: 1748.5654 | AN40: 1755.151 | AO40: 1761.5854 | AP40: 1767.7152 | AQ40: 1773.4204 | AR40: 1778.8097 | AS40: 1784.0038 | AT40: 1789.1894 | AU40: 1794.5215 | AV40: 1800.081 | AW40: 1805.9022 | AX40: 1811.9359 | AY40: 1818.1127 | AZ40: 1824.3441 | BA40: 1830.5551 | BB40: 1836.7014 | BC40: 1842.7648 | BD40: 1848.7615 | BE40: 1854.7233 | BF40: 1860.6917 | BG40: 1866.7045 | BH40: 1872.7864 | BI40: 1878.947 | BJ40: 1885.1791 | BK40: 1891.4647 | BL40: 1897.7807 | BM40: 1904.1053 | BN40: 1910.4236 | BO40: 1916.7294 | BP40: 1923.0255 | BQ40: 1929.3204 | BR40: 1935.6253 | BS40: 1941.9506 | BT40: 1948.3029 | BU40: 1954.6845 | BV40: 1961.0932 | BW40: 1967.524 | BX40: 1973.9704 | BY40: 1980.4265 | BZ40: 1986.888 | CA40: 1993.3531 | CB40: 1999.822 | CC40: 2006.2965 | CD40: 2012.7793 | CE40: 2019.2728 | CF40: 2025.7788 | CG40: 2032.2977 | CH40: 2038.8291 | CI40: 2045.3713 | CJ40: 2051.9227 | CK40: 2058.4813 | CL40: 2065.0459 | CM40: 2071.6156 | CN40: 2078.1903 | CO40: 2084.7704 | CP40: 2091.3564 | CQ40: 2097.9489 | CR40: 2104.5481 | CS40: 2111.1542 | CT40: 2117.7669 | CU40: 2124.3857 | CV40: -1 | CW40: 1
C41: Actual | CV41: 0 | CW41: 0
...

Sheet conditional forecasts_8
A1: GVAR Conditional Forecasts
A2: Last in-sample estimation date: | B2: 2016M12
A3: Last forecast date: | B3: 2024M12
D4: =DATE(LEFT(D5,4),SUBSTITUTE(RIGHT(D5,2),"M",""),1) -> 42736 | E4: =DATE(LEFT(E5,4),SUBSTITUTE(RIGHT(E5,2),"M",""),1) -> 42767 | F4: =DATE(LEFT(F5,4),SUBSTITUTE(RIGHT(F5,2),"M",""),1) -> 42795 | G4: =DATE(LEFT(G5,4),SUBSTITUTE(RIGHT(G5,2),"M",""),1) -> 42826 | H4: =DATE(LEFT(H5,4),SUBSTITUTE(RIGHT(H5,2),"M",""),1) -> 42856 | I4: =DATE(LEFT(I5,4),SUBSTITUTE(RIGHT(I5,2),"M",""),1) -> 42887 | J4: =DATE(LEFT(J5,4),SUBSTITUTE(RIGHT(J5,2),"M",""),1) -> 42917 | K4: =DATE(LEFT(K5,4),SUBSTITUTE(RIGHT(K5,2),"M",""),1) -> 42948 | ... CU4: =DATE(LEFT(CU5,4),SUBSTITUTE(RIGHT(CU5,2),"M",""),1) -> 45627
D5: 2017M1 | E5: 2017M2 | F5: 2017M3 | G5: 2017M4 | H5: 2017M5 | I5: 2017M6 | J5: 2017M7 | K5: 2017M8 | L5: 2017M9 | M5: 2017M10 | N5: 2017M11 | O5: 2017M12 | P5: 2018M1 | Q5: 2018M2 | R5: 2018M3 | S5: 2018M4 | T5: 2018M5 | U5: 2018M6 | V5: 2018M7 | W5: 2018M8 | X5: 2018M9 | Y5: 2018M10 | Z5: 2018M11 | AA5: 2018M12 | AB5: 2019M1 | AC5: 2019M2 | AD5: 2019M3 | AE5: 2019M4 | AF5: 2019M5 | AG5: 2019M6 | AH5: 2019M7 | AI5: 2019M8 | AJ5: 2019M9 | AK5: 2019M10 | AL5: 2019M11 | AM5: 2019M12 | AN5: 2020M1 | AO5: 2020M2 | AP5: 2020M3 | AQ5: 2020M4 | AR5: 2020M5 | AS5: 2020M6 | AT5: 2020M7 | AU5: 2020M8 | AV5: 2020M9 | AW5: 2020M10 | AX5: 2020M11 | AY5: 2020M12 | AZ5: 2021M1 | BA5: 2021M2 | BB5: 2021M3 | BC5: 2021M4 | BD5: 2021M5 | BE5: 2021M6 | BF5: 2021M7 | BG5: 2021M8 | BH5: 2021M9 | BI5: 2021M10 | BJ5: 2021M11 | BK5: 2021M12 | BL5: 2022M1 | BM5: 2022M2 | BN5: 2022M3 | BO5: 2022M4 | BP5: 2022M5 | BQ5: 2022M6 | BR5: 2022M7 | BS5: 2022M8 | BT5: 2022M9 | BU5: 2022M10 | BV5: 2022M11 | BW5: 2022M12 | BX5: 2023M1 | BY5: 2023M2 | BZ5: 2023M3 | CA5: 2023M4 | CB5: 2023M5 | CC5: 2023M6 | CD5: 2023M7 | CE5: 2023M8 | CF5: 2023M9 | CG5: 2023M10 | CH5: 2023M11 | CI5: 2023M12 | CJ5: 2024M1 | CK5: 2024M2 | CL5: 2024M3 | CM5: 2024M4 | CN5: 2024M5 | CO5: 2024M6 | CP5: 2024M7 | CQ5: 2024M8 | CR5: 2024M9 | CS5: 2024M10 | CT5: 2024M11 | CU5: 2024M12 | CV5: Serie | CW5: Regiao
A6: Ro1101 | B6: adm | C6: Forecast | D6: 3115.6169 | E6: 3366.9532 | F6: 3895.1536 | G6: 4031.024 | H6: 4157.4622 | I6: 4381.114 | J6: 4326.4124 | K6: 4376.2513 | L6: 4224.1857 | M6: 3751.245 | N6: 3580.8344 | O6: 3078.0567 | P6: 3906.863 | Q6: 4229.2565 | R6: 4883.0082 | S6: 5027.9508 | T6: 5176.0149 | U6: 5378.6777 | V6: 5292.7516 | W6: 5321.9414 | X6: 5167.1529 | Y6: 4722.4168 | Z6: 4603.9021 | AA6: 4163.5286 | AB6: 5052.5194 | AC6: 5422.0336 | AD6: 6105.4342 | AE6: 6264.675 | AF6: 6417.4864 | AG6: 6621.9488 | AH6: 6540.077 | AI6: 6578.3516 | AJ6: 6438.218 | AK6: 6012.8067 | AL6: 5916.7409 | AM6: 5500.3101 | AN6: 6413.305 | AO6: 6805.736 | AP6: 7510.1488 | AQ6: 7688.081 | AR6: 7857.304 | AS6: 8076.3748 | AT6: 8008.0884 | AU6: 8059.7894 | AV6: 7933.6367 | AW6: 7523.1566 | AX6: 7443.0004 | AY6: 7043.1849 | AZ6: 7973.0683 | BA6: 8382.2238 | BB6: 9102.8713 | BC6: 9296.3858 | BD6: 9480.5287 | BE6: 9713.95 | BF6: 9659.5799 | BG6: 9724.891 | BH6: 9612.1366 | BI6: 9214.9012 | BJ6: 9147.8714 | BK6: 8761.0954 | BL6: 9703.974 | BM6: 10126.138 | BN6: 10859.87 | BO6: 11066.584 | BP6: 11264.035 | BQ6: 11510.785 | BR6: 11469.593 | BS6: 11547.687 | BT6: 11447.056 | BU6: 11061.07 | BV6: 11004.332 | BW6: 10627.001 | BX6: 11578.819 | BY6: 12009.951 | BZ6: 12753.316 | CA6: 12970.923 | CB6: 13180.887 | CC6: 13441.745 | CD6: 13415.716 | CE6: 13508.993 | CF6: 13422.144 | CG6: 13047.061 | CH6: 12997.241 | CI6: 12622.413 | CJ6: 13573.284 | CK6: 14002.38 | CL6: 14744.81 | CM6: 14967.396 | CN6: 15190.192 | CO6: 15469.204 | CP6: 15479.614 | CQ6: 15593.266 | CR6: 15539.161 | CS6: 15256.277 | CT6: 15089.362 | CU6: 14800.144 | CV6: 1 | CW6: 1
C7: Actual | CV7: 0 | CW7: 0
A8: Ro1101 | B8: desl | C8: Forecast | D8: 3253.3177 | E8: 3322.7997 | F8: 3689.5561 | G8: 3784.8754 | H8: 4118.6782 | I8: 4077.4937 | J8: 4281.4478 | K8: 4355.4509 | L8: 4261.6488 | M8: 4504.442 | N8: 4375.9852 | O8: 4250.2461 | P8: 4278.9371 | Q8: 4263.8889 | R8: 4663.4829 | S8: 4710.7249 | T8: 5051.614 | U8: 4991.2221 | V8: 5176.3678 | W8: 5233.3342 | X8: 5134.6359 | Y8: 5391.2624 | Z8: 5296.3924 | AA8: 5218.2797 | AB8: 5299.9512 | AC8: 5334.6652 | AD8: 5775.3243 | AE8: 5853.3125 | AF8: 6216.4852 | AG8: 6173.5599 | AH8: 6375.1032 | AI8: 6450.1278 | AJ8: 6372.4688 | AK8: 6653.2325 | AL8: 6584.9897 | AM8: 6535.0816 | AN8: 6645.5842 | AO8: 6708.898 | AP8: 7177.2252 | AQ8: 7281.464 | AR8: 7669.2557 | AS8: 7649.4052 | AT8: 7872.8332 | AU8: 7969.0675 | AV8: 7912.4723 | AW8: 8214.5567 | AX8: 8168.0824 | AY8: 8140.3599 | AZ8: 8273.2689 | BA8: 8358.9388 | BB8: 8849.3163 | BC8: 8975.1204 | BD8: 9383.9121 | BE8: 9384.5027 | BF8: 9627.8756 | BG8: 9743.6431 | BH8: 9706.2498 | BI8: 10027.268 | BJ8: 9999.5044 | BK8: 9990.3021 | BL8: 10141.569 | BM8: 10245.464 | BN8: 10753.962 | BO8: 10897.801 | BP8: 11324.54 | BQ8: 11342.954 | BR8: 11603.943 | BS8: 11737.002 | BT8: 11716.435 | BU8: 12053.691 | BV8: 12041.507 | BW8: 12047.252 | BX8: 12212.98 | BY8: 12331.105 | BZ8: 12853.935 | CA8: 13012.543 | CB8: 13454.736 | CC8: 13489.352 | CD8: 13767.107 | CE8: 13917.024 | CF8: 13912.714 | CG8: 14264.824 | CH8: 14265.362 | CI8: 14281.373 | CJ8: 14455.085 | CK8: 14579.653 | CL8: 15109.385 | CM8: 15276.252 | CN8: 15730.728 | CO8: 15783.736 | CP8: 16078.434 | CQ8: 16256.336 | CR8: 16281.149 | CS8: 16611.416 | CT8: 16702.961 | CU8: 16661.897 | CV8: -1 | CW8: 1
C9: Actual | CV9: 0 | CW9: 0
A10: Ro1102 | B10: adm | C10: Forecast | D10: 4980.5079 | E10: 5358.7058 | F10: 6017.9881 | G10: 5995.5157 | H10: 5938.4682 | I10: 5977.6758 | J10: 5666.6636 | K10: 5667.5644 | L10: 5460.688 | M10: 5054.6123 | N10: 5240.0048 | O10: 4766.9749 | P10: 5837.8326 | Q10: 6007.6322 | R10: 6596.7262 | S10: 6488.734 | T10: 6381.7847 | U10: 6365.4825 | V10: 6021.1826 | W10: 6013.1366 | X10: 5825.9551 | Y10: 5472.1003 | Z10: 5725.1927 | AA10: 5317.0714 | AB10: 6436.1899 | AC10: 6630.3071 | AD10: 7222.3022 | AE10: 7105.12 | AF10: 6987.5456 | AG10: 6967.2639 | AH10: 6629.2824 | AI10: 6637.3016 | AJ10: 6472.8557 | AK10: 6144.6977 | AL10: 6423.3914 | AM10: 6038.8825 | AN10: 7178.7897 | AO10: 7390.7267 | AP10: 7997.8222 | AQ10: 7893.5353 | AR10: 7787.3874 | AS10: 7777.9558 | AT10: 7451.1471 | AU10: 7471.3652 | AV10: 7320.4785 | AW10: 7007.1438 | AX10: 7301.4754 | AY10: 6932.7963 | AZ10: 8088.1374 | BA10: 8314.7168 | BB10: 8935.5244 | BC10: 8844.1063 | BD10: 8750.2065 | BE10: 8752.6556 | BF10: 8437.5652 | BG10: 8469.4593 | BH10: 8330.2469 | BI10: 8028.5774 | BJ10: 8334.5469 | BK10: 7977.4793 | BL10: 9144.4337 | BM10: 9382.6732 | BN10: 10015.221 | BO10: 9935.6108 | BP10: 9853.4963 | BQ10: 9867.5336 | BR10: 9563.5943 | BS10: 9605.9518 | BT10: 9476.3311 | BU10: 9183.3474 | BV10: 9497.2701 | BW10: 9147.8151 | BX10: 10322.598 | BY10: 10569.49 | BZ10: 11212.015 | CA10: 11143.943 | CB10: 11074.765 | CC10: 11102.521 | CD10: 10812.03 | CE10: 10866.236 | CF10: 10745.49 | CG10: 10457.404 | CH10: 10771.995 | CI10: 10419.808 | CJ10: 11590.723 | CK10: 11836.092 | CL10: 12481.947 | CM10: 12426.972 | CN10: 12379.7 | CO10: 12435.145 | CP10: 12180.291 | CQ10: 12248.762 | CR10: 12135.286 | CS10: 11914.819 | CT10: 12048.529 | CU10: 11840.049 | CV10: 1 | CW10: 1
C11: Actual | CV11: 0 | CW11: 0
A12: Ro1102 | B12: desl | C12: Forecast | D12: 5215.2238 | E12: 5235.7516 | F12: 5791.0833 | G12: 5428.1316 | H12: 5728.3708 | I12: 5271.3767 | J12: 5364.2558 | K12: 5594.3975 | L12: 5112.4405 | M12: 5936.4177 | N12: 5937.62 | O12: 5604.9358 | P12: 5817.9876 | Q12: 5559.5054 | R12: 6148.0127 | S12: 5740.7253 | T12: 6003.3656 | U12: 5552.1936 | V12: 5637.2482 | W12: 5878.0917 | X12: 5425.7438 | Y12: 6289.9413 | Z12: 6336.386 | AA12: 6043.146 | AB12: 6283.3761 | AC12: 6040.0062 | AD12: 6636.0887 | AE12: 6234.8554 | AF12: 6506.9281 | AG12: 6070.8294 | AH12: 6176.2329 | AI12: 6440.7897 | AJ12: 6013.2714 | AK12: 6901.6924 | AL12: 6970.9049 | AM12: 6698.8293 | AN12: 6958.8017 | AO12: 6733.9924 | AP12: 7347.6648 | AQ12: 6963.2689 | AR12: 7251.7118 | AS12: 6831.8668 | AT12: 6953.7459 | AU12: 7235.22 | AV12: 6825.0899 | AW12: 7731.2071 | AX12: 7818.1396 | AY12: 7563.5096 | AZ12: 7840.4338 | BA12: 7631.9901 | BB12: 8261.4705 | BC12: 7892.4304 | BD12: 8195.9044 | BE12: 7790.8719 | BF12: 7927.411 | BG12: 8223.4218 | BH12: 7827.7138 | BI12: 8748.1441 | BJ12: 8849.2937 | BK12: 8608.8041 | BL12: 8899.8078 | BM12: 8705.3794 | BN12: 9348.774 | BO12: 8993.469 | BP12: 9310.3853 | BQ12: 8918.3728 | BR12: 9067.3999 | BS12: 9375.3189 | BT12: 8990.9903 | BU12: 9922.438 | BV12: 10034.511 | BW12: 9805.1669 | BX12: 10107.824 | BY12: 9925.7192 | BZ12: 10582.078 | CA12: 10240.119 | CB12: 10570.294 | CC12: 10190.842 | CD12: 10351.105 | CE12: 10668.414 | CF12: 10291.415 | CG12: 11228.328 | CH12: 11344.678 | CI12: 11119.768 | CJ12: 11428.789 | CK12: 11255.867 | CL12: 11927.053 | CM12: 11603.231 | CN12: 11954.281 | CO12: 11600.711 | CP12: 11766.283 | CQ12: 12092.494 | CR12: 11749.491 | CS12: 12510.017 | CT12: 12847.979 | CU12: 12472.469 | CV12: -1 | CW12: 1
C13: Actual | CV13: 0 | CW13: 0
A14: Ac1201 | B14: adm | C14: Forecast | D14: 129.28288 | E14: 127.28931 | F14: 177.02006 | G14: 209.95592 | H14: 230.05114 | I14: 246.67733 | J14: 231.02716 | K14: 222.21148 | L14: 205.02928 | M14: 174.22828 | N14: 169.41673 | O14: 143.90467 | P14: 173.11489 | Q14: 176.16274 | R14: 212.17861 | S14: 239.62245 | T14: 256.20238 | U14: 267.27595 | V14: 245.98566 | W14: 231.49701 | X14: 210.24501 | Y14: 178.56907 | Z14: 176.31746 | AA14: 156.24246 | AB14: 192.20924 | AC14: 201.55697 | AD14: 242.12817 | AE14: 271.84451 | AF14: 288.65425 | AG14: 298.68633 | AH14: 275.99584 | AI14: 260.48649 | AJ14: 239.00119 | AK14: 207.95519 | AL14: 207.04004 | AM14: 188.74538 | AN14: 226.66608 | AO14: 237.9181 | AP14: 280.18806 | AQ14: 311.31048 | AR14: 329.21095 | AS14: 340.05389 | AT14: 317.97641 | AU14: 302.9912 | AV14: 282.05105 | AW14: 251.65618 | AX14: 251.54049 | AY14: 234.18924 | AZ14: 273.15574 | BA14: 285.49551 | BB14: 328.83575 | BC14: 360.96781 | BD14: 379.79701 | BE14: 391.48907 | BF14: 370.19691 | BG14: 355.9549 | BH14: 335.73599 | BI14: 306.05501 | BJ14: 306.65416 | BK14: 290.02248 | BL14: 329.71523 | BM14: 342.79039 | BN14: 386.87899 | BO14: 419.77654 | BP14: 439.39036 | BQ14: 451.88263 | BR14: 431.39462 | BS14: 417.94023 | BT14: 398.46568 | BU14: 369.4584 | BV14: 370.64078 | BW14: 354.4981 | BX14: 394.60435 | BY14: 408.06034 | BZ14: 452.55903 | CA14: 485.96514 | CB14: 506.2451 | CC14: 519.59094 | CD14: 500.12696 | CE14: 487.7946 | CF14: 469.41389 | CG14: 441.31501 | CH14: 443.06247 | CI14: 427.03594 | CJ14: 466.79894 | CK14: 479.59078 | CL14: 523.31672 | CM14: 556.28016 | CN14: 576.70634 | CO14: 591.14029 | CP14: 573.77022 | CQ14: 564.07651 | CR14: 548.15813 | CS14: 526.73694 | CT14: 523.85305 | CU14: 517.82064 | CV14: 1 | CW14: 1
C15: Actual | CV15: 0 | CW15: 0
A16: Ac1201 | B16: desl | C16: Forecast | D16: 194.57113 | E16: 160.17272 | F16: 162.62916 | G16: 155.30179 | H16: 173.75641 | I16: 171.52241 | J16: 190.16659 | K16: 202.07626 | L16: 195.6393 | M16: 233.98995 | N16: 232.97433 | O16: 227.65978 | P16: 221.46624 | Q16: 194.35189 | R16: 193.15444 | S16: 179.65028 | T16: 197.97286 | U16: 196.28604 | V16: 215.82088 | W16: 228.87548 | X16: 222.33679 | Y16: 259.67196 | Z16: 257.45519 | AA16: 251.47417 | AB16: 245.5843 | AC16: 219.74563 | AD16: 220.4966 | AE16: 209.1856 | AF16: 229.57871 | AG16: 229.64308 | AH16: 250.58524 | AI16: 264.79024 | AJ16: 259.26412 | AK16: 297.5695 | AL16: 296.3351 | AM16: 291.3719 | AN16: 286.54507 | AO16: 261.82168 | AP16: 263.74399 | AQ16: 253.65492 | AR16: 275.30141 | AS16: 276.62011 | AT16: 298.78437 | AU16: 314.15408 | AV16: 309.72569 | AW16: 349.06899 | AX16: 348.83162 | AY16: 344.84707 | AZ16: 340.99891 | BA16: 317.264 | BB16: 320.18526 | BC16: 311.09975 | BD16: 333.7458 | BE16: 336.05224 | BF16: 359.1874 | BG16: 375.50944 | BH16: 372.0156 | BI16: 412.27781 | BJ16: 412.94579 | BK16: 409.85413 | BL16: 406.88601 | BM16: 384.01653 | BN16: 387.78611 | BO16: 379.52966 | BP16: 402.98504 | BQ16: 406.08325 | BR16: 429.99787 | BS16: 447.09475 | BT16: 444.37956 | BU16: 485.43086 | BV16: 486.9006 | BW16: 484.61909 | BX16: 482.45809 | BY16: 460.3755 | BZ16: 464.89211 | CA16: 457.32569 | CB16: 481.40502 | CC16: 485.0649 | CD16: 509.49863 | CE16: 527.10647 | CF16: 524.93997 | CG16: 566.62248 | CH16: 568.83549 | CI16: 567.42169 | CJ16: 566.21106 | CK16: 545.07166 | CL16: 550.48886 | CM16: 543.54084 | CN16: 567.98377 | CO16: 571.90381 | CP16: 595.55716 | CQ16: 613.87422 | CR16: 611.59118 | CS16: 648.40546 | CT16: 659.83404 | CU16: 652.5949 | CV16: -1 | CW16: 1
C17: Actual | CV17: 0 | CW17: 0
A18: Ac1202 | B18: adm | C18: Forecast | D18: 1631.3306 | E18: 1721.5021 | F18: 1893.8196 | G18: 1956.8734 | H18: 1949.5672 | I18: 1978.9168 | J18: 1924.7042 | K18: 1923.8549 | L18: 1858.2958 | M18: 1728.1868 | N18: 1753.4649 | O18: 1541.7077 | P18: 1853.6069 | Q18: 1945.144 | R18: 2147.9136 | S18: 2157.4975 | T18: 2143.2747 | U18: 2154.9152 | V18: 2088.076 | W18: 2084.4676 | X18: 2020.9065 | Y18: 1902.5902 | Z18: 1945.291 | AA18: 1752.7924 | AB18: 2082.6978 | AC18: 2187.6506 | AD18: 2398.0857 | AE18: 2410.4631 | AF18: 2396.1687 | AG18: 2407.235 | AH18: 2341.2253 | AI18: 2340.8258 | AJ18: 2282.8983 | AK18: 2172.0426 | AL18: 2223.1586 | AM18: 2039.2003 | AN18: 2377.165 | AO18: 2489.3557 | AP18: 2706.1012 | AQ18: 2723.9339 | AR18: 2714.4326 | AS18: 2729.8919 | AT18: 2668.1551 | AU18: 2672.1552 | AV18: 2618.9207 | AW18: 2513.1117 | AX18: 2569.5809 | AY18: 2391.156 | AZ18: 2734.674 | BA18: 2852.2912 | BB18: 3074.2372 | BC18: 3097.0069 | BD18: 3092.1965 | BE18: 3112.1533 | BF18: 3054.7849 | BG18: 3063.0817 | BH18: 3014.1125 | BI18: 2912.5594 | BJ18: 2973.2846 | BK18: 2799.1188 | BL18: 3146.9012 | BM18: 3268.7905 | BN18: 3495.016 | BO18: 3522.0628 | BP18: 3521.5023 | BQ18: 3545.6388 | BR18: 3492.3228 | BS18: 3504.4838 | BT18: 3459.1441 | BU18: 3360.9729 | BV18: 3424.8689 | BW18: 3253.7543 | BX18: 3604.6045 | BY18: 3729.7325 | BZ18: 3959.5011 | CA18: 3990.4662 | CB18: 3994.1707 | CC18: 4022.7757 | CD18: 3973.8766 | CE18: 3990.078 | CF18: 3948.0641 | CG18: 3852.2573 | CH18: 3917.464 | CI18: 3746.7913 | CJ18: 4097.6611 | CK18: 4223.2543 | CL18: 4454.417 | CM18: 4488.991 | CN18: 4498.4223 | CO18: 4534.6024 | CP18: 4494.0916 | CQ18: 4518.481 | CR18: 4473.9175 | CS18: 4403.3006 | CT18: 4419.4225 | CU18: 4289.4679 | CV18: 1 | CW18: 1
C19: Actual | CV19: 0 | CW19: 0
A20: Ac1202 | B20: desl | C20: Forecast | D20: 1769.317 | E20: 1703.0219 | F20: 1883.9633 | G20: 1719.809 | H20: 1905.4268 | I20: 1735.212 | J20: 1784.0269 | K20: 1872.1527 | L20: 1717.7498 | M20: 2080.3847 | N20: 2074.9243 | O20: 2069.6951 | P20: 2067.5215 | Q20: 1865.3161 | R20: 2032.2053 | S20: 1864.5393 | T20: 2029.3143 | U20: 1861.5335 | V20: 1908.306 | W20: 1999.8855 | X20: 1855.9582 | Y20: 2231.5647 | Z20: 2241.341 | AA20: 2250.2938 | AB20: 2258.9645 | AC20: 2064.2612 | AD20: 2236.2889 | AE20: 2072.8927 | AF20: 2242.4382 | AG20: 2080.6485 | AH20: 2134.6868 | AI20: 2234.4587 | AJ20: 2099.1693 | AK20: 2483.4469 | AL20: 2501.6819 | AM20: 2518.7766 | AN20: 2535.2372 | AO20: 2347.96 | AP20: 2527.054 | AQ20: 2370.3996 | AR20: 2546.4433 | AS20: 2391.0253 | AT20: 2451.4314 | AU20: 2557.6583 | AV20: 2428.9445 | AW20: 2819.8911 | AX20: 2844.818 | AY20: 2868.5444 | AZ20: 2891.5067 | BA20: 2710.5624 | BB20: 2895.8133 | BC20: 2745.1557 | BD20: 2927.0623 | BE20: 2777.399 | BF20: 2843.4713 | BG20: 2955.2898 | BH20: 2832.1046 | BI20: 3228.5287 | BJ20: 3258.8964 | BK20: 3288.0415 | BL20: 3316.4111 | BM20: 3140.8633 | BN20: 3331.4857 | BO20: 3186.1421 | BP20: 3373.2572 | BQ20: 3228.6414 | BR20: 3299.5519 | BS20: 3415.9742 | BT20: 3297.1733 | BU20: 3697.8238 | BV20: 3732.3645 | BW20: 3765.7565 | BX20: 3798.5672 | BY20: 3627.7307 | BZ20: 3823.3359 | CA20: 3683.1563 | CB20: 3875.4378 | CC20: 3735.7469 | CD20: 3811.0813 | CE20: 3931.2 | CF20: 3815.2578 | CG20: 4217.9873 | CH20: 4254.0822 | CI20: 4289.0144 | CJ20: 4324.1091 | CK20: 4156.6205 | CL20: 4357.8226 | CM20: 4224.7204 | CN20: 4424.8978 | CO20: 4295.6812 | CP20: 4374.337 | CQ20: 4494.8381 | CR20: 4400.0035 | CS20: 4726.7486 | CT20: 4858.0776 | CU20: 4823.9144 | CV20: -1 | CW20: 1
C21: Actual | CV21: 0 | CW21: 0
A22: Am1301 | B22: adm | C22: Forecast | D22: 26.557922 | E22: 16.017332 | F22: 24.009068 | G22: 18.191291 | H22: 15.401722 | I22: 22.969178 | J22: 11.282975 | K22: 14.762628 | L22: 18.243871 | M22: 4.3148319 | N22: 20.26132 | O22: 15.869947 | P22: 34.143157 | Q22: 19.313991 | R22: 20.304048 | S22: 15.913067 | T22: 12.206519 | U22: 19.195481 | V22: 8.0817066 | W22: 11.230621 | X22: 14.695638 | Y22: 0.81246232 | Z22: 16.772126 | AA22: 12.513428 | AB22: 30.947386 | AC22: 16.243552 | AD22: 17.310297 | AE22: 12.94412 | AF22: 9.2252023 | AG22: 16.190091 | AH22: 5.0623475 | AI22: 8.2177824 | AJ22: 11.710824 | AK22: -2.1287125 | AL22: 13.881428 | AM22: 9.6733015 | AN22: 28.154473 | AO22: 13.493304 | AP22: 14.598139 | AQ22: 10.265725 | AR22: 6.5764785 | AS22: 13.567491 | AT22: 2.4634395 | AU22: 5.6417466 | AV22: 9.158562 | AW22: -4.6549959 | AX22: 11.383802 | AY22: 7.2065777 | AZ22: 25.719831 | BA22: 11.090669 | BB22: 12.22642 | BC22: 7.9232818 | BD22: 4.2616081 | BE22: 11.278745 | BF22: 0.19973634 | BG22: 3.4023137 | BH22: 6.9428179 | BI22: -6.8475214 | BJ22: 9.2141484 | BK22: 5.0596703 | BL22: 23.595885 | BM22: 8.9903058 | BN22: 10.150597 | BO22: 5.8730712 | BP22: 2.2378412 | BQ22: 9.2816165 | BR22: -1.7715173 | BS22: 1.4550845 | BT22: 5.0168138 | BU22: -8.7556336 | BV22: 7.3206911 | BW22: 3.1784739 | BX22: 21.726126 | BY22: 7.133321 | BZ22: 8.3101455 | CA22: 4.0550916 | CB22: 0.44948358 | CC22: 7.5295819 | CD22: -3.4835413 | CE22: -0.21854567 | CF22: 3.3722942 | CG22: -10.386809 | CH22: 5.6835486 | CI22: 1.5142307 | CJ22: 20.025969 | CK22: 5.4103014 | CL22: 6.5577472 | CM22: 2.350612 | CN22: -1.2297676 | CO22: 5.8354092 | CP22: -4.8380552 | CQ22: -2.1029098 | CR22: 1.437249 | CS22: -9.2037732 | CT22: -0.40192512 | CU22: 4.7806808 | CV22: 1 | CW22: 1
C23: Actual | CV23: 0 | CW23: 0
A24: Am1301 | B24: desl | C24: Forecast | D24: 17.838627 | E24: 25.415515 | F24: 17.811334 | G24: 17.782937 | H24: 19.896878 | I24: 10.996796 | J24: 14.936565 | K24: 14.581896 | L24: 10.59873 | M24: 26.734261 | N24: 22.242291 | O24: 35.006846 | P24: 15.667755 | Q24: 19.288042 | R24: 12.630537 | S24: 12.383325 | T24: 14.000385 | U24: 5.6660048 | V24: 9.3956107 | W24: 9.2688327 | X24: 5.5023533 | Y24: 21.658929 | Z24: 17.15363 | AA24: 29.828493 | AB24: 10.363303 | AC24: 13.900769 | AD24: 7.226674 | AE24: 7.0204382 | AF24: 8.7102389 | AG24: 0.44916847 | AH24: 4.2307807 | AI24: 4.1294712 | AJ24: 0.36822729 | AK24: 16.520415 | AL24: 12.010513 | AM24: 24.685163 | AN24: 5.2241736 | AO24: 8.7684514 | AP24: 2.1023762 | AQ24: 1.9052396 | AR24: 3.6060002 | AS24: -4.6416274 | AT24: -0.84445625 | AU24: -0.92948028 | AV24: -4.6755154 | AW24: 11.489401 | AX24: 6.9893114 | AY24: 19.671448 | AZ24: 0.21684984 | BA24: 3.767698 | BB24: -2.8907837 | BC24: -3.0790976 | BD24: -1.3686222 | BE24: -9.6062472 | BF24: -5.7993512 | BG24: -5.8752426 | BH24: -9.6127298 | BI24: 6.5604217 | BJ24: 2.0686585 | BK24: 14.759586 | BL24: -4.6855564 | BM24: -1.1246536 | BN24: -7.7728521 | BO24: -7.9512758 | BP24: -6.2320374 | BQ24: -14.462663 | BR24: -10.650832 | BS24: -10.723631 | BT24: -14.459051 | BU24: 1.7164615 | BV24: -2.7710997 | BW24: 9.9272585 | BX24: -9.5064111 | BY24: -5.9301132 | BZ24: -12.560202 | CA24: -12.720087 | CB24: -10.984936 | CC24: -19.205731 | CD24: -15.392875 | CE24: -15.475171 | CF24: -19.229037 | CG24: -3.076825 | CH24: -7.5862287 | CI24: 5.1020318 | CJ24: -14.315669 | CK24: -10.711594 | CL24: -17.257678 | CM24: -17.364756 | CN24: -15.571585 | CO24: -23.66411 | CP24: -20.086945 | CQ24: -20.252557 | CR24: -22.847778 | CS24: -11.064691 | CT24: -8.449302 | CU24: -2.5193421 | CV24: -1 | CW24: 1
C25: Actual | CV25: 0 | CW25: 0
A26: Am1302 | B26: adm | C26: Forecast | D26: 27.941897 | E26: 25.585754 | F26: 30.092035 | G26: 29.908072 | H26: 29.558493 | I26: 32.122741 | J26: 28.836753 | K26: 30.206445 | L26: 30.539159 | M26: 25.043933 | N26: 29.069202 | O26: 25.187936 | P26: 31.99874 | Q26: 30.596576 | R26: 34.081346 | S26: 34.119022 | T26: 33.558415 | U26: 35.850439 | V26: 32.502759 | W26: 33.699988 | X26: 34.058854 | Y26: 28.802813 | Z26: 33.203998 | AA26: 29.759441 | AB26: 36.949639 | AC26: 35.789621 | AD26: 39.369643 | AE26: 39.39885 | AF26: 38.793268 | AG26: 41.064386 | AH26: 37.753589 | AI26: 39.048925 | AJ26: 39.550404 | AK26: 34.458025 | AL26: 39.024052 | AM26: 35.733905 | AN26: 43.06391 | AO26: 42.029053 | AP26: 45.720911 | AQ26: 45.850228 | AR26: 45.335202 | AS26: 47.690658 | AT26: 44.462406 | AU26: 45.843045 | AV26: 46.4359 | AW26: 41.442032 | AX26: 46.112331 | AY26: 42.929128 | AZ26: 50.365165 | BA26: 49.432531 | BB26: 53.2213 | BC26: 53.442193 | BD26: 53.014441 | BE26: 55.454335 | BF26: 52.309025 | BG26: 53.772002 | BH26: 54.446988 | BI26: 49.535082 | BJ26: 54.287062 | BK26: 51.185172 | BL26: 58.70218 | BM26: 57.850297 | BN26: 61.71972 | BO26: 62.021149 | BP26: 61.673511 | BQ26: 64.192437 | BR26: 61.12409 | BS26: 62.660833 | BT26: 63.405433 | BU26: 58.558597 | BV26: 63.371604 | BW26: 60.328235 | BX26: 67.903686 | BY26: 67.112998 | BZ26: 71.048874 | CA26: 71.423398 | CB26: 71.155128 | CC26: 73.757291 | CD26: 70.771727 | CE26: 72.385315 | CF26: 73.194878 | CG26: 68.396513 | CH26: 73.239832 | CI26: 70.208419 | CJ26: 77.786613 | CK26: 77.003709 | CL26: 80.954378 | CM26: 81.396156 | CN26: 81.231749 | CO26: 83.937065 | CP26: 81.272423 | CQ26: 82.751758 | CR26: 83.744769 | CS26: 79.82204 | CT26: 82.312321 | CU26: 81.926074 | CV26: 1 | CW26: 1
C27: Actual | CV27: 0 | CW27: 0
A28: Am1302 | B28: desl | C28: Forecast | D28: 31.380551 | E28: 26.150817 | F28: 29.742052 | G28: 26.680523 | H28: 28.356021 | I28: 28.988406 | J28: 29.087755 | K28: 31.077767 | L28: 33.000939 | M28: 31.141555 | N28: 31.58534 | O28: 27.995519 | P28: 30.375136 | Q28: 26.360933 | R28: 29.950733 | S28: 27.318496 | T28: 29.099974 | U28: 30.059511 | V28: 30.201876 | W28: 32.09975 | X28: 33.971593 | Y28: 32.031355 | Z28: 32.42099 | AA28: 28.840478 | AB28: 31.276566 | AC28: 27.354418 | AD28: 31.058484 | AE28: 28.545484 | AF28: 30.439393 | AG28: 31.498711 | AH28: 31.725468 | AI28: 33.691849 | AJ28: 35.617981 | AK28: 33.721557 | AL28: 34.150102 | AM28: 30.609612 | AN28: 33.091556 | AO28: 29.22354 | AP28: 32.989867 | AQ28: 30.544864 | AR28: 32.508882 | AS28: 33.636811 | AT28: 33.928092 | AU28: 35.953799 | AV28: 37.934347 | AW28: 36.088651 | AX28: 36.565826 | AY28: 33.07333 | AZ28: 35.603656 | BA28: 31.784898 | BB28: 35.601374 | BC28: 33.207104 | BD28: 35.221985 | BE28: 36.400455 | BF28: 36.741605 | BG28: 38.816305 | BH28: 40.844898 | BI28: 39.046307 | BJ28: 39.569654 | BK28: 36.12234 | BL28: 38.696725 | BM28: 34.920728 | BN28: 38.778554 | BO28: 36.424286 | BP28: 38.478141 | BQ28: 39.695158 | BR28: 40.075199 | BS28: 42.189895 | BT28: 44.260101 | BU28: 42.504785 | BV28: 43.072519 | BW28: 39.669564 | BX28: 42.28669 | BY28: 38.550056 | BZ28: 42.442338 | CA28: 40.116733 | CB28: 42.193743 | CC28: 43.430181 | CD28: 43.829442 | CE28: 45.967716 | CF28: 48.071101 | CG28: 46.361878 | CH28: 46.990006 | CI28: 43.654737 | CJ28: 46.343703 | CK28: 42.667027 | CL28: 46.597281 | CM28: 44.276006 | CN28: 46.359173 | CO28: 47.508244 | CP28: 48.01672 | CQ28: 49.850785 | CR28: 52.052361 | CS28: 51.110862 | CT28: 50.705921 | CU28: 49.656763 | CV28: -1 | CW28: 1
C29: Actual | CV29: 0 | CW29: 0
A30: Am1303 | B30: adm | C30: Forecast | D30: 11388.339 | E30: 11972.454 | F30: 13808.242 | G30: 13892.995 | H30: 13895.892 | I30: 14560.565 | J30: 14034.345 | K30: 14641.946 | L30: 14510.623 | M30: 13109.052 | N30: 13298.686 | O30: 10839.834 | P30: 13609.005 | Q30: 14194.683 | R30: 16325.923 | S30: 16431.731 | T30: 16361.834 | U30: 16929.126 | V30: 16341.894 | W30: 16977.127 | X30: 16966.719 | Y30: 15760.366 | Z30: 16147.305 | AA30: 13825.841 | AB30: 16646.42 | AC30: 17202.147 | AD30: 19253.665 | AE30: 19272.151 | AF30: 19140.185 | AG30: 19685.372 | AH30: 19113.577 | AI30: 19788.918 | AJ30: 19828.207 | AK30: 18669.574 | AL30: 19096.004 | AM30: 16803.961 | AN30: 19644.528 | AO30: 20212.317 | AP30: 22269.72 | AQ30: 22289.982 | AR30: 22158.219 | AS30: 22704.814 | AT30: 22138.034 | AU30: 22823.334 | AV30: 22877.414 | AW30: 21736.976 | AX30: 22182.847 | AY30: 19909.363 | AZ30: 22766.136 | BA30: 23347.26 | BB30: 25415.466 | BC30: 25444.865 | BD30: 25321.548 | BE30: 25876.665 | BF30: 25318.89 | BG30: 26013.745 | BH30: 26077.78 | BI30: 24947.492 | BJ30: 25403.58 | BK30: 23140.388 | BL30: 26007.668 | BM30: 26599.705 | BN30: 28679.365 | BO30: 28720.711 | BP30: 28609.519 | BQ30: 29176.346 | BR30: 28629.09 | BS30: 29332.518 | BT30: 29402.704 | BU30: 28276.216 | BV30: 28734.511 | BW30: 26473.352 | BX30: 29344.327 | BY30: 29943.541 | BZ30: 32035.147 | CA30: 32093.477 | CB30: 32003.254 | CC30: 32592.61 | CD30: 32065.9 | CE30: 32783.812 | CF30: 32858.614 | CG30: 31724.574 | CH30: 32163.472 | CI30: 29874.506 | CJ30: 32717.606 | CK30: 33300.115 | CL30: 35392.841 | CM30: 35486.062 | CN30: 35459.245 | CO30: 36122.345 | CP30: 35709.908 | CQ30: 36426.657 | CR30: 36508.109 | CS30: 35609.133 | CT30: 35395.928 | CU30: 33549.447 | CV30: 1 | CW30: 1
C31: Actual | CV31: 0 | CW31: 0
