Workbook
Name B: #REF!
Name bootstrap_flag: #REF!
Name cb_blockdiag: #REF!
Name cb_blockdiagexc: #REF!
Name cb_exccountry: #REF!
Name cb_lambda: #REF!
Name cb_samplecov: #REF!
Name ccodes: #REF!
Name chow_cut: #REF!
Name cnames: #REF!
Name cnames_long: #REF!
Name criterion: #REF!
Name dvflag: #REF!
Name estcase: #REF!
Name first_trdyear: #REF!
Name firstcountries: #REF!
Name firstobs: #REF!
Name fvflag: #REF!
Name fvflag_we: #REF!
Name graphsflag: #REF!
Name gvflag: #REF!
Name gvflag_we: #REF!
Name gvnames: #REF!
Name gvnames_long: #REF!
Name gvshockmtrx: #REF!
Name importbuild_wmat_flag: #REF!
Name last_trdyear: #REF!
Name lastobs: #REF!
Name maxlag: #REF!
Name N: #REF!
Name newordervars: #REF!
Name outdir: #REF!
Name overid_flag: #REF!
Name pauseflag: #REF!
Name pe_blockdiag: #REF!
Name pe_blockdiagexc: #REF!
Name pe_exccountry: #REF!
Name pe_lambda: #REF!
Name pe_samplecov: #REF!
Name rank: #REF!
Name regcountries: #REF!
Name regcountriesx: #REF!
Name rnames: #REF!
Name rnames_long: #REF!
Name rnamesx: #REF!
Name rnamesx_long: #REF!
Name ss_B: #REF!
Name ss_bootstrap_flag: #REF!
Name ss_flag: #REF!
Name trade_window: #REF!
Name tvw_solution: #REF!
Name tvw_solution_modeflag: #REF!
Name urt_criterion: #REF!
Name urt_maxlag: #REF!
Name urtflag: #REF!
Name varxlag: #REF!
Name varxlag_we: #REF!
Name vnames: #REF!
Name vnames_long: #REF!
Name vshockmtrx: #REF!

Sheet MAIN
A1: 1 | B1: 2 | C1: 3 | D1: 4 | E1: 5 | F1: 6 | G1: 7 | H1: 8 | I1: 9 | J1: 10 | K1: 11
D2: CAGED | E2: CAGED | F2: IPEA | G2: IPEA | H2: LCA | I2: LCA
A3: Data | B3: Ano | C3: Mês | D3: Adm | E3: Des | F3: Adm | G3: Des | H3: Adm | I3: Des | J3: PIM | K3: Emp Liquido | L3: LN(PIM) | M3: DLN | N3: Data Fim | O3: Data Inicio | P3: Data Inicio 2 | Q3: Data Fim 2 | R3: PIM Final | S3: Pim Inicial | T3: Var Pim | U3: Média Var Pim Ano | V3: Soma Emp Liq No Ano | W3: Soma PIM Ano
A4: =EOMONTH(A5,-1) -> 27425 | B4: =YEAR(A4) -> 1975 | C4: =MONTH(A4) -> 1 | J4: 40.694754 | K4: =IF(AND(ISNUMBER(D4),ISNUMBER(E4)),D4-E4,IF(AND(ISNUMBER(F4),ISNUMBER(G4)),F4-G4,H4-I4)) -> 0 | L4: =LN(J4) -> 3.7060992 | M4: =L4-L3 -> #VALUE! | N4: {=MAX(IF($B$4:$B$507=B4,$A$4:$A$507))} -> 27759 | O4: {=MIN(IF($B$4:$B$507=B4,$A$4:$A$507))} -> 27425 | P4: =EOMONTH(Q4,-12) -> 27060 | Q4: =A4 -> 27425 | R4: =VLOOKUP(Q4,$A$4:$L$507,$J$1,FALSE) -> 40.694754 | S4: =VLOOKUP(P4,$A$4:$L$507,$J$1,FALSE) -> #N/A | T4: =R4/S4-1 -> #N/A | U4: =AVERAGEIF($B$4:$B$507,B4,$T$4:$T$507) -> #N/A
A5: =EOMONTH(A6,-1) -> 27453 | B5: =YEAR(A5) -> 1975 | C5: =MONTH(A5) -> 2 | J5: 38.18129 | K5: =IF(AND(ISNUMBER(D5),ISNUMBER(E5)),D5-E5,IF(AND(ISNUMBER(F5),ISNUMBER(G5)),F5-G5,H5-I5)) -> 0 | L5: =LN(J5) -> 3.6423456 | M5: =L5-L4 -> -0.063753568 | N5: {=MAX(IF($B$4:$B$507=B5,$A$4:$A$507))} -> 27759 | O5: {=MIN(IF($B$4:$B$507=B5,$A$4:$A$507))} -> 27425 | P5: =EOMONTH(Q5,-12) -> 27088 | Q5: =A5 -> 27453 | R5: =VLOOKUP(Q5,$A$4:$L$507,$J$1,FALSE) -> 38.18129 | S5: =VLOOKUP(P5,$A$4:$L$507,$J$1,FALSE) -> #N/A | T5: =R5/S5-1 -> #N/A | U5: =AVERAGEIF($B$4:$B$507,B5,$T$4:$T$507) -> #N/A
A6: =EOMONTH(A7,-1) -> 27484 | B6: =YEAR(A6) -> 1975 | C6: =MONTH(A6) -> 3 | J6: 41.35231 | K6: =IF(AND(ISNUMBER(D6),ISNUMBER(E6)),D6-E6,IF(AND(ISNUMBER(F6),ISNUMBER(G6)),F6-G6,H6-I6)) -> 0 | L6: =LN(J6) -> 3.7221283 | M6: =L6-L5 -> 0.079782673 | N6: {=MAX(IF($B$4:$B$507=B6,$A$4:$A$507))} -> 27759 | O6: {=MIN(IF($B$4:$B$507=B6,$A$4:$A$507))} -> 27425 | P6: =EOMONTH(Q6,-12) -> 27119 | Q6: =A6 -> 27484 | R6: =VLOOKUP(Q6,$A$4:$L$507,$J$1,FALSE) -> 41.35231 | S6: =VLOOKUP(P6,$A$4:$L$507,$J$1,FALSE) -> #N/A | T6: =R6/S6-1 -> #N/A | U6: =AVERAGEIF($B$4:$B$507,B6,$T$4:$T$507) -> #N/A
A7: =EOMONTH(A8,-1) -> 27514 | B7: =YEAR(A7) -> 1975 | C7: =MONTH(A7) -> 4 | J7: 43.570795 | K7: =IF(AND(ISNUMBER(D7),ISNUMBER(E7)),D7-E7,IF(AND(ISNUMBER(F7),ISNUMBER(G7)),F7-G7,H7-I7)) -> 0 | L7: =LN(J7) -> 3.7743871 | M7: =L7-L6 -> 0.052258796 | N7: {=MAX(IF($B$4:$B$507=B7,$A$4:$A$507))} -> 27759 | O7: {=MIN(IF($B$4:$B$507=B7,$A$4:$A$507))} -> 27425 | P7: =EOMONTH(Q7,-12) -> 27149 | Q7: =A7 -> 27514 | R7: =VLOOKUP(Q7,$A$4:$L$507,$J$1,FALSE) -> 43.570795 | S7: =VLOOKUP(P7,$A$4:$L$507,$J$1,FALSE) -> #N/A | T7: =R7/S7-1 -> #N/A | U7: =AVERAGEIF($B$4:$B$507,B7,$T$4:$T$507) -> #N/A
A8: =EOMONTH(A9,-1) -> 27545 | B8: =YEAR(A8) -> 1975 | C8: =MONTH(A8) -> 5 | J8: 43.724429 | K8: =IF(AND(ISNUMBER(D8),ISNUMBER(E8)),D8-E8,IF(AND(ISNUMBER(F8),ISNUMBER(G8)),F8-G8,H8-I8)) -> 0 | L8: =LN(J8) -> 3.777907 | M8: =L8-L7 -> 0.003519891 | N8: {=MAX(IF($B$4:$B$507=B8,$A$4:$A$507))} -> 27759 | O8: {=MIN(IF($B$4:$B$507=B8,$A$4:$A$507))} -> 27425 | P8: =EOMONTH(Q8,-12) -> 27180 | Q8: =A8 -> 27545 | R8: =VLOOKUP(Q8,$A$4:$L$507,$J$1,FALSE) -> 43.724429 | S8: =VLOOKUP(P8,$A$4:$L$507,$J$1,FALSE) -> #N/A | T8: =R8/S8-1 -> #N/A | U8: =AVERAGEIF($B$4:$B$507,B8,$T$4:$T$507) -> #N/A
A9: =EOMONTH(A10,-1) -> 27575 | B9: =YEAR(A9) -> 1975 | C9: =MONTH(A9) -> 6 | J9: 45.174741 | K9: =IF(AND(ISNUMBER(D9),ISNUMBER(E9)),D9-E9,IF(AND(ISNUMBER(F9),ISNUMBER(G9)),F9-G9,H9-I9)) -> 0 | L9: =LN(J9) -> 3.8105381 | M9: =L9-L8 -> 0.032631127 | N9: {=MAX(IF($B$4:$B$507=B9,$A$4:$A$507))} -> 27759 | O9: {=MIN(IF($B$4:$B$507=B9,$A$4:$A$507))} -> 27425 | P9: =EOMONTH(Q9,-12) -> 27210 | Q9: =A9 -> 27575 | R9: =VLOOKUP(Q9,$A$4:$L$507,$J$1,FALSE) -> 45.174741 | S9: =VLOOKUP(P9,$A$4:$L$507,$J$1,FALSE) -> #N/A | T9: =R9/S9-1 -> #N/A | U9: =AVERAGEIF($B$4:$B$507,B9,$T$4:$T$507) -> #N/A
A10: =EOMONTH(A11,-1) -> 27606 | B10: =YEAR(A10) -> 1975 | C10: =MONTH(A10) -> 7 | J10: 46.877013 | K10: =IF(AND(ISNUMBER(D10),ISNUMBER(E10)),D10-E10,IF(AND(ISNUMBER(F10),ISNUMBER(G10)),F10-G10,H10-I10)) -> 0 | L10: =LN(J10) -> 3.8475274 | M10: =L10-L9 -> 0.036989329 | N10: {=MAX(IF($B$4:$B$507=B10,$A$4:$A$507))} -> 27759 | O10: {=MIN(IF($B$4:$B$507=B10,$A$4:$A$507))} -> 27425 | P10: =EOMONTH(Q10,-12) -> 27241 | Q10: =A10 -> 27606 | R10: =VLOOKUP(Q10,$A$4:$L$507,$J$1,FALSE) -> 46.877013 | S10: =VLOOKUP(P10,$A$4:$L$507,$J$1,FALSE) -> #N/A | T10: =R10/S10-1 -> #N/A | U10: =AVERAGEIF($B$4:$B$507,B10,$T$4:$T$507) -> #N/A
A11: =EOMONTH(A12,-1) -> 27637 | B11: =YEAR(A11) -> 1975 | C11: =MONTH(A11) -> 8 | J11: 46.022804 | K11: =IF(AND(ISNUMBER(D11),ISNUMBER(E11)),D11-E11,IF(AND(ISNUMBER(F11),ISNUMBER(G11)),F11-G11,H11-I11)) -> 0 | L11: =LN(J11) -> 3.829137 | M11: =L11-L10 -> -0.01839041 | N11: {=MAX(IF($B$4:$B$507=B11,$A$4:$A$507))} -> 27759 | O11: {=MIN(IF($B$4:$B$507=B11,$A$4:$A$507))} -> 27425 | P11: =EOMONTH(Q11,-12) -> 27272 | Q11: =A11 -> 27637 | R11: =VLOOKUP(Q11,$A$4:$L$507,$J$1,FALSE) -> 46.022804 | S11: =VLOOKUP(P11,$A$4:$L$507,$J$1,FALSE) -> #N/A | T11: =R11/S11-1 -> #N/A | U11: =AVERAGEIF($B$4:$B$507,B11,$T$4:$T$507) -> #N/A
A12: =EOMONTH(A13,-1) -> 27667 | B12: =YEAR(A12) -> 1975 | C12: =MONTH(A12) -> 9 | J12: 47.178137 | K12: =IF(AND(ISNUMBER(D12),ISNUMBER(E12)),D12-E12,IF(AND(ISNUMBER(F12),ISNUMBER(G12)),F12-G12,H12-I12)) -> 0 | L12: =LN(J12) -> 3.8539306 | M12: =L12-L11 -> 0.024793569 | N12: {=MAX(IF($B$4:$B$507=B12,$A$4:$A$507))} -> 27759 | O12: {=MIN(IF($B$4:$B$507=B12,$A$4:$A$507))} -> 27425 | P12: =EOMONTH(Q12,-12) -> 27302 | Q12: =A12 -> 27667 | R12: =VLOOKUP(Q12,$A$4:$L$507,$J$1,FALSE) -> 47.178137 | S12: =VLOOKUP(P12,$A$4:$L$507,$J$1,FALSE) -> #N/A | T12: =R12/S12-1 -> #N/A | U12: =AVERAGEIF($B$4:$B$507,B12,$T$4:$T$507) -> #N/A
A13: =EOMONTH(A14,-1) -> 27698 | B13: =YEAR(A13) -> 1975 | C13: =MONTH(A13) -> 10 | J13: 48.81281 | K13: =IF(AND(ISNUMBER(D13),ISNUMBER(E13)),D13-E13,IF(AND(ISNUMBER(F13),ISNUMBER(G13)),F13-G13,H13-I13)) -> 0 | L13: =LN(J13) -> 3.8879928 | M13: =L13-L12 -> 0.034062192 | N13: {=MAX(IF($B$4:$B$507=B13,$A$4:$A$507))} -> 27759 | O13: {=MIN(IF($B$4:$B$507=B13,$A$4:$A$507))} -> 27425 | P13: =EOMONTH(Q13,-12) -> 27333 | Q13: =A13 -> 27698 | R13: =VLOOKUP(Q13,$A$4:$L$507,$J$1,FALSE) -> 48.81281 | S13: =VLOOKUP(P13,$A$4:$L$507,$J$1,FALSE) -> #N/A | T13: =R13/S13-1 -> #N/A | U13: =AVERAGEIF($B$4:$B$507,B13,$T$4:$T$507) -> #N/A
A14: =EOMONTH(A15,-1) -> 27728 | B14: =YEAR(A14) -> 1975 | C14: =MONTH(A14) -> 11 | J14: 45.752407 | K14: =IF(AND(ISNUMBER(D14),ISNUMBER(E14)),D14-E14,IF(AND(ISNUMBER(F14),ISNUMBER(G14)),F14-G14,H14-I14)) -> 0 | L14: =LN(J14) -> 3.8232444 | M14: =L14-L13 -> -0.064748372 | N14: {=MAX(IF($B$4:$B$507=B14,$A$4:$A$507))} -> 27759 | O14: {=MIN(IF($B$4:$B$507=B14,$A$4:$A$507))} -> 27425 | P14: =EOMONTH(Q14,-12) -> 27363 | Q14: =A14 -> 27728 | R14: =VLOOKUP(Q14,$A$4:$L$507,$J$1,FALSE) -> 45.752407 | S14: =VLOOKUP(P14,$A$4:$L$507,$J$1,FALSE) -> #N/A | T14: =R14/S14-1 -> #N/A | U14: =AVERAGEIF($B$4:$B$507,B14,$T$4:$T$507) -> #N/A
A15: =EOMONTH(A16,-1) -> 27759 | B15: =YEAR(A15) -> 1975 | C15: =MONTH(A15) -> 12 | J15: 44.394277 | K15: =IF(AND(ISNUMBER(D15),ISNUMBER(E15)),D15-E15,IF(AND(ISNUMBER(F15),ISNUMBER(G15)),F15-G15,H15-I15)) -> 0 | L15: =LN(J15) -> 3.7931106 | M15: =L15-L14 -> -0.03013385 | N15: {=MAX(IF($B$4:$B$507=B15,$A$4:$A$507))} -> 27759 | O15: {=MIN(IF($B$4:$B$507=B15,$A$4:$A$507))} -> 27425 | P15: =EOMONTH(Q15,-12) -> 27394 | Q15: =A15 -> 27759 | R15: =VLOOKUP(Q15,$A$4:$L$507,$J$1,FALSE) -> 44.394277 | S15: =VLOOKUP(P15,$A$4:$L$507,$J$1,FALSE) -> #N/A | T15: =R15/S15-1 -> #N/A | U15: =AVERAGEIF($B$4:$B$507,B15,$T$4:$T$507) -> #N/A
... A231: =EOMONTH(A232,-1) -> 34334 | B231: =YEAR(A231) -> 1993 | C231: =MONTH(A231) -> 12 | J231: 59.691107 | K231: =IF(AND(ISNUMBER(D231),ISNUMBER(E231)),D231-E231,IF(AND(ISNUMBER(F231),ISNUMBER(G231)),F231-G231,H231-I231)) -> 0 | L231: =LN(J231) -> 4.0891831 | M231: =L231-L230 -> -0.10399631 | N231: {=MAX(IF($B$4:$B$507=B231,$A$4:$A$507))} -> 34334 | O231: {=MIN(IF($B$4:$B$507=B231,$A$4:$A$507))} -> 34000 | P231: =EOMONTH(Q231,-12) -> 33969 | Q231: =A231 -> 34334 | R231: =VLOOKUP(Q231,$A$4:$L$507,$J$1,FALSE) -> 59.691107 | S231: =VLOOKUP(P231,$A$4:$L$507,$J$1,FALSE) -> 55.008044 | T231: =R231/S231-1 -> 0.085134155 | U231: =AVERAGEIF($B$4:$B$507,B231,$T$4:$T$507) -> 0.074603129
A232: =EOMONTH(A233,-1) -> 34365 | B232: =YEAR(A232) -> 1994 | C232: =MONTH(A232) -> 1 | J232: 58.70184 | K232: =IF(AND(ISNUMBER(D232),ISNUMBER(E232)),D232-E232,IF(AND(ISNUMBER(F232),ISNUMBER(G232)),F232-G232,H232-I232)) -> 0 | L232: =LN(J232) -> 4.0724711 | M232: =L232-L231 -> -0.016711979 | N232: {=MAX(IF($B$4:$B$507=B232,$A$4:$A$507))} -> 34699 | O232: {=MIN(IF($B$4:$B$507=B232,$A$4:$A$507))} -> 34365 | P232: =EOMONTH(Q232,-12) -> 34000 | Q232: =A232 -> 34365 | R232: =VLOOKUP(Q232,$A$4:$L$507,$J$1,FALSE) -> 58.70184 | S232: =VLOOKUP(P232,$A$4:$L$507,$J$1,FALSE) -> 54.018777 | T232: =R232/S232-1 -> 0.086693251 | U232: =AVERAGEIF($B$4:$B$507,B232,$T$4:$T$507) -> 0.07591762 | V232: =SUMIF($B$232:$B$507,B232,$K$232:$K$507) -> 0 | W232: =SUMIF($B$232:$B$507,B232,$J$232:$J$507) -> 821.23539 | Y232: =SUMIF($B$4:$B$507,B232,$J$4:$J$507) -> 821.23539
A233: =EOMONTH(A234,-1) -> 34393 | B233: =YEAR(A233) -> 1994 | C233: =MONTH(A233) -> 2 | J233: 55.893598 | K233: =IF(AND(ISNUMBER(D233),ISNUMBER(E233)),D233-E233,IF(AND(ISNUMBER(F233),ISNUMBER(G233)),F233-G233,H233-I233)) -> 0 | L233: =LN(J233) -> 4.0234498 | M233: =L233-L232 -> -0.049021232 | N233: {=MAX(IF($B$4:$B$507=B233,$A$4:$A$507))} -> 34699 | O233: {=MIN(IF($B$4:$B$507=B233,$A$4:$A$507))} -> 34365 | P233: =EOMONTH(Q233,-12) -> 34028 | Q233: =A233 -> 34393 | R233: =VLOOKUP(Q233,$A$232:$L$507,$J$1,FALSE) -> 55.893598 | S233: =VLOOKUP(P233,$A$4:$L$507,$J$1,FALSE) -> 53.907085 | T233: =R233/S233-1 -> 0.036850673 | U233: =AVERAGEIF($B$4:$B$507,B233,$T$4:$T$507) -> 0.07591762 | V233: =SUMIF($B$232:$B$507,B233,$K$232:$K$507) -> 0 | W233: =SUMIF($B$232:$B$507,B233,$J$232:$J$507) -> 821.23539 | Y233: =SUMIF($B$4:$B$507,B233,$J$4:$J$507) -> 821.23539
A234: =EOMONTH(A235,-1) -> 34424 | B234: =YEAR(A234) -> 1994 | C234: =MONTH(A234) -> 3 | J234: 67.421752 | K234: =IF(AND(ISNUMBER(D234),ISNUMBER(E234)),D234-E234,IF(AND(ISNUMBER(F234),ISNUMBER(G234)),F234-G234,H234-I234)) -> 0 | L234: =LN(J234) -> 4.2109677 | M234: =L234-L233 -> 0.18751785 | N234: {=MAX(IF($B$4:$B$507=B234,$A$4:$A$507))} -> 34699 | O234: {=MIN(IF($B$4:$B$507=B234,$A$4:$A$507))} -> 34365 | P234: =EOMONTH(Q234,-12) -> 34059 | Q234: =A234 -> 34424 | R234: =VLOOKUP(Q234,$A$232:$L$507,$J$1,FALSE) -> 67.421752 | S234: =VLOOKUP(P234,$A$4:$L$507,$J$1,FALSE) -> 64.262479 | T234: =R234/S234-1 -> 0.049162011 | U234: =AVERAGEIF($B$4:$B$507,B234,$T$4:$T$507) -> 0.07591762 | V234: =SUMIF($B$232:$B$507,B234,$K$232:$K$507) -> 0 | W234: =SUMIF($B$232:$B$507,B234,$J$232:$J$507) -> 821.23539 | Y234: =SUMIF($B$4:$B$507,B234,$J$4:$J$507) -> 821.23539
A235: =EOMONTH(A236,-1) -> 34454 | B235: =YEAR(A235) -> 1994 | C235: =MONTH(A235) -> 4 | J235: 61.390413 | K235: =IF(AND(ISNUMBER(D235),ISNUMBER(E235)),D235-E235,IF(AND(ISNUMBER(F235),ISNUMBER(G235)),F235-G235,H235-I235)) -> 0 | L235: =LN(J235) -> 4.1172537 | M235: =L235-L234 -> -0.09371401 | N235: {=MAX(IF($B$4:$B$507=B235,$A$4:$A$507))} -> 34699 | O235: {=MIN(IF($B$4:$B$507=B235,$A$4:$A$507))} -> 34365 | P235: =EOMONTH(Q235,-12) -> 34089 | Q235: =A235 -> 34454 | R235: =VLOOKUP(Q235,$A$232:$L$507,$J$1,FALSE) -> 61.390413 | S235: =VLOOKUP(P235,$A$4:$L$507,$J$1,FALSE) -> 60.728242 | T235: =R235/S235-1 -> 0.010903836 | U235: =AVERAGEIF($B$4:$B$507,B235,$T$4:$T$507) -> 0.07591762 | V235: =SUMIF($B$232:$B$507,B235,$K$232:$K$507) -> 0 | W235: =SUMIF($B$232:$B$507,B235,$J$232:$J$507) -> 821.23539 | Y235: =SUMIF($B$4:$B$507,B235,$J$4:$J$507) -> 821.23539
A236: =EOMONTH(A237,-1) -> 34485 | B236: =YEAR(A236) -> 1994 | C236: =MONTH(A236) -> 5 | J236: 68.865763 | K236: =IF(AND(ISNUMBER(D236),ISNUMBER(E236)),D236-E236,IF(AND(ISNUMBER(F236),ISNUMBER(G236)),F236-G236,H236-I236)) -> 0 | L236: =LN(J236) -> 4.2321591 | M236: =L236-L235 -> 0.11490546 | N236: {=MAX(IF($B$4:$B$507=B236,$A$4:$A$507))} -> 34699 | O236: {=MIN(IF($B$4:$B$507=B236,$A$4:$A$507))} -> 34365 | P236: =EOMONTH(Q236,-12) -> 34120 | Q236: =A236 -> 34485 | R236: =VLOOKUP(Q236,$A$232:$L$507,$J$1,FALSE) -> 68.865763 | S236: =VLOOKUP(P236,$A$4:$L$507,$J$1,FALSE) -> 65.594799 | T236: =R236/S236-1 -> 0.049866213 | U236: =AVERAGEIF($B$4:$B$507,B236,$T$4:$T$507) -> 0.07591762 | V236: =SUMIF($B$232:$B$507,B236,$K$232:$K$507) -> 0 | W236: =SUMIF($B$232:$B$507,B236,$J$232:$J$507) -> 821.23539 | Y236: =SUMIF($B$4:$B$507,B236,$J$4:$J$507) -> 821.23539
A237: =EOMONTH(A238,-1) -> 34515 | B237: =YEAR(A237) -> 1994 | C237: =MONTH(A237) -> 6 | J237: 68.754072 | K237: =IF(AND(ISNUMBER(D237),ISNUMBER(E237)),D237-E237,IF(AND(ISNUMBER(F237),ISNUMBER(G237)),F237-G237,H237-I237)) -> 0 | L237: =LN(J237) -> 4.230536 | M237: =L237-L236 -> -0.0016231888 | N237: {=MAX(IF($B$4:$B$507=B237,$A$4:$A$507))} -> 34699 | O237: {=MIN(IF($B$4:$B$507=B237,$A$4:$A$507))} -> 34365 | P237: =EOMONTH(Q237,-12) -> 34150 | Q237: =A237 -> 34515 | R237: =VLOOKUP(Q237,$A$232:$L$507,$J$1,FALSE) -> 68.754072 | S237: =VLOOKUP(P237,$A$4:$L$507,$J$1,FALSE) -> 66.073477 | T237: =R237/S237-1 -> 0.040569911 | U237: =AVERAGEIF($B$4:$B$507,B237,$T$4:$T$507) -> 0.07591762 | V237: =SUMIF($B$232:$B$507,B237,$K$232:$K$507) -> 0 | W237: =SUMIF($B$232:$B$507,B237,$J$232:$J$507) -> 821.23539 | Y237: =SUMIF($B$4:$B$507,B237,$J$4:$J$507) -> 821.23539
A238: =EOMONTH(A239,-1) -> 34546 | B238: =YEAR(A238) -> 1994 | C238: =MONTH(A238) -> 7 | J238: 70.222017 | K238: =IF(AND(ISNUMBER(D238),ISNUMBER(E238)),D238-E238,IF(AND(ISNUMBER(F238),ISNUMBER(G238)),F238-G238,H238-I238)) -> 0 | L238: =LN(J238) -> 4.2516619 | M238: =L238-L237 -> 0.021125929 | N238: {=MAX(IF($B$4:$B$507=B238,$A$4:$A$507))} -> 34699 | O238: {=MIN(IF($B$4:$B$507=B238,$A$4:$A$507))} -> 34365 | P238: =EOMONTH(Q238,-12) -> 34181 | Q238: =A238 -> 34546 | R238: =VLOOKUP(Q238,$A$232:$L$507,$J$1,FALSE) -> 70.222017 | S238: =VLOOKUP(P238,$A$4:$L$507,$J$1,FALSE) -> 69.105102 | T238: =R238/S238-1 -> 0.016162549 | U238: =AVERAGEIF($B$4:$B$507,B238,$T$4:$T$507) -> 0.07591762 | V238: =SUMIF($B$232:$B$507,B238,$K$232:$K$507) -> 0 | W238: =SUMIF($B$232:$B$507,B238,$J$232:$J$507) -> 821.23539 | Y238: =SUMIF($B$4:$B$507,B238,$J$4:$J$507) -> 821.23539
A239: =EOMONTH(A240,-1) -> 34577 | B239: =YEAR(A239) -> 1994 | C239: =MONTH(A239) -> 8 | J239: 76.636298 | K239: =IF(AND(ISNUMBER(D239),ISNUMBER(E239)),D239-E239,IF(AND(ISNUMBER(F239),ISNUMBER(G239)),F239-G239,H239-I239)) -> 0 | L239: =LN(J239) -> 4.3390708 | M239: =L239-L238 -> 0.087408935 | N239: {=MAX(IF($B$4:$B$507=B239,$A$4:$A$507))} -> 34699 | O239: {=MIN(IF($B$4:$B$507=B239,$A$4:$A$507))} -> 34365 | P239: =EOMONTH(Q239,-12) -> 34212 | Q239: =A239 -> 34577 | R239: =VLOOKUP(Q239,$A$232:$L$507,$J$1,FALSE) -> 76.636298 | S239: =VLOOKUP(P239,$A$4:$L$507,$J$1,FALSE) -> 69.496022 | T239: =R239/S239-1 -> 0.10274366 | U239: =AVERAGEIF($B$4:$B$507,B239,$T$4:$T$507) -> 0.07591762 | V239: =SUMIF($B$232:$B$507,B239,$K$232:$K$507) -> 0 | W239: =SUMIF($B$232:$B$507,B239,$J$232:$J$507) -> 821.23539 | Y239: =SUMIF($B$4:$B$507,B239,$J$4:$J$507) -> 821.23539
A240: =EOMONTH(A241,-1) -> 34607 | B240: =YEAR(A240) -> 1994 | C240: =MONTH(A240) -> 9 | J240: 74.522138 | K240: =IF(AND(ISNUMBER(D240),ISNUMBER(E240)),D240-E240,IF(AND(ISNUMBER(F240),ISNUMBER(G240)),F240-G240,H240-I240)) -> 0 | L240: =LN(J240) -> 4.3110962 | M240: =L240-L239 -> -0.02797459 | N240: {=MAX(IF($B$4:$B$507=B240,$A$4:$A$507))} -> 34699 | O240: {=MIN(IF($B$4:$B$507=B240,$A$4:$A$507))} -> 34365 | P240: =EOMONTH(Q240,-12) -> 34242 | Q240: =A240 -> 34607 | R240: =VLOOKUP(Q240,$A$232:$L$507,$J$1,FALSE) -> 74.522138 | S240: =VLOOKUP(P240,$A$4:$L$507,$J$1,FALSE) -> 66.887229 | T240: =R240/S240-1 -> 0.11414599 | U240: =AVERAGEIF($B$4:$B$507,B240,$T$4:$T$507) -> 0.07591762 | V240: =SUMIF($B$232:$B$507,B240,$K$232:$K$507) -> 0 | W240: =SUMIF($B$232:$B$507,B240,$J$232:$J$507) -> 821.23539 | Y240: =SUMIF($B$4:$B$507,B240,$J$4:$J$507) -> 821.23539
A241: =EOMONTH(A242,-1) -> 34638 | B241: =YEAR(A241) -> 1994 | C241: =MONTH(A241) -> 10 | J241: 74.266843 | K241: =IF(AND(ISNUMBER(D241),ISNUMBER(E241)),D241-E241,IF(AND(ISNUMBER(F241),ISNUMBER(G241)),F241-G241,H241-I241)) -> 0 | L241: =LN(J241) -> 4.3076646 | M241: =L241-L240 -> -0.0034316388 | N241: {=MAX(IF($B$4:$B$507=B241,$A$4:$A$507))} -> 34699 | O241: {=MIN(IF($B$4:$B$507=B241,$A$4:$A$507))} -> 34365 | P241: =EOMONTH(Q241,-12) -> 34273 | Q241: =A241 -> 34638 | R241: =VLOOKUP(Q241,$A$232:$L$507,$J$1,FALSE) -> 74.266843 | S241: =VLOOKUP(P241,$A$4:$L$507,$J$1,FALSE) -> 67.206347 | T241: =R241/S241-1 -> 0.10505698 | U241: =AVERAGEIF($B$4:$B$507,B241,$T$4:$T$507) -> 0.07591762 | V241: =SUMIF($B$232:$B$507,B241,$K$232:$K$507) -> 0 | W241: =SUMIF($B$232:$B$507,B241,$J$232:$J$507) -> 821.23539 | Y241: =SUMIF($B$4:$B$507,B241,$J$4:$J$507) -> 821.23539
A242: =EOMONTH(A243,-1) -> 34668 | B242: =YEAR(A242) -> 1994 | C242: =MONTH(A242) -> 11 | J242: 74.306733 | K242: =IF(AND(ISNUMBER(D242),ISNUMBER(E242)),D242-E242,IF(AND(ISNUMBER(F242),ISNUMBER(G242)),F242-G242,H242-I242)) -> 0 | L242: =LN(J242) -> 4.3082016 | M242: =L242-L241 -> 0.00053697043 | N242: {=MAX(IF($B$4:$B$507=B242,$A$4:$A$507))} -> 34699 | O242: {=MIN(IF($B$4:$B$507=B242,$A$4:$A$507))} -> 34365 | P242: =EOMONTH(Q242,-12) -> 34303 | Q242: =A242 -> 34668 | R242: =VLOOKUP(Q242,$A$232:$L$507,$J$1,FALSE) -> 74.306733 | S242: =VLOOKUP(P242,$A$4:$L$507,$J$1,FALSE) -> 66.233036 | T242: =R242/S242-1 -> 0.12189834 | U242: =AVERAGEIF($B$4:$B$507,B242,$T$4:$T$507) -> 0.07591762 | V242: =SUMIF($B$232:$B$507,B242,$K$232:$K$507) -> 0 | W242: =SUMIF($B$232:$B$507,B242,$J$232:$J$507) -> 821.23539 | Y242: =SUMIF($B$4:$B$507,B242,$J$4:$J$507) -> 821.23539
A243: =EOMONTH(A244,-1) -> 34699 | B243: =YEAR(A243) -> 1994 | C243: =MONTH(A243) -> 12 | J243: 70.253928 | K243: =IF(AND(ISNUMBER(D243),ISNUMBER(E243)),D243-E243,IF(AND(ISNUMBER(F243),ISNUMBER(G243)),F243-G243,H243-I243)) -> 0 | L243: =LN(J243) -> 4.2521162 | M243: =L243-L242 -> -0.056085337 | N243: {=MAX(IF($B$4:$B$507=B243,$A$4:$A$507))} -> 34699 | O243: {=MIN(IF($B$4:$B$507=B243,$A$4:$A$507))} -> 34365 | P243: =EOMONTH(Q243,-12) -> 34334 | Q243: =A243 -> 34699 | R243: =VLOOKUP(Q243,$A$232:$L$507,$J$1,FALSE) -> 70.253928 | S243: =VLOOKUP(P243,$A$4:$L$507,$J$1,FALSE) -> 59.691107 | T243: =R243/S243-1 -> 0.17695803 | U243: =AVERAGEIF($B$4:$B$507,B243,$T$4:$T$507) -> 0.07591762 | V243: =SUMIF($B$232:$B$507,B243,$K$232:$K$507) -> 0 | W243: =SUMIF($B$232:$B$507,B243,$J$232:$J$507) -> 821.23539 | Y243: =SUMIF($B$4:$B$507,B243,$J$4:$J$507) -> 821.23539
A244: =EOMONTH(A245,-1) -> 34730 | B244: =YEAR(A244) -> 1995 | C244: =MONTH(A244) -> 1 | H244: 759389 | I244: 781822 | J244: 68.650358 | K244: =IF(AND(ISNUMBER(D244),ISNUMBER(E244)),D244-E244,IF(AND(ISNUMBER(F244),ISNUMBER(G244)),F244-G244,H244-I244)) -> -22433 | L244: =LN(J244) -> 4.2290263 | M244: =L244-L243 -> -0.023089878 | N244: {=MAX(IF($B$4:$B$507=B244,$A$4:$A$507))} -> 35064 | O244: {=MIN(IF($B$4:$B$507=B244,$A$4:$A$507))} -> 34730 | P244: =EOMONTH(Q244,-12) -> 34365 | Q244: =A244 -> 34730 | R244: =VLOOKUP(Q244,$A$232:$L$507,$J$1,FALSE) -> 68.650358 | S244: =VLOOKUP(P244,$A$4:$L$507,$J$1,FALSE) -> 58.70184 | T244: =R244/S244-1 -> 0.1694754 | U244: =AVERAGEIF($B$4:$B$507,B244,$T$4:$T$507) -> 0.025854015 | V244: =SUMIF($B$232:$B$507,B244,$K$232:$K$507) -> -200246 | W244: =SUMIF($B$232:$B$507,B244,$J$232:$J$507) -> 836.27385 | Y244: =SUMIF($B$4:$B$507,B244,$J$4:$J$507) -> 836.27385 | AA244: =YEAR(A244) -> 1995 | AB244: =Y244/Y232-1 -> 0.018311994 | AC244: =V244 -> -200246
A245: =EOMONTH(A246,-1) -> 34758 | B245: =YEAR(A245) -> 1995 | C245: =MONTH(A245) -> 2 | H245: 842884 | I245: 782686 | J245: 65.43524 | K245: =IF(AND(ISNUMBER(D245),ISNUMBER(E245)),D245-E245,IF(AND(ISNUMBER(F245),ISNUMBER(G245)),F245-G245,H245-I245)) -> 60198 | L245: =LN(J245) -> 4.1810609 | M245: =L245-L244 -> -0.047965403 | N245: {=MAX(IF($B$4:$B$507=B245,$A$4:$A$507))} -> 35064 | O245: {=MIN(IF($B$4:$B$507=B245,$A$4:$A$507))} -> 34730 | P245: =EOMONTH(Q245,-12) -> 34393 | Q245: =A245 -> 34758 | R245: =VLOOKUP(Q245,$A$232:$L$507,$J$1,FALSE) -> 65.43524 | S245: =VLOOKUP(P245,$A$4:$L$507,$J$1,FALSE) -> 55.893598 | T245: =R245/S245-1 -> 0.17071082 | U245: =AVERAGEIF($B$4:$B$507,B245,$T$4:$T$507) -> 0.025854015 | V245: =SUMIF($B$232:$B$507,B245,$K$232:$K$507) -> -200246 | W245: =SUMIF($B$232:$B$507,B245,$J$232:$J$507) -> 836.27385 | Y245: =SUMIF($B$4:$B$507,B245,$J$4:$J$507) -> 836.27385 | AA245: =YEAR(A245) -> 1995 | AB245: =Y245/Y233-1 -> 0.018311994 | AC245: =V245 -> -200246
A246: =EOMONTH(A247,-1) -> 34789 | B246: =YEAR(A246) -> 1995 | C246: =MONTH(A246) -> 3 | H246: 906380 | I246: 885187 | J246: 76.349091 | K246: =IF(AND(ISNUMBER(D246),ISNUMBER(E246)),D246-E246,IF(AND(ISNUMBER(F246),ISNUMBER(G246)),F246-G246,H246-I246)) -> 21193 | L246: =LN(J246) -> 4.3353161 | M246: =L246-L245 -> 0.15425518 | N246: {=MAX(IF($B$4:$B$507=B246,$A$4:$A$507))} -> 35064 | O246: {=MIN(IF($B$4:$B$507=B246,$A$4:$A$507))} -> 34730 | P246: =EOMONTH(Q246,-12) -> 34424 | Q246: =A246 -> 34789 | R246: =VLOOKUP(Q246,$A$232:$L$507,$J$1,FALSE) -> 76.349091 | S246: =VLOOKUP(P246,$A$4:$L$507,$J$1,FALSE) -> 67.421752 | T246: =R246/S246-1 -> 0.13241037 | U246: =AVERAGEIF($B$4:$B$507,B246,$T$4:$T$507) -> 0.025854015 | V246: =SUMIF($B$232:$B$507,B246,$K$232:$K$507) -> -200246 | W246: =SUMIF($B$232:$B$507,B246,$J$232:$J$507) -> 836.27385 | Y246: =SUMIF($B$4:$B$507,B246,$J$4:$J$507) -> 836.27385 | AA246: =YEAR(A246) -> 1995 | AB246: =Y246/Y234-1 -> 0.018311994 | AC246: =V246 -> -200246
A247: =EOMONTH(A248,-1) -> 34819 | B247: =YEAR(A247) -> 1995 | C247: =MONTH(A247) -> 4 | H247: 817428 | I247: 737642 | J247: 68.546645 | K247: =IF(AND(ISNUMBER(D247),ISNUMBER(E247)),D247-E247,IF(AND(ISNUMBER(F247),ISNUMBER(G247)),F247-G247,H247-I247)) -> 79786 | L247: =LN(J247) -> 4.2275145 | M247: =L247-L246 -> -0.10780167 | N247: {=MAX(IF($B$4:$B$507=B247,$A$4:$A$507))} -> 35064 | O247: {=MIN(IF($B$4:$B$507=B247,$A$4:$A$507))} -> 34730 | P247: =EOMONTH(Q247,-12) -> 34454 | Q247: =A247 -> 34819 | R247: =VLOOKUP(Q247,$A$232:$L$507,$J$1,FALSE) -> 68.546645 | S247: =VLOOKUP(P247,$A$4:$L$507,$J$1,FALSE) -> 61.390413 | T247: =R247/S247-1 -> 0.1165692 | U247: =AVERAGEIF($B$4:$B$507,B247,$T$4:$T$507) -> 0.025854015 | V247: =SUMIF($B$232:$B$507,B247,$K$232:$K$507) -> -200246 | W247: =SUMIF($B$232:$B$507,B247,$J$232:$J$507) -> 836.27385 | Y247: =SUMIF($B$4:$B$507,B247,$J$4:$J$507) -> 836.27385 | AA247: =YEAR(A247) -> 1995 | AB247: =Y247/Y235-1 -> 0.018311994 | AC247: =V247 -> -200246
A248: =EOMONTH(A249,-1) -> 34850 | B248: =YEAR(A248) -> 1995 | C248: =MONTH(A248) -> 5 | H248: 892872 | I248: 809819 | J248: 67.956275 | K248: =IF(AND(ISNUMBER(D248),ISNUMBER(E248)),D248-E248,IF(AND(ISNUMBER(F248),ISNUMBER(G248)),F248-G248,H248-I248)) -> 83053 | L248: =LN(J248) -> 4.2188645 | M248: =L248-L247 -> -0.0086499663 | N248: {=MAX(IF($B$4:$B$507=B248,$A$4:$A$507))} -> 35064 | O248: {=MIN(IF($B$4:$B$507=B248,$A$4:$A$507))} -> 34730 | P248: =EOMONTH(Q248,-12) -> 34485 | Q248: =A248 -> 34850 | R248: =VLOOKUP(Q248,$A$232:$L$507,$J$1,FALSE) -> 67.956275 | S248: =VLOOKUP(P248,$A$4:$L$507,$J$1,FALSE) -> 68.865763 | T248: =R248/S248-1 -> -0.013206673 | U248: =AVERAGEIF($B$4:$B$507,B248,$T$4:$T$507) -> 0.025854015 | V248: =SUMIF($B$232:$B$507,B248,$K$232:$K$507) -> -200246 | W248: =SUMIF($B$232:$B$507,B248,$J$232:$J$507) -> 836.27385 | Y248: =SUMIF($B$4:$B$507,B248,$J$4:$J$507) -> 836.27385 | AA248: =YEAR(A248) -> 1995 | AB248: =Y248/Y236-1 -> 0.018311994 | AC248: =V248 -> -200246
A249: =EOMONTH(A250,-1) -> 34880 | B249: =YEAR(A249) -> 1995 | C249: =MONTH(A249) -> 6 | H249: 787262 | I249: 786155 | J249: 71.322975 | K249: =IF(AND(ISNUMBER(D249),ISNUMBER(E249)),D249-E249,IF(AND(ISNUMBER(F249),ISNUMBER(G249)),F249-G249,H249-I249)) -> 1107 | L249: =LN(J249) -> 4.2672185 | M249: =L249-L248 -> 0.048354018 | N249: {=MAX(IF($B$4:$B$507=B249,$A$4:$A$507))} -> 35064 | O249: {=MIN(IF($B$4:$B$507=B249,$A$4:$A$507))} -> 34730 | P249: =EOMONTH(Q249,-12) -> 34515 | Q249: =A249 -> 34880 | R249: =VLOOKUP(Q249,$A$232:$L$507,$J$1,FALSE) -> 71.322975 | S249: =VLOOKUP(P249,$A$4:$L$507,$J$1,FALSE) -> 68.754072 | T249: =R249/S249-1 -> 0.037363657 | U249: =AVERAGEIF($B$4:$B$507,B249,$T$4:$T$507) -> 0.025854015 | V249: =SUMIF($B$232:$B$507,B249,$K$232:$K$507) -> -200246 | W249: =SUMIF($B$232:$B$507,B249,$J$232:$J$507) -> 836.27385 | Y249: =SUMIF($B$4:$B$507,B249,$J$4:$J$507) -> 836.27385 | AA249: =YEAR(A249) -> 1995 | AB249: =Y249/Y237-1 -> 0.018311994 | AC249: =V249 -> -200246
A250: =EOMONTH(A251,-1) -> 34911 | B250: =YEAR(A250) -> 1995 | C250: =MONTH(A250) -> 7 | H250: 722661 | I250: 793589 | J250: 70.604959 | K250: =IF(AND(ISNUMBER(D250),ISNUMBER(E250)),D250-E250,IF(AND(ISNUMBER(F250),ISNUMBER(G250)),F250-G250,H250-I250)) -> -70928 | L250: =LN(J250) -> 4.2571004 | M250: =L250-L249 -> -0.01011813 | N250: {=MAX(IF($B$4:$B$507=B250,$A$4:$A$507))} -> 35064 | O250: {=MIN(IF($B$4:$B$507=B250,$A$4:$A$507))} -> 34730 | P250: =EOMONTH(Q250,-12) -> 34546 | Q250: =A250 -> 34911 | R250: =VLOOKUP(Q250,$A$232:$L$507,$J$1,FALSE) -> 70.604959 | S250: =VLOOKUP(P250,$A$4:$L$507,$J$1,FALSE) -> 70.222017 | T250: =R250/S250-1 -> 0.0054533061 | U250: =AVERAGEIF($B$4:$B$507,B250,$T$4:$T$507) -> 0.025854015 | V250: =SUMIF($B$232:$B$507,B250,$K$232:$K$507) -> -200246 | W250: =SUMIF($B$232:$B$507,B250,$J$232:$J$507) -> 836.27385 | Y250: =SUMIF($B$4:$B$507,B250,$J$4:$J$507) -> 836.27385 | AA250: =YEAR(A250) -> 1995 | AB250: =Y250/Y238-1 -> 0.018311994 | AC250: =V250 -> -200246
A251: =EOMONTH(A252,-1) -> 34942 | B251: =YEAR(A251) -> 1995 | C251: =MONTH(A251) -> 8 | H251: 758026 | I251: 881354 | J251: 72.647317 | K251: =IF(AND(ISNUMBER(D251),ISNUMBER(E251)),D251-E251,IF(AND(ISNUMBER(F251),ISNUMBER(G251)),F251-G251,H251-I251)) -> -123328 | L251: =LN(J251) -> 4.2856165 | M251: =L251-L250 -> 0.028516078 | N251: {=MAX(IF($B$4:$B$507=B251,$A$4:$A$507))} -> 35064 | O251: {=MIN(IF($B$4:$B$507=B251,$A$4:$A$507))} -> 34730 | P251: =EOMONTH(Q251,-12) -> 34577 | Q251: =A251 -> 34942 | R251: =VLOOKUP(Q251,$A$232:$L$507,$J$1,FALSE) -> 72.647317 | S251: =VLOOKUP(P251,$A$4:$L$507,$J$1,FALSE) -> 76.636298 | T251: =R251/S251-1 -> -0.052050802 | U251: =AVERAGEIF($B$4:$B$507,B251,$T$4:$T$507) -> 0.025854015 | V251: =SUMIF($B$232:$B$507,B251,$K$232:$K$507) -> -200246 | W251: =SUMIF($B$232:$B$507,B251,$J$232:$J$507) -> 836.27385 | Y251: =SUMIF($B$4:$B$507,B251,$J$4:$J$507) -> 836.27385 | AA251: =YEAR(A251) -> 1995 | AB251: =Y251/Y239-1 -> 0.018311994 | AC251: =V251 -> -200246
A252: =EOMONTH(A253,-1) -> 34972 | B252: =YEAR(A252) -> 1995 | C252: =MONTH(A252) -> 9 | H252: 684304 | I252: 756662 | J252: 69.527934 | K252: =IF(AND(ISNUMBER(D252),ISNUMBER(E252)),D252-E252,IF(AND(ISNUMBER(F252),ISNUMBER(G252)),F252-G252,H252-I252)) -> -72358 | L252: =LN(J252) -> 4.2417286 | M252: =L252-L251 -> -0.043887858 | N252: {=MAX(IF($B$4:$B$507=B252,$A$4:$A$507))} -> 35064 | O252: {=MIN(IF($B$4:$B$507=B252,$A$4:$A$507))} -> 34730 | P252: =EOMONTH(Q252,-12) -> 34607 | Q252: =A252 -> 34972 | R252: =VLOOKUP(Q252,$A$232:$L$507,$J$1,FALSE) -> 69.527934 | S252: =VLOOKUP(P252,$A$4:$L$507,$J$1,FALSE) -> 74.522138 | T252: =R252/S252-1 -> -0.067016379 | U252: =AVERAGEIF($B$4:$B$507,B252,$T$4:$T$507) -> 0.025854015 | V252: =SUMIF($B$232:$B$507,B252,$K$232:$K$507) -> -200246 | W252: =SUMIF($B$232:$B$507,B252,$J$232:$J$507) -> 836.27385 | Y252: =SUMIF($B$4:$B$507,B252,$J$4:$J$507) -> 836.27385 | AA252: =YEAR(A252) -> 1995 | AB252: =Y252/Y240-1 -> 0.018311994 | AC252: =V252 -> -200246
A253: =EOMONTH(A254,-1) -> 35003 | B253: =YEAR(A253) -> 1995 | C253: =MONTH(A253) -> 10 | H253: 667271 | I253: 715932 | J253: 72.447868 | K253: =IF(AND(ISNUMBER(D253),ISNUMBER(E253)),D253-E253,IF(AND(ISNUMBER(F253),ISNUMBER(G253)),F253-G253,H253-I253)) -> -48661 | L253: =LN(J253) -> 4.2828672 | M253: =L253-L252 -> 0.04113864 | N253: {=MAX(IF($B$4:$B$507=B253,$A$4:$A$507))} -> 35064 | O253: {=MIN(IF($B$4:$B$507=B253,$A$4:$A$507))} -> 34730 | P253: =EOMONTH(Q253,-12) -> 34638 | Q253: =A253 -> 35003 | R253: =VLOOKUP(Q253,$A$232:$L$507,$J$1,FALSE) -> 72.447868 | S253: =VLOOKUP(P253,$A$4:$L$507,$J$1,FALSE) -> 74.266843 | T253: =R253/S253-1 -> -0.024492427 | U253: =AVERAGEIF($B$4:$B$507,B253,$T$4:$T$507) -> 0.025854015 | V253: =SUMIF($B$232:$B$507,B253,$K$232:$K$507) -> -200246 | W253: =SUMIF($B$232:$B$507,B253,$J$232:$J$507) -> 836.27385 | Y253: =SUMIF($B$4:$B$507,B253,$J$4:$J$507) -> 836.27385 | AA253: =YEAR(A253) -> 1995 | AB253: =Y253/Y241-1 -> 0.018311994 | AC253: =V253 -> -200246
A254: =EOMONTH(A255,-1) -> 35033 | B254: =YEAR(A254) -> 1995 | C254: =MONTH(A254) -> 11 | H254: 629843 | I254: 706894 | J254: 70.900143 | K254: =IF(AND(ISNUMBER(D254),ISNUMBER(E254)),D254-E254,IF(AND(ISNUMBER(F254),ISNUMBER(G254)),F254-G254,H254-I254)) -> -77051 | L254: =LN(J254) -> 4.2612725 | M254: =L254-L253 -> -0.021594784 | N254: {=MAX(IF($B$4:$B$507=B254,$A$4:$A$507))} -> 35064 | O254: {=MIN(IF($B$4:$B$507=B254,$A$4:$A$507))} -> 34730 | P254: =EOMONTH(Q254,-12) -> 34668 | Q254: =A254 -> 35033 | R254: =VLOOKUP(Q254,$A$232:$L$507,$J$1,FALSE) -> 70.900143 | S254: =VLOOKUP(P254,$A$4:$L$507,$J$1,FALSE) -> 74.306733 | T254: =R254/S254-1 -> -0.045844965 | U254: =AVERAGEIF($B$4:$B$507,B254,$T$4:$T$507) -> 0.025854015 | V254: =SUMIF($B$232:$B$507,B254,$K$232:$K$507) -> -200246 | W254: =SUMIF($B$232:$B$507,B254,$J$232:$J$507) -> 836.27385 | Y254: =SUMIF($B$4:$B$507,B254,$J$4:$J$507) -> 836.27385 | AA254: =YEAR(A254) -> 1995 | AB254: =Y254/Y242-1 -> 0.018311994 | AC254: =V254 -> -200246
A255: =EOMONTH(A256,-1) -> 35064 | B255: =YEAR(A255) -> 1995 | C255: =MONTH(A255) -> 12 | H255: 833532 | I255: 864356 | J255: 61.885047 | K255: =IF(AND(ISNUMBER(D255),ISNUMBER(E255)),D255-E255,IF(AND(ISNUMBER(F255),ISNUMBER(G255)),F255-G255,H255-I255)) -> -30824 | L255: =LN(J255) -> 4.1252786 | M255: =L255-L254 -> -0.13599387 | N255: {=MAX(IF($B$4:$B$507=B255,$A$4:$A$507))} -> 35064 | O255: {=MIN(IF($B$4:$B$507=B255,$A$4:$A$507))} -> 34730 | P255: =EOMONTH(Q255,-12) -> 34699 | Q255: =A255 -> 35064 | R255: =VLOOKUP(Q255,$A$232:$L$507,$J$1,FALSE) -> 61.885047 | S255: =VLOOKUP(P255,$A$4:$L$507,$J$1,FALSE) -> 70.253928 | T255: =R255/S255-1 -> -0.11912333 | U255: =AVERAGEIF($B$4:$B$507,B255,$T$4:$T$507) -> 0.025854015 | V255: =SUMIF($B$232:$B$507,B255,$K$232:$K$507) -> -200246 | W255: =SUMIF($B$232:$B$507,B255,$J$232:$J$507) -> 836.27385 | Y255: =SUMIF($B$4:$B$507,B255,$J$4:$J$507) -> 836.27385 | AA255: =YEAR(A255) -> 1995 | AB255: =Y255/Y243-1 -> 0.018311994 | AC255: =V255 -> -200246
...

Sheet Planilha3
A1: Ano | B1: Média Var Pim Ano | C1: Soma Emp Liq No Ano
A2: 1995 | B2: 1.8311994 | C2: -200246 | F2: -49502.849 | G2: 182661.15 | H2: -0.27100918 | I2: 0.79420156 | M2: 100568.76 | N2: 155768.56 | O2: 138989.41 | P2: 257535.1
A3: 1996 | B3: 1.7305362 | C3: -271226 | F3: 100568.76 | G3: 61974.82 | H3: 1.6227358 | I3: 0.14867555 | K3: 100568.76 | L3: 61974.82 | M3: =($K3-M$2)/$L3 -> 0 | N3: =($K3-N$2)/$L3 -> -0.89068105 | O3: =($K3-O$2)/$L3 -> -0.61993966 | P3: =($K3-P$2)/$L3 -> -2.5327437
A4: 1997 | B4: 3.8879563 | C4: -35735 | K4: 155768.56 | L4: 35017.14 | M4: =($K4-M$2)/$L4 -> 1.5763651 | N4: =($K4-N$2)/$L4 -> 0 | O4: =($K4-O$2)/$L4 -> 0.47916961 | P4: =($K4-P$2)/$L4 -> -2.9061922
A5: 1998 | B5: -2.0264842 | C5: -581745 | F5: 710485.91 | G5: 197702.1 | H5: 3.5937197 | I5: 0.0042160555 | K5: 138989.41 | L5: 34036.59 | M5: =($K5-M$2)/$L5 -> 1.1288043 | N5: =($K5-N$2)/$L5 -> -0.49297386 | O5: =($K5-O$2)/$L5 -> 0 | P5: =($K5-P$2)/$L5 -> -3.4828897
A6: 1999 | B6: -0.65322744 | C6: -222346 | F6: 155768.56 | G6: 35017.14 | H6: 4.4483519 | I6: 0.00098136566
A7: 2000 | B7: 6.6401432 | C7: 675194
A8: 2001 | B8: 1.5775422 | C8: 586511 | F8: 378563.52 | G8: 161052.47 | H8: 2.3505602 | I8: 0.029116784
A9: 2002 | B9: 2.3448167 | C9: 468672 | F9: 138989.41 | G9: 34036.59 | H9: 4.0835293 | I9: 0.00057869114
A10: 2003 | B10: 0.32504981 | C10: 710054
A11: 2004 | B11: 8.340301 | C11: 1523276
A12: 2005 | B12: 2.8072545 | C12: 1253999
A13: 2006 | B13: 2.7024491 | C13: 1228686
A14: 2007 | B14: 5.9205116 | C14: 1617392
A15: 2008 | B15: 3.0794445 | C15: 1452205
A16: 2009 | B16: -7.1213389 | C16: 995111
A17: 2010 | B17: 10.217137 | C17: 2136938
A18: 2011 | B18: 0.40873048 | C18: 1566043
A19: 2012 | B19: -2.3039974 | C19: 868241
A20: 2013 | B20: 2.075 | C20: 730687 | F20: OLS | G20: OLS | H20: OLS | I20: GVAR
A21: 2014 | B21: -3.0206547 | C21: 152714 | F21: 1995-2003 | G21: 2004-2016 | H21: 1995-2016 | I21: Steady State
A22: 2015 | B22: -8.2498527 | C22: -1625551 | E22: b0 | F22: -49502.849 | G22: 710485.91 | H22: 378563.52 | I22: 693936.15
A23: 2016 | B23: -6.5602349 | C23: -1371363 | E23: b1 | F23: 100568.76 | G23: 155768.56 | H23: 138989.41 | I23: 257535.08
E25: R-squared | F25: 0.273 | G25: 0.643 | H25: 0.455
E26: Adjusted R-Squared | F26: 0.17 | G26: 0.61 | H26: 0.427

Sheet Planilha2
A1: 1995 | B1: -200246 | C1: 836.27385
A2: 1996 | B2: -271226 | C2: 850.74587
A3: 1997 | B3: -35735 | C3: 883.8225
A4: 1998 | B4: -581745 | C4: 865.91198
A5: 1999 | B5: -222346 | C5: 860.2556
A6: 2000 | B6: 675194 | C6: 917.37781
A7: 2001 | B7: 586511 | C7: 931.84983
A8: 2002 | B8: 468672 | C8: 953.7
A9: 2003 | B9: 710054 | C9: 956.8
A10: 2004 | B10: 1523276 | C10: 1036.6
A11: 2005 | B11: 1253999 | C11: 1065.7
A12: 2006 | B12: 1228686 | C12: 1094.5
... A22: 2016 | B22: -1371363 | C22: 1018.4

Sheet Plan7
B1: 20 | C1: 21
A2: Ano | B2: Média Var Pim Ano | C2: Soma Emp Liq No Ano | D2: OLS | E2: OLS Restrict (GVAR)
A3: 1995 | B3: =VLOOKUP(A3,MAIN!$B$4:$W$507,$B$1,FALSE) -> 0.025854015 | C3: =VLOOKUP(A3,MAIN!$B$4:$W$507,$C$1,FALSE) -> -200246 | D3: =362014.066454871+13836575.3151153*B3 -> 719745.09 | E3: =$G$35+$H$35*B3 -> 1359767.7 | I3: 1 | J3: 1 | K3: 1 | L3: 1 | M3: 1 | N3: 1 | O3: 1
A4: 1996 | B4: =VLOOKUP(A4,MAIN!$B$4:$W$507,$B$1,FALSE) -> 0.018044522 | C4: =VLOOKUP(A4,MAIN!$B$4:$W$507,$C$1,FALSE) -> -271226 | D4: =362014.066454871+13836575.3151153*B4 -> 611688.45 | E4: =$G$35+$H$35*B4 -> 1158645.9 | P4: 1
A5: 1997 | B5: =VLOOKUP(A5,MAIN!$B$4:$W$507,$B$1,FALSE) -> 0.039574538 | C5: =VLOOKUP(A5,MAIN!$B$4:$W$507,$C$1,FALSE) -> -35735 | D5: =362014.066454871+13836575.3151153*B5 -> 909590.15 | E5: =$G$35+$H$35*B5 -> 1713119.3 | P5: 1
A6: 1998 | B6: =VLOOKUP(A6,MAIN!$B$4:$W$507,$B$1,FALSE) -> -0.019428259 | C6: =VLOOKUP(A6,MAIN!$B$4:$W$507,$C$1,FALSE) -> -581745 | D6: =362014.066454871+13836575.3151153*B6 -> 93193.503 | E6: =$G$35+$H$35*B6 -> 193590.33 | P6: 1
A7: 1999 | B7: =VLOOKUP(A7,MAIN!$B$4:$W$507,$B$1,FALSE) -> -0.0060710871 | C7: =VLOOKUP(A7,MAIN!$B$4:$W$507,$C$1,FALSE) -> -222346 | D7: =362014.066454871+13836575.3151153*B7 -> 278011.01 | E7: =$G$35+$H$35*B7 -> 537584.35 | P7: 1
A8: 2000 | B8: =VLOOKUP(A8,MAIN!$B$4:$W$507,$B$1,FALSE) -> 0.067490972 | C8: =VLOOKUP(A8,MAIN!$B$4:$W$507,$C$1,FALSE) -> 675194 | D8: =362014.066454871+13836575.3151153*B8 -> 1295858 | E8: =$G$35+$H$35*B8 -> 2432065.5 | P8: 1
A9: 2001 | B9: =VLOOKUP(A9,MAIN!$B$4:$W$507,$B$1,FALSE) -> 0.01806976 | C9: =VLOOKUP(A9,MAIN!$B$4:$W$507,$C$1,FALSE) -> 586511 | D9: =362014.066454871+13836575.3151153*B9 -> 612037.66 | E9: =$G$35+$H$35*B9 -> 1159295.9 | P9: 1
A10: 2002 | B10: =VLOOKUP(A10,MAIN!$B$4:$W$507,$B$1,FALSE) -> 0.023730584 | C10: =VLOOKUP(A10,MAIN!$B$4:$W$507,$C$1,FALSE) -> 468672 | D10: =362014.066454871+13836575.3151153*B10 -> 690364.08 | E10: =$G$35+$H$35*B10 -> 1305081.9 | P10: 1
A11: 2003 | B11: =VLOOKUP(A11,MAIN!$B$4:$W$507,$B$1,FALSE) -> 0.0038797689 | C11: =VLOOKUP(A11,MAIN!$B$4:$W$507,$C$1,FALSE) -> 710054 | D11: =362014.066454871+13836575.3151153*B11 -> 415696.78 | E11: =$G$35+$H$35*B11 -> 793853.81 | P11: 1
A12: 2004 | B12: =VLOOKUP(A12,MAIN!$B$4:$W$507,$B$1,FALSE) -> 0.083321798 | C12: =VLOOKUP(A12,MAIN!$B$4:$W$507,$C$1,FALSE) -> 1523276 | D12: =362014.066454871+13836575.3151153*B12 -> 1514902.4 | E12: =$G$35+$H$35*B12 -> 2839764.8 | P12: 1
A13: 2005 | B13: =VLOOKUP(A13,MAIN!$B$4:$W$507,$B$1,FALSE) -> 0.028984299 | C13: =VLOOKUP(A13,MAIN!$B$4:$W$507,$C$1,FALSE) -> 1253999 | D13: =362014.066454871+13836575.3151153*B13 -> 763057.5 | E13: =$G$35+$H$35*B13 -> 1440383.5 | P13: 1
A14: 2006 | B14: =VLOOKUP(A14,MAIN!$B$4:$W$507,$B$1,FALSE) -> 0.02716572 | C14: =VLOOKUP(A14,MAIN!$B$4:$W$507,$C$1,FALSE) -> 1228686 | D14: =362014.066454871+13836575.3151153*B14 -> 737894.59 | E14: =$G$35+$H$35*B14 -> 1393548.7 | P14: 1
A15: 2007 | B15: =VLOOKUP(A15,MAIN!$B$4:$W$507,$B$1,FALSE) -> 0.05850802 | C15: =VLOOKUP(A15,MAIN!$B$4:$W$507,$C$1,FALSE) -> 1617392 | D15: =362014.066454871+13836575.3151153*B15 -> 1171564.7 | E15: =$G$35+$H$35*B15 -> 2200722.9 | P15: 1
... A18: 2010 | B18: =VLOOKUP(A18,MAIN!$B$4:$W$507,$B$1,FALSE) -> 0.10648093 | C18: =VLOOKUP(A18,MAIN!$B$4:$W$507,$C$1,FALSE) -> 2136938 | D18: =362014.066454871+13836575.3151153*B18 -> 1835345.5 | E18: =$G$35+$H$35*B18 -> 3436193.7 | P18: 1
A19: 2011 | B19: =VLOOKUP(A19,MAIN!$B$4:$W$507,$B$1,FALSE) -> 0.0050171857 | C19: =VLOOKUP(A19,MAIN!$B$4:$W$507,$C$1,FALSE) -> 1566043 | D19: =362014.066454871+13836575.3151153*B19 -> 431434.73 | E19: =$G$35+$H$35*B19 -> 823146.28
A20: 2012 | B20: =VLOOKUP(A20,MAIN!$B$4:$W$507,$B$1,FALSE) -> -0.024010658 | C20: =VLOOKUP(A20,MAIN!$B$4:$W$507,$C$1,FALSE) -> 868241 | D20: =362014.066454871+13836575.3151153*B20 -> 29788.785 | E20: =$G$35+$H$35*B20 -> 75577.46
A21: 2013 | B21: =VLOOKUP(A21,MAIN!$B$4:$W$507,$B$1,FALSE) -> 0.021236432 | C21: =VLOOKUP(A21,MAIN!$B$4:$W$507,$C$1,FALSE) -> 730687 | D21: =362014.066454871+13836575.3151153*B21 -> 655853.56 | E21: =$G$35+$H$35*B21 -> 1240848.8
A22: 2014 | B22: =VLOOKUP(A22,MAIN!$B$4:$W$507,$B$1,FALSE) -> -0.028932097 | C22: =VLOOKUP(A22,MAIN!$B$4:$W$507,$C$1,FALSE) -> 152714 | D22: =362014.066454871+13836575.3151153*B22 -> -38307.068 | E22: =$G$35+$H$35*B22 -> -51166.844
A23: 2015 | B23: =VLOOKUP(A23,MAIN!$B$4:$W$507,$B$1,FALSE) -> -0.08201925 | C23: =VLOOKUP(A23,MAIN!$B$4:$W$507,$C$1,FALSE) -> -1625551 | D23: =362014.066454871+13836575.3151153*B23 -> -772851.47 | E23: =$G$35+$H$35*B23 -> -1418347.3
A24: 2016 | B24: =VLOOKUP(A24,MAIN!$B$4:$W$507,$B$1,FALSE) -> -0.064971812 | C24: =VLOOKUP(A24,MAIN!$B$4:$W$507,$C$1,FALSE) -> -1371363 | D24: =362014.066454871+13836575.3151153*B24 -> -536973.31 | E24: =$G$35+$H$35*B24 -> -979315.96
O25: 1 | P25: Ano
O26: 2 | P26: Mês
B27: 1995 to 2003 | C27: 2004 to 2016 | D27: 1995 to 2016 | E27: GVAR | O27: 3 | P27: Adm
A28: bo | B28: -28619.258 | C28: 677657.23 | D28: 355628.95 | E28: 693936.15 | O28: 4 | P28: Des
B29: 191366.78 | C29: 199046.68 | D29: 164013.32 | O29: 5 | P29: Adm
O30: 6 | P30: Des
A31: b1 | B31: 81570.96 | C31: 156257.64 | D31: 136916.94 | E31: 257535.08 | O31: 7 | P31: Adm
B32: 60182.067 | C32: 35229.182 | D32: 34199.142 | O32: 8 | P32: Des
O33: 9 | P33: PIM
A34: R-squared: | B34: 0.208 | C34: 0.641 | D34: 0.445 | O34: 10 | P34: Emp Liquido
G35: 693936.15 | H35: 25753508 | O35: 11 | P35: LN(PIM)
J36: 10838680835062 | L36: 1.9820124e+13 | M36: 8.9814428e+12 | O36: 12 | P36: DLN
J37: =SQRT(J36) -> 3292215.2 | L37: =J36/L36 -> 0.54685233 | M37: =M36/L36 -> 0.45314767 | O37: 13 | P37: Data Fim
O38: 14 | P38: Data Inicio
O39: 15 | P39: Data Inicio 2
O40: 16 | P40: Data Fim 2
G41: -0.14955187 | H41: 0.88533584 | O41: 17 | P41: PIM Final
G42: 1.3554031 | H42: 0.21739428 | O42: 18 | P42: Pim Inicial
...

Sheet Planilha1
K1: Ano | L1: Média Var Pim Ano | M1: Soma Emp Liq No Ano
A2: 1976 | B2: 0.11994057 | K2: 1976 | L2: 0.11994057
A3: 1977 | B3: 0.021080314 | K3: 1977 | L3: 0.021080314
A4: 1978 | B4: 0.061492149 | K4: 1978 | L4: 0.061492149
A5: 1979 | B5: 0.0700491 | K5: 1979 | L5: 0.0700491
A6: 1980 | B6: 0.092310143 | K6: 1980 | L6: 0.092310143
A7: 1981 | B7: -0.098712194 | K7: 1981 | L7: -0.098712194
A8: 1982 | B8: 0.00024584611 | K8: 1982 | L8: 0.00024584611
A9: 1983 | B9: -0.050398151 | K9: 1983 | L9: -0.050398151
A10: 1984 | B10: 0.070774781 | K10: 1984 | L10: 0.070774781
A11: 1985 | B11: 0.084242278 | K11: 1985 | L11: 0.084242278
A12: 1986 | B12: 0.11054657 | K12: 1986 | L12: 0.11054657
A13: 1987 | B13: 0.015387935 | K13: 1987 | L13: 0.015387935
... A20: 1994 | B20: 0.07591762 | K20: 1994 | L20: 0.07591762
A21: 1995 | B21: 0.025854015 | K21: 1995 | L21: 0.025854015 | M21: -200246
A22: 1996 | B22: 0.018044522 | K22: 1996 | L22: 0.018044522 | M22: -271226
A23: 1997 | B23: 0.039574538 | K23: 1997 | L23: 0.039574538 | M23: -35735
A24: 1998 | B24: -0.019428259 | K24: 1998 | L24: -0.019428259 | M24: -581745
A25: 1999 | B25: -0.0060710871 | K25: 1999 | L25: -0.0060710871 | M25: -222346
A26: 2000 | B26: 0.067490972 | K26: 2000 | L26: 0.067490972 | M26: 675194
A27: 2001 | B27: 0.01806976 | K27: 2001 | L27: 0.01806976 | M27: 586511
A28: 2002 | B28: 0.023730584 | K28: 2002 | L28: 0.023730584 | M28: 468672
A29: 2003 | B29: 0.0038797689 | K29: 2003 | L29: 0.0038797689 | M29: 710054
A30: 2004 | B30: 0.083321798 | K30: 2004 | L30: 0.083321798 | M30: 1523276
A31: 2005 | B31: 0.028984299 | K31: 2005 | L31: 0.028984299 | M31: 1253999
A32: 2006 | B32: 0.02716572 | K32: 2006 | L32: 0.02716572 | M32: 1228686
... A42: 2016 | B42: -0.064971812 | K42: 2016 | L42: -0.064971812 | M42: -1371363

Sheet PIM
A1: Data | B1: DataPIM_BR | C1: DataPIM_US
A2: 27395 | B2: 40.694754 | C2: 42.2035 | D2: =LN(B2) -> 3.7060992 | E2: =LN(C2) -> 3.7425032 | F2: =D2-D1 -> 3.7060992 | G2: =E2-E1 -> 3.7425032
A3: 27426 | B3: 38.18129 | C3: 42.02 | D3: =LN(B3) -> 3.6423456 | E3: =LN(C3) -> 3.7381457 | F3: =D3-D2 -> -0.063753568 | G3: =E3-E2 -> -0.0043574606
A4: 27454 | B4: 41.35231 | C4: 41.6022 | D4: =LN(B4) -> 3.7221283 | E4: =LN(C4) -> 3.7281531 | F4: =D4-D3 -> 0.079782673 | G4: =E4-E3 -> -0.0099926449
A5: 27485 | B5: 43.570795 | C5: 41.7066 | D5: =LN(B5) -> 3.7743871 | E5: =LN(C5) -> 3.7306594 | F5: =D5-D4 -> 0.052258796 | G5: =E5-E4 -> 0.0025063392
A6: 27515 | B6: 43.724429 | C6: 41.4999 | D6: =LN(B6) -> 3.777907 | E6: =LN(C6) -> 3.725691 | F6: =D6-D5 -> 0.003519891 | G6: =E6-E5 -> -0.0049683721
A7: 27546 | B7: 45.174741 | C7: 42.7036 | D7: =LN(B7) -> 3.8105381 | E7: =LN(C7) -> 3.7542832 | F7: =D7-D6 -> 0.032631127 | G7: =E7-E6 -> 0.028592208
A8: 27576 | B8: 46.877013 | C8: 40.9055 | D8: =LN(B8) -> 3.8475274 | E8: =LN(C8) -> 3.7112645 | F8: =D8-D7 -> 0.036989329 | G8: =E8-E7 -> -0.043018697
A9: 27607 | B9: 46.022804 | C9: 42.5577 | D9: =LN(B9) -> 3.829137 | E9: =LN(C9) -> 3.7508608 | F9: =D9-D8 -> -0.01839041 | G9: =E9-E8 -> 0.039596274
A10: 27638 | B10: 47.178137 | C10: 43.9232 | D10: =LN(B10) -> 3.8539306 | E10: =LN(C10) -> 3.7824427 | F10: =D10-D9 -> 0.024793569 | G10: =E10-E9 -> 0.031581852
A11: 27668 | B11: 48.81281 | C11: 44.1579 | D11: =LN(B11) -> 3.8879928 | E11: =LN(C11) -> 3.7877718 | F11: =D11-D10 -> 0.034062192 | G11: =E11-E10 -> 0.0053291922
A12: 27699 | B12: 45.752407 | C12: 43.6988 | D12: =LN(B12) -> 3.8232444 | E12: =LN(C12) -> 3.7773206 | F12: =D12-D11 -> -0.064748372 | G12: =E12-E11 -> -0.010451205
A13: 27729 | B13: 44.394277 | C13: 43.4423 | D13: =LN(B13) -> 3.7931106 | E13: =LN(C13) -> 3.7714336 | F13: =D13-D12 -> -0.03013385 | G13: =E13-E12 -> -0.005887021
... A349: 37956 | B349: 77.9 | C349: 94.6425 | D349: =LN(B349) -> 4.355426 | E349: =LN(C349) -> 4.5501066 | F349: =D349-D348 -> -0.082508314 | G349: =E349-E348 -> -0.0055549786
A350: 37987 | B350: 76.8 | C350: 94.4102 | D350: =LN(B350) -> 4.3412046 | E350: =LN(C350) -> 4.5476491 | F350: =D350-D349 -> -0.014221313 | G350: =E350-E349 -> -0.0024575171 | H350: <<<< | I350: INICIO | J350: <<<< | K350: INICIO | L350: <<<< | M350: INICIO | N350: <<<< | O350: INICIO | P350: <<<< | Q350: INICIO
A351: 38018 | B351: 74 | C351: 96.2589 | D351: =LN(B351) -> 4.3040651 | E351: =LN(C351) -> 4.5670414 | F351: =D351-D350 -> -0.037139547 | G351: =E351-E350 -> 0.019392318
A352: 38047 | B352: 86.9 | C352: 96.6183 | D352: =LN(B352) -> 4.464758 | E352: =LN(C352) -> 4.5707682 | F352: =D352-D351 -> 0.16069294 | G352: =E352-E351 -> 0.0037267278
A353: 38078 | B353: 82.2 | C353: 94.8371 | D353: =LN(B353) -> 4.4091553 | E353: =LN(C353) -> 4.5521607 | F353: =D353-D352 -> -0.05560273 | G353: =E353-E352 -> -0.018607481
A354: 38108 | B354: 86.3 | C354: 96.3792 | D354: =LN(B354) -> 4.4578296 | E354: =LN(C354) -> 4.5682904 | F354: =D354-D353 -> 0.048674296 | G354: =E354-E353 -> 0.016129728
A355: 38139 | B355: 86.1 | C355: 98.5806 | D355: =LN(B355) -> 4.4555094 | E355: =LN(C355) -> 4.5908745 | F355: =D355-D354 -> -0.0023201867 | G355: =E355-E354 -> 0.022584077
A356: 38169 | B356: 90.1 | C356: 95.4028 | D356: =LN(B356) -> 4.5009202 | E356: =LN(C356) -> 4.5581079 | F356: =D356-D355 -> 0.045410753 | G356: =E356-E355 -> -0.03276656
A357: 38200 | B357: 92.1 | C357: 98.9902 | D357: =LN(B357) -> 4.5228749 | E357: =LN(C357) -> 4.5950209 | F357: =D357-D356 -> 0.021954779 | G357: =E357-E356 -> 0.036912927
A358: 38231 | B358: 92.1 | C358: 98.3802 | D358: =LN(B358) -> 4.5228749 | E358: =LN(C358) -> 4.5888396 | F358: =D358-D357 -> 0 | G358: =E358-E357 -> -0.006181291
A359: 38261 | B359: 93.5 | C359: 98.573 | D359: =LN(B359) -> 4.5379614 | E359: =LN(C359) -> 4.5907974 | F359: =D359-D358 -> 0.015086493 | G359: =E359-E358 -> 0.0019578261
A360: 38292 | B360: 91.8 | C360: 97.6279 | D360: =LN(B360) -> 4.5196123 | E360: =LN(C360) -> 4.5811633 | F360: =D360-D359 -> -0.018349139 | G360: =E360-E359 -> -0.0096340772
A361: 38322 | B361: 84.7 | C361: 98.0015 | D361: =LN(B361) -> 4.4391156 | E361: =LN(C361) -> 4.5849828 | F361: =D361-D360 -> -0.080496696 | G361: =E361-E360 -> 0.0038194715
A362: 38353 | B362: 81 | C362: 98.2289 | D362: =LN(B362) -> 4.3944492 | E362: =LN(C362) -> 4.5873005 | F362: =D362-D361 -> -0.044666447 | G362: =E362-E361 -> 0.0023176847
... A471: 41671 | B471: 92.3 | C471: 102.7889 | D471: =LN(B471) -> 4.5250441 | E471: =LN(C471) -> 4.6326774 | F471: =D471-D470 -> -0.0032450001 | G471: =E471-E470 -> 0.006055917
A472: =EOMONTH(A471,0)+1 -> 41699 | B472: 97.3 | C472: 104.2804 | D472: =LN(B472) -> 4.577799 | E472: =LN(C472) -> 4.6470834 | F472: =D472-D471 -> 0.052754848 | G472: =E472-E471 -> 0.014406054
A473: =EOMONTH(A472,0)+1 -> 41730 | B473: 96 | C473: 102.9064 | D473: =LN(B473) -> 4.5643482 | E473: =LN(C473) -> 4.6338198 | F473: =D473-D472 -> -0.013450798 | G473: =E473-E472 -> -0.013263588
A474: =EOMONTH(A473,0)+1 -> 41760 | B474: 101.7 | C474: 103.7271 | D474: =LN(B474) -> 4.6220273 | E474: =LN(C474) -> 4.6417634 | F474: =D474-D473 -> 0.057679112 | G474: =E474-E473 -> 0.0079435746
A475: =EOMONTH(A474,0)+1 -> 41791 | B475: 94.9 | C475: 106.8076 | D475: =LN(B475) -> 4.5528237 | E475: =LN(C475) -> 4.6710291 | F475: =D475-D474 -> -0.069203597 | G475: =E475-E474 -> 0.029265673
A476: =EOMONTH(A475,0)+1 -> 41821 | B476: 104.4 | C476: 104.8018 | D476: =LN(B476) -> 4.6482297 | E476: =LN(C476) -> 4.6520709 | F476: =D476-D475 -> 0.09540597 | G476: =E476-E475 -> -0.018958138
A477: =EOMONTH(A476,0)+1 -> 41852 | B477: 106.3 | C477: 107.4252 | D477: =LN(B477) -> 4.6662653 | E477: =LN(C477) -> 4.6767948 | F477: =D477-D476 -> 0.01803561 | G477: =E477-E476 -> 0.024723844
A478: =EOMONTH(A477,0)+1 -> 41883 | B478: 105.6 | C478: 106.6147 | D478: =LN(B478) -> 4.6596584 | E478: =LN(C478) -> 4.6692214 | F478: =D478-D477 -> -0.0066069141 | G478: =E478-E477 -> -0.0075733905
A479: =EOMONTH(A478,0)+1 -> 41913 | B479: 109.3 | C479: 105.4789 | D479: =LN(B479) -> 4.6940964 | E479: =LN(C479) -> 4.6585109 | F479: =D479-D478 -> 0.034438024 | G479: =E479-E478 -> -0.010710468
A480: =EOMONTH(A479,0)+1 -> 41944 | B480: 99.8 | C480: 105.915 | D480: =LN(B480) -> 4.6031682 | E480: =LN(C480) -> 4.6626369 | F480: =D480-D479 -> -0.090928212 | G480: =E480-E479 -> 0.0041259527
A481: =EOMONTH(A480,0)+1 -> 41974 | B481: 87.7 | C481: 105.777 | D481: =LN(B481) -> 4.4739219 | E481: =LN(C481) -> 4.6613331 | F481: =D481-D480 -> -0.12924628 | G481: =E481-E480 -> -0.0013037811
A482: =EOMONTH(A481,0)+1 -> 42005 | B482: 88.1 | C482: 105.3085 | D482: =LN(B482) -> 4.4784725 | E482: =LN(C482) -> 4.6568941 | F482: =D482-D481 -> 0.0045506336 | G482: =E482-E481 -> -0.0044389669
A483: =EOMONTH(A482,0)+1 -> 42036 | B483: 83.7 | C483: 105.3511 | D483: =LN(B483) -> 4.427239 | E483: =LN(C483) -> 4.6572986 | F483: =D483-D482 -> -0.051233555 | G483: =E483-E482 -> 0.00040444395
...

Sheet DesSéries
A1: Sigla | B1: Codigo | C1: Brasil | D1: 1999.05 | E1: 1999.06 | F1: 1999.07 | G1: 1999.08 | H1: 1999.09 | I1: 1999.10 | J1: 1999.11 | K1: 1999.12 | L1: 2000.01 | M1: 2000.02 | N1: 2000.03 | O1: 2000.04 | P1: 2000.05 | Q1: 2000.06 | R1: 2000.07 | S1: 2000.08 | T1: 2000.09 | U1: 2000.10 | V1: 2000.11 | W1: 2000.12 | X1: 2001.01 | Y1: 2001.02 | Z1: 2001.03 | AA1: 2001.04 | AB1: 2001.05 | AC1: 2001.06 | AD1: 2001.07 | AE1: 2001.08 | AF1: 2001.09 | AG1: 2001.10 | AH1: 2001.11 | AI1: 2001.12 | AJ1: 2002.01 | AK1: 2002.02 | AL1: 2002.03 | AM1: 2002.04 | AN1: 2002.05 | AO1: 2002.06 | AP1: 2002.07 | AQ1: 2002.08 | AR1: 2002.09 | AS1: 2002.10 | AT1: 2002.11 | AU1: 2002.12 | AV1: 2003.02 | AW1: 2003.03 | AX1: 2003.04 | AY1: 2003.05 | AZ1: 2003.06 | BA1: 2003.07 | BB1: 2003.08 | BC1: 2003.09 | BD1: 2003.10 | BE1: 2003.11 | BF1: 2003.12 | BG1: 2004.01 | BH1: 2004.02 | BI1: 2004.03 | BJ1: 2004.04 | BK1: 2004.05 | BL1: 2004.06 | BM1: 2004.07 | BN1: 2004.08 | BO1: 2004.09 | BP1: 2004.10 | BQ1: 2004.11 | BR1: 2004.12 | BS1: 2005.01 | BT1: 2005.02 | BU1: 2005.03 | BV1: 2005.04 | BW1: 2005.05 | BX1: 2005.06 | BY1: 2005.07 | BZ1: 2005.08 | CA1: 2005.09 | CB1: 2005.10 | CC1: 2005.11 | CD1: 2005.12 | CE1: 2006.01 | CF1: 2006.02 | CG1: 2006.03 | CH1: 2006.04 | CI1: 2006.05 | CJ1: 2006.06 | CK1: 2006.07 | CL1: 2006.08 | CM1: 2006.09 | CN1: 2006.10 | CO1: 2006.11 | CP1: 2006.12 | CQ1: 2007.01 | CR1: 2007.02 | CS1: 2007.03 | CT1: 2007.04 | CU1: 2007.05 | CV1: 2007.06 | CW1: 2007.07 | CX1: 2007.08 | CY1: 2007.09
A2: BR | B2: 0 | C2: Brasil | D2: 635522 | E2: 673129 | F2: 677848 | G2: 676838 | H2: 691425 | I2: 670349 | J2: 703072 | K2: 790647 | L2: 726009 | M2: 716751 | N2: 759494 | O2: 658984 | P2: 760844 | Q2: 718376 | R2: 733354 | S2: 788007 | T2: 722541 | U2: 809479 | V2: 759879 | W2: 856818 | X2: 861188 | Y2: 771367 | Z2: 889041 | AA2: 740237 | AB2: 841129 | AC2: 781159 | AD2: 812844 | AE2: 843325 | AF2: 781155 | AG2: 775040 | AH2: 816160 | AI2: 847919 | AJ2: 732284 | AK2: 664420 | AL2: 783319 | AM2: 770784 | AN2: 771118 | AO2: 642005 | AP2: 770352 | AQ2: 784912 | AR2: 706750 | AS2: 816712 | AT2: 786836 | AU2: 820473 | AV2: 757096 | AW2: 752398 | AX2: 715429 | AY2: 763755 | AZ2: 699084 | BA2: 775150 | BB2: 759702 | BC2: 738317 | BD2: 780861 | BE2: 753845 | BF2: 881481 | BG2: 750092 | BH2: 732972 | BI2: 889880 | BJ2: 773928 | BK2: 739405 | BL2: 778599 | BM2: 780595 | BN2: 818840 | BO2: 787989 | BP2: 790904 | BQ2: 852104 | BR2: 1077912 | BS2: 864648 | BT2: 898017 | BU2: 979505 | BV2: 843935 | BW2: 888802 | BX2: 894412 | BY2: 887229 | BZ2: 936338 | CA2: 869505 | CB2: 853551 | CC2: 953934 | CD2: 1055144 | CE2: 962829 | CF2: 886348 | CG2: 1053182 | CH2: 846299 | CI2: 966940 | CJ2: 924957 | CK2: 925389 | CL2: 1017807 | CM2: 915926 | CN2: 950597 | CO2: 1015408 | CP2: 1136781 | CQ2: 1038575 | CR2: 989718 | CS2: 1109489 | CT2: 970960 | CU2: 1081280 | CV2: 1015942 | CW2: 1063543 | CX2: 1120194 | CY2: 973119

Sheet AdmSéries
A1: Sigla | B1: Codigo | C1: Brasil | D1: 1999.05 | E1: 1999.06 | F1: 1999.07 | G1: 1999.08 | H1: 1999.09 | I1: 1999.10 | J1: 1999.11 | K1: 1999.12 | L1: 2000.01 | M1: 2000.02 | N1: 2000.03 | O1: 2000.04 | P1: 2000.05 | Q1: 2000.06 | R1: 2000.07 | S1: 2000.08 | T1: 2000.09 | U1: 2000.10 | V1: 2000.11 | W1: 2000.12 | X1: 2001.01 | Y1: 2001.02 | Z1: 2001.03 | AA1: 2001.04 | AB1: 2001.05 | AC1: 2001.06 | AD1: 2001.07 | AE1: 2001.08 | AF1: 2001.09 | AG1: 2001.10 | AH1: 2001.11 | AI1: 2001.12 | AJ1: 2002.01 | AK1: 2002.02 | AL1: 2002.03 | AM1: 2002.04 | AN1: 2002.05 | AO1: 2002.06 | AP1: 2002.07 | AQ1: 2002.08 | AR1: 2002.09 | AS1: 2002.10 | AT1: 2002.11 | AU1: 2002.12 | AV1: 2003.02 | AW1: 2003.03 | AX1: 2003.04 | AY1: 2003.05 | AZ1: 2003.06 | BA1: 2003.07 | BB1: 2003.08 | BC1: 2003.09 | BD1: 2003.10 | BE1: 2003.11 | BF1: 2003.12 | BG1: 2004.01 | BH1: 2004.02 | BI1: 2004.03 | BJ1: 2004.04 | BK1: 2004.05 | BL1: 2004.06 | BM1: 2004.07 | BN1: 2004.08 | BO1: 2004.09 | BP1: 2004.10 | BQ1: 2004.11 | BR1: 2004.12 | BS1: 2005.01 | BT1: 2005.02 | BU1: 2005.03 | BV1: 2005.04 | BW1: 2005.05 | BX1: 2005.06 | BY1: 2005.07 | BZ1: 2005.08 | CA1: 2005.09 | CB1: 2005.10 | CC1: 2005.11 | CD1: 2005.12 | CE1: 2006.01 | CF1: 2006.02 | CG1: 2006.03 | CH1: 2006.04 | CI1: 2006.05 | CJ1: 2006.06 | CK1: 2006.07 | CL1: 2006.08 | CM1: 2006.09 | CN1: 2006.10 | CO1: 2006.11 | CP1: 2006.12 | CQ1: 2007.01 | CR1: 2007.02 | CS1: 2007.03 | CT1: 2007.04 | CU1: 2007.05 | CV1: 2007.06 | CW1: 2007.07 | CX1: 2007.08 | CY1: 2007.09
A2: BR | B2: 0 | C2: Brasil | D2: 732704 | E2: 731238 | F2: 685905 | G2: 690144 | H2: 698632 | I2: 687788 | J2: 686902 | K2: 547526 | L2: 757207 | M2: 804926 | N2: 799441 | O2: 784055 | P2: 923681 | Q2: 861260 | R2: 839196 | S2: 866852 | T2: 815219 | U2: 824921 | V2: 760345 | W2: 631029 | X2: 909984 | Y2: 851610 | Z2: 923525 | AA2: 880234 | AB2: 1003027 | AC2: 889730 | AD2: 884230 | AE2: 890652 | AF2: 861183 | AG2: 852227 | AH2: 811245 | AI2: 593996 | AJ2: 776512 | AK2: 746433 | AL2: 873579 | AM2: 945874 | AN2: 926931 | AO2: 775351 | AP2: 831579 | AQ2: 862934 | AR2: 874062 | AS2: 853080 | AT2: 775085 | AU2: 570959 | AV2: 841125 | AW2: 773659 | AX2: 869453 | AY2: 904068 | AZ2: 824879 | BA2: 812383 | BB2: 839474 | BC2: 900082 | BD2: 851731 | BE2: 788649 | BF2: 581563 | BG2: 850198 | BH2: 872046 | BI2: 998092 | BJ2: 961475 | BK2: 1031227 | BL2: 986494 | BM2: 982628 | BN2: 1048597 | BO2: 987731 | BP2: 921063 | BQ2: 931126 | BR2: 725819 | BS2: 980620 | BT2: 971302 | BU2: 1082470 | BV2: 1110030 | BW2: 1101252 | BX2: 1089948 | BY2: 1004702 | BZ2: 1071798 | CA2: 1058963 | CB2: 971726 | CC2: 967765 | CD2: 768425 | CE2: 1049445 | CF2: 1062980 | CG2: 1129637 | CH2: 1076102 | CI2: 1165777 | CJ2: 1080412 | CK2: 1079746 | CL2: 1146722 | CM2: 1092661 | CN2: 1080392 | CO2: 1047987 | CP2: 819288 | CQ2: 1144043 | CR2: 1137737 | CS2: 1255630 | CT2: 1272951 | CU2: 1293497 | CV2: 1197609 | CW2: 1190535 | CX2: 1253523 | CY2: 1224287

Sheet desl
A1: date | B1: Ro1101 | C1: Ro1102 | D1: Ac1201 | E1: Ac1202 | F1: Am1301 | G1: Am1302 | H1: Am1303 | I1: Am1304 | J1: Rr1401 | K1: Rr1402 | L1: Pa1501 | M1: Pa1502 | N1: Pa1503 | O1: Pa1504 | P1: Pa1505 | Q1: Pa1506 | R1: Ap1601 | S1: Ap1602 | T1: To1701 | U1: To1702 | V1: Ma2101 | W1: Ma2102 | X1: Ma2103 | Y1: Ma2104 | Z1: Ma2105 | AA1: Pi2201 | AB1: Pi2202 | AC1: Pi2203 | AD1: Pi2204 | AE1: Ce2301 | AF1: Ce2302 | AG1: Ce2303 | AH1: Ce2304 | AI1: Ce2305 | AJ1: Ce2306 | AK1: Ce2307 | AL1: Rn2401 | AM1: Rn2402 | AN1: Rn2403 | AO1: Rn2404 | AP1: Pb2501 | AQ1: Pb2502 | AR1: Pb2503 | AS1: Pb2504 | AT1: Pe2601 | AU1: Pe2602 | AV1: Pe2603 | AW1: Pe2604 | AX1: Pe2605 | AY1: Al2701 | AZ1: Al2702 | BA1: Al2703 | BB1: Se2801 | BC1: Se2802 | BD1: Se2803 | BE1: Ba2901 | BF1: Ba2902 | BG1: Ba2903 | BH1: Ba2904 | BI1: Ba2905 | BJ1: Ba2906 | BK1: Ba2907 | BL1: Mg3101 | BM1: Mg3102 | BN1: Mg3103 | BO1: Mg3104 | BP1: Mg3105 | BQ1: Mg3106 | BR1: Mg3107 | BS1: Mg3108 | BT1: Mg3109 | BU1: Mg3110 | BV1: Mg3111 | BW1: Mg3112 | BX1: Es3201 | BY1: Es3202 | BZ1: Es3203 | CA1: Es3204 | CB1: Rj3301 | CC1: Rj3302 | CD1: Rj3303 | CE1: Rj3304 | CF1: Rj3305 | CG1: Rj3306 | CH1: Sp3501 | CI1: Sp3502 | CJ1: Sp3503 | CK1: Sp3504 | CL1: Sp3505 | CM1: Sp3506 | CN1: Sp3507 | CO1: Sp3508 | CP1: Sp3509 | CQ1: Sp3510 | CR1: Sp3511 | CS1: Sp3512 | CT1: Sp3513 | CU1: Sp3514 | CV1: Sp3515 | CW1: Pr4101 | CX1: Pr4102 | CY1: Pr4103 | CZ1: Pr4104 | DA1: Pr4105 | DB1: Pr4106 | DC1: Pr4107 | DD1: Pr4108 | DE1: Pr4109 | DF1: Pr4110 | DG1: Sc4201 | DH1: Sc4202 | DI1: Sc4203 | DJ1: Sc4204 | DK1: Sc4205 | DL1: Sc4206 | DM1: Rs4301 | DN1: Rs4302 | DO1: Rs4303 | DP1: Rs4304 | DQ1: Rs4305 | DR1: Rs4306 | DS1: Rs4307 | DT1: Ms5001 | DU1: Ms5002 | DV1: Ms5003 | DW1: Ms5004 | DX1: Mt5101 | DY1: Mt5102 | DZ1: Mt5103 | EA1: Mt5104 | EB1: Mt5105 | EC1: Go5201 | ED1: Go5202 | EE1: Go5203 | EF1: Go5204 | EG1: Go5205 | EH1: Go5301
A2: 2004M01 | B2: 1552 | C2: 2940 | D2: 61 | E2: 841 | F2: 10 | G2: 17 | H2: 7635 | I2: 33 | J2: 540 | K2: 7 | L2: 841 | M2: 160 | N2: 7014 | O2: 804 | P2: 548 | Q2: 3984 | R2: 6 | S2: 825 | T2: 1520 | U2: 1134 | V2: 2352 | W2: 1486 | X2: 186 | Y2: 292 | Z2: 356 | AA2: 343 | AB2: 2788 | AC2: 210 | AD2: 163 | AE2: 807 | AF2: 1295 | AG2: 14684 | AH2: 190 | AI2: 1758 | AJ2: 151 | AK2: 993 | AL2: 2532 | AM2: 300 | AN2: 179 | AO2: 7500 | AP2: 293 | AQ2: 66 | AR2: 1134 | AS2: 6227 | AT2: 469 | AU2: 1179 | AV2: 1729 | AW2: 5233 | AX2: 14565 | AY2: 44 | AZ2: 351 | BA2: 5241 | BB2: 32 | BC2: 227 | BD2: 3644 | BE2: 1094 | BF2: 1258 | BG2: 2245 | BH2: 899 | BI2: 15426 | BJ2: 1777 | BK2: 3656 | BL2: 2579 | BM2: 3053 | BN2: 762 | BO2: 583 | BP2: 12692 | BQ2: 1583 | BR2: 36046 | BS2: 6549 | BT2: 4237 | BU2: 10184 | BV2: 1646 | BW2: 6876 | BX2: 1199 | BY2: 3453 | BZ2: 9945 | CA2: 1204 | CB2: 559 | CC2: 4724 | CD2: 2135 | CE2: 1766 | CF2: 3902 | CG2: 59154 | CH2: 9486 | CI2: 17020 | CJ2: 3280 | CK2: 9739 | CL2: 8435 | CM2: 8969 | CN2: 22174 | CO2: 3087 | CP2: 1788 | CQ2: 2168 | CR2: 4953 | CS2: 13083 | CT2: 9902 | CU2: 893 | CV2: 107413 | CW2: 2642 | CX2: 961 | CY2: 11307 | CZ2: 4606 | DA2: 3558 | DB2: 5857 | DC2: 1916 | DD2: 2209 | DE2: 1393 | DF2: 22029 | DG2: 7430 | DH2: 7012 | DI2: 2835 | DJ2: 11362 | DK2: 7406 | DL2: 5441 | DM2: 6600 | DN2: 8247 | DO2: 1601 | DP2: 4364 | DQ2: 30935 | DR2: 1903 | DS2: 5073 | DT2: 494 | DU2: 5059 | DV2: 2005 | DW2: 2746 | DX2: 4388 | DY2: 1031 | DZ2: 1340 | EA2: 5220 | EB2: 2651 | EC2: 456 | ED2: 429 | EE2: 14943 | EF2: 1544 | EG2: 5639 | EH2: 12413 | EJ2: =SUM(B2:EH2) -> 750092
