Workbook

Sheet RJ_3306
C2: 2017M1 | D2: 2017M2 | E2: 2017M3 | F2: 2017M4 | G2: 2017M5 | H2: 2017M6 | I2: 2017M7 | J2: 2017M8 | K2: 2017M9 | L2: 2017M10 | M2: 2017M11 | N2: 2017M12 | O2: 2018M1 | P2: 2018M2 | Q2: 2018M3 | R2: 2018M4 | S2: 2018M5 | T2: 2018M6 | U2: 2018M7 | V2: 2018M8 | W2: 2018M9 | X2: 2018M10 | Y2: 2018M11 | Z2: 2018M12 | AA2: 2019M1 | AB2: 2019M2 | AC2: 2019M3 | AD2: 2019M4 | AE2: 2019M5 | AF2: 2019M6 | AG2: 2019M7 | AH2: 2019M8 | AI2: 2019M9 | AJ2: 2019M10 | AK2: 2019M11 | AL2: 2019M12 | AM2: 2020M1 | AN2: 2020M2 | AO2: 2020M3 | AP2: 2020M4 | AQ2: 2020M5 | AR2: 2020M6 | AS2: 2020M7 | AT2: 2020M8 | AU2: 2020M9 | AV2: 2020M10 | AW2: 2020M11 | AX2: 2020M12 | AY2: 2021M1 | AZ2: 2021M2 | BA2: 2021M3 | BB2: 2021M4 | BC2: 2021M5 | BD2: 2021M6 | BE2: 2021M7 | BF2: 2021M8 | BG2: 2021M9 | BH2: 2021M10 | BI2: 2021M11 | BJ2: 2021M12 | BK2: 2022M1 | BL2: 2022M2 | BM2: 2022M3 | BN2: 2022M4 | BO2: 2022M5 | BP2: 2022M6 | BQ2: 2022M7 | BR2: 2022M8 | BS2: 2022M9 | BT2: 2022M10 | BU2: 2022M11 | BV2: 2022M12 | BW2: 2023M1 | BX2: 2023M2 | BY2: 2023M3 | BZ2: 2023M4 | CA2: 2023M5 | CB2: 2023M6 | CC2: 2023M7 | CD2: 2023M8 | CE2: 2023M9 | CF2: 2023M10 | CG2: 2023M11 | CH2: 2023M12 | CI2: 2024M1 | CJ2: 2024M2 | CK2: 2024M3 | CL2: 2024M4 | CM2: 2024M5 | CN2: 2024M6 | CO2: 2024M7 | CP2: 2024M8 | CQ2: 2024M9 | CR2: 2024M10 | CS2: 2024M11 | CT2: 2024M12
C3: =DATE(LEFT(C2,4),SUBSTITUTE(RIGHT(C2,2),"M",""),1) -> 42736 | D3: =DATE(LEFT(D2,4),SUBSTITUTE(RIGHT(D2,2),"M",""),1) -> 42767 | E3: =DATE(LEFT(E2,4),SUBSTITUTE(RIGHT(E2,2),"M",""),1) -> 42795 | F3: =DATE(LEFT(F2,4),SUBSTITUTE(RIGHT(F2,2),"M",""),1) -> 42826 | G3: =DATE(LEFT(G2,4),SUBSTITUTE(RIGHT(G2,2),"M",""),1) -> 42856 | H3: =DATE(LEFT(H2,4),SUBSTITUTE(RIGHT(H2,2),"M",""),1) -> 42887 | I3: =DATE(LEFT(I2,4),SUBSTITUTE(RIGHT(I2,2),"M",""),1) -> 42917 | J3: =DATE(LEFT(J2,4),SUBSTITUTE(RIGHT(J2,2),"M",""),1) -> 42948 | ... CT3: =DATE(LEFT(CT2,4),SUBSTITUTE(RIGHT(CT2,2),"M",""),1) -> 45627
B5: 0% growth | C5: ='conditional forecasts_0'!D591 -> -28964.121 | D5: ='conditional forecasts_0'!E591 -> -17218.768 | E5: ='conditional forecasts_0'!F591 -> -14539.542 | F5: ='conditional forecasts_0'!G591 -> -5520.558 | G5: ='conditional forecasts_0'!H591 -> -7614.1227 | H5: ='conditional forecasts_0'!I591 -> -1079.528 | I5: ='conditional forecasts_0'!J591 -> -289.22663 | J5: ='conditional forecasts_0'!K591 -> -4773.4029 | ... CT5: ='conditional forecasts_0'!CU591 -> -5106.4353
B6: 2% growth | C6: ='conditional forecasts_2'!D591 -> -28249.488 | D6: ='conditional forecasts_2'!E591 -> -15337.868 | E6: ='conditional forecasts_2'!F591 -> -13225.654 | F6: ='conditional forecasts_2'!G591 -> -4098.8341 | G6: ='conditional forecasts_2'!H591 -> -6212.7682 | H6: ='conditional forecasts_2'!I591 -> 294.38478 | I6: ='conditional forecasts_2'!J591 -> 1051.7298 | J6: ='conditional forecasts_2'!K591 -> -3611.057 | ... CT6: ='conditional forecasts_2'!CU591 -> -381.21872
B7: 4% growth | C7: ='conditional forecasts_4'!D591 -> -27548.732 | D7: ='conditional forecasts_4'!E591 -> -13493.493 | E7: ='conditional forecasts_4'!F591 -> -11937.281 | F7: ='conditional forecasts_4'!G591 -> -2704.7183 | G7: ='conditional forecasts_4'!H591 -> -4838.6262 | H7: ='conditional forecasts_4'!I591 -> 1641.6179 | I7: ='conditional forecasts_4'!J591 -> 2366.6465 | J7: ='conditional forecasts_4'!K591 -> -2471.2823 | ... CT7: ='conditional forecasts_4'!CU591 -> 4252.2403
B8: 6% growth | C8: ='conditional forecasts_6'!D591 -> -26861.325 | D8: ='conditional forecasts_6'!E591 -> -11684.251 | E8: ='conditional forecasts_6'!F591 -> -10673.45 | F8: ='conditional forecasts_6'!G591 -> -1337.1586 | G8: ='conditional forecasts_6'!H591 -> -3490.6599 | H8: ='conditional forecasts_6'!I591 -> 2963.1879 | I8: ='conditional forecasts_6'!J591 -> 3656.5157 | J8: ='conditional forecasts_6'!K591 -> -1353.219 | ... CT8: ='conditional forecasts_6'!CU591 -> 8797.4375
B9: 8% growth | C9: ='conditional forecasts_8'!D591 -> -26186.767 | D9: ='conditional forecasts_8'!E591 -> -9908.8285 | E9: ='conditional forecasts_8'!F591 -> -9433.2426 | F9: ='conditional forecasts_8'!G591 -> 4.8376235 | G9: ='conditional forecasts_8'!H591 -> -2167.8908 | H9: ='conditional forecasts_8'!I591 -> 4260.0542 | I9: ='conditional forecasts_8'!J591 -> 4922.2738 | J9: ='conditional forecasts_8'!K591 -> -256.05529 | ... CT9: ='conditional forecasts_8'!CU591 -> 13257.673
B10: Actual | C10: -22707 | D10: -7789 | E10: -14259 | F10: -3732 | G10: -6477 | H10: -6819 | I10: -4286 | J10: -3666 | K10: -2963 | L10: -1959 | M10: 2426 | N10: -13622 | O10: -9621 | P10: -3114 | Q10: 65 | R10: 6092 | S10: -2888 | T10: -4843 | U10: -2013 | V10: 2279 | W10: 6550 | X10: -944 | Y10: 13308 | Z10: -12649 | AA10: -12021 | AB10: 5777 | AC10: -6941 | AD10: 2553 | AE10: -5702 | AF10: 324 | AG10: -5537 | AH10: 9207 | AI10: 11960 | AJ10: -9481 | AK10: 14836 | AL10: -10301
B12: =B5 -> 0% growth | C12: =C5 -> -28964.121 | D12: =D5+C12 -> -46182.889 | E12: =E5+D12 -> -60722.431 | F12: =F5+E12 -> -66242.989 | G12: =G5+F12 -> -73857.112 | H12: =H5+G12 -> -74936.64 | I12: =I5+H12 -> -75225.866 | J12: =J5+I12 -> -79999.269 | K12: =K5+J12 -> -81546.507 | ... CT12: =CT5+CS12 -> -376185.84
B13: =B6 -> 2% growth | C13: =C6 -> -28249.488 | D13: =D6+C13 -> -43587.356 | E13: =E6+D13 -> -56813.011 | F13: =F6+E13 -> -60911.845 | G13: =G6+F13 -> -67124.613 | H13: =H6+G13 -> -66830.228 | I13: =I6+H13 -> -65778.498 | J13: =J6+I13 -> -69389.555 | K13: =K6+J13 -> -69238.842 | ... CT13: =CT6+CS13 -> 54994.963
B14: =B7 -> 4% growth | C14: =C7 -> -27548.732 | D14: =D7+C14 -> -41042.225 | E14: =E7+D14 -> -52979.506 | F14: =F7+E14 -> -55684.224 | G14: =G7+F14 -> -60522.851 | H14: =H7+G14 -> -58881.233 | I14: =I7+H14 -> -56514.586 | J14: =J7+I14 -> -58985.869 | K14: =K7+J14 -> -57170.177 | ... CT14: =CT7+CS14 -> 477802.79
B15: =B8 -> 6% growth | C15: =C8 -> -26861.325 | D15: =D8+C15 -> -38545.576 | E15: =E8+D15 -> -49219.025 | F15: =F8+E15 -> -50556.184 | G15: =G8+F15 -> -54046.844 | H15: =H8+G15 -> -51083.656 | I15: =I8+H15 -> -47427.14 | J15: =J8+I15 -> -48780.359 | K15: =K8+J15 -> -45331.404 | ... CT15: =CT8+CS15 -> 892556.64
B16: =B9 -> 8% growth | C16: =C9 -> -26186.767 | D16: =D9+C16 -> -36095.595 | E16: =E9+D16 -> -45528.838 | F16: =F9+E16 -> -45524 | G16: =G9+F16 -> -47691.891 | H16: =H9+G16 -> -43431.837 | I16: =I9+H16 -> -38509.563 | J16: =J9+I16 -> -38765.618 | K16: =K9+J16 -> -33713.931 | ... CT16: =CT9+CS16 -> 1299557.6
B17: 2015-2016 Defict | C17: 328558 | D17: 328558 | E17: 328558 | F17: 328558 | G17: 328558 | H17: 328558 | I17: 328558 | J17: 328558 | K17: 328558 | L17: 328558 | M17: 328558 | N17: 328558 | O17: 328558 | P17: 328558 | Q17: 328558 | R17: 328558 | S17: 328558 | T17: 328558 | U17: 328558 | V17: 328558 | W17: 328558 | X17: 328558 | Y17: 328558 | Z17: 328558 | AA17: 328558 | AB17: 328558 | AC17: 328558 | AD17: 328558 | AE17: 328558 | AF17: 328558 | AG17: 328558 | AH17: 328558 | AI17: 328558 | AJ17: 328558 | AK17: 328558 | AL17: 328558 | AM17: 328558 | AN17: 328558 | AO17: 328558 | AP17: 328558 | AQ17: 328558 | AR17: 328558 | AS17: 328558 | AT17: 328558 | AU17: 328558 | AV17: 328558 | AW17: 328558 | AX17: 328558 | AY17: 328558 | AZ17: 328558 | BA17: 328558 | BB17: 328558 | BC17: 328558 | BD17: 328558 | BE17: 328558 | BF17: 328558 | BG17: 328558 | BH17: 328558 | BI17: 328558 | BJ17: 328558 | BK17: 328558 | BL17: 328558 | BM17: 328558 | BN17: 328558 | BO17: 328558 | BP17: 328558 | BQ17: 328558 | BR17: 328558 | BS17: 328558 | BT17: 328558 | BU17: 328558 | BV17: 328558 | BW17: 328558 | BX17: 328558 | BY17: 328558 | BZ17: 328558 | CA17: 328558 | CB17: 328558 | CC17: 328558 | CD17: 328558 | CE17: 328558 | CF17: 328558 | CG17: 328558 | CH17: 328558 | CI17: 328558 | CJ17: 328558 | CK17: 328558 | CL17: 328558 | CM17: 328558 | CN17: 328558 | CO17: 328558 | CP17: 328558 | CQ17: 328558 | CR17: 328558 | CS17: 328558 | CT17: 328558
B18: Actual | C18: =C10 -> -22707 | D18: =D10+C18 -> -30496 | E18: =E10+D18 -> -44755 | F18: =F10+E18 -> -48487 | G18: =G10+F18 -> -54964 | H18: =H10+G18 -> -61783 | I18: =I10+H18 -> -66069 | J18: =J10+I18 -> -69735 | K18: =K10+J18 -> -72698 | ... AL18: =AL10+AK18 -> -98957

Sheet BH_3107
C2: 2017M1 | D2: 2017M2 | E2: 2017M3 | F2: 2017M4 | G2: 2017M5 | H2: 2017M6 | I2: 2017M7 | J2: 2017M8 | K2: 2017M9 | L2: 2017M10 | M2: 2017M11 | N2: 2017M12 | O2: 2018M1 | P2: 2018M2 | Q2: 2018M3 | R2: 2018M4 | S2: 2018M5 | T2: 2018M6 | U2: 2018M7 | V2: 2018M8 | W2: 2018M9 | X2: 2018M10 | Y2: 2018M11 | Z2: 2018M12 | AA2: 2019M1 | AB2: 2019M2 | AC2: 2019M3 | AD2: 2019M4 | AE2: 2019M5 | AF2: 2019M6 | AG2: 2019M7 | AH2: 2019M8 | AI2: 2019M9 | AJ2: 2019M10 | AK2: 2019M11 | AL2: 2019M12 | AM2: 2020M1 | AN2: 2020M2 | AO2: 2020M3 | AP2: 2020M4 | AQ2: 2020M5 | AR2: 2020M6 | AS2: 2020M7 | AT2: 2020M8 | AU2: 2020M9 | AV2: 2020M10 | AW2: 2020M11 | AX2: 2020M12 | AY2: 2021M1 | AZ2: 2021M2 | BA2: 2021M3 | BB2: 2021M4 | BC2: 2021M5 | BD2: 2021M6 | BE2: 2021M7 | BF2: 2021M8 | BG2: 2021M9 | BH2: 2021M10 | BI2: 2021M11 | BJ2: 2021M12 | BK2: 2022M1 | BL2: 2022M2 | BM2: 2022M3 | BN2: 2022M4 | BO2: 2022M5 | BP2: 2022M6 | BQ2: 2022M7 | BR2: 2022M8 | BS2: 2022M9 | BT2: 2022M10 | BU2: 2022M11 | BV2: 2022M12 | BW2: 2023M1 | BX2: 2023M2 | BY2: 2023M3 | BZ2: 2023M4 | CA2: 2023M5 | CB2: 2023M6 | CC2: 2023M7 | CD2: 2023M8 | CE2: 2023M9 | CF2: 2023M10 | CG2: 2023M11 | CH2: 2023M12 | CI2: 2024M1 | CJ2: 2024M2 | CK2: 2024M3 | CL2: 2024M4 | CM2: 2024M5 | CN2: 2024M6 | CO2: 2024M7 | CP2: 2024M8 | CQ2: 2024M9 | CR2: 2024M10 | CS2: 2024M11 | CT2: 2024M12
C3: =DATE(LEFT(C2,4),SUBSTITUTE(RIGHT(C2,2),"M",""),1) -> 42736 | D3: =DATE(LEFT(D2,4),SUBSTITUTE(RIGHT(D2,2),"M",""),1) -> 42767 | E3: =DATE(LEFT(E2,4),SUBSTITUTE(RIGHT(E2,2),"M",""),1) -> 42795 | F3: =DATE(LEFT(F2,4),SUBSTITUTE(RIGHT(F2,2),"M",""),1) -> 42826 | G3: =DATE(LEFT(G2,4),SUBSTITUTE(RIGHT(G2,2),"M",""),1) -> 42856 | H3: =DATE(LEFT(H2,4),SUBSTITUTE(RIGHT(H2,2),"M",""),1) -> 42887 | I3: =DATE(LEFT(I2,4),SUBSTITUTE(RIGHT(I2,2),"M",""),1) -> 42917 | J3: =DATE(LEFT(J2,4),SUBSTITUTE(RIGHT(J2,2),"M",""),1) -> 42948 | ... CT3: =DATE(LEFT(CT2,4),SUBSTITUTE(RIGHT(CT2,2),"M",""),1) -> 45627
B5: 0% growth | C5: ='conditional forecasts_0'!D590 -> -11535.853 | D5: ='conditional forecasts_0'!E590 -> -7482.1847 | E5: ='conditional forecasts_0'!F590 -> -5197.457 | F5: ='conditional forecasts_0'!G590 -> -3422.4401 | G5: ='conditional forecasts_0'!H590 -> -5716.6409 | H5: ='conditional forecasts_0'!I590 -> 497.18637 | I5: ='conditional forecasts_0'!J590 -> -2218.2487 | J5: ='conditional forecasts_0'!K590 -> -3030.6752 | ... CT5: ='conditional forecasts_0'!CU590 -> -4042.5758
B6: 2% growth | C6: ='conditional forecasts_2'!D590 -> -9950.3881 | D6: ='conditional forecasts_2'!E590 -> -6299.0049 | E6: ='conditional forecasts_2'!F590 -> -4516.0119 | F6: ='conditional forecasts_2'!G590 -> -2434.1206 | G6: ='conditional forecasts_2'!H590 -> -4850.9035 | H6: ='conditional forecasts_2'!I590 -> 1407.0671 | I6: ='conditional forecasts_2'!J590 -> -1361.8511 | J6: ='conditional forecasts_2'!K590 -> -2166.164 | ... CT6: ='conditional forecasts_2'!CU590 -> -3415.6205
B7: 4% growth | C7: ='conditional forecasts_4'!D590 -> -8395.7106 | D7: ='conditional forecasts_4'!E590 -> -5138.8009 | E7: ='conditional forecasts_4'!F590 -> -3847.7997 | F7: ='conditional forecasts_4'!G590 -> -1464.993 | G7: ='conditional forecasts_4'!H590 -> -4001.9777 | H7: ='conditional forecasts_4'!I590 -> 2299.2791 | I7: ='conditional forecasts_4'!J590 -> -522.08356 | J7: ='conditional forecasts_4'!K590 -> -1318.4404 | ... CT7: ='conditional forecasts_4'!CU590 -> -2800.8399
B8: 6% growth | C8: ='conditional forecasts_6'!D590 -> -6870.6478 | D8: ='conditional forecasts_6'!E590 -> -4000.6973 | E8: ='conditional forecasts_6'!F590 -> -3192.3161 | F8: ='conditional forecasts_6'!G590 -> -514.32611 | G8: ='conditional forecasts_6'!H590 -> -3169.2228 | H8: ='conditional forecasts_6'!I590 -> 3174.4956 | I8: ='conditional forecasts_6'!J590 -> 301.68739 | J8: ='conditional forecasts_6'!K590 -> -486.86498 | ... CT8: ='conditional forecasts_6'!CU590 -> -2197.7701
B9: 8% growth | C9: ='conditional forecasts_8'!D590 -> -5374.0926 | D9: ='conditional forecasts_8'!E590 -> -2883.868 | E9: ='conditional forecasts_8'!F590 -> -2549.0852 | F9: ='conditional forecasts_8'!G590 -> 418.57026 | G9: ='conditional forecasts_8'!H590 -> -2352.0344 | H9: ='conditional forecasts_8'!I590 -> 4033.3519 | I9: ='conditional forecasts_8'!J590 -> 1110.0598 | J9: ='conditional forecasts_8'!K590 -> 329.16609 | ... CT9: ='conditional forecasts_8'!CU590 -> -1605.9734
B10: Actual | C10: -3386 | D10: 2024 | E10: -3440 | F10: 2636 | G10: 1086 | H10: -1131 | I10: 2294 | J10: 1376 | K10: 719 | L10: 4197 | M10: 923 | N10: -10673 | O10: 2974 | P10: 2409 | Q10: 4960 | R10: 9141 | S10: 2982 | T10: -230 | U10: 4307 | V10: 10267 | W10: 12329 | X10: 4032 | Y10: 2780 | Z10: -10695 | AA10: 710 | AB10: 12552 | AC10: -600 | AD10: 6797 | AE10: 519 | AF10: 4746 | AG10: 8305 | AH10: 8246 | AI10: 5520 | AJ10: 9950 | AK10: 5310 | AL10: -11007
B12: =B5 -> 0% growth | C12: =C5 -> -11535.853 | D12: =D5+C12 -> -19018.038 | E12: =E5+D12 -> -24215.495 | F12: =F5+E12 -> -27637.935 | G12: =G5+F12 -> -33354.576 | H12: =H5+G12 -> -32857.389 | I12: =I5+H12 -> -35075.638 | J12: =J5+I12 -> -38106.313 | K12: =K5+J12 -> -39064.984 | ... CT12: =CT5+CS12 -> -154081.53
B13: =B6 -> 2% growth | C13: =C6 -> -9950.3881 | D13: =D6+C13 -> -16249.393 | E13: =E6+D13 -> -20765.405 | F13: =F6+E13 -> -23199.525 | G13: =G6+F13 -> -28050.429 | H13: =H6+G13 -> -26643.362 | I13: =I6+H13 -> -28005.213 | J13: =J6+I13 -> -30171.377 | K13: =K6+J13 -> -29937.137 | ... CT13: =CT6+CS13 -> 47139.924
B14: =B7 -> 4% growth | C14: =C7 -> -8395.7106 | D14: =D7+C14 -> -13534.511 | E14: =E7+D14 -> -17382.311 | F14: =F7+E14 -> -18847.304 | G14: =G7+F14 -> -22849.282 | H14: =H7+G14 -> -20550.003 | I14: =I7+H14 -> -21072.086 | J14: =J7+I14 -> -22390.527 | K14: =K7+J14 -> -20986.541 | ... CT14: =CT7+CS14 -> 244453.92
B15: =B8 -> 6% growth | C15: =C8 -> -6870.6478 | D15: =D8+C15 -> -10871.345 | E15: =E8+D15 -> -14063.661 | F15: =F8+E15 -> -14577.987 | G15: =G8+F15 -> -17747.21 | H15: =H8+G15 -> -14572.715 | I15: =I8+H15 -> -14271.027 | J15: =J8+I15 -> -14757.892 | K15: =K8+J15 -> -12206.443 | ... CT15: =CT8+CS15 -> 438009.32
B16: =B9 -> 8% growth | C16: =C9 -> -5374.0926 | D16: =D9+C16 -> -8257.9606 | E16: =E9+D16 -> -10807.046 | F16: =F9+E16 -> -10388.476 | G16: =G9+F16 -> -12740.51 | H16: =H9+G16 -> -8707.1581 | I16: =I9+H16 -> -7597.0982 | J16: =J9+I16 -> -7267.9321 | K16: =K9+J16 -> -3590.4684 | ... CT16: =CT9+CS16 -> 627946.66
B17: 2015-2016 Defict | C17: 217468 | D17: 217468 | E17: 217468 | F17: 217468 | G17: 217468 | H17: 217468 | I17: 217468 | J17: 217468 | K17: 217468 | L17: 217468 | M17: 217468 | N17: 217468 | O17: 217468 | P17: 217468 | Q17: 217468 | R17: 217468 | S17: 217468 | T17: 217468 | U17: 217468 | V17: 217468 | W17: 217468 | X17: 217468 | Y17: 217468 | Z17: 217468 | AA17: 217468 | AB17: 217468 | AC17: 217468 | AD17: 217468 | AE17: 217468 | AF17: 217468 | AG17: 217468 | AH17: 217468 | AI17: 217468 | AJ17: 217468 | AK17: 217468 | AL17: 217468 | AM17: 217468 | AN17: 217468 | AO17: 217468 | AP17: 217468 | AQ17: 217468 | AR17: 217468 | AS17: 217468 | AT17: 217468 | AU17: 217468 | AV17: 217468 | AW17: 217468 | AX17: 217468 | AY17: 217468 | AZ17: 217468 | BA17: 217468 | BB17: 217468 | BC17: 217468 | BD17: 217468 | BE17: 217468 | BF17: 217468 | BG17: 217468 | BH17: 217468 | BI17: 217468 | BJ17: 217468 | BK17: 217468 | BL17: 217468 | BM17: 217468 | BN17: 217468 | BO17: 217468 | BP17: 217468 | BQ17: 217468 | BR17: 217468 | BS17: 217468 | BT17: 217468 | BU17: 217468 | BV17: 217468 | BW17: 217468 | BX17: 217468 | BY17: 217468 | BZ17: 217468 | CA17: 217468 | CB17: 217468 | CC17: 217468 | CD17: 217468 | CE17: 217468 | CF17: 217468 | CG17: 217468 | CH17: 217468 | CI17: 217468 | CJ17: 217468 | CK17: 217468 | CL17: 217468 | CM17: 217468 | CN17: 217468 | CO17: 217468 | CP17: 217468 | CQ17: 217468 | CR17: 217468 | CS17: 217468 | CT17: 217468
B18: Actual | C18: =C10 -> -3386 | D18: =D10+C18 -> -1362 | E18: =E10+D18 -> -4802 | F18: =F10+E18 -> -2166 | G18: =G10+F18 -> -1080 | H18: =H10+G18 -> -2211 | I18: =I10+H18 -> 83 | J18: =J10+I18 -> 1459 | K18: =K10+J18 -> 2178 | ... AL18: =AL10+AK18 -> 92929

Sheet Salva_2905
C2: 2017M1 | D2: 2017M2 | E2: 2017M3 | F2: 2017M4 | G2: 2017M5 | H2: 2017M6 | I2: 2017M7 | J2: 2017M8 | K2: 2017M9 | L2: 2017M10 | M2: 2017M11 | N2: 2017M12 | O2: 2018M1 | P2: 2018M2 | Q2: 2018M3 | R2: 2018M4 | S2: 2018M5 | T2: 2018M6 | U2: 2018M7 | V2: 2018M8 | W2: 2018M9 | X2: 2018M10 | Y2: 2018M11 | Z2: 2018M12 | AA2: 2019M1 | AB2: 2019M2 | AC2: 2019M3 | AD2: 2019M4 | AE2: 2019M5 | AF2: 2019M6 | AG2: 2019M7 | AH2: 2019M8 | AI2: 2019M9 | AJ2: 2019M10 | AK2: 2019M11 | AL2: 2019M12 | AM2: 2020M1 | AN2: 2020M2 | AO2: 2020M3 | AP2: 2020M4 | AQ2: 2020M5 | AR2: 2020M6 | AS2: 2020M7 | AT2: 2020M8 | AU2: 2020M9 | AV2: 2020M10 | AW2: 2020M11 | AX2: 2020M12 | AY2: 2021M1 | AZ2: 2021M2 | BA2: 2021M3 | BB2: 2021M4 | BC2: 2021M5 | BD2: 2021M6 | BE2: 2021M7 | BF2: 2021M8 | BG2: 2021M9 | BH2: 2021M10 | BI2: 2021M11 | BJ2: 2021M12 | BK2: 2022M1 | BL2: 2022M2 | BM2: 2022M3 | BN2: 2022M4 | BO2: 2022M5 | BP2: 2022M6 | BQ2: 2022M7 | BR2: 2022M8 | BS2: 2022M9 | BT2: 2022M10 | BU2: 2022M11 | BV2: 2022M12 | BW2: 2023M1 | BX2: 2023M2 | BY2: 2023M3 | BZ2: 2023M4 | CA2: 2023M5 | CB2: 2023M6 | CC2: 2023M7 | CD2: 2023M8 | CE2: 2023M9 | CF2: 2023M10 | CG2: 2023M11 | CH2: 2023M12 | CI2: 2024M1 | CJ2: 2024M2 | CK2: 2024M3 | CL2: 2024M4 | CM2: 2024M5 | CN2: 2024M6 | CO2: 2024M7 | CP2: 2024M8 | CQ2: 2024M9 | CR2: 2024M10 | CS2: 2024M11 | CT2: 2024M12
C3: =DATE(LEFT(C2,4),SUBSTITUTE(RIGHT(C2,2),"M",""),1) -> 42736 | D3: =DATE(LEFT(D2,4),SUBSTITUTE(RIGHT(D2,2),"M",""),1) -> 42767 | E3: =DATE(LEFT(E2,4),SUBSTITUTE(RIGHT(E2,2),"M",""),1) -> 42795 | F3: =DATE(LEFT(F2,4),SUBSTITUTE(RIGHT(F2,2),"M",""),1) -> 42826 | G3: =DATE(LEFT(G2,4),SUBSTITUTE(RIGHT(G2,2),"M",""),1) -> 42856 | H3: =DATE(LEFT(H2,4),SUBSTITUTE(RIGHT(H2,2),"M",""),1) -> 42887 | I3: =DATE(LEFT(I2,4),SUBSTITUTE(RIGHT(I2,2),"M",""),1) -> 42917 | J3: =DATE(LEFT(J2,4),SUBSTITUTE(RIGHT(J2,2),"M",""),1) -> 42948 | ... CT3: =DATE(LEFT(CT2,4),SUBSTITUTE(RIGHT(CT2,2),"M",""),1) -> 45627
B5: 0% growth | C5: ='conditional forecasts_0'!D589 -> -4740.122 | D5: ='conditional forecasts_0'!E589 -> -5530.2772 | E5: ='conditional forecasts_0'!F589 -> -4861.9969 | F5: ='conditional forecasts_0'!G589 -> -3050.6991 | G5: ='conditional forecasts_0'!H589 -> -4076.3024 | H5: ='conditional forecasts_0'!I589 -> -776.19765 | I5: ='conditional forecasts_0'!J589 -> -1918.9955 | J5: ='conditional forecasts_0'!K589 -> -1409.1962 | ... CT5: ='conditional forecasts_0'!CU589 -> -189.97282
B6: 2% growth | C6: ='conditional forecasts_2'!D589 -> -4431.16 | D6: ='conditional forecasts_2'!E589 -> -5182.9237 | E6: ='conditional forecasts_2'!F589 -> -4506.8713 | F6: ='conditional forecasts_2'!G589 -> -2600.5928 | G6: ='conditional forecasts_2'!H589 -> -3681.839 | H6: ='conditional forecasts_2'!I589 -> -330.08437 | I6: ='conditional forecasts_2'!J589 -> -1535.0232 | J6: ='conditional forecasts_2'!K589 -> -1056.4783 | ... CT6: ='conditional forecasts_2'!CU589 -> 71.027438
B7: 4% growth | C7: ='conditional forecasts_4'!D589 -> -4128.1976 | D7: ='conditional forecasts_4'!E589 -> -4842.3155 | E7: ='conditional forecasts_4'!F589 -> -4158.6418 | F7: ='conditional forecasts_4'!G589 -> -2159.227 | G7: ='conditional forecasts_4'!H589 -> -3295.0356 | H7: ='conditional forecasts_4'!I589 -> 107.36595 | I7: ='conditional forecasts_4'!J589 -> -1158.5071 | J7: ='conditional forecasts_4'!K589 -> -710.60964 | ... CT7: ='conditional forecasts_4'!CU589 -> 326.95941
B8: 6% growth | C8: ='conditional forecasts_6'!D589 -> -3831.0063 | D8: ='conditional forecasts_6'!E589 -> -4508.1954 | E8: ='conditional forecasts_6'!F589 -> -3817.0456 | F8: ='conditional forecasts_6'!G589 -> -1726.2688 | G8: ='conditional forecasts_6'!H589 -> -2915.6004 | H8: ='conditional forecasts_6'!I589 -> 536.48339 | I8: ='conditional forecasts_6'!J589 -> -789.16313 | J8: ='conditional forecasts_6'!K589 -> -371.32937 | ... CT8: ='conditional forecasts_6'!CU589 -> 578.01619
B9: 8% growth | C9: ='conditional forecasts_8'!D589 -> -3539.3703 | D9: ='conditional forecasts_8'!E589 -> -4180.3209 | E9: ='conditional forecasts_8'!F589 -> -3481.8348 | F9: ='conditional forecasts_8'!G589 -> -1301.4036 | G9: ='conditional forecasts_8'!H589 -> -2543.2578 | H9: ='conditional forecasts_8'!I589 -> 957.57946 | I9: ='conditional forecasts_8'!J589 -> -426.72323 | J9: ='conditional forecasts_8'!K589 -> -38.391171 | ... CT9: ='conditional forecasts_8'!CU589 -> 824.38004
B10: Actual | C10: -1198 | D10: -3022 | E10: -2831 | F10: 1598 | G10: -1287 | H10: -1365 | I10: 705 | J10: 877 | K10: -271 | L10: 705 | M10: 1745 | N10: -4621 | O10: 2196 | P10: -1398 | Q10: 1192 | R10: -2070 | S10: -713 | T10: -1370 | U10: 171 | V10: 3368 | W10: 5537 | X10: 220 | Y10: 3862 | Z10: -3193 | AA10: 500 | AB10: 2429 | AC10: 486 | AD10: 1843 | AE10: -1733 | AF10: 460 | AG10: -2821 | AH10: 1352 | AI10: 1026 | AJ10: -1431 | AK10: 4833 | AL10: -6210
B12: =B5 -> 0% growth | C12: =C5 -> -4740.122 | D12: =D5+C12 -> -10270.399 | E12: =E5+D12 -> -15132.396 | F12: =F5+E12 -> -18183.095 | G12: =G5+F12 -> -22259.397 | H12: =H5+G12 -> -23035.595 | I12: =I5+H12 -> -24954.591 | J12: =J5+I12 -> -26363.787 | K12: =K5+J12 -> -26566.598 | ... CT12: =CT5+CS12 -> -102060.18
B13: =B6 -> 2% growth | C13: =C6 -> -4431.16 | D13: =D6+C13 -> -9614.0837 | E13: =E6+D13 -> -14120.955 | F13: =F6+E13 -> -16721.548 | G13: =G6+F13 -> -20403.387 | H13: =H6+G13 -> -20733.471 | I13: =I6+H13 -> -22268.494 | J13: =J6+I13 -> -23324.973 | K13: =K6+J13 -> -23052.105 | ... CT13: =CT6+CS13 -> -17408.303
B14: =B7 -> 4% growth | C14: =C7 -> -4128.1976 | D14: =D7+C14 -> -8970.5131 | E14: =E7+D14 -> -13129.155 | F14: =F7+E14 -> -15288.382 | G14: =G7+F14 -> -18583.418 | H14: =H7+G14 -> -18476.052 | I14: =I7+H14 -> -19634.559 | J14: =J7+I14 -> -20345.168 | K14: =K7+J14 -> -19605.859 | ... CT14: =CT7+CS14 -> 65599.749
B15: =B8 -> 6% growth | C15: =C8 -> -3831.0063 | D15: =D8+C15 -> -8339.2017 | E15: =E8+D15 -> -12156.247 | F15: =F8+E15 -> -13882.516 | G15: =G8+F15 -> -16798.116 | H15: =H8+G15 -> -16261.633 | I15: =I8+H15 -> -17050.796 | J15: =J8+I15 -> -17422.126 | K15: =K8+J15 -> -16225.26 | ... CT15: =CT8+CS15 -> 147026.6
B16: =B9 -> 8% growth | C16: =C9 -> -3539.3703 | D16: =D9+C16 -> -7719.6912 | E16: =E9+D16 -> -11201.526 | F16: =F9+E16 -> -12502.93 | G16: =G9+F16 -> -15046.187 | H16: =H9+G16 -> -14088.608 | I16: =I9+H16 -> -14515.331 | J16: =J9+I16 -> -14553.722 | K16: =K9+J16 -> -12907.853 | ... CT16: =CT9+CS16 -> 226931.36
B17: 2015-2016 Defict | C17: 104758 | D17: 104758 | E17: 104758 | F17: 104758 | G17: 104758 | H17: 104758 | I17: 104758 | J17: 104758 | K17: 104758 | L17: 104758 | M17: 104758 | N17: 104758 | O17: 104758 | P17: 104758 | Q17: 104758 | R17: 104758 | S17: 104758 | T17: 104758 | U17: 104758 | V17: 104758 | W17: 104758 | X17: 104758 | Y17: 104758 | Z17: 104758 | AA17: 104758 | AB17: 104758 | AC17: 104758 | AD17: 104758 | AE17: 104758 | AF17: 104758 | AG17: 104758 | AH17: 104758 | AI17: 104758 | AJ17: 104758 | AK17: 104758 | AL17: 104758 | AM17: 104758 | AN17: 104758 | AO17: 104758 | AP17: 104758 | AQ17: 104758 | AR17: 104758 | AS17: 104758 | AT17: 104758 | AU17: 104758 | AV17: 104758 | AW17: 104758 | AX17: 104758 | AY17: 104758 | AZ17: 104758 | BA17: 104758 | BB17: 104758 | BC17: 104758 | BD17: 104758 | BE17: 104758 | BF17: 104758 | BG17: 104758 | BH17: 104758 | BI17: 104758 | BJ17: 104758 | BK17: 104758 | BL17: 104758 | BM17: 104758 | BN17: 104758 | BO17: 104758 | BP17: 104758 | BQ17: 104758 | BR17: 104758 | BS17: 104758 | BT17: 104758 | BU17: 104758 | BV17: 104758 | BW17: 104758 | BX17: 104758 | BY17: 104758 | BZ17: 104758 | CA17: 104758 | CB17: 104758 | CC17: 104758 | CD17: 104758 | CE17: 104758 | CF17: 104758 | CG17: 104758 | CH17: 104758 | CI17: 104758 | CJ17: 104758 | CK17: 104758 | CL17: 104758 | CM17: 104758 | CN17: 104758 | CO17: 104758 | CP17: 104758 | CQ17: 104758 | CR17: 104758 | CS17: 104758 | CT17: 104758
B18: Actual | C18: =C10 -> -1198 | D18: =D10+C18 -> -4220 | E18: =E10+D18 -> -7051 | F18: =F10+E18 -> -5453 | G18: =G10+F18 -> -6740 | H18: =H10+G18 -> -8105 | I18: =I10+H18 -> -7400 | J18: =J10+I18 -> -6523 | K18: =K10+J18 -> -6794 | ... AL18: =AL10+AK18 -> -429

Sheet SP_3515
C2: 2017M1 | D2: 2017M2 | E2: 2017M3 | F2: 2017M4 | G2: 2017M5 | H2: 2017M6 | I2: 2017M7 | J2: 2017M8 | K2: 2017M9 | L2: 2017M10 | M2: 2017M11 | N2: 2017M12 | O2: 2018M1 | P2: 2018M2 | Q2: 2018M3 | R2: 2018M4 | S2: 2018M5 | T2: 2018M6 | U2: 2018M7 | V2: 2018M8 | W2: 2018M9 | X2: 2018M10 | Y2: 2018M11 | Z2: 2018M12 | AA2: 2019M1 | AB2: 2019M2 | AC2: 2019M3 | AD2: 2019M4 | AE2: 2019M5 | AF2: 2019M6 | AG2: 2019M7 | AH2: 2019M8 | AI2: 2019M9 | AJ2: 2019M10 | AK2: 2019M11 | AL2: 2019M12 | AM2: 2020M1 | AN2: 2020M2 | AO2: 2020M3 | AP2: 2020M4 | AQ2: 2020M5 | AR2: 2020M6 | AS2: 2020M7 | AT2: 2020M8 | AU2: 2020M9 | AV2: 2020M10 | AW2: 2020M11 | AX2: 2020M12 | AY2: 2021M1 | AZ2: 2021M2 | BA2: 2021M3 | BB2: 2021M4 | BC2: 2021M5 | BD2: 2021M6 | BE2: 2021M7 | BF2: 2021M8 | BG2: 2021M9 | BH2: 2021M10 | BI2: 2021M11 | BJ2: 2021M12 | BK2: 2022M1 | BL2: 2022M2 | BM2: 2022M3 | BN2: 2022M4 | BO2: 2022M5 | BP2: 2022M6 | BQ2: 2022M7 | BR2: 2022M8 | BS2: 2022M9 | BT2: 2022M10 | BU2: 2022M11 | BV2: 2022M12 | BW2: 2023M1 | BX2: 2023M2 | BY2: 2023M3 | BZ2: 2023M4 | CA2: 2023M5 | CB2: 2023M6 | CC2: 2023M7 | CD2: 2023M8 | CE2: 2023M9 | CF2: 2023M10 | CG2: 2023M11 | CH2: 2023M12 | CI2: 2024M1 | CJ2: 2024M2 | CK2: 2024M3 | CL2: 2024M4 | CM2: 2024M5 | CN2: 2024M6 | CO2: 2024M7 | CP2: 2024M8 | CQ2: 2024M9 | CR2: 2024M10 | CS2: 2024M11 | CT2: 2024M12
C3: =DATE(LEFT(C2,4),SUBSTITUTE(RIGHT(C2,2),"M",""),1) -> 42736 | D3: =DATE(LEFT(D2,4),SUBSTITUTE(RIGHT(D2,2),"M",""),1) -> 42767 | E3: =DATE(LEFT(E2,4),SUBSTITUTE(RIGHT(E2,2),"M",""),1) -> 42795 | F3: =DATE(LEFT(F2,4),SUBSTITUTE(RIGHT(F2,2),"M",""),1) -> 42826 | G3: =DATE(LEFT(G2,4),SUBSTITUTE(RIGHT(G2,2),"M",""),1) -> 42856 | H3: =DATE(LEFT(H2,4),SUBSTITUTE(RIGHT(H2,2),"M",""),1) -> 42887 | I3: =DATE(LEFT(I2,4),SUBSTITUTE(RIGHT(I2,2),"M",""),1) -> 42917 | J3: =DATE(LEFT(J2,4),SUBSTITUTE(RIGHT(J2,2),"M",""),1) -> 42948 | ... CT3: =DATE(LEFT(CT2,4),SUBSTITUTE(RIGHT(CT2,2),"M",""),1) -> 45627
B5: 0% growth | C5: ='conditional forecasts_0'!D576 -> -33408.732 | D5: ='conditional forecasts_0'!E576 -> -19593.525 | E5: ='conditional forecasts_0'!F576 -> -13854.219 | F5: ='conditional forecasts_0'!G576 -> -5591.4701 | G5: ='conditional forecasts_0'!H576 -> -13780.774 | H5: ='conditional forecasts_0'!I576 -> 5114.2425 | I5: ='conditional forecasts_0'!J576 -> -3891.409 | J5: ='conditional forecasts_0'!K576 -> -6468.0531 | ... CT5: ='conditional forecasts_0'!CU576 -> -938.49433
B6: 2% growth | C6: ='conditional forecasts_2'!D576 -> -29160.784 | D6: ='conditional forecasts_2'!E576 -> -15912.95 | E6: ='conditional forecasts_2'!F576 -> -11222.295 | F6: ='conditional forecasts_2'!G576 -> -2301.631 | G6: ='conditional forecasts_2'!H576 -> -10993.981 | H6: ='conditional forecasts_2'!I576 -> 8102.2155 | I6: ='conditional forecasts_2'!J576 -> -1181.7802 | J6: ='conditional forecasts_2'!K576 -> -3792.1748 | ... CT6: ='conditional forecasts_2'!CU576 -> 887.83839
B7: 4% growth | C7: ='conditional forecasts_4'!D576 -> -24995.325 | D7: ='conditional forecasts_4'!E576 -> -12303.846 | E7: ='conditional forecasts_4'!F576 -> -8641.4786 | F7: ='conditional forecasts_4'!G576 -> 924.32373 | G7: ='conditional forecasts_4'!H576 -> -8261.3044 | H7: ='conditional forecasts_4'!I576 -> 11032.166 | I7: ='conditional forecasts_4'!J576 -> 1475.2312 | J7: ='conditional forecasts_4'!K576 -> -1168.2585 | ... CT7: ='conditional forecasts_4'!CU576 -> 2678.7061
B8: 6% growth | C8: ='conditional forecasts_6'!D576 -> -20909.212 | D8: ='conditional forecasts_6'!E576 -> -8763.4913 | E8: ='conditional forecasts_6'!F576 -> -6109.8239 | F8: ='conditional forecasts_6'!G576 -> 4088.8279 | G8: ='conditional forecasts_6'!H576 -> -5580.6815 | H8: ='conditional forecasts_6'!I576 -> 13906.304 | I8: ='conditional forecasts_6'!J576 -> 4081.6298 | J8: ='conditional forecasts_6'!K576 -> 1405.6753 | ... CT8: ='conditional forecasts_6'!CU576 -> 4435.4599
B9: 8% growth | C9: ='conditional forecasts_8'!D576 -> -16899.481 | D9: ='conditional forecasts_8'!E576 -> -5289.3153 | E9: ='conditional forecasts_8'!F576 -> -3625.4927 | F9: ='conditional forecasts_8'!G576 -> 7194.179 | G9: ='conditional forecasts_8'!H576 -> -2950.1667 | H9: ='conditional forecasts_8'!I576 -> 16726.717 | I9: ='conditional forecasts_8'!J576 -> 6639.3078 | J9: ='conditional forecasts_8'!K576 -> 3931.4954 | ... CT9: ='conditional forecasts_8'!CU576 -> 6159.3753
B10: Actual | C10: -11018 | D10: 3100 | E10: -13073 | F10: 4324 | G10: -3422 | H10: -5707 | I10: 10468 | J10: 8502 | K10: -1374 | L10: 7391 | M10: -816 | N10: -42674 | O10: 3791 | P10: 14914 | Q10: 18926 | R10: 18236 | S10: 1963 | T10: -7657 | U10: 4787 | V10: 15065 | W10: 12170 | X10: 11081 | Y10: 19684 | Z10: -38216 | AA10: 1966 | AB10: 30166 | AC10: -6310 | AD10: 18156 | AE10: -5727 | AF10: 12259 | AG10: 8582 | AH10: 18528 | AI10: 21676 | AJ10: 13443 | AK10: 26599 | AL10: -39546
B12: =B5 -> 0% growth | C12: =C5 -> -33408.732 | D12: =D5+C12 -> -53002.258 | E12: =E5+D12 -> -66856.477 | F12: =F5+E12 -> -72447.947 | G12: =G5+F12 -> -86228.721 | H12: =H5+G12 -> -81114.479 | I12: =I5+H12 -> -85005.888 | J12: =J5+I12 -> -91473.941 | K12: =K5+J12 -> -89272.353 | ... CT12: =CT5+CS12 -> -43019.4
B13: =B6 -> 2% growth | C13: =C6 -> -29160.784 | D13: =D6+C13 -> -45073.733 | E13: =E6+D13 -> -56296.028 | F13: =F6+E13 -> -58597.659 | G13: =G6+F13 -> -69591.64 | H13: =H6+G13 -> -61489.425 | I13: =I6+H13 -> -62671.205 | J13: =J6+I13 -> -66463.38 | K13: =K6+J13 -> -60497.994 | ... CT13: =CT6+CS13 -> 569707.96
B14: =B7 -> 4% growth | C14: =C7 -> -24995.325 | D14: =D7+C14 -> -37299.171 | E14: =E7+D14 -> -45940.649 | F14: =F7+E14 -> -45016.325 | G14: =G7+F14 -> -53277.63 | H14: =H7+G14 -> -42245.464 | I14: =I7+H14 -> -40770.233 | J14: =J7+I14 -> -41938.491 | K14: =K7+J14 -> -32282.396 | ... CT14: =CT7+CS14 -> 1170536.9
B15: =B8 -> 6% growth | C15: =C8 -> -20909.212 | D15: =D8+C15 -> -29672.704 | E15: =E8+D15 -> -35782.528 | F15: =F8+E15 -> -31693.7 | G15: =G8+F15 -> -37274.381 | H15: =H8+G15 -> -23368.077 | I15: =I8+H15 -> -19286.447 | J15: =J8+I15 -> -17880.772 | K15: =K8+J15 -> -4604.2703 | ... CT15: =CT8+CS15 -> 1759920.9
B16: =B9 -> 8% growth | C16: =C9 -> -16899.481 | D16: =D9+C16 -> -22188.796 | E16: =E9+D16 -> -25814.289 | F16: =F9+E16 -> -18620.11 | G16: =G9+F16 -> -21570.276 | H16: =H9+G16 -> -4843.5592 | I16: =I9+H16 -> 1795.7486 | J16: =J9+I16 -> 5727.244 | K16: =K9+J16 -> 22556.477 | ... CT16: =CT9+CS16 -> 2338287.6
B17: 2015-2016 Defict | C17: 511649 | D17: 511649 | E17: 511649 | F17: 511649 | G17: 511649 | H17: 511649 | I17: 511649 | J17: 511649 | K17: 511649 | L17: 511649 | M17: 511649 | N17: 511649 | O17: 511649 | P17: 511649 | Q17: 511649 | R17: 511649 | S17: 511649 | T17: 511649 | U17: 511649 | V17: 511649 | W17: 511649 | X17: 511649 | Y17: 511649 | Z17: 511649 | AA17: 511649 | AB17: 511649 | AC17: 511649 | AD17: 511649 | AE17: 511649 | AF17: 511649 | AG17: 511649 | AH17: 511649 | AI17: 511649 | AJ17: 511649 | AK17: 511649 | AL17: 511649 | AM17: 511649 | AN17: 511649 | AO17: 511649 | AP17: 511649 | AQ17: 511649 | AR17: 511649 | AS17: 511649 | AT17: 511649 | AU17: 511649 | AV17: 511649 | AW17: 511649 | AX17: 511649 | AY17: 511649 | AZ17: 511649 | BA17: 511649 | BB17: 511649 | BC17: 511649 | BD17: 511649 | BE17: 511649 | BF17: 511649 | BG17: 511649 | BH17: 511649 | BI17: 511649 | BJ17: 511649 | BK17: 511649 | BL17: 511649 | BM17: 511649 | BN17: 511649 | BO17: 511649 | BP17: 511649 | BQ17: 511649 | BR17: 511649 | BS17: 511649 | BT17: 511649 | BU17: 511649 | BV17: 511649 | BW17: 511649 | BX17: 511649 | BY17: 511649 | BZ17: 511649 | CA17: 511649 | CB17: 511649 | CC17: 511649 | CD17: 511649 | CE17: 511649 | CF17: 511649 | CG17: 511649 | CH17: 511649 | CI17: 511649 | CJ17: 511649 | CK17: 511649 | CL17: 511649 | CM17: 511649 | CN17: 511649 | CO17: 511649 | CP17: 511649 | CQ17: 511649 | CR17: 511649 | CS17: 511649 | CT17: 511649
B18: Actual | C18: =C10 -> -11018 | D18: =D10+C18 -> -7918 | E18: =E10+D18 -> -20991 | F18: =F10+E18 -> -16667 | G18: =G10+F18 -> -20089 | H18: =H10+G18 -> -25796 | I18: =I10+H18 -> -15328 | J18: =J10+I18 -> -6826 | K18: =K10+J18 -> -8200 | ... AL18: =AL10+AK18 -> 130237

Sheet P.Alegre_4305
C2: 2017M1 | D2: 2017M2 | E2: 2017M3 | F2: 2017M4 | G2: 2017M5 | H2: 2017M6 | I2: 2017M7 | J2: 2017M8 | K2: 2017M9 | L2: 2017M10 | M2: 2017M11 | N2: 2017M12 | O2: 2018M1 | P2: 2018M2 | Q2: 2018M3 | R2: 2018M4 | S2: 2018M5 | T2: 2018M6 | U2: 2018M7 | V2: 2018M8 | W2: 2018M9 | X2: 2018M10 | Y2: 2018M11 | Z2: 2018M12 | AA2: 2019M1 | AB2: 2019M2 | AC2: 2019M3 | AD2: 2019M4 | AE2: 2019M5 | AF2: 2019M6 | AG2: 2019M7 | AH2: 2019M8 | AI2: 2019M9 | AJ2: 2019M10 | AK2: 2019M11 | AL2: 2019M12 | AM2: 2020M1 | AN2: 2020M2 | AO2: 2020M3 | AP2: 2020M4 | AQ2: 2020M5 | AR2: 2020M6 | AS2: 2020M7 | AT2: 2020M8 | AU2: 2020M9 | AV2: 2020M10 | AW2: 2020M11 | AX2: 2020M12 | AY2: 2021M1 | AZ2: 2021M2 | BA2: 2021M3 | BB2: 2021M4 | BC2: 2021M5 | BD2: 2021M6 | BE2: 2021M7 | BF2: 2021M8 | BG2: 2021M9 | BH2: 2021M10 | BI2: 2021M11 | BJ2: 2021M12 | BK2: 2022M1 | BL2: 2022M2 | BM2: 2022M3 | BN2: 2022M4 | BO2: 2022M5 | BP2: 2022M6 | BQ2: 2022M7 | BR2: 2022M8 | BS2: 2022M9 | BT2: 2022M10 | BU2: 2022M11 | BV2: 2022M12 | BW2: 2023M1 | BX2: 2023M2 | BY2: 2023M3 | BZ2: 2023M4 | CA2: 2023M5 | CB2: 2023M6 | CC2: 2023M7 | CD2: 2023M8 | CE2: 2023M9 | CF2: 2023M10 | CG2: 2023M11 | CH2: 2023M12 | CI2: 2024M1 | CJ2: 2024M2 | CK2: 2024M3 | CL2: 2024M4 | CM2: 2024M5 | CN2: 2024M6 | CO2: 2024M7 | CP2: 2024M8 | CQ2: 2024M9 | CR2: 2024M10 | CS2: 2024M11 | CT2: 2024M12
C3: =DATE(LEFT(C2,4),SUBSTITUTE(RIGHT(C2,2),"M",""),1) -> 42736 | D3: =DATE(LEFT(D2,4),SUBSTITUTE(RIGHT(D2,2),"M",""),1) -> 42767 | E3: =DATE(LEFT(E2,4),SUBSTITUTE(RIGHT(E2,2),"M",""),1) -> 42795 | F3: =DATE(LEFT(F2,4),SUBSTITUTE(RIGHT(F2,2),"M",""),1) -> 42826 | G3: =DATE(LEFT(G2,4),SUBSTITUTE(RIGHT(G2,2),"M",""),1) -> 42856 | H3: =DATE(LEFT(H2,4),SUBSTITUTE(RIGHT(H2,2),"M",""),1) -> 42887 | I3: =DATE(LEFT(I2,4),SUBSTITUTE(RIGHT(I2,2),"M",""),1) -> 42917 | J3: =DATE(LEFT(J2,4),SUBSTITUTE(RIGHT(J2,2),"M",""),1) -> 42948 | ... CT3: =DATE(LEFT(CT2,4),SUBSTITUTE(RIGHT(CT2,2),"M",""),1) -> 45627
B5: 0% growth | C5: ='conditional forecasts_0'!D575 -> -1312.6244 | D5: ='conditional forecasts_0'!E575 -> -2473.5261 | E5: ='conditional forecasts_0'!F575 -> -1407.0732 | F5: ='conditional forecasts_0'!G575 -> -223.17286 | G5: ='conditional forecasts_0'!H575 -> -2559.5954 | H5: ='conditional forecasts_0'!I575 -> 857.83362 | I5: ='conditional forecasts_0'!J575 -> -1864.6301 | J5: ='conditional forecasts_0'!K575 -> -1185.3419 | ... CT5: ='conditional forecasts_0'!CU575 -> -69.714936
B6: 2% growth | C6: ='conditional forecasts_2'!D575 -> -570.14186 | D6: ='conditional forecasts_2'!E575 -> -1959.5781 | E6: ='conditional forecasts_2'!F575 -> -907.17326 | F6: ='conditional forecasts_2'!G575 -> 384.96563 | G6: ='conditional forecasts_2'!H575 -> -2028.2325 | H6: ='conditional forecasts_2'!I575 -> 1480.788 | I6: ='conditional forecasts_2'!J575 -> -1294.953 | J6: ='conditional forecasts_2'!K575 -> -573.63338 | ... CT6: ='conditional forecasts_2'!CU575 -> 1680.5246
B7: 4% growth | C7: ='conditional forecasts_4'!D575 -> 157.92262 | D7: ='conditional forecasts_4'!E575 -> -1455.6102 | E7: ='conditional forecasts_4'!F575 -> -416.98074 | F7: ='conditional forecasts_4'!G575 -> 981.29486 | G7: ='conditional forecasts_4'!H575 -> -1507.1879 | H7: ='conditional forecasts_4'!I575 -> 2091.6454 | I7: ='conditional forecasts_4'!J575 -> -736.33835 | J7: ='conditional forecasts_4'!K575 -> 26.196556 | ... CT7: ='conditional forecasts_4'!CU575 -> 3396.7768
B8: 6% growth | C8: ='conditional forecasts_6'!D575 -> 872.11837 | D8: ='conditional forecasts_6'!E575 -> -961.24235 | E8: ='conditional forecasts_6'!F575 -> 63.874204 | F8: ='conditional forecasts_6'!G575 -> 1566.2647 | G8: ='conditional forecasts_6'!H575 -> -996.06867 | H8: ='conditional forecasts_6'!I575 -> 2690.8667 | I8: ='conditional forecasts_6'!J575 -> -188.3646 | J8: ='conditional forecasts_6'!K575 -> 614.60047 | ... CT8: ='conditional forecasts_6'!CU575 -> 5080.3365
B9: 8% growth | C9: ='conditional forecasts_8'!D575 -> 1572.9639 | D9: ='conditional forecasts_8'!E575 -> -476.11555 | E9: ='conditional forecasts_8'!F575 -> 535.74068 | F9: ='conditional forecasts_8'!G575 -> 2140.3 | G9: ='conditional forecasts_8'!H575 -> -494.50358 | H9: ='conditional forecasts_8'!I575 -> 3278.8869 | I9: ='conditional forecasts_8'!J575 -> 349.36604 | J9: ='conditional forecasts_8'!K575 -> 1192.0055 | ... CT9: ='conditional forecasts_8'!CU575 -> 6732.4259
B10: Actual | C10: 1881 | D10: 717 | E10: -3655 | F10: -1733 | G10: -3590 | H10: -3704 | I10: 704 | J10: -1160 | K10: 1438 | L10: 2367 | M10: 3181 | N10: -7424 | O10: 5038 | P10: 2666 | Q10: 4049 | R10: -634 | S10: -4300 | T10: -3247 | U10: -1792 | V10: -1211 | W10: 1611 | X10: 3868 | Y10: 2840 | Z10: -7091 | AA10: 2165 | AB10: 5037 | AC10: -3112 | AD10: 638 | AE10: -3264 | AF10: -85 | AG10: -1721 | AH10: 1176 | AI10: 2536 | AJ10: 1918 | AK10: 4433 | AL10: -3411
B12: =B5 -> 0% growth | C12: =C5 -> -1312.6244 | D12: =D5+C12 -> -3786.1505 | E12: =E5+D12 -> -5193.2237 | F12: =F5+E12 -> -5416.3966 | G12: =G5+F12 -> -7975.992 | H12: =H5+G12 -> -7118.1584 | I12: =I5+H12 -> -8982.7885 | J12: =J5+I12 -> -10168.13 | K12: =K5+J12 -> -10280.267 | ... CT12: =CT5+CS12 -> -22228.147
B13: =B6 -> 2% growth | C13: =C6 -> -570.14186 | D13: =D6+C13 -> -2529.7199 | E13: =E6+D13 -> -3436.8932 | F13: =F6+E13 -> -3051.9276 | G13: =G6+F13 -> -5080.1601 | H13: =H6+G13 -> -3599.3721 | I13: =I6+H13 -> -4894.3251 | J13: =J6+I13 -> -5467.9585 | K13: =K6+J13 -> -4795.0855 | ... CT13: =CT6+CS13 -> 143711.34
B14: =B7 -> 4% growth | C14: =C7 -> 157.92262 | D14: =D7+C14 -> -1297.6876 | E14: =E7+D14 -> -1714.6683 | F14: =F7+E14 -> -733.37348 | G14: =G7+F14 -> -2240.5614 | H14: =H7+G14 -> -148.91607 | I14: =I7+H14 -> -885.25442 | J14: =J7+I14 -> -859.05786 | K14: =K7+J14 -> 583.58044 | ... CT14: =CT7+CS14 -> 306428.5
B15: =B8 -> 6% growth | C15: =C8 -> 872.11837 | D15: =D8+C15 -> -89.123988 | E15: =E8+D15 -> -25.249784 | F15: =F8+E15 -> 1541.015 | G15: =G8+F15 -> 544.9463 | H15: =H8+G15 -> 3235.813 | I15: =I8+H15 -> 3047.4484 | J15: =J8+I15 -> 3662.0488 | K15: =K8+J15 -> 5859.7893 | ... CT15: =CT8+CS15 -> 466046.09
B16: =B9 -> 8% growth | C16: =C9 -> 1572.9639 | D16: =D9+C16 -> 1096.8483 | E16: =E9+D16 -> 1632.589 | F16: =F9+E16 -> 3772.889 | G16: =G9+F16 -> 3278.3854 | H16: =H9+G16 -> 6557.2723 | I16: =I9+H16 -> 6906.6383 | J16: =J9+I16 -> 8098.6439 | K16: =K9+J16 -> 11037.372 | ... CT16: =CT9+CS16 -> 622680
B17: 2015-2016 Defict | C17: 83663 | D17: 83663 | E17: 83663 | F17: 83663 | G17: 83663 | H17: 83663 | I17: 83663 | J17: 83663 | K17: 83663 | L17: 83663 | M17: 83663 | N17: 83663 | O17: 83663 | P17: 83663 | Q17: 83663 | R17: 83663 | S17: 83663 | T17: 83663 | U17: 83663 | V17: 83663 | W17: 83663 | X17: 83663 | Y17: 83663 | Z17: 83663 | AA17: 83663 | AB17: 83663 | AC17: 83663 | AD17: 83663 | AE17: 83663 | AF17: 83663 | AG17: 83663 | AH17: 83663 | AI17: 83663 | AJ17: 83663 | AK17: 83663 | AL17: 83663 | AM17: 83663 | AN17: 83663 | AO17: 83663 | AP17: 83663 | AQ17: 83663 | AR17: 83663 | AS17: 83663 | AT17: 83663 | AU17: 83663 | AV17: 83663 | AW17: 83663 | AX17: 83663 | AY17: 83663 | AZ17: 83663 | BA17: 83663 | BB17: 83663 | BC17: 83663 | BD17: 83663 | BE17: 83663 | BF17: 83663 | BG17: 83663 | BH17: 83663 | BI17: 83663 | BJ17: 83663 | BK17: 83663 | BL17: 83663 | BM17: 83663 | BN17: 83663 | BO17: 83663 | BP17: 83663 | BQ17: 83663 | BR17: 83663 | BS17: 83663 | BT17: 83663 | BU17: 83663 | BV17: 83663 | BW17: 83663 | BX17: 83663 | BY17: 83663 | BZ17: 83663 | CA17: 83663 | CB17: 83663 | CC17: 83663 | CD17: 83663 | CE17: 83663 | CF17: 83663 | CG17: 83663 | CH17: 83663 | CI17: 83663 | CJ17: 83663 | CK17: 83663 | CL17: 83663 | CM17: 83663 | CN17: 83663 | CO17: 83663 | CP17: 83663 | CQ17: 83663 | CR17: 83663 | CS17: 83663 | CT17: 83663
B18: Actual | C18: =C10 -> 1881 | D18: =D10+C18 -> 2598 | E18: =E10+D18 -> -1057 | F18: =F10+E18 -> -2790 | G18: =G10+F18 -> -6380 | H18: =H10+G18 -> -10084 | I18: =I10+H18 -> -9380 | J18: =J10+I18 -> -10540 | K18: =K10+J18 -> -9102 | ... AL18: =AL10+AK18 -> -2871

Sheet Jequit_3103
C2: 2017M1 | D2: 2017M2 | E2: 2017M3 | F2: 2017M4 | G2: 2017M5 | H2: 2017M6 | I2: 2017M7 | J2: 2017M8 | K2: 2017M9 | L2: 2017M10 | M2: 2017M11 | N2: 2017M12 | O2: 2018M1 | P2: 2018M2 | Q2: 2018M3 | R2: 2018M4 | S2: 2018M5 | T2: 2018M6 | U2: 2018M7 | V2: 2018M8 | W2: 2018M9 | X2: 2018M10 | Y2: 2018M11 | Z2: 2018M12 | AA2: 2019M1 | AB2: 2019M2 | AC2: 2019M3 | AD2: 2019M4 | AE2: 2019M5 | AF2: 2019M6 | AG2: 2019M7 | AH2: 2019M8 | AI2: 2019M9 | AJ2: 2019M10 | AK2: 2019M11 | AL2: 2019M12 | AM2: 2020M1 | AN2: 2020M2 | AO2: 2020M3 | AP2: 2020M4 | AQ2: 2020M5 | AR2: 2020M6 | AS2: 2020M7 | AT2: 2020M8 | AU2: 2020M9 | AV2: 2020M10 | AW2: 2020M11 | AX2: 2020M12 | AY2: 2021M1 | AZ2: 2021M2 | BA2: 2021M3 | BB2: 2021M4 | BC2: 2021M5 | BD2: 2021M6 | BE2: 2021M7 | BF2: 2021M8 | BG2: 2021M9 | BH2: 2021M10 | BI2: 2021M11 | BJ2: 2021M12 | BK2: 2022M1 | BL2: 2022M2 | BM2: 2022M3 | BN2: 2022M4 | BO2: 2022M5 | BP2: 2022M6 | BQ2: 2022M7 | BR2: 2022M8 | BS2: 2022M9 | BT2: 2022M10 | BU2: 2022M11 | BV2: 2022M12 | BW2: 2023M1 | BX2: 2023M2 | BY2: 2023M3 | BZ2: 2023M4 | CA2: 2023M5 | CB2: 2023M6 | CC2: 2023M7 | CD2: 2023M8 | CE2: 2023M9 | CF2: 2023M10 | CG2: 2023M11 | CH2: 2023M12 | CI2: 2024M1 | CJ2: 2024M2 | CK2: 2024M3 | CL2: 2024M4 | CM2: 2024M5 | CN2: 2024M6 | CO2: 2024M7 | CP2: 2024M8 | CQ2: 2024M9 | CR2: 2024M10 | CS2: 2024M11 | CT2: 2024M12
C3: =DATE(LEFT(C2,4),SUBSTITUTE(RIGHT(C2,2),"M",""),1) -> 42736 | D3: =DATE(LEFT(D2,4),SUBSTITUTE(RIGHT(D2,2),"M",""),1) -> 42767 | E3: =DATE(LEFT(E2,4),SUBSTITUTE(RIGHT(E2,2),"M",""),1) -> 42795 | F3: =DATE(LEFT(F2,4),SUBSTITUTE(RIGHT(F2,2),"M",""),1) -> 42826 | G3: =DATE(LEFT(G2,4),SUBSTITUTE(RIGHT(G2,2),"M",""),1) -> 42856 | H3: =DATE(LEFT(H2,4),SUBSTITUTE(RIGHT(H2,2),"M",""),1) -> 42887 | I3: =DATE(LEFT(I2,4),SUBSTITUTE(RIGHT(I2,2),"M",""),1) -> 42917 | J3: =DATE(LEFT(J2,4),SUBSTITUTE(RIGHT(J2,2),"M",""),1) -> 42948 | ... CT3: =DATE(LEFT(CT2,4),SUBSTITUTE(RIGHT(CT2,2),"M",""),1) -> 45627
B5: 0% growth | C5: ='conditional forecasts_0'!D574 -> -342.90295 | D5: ='conditional forecasts_0'!E574 -> -13.916269 | E5: ='conditional forecasts_0'!F574 -> 249.71177 | F5: ='conditional forecasts_0'!G574 -> 411.19355 | G5: ='conditional forecasts_0'!H574 -> 216.50096 | H5: ='conditional forecasts_0'!I574 -> 167.73819 | I5: ='conditional forecasts_0'!J574 -> 90.03698 | J5: ='conditional forecasts_0'!K574 -> 181.81 | ... CT5: ='conditional forecasts_0'!CU574 -> -488.2577
B6: 2% growth | C6: ='conditional forecasts_2'!D574 -> -309.31443 | D6: ='conditional forecasts_2'!E574 -> 35.61644 | E6: ='conditional forecasts_2'!F574 -> 240.43454 | F6: ='conditional forecasts_2'!G574 -> 389.21585 | G6: ='conditional forecasts_2'!H574 -> 190.52267 | H6: ='conditional forecasts_2'!I574 -> 146.10601 | I6: ='conditional forecasts_2'!J574 -> 82.563628 | J6: ='conditional forecasts_2'!K574 -> 185.56349 | ... CT6: ='conditional forecasts_2'!CU574 -> -430.49428
B7: 4% growth | C7: ='conditional forecasts_4'!D574 -> -276.37816 | D7: ='conditional forecasts_4'!E574 -> 84.187288 | E7: ='conditional forecasts_4'!F574 -> 231.33745 | F7: ='conditional forecasts_4'!G574 -> 367.66493 | G7: ='conditional forecasts_4'!H574 -> 165.04885 | H7: ='conditional forecasts_4'!I574 -> 124.8939 | I7: ='conditional forecasts_4'!J574 -> 75.235399 | J7: ='conditional forecasts_4'!K574 -> 189.24409 | ... CT7: ='conditional forecasts_4'!CU574 -> -373.85255
B8: 6% growth | C8: ='conditional forecasts_6'!D574 -> -244.06928 | D8: ='conditional forecasts_6'!E574 -> 131.83292 | E8: ='conditional forecasts_6'!F574 -> 222.41365 | F8: ='conditional forecasts_6'!G574 -> 346.52453 | G8: ='conditional forecasts_6'!H574 -> 140.06027 | H8: ='conditional forecasts_6'!I574 -> 104.08585 | I8: ='conditional forecasts_6'!J574 -> 68.046764 | J8: ='conditional forecasts_6'!K574 -> 192.85457 | ... CT8: ='conditional forecasts_6'!CU574 -> -318.28977
B9: 8% growth | C9: ='conditional forecasts_8'!D574 -> -212.36434 | D9: ='conditional forecasts_8'!E574 -> 178.58793 | E9: ='conditional forecasts_8'!F574 -> 213.65667 | F9: ='conditional forecasts_8'!G574 -> 325.7793 | G9: ='conditional forecasts_8'!H574 -> 115.53879 | H9: ='conditional forecasts_8'!I574 -> 83.666758 | I9: ='conditional forecasts_8'!J574 -> 60.992504 | J9: ='conditional forecasts_8'!K574 -> 196.39757 | ... CT9: ='conditional forecasts_8'!CU574 -> -263.76561
B10: Actual | C10: -134 | D10: 47 | E10: -135 | F10: 123 | G10: 278 | H10: 701 | I10: -131 | J10: -139 | K10: 58 | L10: 10 | M10: 56 | N10: -141 | O10: 24 | P10: 123 | Q10: -8 | R10: 155 | S10: 421 | T10: 362 | U10: 765 | V10: 119 | W10: -99 | X10: -194 | Y10: -78 | Z10: -244 | AA10: -7 | AB10: 112 | AC10: -170 | AD10: 62 | AE10: 554 | AF10: 468 | AG10: 14 | AH10: 93 | AI10: -83 | AJ10: 50 | AK10: 213 | AL10: -163
B12: =B5 -> 0% growth | C12: =C5 -> -342.90295 | D12: =D5+C12 -> -356.81922 | E12: =E5+D12 -> -107.10745 | F12: =F5+E12 -> 304.08611 | G12: =G5+F12 -> 520.58706 | H12: =H5+G12 -> 688.32525 | I12: =I5+H12 -> 778.36223 | J12: =J5+I12 -> 960.17223 | K12: =K5+J12 -> 1118.6755 | ... CT12: =CT5+CS12 -> 3160.4647
B13: =B6 -> 2% growth | C13: =C6 -> -309.31443 | D13: =D6+C13 -> -273.69799 | E13: =E6+D13 -> -33.263457 | F13: =F6+E13 -> 355.9524 | G13: =G6+F13 -> 546.47507 | H13: =H6+G13 -> 692.58108 | I13: =I6+H13 -> 775.1447 | J13: =J6+I13 -> 960.70819 | K13: =K6+J13 -> 1118.2406 | ... CT13: =CT6+CS13 -> 6084.0089
B14: =B7 -> 4% growth | C14: =C7 -> -276.37816 | D14: =D7+C14 -> -192.19087 | E14: =E7+D14 -> 39.146581 | F14: =F7+E14 -> 406.81151 | G14: =G7+F14 -> 571.86036 | H14: =H7+G14 -> 696.75425 | I14: =I7+H14 -> 771.98965 | J14: =J7+I14 -> 961.23374 | K14: =K7+J14 -> 1117.8141 | ... CT14: =CT7+CS14 -> 8950.7817
B15: =B8 -> 6% growth | C15: =C8 -> -244.06928 | D15: =D8+C15 -> -112.23636 | E15: =E8+D15 -> 110.17729 | F15: =F8+E15 -> 456.70183 | G15: =G8+F15 -> 596.76209 | H15: =H8+G15 -> 700.84794 | I15: =I8+H15 -> 768.8947 | J15: =J8+I15 -> 961.74928 | K15: =K8+J15 -> 1117.3958 | ... CT15: =CT8+CS15 -> 11762.946
B16: =B9 -> 8% growth | C16: =C9 -> -212.36434 | D16: =D9+C16 -> -33.776412 | E16: =E9+D16 -> 179.88025 | F16: =F9+E16 -> 505.65955 | G16: =G9+F16 -> 621.19834 | H16: =H9+G16 -> 704.8651 | I16: =I9+H16 -> 765.85761 | J16: =J9+I16 -> 962.25518 | K16: =K9+J16 -> 1116.9853 | ... CT16: =CT9+CS16 -> 14522.543
B17: 2015-2016 Defict | C17: 2306 | D17: 2306 | E17: 2306 | F17: 2306 | G17: 2306 | H17: 2306 | I17: 2306 | J17: 2306 | K17: 2306 | L17: 2306 | M17: 2306 | N17: 2306 | O17: 2306 | P17: 2306 | Q17: 2306 | R17: 2306 | S17: 2306 | T17: 2306 | U17: 2306 | V17: 2306 | W17: 2306 | X17: 2306 | Y17: 2306 | Z17: 2306 | AA17: 2306 | AB17: 2306 | AC17: 2306 | AD17: 2306 | AE17: 2306 | AF17: 2306 | AG17: 2306 | AH17: 2306 | AI17: 2306 | AJ17: 2306 | AK17: 2306 | AL17: 2306 | AM17: 2306 | AN17: 2306 | AO17: 2306 | AP17: 2306 | AQ17: 2306 | AR17: 2306 | AS17: 2306 | AT17: 2306 | AU17: 2306 | AV17: 2306 | AW17: 2306 | AX17: 2306 | AY17: 2306 | AZ17: 2306 | BA17: 2306 | BB17: 2306 | BC17: 2306 | BD17: 2306 | BE17: 2306 | BF17: 2306 | BG17: 2306 | BH17: 2306 | BI17: 2306 | BJ17: 2306 | BK17: 2306 | BL17: 2306 | BM17: 2306 | BN17: 2306 | BO17: 2306 | BP17: 2306 | BQ17: 2306 | BR17: 2306 | BS17: 2306 | BT17: 2306 | BU17: 2306 | BV17: 2306 | BW17: 2306 | BX17: 2306 | BY17: 2306 | BZ17: 2306 | CA17: 2306 | CB17: 2306 | CC17: 2306 | CD17: 2306 | CE17: 2306 | CF17: 2306 | CG17: 2306 | CH17: 2306 | CI17: 2306 | CJ17: 2306 | CK17: 2306 | CL17: 2306 | CM17: 2306 | CN17: 2306 | CO17: 2306 | CP17: 2306 | CQ17: 2306 | CR17: 2306 | CS17: 2306 | CT17: 2306
B18: Actual | C18: =C10 -> -134 | D18: =C18+D10 -> -87 | E18: =D18+E10 -> -222 | F18: =E18+F10 -> -99 | G18: =F18+G10 -> 179 | H18: =G18+H10 -> 880 | I18: =H18+I10 -> 749 | J18: =I18+J10 -> 610 | K18: =J18+K10 -> 668 | ... AL18: =AK18+AL10 -> 3082

Sheet Borbo_2502
C2: 2017M1 | D2: 2017M2 | E2: 2017M3 | F2: 2017M4 | G2: 2017M5 | H2: 2017M6 | I2: 2017M7 | J2: 2017M8 | K2: 2017M9 | L2: 2017M10 | M2: 2017M11 | N2: 2017M12 | O2: 2018M1 | P2: 2018M2 | Q2: 2018M3 | R2: 2018M4 | S2: 2018M5 | T2: 2018M6 | U2: 2018M7 | V2: 2018M8 | W2: 2018M9 | X2: 2018M10 | Y2: 2018M11 | Z2: 2018M12 | AA2: 2019M1 | AB2: 2019M2 | AC2: 2019M3 | AD2: 2019M4 | AE2: 2019M5 | AF2: 2019M6 | AG2: 2019M7 | AH2: 2019M8 | AI2: 2019M9 | AJ2: 2019M10 | AK2: 2019M11 | AL2: 2019M12 | AM2: 2020M1 | AN2: 2020M2 | AO2: 2020M3 | AP2: 2020M4 | AQ2: 2020M5 | AR2: 2020M6 | AS2: 2020M7 | AT2: 2020M8 | AU2: 2020M9 | AV2: 2020M10 | AW2: 2020M11 | AX2: 2020M12 | AY2: 2021M1 | AZ2: 2021M2 | BA2: 2021M3 | BB2: 2021M4 | BC2: 2021M5 | BD2: 2021M6 | BE2: 2021M7 | BF2: 2021M8 | BG2: 2021M9 | BH2: 2021M10 | BI2: 2021M11 | BJ2: 2021M12 | BK2: 2022M1 | BL2: 2022M2 | BM2: 2022M3 | BN2: 2022M4 | BO2: 2022M5 | BP2: 2022M6 | BQ2: 2022M7 | BR2: 2022M8 | BS2: 2022M9 | BT2: 2022M10 | BU2: 2022M11 | BV2: 2022M12 | BW2: 2023M1 | BX2: 2023M2 | BY2: 2023M3 | BZ2: 2023M4 | CA2: 2023M5 | CB2: 2023M6 | CC2: 2023M7 | CD2: 2023M8 | CE2: 2023M9 | CF2: 2023M10 | CG2: 2023M11 | CH2: 2023M12 | CI2: 2024M1 | CJ2: 2024M2 | CK2: 2024M3 | CL2: 2024M4 | CM2: 2024M5 | CN2: 2024M6 | CO2: 2024M7 | CP2: 2024M8 | CQ2: 2024M9 | CR2: 2024M10 | CS2: 2024M11 | CT2: 2024M12
C3: =DATE(LEFT(C2,4),SUBSTITUTE(RIGHT(C2,2),"M",""),1) -> 42736 | D3: =DATE(LEFT(D2,4),SUBSTITUTE(RIGHT(D2,2),"M",""),1) -> 42767 | E3: =DATE(LEFT(E2,4),SUBSTITUTE(RIGHT(E2,2),"M",""),1) -> 42795 | F3: =DATE(LEFT(F2,4),SUBSTITUTE(RIGHT(F2,2),"M",""),1) -> 42826 | G3: =DATE(LEFT(G2,4),SUBSTITUTE(RIGHT(G2,2),"M",""),1) -> 42856 | H3: =DATE(LEFT(H2,4),SUBSTITUTE(RIGHT(H2,2),"M",""),1) -> 42887 | I3: =DATE(LEFT(I2,4),SUBSTITUTE(RIGHT(I2,2),"M",""),1) -> 42917 | J3: =DATE(LEFT(J2,4),SUBSTITUTE(RIGHT(J2,2),"M",""),1) -> 42948 | ... CT3: =DATE(LEFT(CT2,4),SUBSTITUTE(RIGHT(CT2,2),"M",""),1) -> 45627
B5: 0% growth | C5: ='conditional forecasts_0'!D573 -> -24.363005 | D5: ='conditional forecasts_0'!E573 -> -22.181569 | E5: ='conditional forecasts_0'!F573 -> -11.24654 | F5: ='conditional forecasts_0'!G573 -> -18.86656 | G5: ='conditional forecasts_0'!H573 -> -12.20695 | H5: ='conditional forecasts_0'!I573 -> -5.5548036 | I5: ='conditional forecasts_0'!J573 -> -3.8178921 | J5: ='conditional forecasts_0'!K573 -> 3.7172066 | ... CT5: ='conditional forecasts_0'!CU573 -> -22.51416
B6: 2% growth | C6: ='conditional forecasts_2'!D573 -> -17.661865 | D6: ='conditional forecasts_2'!E573 -> -18.012832 | E6: ='conditional forecasts_2'!F573 -> -7.7100332 | F6: ='conditional forecasts_2'!G573 -> -14.44104 | G6: ='conditional forecasts_2'!H573 -> -7.9153311 | H6: ='conditional forecasts_2'!I573 -> -1.3866979 | I6: ='conditional forecasts_2'!J573 -> 0.37431152 | J6: ='conditional forecasts_2'!K573 -> 7.8953357 | ... CT6: ='conditional forecasts_2'!CU573 -> -3.7805606
B7: 4% growth | C7: ='conditional forecasts_4'!D573 -> -11.090852 | D7: ='conditional forecasts_4'!E573 -> -13.925046 | E7: ='conditional forecasts_4'!F573 -> -4.2422004 | F7: ='conditional forecasts_4'!G573 -> -10.101457 | G7: ='conditional forecasts_4'!H573 -> -3.7070497 | H7: ='conditional forecasts_4'!I573 -> 2.7004687 | I7: ='conditional forecasts_4'!J573 -> 4.4851079 | J7: ='conditional forecasts_4'!K573 -> 11.992331 | ... CT7: ='conditional forecasts_4'!CU573 -> 14.589256
B8: 6% growth | C8: ='conditional forecasts_6'!D573 -> -4.6450091 | D8: ='conditional forecasts_6'!E573 -> -9.9151279 | E8: ='conditional forecasts_6'!F573 -> -0.84042566 | F8: ='conditional forecasts_6'!G573 -> -5.844539 | G8: ='conditional forecasts_6'!H573 -> 0.42106896 | H8: ='conditional forecasts_6'!I573 -> 6.7097796 | I8: ='conditional forecasts_6'!J573 -> 8.5175987 | J8: ='conditional forecasts_6'!K573 -> 16.011283 | ... CT8: ='conditional forecasts_6'!CU573 -> 32.609151
B9: 8% growth | C9: ='conditional forecasts_8'!D573 -> 1.6803439 | D9: ='conditional forecasts_8'!E573 -> -5.9801656 | E9: ='conditional forecasts_8'!F573 -> 2.4977608 | F9: ='conditional forecasts_8'!G573 -> -1.6671938 | G9: ='conditional forecasts_8'!H573 -> 4.472022 | H9: ='conditional forecasts_8'!I573 -> 10.644146 | I9: ='conditional forecasts_8'!J573 -> 12.474711 | J9: ='conditional forecasts_8'!K573 -> 19.955111 | ... CT9: ='conditional forecasts_8'!CU573 -> 50.292205
B10: Actual | C10: 23 | D10: 80 | E10: 31 | F10: 53 | G10: 3 | H10: 34 | I10: -36 | J10: -12 | K10: -34 | L10: 4 | M10: -55 | N10: -38 | O10: 46 | P10: -3 | Q10: 20 | R10: 39 | S10: 72 | T10: 23 | U10: -28 | V10: 12 | W10: 43 | X10: -33 | Y10: -108 | Z10: -60 | AA10: 26 | AB10: 32 | AC10: -10 | AD10: 27 | AE10: 9 | AF10: 14 | AG10: 50 | AH10: 41 | AI10: 13 | AJ10: 46 | AK10: 15 | AL10: -36
B12: =B5 -> 0% growth | C12: =C5 -> -24.363005 | D12: =D5+C12 -> -46.544575 | E12: =E5+D12 -> -57.791115 | F12: =F5+E12 -> -76.657675 | G12: =G5+F12 -> -88.864625 | H12: =H5+G12 -> -94.419428 | I12: =I5+H12 -> -98.23732 | J12: =J5+I12 -> -94.520114 | K12: =K5+J12 -> -92.597716 | ... CT12: =CT5+CS12 -> -634.84231
B13: =B6 -> 2% growth | C13: =C6 -> -17.661865 | D13: =D6+C13 -> -35.674697 | E13: =E6+D13 -> -43.38473 | F13: =F6+E13 -> -57.82577 | G13: =G6+F13 -> -65.741101 | H13: =H6+G13 -> -67.127799 | I13: =I6+H13 -> -66.753487 | J13: =J6+I13 -> -58.858152 | K13: =K6+J13 -> -52.470903 | ... CT13: =CT6+CS13 -> 664.22288
B14: =B7 -> 4% growth | C14: =C7 -> -11.090852 | D14: =D7+C14 -> -25.015898 | E14: =E7+D14 -> -29.258099 | F14: =F7+E14 -> -39.359556 | G14: =G7+F14 -> -43.066606 | H14: =H7+G14 -> -40.366137 | I14: =I7+H14 -> -35.881029 | J14: =J7+I14 -> -23.888699 | K14: =K7+J14 -> -13.123301 | ... CT14: =CT7+CS14 -> 1938.0619
B15: =B8 -> 6% growth | C15: =C8 -> -4.6450091 | D15: =D8+C15 -> -14.560137 | E15: =E8+D15 -> -15.400563 | F15: =F8+E15 -> -21.245102 | G15: =G8+F15 -> -20.824033 | H15: =H8+G15 -> -14.114253 | I15: =I8+H15 -> -5.5966543 | J15: =J8+I15 -> 10.414629 | K15: =K8+J15 -> 25.474777 | ... CT15: =CT8+CS15 -> 3187.6359
B16: =B9 -> 8% growth | C16: =C9 -> 1.6803439 | D16: =D9+C16 -> -4.2998217 | E16: =E9+D16 -> -1.8020609 | F16: =F9+E16 -> -3.4692547 | G16: =G9+F16 -> 1.0027673 | H16: =H9+G16 -> 11.646913 | I16: =I9+H16 -> 24.121624 | J16: =J9+I16 -> 44.076735 | K16: =K9+J16 -> 63.351353 | ... CT16: =CT9+CS16 -> 4413.8519
B17: 2015-2016 Defict | C17: 726 | D17: 726 | E17: 726 | F17: 726 | G17: 726 | H17: 726 | I17: 726 | J17: 726 | K17: 726 | L17: 726 | M17: 726 | N17: 726 | O17: 726 | P17: 726 | Q17: 726 | R17: 726 | S17: 726 | T17: 726 | U17: 726 | V17: 726 | W17: 726 | X17: 726 | Y17: 726 | Z17: 726 | AA17: 726 | AB17: 726 | AC17: 726 | AD17: 726 | AE17: 726 | AF17: 726 | AG17: 726 | AH17: 726 | AI17: 726 | AJ17: 726 | AK17: 726 | AL17: 726 | AM17: 726 | AN17: 726 | AO17: 726 | AP17: 726 | AQ17: 726 | AR17: 726 | AS17: 726 | AT17: 726 | AU17: 726 | AV17: 726 | AW17: 726 | AX17: 726 | AY17: 726 | AZ17: 726 | BA17: 726 | BB17: 726 | BC17: 726 | BD17: 726 | BE17: 726 | BF17: 726 | BG17: 726 | BH17: 726 | BI17: 726 | BJ17: 726 | BK17: 726 | BL17: 726 | BM17: 726 | BN17: 726 | BO17: 726 | BP17: 726 | BQ17: 726 | BR17: 726 | BS17: 726 | BT17: 726 | BU17: 726 | BV17: 726 | BW17: 726 | BX17: 726 | BY17: 726 | BZ17: 726 | CA17: 726 | CB17: 726 | CC17: 726 | CD17: 726 | CE17: 726 | CF17: 726 | CG17: 726 | CH17: 726 | CI17: 726 | CJ17: 726 | CK17: 726 | CL17: 726 | CM17: 726 | CN17: 726 | CO17: 726 | CP17: 726 | CQ17: 726 | CR17: 726 | CS17: 726 | CT17: 726
B18: Actual | C18: =C10 -> 23 | D18: =D10+C18 -> 103 | E18: =E10+D18 -> 134 | F18: =F10+E18 -> 187 | G18: =G10+F18 -> 190 | H18: =H10+G18 -> 224 | I18: =I10+H18 -> 188 | J18: =J10+I18 -> 176 | K18: =K10+J18 -> 142 | ... AL18: =AL10+AK18 -> 303

Sheet C.Goia_5203
C2: 2017M1 | D2: 2017M2 | E2: 2017M3 | F2: 2017M4 | G2: 2017M5 | H2: 2017M6 | I2: 2017M7 | J2: 2017M8 | K2: 2017M9 | L2: 2017M10 | M2: 2017M11 | N2: 2017M12 | O2: 2018M1 | P2: 2018M2 | Q2: 2018M3 | R2: 2018M4 | S2: 2018M5 | T2: 2018M6 | U2: 2018M7 | V2: 2018M8 | W2: 2018M9 | X2: 2018M10 | Y2: 2018M11 | Z2: 2018M12 | AA2: 2019M1 | AB2: 2019M2 | AC2: 2019M3 | AD2: 2019M4 | AE2: 2019M5 | AF2: 2019M6 | AG2: 2019M7 | AH2: 2019M8 | AI2: 2019M9 | AJ2: 2019M10 | AK2: 2019M11 | AL2: 2019M12 | AM2: 2020M1 | AN2: 2020M2 | AO2: 2020M3 | AP2: 2020M4 | AQ2: 2020M5 | AR2: 2020M6 | AS2: 2020M7 | AT2: 2020M8 | AU2: 2020M9 | AV2: 2020M10 | AW2: 2020M11 | AX2: 2020M12 | AY2: 2021M1 | AZ2: 2021M2 | BA2: 2021M3 | BB2: 2021M4 | BC2: 2021M5 | BD2: 2021M6 | BE2: 2021M7 | BF2: 2021M8 | BG2: 2021M9 | BH2: 2021M10 | BI2: 2021M11 | BJ2: 2021M12 | BK2: 2022M1 | BL2: 2022M2 | BM2: 2022M3 | BN2: 2022M4 | BO2: 2022M5 | BP2: 2022M6 | BQ2: 2022M7 | BR2: 2022M8 | BS2: 2022M9 | BT2: 2022M10 | BU2: 2022M11 | BV2: 2022M12 | BW2: 2023M1 | BX2: 2023M2 | BY2: 2023M3 | BZ2: 2023M4 | CA2: 2023M5 | CB2: 2023M6 | CC2: 2023M7 | CD2: 2023M8 | CE2: 2023M9 | CF2: 2023M10 | CG2: 2023M11 | CH2: 2023M12 | CI2: 2024M1 | CJ2: 2024M2 | CK2: 2024M3 | CL2: 2024M4 | CM2: 2024M5 | CN2: 2024M6 | CO2: 2024M7 | CP2: 2024M8 | CQ2: 2024M9 | CR2: 2024M10 | CS2: 2024M11 | CT2: 2024M12
C3: =DATE(LEFT(C2,4),SUBSTITUTE(RIGHT(C2,2),"M",""),1) -> 42736 | D3: =DATE(LEFT(D2,4),SUBSTITUTE(RIGHT(D2,2),"M",""),1) -> 42767 | E3: =DATE(LEFT(E2,4),SUBSTITUTE(RIGHT(E2,2),"M",""),1) -> 42795 | F3: =DATE(LEFT(F2,4),SUBSTITUTE(RIGHT(F2,2),"M",""),1) -> 42826 | G3: =DATE(LEFT(G2,4),SUBSTITUTE(RIGHT(G2,2),"M",""),1) -> 42856 | H3: =DATE(LEFT(H2,4),SUBSTITUTE(RIGHT(H2,2),"M",""),1) -> 42887 | I3: =DATE(LEFT(I2,4),SUBSTITUTE(RIGHT(I2,2),"M",""),1) -> 42917 | J3: =DATE(LEFT(J2,4),SUBSTITUTE(RIGHT(J2,2),"M",""),1) -> 42948 | ... CT3: =DATE(LEFT(CT2,4),SUBSTITUTE(RIGHT(CT2,2),"M",""),1) -> 45627
B5: 0% growth | C5: ='conditional forecasts_0'!D572 -> -526.91644 | D5: ='conditional forecasts_0'!E572 -> 1966.1141 | E5: ='conditional forecasts_0'!F572 -> 4441.7322 | F5: ='conditional forecasts_0'!G572 -> 5997.952 | G5: ='conditional forecasts_0'!H572 -> 2964.9584 | H5: ='conditional forecasts_0'!I572 -> 5388.5527 | I5: ='conditional forecasts_0'!J572 -> 1272.8121 | J5: ='conditional forecasts_0'!K572 -> 370.96219 | ... CT5: ='conditional forecasts_0'!CU572 -> -3437.7673
B6: 2% growth | C6: ='conditional forecasts_2'!D572 -> 291.54526 | D6: ='conditional forecasts_2'!E572 -> 2400.2094 | E6: ='conditional forecasts_2'!F572 -> 4424.0003 | F6: ='conditional forecasts_2'!G572 -> 6101.2323 | G6: ='conditional forecasts_2'!H572 -> 2908.8202 | H6: ='conditional forecasts_2'!I572 -> 5394.1672 | I6: ='conditional forecasts_2'!J572 -> 1283.018 | J6: ='conditional forecasts_2'!K572 -> 455.91315 | ... CT6: ='conditional forecasts_2'!CU572 -> -3089.1226
B7: 4% growth | C7: ='conditional forecasts_4'!D572 -> 1094.1135 | D7: ='conditional forecasts_4'!E572 -> 2825.8752 | E7: ='conditional forecasts_4'!F572 -> 4406.6128 | F7: ='conditional forecasts_4'!G572 -> 6202.5069 | G7: ='conditional forecasts_4'!H572 -> 2853.7722 | H7: ='conditional forecasts_4'!I572 -> 5399.6727 | I7: ='conditional forecasts_4'!J572 -> 1293.0257 | J7: ='conditional forecasts_4'!K572 -> 539.21448 | ... CT7: ='conditional forecasts_4'!CU572 -> -2747.2482
B8: 6% growth | C8: ='conditional forecasts_6'!D572 -> 1881.3938 | D8: ='conditional forecasts_6'!E572 -> 3243.4326 | E8: ='conditional forecasts_6'!F572 -> 4389.5565 | F8: ='conditional forecasts_6'!G572 -> 6301.8524 | G8: ='conditional forecasts_6'!H572 -> 2799.7728 | H8: ='conditional forecasts_6'!I572 -> 5405.0733 | I8: ='conditional forecasts_6'!J572 -> 1302.8428 | J8: ='conditional forecasts_6'!K572 -> 620.92901 | ... CT8: ='conditional forecasts_6'!CU572 -> -2411.886
