Workbook

Sheet SP
C2: 2017M1 | D2: 2017M2 | E2: 2017M3 | F2: 2017M4 | G2: 2017M5 | H2: 2017M6 | I2: 2017M7 | J2: 2017M8 | K2: 2017M9 | L2: 2017M10 | M2: 2017M11 | N2: 2017M12 | O2: 2018M1 | P2: 2018M2 | Q2: 2018M3 | R2: 2018M4 | S2: 2018M5 | T2: 2018M6 | U2: 2018M7 | V2: 2018M8 | W2: 2018M9 | X2: 2018M10 | Y2: 2018M11 | Z2: 2018M12 | AA2: 2019M1 | AB2: 2019M2 | AC2: 2019M3 | AD2: 2019M4 | AE2: 2019M5 | AF2: 2019M6 | AG2: 2019M7 | AH2: 2019M8 | AI2: 2019M9 | AJ2: 2019M10 | AK2: 2019M11 | AL2: 2019M12 | AM2: 2020M1 | AN2: 2020M2 | AO2: 2020M3 | AP2: 2020M4 | AQ2: 2020M5 | AR2: 2020M6 | AS2: 2020M7 | AT2: 2020M8 | AU2: 2020M9 | AV2: 2020M10 | AW2: 2020M11 | AX2: 2020M12 | AY2: 2021M1 | AZ2: 2021M2 | BA2: 2021M3 | BB2: 2021M4 | BC2: 2021M5 | BD2: 2021M6 | BE2: 2021M7 | BF2: 2021M8 | BG2: 2021M9 | BH2: 2021M10 | BI2: 2021M11 | BJ2: 2021M12 | BK2: 2022M1 | BL2: 2022M2 | BM2: 2022M3 | BN2: 2022M4 | BO2: 2022M5 | BP2: 2022M6 | BQ2: 2022M7 | BR2: 2022M8 | BS2: 2022M9 | BT2: 2022M10 | BU2: 2022M11 | BV2: 2022M12 | BW2: 2023M1 | BX2: 2023M2 | BY2: 2023M3 | BZ2: 2023M4 | CA2: 2023M5 | CB2: 2023M6 | CC2: 2023M7 | CD2: 2023M8 | CE2: 2023M9 | CF2: 2023M10 | CG2: 2023M11 | CH2: 2023M12 | CI2: 2024M1 | CJ2: 2024M2 | CK2: 2024M3 | CL2: 2024M4 | CM2: 2024M5 | CN2: 2024M6 | CO2: 2024M7 | CP2: 2024M8 | CQ2: 2024M9 | CR2: 2024M10 | CS2: 2024M11 | CT2: 2024M12
C3: =DATE(LEFT(C2,4),SUBSTITUTE(RIGHT(C2,2),"M",""),1) -> 42736 | D3: =DATE(LEFT(D2,4),SUBSTITUTE(RIGHT(D2,2),"M",""),1) -> 42767 | E3: =DATE(LEFT(E2,4),SUBSTITUTE(RIGHT(E2,2),"M",""),1) -> 42795 | F3: =DATE(LEFT(F2,4),SUBSTITUTE(RIGHT(F2,2),"M",""),1) -> 42826 | G3: =DATE(LEFT(G2,4),SUBSTITUTE(RIGHT(G2,2),"M",""),1) -> 42856 | H3: =DATE(LEFT(H2,4),SUBSTITUTE(RIGHT(H2,2),"M",""),1) -> 42887 | I3: =DATE(LEFT(I2,4),SUBSTITUTE(RIGHT(I2,2),"M",""),1) -> 42917 | J3: =DATE(LEFT(J2,4),SUBSTITUTE(RIGHT(J2,2),"M",""),1) -> 42948 | ... CT3: =DATE(LEFT(CT2,4),SUBSTITUTE(RIGHT(CT2,2),"M",""),1) -> 45627
B5: 0% growth | C5: ='conditional forecasts_0'!D575 -> -67833.339 | D5: ='conditional forecasts_0'!E575 -> -18541.729 | E5: ='conditional forecasts_0'!F575 -> 5451.6085 | F5: ='conditional forecasts_0'!G575 -> 33581.322 | G5: ='conditional forecasts_0'!H575 -> 5449.3874 | H5: ='conditional forecasts_0'!I575 -> 66184.701 | I5: ='conditional forecasts_0'!J575 -> 24349.053 | J5: ='conditional forecasts_0'!K575 -> -833.4728 | ... CT5: ='conditional forecasts_0'!CU575 -> -40252.752
B6: 2% growth | C6: ='conditional forecasts_2'!D575 -> -55573.065 | D6: ='conditional forecasts_2'!E575 -> -13308.212 | E6: ='conditional forecasts_2'!F575 -> 7609.8016 | F6: ='conditional forecasts_2'!G575 -> 38002.47 | G6: ='conditional forecasts_2'!H575 -> 7281.0783 | H6: ='conditional forecasts_2'!I575 -> 68876.896 | I6: ='conditional forecasts_2'!J575 -> 26183 | J6: ='conditional forecasts_2'!K575 -> 742.03229 | ... CT6: ='conditional forecasts_2'!CU575 -> -45347.214
B7: 4% growth | C7: ='conditional forecasts_4'!D575 -> -43550.87 | D7: ='conditional forecasts_4'!E575 -> -8176.3236 | E7: ='conditional forecasts_4'!F575 -> 9726.0853 | F7: ='conditional forecasts_4'!G575 -> 42337.765 | G7: ='conditional forecasts_4'!H575 -> 9077.2002 | H7: ='conditional forecasts_4'!I575 -> 71516.811 | I7: ='conditional forecasts_4'!J575 -> 27981.334 | J7: ='conditional forecasts_4'!K575 -> 2286.9431 | ... CT7: ='conditional forecasts_4'!CU575 -> -50342.748
B8: 6% growth | C8: ='conditional forecasts_6'!D575 -> -31757.683 | D8: ='conditional forecasts_6'!E575 -> -3142.191 | E8: ='conditional forecasts_6'!F575 -> 11802.056 | F8: ='conditional forecasts_6'!G575 -> 46590.478 | G8: ='conditional forecasts_6'!H575 -> 10839.108 | H8: ='conditional forecasts_6'!I575 -> 74106.44 | I8: ='conditional forecasts_6'!J575 -> 29745.412 | J8: ='conditional forecasts_6'!K575 -> 3802.4252 | ... CT8: ='conditional forecasts_6'!CU575 -> -55243.124
B9: 8% growth | C9: ='conditional forecasts_8'!D575 -> -20184.943 | D9: ='conditional forecasts_8'!E575 -> 1797.8401 | E9: ='conditional forecasts_8'!F575 -> 13839.222 | F9: ='conditional forecasts_8'!G575 -> 50763.696 | G9: ='conditional forecasts_8'!H575 -> 12568.081 | H9: ='conditional forecasts_8'!I575 -> 76647.661 | I9: ='conditional forecasts_8'!J575 -> 31476.515 | J9: ='conditional forecasts_8'!K575 -> 5289.579 | ... CT9: ='conditional forecasts_8'!CU575 -> -60051.898
B10: Actual | C10: -4457 | D10: 25412 | E10: -9646 | F10: 30227 | G10: 17226 | H10: 983 | I10: 21805 | J10: 17320 | K10: -251 | L10: 11349 | M10: -17611 | N10: -116391 | O10: 20278 | P10: 30040 | Q10: 30459 | R10: 44426 | S10: 9155 | T10: -4450 | U10: 15333 | V10: 34244 | W10: 22448 | X10: 13088 | Y10: 17754 | Z10: -110263 | AA10: 14638 | AB10: 62339 | AC10: -8007 | AD10: 50168 | AE10: 6023 | AF10: 18262 | AG10: 20204 | AH10: 33298 | AI10: 36156 | AJ10: 11727 | AK10: 23140 | AL10: -105309
B12: =B5 -> 0% growth | C12: =C5 -> -67833.339 | D12: =D5+C12 -> -86375.068 | E12: =E5+D12 -> -80923.46 | F12: =F5+E12 -> -47342.138 | G12: =G5+F12 -> -41892.75 | H12: =H5+G12 -> 24291.951 | I12: =I5+H12 -> 48641.003 | J12: =J5+I12 -> 47807.531 | K12: =K5+J12 -> 64289.801 | ... CT12: =CT5+CS12 -> 449068.36
B13: =B6 -> 2% growth | C13: =C6 -> -55573.065 | D13: =D6+C13 -> -68881.278 | E13: =E6+D13 -> -61271.476 | F13: =F6+E13 -> -23269.006 | G13: =G6+F13 -> -15987.928 | H13: =H6+G13 -> 52888.968 | I13: =I6+H13 -> 79071.968 | J13: =J6+I13 -> 79814 | K13: =K6+J13 -> 102482.08 | ... CT13: =CT6+CS13 -> 1085031.2
B14: =B7 -> 4% growth | C14: =C7 -> -43550.87 | D14: =D7+C14 -> -51727.194 | E14: =E7+D14 -> -42001.108 | F14: =F7+E14 -> 336.65621 | G14: =G7+F14 -> 9413.8564 | H14: =H7+G14 -> 80930.668 | I14: =I7+H14 -> 108912 | J14: =J7+I14 -> 111198.94 | K14: =K7+J14 -> 139932.71 | ... CT14: =CT7+CS14 -> 1708644.5
B15: =B8 -> 6% growth | C15: =C8 -> -31757.683 | D15: =D8+C15 -> -34899.874 | E15: =E8+D15 -> -23097.818 | F15: =F8+E15 -> 23492.66 | G15: =G8+F15 -> 34331.768 | H15: =H8+G15 -> 108438.21 | I15: =I8+H15 -> 138183.62 | J15: =J8+I15 -> 141986.05 | K15: =K8+J15 -> 176669.95 | ... CT15: =CT8+CS15 -> 2320378.7
B16: =B9 -> 8% growth | C16: =C9 -> -20184.943 | D16: =D9+C16 -> -18387.103 | E16: =E9+D16 -> -4547.8807 | F16: =F9+E16 -> 46215.815 | G16: =G9+F16 -> 58783.896 | H16: =H9+G16 -> 135431.56 | I16: =I9+H16 -> 166908.07 | J16: =J9+I16 -> 172197.65 | K16: =K9+J16 -> 212720.48 | ... CT16: =CT9+CS16 -> 2920677.9
B17: 2015-2016 Defict | C17: 879508 | D17: 879508 | E17: 879508 | F17: 879508 | G17: 879508 | H17: 879508 | I17: 879508 | J17: 879508 | K17: 879508 | L17: 879508 | M17: 879508 | N17: 879508 | O17: 879508 | P17: 879508 | Q17: 879508 | R17: 879508 | S17: 879508 | T17: 879508 | U17: 879508 | V17: 879508 | W17: 879508 | X17: 879508 | Y17: 879508 | Z17: 879508 | AA17: 879508 | AB17: 879508 | AC17: 879508 | AD17: 879508 | AE17: 879508 | AF17: 879508 | AG17: 879508 | AH17: 879508 | AI17: 879508 | AJ17: 879508 | AK17: 879508 | AL17: 879508 | AM17: 879508 | AN17: 879508 | AO17: 879508 | AP17: 879508 | AQ17: 879508 | AR17: 879508 | AS17: 879508 | AT17: 879508 | AU17: 879508 | AV17: 879508 | AW17: 879508 | AX17: 879508 | AY17: 879508 | AZ17: 879508 | BA17: 879508 | BB17: 879508 | BC17: 879508 | BD17: 879508 | BE17: 879508 | BF17: 879508 | BG17: 879508 | BH17: 879508 | BI17: 879508 | BJ17: 879508 | BK17: 879508 | BL17: 879508 | BM17: 879508 | BN17: 879508 | BO17: 879508 | BP17: 879508 | BQ17: 879508 | BR17: 879508 | BS17: 879508 | BT17: 879508 | BU17: 879508 | BV17: 879508 | BW17: 879508 | BX17: 879508 | BY17: 879508 | BZ17: 879508 | CA17: 879508 | CB17: 879508 | CC17: 879508 | CD17: 879508 | CE17: 879508 | CF17: 879508 | CG17: 879508 | CH17: 879508 | CI17: 879508 | CJ17: 879508 | CK17: 879508 | CL17: 879508 | CM17: 879508 | CN17: 879508 | CO17: 879508 | CP17: 879508 | CQ17: 879508 | CR17: 879508 | CS17: 879508 | CT17: 879508
B18: Actual | C18: =C10 -> -4457 | D18: =D10+C18 -> 20955 | E18: =E10+D18 -> 11309 | F18: =F10+E18 -> 41536 | G18: =G10+F18 -> 58762 | H18: =H10+G18 -> 59745 | I18: =I10+H18 -> 81550 | J18: =J10+I18 -> 98870 | K18: =K10+J18 -> 98619 | ... AL18: =AL10+AK18 -> 261117

Sheet RJ
C2: 2017M1 | D2: 2017M2 | E2: 2017M3 | F2: 2017M4 | G2: 2017M5 | H2: 2017M6 | I2: 2017M7 | J2: 2017M8 | K2: 2017M9 | L2: 2017M10 | M2: 2017M11 | N2: 2017M12 | O2: 2018M1 | P2: 2018M2 | Q2: 2018M3 | R2: 2018M4 | S2: 2018M5 | T2: 2018M6 | U2: 2018M7 | V2: 2018M8 | W2: 2018M9 | X2: 2018M10 | Y2: 2018M11 | Z2: 2018M12 | AA2: 2019M1 | AB2: 2019M2 | AC2: 2019M3 | AD2: 2019M4 | AE2: 2019M5 | AF2: 2019M6 | AG2: 2019M7 | AH2: 2019M8 | AI2: 2019M9 | AJ2: 2019M10 | AK2: 2019M11 | AL2: 2019M12 | AM2: 2020M1 | AN2: 2020M2 | AO2: 2020M3 | AP2: 2020M4 | AQ2: 2020M5 | AR2: 2020M6 | AS2: 2020M7 | AT2: 2020M8 | AU2: 2020M9 | AV2: 2020M10 | AW2: 2020M11 | AX2: 2020M12 | AY2: 2021M1 | AZ2: 2021M2 | BA2: 2021M3 | BB2: 2021M4 | BC2: 2021M5 | BD2: 2021M6 | BE2: 2021M7 | BF2: 2021M8 | BG2: 2021M9 | BH2: 2021M10 | BI2: 2021M11 | BJ2: 2021M12 | BK2: 2022M1 | BL2: 2022M2 | BM2: 2022M3 | BN2: 2022M4 | BO2: 2022M5 | BP2: 2022M6 | BQ2: 2022M7 | BR2: 2022M8 | BS2: 2022M9 | BT2: 2022M10 | BU2: 2022M11 | BV2: 2022M12 | BW2: 2023M1 | BX2: 2023M2 | BY2: 2023M3 | BZ2: 2023M4 | CA2: 2023M5 | CB2: 2023M6 | CC2: 2023M7 | CD2: 2023M8 | CE2: 2023M9 | CF2: 2023M10 | CG2: 2023M11 | CH2: 2023M12 | CI2: 2024M1 | CJ2: 2024M2 | CK2: 2024M3 | CL2: 2024M4 | CM2: 2024M5 | CN2: 2024M6 | CO2: 2024M7 | CP2: 2024M8 | CQ2: 2024M9 | CR2: 2024M10 | CS2: 2024M11 | CT2: 2024M12
C3: =DATE(LEFT(C2,4),SUBSTITUTE(RIGHT(C2,2),"M",""),1) -> 42736 | D3: =DATE(LEFT(D2,4),SUBSTITUTE(RIGHT(D2,2),"M",""),1) -> 42767 | E3: =DATE(LEFT(E2,4),SUBSTITUTE(RIGHT(E2,2),"M",""),1) -> 42795 | F3: =DATE(LEFT(F2,4),SUBSTITUTE(RIGHT(F2,2),"M",""),1) -> 42826 | G3: =DATE(LEFT(G2,4),SUBSTITUTE(RIGHT(G2,2),"M",""),1) -> 42856 | H3: =DATE(LEFT(H2,4),SUBSTITUTE(RIGHT(H2,2),"M",""),1) -> 42887 | I3: =DATE(LEFT(I2,4),SUBSTITUTE(RIGHT(I2,2),"M",""),1) -> 42917 | J3: =DATE(LEFT(J2,4),SUBSTITUTE(RIGHT(J2,2),"M",""),1) -> 42948 | ... CT3: =DATE(LEFT(CT2,4),SUBSTITUTE(RIGHT(CT2,2),"M",""),1) -> 45627
B5: 0% growth | C5: ='conditional forecasts_0'!D574 -> -34968.777 | D5: ='conditional forecasts_0'!E574 -> -22043.571 | E5: ='conditional forecasts_0'!F574 -> -17881.621 | F5: ='conditional forecasts_0'!G574 -> -7167.2329 | G5: ='conditional forecasts_0'!H574 -> -9558.4697 | H5: ='conditional forecasts_0'!I574 -> -1060.6469 | I5: ='conditional forecasts_0'!J574 -> -572.4727 | J5: ='conditional forecasts_0'!K574 -> -5547.2317 | ... CT5: ='conditional forecasts_0'!CU574 -> -7621.8939
B6: 2% growth | C6: ='conditional forecasts_2'!D574 -> -33823.138 | D6: ='conditional forecasts_2'!E574 -> -19721.297 | E6: ='conditional forecasts_2'!F574 -> -16253.419 | F6: ='conditional forecasts_2'!G574 -> -5352.2728 | G6: ='conditional forecasts_2'!H574 -> -7811.1965 | H6: ='conditional forecasts_2'!I574 -> 669.67598 | I6: ='conditional forecasts_2'!J574 -> 1112.3261 | J6: ='conditional forecasts_2'!K574 -> -4072.8032 | ... CT6: ='conditional forecasts_2'!CU574 -> -1817.1133
B7: 4% growth | C7: ='conditional forecasts_4'!D574 -> -32699.746 | D7: ='conditional forecasts_4'!E574 -> -17444.119 | E7: ='conditional forecasts_4'!F574 -> -14656.835 | F7: ='conditional forecasts_4'!G574 -> -3572.5569 | G7: ='conditional forecasts_4'!H574 -> -6097.8532 | H7: ='conditional forecasts_4'!I574 -> 2366.3982 | I7: ='conditional forecasts_4'!J574 -> 2764.4083 | J7: ='conditional forecasts_4'!K574 -> -2627.0063 | ... CT7: ='conditional forecasts_4'!CU574 -> 3874.9459
B8: 6% growth | C8: ='conditional forecasts_6'!D574 -> -31597.753 | D8: ='conditional forecasts_6'!E574 -> -15210.318 | E8: ='conditional forecasts_6'!F574 -> -13090.663 | F8: ='conditional forecasts_6'!G574 -> -1826.7424 | G8: ='conditional forecasts_6'!H574 -> -4417.1469 | H8: ='conditional forecasts_6'!I574 -> 4030.7999 | I8: ='conditional forecasts_6'!J574 -> 4385.0204 | J8: ='conditional forecasts_6'!K574 -> -1208.75 | ... CT8: ='conditional forecasts_6'!CU574 -> 9458.5783
B9: 8% growth | C9: ='conditional forecasts_8'!D574 -> -30516.359 | D9: ='conditional forecasts_8'!E574 -> -13018.273 | E9: ='conditional forecasts_8'!F574 -> -11553.767 | F9: ='conditional forecasts_8'!G574 -> -113.56181 | G9: ='conditional forecasts_8'!H574 -> -2767.8575 | H9: ='conditional forecasts_8'!I574 -> 5664.0894 | I9: ='conditional forecasts_8'!J574 -> 5975.3388 | J9: ='conditional forecasts_8'!K574 -> 182.99528 | ... CT9: ='conditional forecasts_8'!CU574 -> 14937.838
B10: Actual | C10: -26472 | D10: -8172 | E10: -17894 | F10: -2554 | G10: -5583 | H10: -5689 | I10: -9320 | J10: -3400 | K10: -4769 | L10: -3861 | M10: 3038 | N10: -15578 | O10: -9830 | P10: -2750 | Q10: 247 | R10: 7320 | S10: -3139 | T10: -2519 | U10: -1001 | V10: 2917 | W10: 7944 | X10: -847 | Y10: 13700 | Z10: -14141 | AA10: -12253 | AB10: 9753 | AC10: -6986 | AD10: 5709 | AE10: -4289 | AF10: 2341 | AG10: -2845 | AH10: 11810 | AI10: 13957 | AJ10: -9942 | AK10: 16922 | AL10: -10548
B12: =B5 -> 0% growth | C12: =C5 -> -34968.777 | D12: =D5+C12 -> -57012.349 | E12: =E5+D12 -> -74893.97 | F12: =F5+E12 -> -82061.203 | G12: =G5+F12 -> -91619.672 | H12: =H5+G12 -> -92680.319 | I12: =I5+H12 -> -93252.792 | J12: =J5+I12 -> -98800.024 | K12: =K5+J12 -> -100791.37 | ... CT12: =CT5+CS12 -> -482569.81
B13: =B6 -> 2% growth | C13: =C6 -> -33823.138 | D13: =D6+C13 -> -53544.435 | E13: =E6+D13 -> -69797.854 | F13: =F6+E13 -> -75150.127 | G13: =G6+F13 -> -82961.324 | H13: =H6+G13 -> -82291.648 | I13: =I6+H13 -> -81179.322 | J13: =J6+I13 -> -85252.125 | K13: =K6+J13 -> -85116.711 | ... CT13: =CT6+CS13 -> 54588.747
B14: =B7 -> 4% growth | C14: =C7 -> -32699.746 | D14: =D7+C14 -> -50143.865 | E14: =E7+D14 -> -64800.699 | F14: =F7+E14 -> -68373.256 | G14: =G7+F14 -> -74471.109 | H14: =H7+G14 -> -72104.711 | I14: =I7+H14 -> -69340.303 | J14: =J7+I14 -> -71967.309 | K14: =K7+J14 -> -69746.43 | ... CT14: =CT7+CS14 -> 581316.38
B15: =B8 -> 6% growth | C15: =C8 -> -31597.753 | D15: =D8+C15 -> -46808.071 | E15: =E8+D15 -> -59898.734 | F15: =F8+E15 -> -61725.476 | G15: =G8+F15 -> -66142.623 | H15: =H8+G15 -> -62111.823 | I15: =I8+H15 -> -57726.803 | J15: =J8+I15 -> -58935.553 | K15: =K8+J15 -> -54668.933 | ... CT15: =CT8+CS15 -> 1098010.5
B16: =B9 -> 8% growth | C16: =C9 -> -30516.359 | D16: =D9+C16 -> -43534.632 | E16: =E9+D16 -> -55088.399 | F16: =F9+E16 -> -55201.961 | G16: =G9+F16 -> -57969.819 | H16: =H9+G16 -> -52305.729 | I16: =I9+H16 -> -46330.39 | J16: =J9+I16 -> -46147.395 | K16: =K9+J16 -> -39873.276 | ... CT16: =CT9+CS16 -> 1605046.2
B17: 2015-2016 Defict | C17: 420403 | D17: 420403 | E17: 420403 | F17: 420403 | G17: 420403 | H17: 420403 | I17: 420403 | J17: 420403 | K17: 420403 | L17: 420403 | M17: 420403 | N17: 420403 | O17: 420403 | P17: 420403 | Q17: 420403 | R17: 420403 | S17: 420403 | T17: 420403 | U17: 420403 | V17: 420403 | W17: 420403 | X17: 420403 | Y17: 420403 | Z17: 420403 | AA17: 420403 | AB17: 420403 | AC17: 420403 | AD17: 420403 | AE17: 420403 | AF17: 420403 | AG17: 420403 | AH17: 420403 | AI17: 420403 | AJ17: 420403 | AK17: 420403 | AL17: 420403 | AM17: 420403 | AN17: 420403 | AO17: 420403 | AP17: 420403 | AQ17: 420403 | AR17: 420403 | AS17: 420403 | AT17: 420403 | AU17: 420403 | AV17: 420403 | AW17: 420403 | AX17: 420403 | AY17: 420403 | AZ17: 420403 | BA17: 420403 | BB17: 420403 | BC17: 420403 | BD17: 420403 | BE17: 420403 | BF17: 420403 | BG17: 420403 | BH17: 420403 | BI17: 420403 | BJ17: 420403 | BK17: 420403 | BL17: 420403 | BM17: 420403 | BN17: 420403 | BO17: 420403 | BP17: 420403 | BQ17: 420403 | BR17: 420403 | BS17: 420403 | BT17: 420403 | BU17: 420403 | BV17: 420403 | BW17: 420403 | BX17: 420403 | BY17: 420403 | BZ17: 420403 | CA17: 420403 | CB17: 420403 | CC17: 420403 | CD17: 420403 | CE17: 420403 | CF17: 420403 | CG17: 420403 | CH17: 420403 | CI17: 420403 | CJ17: 420403 | CK17: 420403 | CL17: 420403 | CM17: 420403 | CN17: 420403 | CO17: 420403 | CP17: 420403 | CQ17: 420403 | CR17: 420403 | CS17: 420403 | CT17: 420403
B18: Actual | C18: =C10 -> -26472 | D18: =D10+C18 -> -34644 | E18: =E10+D18 -> -52538 | F18: =F10+E18 -> -55092 | G18: =G10+F18 -> -60675 | H18: =H10+G18 -> -66364 | I18: =I10+H18 -> -75684 | J18: =J10+I18 -> -79084 | K18: =K10+J18 -> -83853 | ... AL18: =AL10+AK18 -> -88724

Sheet ES
C2: 2017M1 | D2: 2017M2 | E2: 2017M3 | F2: 2017M4 | G2: 2017M5 | H2: 2017M6 | I2: 2017M7 | J2: 2017M8 | K2: 2017M9 | L2: 2017M10 | M2: 2017M11 | N2: 2017M12 | O2: 2018M1 | P2: 2018M2 | Q2: 2018M3 | R2: 2018M4 | S2: 2018M5 | T2: 2018M6 | U2: 2018M7 | V2: 2018M8 | W2: 2018M9 | X2: 2018M10 | Y2: 2018M11 | Z2: 2018M12 | AA2: 2019M1 | AB2: 2019M2 | AC2: 2019M3 | AD2: 2019M4 | AE2: 2019M5 | AF2: 2019M6 | AG2: 2019M7 | AH2: 2019M8 | AI2: 2019M9 | AJ2: 2019M10 | AK2: 2019M11 | AL2: 2019M12 | AM2: 2020M1 | AN2: 2020M2 | AO2: 2020M3 | AP2: 2020M4 | AQ2: 2020M5 | AR2: 2020M6 | AS2: 2020M7 | AT2: 2020M8 | AU2: 2020M9 | AV2: 2020M10 | AW2: 2020M11 | AX2: 2020M12 | AY2: 2021M1 | AZ2: 2021M2 | BA2: 2021M3 | BB2: 2021M4 | BC2: 2021M5 | BD2: 2021M6 | BE2: 2021M7 | BF2: 2021M8 | BG2: 2021M9 | BH2: 2021M10 | BI2: 2021M11 | BJ2: 2021M12 | BK2: 2022M1 | BL2: 2022M2 | BM2: 2022M3 | BN2: 2022M4 | BO2: 2022M5 | BP2: 2022M6 | BQ2: 2022M7 | BR2: 2022M8 | BS2: 2022M9 | BT2: 2022M10 | BU2: 2022M11 | BV2: 2022M12 | BW2: 2023M1 | BX2: 2023M2 | BY2: 2023M3 | BZ2: 2023M4 | CA2: 2023M5 | CB2: 2023M6 | CC2: 2023M7 | CD2: 2023M8 | CE2: 2023M9 | CF2: 2023M10 | CG2: 2023M11 | CH2: 2023M12 | CI2: 2024M1 | CJ2: 2024M2 | CK2: 2024M3 | CL2: 2024M4 | CM2: 2024M5 | CN2: 2024M6 | CO2: 2024M7 | CP2: 2024M8 | CQ2: 2024M9 | CR2: 2024M10 | CS2: 2024M11 | CT2: 2024M12
C3: =DATE(LEFT(C2,4),SUBSTITUTE(RIGHT(C2,2),"M",""),1) -> 42736 | D3: =DATE(LEFT(D2,4),SUBSTITUTE(RIGHT(D2,2),"M",""),1) -> 42767 | E3: =DATE(LEFT(E2,4),SUBSTITUTE(RIGHT(E2,2),"M",""),1) -> 42795 | F3: =DATE(LEFT(F2,4),SUBSTITUTE(RIGHT(F2,2),"M",""),1) -> 42826 | G3: =DATE(LEFT(G2,4),SUBSTITUTE(RIGHT(G2,2),"M",""),1) -> 42856 | H3: =DATE(LEFT(H2,4),SUBSTITUTE(RIGHT(H2,2),"M",""),1) -> 42887 | I3: =DATE(LEFT(I2,4),SUBSTITUTE(RIGHT(I2,2),"M",""),1) -> 42917 | J3: =DATE(LEFT(J2,4),SUBSTITUTE(RIGHT(J2,2),"M",""),1) -> 42948 | ... CT3: =DATE(LEFT(CT2,4),SUBSTITUTE(RIGHT(CT2,2),"M",""),1) -> 45627
B5: 0% growth | C5: ='conditional forecasts_0'!D573 -> -5144.2424 | D5: ='conditional forecasts_0'!E573 -> -2524.4781 | E5: ='conditional forecasts_0'!F573 -> -850.53203 | F5: ='conditional forecasts_0'!G573 -> -46.172734 | G5: ='conditional forecasts_0'!H573 -> -583.36804 | H5: ='conditional forecasts_0'!I573 -> 1948.7225 | I5: ='conditional forecasts_0'!J573 -> 916.69221 | J5: ='conditional forecasts_0'!K573 -> -455.83605 | ... CT5: ='conditional forecasts_0'!CU573 -> -2637.2076
B6: 2% growth | C6: ='conditional forecasts_2'!D573 -> -4492.6474 | D6: ='conditional forecasts_2'!E573 -> -2335.3552 | E6: ='conditional forecasts_2'!F573 -> -711.66439 | F6: ='conditional forecasts_2'!G573 -> 353.96621 | G6: ='conditional forecasts_2'!H573 -> -343.52434 | H6: ='conditional forecasts_2'!I573 -> 2188.7152 | I6: ='conditional forecasts_2'!J573 -> 1150.6653 | J6: ='conditional forecasts_2'!K573 -> -299.89728 | ... CT6: ='conditional forecasts_2'!CU573 -> -2628.4663
B7: 4% growth | C7: ='conditional forecasts_4'!D573 -> -3853.7056 | D7: ='conditional forecasts_4'!E573 -> -2149.9049 | E7: ='conditional forecasts_4'!F573 -> -575.49337 | F7: ='conditional forecasts_4'!G573 -> 746.33497 | G7: ='conditional forecasts_4'!H573 -> -108.3381 | H7: ='conditional forecasts_4'!I573 -> 2424.0475 | I7: ='conditional forecasts_4'!J573 -> 1380.0949 | J7: ='conditional forecasts_4'!K573 -> -146.98664 | ... CT7: ='conditional forecasts_4'!CU573 -> -2619.8948
B8: 6% growth | C8: ='conditional forecasts_6'!D573 -> -3226.9348 | D8: ='conditional forecasts_6'!E573 -> -1967.9871 | E8: ='conditional forecasts_6'!F573 -> -441.91625 | F8: ='conditional forecasts_6'!G573 -> 1131.2296 | G8: ='conditional forecasts_6'!H573 -> 122.36813 | H8: ='conditional forecasts_6'!I573 -> 2654.8971 | I8: ='conditional forecasts_6'!J573 -> 1605.1541 | J8: ='conditional forecasts_6'!K573 -> 3.0112432 | ... CT8: ='conditional forecasts_6'!CU573 -> -2611.4865
B9: 8% growth | C9: ='conditional forecasts_8'!D573 -> -2611.88 | D9: ='conditional forecasts_8'!E573 -> -1789.4699 | E9: ='conditional forecasts_8'!F573 -> -310.83605 | F9: ='conditional forecasts_8'!G573 -> 1508.9295 | G9: ='conditional forecasts_8'!H573 -> 348.76185 | H9: ='conditional forecasts_8'!I573 -> 2881.4315 | I9: ='conditional forecasts_8'!J573 -> 1826.0064 | J9: ='conditional forecasts_8'!K573 -> 150.20526 | ... CT9: ='conditional forecasts_8'!CU573 -> -2603.2354
B10: Actual | C10: 726 | D10: -2077 | E10: -794 | F10: 3548 | G10: 4117 | H10: -1466 | I10: -1841 | J10: -2847 | K10: 324 | L10: 1555 | M10: 189 | N10: -5981 | O10: 3140 | P10: 447 | Q10: 1780 | R10: 2765 | S10: 5001 | T10: -1562 | U10: -641 | V10: -388 | W10: 3341 | X10: 912 | Y10: 3248 | Z10: -4035 | AA10: 2608 | AB10: 3541 | AC10: -843 | AD10: 2881 | AE10: 9384 | AF10: -1152 | AG10: -4117 | AH10: 379 | AI10: 2929 | AJ10: 1913 | AK10: 2616 | AL10: -3846
B12: =B5 -> 0% growth | C12: =C5 -> -5144.2424 | D12: =D5+C12 -> -7668.7205 | E12: =E5+D12 -> -8519.2526 | F12: =F5+E12 -> -8565.4253 | G12: =G5+F12 -> -9148.7933 | H12: =H5+G12 -> -7200.0708 | I12: =I5+H12 -> -6283.3786 | J12: =J5+I12 -> -6739.2147 | K12: =K5+J12 -> -7077.4174 | ... CT12: =CT5+CS12 -> -22578.531
B13: =B6 -> 2% growth | C13: =C6 -> -4492.6474 | D13: =D6+C13 -> -6828.0027 | E13: =E6+D13 -> -7539.6671 | F13: =F6+E13 -> -7185.7008 | G13: =G6+F13 -> -7529.2252 | H13: =H6+G13 -> -5340.51 | I13: =I6+H13 -> -4189.8447 | J13: =J6+I13 -> -4489.742 | K13: =K6+J13 -> -4458.4109 | ... CT13: =CT6+CS13 -> 37548.828
B14: =B7 -> 4% growth | C14: =C7 -> -3853.7056 | D14: =D7+C14 -> -6003.6105 | E14: =E7+D14 -> -6579.1038 | F14: =F7+E14 -> -5832.7689 | G14: =G7+F14 -> -5941.107 | H14: =H7+G14 -> -3517.0594 | I14: =I7+H14 -> -2136.9645 | J14: =J7+I14 -> -2283.9512 | K14: =K7+J14 -> -1890.2623 | ... CT14: =CT7+CS14 -> 96508.591
B15: =B8 -> 6% growth | C15: =C8 -> -3226.9348 | D15: =D8+C15 -> -5194.9219 | E15: =E8+D15 -> -5636.8382 | F15: =F8+E15 -> -4505.6086 | G15: =G8+F15 -> -4383.2404 | H15: =H8+G15 -> -1728.3434 | I15: =I8+H15 -> -123.18923 | J15: =J8+I15 -> -120.17799 | K15: =K8+J15 -> 628.96633 | ... CT15: =CT8+CS15 -> 154345.24
B16: =B9 -> 8% growth | C16: =C9 -> -2611.88 | D16: =D9+C16 -> -4401.3499 | E16: =E9+D16 -> -4712.186 | F16: =F9+E16 -> -3203.2565 | G16: =G9+F16 -> -2854.4946 | H16: =H9+G16 -> 26.936803 | I16: =I9+H16 -> 1852.9432 | J16: =J9+I16 -> 2003.1485 | K16: =K9+J16 -> 3101.1038 | ... CT16: =CT9+CS16 -> 211100.77
B17: 2015-2016 Defict | C17: 84526 | D17: 84526 | E17: 84526 | F17: 84526 | G17: 84526 | H17: 84526 | I17: 84526 | J17: 84526 | K17: 84526 | L17: 84526 | M17: 84526 | N17: 84526 | O17: 84526 | P17: 84526 | Q17: 84526 | R17: 84526 | S17: 84526 | T17: 84526 | U17: 84526 | V17: 84526 | W17: 84526 | X17: 84526 | Y17: 84526 | Z17: 84526 | AA17: 84526 | AB17: 84526 | AC17: 84526 | AD17: 84526 | AE17: 84526 | AF17: 84526 | AG17: 84526 | AH17: 84526 | AI17: 84526 | AJ17: 84526 | AK17: 84526 | AL17: 84526 | AM17: 84526 | AN17: 84526 | AO17: 84526 | AP17: 84526 | AQ17: 84526 | AR17: 84526 | AS17: 84526 | AT17: 84526 | AU17: 84526 | AV17: 84526 | AW17: 84526 | AX17: 84526 | AY17: 84526 | AZ17: 84526 | BA17: 84526 | BB17: 84526 | BC17: 84526 | BD17: 84526 | BE17: 84526 | BF17: 84526 | BG17: 84526 | BH17: 84526 | BI17: 84526 | BJ17: 84526 | BK17: 84526 | BL17: 84526 | BM17: 84526 | BN17: 84526 | BO17: 84526 | BP17: 84526 | BQ17: 84526 | BR17: 84526 | BS17: 84526 | BT17: 84526 | BU17: 84526 | BV17: 84526 | BW17: 84526 | BX17: 84526 | BY17: 84526 | BZ17: 84526 | CA17: 84526 | CB17: 84526 | CC17: 84526 | CD17: 84526 | CE17: 84526 | CF17: 84526 | CG17: 84526 | CH17: 84526 | CI17: 84526 | CJ17: 84526 | CK17: 84526 | CL17: 84526 | CM17: 84526 | CN17: 84526 | CO17: 84526 | CP17: 84526 | CQ17: 84526 | CR17: 84526 | CS17: 84526 | CT17: 84526
B18: Actual | C18: =C10 -> 726 | D18: =D10+C18 -> -1351 | E18: =E10+D18 -> -2145 | F18: =F10+E18 -> 1403 | G18: =G10+F18 -> 5520 | H18: =H10+G18 -> 4054 | I18: =I10+H18 -> 2213 | J18: =J10+I18 -> -634 | K18: =K10+J18 -> -310 | ... AL18: =AL10+AK18 -> 25754

Sheet MG
C2: 2017M1 | D2: 2017M2 | E2: 2017M3 | F2: 2017M4 | G2: 2017M5 | H2: 2017M6 | I2: 2017M7 | J2: 2017M8 | K2: 2017M9 | L2: 2017M10 | M2: 2017M11 | N2: 2017M12 | O2: 2018M1 | P2: 2018M2 | Q2: 2018M3 | R2: 2018M4 | S2: 2018M5 | T2: 2018M6 | U2: 2018M7 | V2: 2018M8 | W2: 2018M9 | X2: 2018M10 | Y2: 2018M11 | Z2: 2018M12 | AA2: 2019M1 | AB2: 2019M2 | AC2: 2019M3 | AD2: 2019M4 | AE2: 2019M5 | AF2: 2019M6 | AG2: 2019M7 | AH2: 2019M8 | AI2: 2019M9 | AJ2: 2019M10 | AK2: 2019M11 | AL2: 2019M12 | AM2: 2020M1 | AN2: 2020M2 | AO2: 2020M3 | AP2: 2020M4 | AQ2: 2020M5 | AR2: 2020M6 | AS2: 2020M7 | AT2: 2020M8 | AU2: 2020M9 | AV2: 2020M10 | AW2: 2020M11 | AX2: 2020M12 | AY2: 2021M1 | AZ2: 2021M2 | BA2: 2021M3 | BB2: 2021M4 | BC2: 2021M5 | BD2: 2021M6 | BE2: 2021M7 | BF2: 2021M8 | BG2: 2021M9 | BH2: 2021M10 | BI2: 2021M11 | BJ2: 2021M12 | BK2: 2022M1 | BL2: 2022M2 | BM2: 2022M3 | BN2: 2022M4 | BO2: 2022M5 | BP2: 2022M6 | BQ2: 2022M7 | BR2: 2022M8 | BS2: 2022M9 | BT2: 2022M10 | BU2: 2022M11 | BV2: 2022M12 | BW2: 2023M1 | BX2: 2023M2 | BY2: 2023M3 | BZ2: 2023M4 | CA2: 2023M5 | CB2: 2023M6 | CC2: 2023M7 | CD2: 2023M8 | CE2: 2023M9 | CF2: 2023M10 | CG2: 2023M11 | CH2: 2023M12 | CI2: 2024M1 | CJ2: 2024M2 | CK2: 2024M3 | CL2: 2024M4 | CM2: 2024M5 | CN2: 2024M6 | CO2: 2024M7 | CP2: 2024M8 | CQ2: 2024M9 | CR2: 2024M10 | CS2: 2024M11 | CT2: 2024M12
C3: =DATE(LEFT(C2,4),SUBSTITUTE(RIGHT(C2,2),"M",""),1) -> 42736 | D3: =DATE(LEFT(D2,4),SUBSTITUTE(RIGHT(D2,2),"M",""),1) -> 42767 | E3: =DATE(LEFT(E2,4),SUBSTITUTE(RIGHT(E2,2),"M",""),1) -> 42795 | F3: =DATE(LEFT(F2,4),SUBSTITUTE(RIGHT(F2,2),"M",""),1) -> 42826 | G3: =DATE(LEFT(G2,4),SUBSTITUTE(RIGHT(G2,2),"M",""),1) -> 42856 | H3: =DATE(LEFT(H2,4),SUBSTITUTE(RIGHT(H2,2),"M",""),1) -> 42887 | I3: =DATE(LEFT(I2,4),SUBSTITUTE(RIGHT(I2,2),"M",""),1) -> 42917 | J3: =DATE(LEFT(J2,4),SUBSTITUTE(RIGHT(J2,2),"M",""),1) -> 42948 | ... CT3: =DATE(LEFT(CT2,4),SUBSTITUTE(RIGHT(CT2,2),"M",""),1) -> 45627
B5: 0% growth | C5: ='conditional forecasts_0'!D572 -> -27488.586 | D5: ='conditional forecasts_0'!E572 -> -11836.064 | E5: ='conditional forecasts_0'!F572 -> 917.31628 | F5: ='conditional forecasts_0'!G572 -> 11057.898 | G5: ='conditional forecasts_0'!H572 -> 7312.0845 | H5: ='conditional forecasts_0'!I572 -> 22693.214 | I5: ='conditional forecasts_0'!J572 -> 10932.713 | J5: ='conditional forecasts_0'!K572 -> 2666.36 | ... CT5: ='conditional forecasts_0'!CU572 -> -26954.561
B6: 2% growth | C6: ='conditional forecasts_2'!D572 -> -23575.864 | D6: ='conditional forecasts_2'!E572 -> -9912.9888 | E6: ='conditional forecasts_2'!F572 -> 1132.8221 | F6: ='conditional forecasts_2'!G572 -> 12057.591 | G6: ='conditional forecasts_2'!H572 -> 7755.6254 | H6: ='conditional forecasts_2'!I572 -> 23205.862 | I6: ='conditional forecasts_2'!J572 -> 11465.194 | J6: ='conditional forecasts_2'!K572 -> 3346.4728 | ... CT6: ='conditional forecasts_2'!CU572 -> -27233.986
B7: 4% growth | C7: ='conditional forecasts_4'!D572 -> -19739.122 | D7: ='conditional forecasts_4'!E572 -> -8027.2571 | E7: ='conditional forecasts_4'!F572 -> 1344.1431 | F7: ='conditional forecasts_4'!G572 -> 13037.87 | G7: ='conditional forecasts_4'!H572 -> 8190.5533 | H7: ='conditional forecasts_4'!I572 -> 23708.556 | I7: ='conditional forecasts_4'!J572 -> 11987.335 | J7: ='conditional forecasts_4'!K572 -> 4013.3787 | ... CT7: ='conditional forecasts_4'!CU572 -> -27507.986
B8: 6% growth | C8: ='conditional forecasts_6'!D572 -> -15975.466 | D8: ='conditional forecasts_6'!E572 -> -6177.4463 | E8: ='conditional forecasts_6'!F572 -> 1551.4386 | F8: ='conditional forecasts_6'!G572 -> 13999.477 | G8: ='conditional forecasts_6'!H572 -> 8617.1964 | H8: ='conditional forecasts_6'!I572 -> 24201.674 | I8: ='conditional forecasts_6'!J572 -> 12499.53 | J8: ='conditional forecasts_6'!K572 -> 4667.5809 | ... CT8: ='conditional forecasts_6'!CU572 -> -27776.766
B9: 8% growth | C9: ='conditional forecasts_8'!D572 -> -12282.162 | D9: ='conditional forecasts_8'!E572 -> -4362.2134 | E9: ='conditional forecasts_8'!F572 -> 1754.8593 | F9: ='conditional forecasts_8'!G572 -> 14943.109 | G9: ='conditional forecasts_8'!H572 -> 9035.8644 | H9: ='conditional forecasts_8'!I572 -> 24685.574 | I9: ='conditional forecasts_8'!J572 -> 13002.15 | J9: ='conditional forecasts_8'!K572 -> 5309.5542 | ... CT9: ='conditional forecasts_8'!CU572 -> -28040.521
B10: Actual | C10: -185 | D10: 9025 | E10: -6 | F10: 14818 | G10: 22931 | H10: 15445 | I10: 1120 | J10: -9445 | K10: -4291 | L10: 4509 | M10: -2037 | N10: -36446 | O10: 8336 | P10: 7288 | Q10: 14149 | R10: 23563 | S10: 19823 | T10: 12143 | U10: 10332 | V10: 4530 | W10: 5200 | X10: 2835 | Y10: 367 | Z10: -38761 | AA10: 1492 | AB10: 26016 | AC10: 5163 | AD10: 22348 | AE10: 18380 | AF10: 11603 | AG10: 10609 | AH10: 5895 | AI10: 3841 | AJ10: 12282 | AK10: 8382 | AL10: -35888
B12: =B5 -> 0% growth | C12: =C5 -> -27488.586 | D12: =D5+C12 -> -39324.65 | E12: =E5+D12 -> -38407.334 | F12: =F5+E12 -> -27349.436 | G12: =G5+F12 -> -20037.351 | H12: =H5+G12 -> 2655.8628 | I12: =I5+H12 -> 13588.575 | J12: =J5+I12 -> 16254.935 | K12: =K5+J12 -> 16182.08 | ... CT12: =CT5+CS12 -> 28986.142
B13: =B6 -> 2% growth | C13: =C6 -> -23575.864 | D13: =D6+C13 -> -33488.853 | E13: =E6+D13 -> -32356.031 | F13: =F6+E13 -> -20298.44 | G13: =G6+F13 -> -12542.815 | H13: =H6+G13 -> 10663.048 | I13: =I6+H13 -> 22128.241 | J13: =J6+I13 -> 25474.714 | K13: =K6+J13 -> 27052.435 | ... CT13: =CT6+CS13 -> 272078.25
B14: =B7 -> 4% growth | C14: =C7 -> -19739.122 | D14: =D7+C14 -> -27766.38 | E14: =E7+D14 -> -26422.237 | F14: =F7+E14 -> -13384.366 | G14: =G7+F14 -> -5193.8127 | H14: =H7+G14 -> 18514.743 | I14: =I7+H14 -> 30502.078 | J14: =J7+I14 -> 34515.457 | K14: =K7+J14 -> 37711.701 | ... CT14: =CT7+CS14 -> 510449.82
B15: =B8 -> 6% growth | C15: =C8 -> -15975.466 | D15: =D8+C15 -> -22152.912 | E15: =E8+D15 -> -20601.474 | F15: =F8+E15 -> -6601.9965 | G15: =G8+F15 -> 2015.1998 | H15: =H8+G15 -> 26216.874 | I15: =I8+H15 -> 38716.403 | J15: =J8+I15 -> 43383.984 | K15: =K8+J15 -> 48167.921 | ... CT15: =CT8+CS15 -> 744280.7
B16: =B9 -> 8% growth | C16: =C9 -> -12282.162 | D16: =D9+C16 -> -16644.376 | E16: =E9+D16 -> -14889.516 | F16: =F9+E16 -> 53.592244 | G16: =G9+F16 -> 9089.4566 | H16: =H9+G16 -> 33775.03 | I16: =I9+H16 -> 46777.181 | J16: =J9+I16 -> 52086.735 | K16: =K9+J16 -> 58428.686 | ... CT16: =CT9+CS16 -> 973740.66
B17: 2015-2016 Defict | C17: 327313 | D17: 327313 | E17: 327313 | F17: 327313 | G17: 327313 | H17: 327313 | I17: 327313 | J17: 327313 | K17: 327313 | L17: 327313 | M17: 327313 | N17: 327313 | O17: 327313 | P17: 327313 | Q17: 327313 | R17: 327313 | S17: 327313 | T17: 327313 | U17: 327313 | V17: 327313 | W17: 327313 | X17: 327313 | Y17: 327313 | Z17: 327313 | AA17: 327313 | AB17: 327313 | AC17: 327313 | AD17: 327313 | AE17: 327313 | AF17: 327313 | AG17: 327313 | AH17: 327313 | AI17: 327313 | AJ17: 327313 | AK17: 327313 | AL17: 327313 | AM17: 327313 | AN17: 327313 | AO17: 327313 | AP17: 327313 | AQ17: 327313 | AR17: 327313 | AS17: 327313 | AT17: 327313 | AU17: 327313 | AV17: 327313 | AW17: 327313 | AX17: 327313 | AY17: 327313 | AZ17: 327313 | BA17: 327313 | BB17: 327313 | BC17: 327313 | BD17: 327313 | BE17: 327313 | BF17: 327313 | BG17: 327313 | BH17: 327313 | BI17: 327313 | BJ17: 327313 | BK17: 327313 | BL17: 327313 | BM17: 327313 | BN17: 327313 | BO17: 327313 | BP17: 327313 | BQ17: 327313 | BR17: 327313 | BS17: 327313 | BT17: 327313 | BU17: 327313 | BV17: 327313 | BW17: 327313 | BX17: 327313 | BY17: 327313 | BZ17: 327313 | CA17: 327313 | CB17: 327313 | CC17: 327313 | CD17: 327313 | CE17: 327313 | CF17: 327313 | CG17: 327313 | CH17: 327313 | CI17: 327313 | CJ17: 327313 | CK17: 327313 | CL17: 327313 | CM17: 327313 | CN17: 327313 | CO17: 327313 | CP17: 327313 | CQ17: 327313 | CR17: 327313 | CS17: 327313 | CT17: 327313
B18: Actual | C18: =C10 -> -185 | D18: =D10+C18 -> 8840 | E18: =E10+D18 -> 8834 | F18: =F10+E18 -> 23652 | G18: =G10+F18 -> 46583 | H18: =H10+G18 -> 62028 | I18: =I10+H18 -> 63148 | J18: =J10+I18 -> 53703 | K18: =K10+J18 -> 49412 | ... AL18: =AL10+AK18 -> 175366

Sheet Mapa Regiao
A1: ID | B1: Name
A2: 1 | B2: North
A3: 2 | B3: Northeast
A4: 3 | B4: Southeast
A5: 4 | B5: South
A6: 5 | B6: Central
A8: 31 | B8: MG
A9: 35 | B9: SP
A10: 32 | B10: ES
A11: 33 | B11: RJ

Sheet forecasts (2)
A1: GVAR Forecasts
A2: Last in-sample estimation date: | B2: 2016M12
A3: Last forecast date: | B3: 2024M12
D5: 2017M1 | E5: 2017M2 | F5: 2017M3 | G5: 2017M4 | H5: 2017M5 | I5: 2017M6 | J5: 2017M7 | K5: 2017M8 | L5: 2017M9 | M5: 2017M10 | N5: 2017M11 | O5: 2017M12 | P5: 2018M1 | Q5: 2018M2 | R5: 2018M3 | S5: 2018M4 | T5: 2018M5 | U5: 2018M6 | V5: 2018M7 | W5: 2018M8 | X5: 2018M9 | Y5: 2018M10 | Z5: 2018M11 | AA5: 2018M12 | AB5: 2019M1 | AC5: 2019M2 | AD5: 2019M3 | AE5: 2019M4 | AF5: 2019M5 | AG5: 2019M6 | AH5: 2019M7 | AI5: 2019M8 | AJ5: 2019M9 | AK5: 2019M10 | AL5: 2019M11 | AM5: 2019M12 | AN5: 2020M1 | AO5: 2020M2 | AP5: 2020M3 | AQ5: 2020M4 | AR5: 2020M5 | AS5: 2020M6 | AT5: 2020M7 | AU5: 2020M8 | AV5: 2020M9 | AW5: 2020M10 | AX5: 2020M11 | AY5: 2020M12 | AZ5: 2021M1 | BA5: 2021M2 | BB5: 2021M3 | BC5: 2021M4 | BD5: 2021M5 | BE5: 2021M6 | BF5: 2021M7 | BG5: 2021M8 | BH5: 2021M9 | BI5: 2021M10 | BJ5: 2021M11 | BK5: 2021M12 | BL5: 2022M1 | BM5: 2022M2 | BN5: 2022M3 | BO5: 2022M4 | BP5: 2022M5 | BQ5: 2022M6 | BR5: 2022M7 | BS5: 2022M8 | BT5: 2022M9 | BU5: 2022M10 | BV5: 2022M11 | BW5: 2022M12 | BX5: 2023M1 | BY5: 2023M2 | BZ5: 2023M3 | CA5: 2023M4 | CB5: 2023M5 | CC5: 2023M6 | CD5: 2023M7 | CE5: 2023M8 | CF5: 2023M9 | CG5: 2023M10 | CH5: 2023M11 | CI5: 2023M12 | CJ5: 2024M1 | CK5: 2024M2 | CL5: 2024M3 | CM5: 2024M4 | CN5: 2024M5 | CO5: 2024M6 | CP5: 2024M7 | CQ5: 2024M8 | CR5: 2024M9 | CS5: 2024M10 | CT5: 2024M11 | CU5: 2024M12 | CX5: Estado
A6: Ro1101 | B6: adm | C6: Forecast | D6: 2336.9808 | E6: 2312.3801 | F6: 2657.806 | G6: 2863.4845 | H6: 2929.8957 | I6: 2932.1209 | J6: 2722.6753 | K6: 2533.8324 | L6: 2267.0652 | M6: 2069.9615 | N6: 1943.9223 | O6: 1881.0981 | P6: 1905.1517 | Q6: 1947.7631 | R6: 2016.3741 | S6: 2065.4142 | T6: 2086.708 | U6: 2079.0643 | V6: 2038.9515 | W6: 1987.4013 | X6: 1929.4789 | Y6: 1881.6535 | Z6: 1850.2302 | AA6: 1837.4009 | AB6: 1843.2285 | AC6: 1859.8933 | AD6: 1882.0422 | AE6: 1901.8471 | AF6: 1914.9245 | AG6: 1919.5119 | AH6: 1915.9575 | AI6: 1907.6058 | AJ6: 1897.7589 | AK6: 1890.1217 | AL6: 1886.9702 | AM6: 1889.1262 | AN6: 1896.1482 | AO6: 1906.3751 | AP6: 1917.9433 | AQ6: 1928.9859 | AR6: 1938.2634 | AS6: 1945.2694 | AT6: 1950.1712 | AU6: 1953.7006 | AV6: 1956.7748 | AW6: 1960.3005 | AX6: 1964.9103 | AY6: 1970.8715 | AZ6: 1978.094 | BA6: 1986.2009 | BB6: 1994.6927 | BC6: 2003.0766 | BD6: 2010.9946 | BE6: 2018.2818 | BF6: 2024.9663 | BG6: 2031.2278 | BH6: 2037.3166 | BI6: 2043.4797 | BJ6: 2049.897 | BK6: 2056.6493 | BL6: 2063.7177 | BM6: 2071.007 | BN6: 2078.3845 | BO6: 2085.7193 | BP6: 2092.9142 | BQ6: 2099.9224 | BR6: 2106.7487 | BS6: 2113.4378 | BT6: 2120.0552 | BU6: 2126.6669 | BV6: 2133.3228 | BW6: 2140.0476 | BX6: 2146.8394 | BY6: 2153.6756 | BZ6: 2160.5221 | CA6: 2167.3444 | CB6: 2174.116 | CC6: 2180.8235 | CD6: 2187.4673 | CE6: 2194.0589 | CF6: 2200.6161 | CG6: 2207.1569 | CH6: 2213.6957 | CI6: 2220.2402 | CJ6: 2226.7906 | CK6: 2233.342 | CL6: 2239.8857 | CM6: 2246.4129 | CN6: 2252.9167 | CO6: 2259.3936 | CP6: 2265.8438 | CQ6: 2272.2704 | CR6: 2278.6783 | CS6: 2285.0727 | CT6: 2291.4578 | CU6: 2297.8361 | CV6: 1 | CW6: 1 | CX6: 11
C7: Actual | CV7: 0 | CW7: 0 | CX7: 0
A8: Ro1101 | B8: desl | C8: Forecast | D8: 3171.6865 | E8: 3043.8417 | F8: 3116.1931 | G8: 3065.1451 | H8: 3169.497 | I8: 3103.7389 | J8: 3063.4059 | K8: 2947.4825 | L8: 2780.9638 | M8: 2634.6895 | N8: 2467.2418 | O8: 2364.64 | P8: 2288.1828 | Q8: 2256.2625 | R8: 2252.0299 | S8: 2248.9762 | T8: 2248.137 | U8: 2226.0539 | V8: 2191.5499 | W8: 2143.0077 | X8: 2087.8574 | Y8: 2035.4439 | Z8: 1987.8242 | AA8: 1951.5844 | AB8: 1925.0338 | AC8: 1908.0051 | AD8: 1897.5939 | AE8: 1889.9574 | AF8: 1882.8145 | AG8: 1873.1463 | AH8: 1860.4555 | AI8: 1844.6843 | AJ8: 1827.0799 | AK8: 1809.5083 | AL8: 1793.4999 | AM8: 1780.4554 | AN8: 1770.7296 | AO8: 1764.1112 | AP8: 1759.7735 | AQ8: 1756.6334 | AR8: 1753.7581 | AS8: 1750.4382 | AT8: 1746.4344 | AU8: 1741.8373 | AV8: 1737.0084 | AW8: 1732.417 | AX8: 1728.4772 | AY8: 1725.4835 | AZ8: 1723.532 | BA8: 1722.5535 | BB8: 1722.3474 | BC8: 1722.6523 | BD8: 1723.2192 | BE8: 1723.8583 | BF8: 1724.4765 | BG8: 1725.0741 | BH8: 1725.7265 | BI8: 1726.5477 | BJ8: 1727.6505 | BK8: 1729.1169 | BL8: 1730.9787 | BM8: 1733.2179 | BN8: 1735.7777 | BO8: 1738.5823 | BP8: 1741.5578 | BQ8: 1744.6478 | BR8: 1747.8225 | BS8: 1751.0782 | BT8: 1754.4315 | BU8: 1757.9092 | BV8: 1761.5382 | BW8: 1765.3371 | BX8: 1769.3123 | BY8: 1773.4571 | BZ8: 1777.755 | CA8: 1782.1842 | CB8: 1786.7229 | CC8: 1791.3532 | CD8: 1796.0644 | CE8: 1800.8524 | CF8: 1805.719 | CG8: 1810.6691 | CH8: 1815.7081 | CI8: 1820.8396 | CJ8: 1826.0638 | CK8: 1831.3776 | CL8: 1836.7753 | CM8: 1842.2494 | CN8: 1847.7927 | CO8: 1853.3987 | CP8: 1859.063 | CQ8: 1864.7831 | CR8: 1870.5582 | CS8: 1876.3881 | CT8: 1882.2732 | CU8: 1888.2132 | CV8: -1 | CW8: 1 | CX8: 11
C9: Actual | CV9: 0 | CW9: 0 | CX9: 0
A10: Ro1102 | B10: adm | C10: Forecast | D10: 4137.5519 | E10: 4444.5537 | F10: 5010.4524 | G10: 5191.2041 | H10: 5154.9613 | I10: 5075.0248 | J10: 4758.7789 | K10: 4580.7946 | L10: 4351.9333 | M10: 4251.2794 | N10: 4238.3129 | O10: 4269.8338 | P10: 4372.4476 | Q10: 4442.5826 | R10: 4507.4578 | S10: 4517.8557 | T10: 4483.2062 | U10: 4419.6918 | V10: 4331.3627 | W10: 4252.5203 | X10: 4184.8822 | Y10: 4143.3702 | Z10: 4125.8544 | AA10: 4125.7486 | AB10: 4137.6964 | AC10: 4149.0379 | AD10: 4155.3258 | AE10: 4150.7121 | AF10: 4135.0917 | AG10: 4111.0759 | AH10: 4082.0784 | AI10: 4053.5659 | AJ10: 4028.8044 | AK10: 4010.5231 | AL10: 3999.0752 | AM10: 3993.216 | AN10: 3990.8947 | AO10: 3989.4078 | AP10: 3986.7774 | AQ10: 3981.636 | AR10: 3973.7276 | AS10: 3963.6517 | AT10: 3952.492 | AU10: 3941.5596 | AV10: 3931.8848 | AW10: 3924.1209 | AX10: 3918.3927 | AY10: 3914.3907 | AZ10: 3911.5419 | BA10: 3909.1731 | BB10: 3906.7224 | BC10: 3903.8274 | BD10: 3900.3855 | BE10: 3896.5214 | BF10: 3892.5063 | BG10: 3888.6668 | BH10: 3885.2843 | BI10: 3882.5373 | BJ10: 3880.4715 | BK10: 3879.0132 | BL10: 3878.0092 | BM10: 3877.2768 | BN10: 3876.6547 | BO10: 3876.036 | BP10: 3875.3823 | BQ10: 3874.7183 | BR10: 3874.1109 | BS10: 3873.6432 | BT10: 3873.3883 | BU10: 3873.3924 | BV10: 3873.6669 | BW10: 3874.1912 | BX10: 3874.9229 | BY10: 3875.8111 | BZ10: 3876.8093 | CA10: 3877.8852 | CB10: 3879.0243 | CC10: 3880.2289 | CD10: 3881.5134 | CE10: 3882.897 | CF10: 3884.3974 | CG10: 3886.0252 | CH10: 3887.7824 | CI10: 3889.6621 | CJ10: 3891.6515 | CK10: 3893.7352 | CL10: 3895.8988 | CM10: 3898.1315 | CN10: 3900.4272 | CO10: 3902.7845 | CP10: 3905.2054 | CQ10: 3907.6934 | CR10: 3910.2518 | CS10: 3912.8823 | CT10: 3915.584 | CU10: 3918.354 | CV10: 1 | CW10: 1 | CX10: 11
C11: Actual | CV11: 0 | CW11: 0 | CX11: 0
A12: Ro1102 | B12: desl | C12: Forecast | D12: 5184.4937 | E12: 5069.5182 | F12: 5288.3821 | G12: 5045.6956 | H12: 5145.1068 | I12: 4969.0827 | J12: 4867.0074 | K12: 4829.8545 | L12: 4688.2598 | M12: 4682.2469 | N12: 4608.8389 | O12: 4611.118 | P12: 4607.9062 | Q12: 4589.6876 | R12: 4581.2162 | S12: 4527.0458 | T12: 4478.1086 | U12: 4409.0183 | V12: 4345.4879 | W12: 4294.0142 | X12: 4249.7012 | Y12: 4223.2032 | Z12: 4199.7286 | AA12: 4182.3558 | AB12: 4163.8526 | AC12: 4142.3055 | AD12: 4118.9745 | AE12: 4091.6344 | AF12: 4063.8673 | AG12: 4035.2449 | AH12: 4007.8111 | AI12: 3982.5532 | AJ12: 3959.7141 | AK12: 3940.1412 | AL12: 3922.9989 | AM12: 3907.994 | AN12: 3894.0468 | AO12: 3880.3084 | AP12: 3866.2975 | AQ12: 3851.6823 | AR12: 3836.7818 | AS12: 3821.9481 | AT12: 3807.7321 | AU12: 3794.5459 | AV12: 3782.5806 | AW12: 3771.8658 | AX12: 3762.1985 | AY12: 3753.3371 | AZ12: 3745.0056 | BA12: 3736.9946 | BB12: 3729.1884 | BC12: 3721.5492 | BD12: 3714.1261 | BE12: 3707.0007 | BF12: 3700.2734 | BG12: 3694.027 | BH12: 3688.3083 | BI12: 3683.1239 | BJ12: 3678.436 | BK12: 3674.1811 | BL12: 3670.283 | BM12: 3666.6725 | BN12: 3663.3011 | BO12: 3660.1458 | BP12: 3657.2087 | BQ12: 3654.5077 | BR12: 3652.0671 | BS12: 3649.9068 | BT12: 3648.0358 | BU12: 3646.4499 | BV12: 3645.1334 | BW12: 3644.063 | BX12: 3643.2136 | BY12: 3642.5625 | BZ12: 3642.093 | CA12: 3641.795 | CB12: 3641.6644 | CC12: 3641.7017 | CD12: 3641.9087 | CE12: 3642.2868 | CF12: 3642.835 | CG12: 3643.5494 | CH12: 3644.423 | CI12: 3645.4468 | CJ12: 3646.6113 | CK12: 3647.9072 | CL12: 3649.327 | CM12: 3650.8649 | CN12: 3652.5172 | CO12: 3654.2813 | CP12: 3656.1554 | CQ12: 3658.1376 | CR12: 3660.2254 | CS12: 3662.4157 | CT12: 3664.7045 | CU12: 3667.0874 | CV12: -1 | CW12: 1 | CX12: 11
C13: Actual | CV13: 0 | CW13: 0 | CX13: 0
A14: Ac1201 | B14: adm | C14: Forecast | D14: 115.87824 | E14: 122.22568 | F14: 159.99944 | G14: 189.92608 | H14: 210.50288 | I14: 226.23131 | J14: 218.50408 | K14: 205.81668 | L14: 181.40742 | M14: 158.0026 | N14: 138.97397 | O14: 125.71312 | P14: 122.84775 | Q14: 125.51348 | R14: 133.57703 | S14: 141.99013 | T14: 148.14426 | U14: 150.63869 | V14: 148.30071 | W14: 142.84803 | X14: 135.28814 | Y14: 127.7757 | Z14: 121.66734 | AA14: 117.66068 | AB14: 116.03535 | AC14: 116.13942 | AD14: 117.33725 | AE14: 118.70458 | AF14: 119.56194 | AG14: 119.50974 | AH14: 118.40103 | AI14: 116.45363 | AJ14: 113.99433 | AK14: 111.46699 | AL14: 109.24536 | AM14: 107.57015 | AN14: 106.52701 | AO14: 106.02251 | AP14: 105.87051 | AQ14: 105.83219 | AR14: 105.69973 | AS14: 105.33967 | AT14: 104.70869 | AU14: 103.85308 | AV14: 102.87155 | AW14: 101.8845 | AX14: 100.99608 | AY14: 100.27196 | AZ14: 99.731655 | BA14: 99.351461 | BB14: 99.08057 | BC14: 98.857533 | BD14: 98.627801 | BE14: 98.355183 | BF14: 98.026585 | BG14: 97.650811 | BH14: 97.251603 | BI14: 96.859044 | BJ14: 96.500626 | BK14: 96.194829 | BL14: 95.948143 | BM14: 95.755511 | BN14: 95.603725 | BO14: 95.476077 | BP14: 95.357097 | BQ14: 95.236017 | BR14: 95.108388 | BS14: 94.975818 | BT14: 94.844219 | BU14: 94.721368 | BV14: 94.61447 | BW14: 94.52838 | BX14: 94.464764 | BY14: 94.422213 | BZ14: 94.397113 | CA14: 94.384868 | CB14: 94.381135 | CC14: 94.38275 | CD14: 94.388186 | CE14: 94.397522 | CF14: 94.412026 | CG14: 94.43353 | CH14: 94.463796 | CI14: 94.504015 | CJ14: 94.554559 | CK14: 94.614978 | CL14: 94.684206 | CM14: 94.760887 | CN14: 94.843704 | CO14: 94.931637 | CP14: 95.024109 | CQ14: 95.120976 | CR14: 95.222433 | CS14: 95.328844 | CT14: 95.44057 | CU14: 95.557835 | CV14: 1 | CW14: 1 | CX14: 12
C15: Actual | CV15: 0 | CW15: 0 | CX15: 0
A16: Ac1201 | B16: desl | C16: Forecast | D16: 204.3715 | E16: 170.28649 | F16: 161.97532 | G16: 145.91385 | H16: 145.94902 | I16: 145.11911 | J16: 150.91298 | K16: 157.89436 | L16: 159.75952 | M16: 161.99066 | N16: 157.72249 | O16: 152.39984 | P16: 145.0417 | Q16: 137.75736 | R16: 132.59744 | S16: 128.57336 | T16: 126.9994 | U16: 126.21613 | V16: 126.07451 | W16: 125.82973 | X16: 124.87459 | Y16: 123.39798 | Z16: 121.13125 | AA16: 118.52404 | AB16: 115.71102 | AC16: 112.97752 | AD16: 110.58109 | AE16: 108.5705 | AF16: 107.04709 | AG16: 105.88467 | AH16: 104.97474 | AI16: 104.14976 | AJ16: 103.25629 | AK16: 102.22397 | AL16: 101.01646 | AM16: 99.689833 | AN16: 98.319508 | AO16: 96.996808 | AP16: 95.79619 | AQ16: 94.751355 | AR16: 93.867019 | AS16: 93.111718 | AT16: 92.442649 | AU16: 91.81393 | AV16: 91.189101 | AW16: 90.549071 | AX16: 89.889629 | AY16: 89.221697 | AZ16: 88.563275 | BA16: 87.934657 | BB16: 87.352776 | BC16: 86.827188 | BD16: 86.359531 | BE16: 85.943634 | BF16: 85.568631 | BG16: 85.221994 | BH16: 84.892769 | BI16: 84.573915 | BJ16: 84.262989 | BK16: 83.961829 | BL16: 83.674941 | BM16: 83.407677 | BN16: 83.164502 | BO16: 82.947833 | BP16: 82.757708 | BQ16: 82.592062 | BR16: 82.447536 | BS16: 82.320412 | BT16: 82.207447 | BU16: 82.106432 | BV16: 82.016374 | BW16: 81.937365 | BX16: 81.87021 | BY16: 81.815967 | BZ16: 81.775525 | CA16: 81.749298 | CB16: 81.73711 | CC16: 81.738238 | CD16: 81.751592 | CE16: 81.775957 | CF16: 81.810217 | CG16: 81.853521 | CH16: 81.905353 | CI16: 81.965505 | CJ16: 82.033989 | CK16: 82.110902 | CL16: 82.196313 | CM16: 82.29017 | CN16: 82.39227 | CO16: 82.502265 | CP16: 82.619712 | CQ16: 82.744138 | CR16: 82.875096 | CS16: 83.012217 | CT16: 83.155221 | CU16: 83.303916 | CV16: -1 | CW16: 1 | CX16: 12
C17: Actual | CV17: 0 | CW17: 0 | CX17: 0
A18: Ac1202 | B18: adm | C18: Forecast | D18: 1346.32 | E18: 1379.2961 | F18: 1523.3626 | G18: 1628.7088 | H18: 1634.9611 | I18: 1628.978 | J18: 1538.0996 | K18: 1470.9891 | L18: 1388.7794 | M18: 1335.1077 | N18: 1314.4614 | O18: 1308.902 | P18: 1330.1977 | Q18: 1349.1277 | R18: 1370.5834 | S18: 1381.8493 | T18: 1380.4775 | U18: 1370.1813 | V18: 1349.2702 | W18: 1326.6261 | X18: 1303.7347 | Y18: 1285.6809 | Z18: 1274.3994 | AA18: 1269.3067 | AB18: 1270.0246 | AC18: 1273.0605 | AD18: 1276.4329 | AE18: 1277.6826 | AF18: 1275.6965 | AG18: 1270.6203 | AH18: 1263.0616 | AI18: 1254.591 | AJ18: 1246.4259 | AK18: 1239.6864 | AL18: 1234.8911 | AM18: 1231.9775 | AN18: 1230.5615 | AO18: 1229.9264 | AP18: 1229.4268 | AQ18: 1228.5131 | AR18: 1226.8964 | AS18: 1224.5594 | AT18: 1221.6776 | AU18: 1218.5796 | AV18: 1215.6 | AW18: 1213.022 | AX18: 1211.0043 | AY18: 1209.5644 | AZ18: 1208.6059 | BA18: 1207.9539 | BB18: 1207.4207 | BC18: 1206.8493 | BD18: 1206.1481 | BE18: 1205.3008 | BF18: 1204.3526 | BG18: 1203.3883 | BH18: 1202.5001 | BI18: 1201.7634 | BJ18: 1201.2207 | BK18: 1200.8765 | BL18: 1200.7039 | BM18: 1200.6563 | BN18: 1200.6827 | BO18: 1200.7402 | BP18: 1200.8022 | BQ18: 1200.8614 | BR18: 1200.927 | BS18: 1201.0188 | BT18: 1201.1598 | BU18: 1201.3693 | BV18: 1201.6585 | BW18: 1202.0288 | BX18: 1202.4729 | BY18: 1202.978 | BZ18: 1203.5294 | CA18: 1204.1143 | CB18: 1204.7243 | CC18: 1205.356 | CD18: 1206.0108 | CE18: 1206.693 | CF18: 1207.4081 | CG18: 1208.1605 | CH18: 1208.9527 | CI18: 1209.7847 | CJ18: 1210.6539 | CK18: 1211.5565 | CL18: 1212.4879 | CM18: 1213.4442 | CN18: 1214.4223 | CO18: 1215.4208 | CP18: 1216.4394 | CQ18: 1217.4787 | CR18: 1218.5396 | CS18: 1219.6228 | CT18: 1220.7286 | CU18: 1221.8566 | CV18: 1 | CW18: 1 | CX18: 12
C19: Actual | CV19: 0 | CW19: 0 | CX19: 0
A20: Ac1202 | B20: desl | C20: Forecast | D20: 1851.9404 | E20: 1770.2276 | F20: 1801.1693 | G20: 1630.3924 | H20: 1670.5878 | I20: 1596.3179 | J20: 1585.1338 | K20: 1583.7567 | L20: 1538.2506 | M20: 1542.7769 | N20: 1503.8192 | O20: 1497.6911 | P20: 1483.9862 | Q20: 1471.3549 | R20: 1466.9974 | S20: 1447.9043 | T20: 1435.3893 | U20: 1414.0148 | V20: 1395.5055 | W20: 1379.4823 | X20: 1364.6289 | Y20: 1355.4971 | Z20: 1346.0305 | AA20: 1338.7289 | AB20: 1330.4955 | AC20: 1321.4853 | AD20: 1312.3682 | AE20: 1302.4208 | AF20: 1293.1615 | AG20: 1283.984 | AH20: 1275.4874 | AI20: 1267.5831 | AJ20: 1260.1413 | AK20: 1253.409 | AL20: 1247.1025 | AM20: 1241.3499 | AN20: 1235.925 | AO20: 1230.7126 | AP20: 1225.6237 | AQ20: 1220.5406 | AR20: 1215.5376 | AS20: 1210.6451 | AT20: 1205.986 | AU20: 1201.6371 | AV20: 1197.6308 | AW20: 1193.9708 | AX20: 1190.597 | AY20: 1187.4572 | AZ20: 1184.4887 | BA20: 1181.6535 | BB20: 1178.9357 | BC20: 1176.3321 | BD20: 1173.8567 | BE20: 1171.5212 | BF20: 1169.3398 | BG20: 1167.3202 | BH20: 1165.4645 | BI20: 1163.7693 | BJ20: 1162.2247 | BK20: 1160.818 | BL20: 1159.5341 | BM20: 1158.3593 | BN20: 1157.2833 | BO20: 1156.3002 | BP20: 1155.4088 | BQ20: 1154.6105 | BR20: 1153.9081 | BS20: 1153.3036 | BT20: 1152.7966 | BU20: 1152.3842 | BV20: 1152.0616 | BW20: 1151.8227 | BX20: 1151.6613 | BY20: 1151.5723 | BZ20: 1151.5515 | CA20: 1151.5961 | CB20: 1151.7046 | CC20: 1151.8758 | CD20: 1152.109 | CE20: 1152.403 | CF20: 1152.7565 | CG20: 1153.1676 | CH20: 1153.6339 | CI20: 1154.1528 | CJ20: 1154.7216 | CK20: 1155.338 | CL20: 1155.9996 | CM20: 1156.7048 | CN20: 1157.4519 | CO20: 1158.24 | CP20: 1159.0678 | CQ20: 1159.9343 | CR20: 1160.8384 | CS20: 1161.7787 | CT20: 1162.7539 | CU20: 1163.7625 | CV20: -1 | CW20: 1 | CX20: 12
C21: Actual | CV21: 0 | CW21: 0 | CX21: 0
A22: Am1301 | B22: adm | C22: Forecast | D22: 20.57114 | E22: 27.653351 | F22: 33.591843 | G22: 30.158634 | H22: 26.779868 | I22: 28.438469 | J22: 24.279521 | K22: 26.136799 | L22: 25.028429 | M22: 25.367057 | N22: 25.860524 | O22: 24.953484 | P22: 25.352419 | Q22: 24.520757 | R22: 24.51491 | S22: 24.217185 | T22: 23.85015 | U22: 23.717568 | V22: 23.221395 | W22: 22.999849 | X22: 22.634648 | Y22: 22.408494 | Z22: 22.271379 | AA22: 22.122016 | AB22: 22.057999 | AC22: 21.905742 | AD22: 21.754442 | AE22: 21.552719 | AF22: 21.330705 | AG22: 21.127338 | AH22: 20.926516 | AI22: 20.766072 | AJ22: 20.61969 | AK22: 20.492911 | AL22: 20.375691 | AM22: 20.258607 | AN22: 20.146251 | AO22: 20.030415 | AP22: 19.916331 | AQ22: 19.801317 | AR22: 19.686505 | AS22: 19.574055 | AT22: 19.464066 | AU22: 19.360134 | AV22: 19.262492 | AW22: 19.172208 | AX22: 19.088399 | AY22: 19.009192 | AZ22: 18.933055 | BA22: 18.858051 | BB22: 18.783666 | BC22: 18.709793 | BD22: 18.637095 | BE22: 18.566502 | BF22: 18.498686 | BG22: 18.434169 | BH22: 18.372949 | BI22: 18.31482 | BJ22: 18.259367 | BK22: 18.206127 | BL22: 18.154724 | BM22: 18.104844 | BN22: 18.056328 | BO22: 18.009115 | BP22: 17.963247 | BQ22: 17.91883 | BR22: 17.87598 | BS22: 17.834797 | BT22: 17.795311 | BU22: 17.757484 | BV22: 17.721209 | BW22: 17.686334 | BX22: 17.652704 | BY22: 17.620186 | BZ22: 17.588691 | CA22: 17.558179 | CB22: 17.528646 | CC22: 17.500108 | CD22: 17.472582 | CE22: 17.446074 | CF22: 17.420567 | CG22: 17.396027 | CH22: 17.372402 | CI22: 17.349636 | CJ22: 17.327672 | CK22: 17.306462 | CL22: 17.285965 | CM22: 17.266155 | CN22: 17.247012 | CO22: 17.228524 | CP22: 17.21068 | CQ22: 17.193469 | CR22: 17.176874 | CS22: 17.160874 | CT22: 17.145446 | CU22: 17.130562 | CV22: 1 | CW22: 1 | CX22: 13
C23: Actual | CV23: 0 | CW23: 0 | CX23: 0
A24: Am1301 | B24: desl | C24: Forecast | D24: 36.580924 | E24: 38.527885 | F24: 32.243856 | G24: 30.42985 | H24: 31.397536 | I24: 28.674524 | J24: 31.353747 | K24: 30.590702 | L24: 31.637135 | M24: 31.903292 | N24: 31.258334 | O24: 31.427053 | P24: 30.382727 | Q24: 30.094884 | R24: 29.342084 | S24: 28.759256 | T24: 28.413671 | U24: 27.962448 | V24: 27.890834 | W24: 27.730514 | X24: 27.721589 | Y24: 27.676499 | Z24: 27.540386 | AA24: 27.375396 | AB24: 27.077842 | AC24: 26.778955 | AD24: 26.452761 | AE24: 26.162644 | AF24: 25.93048 | AG24: 25.739803 | AH24: 25.605761 | AI24: 25.487779 | AJ24: 25.382414 | AK24: 25.269152 | AL24: 25.1399 | AM24: 24.997934 | AN24: 24.840939 | AO24: 24.68054 | AP24: 24.520715 | AQ24: 24.369493 | AR24: 24.231548 | AS24: 24.107618 | AT24: 23.998037 | AU24: 23.898398 | AV24: 23.805088 | AW24: 23.713499 | AX24: 23.620475 | AY24: 23.524914 | AZ24: 23.426961 | BA24: 23.328653 | BB24: 23.232145 | BC24: 23.139637 | BD24: 23.052509 | BE24: 22.971104 | BF24: 22.894999 | BG24: 22.823053 | BH24: 22.754017 | BI24: 22.686718 | BJ24: 22.620366 | BK24: 22.554635 | BL24: 22.489591 | BM24: 22.425623 | BN24: 22.36323 | BO24: 22.302889 | BP24: 22.244924 | BQ24: 22.189436 | BR24: 22.136314 | BS24: 22.085276 | BT24: 22.035963 | BU24: 21.988024 | BV24: 21.94119 | BW24: 21.895314 | BX24: 21.850372 | BY24: 21.806434 | BZ24: 21.763614 | CA24: 21.722024 | CB24: 21.681731 | CC24: 21.642744 | CD24: 21.605009 | CE24: 21.568429 | CF24: 21.532885 | CG24: 21.498263 | CH24: 21.464472 | CI24: 21.431454 | CJ24: 21.399181 | CK24: 21.367651 | CL24: 21.336876 | CM24: 21.306867 | CN24: 21.277628 | CO24: 21.249147 | CP24: 21.221397 | CQ24: 21.194338 | CR24: 21.167928 | CS24: 21.14212 | CT24: 21.116878 | CU24: 21.092172 | CV24: -1 | CW24: 1 | CX24: 13
C25: Actual | CV25: 0 | CW25: 0 | CX25: 0
A26: Am1302 | B26: adm | C26: Forecast | D26: 21.5856 | E26: 21.047007 | F26: 23.625159 | G26: 23.80825 | H26: 22.935351 | I26: 22.97805 | J26: 20.90142 | K26: 20.28191 | L26: 19.016717 | M26: 18.308703 | N26: 18.12814 | O26: 17.933537 | P26: 18.408916 | Q26: 18.681242 | R26: 19.110556 | S26: 19.310713 | T26: 19.245105 | U26: 19.04507 | V26: 18.608063 | W26: 18.205893 | X26: 17.815909 | Y26: 17.557222 | Z26: 17.441096 | AA26: 17.418193 | AB26: 17.484196 | AC26: 17.550587 | AD26: 17.603162 | AE26: 17.604653 | AF26: 17.549972 | AG26: 17.454025 | AH26: 17.325194 | AI26: 17.193264 | AJ26: 17.071361 | AK26: 16.976037 | AL26: 16.913057 | AM26: 16.879108 | AN26: 16.868271 | AO26: 16.867112 | AP26: 16.865529 | AQ26: 16.854249 | AR26: 16.829311 | AS26: 16.79191 | AT26: 16.746138 | AU26: 16.698829 | AV26: 16.655788 | AW26: 16.621445 | AX26: 16.597483 | AY26: 16.583026 | AZ26: 16.575623 | BA26: 16.571859 | BB26: 16.568714 | BC26: 16.563978 | BD26: 16.556704 | BE26: 16.547141 | BF26: 16.536362 | BG26: 16.525903 | BH26: 16.517224 | BI26: 16.511414 | BJ26: 16.508965 | BK26: 16.509755 | BL26: 16.51319 | BM26: 16.518413 | BN26: 16.524568 | BO26: 16.530992 | BP26: 16.537342 | BQ26: 16.543609 | BR26: 16.550047 | BS26: 16.55705 | BT26: 16.565014 | BU26: 16.574231 | BV26: 16.584829 | BW26: 16.596763 | BX26: 16.609858 | BY26: 16.62387 | BZ26: 16.638552 | CA26: 16.653714 | CB26: 16.669246 | CC26: 16.685129 | CD26: 16.70141 | CE26: 16.718176 | CF26: 16.735518 | CG26: 16.753504 | CH26: 16.772159 | CI26: 16.791467 | CJ26: 16.811374 | CK26: 16.831808 | CL26: 16.852691 | CM26: 16.873962 | CN26: 16.895579 | CO26: 16.917526 | CP26: 16.939805 | CQ26: 16.962432 | CR26: 16.985421 | CS26: 17.008786 | CT26: 17.032525 | CU26: 17.05663 | CV26: 1 | CW26: 1 | CX26: 13
C27: Actual | CV27: 0 | CW27: 0 | CX27: 0
A28: Am1302 | B28: desl | C28: Forecast | D28: 30.184879 | E28: 27.172164 | F28: 28.005691 | G28: 26.551151 | H28: 27.606337 | I28: 27.513428 | J28: 27.824184 | K28: 28.501935 | L28: 28.203672 | M28: 28.374024 | N28: 27.798229 | O28: 27.408673 | P28: 26.94631 | Q28: 26.467676 | R28: 26.270197 | S28: 26.033283 | T28: 26.024342 | U28: 26.007799 | V28: 26.021 | W28: 26.032489 | X28: 25.961624 | Y28: 25.876675 | Z28: 25.718356 | AA28: 25.547568 | AB28: 25.367613 | AC28: 25.19747 | AD28: 25.06487 | AE28: 24.958249 | AF28: 24.88976 | AG28: 24.840029 | AH28: 24.800692 | AI28: 24.760355 | AJ28: 24.707759 | AK28: 24.643769 | AL28: 24.5667 | AM28: 24.483914 | AN28: 24.400925 | AO28: 24.323449 | AP28: 24.256039 | AQ28: 24.199084 | AR28: 24.152319 | AS28: 24.112586 | AT28: 24.076801 | AU28: 24.041967 | AV28: 24.005809 | AW28: 23.967646 | AX28: 23.927583 | AY28: 23.886882 | AZ28: 23.847044 | BA28: 23.809544 | BB28: 23.77547 | BC28: 23.745197 | BD28: 23.718563 | BE28: 23.694861 | BF28: 23.673197 | BG28: 23.652695 | BH28: 23.6327 | BI28: 23.612913 | BJ28: 23.593349 | BK28: 23.574288 | BL28: 23.556122 | BM28: 23.539233 | BN28: 23.523888 | BO28: 23.51018 | BP28: 23.498042 | BQ28: 23.487276 | BR28: 23.477625 | BS28: 23.468837 | BT28: 23.460719 | BU28: 23.453163 | BV28: 23.44615 | BW28: 23.439727 | BX28: 23.433978 | BY28: 23.428989 | BZ28: 23.424819 | CA28: 23.421483 | CB28: 23.418952 | CC28: 23.417165 | CD28: 23.41604 | CE28: 23.415497 | CF28: 23.415467 | CG28: 23.41591 | CH28: 23.416805 | CI28: 23.418154 | CJ28: 23.419967 | CK28: 23.422257 | CL28: 23.425031 | CM28: 23.428284 | CN28: 23.431999 | CO28: 23.436153 | CP28: 23.440715 | CQ28: 23.445655 | CR28: 23.450947 | CS28: 23.456572 | CT28: 23.462516 | CU28: 23.468772 | CV28: -1 | CW28: 1 | CX28: 13
C29: Actual | CV29: 0 | CW29: 0 | CX29: 0
A30: Am1303 | B30: adm | C30: Forecast | D30: 8134.5837 | E30: 7418.0982 | F30: 8015.1295 | G30: 8167.6662 | H30: 7984.3458 | I30: 7956.2369 | J30: 7260.9462 | K30: 7037.5045 | L30: 6633.1164 | M30: 6583.8764 | N30: 6805.3284 | O30: 7128.641 | P30: 7647.7099 | Q30: 8015.782 | R30: 8327.5498 | S30: 8454.4497 | T30: 8445.616 | U30: 8380.4505 | V30: 8273.5072 | W30: 8226.6457 | X30: 8225.1329 | Y30: 8293.1036 | Z30: 8410.2758 | AA30: 8549.6061 | AB30: 8700.497 | AC30: 8832.9636 | AD30: 8944.0251 | AE30: 9023.4263 | AF30: 9074.0011 | AG30: 9104.1357 | AH30: 9121.8228 | AI30: 9141.176 | AJ30: 9169.4759 | AK30: 9212.9446 | AL30: 9271.2546 | AM30: 9339.6841 | AN30: 9411.982 | AO30: 9480.5944 | AP30: 9540.9329 | AQ30: 9590.6022 | AR30: 9630.4375 | AS30: 9663.3573 | AT30: 9692.9229 | AU30: 9722.6742 | AV30: 9754.8201 | AW30: 9790.3477 | AX30: 9828.8995 | AY30: 9869.23 | AZ30: 9909.7514 | BA30: 9948.8844 | BB30: 9985.5233 | BC30: 10019.125 | BD30: 10049.781 | BE30: 10078.074 | BF30: 10104.855 | BG30: 10131.017 | BH30: 10157.253 | BI30: 10183.94 | BJ30: 10211.101 | BK30: 10238.464 | BL30: 10265.603 | BM30: 10292.07 | BN30: 10317.532 | BO30: 10341.831 | BP30: 10364.997 | BQ30: 10387.207 | BR30: 10408.715 | BS30: 10429.775 | BT30: 10450.582 | BU30: 10471.244 | BV30: 10491.774 | BW30: 10512.113 | BX30: 10532.161 | BY30: 10551.812 | BZ30: 10570.989 | CA30: 10589.654 | CB30: 10607.818 | CC30: 10625.529 | CD30: 10642.856 | CE30: 10659.875 | CF30: 10676.645 | CG30: 10693.207 | CH30: 10709.572 | CI30: 10725.733 | CJ30: 10741.67 | CK30: 10757.359 | CL30: 10772.782 | CM30: 10787.935 | CN30: 10802.823 | CO30: 10817.464 | CP30: 10831.881 | CQ30: 10846.098 | CR30: 10860.136 | CS30: 10874.009 | CT30: 10887.725 | CU30: 10901.287 | CV30: 1 | CW30: 1 | CX30: 13
C31: Actual | CV31: 0 | CW31: 0 | CX31: 0
A32: Am1303 | B32: desl | C32: Forecast | D32: 12971.077 | E32: 12691.969 | F32: 12666.568 | G32: 11770.487 | H32: 11825.135 | I32: 11184.618 | J32: 10950.693 | K32: 10789.858 | L32: 10475.456 | M32: 10480.665 | N32: 10341.393 | O32: 10456.424 | P32: 10557.926 | Q32: 10662.642 | R32: 10754.088 | S32: 10702.064 | T32: 10622.359 | U32: 10455.602 | V32: 10299.135 | W32: 10173.633 | X32: 10090.109 | Y32: 10070.848 | Z32: 10074.278 | AA32: 10099.807 | AB32: 10117.266 | AC32: 10119.899 | AD32: 10106.843 | AE32: 10075.253 | AF32: 10036.241 | AG32: 9990.9817 | AH32: 9947.5056 | AI32: 9909.1818 | AJ32: 9878.4053 | AK32: 9857.6889 | AL32: 9845.117 | AM32: 9839.4255 | AN32: 9836.5266 | AO32: 9832.9988 | AP32: 9826.2387 | AQ32: 9814.8127 | AR32: 9799.5712 | AS32: 9782.0793 | AT32: 9764.7838 | AU32: 9749.6669 | AV32: 9737.907 | AW32: 9729.7922 | AX32: 9724.6551 | AY32: 9721.4914 | AZ32: 9719.1378 | BA32: 9716.7 | BB32: 9713.6655 | BC32: 9709.9031 | BD32: 9705.6363 | BE32: 9701.2573 | BF32: 9697.2397 | BG32: 9693.9923 | BH32: 9691.7855 | BI32: 9690.7148 | BJ32: 9690.6929 | BK32: 9691.5065 | BL32: 9692.8751 | BM32: 9694.5326 | BN32: 9696.2878 | BO32: 9698.0562 | BP32: 9699.862 | BQ32: 9701.8059 | BR32: 9704.0225 | BS32: 9706.6344 | BT32: 9709.7194 | BU32: 9713.2972 | BV32: 9717.3335 | BW32: 9721.7579 | BX32: 9726.4866 | BY32: 9731.4435 | BZ32: 9736.575 | CA32: 9741.8558 | CB32: 9747.2871 | CC32: 9752.8885 | CD32: 9758.6879 | CE32: 9764.711 | CF32: 9770.9743 | CG32: 9777.4803 | CH32: 9784.2185 | CI32: 9791.1683 | CJ32: 9798.3043 | CK32: 9805.6021 | CL32: 9813.0427 | CM32: 9820.6144 | CN32: 9828.3133 | CO32: 9836.1411 | CP32: 9844.1024 | CQ32: 9852.2017 | CR32: 9860.4408 | CS32: 9868.818 | CT32: 9877.328 | CU32: 9885.9627 | CV32: -1 | CW32: 1 | CX32: 13
C33: Actual | CV33: 0 | CW33: 0 | CX33: 0
