Workbook

Sheet CF-8
A1: GVAR Conditional Forecasts
A2: Last in-sample estimation date: | B2: 2017M07
A3: Last forecast date: | B3: 2025M7
D5: 2017M8 | E5: 2017M9 | F5: 2017M10 | G5: 2017M11 | H5: 2017M12 | I5: 2018M1 | J5: 2018M2 | K5: 2018M3 | L5: 2018M4 | M5: 2018M5 | N5: 2018M6 | O5: 2018M7 | P5: 2018M8 | Q5: 2018M9 | R5: 2018M10 | S5: 2018M11 | T5: 2018M12 | U5: 2019M1 | V5: 2019M2 | W5: 2019M3 | X5: 2019M4 | Y5: 2019M5 | Z5: 2019M6 | AA5: 2019M7 | AB5: 2019M8 | AC5: 2019M9 | AD5: 2019M10 | AE5: 2019M11 | AF5: 2019M12 | AG5: 2020M1 | AH5: 2020M2 | AI5: 2020M3 | AJ5: 2020M4 | AK5: 2020M5 | AL5: 2020M6 | AM5: 2020M7 | AN5: 2020M8 | AO5: 2020M9 | AP5: 2020M10 | AQ5: 2020M11 | AR5: 2020M12 | AS5: 2021M1 | AT5: 2021M2 | AU5: 2021M3 | AV5: 2021M4 | AW5: 2021M5 | AX5: 2021M6 | AY5: 2021M7 | AZ5: 2021M8 | BA5: 2021M9 | BB5: 2021M10 | BC5: 2021M11 | BD5: 2021M12 | BE5: 2022M1 | BF5: 2022M2 | BG5: 2022M3 | BH5: 2022M4 | BI5: 2022M5 | BJ5: 2022M6 | BK5: 2022M7 | BL5: 2022M8 | BM5: 2022M9 | BN5: 2022M10 | BO5: 2022M11 | BP5: 2022M12 | BQ5: 2023M1 | BR5: 2023M2 | BS5: 2023M3 | BT5: 2023M4 | BU5: 2023M5 | BV5: 2023M6 | BW5: 2023M7 | BX5: 2023M8 | BY5: 2023M9 | BZ5: 2023M10 | CA5: 2023M11 | CB5: 2023M12 | CC5: 2024M1 | CD5: 2024M2 | CE5: 2024M3 | CF5: 2024M4 | CG5: 2024M5 | CH5: 2024M6 | CI5: 2024M7 | CJ5: 2024M8 | CK5: 2024M9 | CL5: 2024M10 | CM5: 2024M11 | CN5: 2024M12 | CO5: 2025M1 | CP5: 2025M2 | CQ5: 2025M3 | CR5: 2025M4 | CS5: 2025M5 | CT5: 2025M6 | CU5: 2025M7 | CW5: Seletor
A6: Ro1101 | B6: adm | C6: Forecast | D6: 3522.6097 | E6: 3185.2505 | F6: 2661.399 | G6: 2479.0046 | H6: 1494.6504 | I6: 2176.8476 | J6: 1997.199 | K6: 2887.4807 | L6: 2833.5398 | M6: 3228.2945 | N6: 3556.1829 | O6: 3589.5216 | P6: 3958.7321 | Q6: 3738.7278 | R6: 3196.2822 | S6: 3048.0934 | T6: 2117.0213 | U6: 2859.3494 | V6: 2771.5728 | W6: 3758.8528 | X6: 3804.5796 | Y6: 4293.604 | Z6: 4702.4235 | AA6: 4802.8899 | AB6: 5225.9376 | AC6: 5049.4917 | AD6: 4544.5204 | AE6: 4431.0211 | AF6: 3534.0993 | AG6: 4311.1633 | AH6: 4259.1054 | AI6: 5283.1475 | AJ6: 5366.5934 | AK6: 5894.1166 | AL6: 6341.9015 | AM6: 6481.3254 | AN6: 6942.7388 | AO6: 6803.4903 | AP6: 6334.1168 | AQ6: 6254.4177 | AR6: 5389.5379 | AS6: 6197.0953 | AT6: 6174.2598 | AU6: 7226.5074 | AV6: 7337.3195 | AW6: 7891.4619 | AX6: 8365.1487 | AY6: 8529.7556 | AZ6: 9015.6251 | BA6: 8900.1026 | BB6: 8453.7259 | BC6: 8396.2945 | BD6: 7552.9495 | BE6: 8381.3004 | BF6: 8378.5076 | BG6: 9450.0382 | BH6: 9579.3694 | BI6: 10151.271 | BJ6: 10641.972 | BK6: 10822.88 | BL6: 11324.388 | BM6: 11223.896 | BN6: 10791.995 | BO6: 10748.518 | BP6: 9918.6092 | BQ6: 10759.866 | BR6: 10769.44 | BS6: 11852.819 | BT6: 11993.54 | BU6: 12576.449 | BV6: 13077.811 | BW6: 13268.959 | BX6: 13780.071 | BY6: 13688.231 | BZ6: 13263.738 | CA6: 13226.325 | CB6: 12401.349 | CC6: 13246.983 | CD6: 13261.081 | CE6: 14349.677 | CF6: 14496.619 | CG6: 15086.265 | CH6: 15594.564 | CI6: 15792.9 | CJ6: 16310.35 | CK6: 16228.056 | CL6: 15813.525 | CM6: 15782.386 | CN6: 14978.889 | CO6: 15808.603 | CP6: 15808.397 | CQ6: 16917.465 | CR6: 16933.678 | CS6: 17772.005 | CT6: 18052.567 | CU6: 17984.346 | CW6: 1
C7: Actual | CW7: 0
A8: Ro1101 | B8: desl | C8: Forecast | D8: 3027.8475 | E8: 2876.8587 | F8: 3023.9026 | G8: 2967.2786 | H8: 2767.0062 | I8: 2556.0882 | J8: 2407.2476 | K8: 2647.3818 | L8: 2434.7491 | M8: 2929.9851 | N8: 2684.219 | O8: 2884.3453 | P8: 3014.1663 | Q8: 3026.0636 | R8: 3240.01 | S8: 3295.7384 | T8: 3204.6501 | U8: 3108.8009 | V8: 3081.1128 | W8: 3449.256 | X8: 3364.0881 | Y8: 3981.4229 | Z8: 3846.5155 | AA8: 4143.9015 | AB8: 4357.1364 | AC8: 4440.8673 | AD8: 4717.9703 | AE8: 4831.0521 | AF8: 4793.7531 | AG8: 4749.5392 | AH8: 4772.1 | AI8: 5189.5393 | AJ8: 5153.0057 | AK8: 5818.5224 | AL8: 5731.4183 | AM8: 6076.1059 | AN8: 6335.8347 | AO8: 6464.8489 | AP8: 6785.6484 | AQ8: 6940.5943 | AR8: 6943.2604 | AS8: 6937.2055 | AT8: 6996.3067 | AU8: 7448.8741 | AV8: 7446.226 | AW8: 8144.4977 | AX8: 8089.0785 | AY8: 8464.4109 | AZ8: 8753.7633 | BA8: 8911.3988 | BB8: 9259.837 | BC8: 9441.4569 | BD8: 9469.845 | BE8: 9488.5674 | BF8: 9571.5048 | BG8: 10046.969 | BH8: 10066.282 | BI8: 10785.581 | BJ8: 10750.268 | BK8: 11144.805 | BL8: 11452.499 | BM8: 11627.663 | BN8: 11992.872 | BO8: 12190.55 | BP8: 12234.3 | BQ8: 12267.677 | BR8: 12364.536 | BS8: 12853.176 | BT8: 12884.946 | BU8: 13616.062 | BV8: 13592.012 | BW8: 13997.305 | BX8: 14315.175 | BY8: 14499.733 | BZ8: 14873.278 | CA8: 15078.015 | CB8: 15127.547 | CC8: 15165.726 | CD8: 15266.966 | CE8: 15760.14 | CF8: 15796.949 | CG8: 16533.446 | CH8: 16514.414 | CI8: 16923.946 | CJ8: 17244.783 | CK8: 17431.257 | CL8: 17808.314 | CM8: 18016.538 | CN8: 18072.609 | CO8: 18115.079 | CP8: 18203.459 | CQ8: 18696.218 | CR8: 18705.931 | CS8: 19327.364 | CT8: 19413.353 | CU8: 20006.131 | CW8: -1
C9: Actual | CW9: 0
A10: Ro1102 | B10: adm | C10: Forecast | D10: 6029.3631 | E10: 5137.0331 | F10: 4439.4159 | G10: 4429.5442 | H10: 3555.0401 | I10: 4557.748 | J10: 4219.2089 | K10: 5294.1154 | L10: 4919.7559 | M10: 5207.8969 | N10: 5318.2801 | O10: 4922.9317 | P10: 5139.6881 | Q10: 4710.6734 | R10: 4207.4396 | S10: 4390.0307 | T10: 3691.7087 | U10: 4845.8169 | V10: 4657.4476 | W10: 5856.1241 | X10: 5588.231 | Y10: 5961.0634 | Z10: 6131.4181 | AA10: 5776.7636 | AB10: 6020.2059 | AC10: 5610.9865 | AD10: 5127.2122 | AE10: 5332.3336 | AF10: 4660.4885 | AG10: 5844.2086 | AH10: 5687.1544 | AI10: 6917.5847 | AJ10: 6681.1079 | AK10: 7084.6743 | AL10: 7284.8963 | AM10: 6959.0004 | AN10: 7229.7465 | AO10: 6846.0394 | AP10: 6385.8217 | AQ10: 6612.6411 | AR10: 5960.9646 | AS10: 7163.766 | AT10: 7025.1151 | AU10: 8273.5421 | AV10: 8054.7556 | AW10: 8475.6712 | AX10: 8692.8007 | AY10: 8383.2696 | AZ10: 8669.7731 | BA10: 8301.1934 | BB10: 7855.4789 | BC10: 8096.1947 | BD10: 7457.826 | BE10: 8673.3605 | BF10: 8546.8772 | BG10: 9806.9084 | BH10: 9599.1576 | BI10: 10030.532 | BJ10: 10257.544 | BK10: 9957.3477 | BL10: 10252.701 | BM10: 9892.577 | BN10: 9455.0101 | BO10: 9703.6027 | BP10: 9072.7982 | BQ10: 10295.472 | BR10: 10175.58 | BS10: 11441.601 | BT10: 11239.322 | BU10: 11675.859 | BV10: 11907.943 | BW10: 11612.785 | BX10: 11912.9 | BY10: 11556.725 | BZ10: 11121.685 | CA10: 11371.067 | CB10: 10739.628 | CC10: 11961.323 | CD10: 11841.513 | CE10: 13109.78 | CF10: 12912.052 | CG10: 13353.864 | CH10: 13590.024 | CI10: 13295.747 | CJ10: 13592.131 | CK10: 13233.261 | CL10: 12794.048 | CM10: 13043.508 | CN10: 12430.284 | CO10: 13633.631 | CP10: 13510.767 | CQ10: 14763.643 | CR10: 14392.315 | CS10: 15053.518 | CT10: 14974.103 | CU10: 14692.274 | CW10: 1
C11: Actual | CW11: 0
A12: Ro1102 | B12: desl | C12: Forecast | D12: 4901.9121 | E12: 4393.4724 | F12: 4802.8997 | G12: 4879.4422 | H12: 4792.9151 | I12: 4429.6368 | J12: 4296.9644 | K12: 4960.1204 | L12: 4059.5854 | M12: 4976.5356 | N12: 4127.6485 | O12: 4005.138 | P12: 4352.8898 | Q12: 4026.6267 | R12: 4630.7534 | S12: 4884.079 | T12: 4960.4716 | U12: 4743.1479 | V12: 4727.1074 | W12: 5502.0801 | X12: 4696.486 | Y12: 5689.6646 | Z12: 4901.1363 | AA12: 4825.8136 | AB12: 5213.314 | AC12: 4924.7091 | AD12: 5567.0215 | AE12: 5859.4968 | AF12: 5975.2515 | AG12: 5796.4409 | AH12: 5817.2896 | AI12: 6627.3595 | AJ12: 5855.3665 | AK12: 6881.0424 | AL12: 6124.0984 | AM12: 6079.3359 | AN12: 6496.082 | AO12: 6235.1554 | AP12: 6903.5124 | AQ12: 7220.5479 | AR12: 7359.6677 | AS12: 7203.3327 | AT12: 7245.9845 | AU12: 8077.2698 | AV12: 7325.8799 | AW12: 8371.4719 | AX12: 7633.69 | AY12: 7607.3085 | AZ12: 8041.6676 | BA12: 7797.6211 | BB12: 8482.1621 | BC12: 8814.7132 | BD12: 8968.6985 | BE12: 8826.5908 | BF12: 8882.8393 | BG12: 9727.0919 | BH12: 8988.0341 | BI12: 10045.316 | BJ12: 9318.5903 | BK12: 9302.6667 | BL12: 9746.9555 | BM12: 9512.3956 | BN12: 10206.043 | BO12: 10547.317 | BP12: 10709.563 | BQ12: 10575.12 | BR12: 10638.329 | BS12: 11488.839 | BT12: 10755.481 | BU12: 11818.153 | BV12: 11096.714 | BW12: 11085.972 | BX12: 11535.032 | BY12: 11304.302 | BZ12: 12000.354 | CA12: 12342.54 | CB12: 12504.792 | CC12: 12370.577 | CD12: 12435.442 | CE12: 13289.575 | CF12: 12561.082 | CG12: 13627.92 | CH12: 12907.302 | CI12: 12892.725 | CJ12: 13334.723 | CK12: 13094.763 | CL12: 13786.7 | CM12: 14132.849 | CN12: 14298.149 | CO12: 14169.767 | CP12: 14216.076 | CQ12: 15022.989 | CR12: 14309.029 | CS12: 15004.604 | CT12: 14575.378 | CU12: 15332.037 | CW12: -1
C13: Actual | CW13: 0
A14: Ac1201 | B14: adm | C14: Forecast | D14: 198.49594 | E14: 144.11947 | F14: 115.42723 | G14: 108.54698 | H14: 64.190599 | I14: 92.845479 | J14: 65.835985 | K14: 117.33493 | L14: 122.15502 | M14: 149.29868 | N14: 166.07288 | O14: 142.97887 | P14: 150.77343 | Q14: 124.86116 | R14: 106.29033 | S14: 109.9962 | T14: 70.435095 | U14: 104.72886 | V14: 84.142911 | W14: 142.71383 | X14: 155.61478 | Y14: 190.30032 | Z14: 213.28368 | AA14: 194.5459 | AB14: 204.71984 | AC14: 179.62813 | AD14: 160.92788 | AE14: 164.16545 | AF14: 124.2829 | AG14: 158.67668 | AH14: 138.70102 | AI14: 198.35832 | AJ14: 212.73411 | AK14: 249.18679 | AL14: 274.13946 | AM14: 257.48637 | AN14: 269.77256 | AO14: 246.73558 | AP14: 229.96152 | AQ14: 234.95212 | AR14: 196.63803 | AS14: 232.43509 | AT14: 213.73662 | AU14: 274.5894 | AV14: 290.11612 | AW14: 327.69854 | AX14: 353.76895 | AY14: 338.22051 | AZ14: 351.59217 | BA14: 329.61471 | BB14: 313.86889 | BC14: 319.85299 | BD14: 282.49552 | BE14: 319.21064 | BF14: 301.39001 | BG14: 363.07859 | BH14: 379.39725 | BI14: 417.72644 | BJ14: 444.4984 | BK14: 429.60844 | BL14: 443.60027 | BM14: 422.21145 | BN14: 407.02969 | BO14: 413.55769 | BP14: 376.7237 | BQ14: 413.93686 | BR14: 396.58204 | BS14: 458.70055 | BT14: 475.41725 | BU14: 514.1245 | BV14: 541.26858 | BW14: 526.75027 | BX14: 541.10005 | BY14: 520.02082 | BZ14: 505.05479 | CA14: 511.67039 | CB14: 474.79724 | CC14: 511.89632 | CD14: 494.43867 | CE14: 556.55331 | CF14: 573.41023 | CG14: 612.35463 | CH14: 639.7482 | CI14: 625.38862 | CJ14: 639.72793 | CK14: 618.72007 | CL14: 603.83651 | CM14: 610.84907 | CN14: 575.17925 | CO14: 611.75601 | CP14: 594.31018 | CQ14: 655.09536 | CR14: 662.88751 | CS14: 709.45294 | CT14: 727.74577 | CU14: 728.35703 | CW14: 1
C15: Actual | CW15: 0
A16: Ac1201 | B16: desl | C16: Forecast | D16: 166.81955 | E16: 155.88785 | F16: 176.21354 | G16: 176.57935 | H16: 186.1051 | I16: 168.48317 | J16: 157.14191 | K16: 150.33865 | L16: 105.27933 | M16: 136.70158 | N16: 105.38851 | O16: 113.98482 | P16: 129.7727 | Q16: 119.12989 | R16: 153.30491 | S16: 166.00406 | T16: 184.49364 | U16: 175.4518 | V16: 170.84925 | W16: 169.93373 | X16: 130.12833 | Y16: 166.7897 | Z16: 140.83019 | AA16: 154.65718 | AB16: 175.36739 | AC16: 169.17924 | AD16: 207.26663 | AE16: 223.38452 | AF16: 244.89709 | AG16: 238.57816 | AH16: 236.47003 | AI16: 237.8614 | AJ16: 200.19758 | AK16: 238.85633 | AL16: 214.7801 | AM16: 230.41312 | AN16: 252.8859 | AO16: 248.43778 | AP16: 288.2464 | AQ16: 306.05609 | AR16: 329.21368 | AS16: 324.47705 | AT16: 323.87941 | AU16: 326.70849 | AV16: 290.41442 | AW16: 330.38199 | AX16: 307.55981 | AY16: 324.39602 | AZ16: 348.02316 | BA16: 344.68181 | BB16: 385.55104 | BC16: 404.37727 | BD16: 428.50973 | BE16: 424.70861 | BF16: 425.00874 | BG16: 428.69878 | BH16: 393.22919 | BI16: 433.9848 | BJ16: 411.91414 | BK16: 429.46533 | BL16: 453.77104 | BM16: 451.07224 | BN16: 492.54878 | BO16: 511.94824 | BP16: 536.6211 | BQ16: 533.32835 | BR16: 534.10464 | BS16: 538.23744 | BT16: 503.17564 | BU16: 544.3036 | BV16: 522.57215 | BW16: 540.43518 | BX16: 565.0335 | BY16: 562.61572 | BZ16: 604.36479 | CA16: 624.02415 | CB16: 648.93345 | CC16: 645.83766 | CD16: 646.75986 | CE16: 650.9855 | CF16: 615.96661 | CG16: 657.1053 | CH16: 635.34388 | CI16: 653.12031 | CJ16: 677.58916 | CK16: 674.83045 | CL16: 716.21977 | CM16: 735.58901 | CN16: 759.62138 | CO16: 756.97966 | CP16: 757.86589 | CQ16: 761.56457 | CR16: 730.93495 | CS16: 757.25446 | CT16: 745.44983 | CU16: 782.0434 | CW16: -1
C17: Actual | CW17: 0
A18: Ac1202 | B18: adm | C18: Forecast | D18: 1937.345 | E18: 1631.7273 | F18: 1401.5383 | G18: 1415.6651 | H18: 1053.4316 | I18: 1414.5531 | J18: 1299.9466 | K18: 1681.7631 | L18: 1543.2649 | M18: 1675.9054 | N18: 1731.7795 | O18: 1623.1263 | P18: 1746.0996 | Q18: 1596.1864 | R18: 1400.9671 | S18: 1461.9041 | T18: 1143.2439 | U18: 1543.0674 | V18: 1474.7744 | W18: 1897.9276 | X18: 1797.4243 | Y18: 1963.7443 | Z18: 2046.3831 | AA18: 1958.3349 | AB18: 2096.0982 | AC18: 1956.6629 | AD18: 1769.6354 | AE18: 1838.1032 | AF18: 1527.4579 | AG18: 1936.2657 | AH18: 1877.9141 | AI18: 2311.6911 | AJ18: 2222.1431 | AK18: 2399.459 | AL18: 2492.9345 | AM18: 2415.4267 | AN18: 2563.3241 | AO18: 2433.5159 | AP18: 2255.5306 | AQ18: 2332.4234 | AR18: 2029.6142 | AS18: 2445.752 | AT18: 2394.337 | AU18: 2834.7685 | AV18: 2751.676 | AW18: 2935.2922 | AX18: 3034.9199 | AY18: 2963.4009 | AZ18: 3117.1 | BA18: 2992.8866 | BB18: 2820.2773 | BC18: 2902.3239 | BD18: 2604.4488 | BE18: 3025.3059 | BF18: 2978.4006 | BG18: 3423.1356 | BH18: 3344.1415 | BI18: 3531.6498 | BJ18: 3634.9626 | BK18: 3566.9258 | BL18: 3723.9168 | BM18: 3602.8269 | BN18: 3433.1994 | BO18: 3518.1073 | BP18: 3222.978 | BQ18: 3646.4495 | BR18: 3601.9963 | BS18: 4048.9928 | BT18: 3972.0643 | BU18: 4161.4712 | BV18: 4266.5678 | BW18: 4200.2414 | BX18: 4358.8598 | BY18: 4239.2273 | BZ18: 4070.7437 | CA18: 4156.3512 | CB18: 3861.4507 | CC18: 4284.8458 | CD18: 4240.3224 | CE18: 4687.611 | CF18: 4611.5919 | CG18: 4802.3473 | CH18: 4908.8845 | CI18: 4843.5728 | CJ18: 5001.7805 | CK18: 4881.6792 | CL18: 4711.5053 | CM18: 4795.0268 | CN18: 4504.2493 | CO18: 4921.2396 | CP18: 4875.0123 | CQ18: 5331.4111 | CR18: 5193.4635 | CS18: 5465.5476 | CT18: 5473.8773 | CU18: 5388.7154 | CW18: 1
C19: Actual | CW19: 0
A20: Ac1202 | B20: desl | C20: Forecast | D20: 1499.8276 | E20: 1369.5218 | F20: 1615.041 | G20: 1621.2071 | H20: 1744.3109 | I20: 1561.4663 | J20: 1491.8081 | K20: 1595.98 | L20: 1259.3958 | M20: 1625.9774 | N20: 1242.3275 | O20: 1300.2426 | P20: 1341.575 | Q20: 1239.9944 | R20: 1563.9987 | S20: 1630.6541 | T20: 1810.6153 | U20: 1681.1198 | V20: 1653.71 | W20: 1800.6081 | X20: 1501.4849 | Y20: 1899.5322 | Z20: 1542.2686 | AA20: 1621.4553 | AB20: 1680.5916 | AC20: 1594.9137 | AD20: 1933.867 | AE20: 2015.0189 | AF20: 2209.1552 | AG20: 2093.496 | AH20: 2079.532 | AI20: 2239.4958 | AJ20: 1953.1303 | AK20: 2363.6919 | AL20: 2018.7016 | AM20: 2109.844 | AN20: 2180.4979 | AO20: 2105.7945 | AP20: 2455.1313 | AQ20: 2546.0955 | AR20: 2749.5428 | AS20: 2642.7813 | AT20: 2637.3772 | AU20: 2805.6095 | AV20: 2527.2383 | AW20: 2945.5194 | AX20: 2607.9679 | AY20: 2706.2665 | AZ20: 2783.798 | BA20: 2715.701 | BB20: 3071.3807 | BC20: 3168.4307 | BD20: 3377.7114 | BE20: 3276.5348 | BF20: 3276.4695 | BG20: 3449.7948 | BH20: 3176.269 | BI20: 3599.1455 | BJ20: 3265.9428 | BK20: 3368.3568 | BL20: 3449.7948 | BM20: 3385.4251 | BN20: 3744.6755 | BO20: 3845.1415 | BP20: 4057.6596 | BQ20: 3959.5011 | BR20: 3962.2004 | BS20: 4138.0356 | BT20: 3866.8093 | BU20: 4291.8509 | BV20: 3960.7416 | BW20: 4065.1742 | BX20: 4148.457 | BY20: 4085.5898 | BZ20: 4445.8482 | CA20: 4546.8069 | CB20: 4759.4954 | CC20: 4661.5485 | CD20: 4664.8954 | CE20: 4842.0027 | CF20: 4572.4476 | CG20: 4998.9764 | CH20: 4668.315 | CI20: 4771.6881 | CJ20: 4853.041 | CK20: 4787.3022 | CL20: 5146.278 | CM20: 5248.6627 | CN20: 5460.7408 | CO20: 5364.8271 | CP20: 5361.8058 | CQ20: 5514.1215 | CR20: 5270.294 | CS20: 5548.4516 | CT20: 5334.3417 | CU20: 5700.0219 | CW20: -1
C21: Actual | CW21: 0
A22: Am1301 | B22: adm | C22: Forecast | D22: 10.165988 | E22: 5.1848812 | F22: 8.4464209 | G22: 15.440655 | H22: 10.783111 | I22: 34.82025 | J22: 15.662345 | K22: 24.84044 | L22: 15.985205 | M22: 13.352769 | N22: 17.049977 | O22: 9.8772434 | P22: 10.007646 | Q22: 6.5904483 | R22: 3.9234946 | S22: 12.164559 | T22: 8.2465475 | U22: 32.073879 | V22: 13.38349 | W22: 22.383948 | X22: 13.808541 | Y22: 11.349923 | Z22: 15.175287 | AA22: 8.1569596 | AB22: 8.3704789 | AC22: 5.0025154 | AD22: 2.3804052 | AE22: 10.663666 | AF22: 6.7932016 | AG22: 30.676271 | AH22: 12.046643 | AI22: 21.10735 | AJ22: 12.588352 | AK22: 10.182323 | AL22: 14.058257 | AM22: 7.0906695 | AN22: 7.3559525 | AO22: 4.0400022 | AP22: 1.4685899 | AQ22: 9.7996586 | AR22: 5.9732231 | AS22: 29.896674 | AT22: 11.304682 | AU22: 20.401404 | AV22: 11.917632 | AW22: 9.5463373 | AX22: 13.456325 | AY22: 6.521699 | AZ22: 6.8185058 | BA22: 3.5325516 | BB22: 0.98979353 | BC22: 9.3485096 | BD22: 5.5489977 | BE22: 29.498706 | BF22: 10.932081 | BG22: 20.052865 | BH22: 11.591477 | BI22: 9.2407968 | BJ22: 13.169969 | BK22: 6.2537904 | BL22: 6.569029 | BM22: 3.3018111 | BN22: 0.77769333 | BO22: 9.1538841 | BP22: 5.3694592 | BQ22: 29.3313 | BR22: 10.774607 | BS22: 19.905207 | BT22: 11.456044 | BU22: 9.121397 | BV22: 13.069225 | BW22: 6.1702686 | BX22: 6.495884 | BY22: 3.2284202 | BZ22: 0.6944854 | CA22: 9.058068 | CB22: 5.2685133 | CC22: 29.241518 | CD22: 10.711706 | CE22: 19.874026 | CF22: 11.44273 | CG22: 9.0933602 | CH22: 13.001163 | CI22: 6.0454255 | CJ22: 6.3361868 | CK22: 3.1489504 | CL22: 0.67493743 | CM22: 9.1732612 | CN22: 5.5457238 | CO22: 29.102108 | CP22: 10.643607 | CQ22: 18.773127 | CR22: 9.1418563 | CS22: 14.401573 | CT22: 8.7064088 | CU22: 3.0146249 | CW22: 1
C23: Actual | CW23: 0
A24: Am1301 | B24: desl | C24: Forecast | D24: 2.9674554 | E24: 16.621937 | F24: 24.716662 | G24: 21.821683 | H24: 37.580794 | I24: 18.472147 | J24: 27.684585 | K24: 13.658908 | L24: 19.777663 | M24: 13.962843 | N24: 8.4119978 | O24: 9.7382209 | P24: 4.4378114 | Q24: 8.8613118 | R24: 18.886739 | S24: 17.307597 | T24: 32.477001 | U24: 13.994425 | V24: 23.005724 | W24: 9.1888389 | X24: 15.305977 | Y24: 9.3951612 | Z24: 3.8336358 | AA24: 5.14486 | AB24: -0.12075923 | AC24: 4.382597 | AD24: 14.490199 | AE24: 12.980936 | AF24: 28.200947 | AG24: 9.7504192 | AH24: 18.781878 | AI24: 4.9808371 | AJ24: 11.114656 | AK24: 5.2219946 | AL24: -0.32202183 | AM24: 1.0036096 | AN24: -4.2515779 | AO24: 0.25945695 | AP24: 10.374255 | AQ24: 8.8737555 | AR24: 24.105078 | AS24: 5.6680769 | AT24: 14.714043 | AU24: 0.92708441 | AV24: 7.0735996 | AW24: 1.191979 | AX24: -4.3423499 | AY24: -3.0078395 | AZ24: -8.2544762 | BA24: -3.7349635 | BB24: 6.3882672 | BC24: 4.8960422 | BD24: 20.13532 | BE24: 1.7058038 | BF24: 10.758675 | BG24: -3.0219901 | BH24: 3.1303028 | BI24: -2.7458017 | BJ24: -8.2745087 | BK24: -6.9339389 | BL24: -12.173992 | BM24: -7.647679 | BN24: 2.4819171 | BO24: 0.9949285 | BP24: 16.238032 | BQ24: -2.1885869 | BR24: 6.8674493 | BS24: -6.9084521 | BT24: -0.74926803 | BU24: -6.6174113 | BV24: -12.139742 | BW24: -10.797569 | BX24: -16.042587 | BY24: -11.526355 | BZ24: -1.4067642 | CA24: -2.896399 | CB24: 12.357074 | CC24: -6.0464245 | CD24: 3.0382312 | CE24: -10.716222 | CF24: -4.5531062 | CG24: -10.436922 | CH24: -15.986117 | CI24: -14.651144 | CJ24: -19.858709 | CK24: -15.288043 | CL24: -5.0584265 | CM24: -6.5315959 | CN24: 8.6537164 | CO24: -9.9951154 | CP24: -1.3925462 | CQ24: -15.208658 | CR24: -7.2152418 | CS24: -18.317073 | CT24: -16.093762 | CU24: -10.014338 | CW24: -1
C25: Actual | CW25: 0
A26: Am1302 | B26: adm | C26: Forecast | D26: 24.364513 | E26: 19.867641 | F26: 17.729604 | G26: 20.052164 | H26: 16.390056 | I26: 22.325766 | J26: 17.785933 | K26: 24.606544 | L26: 21.152714 | M26: 24.059007 | N26: 25.211101 | O26: 23.123121 | P26: 24.814346 | Q26: 23.24778 | R26: 21.174164 | S26: 23.459534 | T26: 20.476097 | U26: 26.876396 | V26: 22.996451 | W26: 30.401762 | X26: 27.563716 | Y26: 31.01365 | Z26: 32.566962 | AA26: 30.756024 | AB26: 32.616502 | AC26: 31.158593 | AD26: 29.185526 | AE26: 31.592032 | AF26: 28.759167 | AG26: 35.334732 | AH26: 31.643606 | AI26: 39.241238 | AJ26: 36.59377 | AK26: 40.23174 | AL26: 41.971337 | AM26: 40.344611 | AN26: 42.38473 | AO26: 41.098097 | AP26: 39.284686 | AQ26: 41.83795 | AR26: 39.140015 | AS26: 45.841442 | AT26: 42.270322 | AU26: 49.984619 | AV26: 47.451709 | AW26: 51.202162 | AX26: 53.051502 | AY26: 51.531005 | AZ26: 53.67334 | BA26: 52.484772 | BB26: 50.76538 | BC26: 53.408783 | BD26: 50.797228 | BE26: 57.581327 | BF26: 54.089195 | BG26: 61.878817 | BH26: 59.417573 | BI26: 63.235995 | BJ26: 65.149544 | BK26: 63.689492 | BL26: 65.888705 | BM26: 64.753915 | BN26: 63.085858 | BO26: 65.778736 | BP26: 63.214959 | BQ26: 70.044664 | BR26: 66.594979 | BS26: 74.422892 | BT26: 71.99548 | BU26: 75.84414 | BV26: 77.786178 | BW26: 76.354734 | BX26: 78.583145 | BY26: 77.476137 | BZ26: 75.830192 | CA26: 78.534828 | CB26: 75.970322 | CC26: 82.789986 | CD26: 79.329194 | CE26: 87.155551 | CF26: 84.743836 | CG26: 88.622565 | CH26: 90.597276 | CI26: 89.17817 | CJ26: 91.381987 | CK26: 90.232137 | CL26: 88.51553 | CM26: 91.180874 | CN26: 88.709741 | CO26: 95.49023 | CP26: 92.151581 | CQ26: 99.769469 | CR26: 96.840139 | CS26: 101.73236 | CT26: 100.50346 | CU26: 100.39741 | CW26: 1
C27: Actual | CW27: 0
A28: Am1302 | B28: desl | C28: Forecast | D28: 25.331391 | E28: 26.296828 | F28: 28.847357 | G28: 29.597226 | H28: 25.799681 | I28: 30.563795 | J28: 23.202961 | K28: 27.949436 | L28: 23.102051 | M28: 26.461124 | N28: 22.196779 | O28: 25.369504 | P28: 24.998605 | Q28: 26.384063 | R28: 29.173186 | S28: 30.360501 | T28: 26.530901 | U28: 31.476207 | V28: 24.075097 | W28: 28.94689 | X28: 24.336962 | Y28: 27.933284 | Z28: 23.919714 | AA28: 27.311984 | AB28: 27.120841 | AC28: 28.663927 | AD28: 31.59734 | AE28: 32.922081 | AF28: 29.224443 | AG28: 34.293939 | AH28: 27.005674 | AI28: 31.977215 | AJ28: 27.456242 | AK28: 31.135632 | AL28: 27.204267 | AM28: 30.681033 | AN28: 30.577176 | AO28: 32.208752 | AP28: 35.22938 | AQ28: 36.637883 | AR28: 33.019436 | AS28: 38.163552 | AT28: 30.946007 | AU28: 35.985129 | AV28: 31.529067 | AW28: 35.270802 | AX28: 31.399102 | AY28: 34.932744 | AZ28: 34.883008 | BA28: 36.566136 | BB28: 39.636003 | BC28: 41.091649 | BD28: 37.518388 | BE28: 42.705805 | BF28: 35.529728 | BG28: 40.608536 | BH28: 36.190393 | BI28: 39.968203 | BJ28: 36.130551 | BK28: 39.695991 | BL28: 39.675691 | BM28: 41.386035 | BN28: 44.481326 | BO28: 45.961155 | BP28: 42.41117 | BQ28: 47.620758 | BR28: 40.464919 | BS28: 45.560894 | BT28: 41.15608 | BU28: 44.943721 | BV28: 41.114149 | BW28: 44.688569 | BX28: 44.680414 | BY28: 46.40637 | BZ28: 49.518251 | CA28: 51.010971 | CB28: 47.465392 | CC28: 52.669421 | CD28: 45.501249 | CE28: 50.585078 | CF28: 46.178174 | CG28: 49.972564 | CH28: 46.153901 | CI28: 49.730187 | CJ28: 49.681689 | CK28: 51.355795 | CL28: 54.393702 | CM28: 55.734046 | CN28: 52.352294 | CO28: 57.439641 | CP28: 50.440334 | CQ28: 55.960788 | CR28: 50.042936 | CS28: 56.423647 | CT28: 52.642665 | CU28: 57.394841 | CW28: -1
C29: Actual | CW29: 0
A30: Am1303 | B30: adm | C30: Forecast | D30: 13076.681 | E30: 12434.54 | F30: 11437.751 | G30: 11646.232 | H30: 7777.8379 | I30: 10851.618 | J30: 8905.3759 | K30: 12652.545 | L30: 11921.171 | M30: 13080.678 | N30: 14477.861 | O30: 14078.746 | P30: 15906.057 | Q30: 15545.265 | R30: 14110.164 | S30: 14397.337 | T30: 10598.777 | U30: 13790.608 | V30: 12018.189 | W30: 15895.579 | X30: 15266.25 | Y30: 16474.636 | Z30: 17868.708 | AA30: 17436.175 | AB30: 19215.763 | AC30: 18811.169 | AD30: 17348.918 | AE30: 17628.451 | AF30: 13839.056 | AG30: 17051.602 | AH30: 15306.59 | AI30: 19214.833 | AJ30: 18618.021 | AK30: 19859.486 | AL30: 21286.039 | AM30: 20883.971 | AN30: 22690.625 | AO30: 22308.855 | AP30: 20865.22 | AQ30: 21160.053 | AR30: 17384.003 | AS30: 20609.29 | AT30: 18877.355 | AU30: 22799.392 | AV30: 22216.998 | AW30: 23473.156 | AX30: 24914.299 | AY30: 24526.442 | AZ30: 26346.793 | BA30: 25978.158 | BB30: 24547.086 | BC30: 24853.901 | BD30: 21089.244 | BE30: 24325.337 | BF30: 22603.64 | BG30: 26535.36 | BH30: 25962.084 | BI30: 27226.767 | BJ30: 28675.821 | BK30: 28295.313 | BL30: 30122.6 | BM30: 29760.723 | BN30: 28336.454 | BO30: 28650.2 | BP30: 24892.455 | BQ30: 28135.1 | BR30: 26419.218 | BS30: 30355.866 | BT30: 29786.879 | BU30: 31055.802 | BV30: 32509.648 | BW30: 32134.584 | BX30: 33967.187 | BY30: 33608.891 | BZ30: 32184.731 | CA30: 32494.323 | CB30: 28729.256 | CC30: 31964.784 | CD30: 30246.178 | CE30: 34187.633 | CF30: 33631.375 | CG30: 34915.634 | CH30: 36382.06 | CI30: 36011.23 | CJ30: 37833.861 | CK30: 37474.157 | CL30: 36043.228 | CM30: 36352.922 | CN30: 32669.739 | CO30: 35834.116 | CP30: 34141.163 | CQ30: 38091.049 | CR30: 36823.304 | CS30: 39271.926 | CT30: 39637.354 | CU30: 38794.482 | CW30: 1
C31: Actual | CW31: 0
A32: Am1303 | B32: desl | C32: Forecast | D32: 8712.3854 | E32: 8607.4415 | F32: 10928.305 | G32: 11957.367 | H32: 12292.948 | I32: 11153.619 | J32: 10559.762 | K32: 11770.864 | L32: 9828.2065 | M32: 12085.181 | N32: 10085.555 | O32: 9946.3006 | P32: 10906.121 | Q32: 10608.826 | R32: 12831.157 | S32: 13940.215 | T32: 14371.221 | U32: 13382.802 | V32: 12927.732 | W32: 14316.021 | X32: 12527.167 | Y32: 14899.17 | Z32: 12975.47 | AA32: 12877.463 | AB32: 13861.016 | AC32: 13587.785 | AD32: 15843.768 | AE32: 16998.489 | AF32: 17485.283 | AG32: 16558.718 | AH32: 16167.878 | AI32: 17620.844 | AJ32: 15896.698 | AK32: 18333.531 | AL32: 16474.432 | AM32: 16439.659 | AN32: 17483.544 | AO32: 17266.492 | AP32: 19574.029 | AQ32: 20776.079 | AR32: 21306.986 | AS32: 20422.479 | AT32: 20072.545 | AU32: 21565.701 | AV32: 19881.037 | AW32: 22356.407 | AX32: 20534.627 | AY32: 20535.778 | AZ32: 21614.142 | BA32: 21430.158 | BB32: 23769.411 | BC32: 25001.867 | BD32: 25561.887 | BE32: 24705.204 | BF32: 24381.792 | BG32: 25900.146 | BH32: 24239.322 | BI32: 26737.15 | BJ32: 24936.472 | BK32: 24957.495 | BL32: 26054.719 | BM32: 25888.839 | BN32: 28245.616 | BO32: 29494.987 | BP32: 30071.046 | BQ32: 29229.125 | BR32: 28918.897 | BS32: 30448.899 | BT32: 28798.677 | BU32: 31306.806 | BV32: 29516.683 | BW32: 29548.351 | BX32: 30655.192 | BY32: 30496.139 | BZ32: 32855.444 | CA32: 34102.939 | CB32: 34674.731 | CC32: 33829.856 | CD32: 33521.801 | CE32: 35060.823 | CF32: 33424.271 | CG32: 35944.515 | CH32: 34157.441 | CI32: 34179.848 | CJ32: 35268.81 | CK32: 35089.495 | CL32: 37444.071 | CM32: 38712.793 | CN32: 39311.426 | CO32: 38473.286 | CP32: 38125.682 | CQ32: 39551.168 | CR32: 37831.238 | CS32: 39353.211 | CT32: 38494.845 | CU32: 40703.487 | CW32: -1
C33: Actual | CW33: 0
A34: Am1304 | B34: adm | C34: Forecast | D34: 147.88497 | E34: 109.91692 | F34: 90.515936 | G34: 86.527501 | H34: 60.431949 | I34: 87.747656 | J34: 75.716779 | K34: 102.83992 | L34: 81.059739 | M34: 93.202814 | N34: 85.400504 | O34: 77.119204 | P34: 82.724717 | Q34: 66.452962 | R34: 55.935741 | S34: 60.226876 | T34: 41.484616 | U34: 74.576368 | V34: 67.820969 | W34: 99.074776 | X34: 80.763935 | Y34: 95.756679 | Z34: 90.206465 | AA34: 83.765294 | AB34: 90.881108 | AC34: 75.893374 | AD34: 66.530351 | AE34: 71.892829 | AF34: 54.162189 | AG34: 88.213405 | AH34: 82.366963 | AI34: 114.4806 | AJ34: 96.98299 | AK34: 112.74606 | AL34: 107.92628 | AM34: 102.17702 | AN34: 109.94634 | AO34: 95.573893 | AP34: 86.789638 | AQ34: 92.698037 | AR34: 75.485459 | AS34: 110.03204 | AT34: 104.66248 | AU34: 137.23714 | AV34: 120.18578 | AW34: 136.3803 | AX34: 131.97674 | AY34: 126.62811 | AZ34: 134.78241 | BA34: 120.77956 | BB34: 112.34997 | BC34: 118.59858 | BD34: 101.71221 | BE34: 136.57137 | BF34: 131.50097 | BG34: 164.36153 | BH34: 147.58288 | BI34: 164.03705 | BJ34: 159.88047 | BK34: 154.76687 | BL34: 163.14528 | BM34: 149.3566 | BN34: 141.13188 | BO34: 147.57593 | BP34: 130.87476 | BQ34: 165.90778 | BR34: 160.99942 | BS34: 194.01092 | BT34: 177.3741 | BU34: 193.96335 | BV34: 189.93612 | BW34: 184.94444 | BX34: 193.43267 | BY34: 179.73572 | BZ34: 171.58075 | CA34: 178.07423 | CB34: 161.41031 | CC34: 196.48182 | CD34: 191.6234 | CE34: 224.69732 | CF34: 208.12581 | CG34: 224.75863 | CH34: 220.74158 | CI34: 215.72652 | CJ34: 224.14922 | CK34: 210.45818 | CL34: 202.28908 | CM34: 208.80602 | CN34: 192.42321 | CO34: 226.9159 | CP34: 221.60258 | CQ34: 254.67496 | CR34: 234.51262 | CS34: 256.66638 | CT34: 246.65879 | CU34: 242.79246 | CW34: 1
C35: Actual | CW35: 0
A36: Am1304 | B36: desl | C36: Forecast | D36: 96.325959 | E36: 90.710778 | F36: 90.741475 | G36: 85.447372 | H36: 83.663615 | I36: 75.453126 | J36: 72.762738 | K36: 72.979955 | L36: 67.637246 | M36: 68.148412 | N36: 58.7829 | O36: 54.422722 | P36: 53.281252 | Q36: 51.810058 | R36: 59.536967 | S36: 62.795701 | T36: 66.982354 | U36: 64.541197 | V36: 66.283396 | W36: 70.343072 | X36: 68.228082 | Y36: 71.347151 | Z36: 64.172969 | AA36: 61.621867 | AB36: 61.998425 | AC36: 61.848222 | AD36: 70.754071 | AE36: 75.092735 | AF36: 80.287497 | AG36: 78.797138 | AH36: 81.440289 | AI36: 86.354959 | AJ36: 85.052482 | AK36: 88.944586 | AL36: 82.506101 | AM36: 80.654458 | AN36: 81.694702 | AO36: 82.173188 | AP36: 91.674436 | AQ36: 96.577966 | AR36: 102.31056 | AS36: 101.33462 | AT36: 104.47189 | AU36: 109.86258 | AV36: 109.01928 | AW36: 113.35424 | AX36: 107.34244 | AY36: 105.90134 | AZ36: 107.3361 | BA36: 108.19333 | BB36: 118.05788 | BC36: 123.3097 | BD36: 129.376 | BE36: 128.71959 | BF36: 132.16253 | BG36: 137.84525 | BH36: 137.28047 | BI36: 141.88059 | BJ36: 136.12092 | BK36: 134.91952 | BL36: 136.58239 | BM36: 137.65694 | BN36: 147.72856 | BO36: 153.17708 | BP36: 159.429 | BQ36: 158.94622 | BR36: 162.55034 | BS36: 168.38238 | BT36: 167.95679 | BU36: 172.68817 | BV36: 167.05318 | BW36: 165.96912 | BX36: 167.73878 | BY36: 168.90509 | BZ36: 179.05027 | CA36: 184.555 | CB36: 190.85178 | CC36: 190.4115 | CD36: 194.06326 | CE36: 199.94843 | CF36: 199.57139 | CG36: 204.32868 | CH36: 198.67931 | CI36: 197.53985 | CJ36: 199.23321 | CK36: 200.32295 | CL36: 210.45479 | CM36: 216.00892 | CN36: 222.34548 | CO36: 221.8946 | CP36: 225.19672 | CQ36: 230.35281 | CR36: 229.16708 | CS36: 231.60354 | CT36: 231.4434 | CU36: 238.71726 | CW36: -1
C37: Actual | CW37: 0
A38: Rr1401 | B38: adm | C38: Forecast | D38: 1653.7529 | E38: 1562.4766 | F38: 1460.4409 | G38: 1488.3553 | H38: 1252.724 | I38: 1534.3676 | J38: 1379.9132 | K38: 1630.4986 | L38: 1574.7121 | M38: 1612.316 | N38: 1720.8331 | O38: 1667.8612 | P38: 1754.8513 | Q38: 1718.8478 | R38: 1593.9492 | S38: 1645.9108 | T38: 1417.5458 | U38: 1714.2823 | V38: 1573.6082 | W38: 1834.8253 | X38: 1787.5039 | Y38: 1830.6172 | Z38: 1941.5659 | AA38: 1889.3576 | AB38: 1976.0818 | AC38: 1939.8093 | AD38: 1815.3732 | AE38: 1868.7273 | AF38: 1642.5502 | AG38: 1941.9937 | AH38: 1804.2863 | AI38: 2068.5494 | AJ38: 2024.2571 | AK38: 2070.3346 | AL38: 2184.1417 | AM38: 2134.6355 | AN38: 2223.8523 | AO38: 2189.828 | AP38: 2067.4001 | AQ38: 2122.5662 | AR38: 1898.0727 | AS38: 2199.1398 | AT38: 2063.0449 | AU38: 2328.9309 | AV38: 2286.2686 | AW38: 2333.9662 | AX38: 2449.3642 | AY38: 2401.4053 | AZ38: 2492.1184 | BA38: 2459.5379 | BB38: 2338.5015 | BC38: 2395.0081 | BD38: 2171.8055 | BE38: 2474.1161 | BF38: 2339.2196 | BG38: 2606.2608 | BH38: 2564.7103 | BI38: 2613.4742 | BJ38: 2729.8914 | BK38: 2682.9066 | BL38: 2774.5578 | BM38: 2742.8936 | BN38: 2622.767 | BO38: 2680.1841 | BP38: 2457.8861 | BQ38: 2761.0747 | BR38: 2627.0053 | BS38: 2894.8095 | BT38: 2853.9689 | BU38: 2903.4252 | BV38: 3020.5584 | BW38: 2974.33 | BX38: 3066.7433 | BY38: 3035.7585 | BZ38: 2916.1233 | CA38: 2973.7857 | CB38: 2751.5349 | CC38: 3054.7653 | CD38: 2920.9833 | CE38: 3189.522 | CF38: 3149.9209 | CG38: 3200.808 | CH38: 3319.2283 | CI38: 3273.7802 | CJ38: 3365.9659 | CK38: 3335.3499 | CL38: 3215.5554 | CM38: 3273.0806 | CN38: 3057.0092 | CO38: 3355.9962 | CP38: 3224.7047 | CQ38: 3499.9645 | CR38: 3409.1781 | CS38: 3553.4378 | CT38: 3564.2513 | CU38: 3477.5073 | CW38: 1
C39: Actual | CW39: 0
A40: Rr1401 | B40: desl | C40: Forecast | D40: 1541.5052 | E40: 1340.7305 | F40: 1474.8776 | G40: 1476.1222 | H40: 1363.6645 | I40: 1515.989 | J40: 1331.3008 | K40: 1668.6209 | L40: 1350.8942 | M40: 1653.5113 | N40: 1472.5038 | O40: 1465.1767 | P40: 1590.185 | Q40: 1455.4041 | R40: 1557.609 | S40: 1602.9558 | T40: 1491.9632 | U40: 1668.2816 | V40: 1495.9252 | W40: 1849.2155 | X40: 1542.9657 | Y40: 1853.4458 | Z40: 1676.9573 | AA40: 1671.9672 | AB40: 1798.2401 | AC40: 1665.0889 | AD40: 1769.7538 | AE40: 1818.4504 | AF40: 1711.4799 | AG40: 1892.1719 | AH40: 1724.2905 | AI40: 2082.0383 | AJ40: 1780.2047 | AK40: 2095.0535 | AL40: 1922.845 | AM40: 1921.9626 | AN40: 2052.0776 | AO40: 1922.4463 | AP40: 2030.3118 | AQ40: 2081.9481 | AR40: 1977.7435 | AS40: 2161.1101 | AT40: 1995.8657 | AU40: 2356.2305 | AV40: 2056.9829 | AW40: 2374.3643 | AX40: 2204.6142 | AY40: 2206.1049 | AZ40: 2338.5061 | BA40: 2211.0773 | BB40: 2321.0653 | BC40: 2374.7456 | BD40: 2272.5063 | BE40: 2457.7591 | BF40: 2294.3219 | BG40: 2656.4157 | BH40: 2358.8204 | BI40: 2677.7792 | BJ40: 2509.5353 | BK40: 2512.4679 | BL40: 2646.2571 | BM40: 2520.1734 | BN40: 2631.4709 | BO40: 2686.4236 | BP40: 2585.4087 | BQ40: 2771.822 | BR40: 2609.4707 | BS40: 2972.5799 | BT40: 2675.9511 | BU40: 2995.8568 | BV40: 2828.5582 | BW40: 2832.4196 | BX40: 2967.0663 | BY40: 2841.6918 | BZ40: 2953.4929 | CA40: 3008.7538 | CB40: 2907.9548 | CC40: 3094.6695 | CD40: 2932.8712 | CE40: 3296.8566 | CF40: 3001.3429 | CG40: 3322.3037 | CH40: 3155.743 | CI40: 3159.8443 | CJ40: 3294.3461 | CK40: 3169.1116 | CL40: 3281.2603 | CM40: 3338.0825 | CN40: 3241.3484 | CO40: 3425.7067 | CP40: 3266.5316 | CQ40: 3621.5121 | CR40: 3310.7875 | CS40: 3625.8329 | CT40: 3437.2553 | CU40: 3581.7258 | CW40: -1
C41: Actual | CW41: 0
...

Sheet CF-6
A1: GVAR Conditional Forecasts
A2: Last in-sample estimation date: | B2: 2017M07
A3: Last forecast date: | B3: 2025M7
D5: 2017M8 | E5: 2017M9 | F5: 2017M10 | G5: 2017M11 | H5: 2017M12 | I5: 2018M1 | J5: 2018M2 | K5: 2018M3 | L5: 2018M4 | M5: 2018M5 | N5: 2018M6 | O5: 2018M7 | P5: 2018M8 | Q5: 2018M9 | R5: 2018M10 | S5: 2018M11 | T5: 2018M12 | U5: 2019M1 | V5: 2019M2 | W5: 2019M3 | X5: 2019M4 | Y5: 2019M5 | Z5: 2019M6 | AA5: 2019M7 | AB5: 2019M8 | AC5: 2019M9 | AD5: 2019M10 | AE5: 2019M11 | AF5: 2019M12 | AG5: 2020M1 | AH5: 2020M2 | AI5: 2020M3 | AJ5: 2020M4 | AK5: 2020M5 | AL5: 2020M6 | AM5: 2020M7 | AN5: 2020M8 | AO5: 2020M9 | AP5: 2020M10 | AQ5: 2020M11 | AR5: 2020M12 | AS5: 2021M1 | AT5: 2021M2 | AU5: 2021M3 | AV5: 2021M4 | AW5: 2021M5 | AX5: 2021M6 | AY5: 2021M7 | AZ5: 2021M8 | BA5: 2021M9 | BB5: 2021M10 | BC5: 2021M11 | BD5: 2021M12 | BE5: 2022M1 | BF5: 2022M2 | BG5: 2022M3 | BH5: 2022M4 | BI5: 2022M5 | BJ5: 2022M6 | BK5: 2022M7 | BL5: 2022M8 | BM5: 2022M9 | BN5: 2022M10 | BO5: 2022M11 | BP5: 2022M12 | BQ5: 2023M1 | BR5: 2023M2 | BS5: 2023M3 | BT5: 2023M4 | BU5: 2023M5 | BV5: 2023M6 | BW5: 2023M7 | BX5: 2023M8 | BY5: 2023M9 | BZ5: 2023M10 | CA5: 2023M11 | CB5: 2023M12 | CC5: 2024M1 | CD5: 2024M2 | CE5: 2024M3 | CF5: 2024M4 | CG5: 2024M5 | CH5: 2024M6 | CI5: 2024M7 | CJ5: 2024M8 | CK5: 2024M9 | CL5: 2024M10 | CM5: 2024M11 | CN5: 2024M12 | CO5: 2025M1 | CP5: 2025M2 | CQ5: 2025M3 | CR5: 2025M4 | CS5: 2025M5 | CT5: 2025M6 | CU5: 2025M7 | CW5: Seletor
A6: Ro1101 | B6: adm | C6: Forecast | D6: 3387.86 | E6: 3076.8455 | F6: 2578.5728 | G6: 2382.4548 | H6: 1402.9919 | I6: 2072.6512 | J6: 1876.0426 | K6: 2751.8084 | L6: 2656.7408 | M6: 3064.0068 | N6: 3323.6963 | O6: 3303.1474 | P6: 3560.6712 | Q6: 3331.0133 | R6: 2794.0553 | S6: 2623.7955 | T6: 1686.5705 | U6: 2410.4267 | V6: 2298.6784 | W6: 3263.2864 | X6: 3259.1672 | Y6: 3750.5814 | Z6: 4080.6222 | AA6: 4116.4558 | AB6: 4417.1637 | AC6: 4220.7902 | AD6: 3711.4689 | AE6: 3566.5383 | AF6: 2654.609 | AG6: 3404.8616 | AH6: 3321.0034 | AI6: 4315.014 | AJ6: 4341.6492 | AK6: 4864.9004 | AL6: 5227.4606 | AM6: 5295.9597 | AN6: 5628.8671 | AO6: 5463.6532 | AP6: 4984.0411 | AQ6: 4867.1965 | AR6: 3981.7884 | AS6: 4757.2159 | AT6: 4697.4641 | AU6: 5714.7621 | AV6: 5764.037 | AW6: 6309.3673 | AX6: 6693.4701 | AY6: 6782.9682 | AZ6: 7136.3159 | BA6: 6990.9718 | BB6: 6530.6508 | BC6: 6432.5103 | BD6: 5565.2086 | BE6: 6358.1319 | BF6: 6315.2531 | BG6: 7348.7919 | BH6: 7413.672 | BI6: 7973.977 | BJ6: 8372.441 | BK6: 8475.7187 | BL6: 8842.3101 | BM6: 8709.7263 | BN6: 8261.7285 | BO6: 8175.5006 | BP6: 7319.701 | BQ6: 8123.698 | BR6: 8091.4486 | BS6: 9135.183 | BT6: 9209.8703 | BU6: 9779.654 | BV6: 10187.293 | BW6: 10299.373 | BX6: 10674.209 | BY6: 10549.047 | BZ6: 10107.421 | CA6: 10026.47 | CB6: 9175.0886 | CC6: 9983.1965 | CD6: 9955.3945 | CE6: 11004.385 | CF6: 11085.348 | CG6: 11661.919 | CH6: 12076.444 | CI6: 12195.413 | CJ6: 12576.131 | CK6: 12459.107 | CL6: 12025.6 | CM6: 11949.215 | CN6: 11114.343 | CO6: 11907.81 | CP6: 11865.765 | CQ6: 12930.03 | CR6: 12902.143 | CS6: 13683.52 | CT6: 13920.196 | CU6: 13814.885 | CW6: 1
C7: Actual | CW7: 0
A8: Ro1101 | B8: desl | C8: Forecast | D8: 2987.6073 | E8: 2821.8777 | F8: 2937.5748 | G8: 2866.6134 | H8: 2647.7696 | I8: 2418.6586 | J8: 2245.1588 | K8: 2461.4051 | L8: 2217.6358 | M8: 2667.3847 | N8: 2408.1984 | O8: 2598.9462 | P8: 2656.4731 | Q8: 2633.6458 | R8: 2796.3243 | S8: 2824.4524 | T8: 2699.9544 | U8: 2574.8306 | V8: 2511.7618 | W8: 2845.2699 | X8: 2717.6958 | Y8: 3277.7264 | Z8: 3117.2227 | AA8: 3392.9536 | AB8: 3521.7562 | AC8: 3558.9206 | AD8: 3773.2809 | AE8: 3847.704 | AF8: 3766.3877 | AG8: 3682.7767 | AH8: 3660.3423 | AI8: 4034.0351 | AJ8: 3946.4496 | AK8: 4546.4187 | AL8: 4425.8029 | AM8: 4741.1845 | AN8: 4909.0531 | AO8: 4984.2805 | AP8: 5235.3277 | AQ8: 5344.8283 | AR8: 5296.9252 | AS8: 5245.162 | AT8: 5253.1971 | AU8: 5656.183 | AV8: 5596.8783 | AW8: 6224.2225 | AX8: 6130.1319 | AY8: 6471.214 | AZ8: 6663.9712 | BA8: 6763.2867 | BB8: 7037.6334 | BC8: 7169.6541 | BD8: 7143.4971 | BE8: 7112.707 | BF8: 7140.9413 | BG8: 7563.3517 | BH8: 7522.6974 | BI8: 8167.9221 | BJ8: 8090.9522 | BK8: 8448.4163 | BL8: 8656.8516 | BM8: 8771.1881 | BN8: 9059.9482 | BO8: 9205.8129 | BP8: 9192.9434 | BQ8: 9174.8707 | BR8: 9215.2244 | BS8: 9649.1407 | BT8: 9619.4009 | BU8: 10275.011 | BV8: 10207.975 | BW8: 10574.955 | BX8: 10792.426 | BY8: 10915.143 | BZ8: 11211.393 | CA8: 11363.69 | CB8: 11356.222 | CC8: 11342.818 | CD8: 11387.627 | CE8: 11826.296 | CF8: 11801.895 | CG8: 12463.238 | CH8: 12401.645 | CI8: 12773.324 | CJ8: 12994.272 | CK8: 13119.408 | CL8: 13419.237 | CM8: 13574.984 | CN8: 13573.304 | CO8: 13563.704 | CP8: 13597.749 | CQ8: 14035.596 | CR8: 13988.765 | CS8: 14556.629 | CT8: 14583.02 | CU8: 15111.039 | CW8: -1
C9: Actual | CW9: 0
A10: Ro1102 | B10: adm | C10: Forecast | D10: 5862.0419 | E10: 5026.9574 | F10: 4366.3855 | G10: 4337.8851 | H10: 3466.2412 | I10: 4449.7572 | J10: 4090.1043 | K10: 5141.6437 | L10: 4719.5463 | M10: 5018.3454 | N10: 5051.468 | O10: 4644.5967 | P10: 4774.0502 | Q10: 4366.9666 | R10: 3889.1711 | S10: 4057.1296 | T10: 3359.2916 | U10: 4493.6453 | V10: 4279.8403 | W10: 5448.8594 | X10: 5125.6613 | Y10: 5500.0616 | Z10: 5584.2261 | AA10: 5209.687 | AB10: 5358.2506 | AC10: 4964.2755 | AD10: 4499.9173 | AE10: 4684.8643 | AF10: 4008.3342 | AG10: 5167.4495 | AH10: 4980.4055 | AI10: 6176.8789 | AJ10: 5880.9839 | AK10: 6282.1105 | AL10: 6392.1733 | AM10: 6042.4321 | AN10: 6214.3597 | AO10: 5842.0215 | AP10: 5397.4621 | AQ10: 5600.5089 | AR10: 4940.7286 | AS10: 6115.6843 | AT10: 5943.9661 | AU10: 7155.5037 | AV10: 6874.4973 | AW10: 7290.2936 | AX10: 7414.7023 | AY10: 7078.8795 | AZ10: 7264.2296 | BA10: 6904.7904 | BB10: 6472.6066 | BC10: 6687.5179 | BD10: 6039.1054 | BE10: 7224.9444 | BF10: 7063.6337 | BG10: 8285.1073 | BH10: 8013.5633 | BI10: 8438.3443 | BJ10: 8571.265 | BK10: 8243.5094 | BL10: 8436.5411 | BM10: 8084.4795 | BN10: 7659.4437 | BO10: 7881.3018 | BP10: 7239.5908 | BQ10: 8431.779 | BR10: 8276.3488 | BS10: 9503.185 | BT10: 9236.5601 | BU10: 9666.0025 | BV10: 9803.5216 | BW10: 9480.3528 | BX10: 9677.7467 | BY10: 9329.3573 | BZ10: 8906.7894 | CA10: 9129.673 | CB10: 8487.8737 | CC10: 9679.8528 | CD10: 9525.3486 | CE10: 10755.18 | CF10: 10493.646 | CG10: 10928.768 | CH10: 11070.714 | CI10: 10748.891 | CJ10: 10943.354 | CK10: 10592.573 | CL10: 10166.436 | CM10: 10389.375 | CN10: 9762.8534 | CO10: 10940.047 | CP10: 10782.681 | CQ10: 11999.781 | CR10: 11595.014 | CS10: 12212.047 | CT10: 12105.88 | CU10: 11794.377 | CW10: 1
C11: Actual | CW11: 0
A12: Ro1102 | B12: desl | C12: Forecast | D12: 4839.0291 | E12: 4330.1046 | F12: 4716.3249 | G12: 4789.3136 | H12: 4681.6437 | I12: 4299.5276 | J12: 4142.753 | K12: 4776.8405 | L12: 3857.3768 | M12: 4696.2957 | N12: 3877.0745 | O12: 3826.1339 | P12: 4061.2303 | Q12: 3726.1209 | R12: 4306.1641 | S12: 4550.8353 | T12: 4600.4075 | U12: 4355.6313 | V12: 4308.3766 | W12: 5045.6944 | X12: 4211.6093 | Y12: 5117.7223 | Z12: 4350.3392 | AA12: 4338.7744 | AB12: 4606.501 | AC12: 4302.3699 | AD12: 4914.1894 | AE12: 5191.8043 | AF12: 5274.7554 | AG12: 5062.7799 | AH12: 5046.9962 | AI12: 5814.2649 | AJ12: 5008.8481 | AK12: 5942.6738 | AL12: 5202.194 | AM12: 5216.6016 | AN12: 5509.1018 | AO12: 5228.3274 | AP12: 5862.0502 | AQ12: 6160.2762 | AR12: 6262.8305 | AS12: 6069.7403 | AT12: 6072.3235 | AU12: 6857.5131 | AV12: 6069.5413 | AW12: 7020.2606 | AX12: 6296.056 | AY12: 6326.0922 | AZ12: 6633.5836 | BA12: 6367.1924 | BB12: 7014.7219 | BC12: 7326.2017 | BD12: 7441.4716 | BE12: 7260.5689 | BF12: 7274.8184 | BG12: 8071.1548 | BH12: 7293.8065 | BI12: 8254.6216 | BJ12: 7539.9936 | BK12: 7579.1211 | BL12: 7895.2814 | BM12: 7637.2118 | BN12: 8292.7678 | BO12: 8611.9729 | BP12: 8734.5896 | BQ12: 8560.5342 | BR12: 8581.0346 | BS12: 9383.028 | BT12: 8610.8789 | BU12: 9576.6592 | BV12: 8866.9481 | BW12: 8910.941 | BX12: 9231.6421 | BY12: 8977.3239 | BZ12: 9635.4305 | CA12: 9955.9492 | CB12: 10079.192 | CC12: 9906.0897 | CD12: 9928.9183 | CE12: 10735.039 | CF12: 9968.0886 | CG12: 10938.344 | CH12: 10230.019 | CI12: 10271.166 | CJ12: 10586.11 | CK12: 10324.336 | CL12: 10979.595 | CM12: 11304.539 | CN12: 11431.84 | CO12: 11265.14 | CP12: 11273.716 | CQ12: 12041.225 | CR12: 11286.632 | CS12: 11956.987 | CT12: 11487.34 | CU12: 12181.428 | CW12: -1
C13: Actual | CW13: 0
A14: Ac1201 | B14: adm | C14: Forecast | D14: 194.73158 | E14: 143.4531 | F14: 114.02576 | G14: 106.93704 | H14: 64.197254 | I14: 92.547025 | J14: 65.074332 | K14: 115.0897 | L14: 116.84868 | M14: 143.1293 | N14: 155.96225 | O14: 132.89477 | P14: 137.03683 | Q14: 110.21768 | R14: 90.935319 | S14: 93.852283 | T14: 55.962354 | U14: 90.342835 | V14: 69.57685 | W14: 126.88891 | X14: 136.68249 | Y14: 170.19148 | Z14: 188.74537 | AA14: 169.42426 | AB14: 175.30276 | AC14: 148.68229 | AD14: 128.6962 | AE14: 130.6302 | AF14: 91.962991 | AG14: 126.04245 | AH14: 105.53547 | AI14: 163.62549 | AJ14: 174.61926 | AK14: 209.64317 | AL14: 229.92465 | AM14: 212.44702 | AN14: 220.19112 | AO14: 195.37223 | AP14: 177.05549 | AQ14: 180.48691 | AR14: 143.13883 | AS14: 178.38221 | AT14: 158.92497 | AU14: 217.99527 | AV14: 229.9365 | AW14: 265.89759 | AX14: 287.11435 | AY14: 270.56839 | AZ14: 279.23392 | BA14: 255.31876 | BB14: 237.88202 | BC14: 242.16554 | BD14: 205.63886 | BE14: 241.67085 | BF14: 222.9676 | BG14: 282.75558 | BH14: 295.37673 | BI14: 331.97915 | BJ14: 353.79914 | BK14: 337.82075 | BL14: 347.02293 | BM14: 323.61989 | BN14: 306.67709 | BO14: 311.44014 | BP14: 275.378 | BQ14: 311.85454 | BR14: 293.56923 | BS14: 353.74478 | BT14: 366.72618 | BU14: 403.67168 | BV14: 425.82951 | BW14: 410.1881 | BX14: 419.71444 | BY14: 396.59251 | BZ14: 379.84927 | CA14: 384.70331 | CB14: 348.62948 | CC14: 385.04238 | CD14: 366.72141 | CE14: 426.96732 | CF14: 440.16119 | CG14: 477.41275 | CH14: 499.88467 | CI14: 484.46443 | CJ14: 494.04409 | CK14: 471.01339 | CL14: 454.35027 | CM14: 459.52184 | CN14: 424.41181 | CO14: 460.33275 | CP14: 441.89056 | CQ14: 500.89477 | CR14: 506.46671 | CS14: 549.95269 | CT14: 565.37691 | CU14: 562.40809 | CW14: 1
C15: Actual | CW15: 0
A16: Ac1201 | B16: desl | C16: Forecast | D16: 165.67495 | E16: 154.33519 | F16: 172.54243 | G16: 171.27006 | H16: 178.75673 | I16: 159.98632 | J16: 147.6971 | K16: 139.85934 | L16: 94.489692 | M16: 122.74324 | N16: 92.323328 | O16: 102.06949 | P16: 114.59811 | Q16: 104.76067 | R16: 136.41198 | S16: 146.19032 | T16: 162.00406 | U16: 151.12162 | V16: 144.96972 | W16: 142.49862 | X16: 101.9427 | Y16: 135.03228 | Z16: 109.55422 | AA16: 124.11304 | AB16: 141.14584 | AC16: 135.34598 | AD16: 170.50024 | AE16: 183.29659 | AF16: 201.73911 | AG16: 193.19105 | AH16: 189.15194 | AI16: 188.61662 | AJ16: 149.84603 | AK16: 184.59502 | AL16: 160.68178 | AM16: 176.74648 | AN16: 195.25727 | AO16: 190.92532 | AP16: 227.53869 | AQ16: 241.77344 | AR16: 261.61603 | AS16: 254.41398 | AT16: 251.65807 | AU16: 252.34218 | AV16: 214.73192 | AW16: 250.58887 | AX16: 227.7371 | AY16: 244.82061 | AZ16: 264.30961 | BA16: 260.91655 | BB16: 298.43095 | BC16: 313.53078 | BD16: 334.2047 | BE16: 327.8022 | BF16: 325.81537 | BG16: 327.23875 | BH16: 290.33806 | BI16: 326.87471 | BJ16: 304.67258 | BK16: 322.37559 | BL16: 342.45398 | BM16: 339.62054 | BN16: 377.66552 | BO16: 393.26799 | BP16: 414.4178 | BQ16: 408.46527 | BR16: 406.90251 | BS16: 408.72317 | BT16: 372.19178 | BU16: 409.06961 | BV16: 387.18274 | BW16: 405.18023 | BX16: 425.53933 | BY16: 422.97903 | BZ16: 461.29141 | CA16: 477.15078 | CB16: 498.53629 | CC16: 492.78356 | CD16: 491.37444 | CE16: 493.30166 | CF16: 456.83444 | CG16: 493.75167 | CH16: 471.87544 | CI16: 489.8435 | CJ16: 510.14601 | CK16: 507.36543 | CL16: 545.45299 | CM16: 561.1646 | CN16: 581.94164 | CO16: 576.69438 | CP16: 575.41863 | CQ16: 577.04167 | CR16: 544.32976 | CS16: 569.17798 | CT16: 555.22028 | CU16: 589.03051 | CW16: -1
C17: Actual | CW17: 0
A18: Ac1202 | B18: adm | C18: Forecast | D18: 1872.5363 | E18: 1589.4395 | F18: 1373.9879 | G18: 1378.651 | H18: 1017.8516 | I18: 1372.2775 | J18: 1249.617 | K18: 1625.189 | L18: 1468.7107 | M18: 1605.4839 | N18: 1635.281 | O18: 1519.6621 | P18: 1603.8144 | Q18: 1461.3922 | R18: 1275.9811 | S18: 1328.6037 | T18: 1009.4312 | U18: 1402.7564 | V18: 1325.4399 | W18: 1740.6319 | X18: 1620.2349 | Y18: 1788.0044 | Z18: 1841.6628 | AA18: 1743.6704 | AB18: 1839.711 | AC18: 1705.0977 | AD18: 1525.4496 | AE18: 1583.3988 | AF18: 1270.2264 | AG18: 1670.6711 | AH18: 1601.5561 | AI18: 2025.7355 | AJ18: 1914.7413 | AK18: 2092.0175 | AL18: 2155.065 | AM18: 2066.1901 | AN18: 2170.9581 | AO18: 2044.5832 | AP18: 1872.6157 | AQ18: 1937.6683 | AR18: 1631.0614 | AS18: 2037.6232 | AT18: 1974.2916 | AU18: 2404.0294 | AV18: 2298.4478 | AW18: 2481.0301 | AX18: 2549.2812 | AY18: 2465.4896 | AZ18: 2575.1953 | BA18: 2453.591 | BB18: 2286.2137 | BC18: 2355.6711 | BD18: 2053.2846 | BE18: 2463.886 | BF18: 2404.4178 | BG18: 2837.8462 | BH18: 2735.784 | BI18: 2921.7141 | BJ18: 2993.1422 | BK18: 2912.3614 | BL18: 3024.9242 | BM18: 2906.0435 | BN18: 2741.2797 | BO18: 2813.2586 | BP18: 2513.3043 | BQ18: 2926.2324 | BR18: 2868.9557 | BS18: 3304.4136 | BT18: 3204.2137 | BU18: 3391.8648 | BV18: 3464.9195 | BW18: 3385.709 | BX18: 3499.7779 | BY18: 3382.2648 | BZ18: 3218.6081 | CA18: 3291.3265 | CB18: 2991.7328 | CC18: 3404.8003 | CD18: 3347.7248 | CE18: 3783.7569 | CF18: 3684.7091 | CG18: 3873.9063 | CH18: 3948.5518 | CI18: 3870.4852 | CJ18: 3984.3883 | CK18: 3866.5244 | CL18: 3701.4621 | CM18: 3772.4277 | CN18: 3476.291 | CO18: 3884.2465 | CP18: 3825.854 | CQ18: 4269.6059 | CR18: 4119.9254 | CS18: 4375.9299 | CT18: 4373.5076 | CU18: 4276.6514 | CW18: 1
C19: Actual | CW19: 0
A20: Ac1202 | B20: desl | C20: Forecast | D20: 1497.7626 | E20: 1366.4715 | F20: 1588.8353 | G20: 1592.2593 | H20: 1704.2665 | I20: 1514.3994 | J20: 1435.8754 | K20: 1527.6083 | L20: 1186.6239 | M20: 1521.303 | N20: 1149.6625 | O20: 1228.8116 | P20: 1243.3826 | Q20: 1145.0324 | R20: 1444.6903 | S20: 1504.9554 | T20: 1671.9824 | U20: 1532.1097 | V20: 1493.4655 | W20: 1625.1102 | X20: 1318.2845 | Y20: 1681.2793 | Z20: 1332.8633 | AA20: 1430.2503 | AB20: 1459.7647 | AC20: 1374.581 | AD20: 1686.568 | AE20: 1758.8179 | AF20: 1937.6236 | AG20: 1809.3176 | AH20: 1781.977 | AI20: 1924.6611 | AJ20: 1628.6608 | AK20: 2002.3078 | AL20: 1664.3551 | AM20: 1771.9319 | AN20: 1811.2432 | AO20: 1735.3663 | AP20: 2056.1295 | AQ20: 2136.6494 | AR20: 2323.2895 | AS20: 2202.4681 | AT20: 2182.3343 | AU20: 2331.9912 | AV20: 2042.7451 | AW20: 2422.926 | AX20: 2091.2804 | AY20: 2204.9345 | AZ20: 2250.0955 | BA20: 2179.8459 | BB20: 2506.02 | BC20: 2591.7386 | BD20: 2783.3688 | BE20: 2667.3317 | BF20: 2651.7783 | BG20: 2805.8122 | BH20: 2520.738 | BI20: 2904.8849 | BJ20: 2577.0028 | BK20: 2694.2304 | BL20: 2742.7972 | BM20: 2675.8121 | BN20: 3005.1283 | BO20: 3093.8669 | BP20: 3288.3718 | BQ20: 3175.0264 | BR20: 3161.9509 | BS20: 3318.2482 | BT20: 3035.2641 | BU20: 3421.3962 | BV20: 3095.4511 | BW20: 3214.5647 | BX20: 3264.8793 | BY20: 3199.3568 | BZ20: 3529.7219 | CA20: 3619.0871 | CB20: 3813.9763 | CC20: 3701.1004 | CD20: 3688.9228 | CE20: 3846.6942 | CF20: 3565.5321 | CG20: 3953.2881 | CH20: 3628.0017 | CI20: 3746.3976 | CJ20: 3795.1822 | CK20: 3727.3668 | CL20: 4056.8488 | CM20: 4147.7492 | CN20: 4342.6015 | CO20: 4231.8881 | CP20: 4214.8298 | CQ20: 4352.3961 | CR20: 4092.5422 | CS20: 4360.8067 | CT20: 4130.3331 | CU20: 4472.7479 | CW20: -1
C21: Actual | CW21: 0
A22: Am1301 | B22: adm | C22: Forecast | D22: 9.4285678 | E22: 7.5953441 | F22: 9.506837 | G22: 15.826265 | H22: 11.7948 | I22: 35.432003 | J22: 16.279622 | K22: 25.330665 | L22: 16.241534 | M22: 14.668713 | N22: 16.650481 | O22: 9.8825188 | P22: 10.847475 | Q22: 8.4379277 | R22: 5.309137 | S22: 13.128837 | T22: 9.525913 | U22: 33.0437 | V22: 14.290862 | W22: 23.190579 | X22: 14.372282 | Y22: 12.948339 | Z22: 15.049131 | AA22: 8.4184262 | AB22: 9.4497998 | AC22: 7.0777225 | AD22: 3.9820325 | AE22: 11.832991 | AF22: 8.2669926 | AG22: 31.829872 | AH22: 13.127414 | AI22: 22.077543 | AJ22: 13.306604 | AK22: 11.926968 | AL22: 14.070608 | AM22: 7.4831883 | AN22: 8.558908 | AO22: 6.2314014 | AP22: 3.1790125 | AQ22: 11.07056 | AR22: 7.5416756 | AS22: 31.138386 | AT22: 12.467368 | AU22: 21.447614 | AV22: 12.706241 | AW22: 11.35588 | AX22: 13.528315 | AY22: 6.9688227 | AZ22: 8.0712795 | BA22: 5.7692361 | BB22: 2.7412026 | BC22: 10.656294 | BD22: 7.1503884 | BE22: 30.769548 | BF22: 12.120235 | BG22: 21.121069 | BH22: 12.398835 | BI22: 11.066103 | BJ22: 13.254981 | BK22: 6.7113791 | BL22: 7.8298198 | BM22: 5.5441228 | BN22: 2.5324142 | BO22: 10.462833 | BP22: 6.970161 | BQ22: 30.599976 | BR22: 11.959441 | BS22: 20.969051 | BT22: 12.25782 | BU22: 10.939493 | BV22: 13.145026 | BW22: 6.6166524 | BX22: 7.7441062 | BY22: 5.4580096 | BZ22: 2.4376909 | CA22: 10.357605 | CB22: 6.8618173 | CC22: 30.503613 | CD22: 11.889353 | CE22: 20.92939 | CF22: 12.235836 | CG22: 10.905928 | CH22: 13.076945 | CI22: 6.5001632 | CJ22: 7.5994649 | CK22: 5.383805 | CL22: 2.4208709 | CM22: 10.457251 | CN22: 7.0953624 | CO22: 30.381336 | CP22: 11.80676 | CQ22: 19.991302 | CR22: 10.300359 | CS22: 15.252864 | CT22: 9.7225902 | CU22: 4.0333653 | CW22: 1
C23: Actual | CW23: 0
A24: Am1301 | B24: desl | C24: Forecast | D24: 6.4419299 | E24: 17.810264 | F24: 25.212373 | G24: 23.247065 | H24: 38.605748 | I24: 19.459651 | J24: 28.723873 | K24: 14.619144 | L24: 21.025523 | M24: 14.334545 | N24: 10.084476 | O24: 11.788572 | P24: 7.4714644 | Q24: 11.085107 | R24: 20.858013 | S24: 19.679075 | T24: 34.606509 | U24: 16.003773 | V24: 25.074907 | W24: 11.164947 | X24: 17.546743 | Y24: 10.767403 | Z24: 6.5075581 | AA24: 8.1967369 | AB24: 3.9168373 | AC24: 7.608175 | AD24: 17.459931 | AE24: 16.347489 | AF24: 31.322468 | AG24: 12.749363 | AH24: 21.838454 | AI24: 7.9419398 | AJ24: 14.337569 | AK24: 7.5731111 | AL24: 3.3273725 | AM24: 5.0277871 | AN24: 0.75563582 | AO24: 4.4524981 | AP24: 14.309685 | AQ24: 13.204419 | AR24: 28.18912 | AS24: 9.6278651 | AT24: 18.72971 | AU24: 4.8455133 | AV24: 11.252133 | AW24: 4.4971097 | AX24: 0.25955087 | AY24: 1.9674098 | AZ24: -2.2975826 | BA24: 1.4063886 | BB24: 11.270659 | BC24: 10.172349 | BD24: 25.163738 | BE24: 6.6087706 | BF24: 15.716416 | BG24: 1.837516 | BH24: 8.2490218 | BI24: 1.4987055 | BJ24: -2.7339992 | BK24: -1.0208555 | BL24: -5.2800767 | BM24: -1.5701476 | BN24: 8.2996639 | BO24: 7.2058483 | BP24: 22.200437 | BQ24: 3.6478212 | BR24: 12.758046 | BS24: -1.1168653 | BT24: 5.3004939 | BU24: -1.4430643 | BV24: -5.6704569 | BW24: -3.9562068 | BX24: -8.2199752 | BY24: -4.5187687 | BZ24: 5.3429004 | CA24: 4.2479904 | CB24: 19.253339 | CC24: 0.72269729 | CD24: 9.8591419 | CE24: -3.9969494 | CF24: 2.4224521 | CG24: -4.3374251 | CH24: -8.591455 | CI24: -6.8870448 | CJ24: -11.121929 | CK24: -7.3757039 | CL24: 2.5760839 | CM24: 1.4917858 | CN24: 16.430256 | CO24: -2.3109548 | CP24: 6.4159749 | CQ24: -7.4799002 | CR24: 0.46064835 | CS24: -10.460371 | CT24: -8.4360718 | CU24: -2.5983503 | CW24: -1
C25: Actual | CW25: 0
A26: Am1302 | B26: adm | C26: Forecast | D26: 23.213192 | E26: 19.220954 | F26: 17.138251 | G26: 19.152736 | H26: 15.457648 | I26: 21.242701 | J26: 16.536383 | K26: 23.171972 | L26: 19.485544 | M26: 22.37823 | N26: 22.880764 | O26: 20.902039 | P26: 22.175561 | Q26: 20.613188 | R26: 18.422362 | S26: 20.525156 | T26: 17.466819 | U26: 23.715338 | V26: 19.643709 | W26: 26.835376 | X26: 23.722111 | Y26: 27.101809 | Z26: 27.948747 | AA26: 26.193016 | AB26: 27.58604 | AC26: 26.088531 | AD26: 23.958513 | AE26: 26.145338 | AF26: 23.20246 | AG26: 29.593009 | AH26: 25.679089 | AI26: 33.034169 | AJ26: 30.084474 | AK26: 33.626479 | AL26: 34.634559 | AM26: 33.03799 | AN26: 34.585568 | AO26: 33.23442 | AP26: 31.239701 | AQ26: 33.549851 | AR26: 30.719615 | AS26: 37.214923 | AT26: 33.401 | AU26: 40.853694 | AV26: 38.000355 | AW26: 41.63743 | AX26: 42.738619 | AY26: 41.232425 | AZ26: 42.867135 | BA26: 41.599706 | BB26: 39.685355 | BC26: 42.072646 | BD26: 39.316409 | BE26: 45.882606 | BF26: 42.136479 | BG26: 49.6539 | BH26: 46.862235 | BI26: 50.557916 | BJ26: 51.714604 | BK26: 50.260823 | BL26: 51.945054 | BM26: 50.724686 | BN26: 48.85552 | BO26: 51.286625 | BP26: 48.572939 | BQ26: 55.179963 | BR26: 51.472018 | BS26: 59.02407 | BT26: 56.263218 | BU26: 59.986683 | BV26: 61.169791 | BW26: 59.742728 | BX26: 61.454377 | BY26: 60.260336 | BZ26: 58.412673 | CA26: 60.856445 | CB26: 58.144956 | CC26: 64.746824 | CD26: 61.033931 | CE26: 68.590663 | CF26: 65.850583 | CG26: 69.607782 | CH26: 70.826343 | CI26: 69.41586 | CJ26: 71.110399 | CK26: 69.881449 | CL26: 67.975559 | CM26: 70.388853 | CN26: 67.759785 | CO26: 74.338267 | CP26: 70.731507 | CQ26: 78.122959 | CR26: 74.943511 | CS26: 79.539807 | CT26: 78.158396 | CU26: 77.822557 | CW26: 1
C27: Actual | CW27: 0
A28: Am1302 | B28: desl | C28: Forecast | D28: 24.939843 | E28: 26.566257 | F28: 28.425094 | G28: 29.334999 | H28: 25.483484 | I28: 30.109291 | J28: 22.73566 | K28: 27.45121 | L28: 22.345453 | M28: 26.046726 | N28: 21.670621 | O28: 24.970118 | P28: 24.315256 | Q28: 25.929948 | R28: 28.176272 | S28: 29.445588 | T28: 25.550299 | U28: 30.312764 | V28: 22.875894 | W28: 27.705326 | X28: 22.80945 | Y28: 26.725646 | Z28: 22.57911 | AA28: 26.076452 | AB28: 25.582178 | AC28: 27.335955 | AD28: 29.707669 | AE28: 31.094812 | AF28: 27.311242 | AG28: 32.177622 | AH28: 24.833959 | AI28: 29.744737 | AJ28: 24.920923 | AK28: 28.90469 | AL28: 24.825911 | AM28: 28.393979 | AN28: 27.973655 | AO28: 29.802942 | AP28: 32.249283 | AQ28: 33.708077 | AR28: 29.992117 | AS28: 34.922062 | AT28: 27.638543 | AU28: 32.606753 | AV28: 27.838097 | AW28: 31.874848 | AX28: 27.846794 | AY28: 31.463247 | AZ28: 31.08902 | BA28: 32.962303 | BB28: 35.450779 | BC28: 36.950045 | BD28: 33.273008 | BE28: 38.240382 | BF28: 30.992828 | BG28: 35.995569 | BH28: 31.26001 | BI28: 35.328345 | BJ28: 31.33019 | BK28: 34.974656 | BL28: 34.626462 | BM28: 36.523935 | BN28: 39.035151 | BO28: 40.556204 | BP28: 36.900304 | BQ28: 41.887982 | BR28: 34.659166 | BS28: 39.678088 | BT28: 34.955509 | BU28: 39.033981 | BV28: 35.044714 | BW28: 38.699167 | BX28: 38.363994 | BY28: 40.277634 | BZ28: 42.805771 | CA28: 44.340198 | CB28: 40.689852 | CC28: 45.674055 | CD28: 38.435803 | CE28: 43.445791 | CF28: 38.72356 | CG28: 42.810891 | CH28: 38.834563 | CI28: 42.494386 | CJ28: 42.128788 | CK28: 44.001852 | CL28: 46.472374 | CM28: 47.88827 | CN28: 44.383018 | CO28: 49.291534 | CP28: 42.203063 | CQ28: 47.59791 | CR28: 41.617788 | CS28: 47.81802 | CT28: 43.878836 | CU28: 48.424044 | CW28: -1
C29: Actual | CW29: 0
A30: Am1303 | B30: adm | C30: Forecast | D30: 12501.9 | E30: 11963.912 | F30: 10966.619 | G30: 11091.36 | H30: 7235.9655 | I30: 10246.267 | J30: 8263.113 | K30: 11971.448 | L30: 11101.83 | M30: 12406.493 | N30: 13575.725 | O30: 13117.708 | P30: 14591.807 | Q30: 14214.283 | R30: 12810.9 | S30: 13039.202 | T30: 9262.2159 | U30: 12402.839 | V30: 10592.019 | W30: 14423.064 | X30: 13644.547 | Y30: 14984.075 | Z30: 16137.997 | AA30: 15636.105 | AB30: 17054.074 | AC30: 16626.298 | AD30: 15190.522 | AE30: 15406.778 | AF30: 11635.217 | AG30: 14793.38 | AH30: 13007.251 | AI30: 16866.675 | AJ30: 16118.178 | AK30: 17488.038 | AL30: 18671.328 | AM30: 18196.453 | AN30: 19637.851 | AO30: 19229.253 | AP30: 17808.603 | AQ30: 18036.914 | AR30: 14275.721 | AS30: 17443.88 | AT30: 15668.266 | AU30: 19539.065 | AV30: 18802.687 | AW30: 20185.051 | AX30: 21380.847 | AY30: 20918.201 | AZ30: 22371.399 | BA30: 21974.115 | BB30: 20564.272 | BC30: 20802.869 | BD30: 17051.431 | BE30: 20228.823 | BF30: 18461.943 | BG30: 22340.996 | BH30: 21612.397 | BI30: 23002.048 | BJ30: 24204.634 | BK30: 23748.33 | BL30: 25207.567 | BM30: 24816.227 | BN30: 23412.425 | BO30: 23657.216 | BP30: 19911.979 | BQ30: 23095.248 | BR30: 21333.572 | BS30: 25217.015 | BT30: 24492.208 | BU30: 25885.585 | BV30: 27092.366 | BW30: 26640.819 | BX30: 28104.694 | BY30: 27716.485 | BZ30: 26312.848 | CA30: 26554.263 | CB30: 22803.22 | CC30: 25981.338 | CD30: 24218.883 | CE30: 28108.546 | CF30: 27396.976 | CG30: 28805.582 | CH30: 30024.377 | CI30: 29576.496 | CJ30: 31030.794 | CK30: 30639.012 | CL30: 29227.485 | CM30: 29466.856 | CN30: 25781.759 | CO30: 28900.082 | CP30: 27154.472 | CQ30: 31049.496 | CR30: 29747.242 | CS30: 32112.475 | CT30: 32462.117 | CU30: 31611.955 | CW30: 1
C31: Actual | CW31: 0
A32: Am1303 | B32: desl | C32: Forecast | D32: 8649.6299 | E32: 8505.535 | F32: 10680.454 | G32: 11666.454 | H32: 11927.716 | I32: 10718.396 | J32: 10052.603 | K32: 11181.895 | L32: 9168.7115 | M32: 11218.429 | N32: 9323.4704 | O32: 9391.6951 | P32: 10107.062 | Q32: 9740.9176 | R32: 11835.629 | S32: 12890.82 | T32: 13243.953 | U32: 12175.317 | V32: 11640.683 | W32: 12931.574 | X32: 11052.588 | Y32: 13197.514 | Z32: 11359.297 | AA32: 11451.212 | AB32: 12174.789 | AC32: 11818.577 | AD32: 13933.747 | AE32: 15022.138 | AF32: 15419.315 | AG32: 14401.595 | AH32: 13921.075 | AI32: 15267.214 | AJ32: 13443.953 | AK32: 15644.915 | AL32: 13862.515 | AM32: 14008.85 | AN32: 14783.992 | AO32: 14475.385 | AP32: 16633.857 | AQ32: 17761.728 | AR32: 18195.585 | AS32: 17212.877 | AT32: 16766.553 | AU32: 18146.473 | AV32: 16356.567 | AW32: 18590.217 | AX32: 16839.565 | AY32: 17016.527 | AZ32: 17821.114 | BA32: 17540.786 | BB32: 19726.414 | BC32: 20880.346 | BD32: 21339.181 | BE32: 20380.366 | BF32: 19956.844 | BG32: 21358.458 | BH32: 19589.115 | BI32: 21842.185 | BJ32: 20109.844 | BK32: 20304.125 | BL32: 21125.238 | BM32: 20860.873 | BN32: 23062.046 | BO32: 24231.065 | BP32: 24704.273 | BQ32: 23758.747 | BR32: 23347.156 | BS32: 24759.385 | BT32: 22999.786 | BU32: 25262.395 | BV32: 23539.878 | BW32: 23744.118 | BX32: 24574.336 | BY32: 24316.683 | BZ32: 26520.915 | CA32: 27689.352 | CB32: 28160.233 | CC32: 27213.98 | CD32: 26806.594 | CE32: 28229.296 | CF32: 26484.206 | CG32: 28759.596 | CH32: 27041.325 | CI32: 27238.364 | CJ32: 28053.352 | CK32: 27778.526 | CL32: 29979.259 | CM32: 31166.865 | CN32: 31662.215 | CO32: 30723.477 | CP32: 30282.956 | CQ32: 31609.578 | CR32: 29794.072 | CS32: 31261.92 | CT32: 30304.676 | CU32: 32354.319 | CW32: -1
C33: Actual | CW33: 0
