Workbook

Sheet Central
C2: 2017M1 | D2: 2017M2 | E2: 2017M3 | F2: 2017M4 | G2: 2017M5 | H2: 2017M6 | I2: 2017M7 | J2: 2017M8 | K2: 2017M9 | L2: 2017M10 | M2: 2017M11 | N2: 2017M12 | O2: 2018M1 | P2: 2018M2 | Q2: 2018M3 | R2: 2018M4 | S2: 2018M5 | T2: 2018M6 | U2: 2018M7 | V2: 2018M8 | W2: 2018M9 | X2: 2018M10 | Y2: 2018M11 | Z2: 2018M12 | AA2: 2019M1 | AB2: 2019M2 | AC2: 2019M3 | AD2: 2019M4 | AE2: 2019M5 | AF2: 2019M6 | AG2: 2019M7 | AH2: 2019M8 | AI2: 2019M9 | AJ2: 2019M10 | AK2: 2019M11 | AL2: 2019M12 | AM2: 2020M1 | AN2: 2020M2 | AO2: 2020M3 | AP2: 2020M4 | AQ2: 2020M5 | AR2: 2020M6 | AS2: 2020M7 | AT2: 2020M8 | AU2: 2020M9 | AV2: 2020M10 | AW2: 2020M11 | AX2: 2020M12 | AY2: 2021M1 | AZ2: 2021M2 | BA2: 2021M3 | BB2: 2021M4 | BC2: 2021M5 | BD2: 2021M6 | BE2: 2021M7 | BF2: 2021M8 | BG2: 2021M9 | BH2: 2021M10 | BI2: 2021M11 | BJ2: 2021M12 | BK2: 2022M1 | BL2: 2022M2 | BM2: 2022M3 | BN2: 2022M4 | BO2: 2022M5 | BP2: 2022M6 | BQ2: 2022M7 | BR2: 2022M8 | BS2: 2022M9 | BT2: 2022M10 | BU2: 2022M11 | BV2: 2022M12 | BW2: 2023M1 | BX2: 2023M2 | BY2: 2023M3 | BZ2: 2023M4 | CA2: 2023M5 | CB2: 2023M6 | CC2: 2023M7 | CD2: 2023M8 | CE2: 2023M9 | CF2: 2023M10 | CG2: 2023M11 | CH2: 2023M12 | CI2: 2024M1 | CJ2: 2024M2 | CK2: 2024M3 | CL2: 2024M4 | CM2: 2024M5 | CN2: 2024M6 | CO2: 2024M7 | CP2: 2024M8 | CQ2: 2024M9 | CR2: 2024M10 | CS2: 2024M11 | CT2: 2024M12
C3: =DATE(LEFT(C2,4),SUBSTITUTE(RIGHT(C2,2),"M",""),1) -> 42736 | D3: =DATE(LEFT(D2,4),SUBSTITUTE(RIGHT(D2,2),"M",""),1) -> 42767 | E3: =DATE(LEFT(E2,4),SUBSTITUTE(RIGHT(E2,2),"M",""),1) -> 42795 | F3: =DATE(LEFT(F2,4),SUBSTITUTE(RIGHT(F2,2),"M",""),1) -> 42826 | G3: =DATE(LEFT(G2,4),SUBSTITUTE(RIGHT(G2,2),"M",""),1) -> 42856 | H3: =DATE(LEFT(H2,4),SUBSTITUTE(RIGHT(H2,2),"M",""),1) -> 42887 | I3: =DATE(LEFT(I2,4),SUBSTITUTE(RIGHT(I2,2),"M",""),1) -> 42917 | J3: =DATE(LEFT(J2,4),SUBSTITUTE(RIGHT(J2,2),"M",""),1) -> 42948 | ... CT3: =DATE(LEFT(CT2,4),SUBSTITUTE(RIGHT(CT2,2),"M",""),1) -> 45627
B5: 0% growth | C5: ='conditional forecasts_0'!D576 -> -3017.5795 | D5: ='conditional forecasts_0'!E576 -> 9202.0711 | E5: ='conditional forecasts_0'!F576 -> 11583.151 | F5: ='conditional forecasts_0'!G576 -> 14319.87 | G5: ='conditional forecasts_0'!H576 -> 5108.3272 | H5: ='conditional forecasts_0'!I576 -> 19176.409 | I5: ='conditional forecasts_0'!J576 -> 4581.6515 | J5: ='conditional forecasts_0'!K576 -> -1608.9751 | ... CT5: ='conditional forecasts_0'!CU576 -> -10527.779
B6: 2% growth | C6: ='conditional forecasts_2'!D576 -> 276.14311 | D6: ='conditional forecasts_2'!E576 -> 10399.844 | E6: ='conditional forecasts_2'!F576 -> 11164.1 | F6: ='conditional forecasts_2'!G576 -> 14790.758 | G6: ='conditional forecasts_2'!H576 -> 5219.0485 | H6: ='conditional forecasts_2'!I576 -> 19434.069 | I6: ='conditional forecasts_2'!J576 -> 4668.3817 | J6: ='conditional forecasts_2'!K576 -> -1336.474 | ... CT6: ='conditional forecasts_2'!CU576 -> -9908.6298
B7: 4% growth | C7: ='conditional forecasts_4'!D576 -> 3505.9059 | D7: ='conditional forecasts_4'!E576 -> 11574.357 | E7: ='conditional forecasts_4'!F576 -> 10753.186 | F7: ='conditional forecasts_4'!G576 -> 15252.502 | G7: ='conditional forecasts_4'!H576 -> 5327.6197 | H7: ='conditional forecasts_4'!I576 -> 19686.727 | I7: ='conditional forecasts_4'!J576 -> 4753.4279 | J7: ='conditional forecasts_4'!K576 -> -1069.2645 | ... CT7: ='conditional forecasts_4'!CU576 -> -9301.5035
B8: 6% growth | C8: ='conditional forecasts_6'!D576 -> 6674.1456 | D8: ='conditional forecasts_6'!E576 -> 12726.498 | E8: ='conditional forecasts_6'!F576 -> 10350.1 | F8: ='conditional forecasts_6'!G576 -> 15705.449 | G8: ='conditional forecasts_6'!H576 -> 5434.1228 | H8: ='conditional forecasts_6'!I576 -> 19934.572 | I8: ='conditional forecasts_6'!J576 -> 4836.8539 | J8: ='conditional forecasts_6'!K576 -> -807.14504 | ... CT8: ='conditional forecasts_6'!CU576 -> -8705.9422
B9: 8% growth | C9: ='conditional forecasts_8'!D576 -> 9783.1624 | D9: ='conditional forecasts_8'!E576 -> 13857.102 | E9: ='conditional forecasts_8'!F576 -> 9954.5487 | F9: ='conditional forecasts_8'!G576 -> 16149.931 | G9: ='conditional forecasts_8'!H576 -> 5538.635 | H9: ='conditional forecasts_8'!I576 -> 20177.783 | I9: ='conditional forecasts_8'!J576 -> 4918.7206 | J9: ='conditional forecasts_8'!K576 -> -549.92529 | ... CT9: ='conditional forecasts_8'!CU576 -> -8121.5136
B10: Actual | C10: 12771 | D10: 15740 | E10: -854 | F10: 10538 | G10: 6809 | H10: 8340 | I10: 12211 | J10: 4655 | K10: -2148 | L10: -408 | M10: -14412 | N10: -34808 | O10: 20421 | P10: 14407 | Q10: 2264 | R10: 15769 | S10: 3962 | T10: 8366 | U10: 9911 | V10: 13117 | W10: 7901 | X10: -59 | Y10: -7537 | Z10: -39275 | AA10: 22802 | AB10: 14316 | AC10: -1706 | AD10: 15240 | AE10: 6148 | AF10: 10952 | AG10: 9940 | AH10: 11431 | AI10: 10073 | AJ10: 1477 | AK10: -5138 | AL10: -36966
B12: =B5 -> 0% growth | C12: =C5 -> -3017.5795 | D12: =D5+C12 -> 6184.4916 | E12: =E5+D12 -> 17767.643 | F12: =F5+E12 -> 32087.513 | G12: =G5+F12 -> 37195.84 | H12: =H5+G12 -> 56372.249 | I12: =I5+H12 -> 60953.9 | J12: =J5+I12 -> 59344.925 | K12: =K5+J12 -> 60136.969 | ... CT12: =CT5+CS12 -> 159202.62
B13: =B6 -> 2% growth | C13: =C6 -> 276.14311 | D13: =D6+C13 -> 10675.987 | E13: =E6+D13 -> 21840.087 | F13: =F6+E13 -> 36630.845 | G13: =G6+F13 -> 41849.893 | H13: =H6+G13 -> 61283.963 | I13: =I6+H13 -> 65952.345 | J13: =J6+I13 -> 64615.871 | K13: =K6+J13 -> 66752.939 | ... CT13: =CT6+CS13 -> 312492.76
B14: =B7 -> 4% growth | C14: =C7 -> 3505.9059 | D14: =D7+C14 -> 15080.263 | E14: =E7+D14 -> 25833.45 | F14: =F7+E14 -> 41085.951 | G14: =G7+F14 -> 46413.571 | H14: =H7+G14 -> 66100.298 | I14: =I7+H14 -> 70853.726 | J14: =J7+I14 -> 69784.461 | K14: =K7+J14 -> 73240.435 | ... CT14: =CT7+CS14 -> 462806.21
B15: =B8 -> 6% growth | C15: =C8 -> 6674.1456 | D15: =D8+C15 -> 19400.644 | E15: =E8+D15 -> 29750.744 | F15: =F8+E15 -> 45456.193 | G15: =G8+F15 -> 50890.316 | H15: =H8+G15 -> 70824.887 | I15: =I8+H15 -> 75661.741 | J15: =J8+I15 -> 74854.596 | K15: =K8+J15 -> 79604.352 | ... CT15: =CT8+CS15 -> 610256.37
B16: =B9 -> 8% growth | C16: =C9 -> 9783.1624 | D16: =D9+C16 -> 23640.264 | E16: =E9+D16 -> 33594.813 | F16: =F9+E16 -> 49744.743 | G16: =G9+F16 -> 55283.378 | H16: =H9+G16 -> 75461.162 | I16: =I9+H16 -> 80379.882 | J16: =J9+I16 -> 79829.957 | K16: =K9+J16 -> 85849.31 | ... CT16: =CT9+CS16 -> 754950.29
B17: 2015-2016 Defict | C17: 171019 | D17: 171019 | E17: 171019 | F17: 171019 | G17: 171019 | H17: 171019 | I17: 171019 | J17: 171019 | K17: 171019 | L17: 171019 | M17: 171019 | N17: 171019 | O17: 171019 | P17: 171019 | Q17: 171019 | R17: 171019 | S17: 171019 | T17: 171019 | U17: 171019 | V17: 171019 | W17: 171019 | X17: 171019 | Y17: 171019 | Z17: 171019 | AA17: 171019 | AB17: 171019 | AC17: 171019 | AD17: 171019 | AE17: 171019 | AF17: 171019 | AG17: 171019 | AH17: 171019 | AI17: 171019 | AJ17: 171019 | AK17: 171019 | AL17: 171019 | AM17: 171019 | AN17: 171019 | AO17: 171019 | AP17: 171019 | AQ17: 171019 | AR17: 171019 | AS17: 171019 | AT17: 171019 | AU17: 171019 | AV17: 171019 | AW17: 171019 | AX17: 171019 | AY17: 171019 | AZ17: 171019 | BA17: 171019 | BB17: 171019 | BC17: 171019 | BD17: 171019 | BE17: 171019 | BF17: 171019 | BG17: 171019 | BH17: 171019 | BI17: 171019 | BJ17: 171019 | BK17: 171019 | BL17: 171019 | BM17: 171019 | BN17: 171019 | BO17: 171019 | BP17: 171019 | BQ17: 171019 | BR17: 171019 | BS17: 171019 | BT17: 171019 | BU17: 171019 | BV17: 171019 | BW17: 171019 | BX17: 171019 | BY17: 171019 | BZ17: 171019 | CA17: 171019 | CB17: 171019 | CC17: 171019 | CD17: 171019 | CE17: 171019 | CF17: 171019 | CG17: 171019 | CH17: 171019 | CI17: 171019 | CJ17: 171019 | CK17: 171019 | CL17: 171019 | CM17: 171019 | CN17: 171019 | CO17: 171019 | CP17: 171019 | CQ17: 171019 | CR17: 171019 | CS17: 171019 | CT17: 171019
B18: Actual | C18: =C10 -> 12771 | D18: =D10+C18 -> 28511 | E18: =E10+D18 -> 27657 | F18: =F10+E18 -> 38195 | G18: =G10+F18 -> 45004 | H18: =H10+G18 -> 53344 | I18: =I10+H18 -> 65555 | J18: =J10+I18 -> 70210 | K18: =K10+J18 -> 68062 | ... AL18: =AL10+AK18 -> 126250

Sheet South
C2: 2017M1 | D2: 2017M2 | E2: 2017M3 | F2: 2017M4 | G2: 2017M5 | H2: 2017M6 | I2: 2017M7 | J2: 2017M8 | K2: 2017M9 | L2: 2017M10 | M2: 2017M11 | N2: 2017M12 | O2: 2018M1 | P2: 2018M2 | Q2: 2018M3 | R2: 2018M4 | S2: 2018M5 | T2: 2018M6 | U2: 2018M7 | V2: 2018M8 | W2: 2018M9 | X2: 2018M10 | Y2: 2018M11 | Z2: 2018M12 | AA2: 2019M1 | AB2: 2019M2 | AC2: 2019M3 | AD2: 2019M4 | AE2: 2019M5 | AF2: 2019M6 | AG2: 2019M7 | AH2: 2019M8 | AI2: 2019M9 | AJ2: 2019M10 | AK2: 2019M11 | AL2: 2019M12 | AM2: 2020M1 | AN2: 2020M2 | AO2: 2020M3 | AP2: 2020M4 | AQ2: 2020M5 | AR2: 2020M6 | AS2: 2020M7 | AT2: 2020M8 | AU2: 2020M9 | AV2: 2020M10 | AW2: 2020M11 | AX2: 2020M12 | AY2: 2021M1 | AZ2: 2021M2 | BA2: 2021M3 | BB2: 2021M4 | BC2: 2021M5 | BD2: 2021M6 | BE2: 2021M7 | BF2: 2021M8 | BG2: 2021M9 | BH2: 2021M10 | BI2: 2021M11 | BJ2: 2021M12 | BK2: 2022M1 | BL2: 2022M2 | BM2: 2022M3 | BN2: 2022M4 | BO2: 2022M5 | BP2: 2022M6 | BQ2: 2022M7 | BR2: 2022M8 | BS2: 2022M9 | BT2: 2022M10 | BU2: 2022M11 | BV2: 2022M12 | BW2: 2023M1 | BX2: 2023M2 | BY2: 2023M3 | BZ2: 2023M4 | CA2: 2023M5 | CB2: 2023M6 | CC2: 2023M7 | CD2: 2023M8 | CE2: 2023M9 | CF2: 2023M10 | CG2: 2023M11 | CH2: 2023M12 | CI2: 2024M1 | CJ2: 2024M2 | CK2: 2024M3 | CL2: 2024M4 | CM2: 2024M5 | CN2: 2024M6 | CO2: 2024M7 | CP2: 2024M8 | CQ2: 2024M9 | CR2: 2024M10 | CS2: 2024M11 | CT2: 2024M12
C3: =DATE(LEFT(C2,4),SUBSTITUTE(RIGHT(C2,2),"M",""),1) -> 42736 | D3: =DATE(LEFT(D2,4),SUBSTITUTE(RIGHT(D2,2),"M",""),1) -> 42767 | E3: =DATE(LEFT(E2,4),SUBSTITUTE(RIGHT(E2,2),"M",""),1) -> 42795 | F3: =DATE(LEFT(F2,4),SUBSTITUTE(RIGHT(F2,2),"M",""),1) -> 42826 | G3: =DATE(LEFT(G2,4),SUBSTITUTE(RIGHT(G2,2),"M",""),1) -> 42856 | H3: =DATE(LEFT(H2,4),SUBSTITUTE(RIGHT(H2,2),"M",""),1) -> 42887 | I3: =DATE(LEFT(I2,4),SUBSTITUTE(RIGHT(I2,2),"M",""),1) -> 42917 | J3: =DATE(LEFT(J2,4),SUBSTITUTE(RIGHT(J2,2),"M",""),1) -> 42948 | ... CT3: =DATE(LEFT(CT2,4),SUBSTITUTE(RIGHT(CT2,2),"M",""),1) -> 45627
B5: 0% growth | C5: ='conditional forecasts_0'!D575 -> -13884.106 | D5: ='conditional forecasts_0'!E575 -> 3004.6338 | E5: ='conditional forecasts_0'!F575 -> 5730.4693 | F5: ='conditional forecasts_0'!G575 -> 12703.214 | G5: ='conditional forecasts_0'!H575 -> -8569.5664 | H5: ='conditional forecasts_0'!I575 -> 18207.577 | I5: ='conditional forecasts_0'!J575 -> -4895.4459 | J5: ='conditional forecasts_0'!K575 -> -8788.1769 | ... CT5: ='conditional forecasts_0'!CU575 -> -9212.362
B6: 2% growth | C6: ='conditional forecasts_2'!D575 -> -7422.1642 | D6: ='conditional forecasts_2'!E575 -> 6391.4149 | E6: ='conditional forecasts_2'!F575 -> 7287.5175 | F6: ='conditional forecasts_2'!G575 -> 15831.835 | G6: ='conditional forecasts_2'!H575 -> -6147.3018 | H6: ='conditional forecasts_2'!I575 -> 21143.015 | I6: ='conditional forecasts_2'!J575 -> -2177.2604 | J6: ='conditional forecasts_2'!K575 -> -5876.983 | ... CT6: ='conditional forecasts_2'!CU575 -> 199.82204
B7: 4% growth | C7: ='conditional forecasts_4'!D575 -> -1085.7054 | D7: ='conditional forecasts_4'!E575 -> 9712.4291 | E7: ='conditional forecasts_4'!F575 -> 8814.33 | F7: ='conditional forecasts_4'!G575 -> 18899.703 | G7: ='conditional forecasts_4'!H575 -> -3772.0744 | H7: ='conditional forecasts_4'!I575 -> 24021.45 | I7: ='conditional forecasts_4'!J575 -> 488.14146 | J7: ='conditional forecasts_4'!K575 -> -3022.3206 | ... CT7: ='conditional forecasts_4'!CU575 -> 9429.2336
B8: 6% growth | C8: ='conditional forecasts_6'!D575 -> 5130.0516 | D8: ='conditional forecasts_6'!E575 -> 12970.182 | E8: ='conditional forecasts_6'!F575 -> 10312.058 | F8: ='conditional forecasts_6'!G575 -> 21909.131 | G8: ='conditional forecasts_6'!H575 -> -1442.0922 | H8: ='conditional forecasts_6'!I575 -> 26845.054 | I8: ='conditional forecasts_6'!J575 -> 3102.7706 | J8: ='conditional forecasts_6'!K575 -> -222.03607 | ... CT8: ='conditional forecasts_6'!CU575 -> 18482.836
B9: 8% growth | C9: ='conditional forecasts_8'!D575 -> 11229.619 | D9: ='conditional forecasts_8'!E575 -> 16167.039 | E9: ='conditional forecasts_8'!F575 -> 11781.79 | F9: ='conditional forecasts_8'!G575 -> 24862.306 | G9: ='conditional forecasts_8'!H575 -> 844.33642 | H9: ='conditional forecasts_8'!I575 -> 29615.877 | I9: ='conditional forecasts_8'!J575 -> 5668.5254 | J9: ='conditional forecasts_8'!K575 -> 2525.9036 | ... CT9: ='conditional forecasts_8'!CU575 -> 27367.203
B10: Actual | C10: 24391 | D10: 35422 | E10: 1724 | F10: 5537 | G10: -10595 | H10: -14620 | I10: -62 | J10: 5935 | K10: 10534 | L10: 21444 | M10: 15181 | N10: -72740 | O10: 46754 | P10: 37071 | Q10: 21091 | R10: 13298 | S10: -13413 | T10: -17150 | U10: -413 | V10: 10243 | W10: 18063 | X10: 25999 | Y10: 24763 | Z10: -71720 | AA10: 41733 | AB10: 66021 | AC10: -1748 | AD10: 14570 | AE10: -10935 | AF10: -2714 | AG10: 356 | AH10: 13267 | AI10: 23870 | AJ10: 27304 | AK10: 28995 | AL10: -65761
B12: =B5 -> 0% growth | C12: =C5 -> -13884.106 | D12: =D5+C12 -> -10879.472 | E12: =E5+D12 -> -5149.0025 | F12: =F5+E12 -> 7554.2111 | G12: =G5+F12 -> -1015.3553 | H12: =H5+G12 -> 17192.222 | I12: =I5+H12 -> 12296.776 | J12: =J5+I12 -> 3508.5993 | K12: =K5+J12 -> 5140.0478 | ... CT12: =CT5+CS12 -> -65094.233
B13: =B6 -> 2% growth | C13: =C6 -> -7422.1642 | D13: =D6+C13 -> -1030.7493 | E13: =E6+D13 -> 6256.7682 | F13: =F6+E13 -> 22088.603 | G13: =G6+F13 -> 15941.302 | H13: =H6+G13 -> 37084.316 | I13: =I6+H13 -> 34907.056 | J13: =J6+I13 -> 29030.073 | K13: =K6+J13 -> 35465.748 | ... CT13: =CT6+CS13 -> 828782.19
B14: =B7 -> 4% growth | C14: =C7 -> -1085.7054 | D14: =D7+C14 -> 8626.7236 | E14: =E7+D14 -> 17441.054 | F14: =F7+E14 -> 36340.756 | G14: =G7+F14 -> 32568.682 | H14: =H7+G14 -> 56590.132 | I14: =I7+H14 -> 57078.273 | J14: =J7+I14 -> 54055.953 | K14: =K7+J14 -> 65202.563 | ... CT14: =CT7+CS14 -> 1705300.7
B15: =B8 -> 6% growth | C15: =C8 -> 5130.0516 | D15: =D8+C15 -> 18100.234 | E15: =E8+D15 -> 28412.292 | F15: =F8+E15 -> 50321.423 | G15: =G8+F15 -> 48879.331 | H15: =H8+G15 -> 75724.385 | I15: =I8+H15 -> 78827.156 | J15: =J8+I15 -> 78605.12 | K15: =K8+J15 -> 94372.928 | ... CT15: =CT8+CS15 -> 2565122.6
B16: =B9 -> 8% growth | C16: =C9 -> 11229.619 | D16: =D9+C16 -> 27396.658 | E16: =E9+D16 -> 39178.448 | F16: =F9+E16 -> 64040.754 | G16: =G9+F16 -> 64885.09 | H16: =H9+G16 -> 94500.968 | I16: =I9+H16 -> 100169.49 | J16: =J9+I16 -> 102695.4 | K16: =K9+J16 -> 122998.02 | ... CT16: =CT9+CS16 -> 3408872.1
B17: 2015-2016 Defict | C17: 384194 | D17: 384194 | E17: 384194 | F17: 384194 | G17: 384194 | H17: 384194 | I17: 384194 | J17: 384194 | K17: 384194 | L17: 384194 | M17: 384194 | N17: 384194 | O17: 384194 | P17: 384194 | Q17: 384194 | R17: 384194 | S17: 384194 | T17: 384194 | U17: 384194 | V17: 384194 | W17: 384194 | X17: 384194 | Y17: 384194 | Z17: 384194 | AA17: 384194 | AB17: 384194 | AC17: 384194 | AD17: 384194 | AE17: 384194 | AF17: 384194 | AG17: 384194 | AH17: 384194 | AI17: 384194 | AJ17: 384194 | AK17: 384194 | AL17: 384194 | AM17: 384194 | AN17: 384194 | AO17: 384194 | AP17: 384194 | AQ17: 384194 | AR17: 384194 | AS17: 384194 | AT17: 384194 | AU17: 384194 | AV17: 384194 | AW17: 384194 | AX17: 384194 | AY17: 384194 | AZ17: 384194 | BA17: 384194 | BB17: 384194 | BC17: 384194 | BD17: 384194 | BE17: 384194 | BF17: 384194 | BG17: 384194 | BH17: 384194 | BI17: 384194 | BJ17: 384194 | BK17: 384194 | BL17: 384194 | BM17: 384194 | BN17: 384194 | BO17: 384194 | BP17: 384194 | BQ17: 384194 | BR17: 384194 | BS17: 384194 | BT17: 384194 | BU17: 384194 | BV17: 384194 | BW17: 384194 | BX17: 384194 | BY17: 384194 | BZ17: 384194 | CA17: 384194 | CB17: 384194 | CC17: 384194 | CD17: 384194 | CE17: 384194 | CF17: 384194 | CG17: 384194 | CH17: 384194 | CI17: 384194 | CJ17: 384194 | CK17: 384194 | CL17: 384194 | CM17: 384194 | CN17: 384194 | CO17: 384194 | CP17: 384194 | CQ17: 384194 | CR17: 384194 | CS17: 384194 | CT17: 384194
B18: Actual | C18: =C10 -> 24391 | D18: =D10+C18 -> 59813 | E18: =E10+D18 -> 61537 | F18: =F10+E18 -> 67074 | G18: =G10+F18 -> 56479 | H18: =H10+G18 -> 41859 | I18: =I10+H18 -> 41797 | J18: =J10+I18 -> 47732 | K18: =K10+J18 -> 58266 | ... AL18: =AL10+AK18 -> 251695

Sheet Southeast
C2: 2017M1 | D2: 2017M2 | E2: 2017M3 | F2: 2017M4 | G2: 2017M5 | H2: 2017M6 | I2: 2017M7 | J2: 2017M8 | K2: 2017M9 | L2: 2017M10 | M2: 2017M11 | N2: 2017M12 | O2: 2018M1 | P2: 2018M2 | Q2: 2018M3 | R2: 2018M4 | S2: 2018M5 | T2: 2018M6 | U2: 2018M7 | V2: 2018M8 | W2: 2018M9 | X2: 2018M10 | Y2: 2018M11 | Z2: 2018M12 | AA2: 2019M1 | AB2: 2019M2 | AC2: 2019M3 | AD2: 2019M4 | AE2: 2019M5 | AF2: 2019M6 | AG2: 2019M7 | AH2: 2019M8 | AI2: 2019M9 | AJ2: 2019M10 | AK2: 2019M11 | AL2: 2019M12 | AM2: 2020M1 | AN2: 2020M2 | AO2: 2020M3 | AP2: 2020M4 | AQ2: 2020M5 | AR2: 2020M6 | AS2: 2020M7 | AT2: 2020M8 | AU2: 2020M9 | AV2: 2020M10 | AW2: 2020M11 | AX2: 2020M12 | AY2: 2021M1 | AZ2: 2021M2 | BA2: 2021M3 | BB2: 2021M4 | BC2: 2021M5 | BD2: 2021M6 | BE2: 2021M7 | BF2: 2021M8 | BG2: 2021M9 | BH2: 2021M10 | BI2: 2021M11 | BJ2: 2021M12 | BK2: 2022M1 | BL2: 2022M2 | BM2: 2022M3 | BN2: 2022M4 | BO2: 2022M5 | BP2: 2022M6 | BQ2: 2022M7 | BR2: 2022M8 | BS2: 2022M9 | BT2: 2022M10 | BU2: 2022M11 | BV2: 2022M12 | BW2: 2023M1 | BX2: 2023M2 | BY2: 2023M3 | BZ2: 2023M4 | CA2: 2023M5 | CB2: 2023M6 | CC2: 2023M7 | CD2: 2023M8 | CE2: 2023M9 | CF2: 2023M10 | CG2: 2023M11 | CH2: 2023M12 | CI2: 2024M1 | CJ2: 2024M2 | CK2: 2024M3 | CL2: 2024M4 | CM2: 2024M5 | CN2: 2024M6 | CO2: 2024M7 | CP2: 2024M8 | CQ2: 2024M9 | CR2: 2024M10 | CS2: 2024M11 | CT2: 2024M12
C3: =DATE(LEFT(C2,4),SUBSTITUTE(RIGHT(C2,2),"M",""),1) -> 42736 | D3: =DATE(LEFT(D2,4),SUBSTITUTE(RIGHT(D2,2),"M",""),1) -> 42767 | E3: =DATE(LEFT(E2,4),SUBSTITUTE(RIGHT(E2,2),"M",""),1) -> 42795 | F3: =DATE(LEFT(F2,4),SUBSTITUTE(RIGHT(F2,2),"M",""),1) -> 42826 | G3: =DATE(LEFT(G2,4),SUBSTITUTE(RIGHT(G2,2),"M",""),1) -> 42856 | H3: =DATE(LEFT(H2,4),SUBSTITUTE(RIGHT(H2,2),"M",""),1) -> 42887 | I3: =DATE(LEFT(I2,4),SUBSTITUTE(RIGHT(I2,2),"M",""),1) -> 42917 | J3: =DATE(LEFT(J2,4),SUBSTITUTE(RIGHT(J2,2),"M",""),1) -> 42948 | ... CT3: =DATE(LEFT(CT2,4),SUBSTITUTE(RIGHT(CT2,2),"M",""),1) -> 45627
B5: 0% growth | C5: ='conditional forecasts_0'!D574 -> -135434.94 | D5: ='conditional forecasts_0'!E574 -> -54945.843 | E5: ='conditional forecasts_0'!F574 -> -12363.228 | F5: ='conditional forecasts_0'!G574 -> 37425.815 | G5: ='conditional forecasts_0'!H574 -> 2619.6341 | H5: ='conditional forecasts_0'!I574 -> 89765.991 | I5: ='conditional forecasts_0'!J574 -> 35625.985 | J5: ='conditional forecasts_0'!K574 -> -4170.1805 | ... CT5: ='conditional forecasts_0'!CU574 -> -77466.415
B6: 2% growth | C6: ='conditional forecasts_2'!D574 -> -117464.72 | D6: ='conditional forecasts_2'!E574 -> -45277.854 | E6: ='conditional forecasts_2'!F574 -> -8222.4598 | F6: ='conditional forecasts_2'!G574 -> 45061.754 | G6: ='conditional forecasts_2'!H574 -> 6881.9828 | H6: ='conditional forecasts_2'!I574 -> 94941.149 | I6: ='conditional forecasts_2'!J574 -> 39911.185 | J6: ='conditional forecasts_2'!K574 -> -284.19539 | ... CT6: ='conditional forecasts_2'!CU574 -> -77026.78
B7: 4% growth | C7: ='conditional forecasts_4'!D574 -> -99843.444 | D7: ='conditional forecasts_4'!E574 -> -35797.605 | E7: ='conditional forecasts_4'!F574 -> -4162.0996 | F7: ='conditional forecasts_4'!G574 -> 52549.413 | G7: ='conditional forecasts_4'!H574 -> 11061.562 | H7: ='conditional forecasts_4'!I574 -> 100015.81 | I7: ='conditional forecasts_4'!J574 -> 44113.172 | J7: ='conditional forecasts_4'!K574 -> 3526.3289 | ... CT7: ='conditional forecasts_4'!CU574 -> -76595.683
B8: 6% growth | C8: ='conditional forecasts_6'!D574 -> -82557.837 | D8: ='conditional forecasts_6'!E574 -> -26497.943 | E8: ='conditional forecasts_6'!F574 -> -179.08427 | F8: ='conditional forecasts_6'!G574 -> 59894.442 | G8: ='conditional forecasts_6'!H574 -> 15161.526 | H8: ='conditional forecasts_6'!I574 -> 104993.81 | I8: ='conditional forecasts_6'!J574 -> 48235.117 | J8: ='conditional forecasts_6'!K574 -> 7264.2674 | ... CT8: ='conditional forecasts_6'!CU574 -> -76172.798
B9: 8% growth | C9: ='conditional forecasts_8'!D574 -> -65595.344 | D9: ='conditional forecasts_8'!E574 -> -17372.116 | E9: ='conditional forecasts_8'!F574 -> 3729.4778 | F9: ='conditional forecasts_8'!G574 -> 67102.172 | G9: ='conditional forecasts_8'!H574 -> 19184.85 | H9: ='conditional forecasts_8'!I574 -> 109878.76 | I9: ='conditional forecasts_8'!J574 -> 52280.011 | J9: ='conditional forecasts_8'!K574 -> 10932.334 | ... CT9: ='conditional forecasts_8'!CU574 -> -75757.817
B10: Actual | C10: -30388 | D10: 24188 | E10: -28340 | F10: 46039 | G10: 38691 | H10: 9273 | I10: 11764 | J10: 1628 | K10: -8987 | L10: 13552 | M10: -16421 | N10: -174396 | O10: 21924 | P10: 35025 | Q10: 46635 | R10: 78074 | S10: 30840 | T10: 3612 | U10: 24023 | V10: 41303 | W10: 38933 | X10: 15988 | Y10: 35069 | Z10: -167200 | AA10: 6485 | AB10: 101649 | AC10: -10673 | AD10: 81106 | AE10: 29498 | AF10: 31054 | AG10: 23851 | AH10: 51382 | AI10: 56883 | AJ10: 15980 | AK10: 51060 | AL10: -155591
B12: =B5 -> 0% growth | C12: =C5 -> -135434.94 | D12: =D5+C12 -> -190380.79 | E12: =E5+D12 -> -202744.02 | F12: =F5+E12 -> -165318.2 | G12: =G5+F12 -> -162698.57 | H12: =H5+G12 -> -72932.577 | I12: =I5+H12 -> -37306.592 | J12: =J5+I12 -> -41476.772 | K12: =K5+J12 -> -27396.91 | ... CT12: =CT5+CS12 -> -27093.847
B13: =B6 -> 2% growth | C13: =C6 -> -117464.72 | D13: =D6+C13 -> -162742.57 | E13: =E6+D13 -> -170965.03 | F13: =F6+E13 -> -125903.27 | G13: =G6+F13 -> -119021.29 | H13: =H6+G13 -> -24080.143 | I13: =I6+H13 -> 15831.043 | J13: =J6+I13 -> 15546.847 | K13: =K6+J13 -> 39959.39 | ... CT13: =CT6+CS13 -> 1449247
B14: =B7 -> 4% growth | C14: =C7 -> -99843.444 | D14: =D7+C14 -> -135641.05 | E14: =E7+D14 -> -139803.15 | F14: =F7+E14 -> -87253.735 | G14: =G7+F14 -> -76192.173 | H14: =H7+G14 -> 23823.64 | I14: =I7+H14 -> 67936.813 | J14: =J7+I14 -> 71463.141 | K14: =K7+J14 -> 106007.72 | ... CT14: =CT7+CS14 -> 2896919.3
B15: =B8 -> 6% growth | C15: =C8 -> -82557.837 | D15: =D8+C15 -> -109055.78 | E15: =E8+D15 -> -109234.86 | F15: =F8+E15 -> -49340.422 | G15: =G8+F15 -> -34178.896 | H15: =H8+G15 -> 70814.914 | I15: =I8+H15 -> 119050.03 | J15: =J8+I15 -> 126314.3 | K15: =K8+J15 -> 170797.91 | ... CT15: =CT8+CS15 -> 4317015.1
B16: =B9 -> 8% growth | C16: =C9 -> -65595.344 | D16: =D9+C16 -> -82967.46 | E16: =E9+D16 -> -79237.982 | F16: =F9+E16 -> -12135.81 | G16: =G9+F16 -> 7049.0396 | H16: =H9+G16 -> 116927.8 | I16: =I9+H16 -> 169207.81 | J16: =J9+I16 -> 180140.14 | K16: =K9+J16 -> 234376.99 | ... CT16: =CT9+CS16 -> 5710565.6
B17: 2015-2016 Defict | C17: 1711750 | D17: 1711750 | E17: 1711750 | F17: 1711750 | G17: 1711750 | H17: 1711750 | I17: 1711750 | J17: 1711750 | K17: 1711750 | L17: 1711750 | M17: 1711750 | N17: 1711750 | O17: 1711750 | P17: 1711750 | Q17: 1711750 | R17: 1711750 | S17: 1711750 | T17: 1711750 | U17: 1711750 | V17: 1711750 | W17: 1711750 | X17: 1711750 | Y17: 1711750 | Z17: 1711750 | AA17: 1711750 | AB17: 1711750 | AC17: 1711750 | AD17: 1711750 | AE17: 1711750 | AF17: 1711750 | AG17: 1711750 | AH17: 1711750 | AI17: 1711750 | AJ17: 1711750 | AK17: 1711750 | AL17: 1711750 | AM17: 1711750 | AN17: 1711750 | AO17: 1711750 | AP17: 1711750 | AQ17: 1711750 | AR17: 1711750 | AS17: 1711750 | AT17: 1711750 | AU17: 1711750 | AV17: 1711750 | AW17: 1711750 | AX17: 1711750 | AY17: 1711750 | AZ17: 1711750 | BA17: 1711750 | BB17: 1711750 | BC17: 1711750 | BD17: 1711750 | BE17: 1711750 | BF17: 1711750 | BG17: 1711750 | BH17: 1711750 | BI17: 1711750 | BJ17: 1711750 | BK17: 1711750 | BL17: 1711750 | BM17: 1711750 | BN17: 1711750 | BO17: 1711750 | BP17: 1711750 | BQ17: 1711750 | BR17: 1711750 | BS17: 1711750 | BT17: 1711750 | BU17: 1711750 | BV17: 1711750 | BW17: 1711750 | BX17: 1711750 | BY17: 1711750 | BZ17: 1711750 | CA17: 1711750 | CB17: 1711750 | CC17: 1711750 | CD17: 1711750 | CE17: 1711750 | CF17: 1711750 | CG17: 1711750 | CH17: 1711750 | CI17: 1711750 | CJ17: 1711750 | CK17: 1711750 | CL17: 1711750 | CM17: 1711750 | CN17: 1711750 | CO17: 1711750 | CP17: 1711750 | CQ17: 1711750 | CR17: 1711750 | CS17: 1711750 | CT17: 1711750
B18: Actual | C18: =C10 -> -30388 | D18: =D10+C18 -> -6200 | E18: =E10+D18 -> -34540 | F18: =F10+E18 -> 11499 | G18: =G10+F18 -> 50190 | H18: =H10+G18 -> 59463 | I18: =I10+H18 -> 71227 | J18: =J10+I18 -> 72855 | K18: =K10+J18 -> 63868 | ... AL18: =AL10+AK18 -> 373513

Sheet Northeast
C2: 2017M1 | D2: 2017M2 | E2: 2017M3 | F2: 2017M4 | G2: 2017M5 | H2: 2017M6 | I2: 2017M7 | J2: 2017M8 | K2: 2017M9 | L2: 2017M10 | M2: 2017M11 | N2: 2017M12 | O2: 2018M1 | P2: 2018M2 | Q2: 2018M3 | R2: 2018M4 | S2: 2018M5 | T2: 2018M6 | U2: 2018M7 | V2: 2018M8 | W2: 2018M9 | X2: 2018M10 | Y2: 2018M11 | Z2: 2018M12 | AA2: 2019M1 | AB2: 2019M2 | AC2: 2019M3 | AD2: 2019M4 | AE2: 2019M5 | AF2: 2019M6 | AG2: 2019M7 | AH2: 2019M8 | AI2: 2019M9 | AJ2: 2019M10 | AK2: 2019M11 | AL2: 2019M12 | AM2: 2020M1 | AN2: 2020M2 | AO2: 2020M3 | AP2: 2020M4 | AQ2: 2020M5 | AR2: 2020M6 | AS2: 2020M7 | AT2: 2020M8 | AU2: 2020M9 | AV2: 2020M10 | AW2: 2020M11 | AX2: 2020M12 | AY2: 2021M1 | AZ2: 2021M2 | BA2: 2021M3 | BB2: 2021M4 | BC2: 2021M5 | BD2: 2021M6 | BE2: 2021M7 | BF2: 2021M8 | BG2: 2021M9 | BH2: 2021M10 | BI2: 2021M11 | BJ2: 2021M12 | BK2: 2022M1 | BL2: 2022M2 | BM2: 2022M3 | BN2: 2022M4 | BO2: 2022M5 | BP2: 2022M6 | BQ2: 2022M7 | BR2: 2022M8 | BS2: 2022M9 | BT2: 2022M10 | BU2: 2022M11 | BV2: 2022M12 | BW2: 2023M1 | BX2: 2023M2 | BY2: 2023M3 | BZ2: 2023M4 | CA2: 2023M5 | CB2: 2023M6 | CC2: 2023M7 | CD2: 2023M8 | CE2: 2023M9 | CF2: 2023M10 | CG2: 2023M11 | CH2: 2023M12 | CI2: 2024M1 | CJ2: 2024M2 | CK2: 2024M3 | CL2: 2024M4 | CM2: 2024M5 | CN2: 2024M6 | CO2: 2024M7 | CP2: 2024M8 | CQ2: 2024M9 | CR2: 2024M10 | CS2: 2024M11 | CT2: 2024M12
C3: =DATE(LEFT(C2,4),SUBSTITUTE(RIGHT(C2,2),"M",""),1) -> 42736 | D3: =DATE(LEFT(D2,4),SUBSTITUTE(RIGHT(D2,2),"M",""),1) -> 42767 | E3: =DATE(LEFT(E2,4),SUBSTITUTE(RIGHT(E2,2),"M",""),1) -> 42795 | F3: =DATE(LEFT(F2,4),SUBSTITUTE(RIGHT(F2,2),"M",""),1) -> 42826 | G3: =DATE(LEFT(G2,4),SUBSTITUTE(RIGHT(G2,2),"M",""),1) -> 42856 | H3: =DATE(LEFT(H2,4),SUBSTITUTE(RIGHT(H2,2),"M",""),1) -> 42887 | I3: =DATE(LEFT(I2,4),SUBSTITUTE(RIGHT(I2,2),"M",""),1) -> 42917 | J3: =DATE(LEFT(J2,4),SUBSTITUTE(RIGHT(J2,2),"M",""),1) -> 42948 | ... CT3: =DATE(LEFT(CT2,4),SUBSTITUTE(RIGHT(CT2,2),"M",""),1) -> 45627
B5: 0% growth | C5: ='conditional forecasts_0'!D573 -> -77969.91 | D5: ='conditional forecasts_0'!E573 -> -65625.965 | E5: ='conditional forecasts_0'!F573 -> -60086.118 | F5: ='conditional forecasts_0'!G573 -> -32018.079 | G5: ='conditional forecasts_0'!H573 -> -28453.815 | H5: ='conditional forecasts_0'!I573 -> -2791.3684 | I5: ='conditional forecasts_0'!J573 -> -210.10356 | J5: ='conditional forecasts_0'!K573 -> -7614.8038 | ... CT5: ='conditional forecasts_0'!CU573 -> -19927.436
B6: 2% growth | C6: ='conditional forecasts_2'!D573 -> -74669.897 | D6: ='conditional forecasts_2'!E573 -> -60110.633 | E6: ='conditional forecasts_2'!F573 -> -54345.719 | F6: ='conditional forecasts_2'!G573 -> -25688.723 | G6: ='conditional forecasts_2'!H573 -> -22821.359 | H6: ='conditional forecasts_2'!I573 -> 2289.5737 | I6: ='conditional forecasts_2'!J573 -> 4418.897 | J6: ='conditional forecasts_2'!K573 -> -3623.6173 | ... CT6: ='conditional forecasts_2'!CU573 -> -2955.5614
B7: 4% growth | C7: ='conditional forecasts_4'!D573 -> -71433.966 | D7: ='conditional forecasts_4'!E573 -> -54702.402 | E7: ='conditional forecasts_4'!F573 -> -48716.792 | F7: ='conditional forecasts_4'!G573 -> -19482.274 | G7: ='conditional forecasts_4'!H573 -> -17298.279 | H7: ='conditional forecasts_4'!I573 -> 7271.8506 | I7: ='conditional forecasts_4'!J573 -> 8958.0083 | J7: ='conditional forecasts_4'!K573 -> 290.06558 | ... CT7: ='conditional forecasts_4'!CU573 -> 13686.742
B8: 6% growth | C8: ='conditional forecasts_6'!D573 -> -68259.675 | D8: ='conditional forecasts_6'!E573 -> -49397.191 | E8: ='conditional forecasts_6'!F573 -> -43195.088 | F8: ='conditional forecasts_6'!G573 -> -13394.05 | G8: ='conditional forecasts_6'!H573 -> -11880.406 | H8: ='conditional forecasts_6'!I573 -> 12159.221 | I8: ='conditional forecasts_6'!J573 -> 13410.655 | J8: ='conditional forecasts_6'!K573 -> 4129.1975 | ... CT8: ='conditional forecasts_6'!CU573 -> 30012.029
B9: 8% growth | C9: ='conditional forecasts_8'!D573 -> -65144.72 | D9: ='conditional forecasts_8'!E573 -> -44191.148 | E9: ='conditional forecasts_8'!F573 -> -37776.6 | F9: ='conditional forecasts_8'!G573 -> -7419.632 | G9: ='conditional forecasts_8'!H573 -> -6563.8075 | H9: ='conditional forecasts_8'!I573 -> 16955.234 | I9: ='conditional forecasts_8'!J573 -> 17780.07 | J9: ='conditional forecasts_8'!K573 -> 7896.5658 | ... CT9: ='conditional forecasts_8'!CU573 -> 46032.153
B10: Actual | C10: -40803 | D10: -37008 | E10: -29495 | F10: -1119 | G10: 372 | H10: 4981 | I10: 6641 | J10: 19964 | K10: 29644 | L10: 37801 | M10: 3758 | N10: -34332 | O10: -6035 | P10: -25953 | Q10: -13608 | R10: 4447 | S10: 10710 | T10: 3581 | U10: 7163 | V10: 36460 | W10: 62177 | X10: 13426 | Y10: 7301 | Z10: -43984 | AA10: -30279 | AB10: -12441 | AC10: -23728 | AD10: 15593 | AE10: 3319 | AF10: 5142 | AG10: 2582 | AH10: 34697 | AI10: 57035 | AJ10: 21776 | AK10: 19824 | AL10: -34803
B12: =B5 -> 0% growth | C12: =C5 -> -77969.91 | D12: =D5+C12 -> -143595.88 | E12: =E5+D12 -> -203681.99 | F12: =F5+E12 -> -235700.07 | G12: =G5+F12 -> -264153.89 | H12: =H5+G12 -> -266945.26 | I12: =I5+H12 -> -267155.36 | J12: =J5+I12 -> -274770.16 | K12: =K5+J12 -> -266909.15 | ... CT12: =CT5+CS12 -> -1571622
B13: =B6 -> 2% growth | C13: =C6 -> -74669.897 | D13: =D6+C13 -> -134780.53 | E13: =E6+D13 -> -189126.25 | F13: =F6+E13 -> -214814.97 | G13: =G6+F13 -> -237636.33 | H13: =H6+G13 -> -235346.76 | I13: =I6+H13 -> -230927.86 | J13: =J6+I13 -> -234551.48 | K13: =K6+J13 -> -221560.97 | ... CT13: =CT6+CS13 -> -114972.66
B14: =B7 -> 4% growth | C14: =C7 -> -71433.966 | D14: =D7+C14 -> -126136.37 | E14: =E7+D14 -> -174853.16 | F14: =F7+E14 -> -194335.43 | G14: =G7+F14 -> -211633.71 | H14: =H7+G14 -> -204361.86 | I14: =I7+H14 -> -195403.85 | J14: =J7+I14 -> -195113.79 | K14: =K7+J14 -> -177093.39 | ... CT14: =CT7+CS14 -> 1313390.4
B15: =B8 -> 6% growth | C15: =C8 -> -68259.675 | D15: =D8+C15 -> -117656.87 | E15: =E8+D15 -> -160851.95 | F15: =F8+E15 -> -174246 | G15: =G8+F15 -> -186126.41 | H15: =H8+G15 -> -173967.19 | I15: =I8+H15 -> -160556.53 | J15: =J8+I15 -> -156427.34 | K15: =K8+J15 -> -133472.87 | ... CT15: =CT8+CS15 -> 2714544.9
B16: =B9 -> 8% growth | C16: =C9 -> -65144.72 | D16: =D9+C16 -> -109335.87 | E16: =E9+D16 -> -147112.47 | F16: =F9+E16 -> -154532.1 | G16: =G9+F16 -> -161095.91 | H16: =H9+G16 -> -144140.67 | I16: =I9+H16 -> -126360.61 | J16: =J9+I16 -> -118464.04 | K16: =K9+J16 -> -90667.725 | ... CT16: =CT9+CS16 -> 4089508.1
B17: 2015-2016 Defict | C17: 525026 | D17: 525026 | E17: 525026 | F17: 525026 | G17: 525026 | H17: 525026 | I17: 525026 | J17: 525026 | K17: 525026 | L17: 525026 | M17: 525026 | N17: 525026 | O17: 525026 | P17: 525026 | Q17: 525026 | R17: 525026 | S17: 525026 | T17: 525026 | U17: 525026 | V17: 525026 | W17: 525026 | X17: 525026 | Y17: 525026 | Z17: 525026 | AA17: 525026 | AB17: 525026 | AC17: 525026 | AD17: 525026 | AE17: 525026 | AF17: 525026 | AG17: 525026 | AH17: 525026 | AI17: 525026 | AJ17: 525026 | AK17: 525026 | AL17: 525026 | AM17: 525026 | AN17: 525026 | AO17: 525026 | AP17: 525026 | AQ17: 525026 | AR17: 525026 | AS17: 525026 | AT17: 525026 | AU17: 525026 | AV17: 525026 | AW17: 525026 | AX17: 525026 | AY17: 525026 | AZ17: 525026 | BA17: 525026 | BB17: 525026 | BC17: 525026 | BD17: 525026 | BE17: 525026 | BF17: 525026 | BG17: 525026 | BH17: 525026 | BI17: 525026 | BJ17: 525026 | BK17: 525026 | BL17: 525026 | BM17: 525026 | BN17: 525026 | BO17: 525026 | BP17: 525026 | BQ17: 525026 | BR17: 525026 | BS17: 525026 | BT17: 525026 | BU17: 525026 | BV17: 525026 | BW17: 525026 | BX17: 525026 | BY17: 525026 | BZ17: 525026 | CA17: 525026 | CB17: 525026 | CC17: 525026 | CD17: 525026 | CE17: 525026 | CF17: 525026 | CG17: 525026 | CH17: 525026 | CI17: 525026 | CJ17: 525026 | CK17: 525026 | CL17: 525026 | CM17: 525026 | CN17: 525026 | CO17: 525026 | CP17: 525026 | CQ17: 525026 | CR17: 525026 | CS17: 525026 | CT17: 525026
B18: Actual | C18: =C10 -> -40803 | D18: =D10+C18 -> -77811 | E18: =E10+D18 -> -107306 | F18: =F10+E18 -> -108425 | G18: =G10+F18 -> -108053 | H18: =H10+G18 -> -103072 | I18: =I10+H18 -> -96431 | J18: =J10+I18 -> -76467 | K18: =K10+J18 -> -46823 | ... AL18: =AL10+AK18 -> 74806

Sheet North
C2: 2017M1 | D2: 2017M2 | E2: 2017M3 | F2: 2017M4 | G2: 2017M5 | H2: 2017M6 | I2: 2017M7 | J2: 2017M8 | K2: 2017M9 | L2: 2017M10 | M2: 2017M11 | N2: 2017M12 | O2: 2018M1 | P2: 2018M2 | Q2: 2018M3 | R2: 2018M4 | S2: 2018M5 | T2: 2018M6 | U2: 2018M7 | V2: 2018M8 | W2: 2018M9 | X2: 2018M10 | Y2: 2018M11 | Z2: 2018M12 | AA2: 2019M1 | AB2: 2019M2 | AC2: 2019M3 | AD2: 2019M4 | AE2: 2019M5 | AF2: 2019M6 | AG2: 2019M7 | AH2: 2019M8 | AI2: 2019M9 | AJ2: 2019M10 | AK2: 2019M11 | AL2: 2019M12 | AM2: 2020M1 | AN2: 2020M2 | AO2: 2020M3 | AP2: 2020M4 | AQ2: 2020M5 | AR2: 2020M6 | AS2: 2020M7 | AT2: 2020M8 | AU2: 2020M9 | AV2: 2020M10 | AW2: 2020M11 | AX2: 2020M12 | AY2: 2021M1 | AZ2: 2021M2 | BA2: 2021M3 | BB2: 2021M4 | BC2: 2021M5 | BD2: 2021M6 | BE2: 2021M7 | BF2: 2021M8 | BG2: 2021M9 | BH2: 2021M10 | BI2: 2021M11 | BJ2: 2021M12 | BK2: 2022M1 | BL2: 2022M2 | BM2: 2022M3 | BN2: 2022M4 | BO2: 2022M5 | BP2: 2022M6 | BQ2: 2022M7 | BR2: 2022M8 | BS2: 2022M9 | BT2: 2022M10 | BU2: 2022M11 | BV2: 2022M12 | BW2: 2023M1 | BX2: 2023M2 | BY2: 2023M3 | BZ2: 2023M4 | CA2: 2023M5 | CB2: 2023M6 | CC2: 2023M7 | CD2: 2023M8 | CE2: 2023M9 | CF2: 2023M10 | CG2: 2023M11 | CH2: 2023M12 | CI2: 2024M1 | CJ2: 2024M2 | CK2: 2024M3 | CL2: 2024M4 | CM2: 2024M5 | CN2: 2024M6 | CO2: 2024M7 | CP2: 2024M8 | CQ2: 2024M9 | CR2: 2024M10 | CS2: 2024M11 | CT2: 2024M12
C3: =DATE(LEFT(C2,4),SUBSTITUTE(RIGHT(C2,2),"M",""),1) -> 42736 | D3: =DATE(LEFT(D2,4),SUBSTITUTE(RIGHT(D2,2),"M",""),1) -> 42767 | E3: =DATE(LEFT(E2,4),SUBSTITUTE(RIGHT(E2,2),"M",""),1) -> 42795 | F3: =DATE(LEFT(F2,4),SUBSTITUTE(RIGHT(F2,2),"M",""),1) -> 42826 | G3: =DATE(LEFT(G2,4),SUBSTITUTE(RIGHT(G2,2),"M",""),1) -> 42856 | H3: =DATE(LEFT(H2,4),SUBSTITUTE(RIGHT(H2,2),"M",""),1) -> 42887 | I3: =DATE(LEFT(I2,4),SUBSTITUTE(RIGHT(I2,2),"M",""),1) -> 42917 | J3: =DATE(LEFT(J2,4),SUBSTITUTE(RIGHT(J2,2),"M",""),1) -> 42948 | ... CT3: =DATE(LEFT(CT2,4),SUBSTITUTE(RIGHT(CT2,2),"M",""),1) -> 45627
B5: 0% growth | C5: ='conditional forecasts_0'!D572 -> -13588.993 | D5: ='conditional forecasts_0'!E572 -> -7939.7016 | E5: ='conditional forecasts_0'!F572 -> -3923.5238 | F5: ='conditional forecasts_0'!G572 -> -393.20571 | G5: ='conditional forecasts_0'!H572 -> -3154.7061 | H5: ='conditional forecasts_0'!I572 -> 3696.402 | I5: ='conditional forecasts_0'!J572 -> 386.59351 | J5: ='conditional forecasts_0'!K572 -> -758.68359 | ... CT5: ='conditional forecasts_0'!CU572 -> -7482.2748
B6: 2% growth | C6: ='conditional forecasts_2'!D572 -> -11792.135 | D6: ='conditional forecasts_2'!E572 -> -6489.4741 | E6: ='conditional forecasts_2'!F572 -> -3163.0747 | F6: ='conditional forecasts_2'!G572 -> 564.94466 | G6: ='conditional forecasts_2'!H572 -> -2464.3858 | H6: ='conditional forecasts_2'!I572 -> 4406.6274 | I6: ='conditional forecasts_2'!J572 -> 1013.6206 | J6: ='conditional forecasts_2'!K572 -> -151.49648 | ... CT6: ='conditional forecasts_2'!CU572 -> -6617.8461
B7: 4% growth | C7: ='conditional forecasts_4'!D572 -> -10030.17 | D7: ='conditional forecasts_4'!E572 -> -5067.4082 | E7: ='conditional forecasts_4'!F572 -> -2417.3926 | F7: ='conditional forecasts_4'!G572 -> 1504.489 | G7: ='conditional forecasts_4'!H572 -> -1787.4707 | H7: ='conditional forecasts_4'!I572 -> 5103.0612 | I7: ='conditional forecasts_4'!J572 -> 1628.4717 | J7: ='conditional forecasts_4'!K572 -> 443.89985 | ... CT7: ='conditional forecasts_4'!CU572 -> -5770.2035
B8: 6% growth | C8: ='conditional forecasts_6'!D572 -> -8301.7676 | D8: ='conditional forecasts_6'!E572 -> -3672.4309 | E8: ='conditional forecasts_6'!F572 -> -1685.9149 | F8: ='conditional forecasts_6'!G572 -> 2426.1361 | G8: ='conditional forecasts_6'!H572 -> -1123.4499 | H8: ='conditional forecasts_6'!I572 -> 5786.2288 | I8: ='conditional forecasts_6'!J572 -> 2231.6106 | J8: ='conditional forecasts_6'!K572 -> 1027.9546 | ... CT8: ='conditional forecasts_6'!CU572 -> -4938.7075
B9: 8% growth | C9: ='conditional forecasts_8'!D572 -> -6605.6741 | D9: ='conditional forecasts_8'!E572 -> -2303.5295 | E9: ='conditional forecasts_8'!F572 -> -968.11042 | F9: ='conditional forecasts_8'!G572 -> 3330.5552 | G9: ='conditional forecasts_8'!H572 -> -471.8415 | H9: ='conditional forecasts_8'!I572 -> 6456.6261 | I9: ='conditional forecasts_8'!J572 -> 2823.4752 | J9: ='conditional forecasts_8'!K572 -> 1601.0918 | ... CT9: ='conditional forecasts_8'!CU572 -> -4122.7543
B10: Actual | C10: -6835 | D10: -2730 | E10: -6659 | F10: -1139 | G10: -1024 | H10: 1847 | I10: 5346 | J10: 3275 | K10: 5349 | L10: 4210 | M10: -398 | N10: -12263 | O10: -5242 | P10: 638 | Q10: -231 | R10: 4310 | S10: 1560 | T10: 930 | U10: 6635 | V10: 9308 | W10: 10262 | X10: 2379 | Y10: -932 | Z10: -12283 | AA10: -6428 | AB10: 3594 | AC10: -5341 | AD10: 3092 | AE10: 4110 | AF10: 4002 | AG10: 7091 | AH10: 10610 | AI10: 9352 | AJ10: 4315 | AK10: 4491 | AL10: -14190
B12: =B5 -> 0% growth | C12: =C5 -> -13588.993 | D12: =D5+C12 -> -21528.694 | E12: =E5+D12 -> -25452.218 | F12: =F5+E12 -> -25845.424 | G12: =G5+F12 -> -29000.13 | H12: =H5+G12 -> -25303.728 | I12: =I5+H12 -> -24917.134 | J12: =J5+I12 -> -25675.818 | K12: =K5+J12 -> -24376.015 | ... CT12: =CT5+CS12 -> -178163.37
B13: =B6 -> 2% growth | C13: =C6 -> -11792.135 | D13: =D6+C13 -> -18281.609 | E13: =E6+D13 -> -21444.684 | F13: =F6+E13 -> -20879.739 | G13: =G6+F13 -> -23344.125 | H13: =H6+G13 -> -18937.497 | I13: =I6+H13 -> -17923.877 | J13: =J6+I13 -> -18075.373 | K13: =K6+J13 -> -15789.291 | ... CT13: =CT6+CS13 -> 6703.4791
B14: =B7 -> 4% growth | C14: =C7 -> -10030.17 | D14: =D7+C14 -> -15097.578 | E14: =E7+D14 -> -17514.97 | F14: =F7+E14 -> -16010.481 | G14: =G7+F14 -> -17797.952 | H14: =H7+G14 -> -12694.891 | I14: =I7+H14 -> -11066.419 | J14: =J7+I14 -> -10622.519 | K14: =K7+J14 -> -7369.3103 | ... CT14: =CT7+CS14 -> 187980.46
B15: =B8 -> 6% growth | C15: =C8 -> -8301.7676 | D15: =D8+C15 -> -11974.199 | E15: =E8+D15 -> -13660.113 | F15: =F8+E15 -> -11233.977 | G15: =G8+F15 -> -12357.427 | H15: =H8+G15 -> -6571.1984 | I15: =I8+H15 -> -4339.5879 | J15: =J8+I15 -> -3311.6333 | K15: =K8+J15 -> 890.28009 | ... CT15: =CT8+CS15 -> 365804.33
B16: =B9 -> 8% growth | C16: =C9 -> -6605.6741 | D16: =D9+C16 -> -8909.2036 | E16: =E9+D16 -> -9877.314 | F16: =F9+E16 -> -6546.7588 | G16: =G9+F16 -> -7018.6003 | H16: =H9+G16 -> -561.97423 | I16: =I9+H16 -> 2261.5009 | J16: =J9+I16 -> 3862.5927 | K16: =K9+J16 -> 8995.4766 | ... CT16: =CT9+CS16 -> 540304.19
B17: 2015-2016 Defict | C17: 204925 | D17: 204925 | E17: 204925 | F17: 204925 | G17: 204925 | H17: 204925 | I17: 204925 | J17: 204925 | K17: 204925 | L17: 204925 | M17: 204925 | N17: 204925 | O17: 204925 | P17: 204925 | Q17: 204925 | R17: 204925 | S17: 204925 | T17: 204925 | U17: 204925 | V17: 204925 | W17: 204925 | X17: 204925 | Y17: 204925 | Z17: 204925 | AA17: 204925 | AB17: 204925 | AC17: 204925 | AD17: 204925 | AE17: 204925 | AF17: 204925 | AG17: 204925 | AH17: 204925 | AI17: 204925 | AJ17: 204925 | AK17: 204925 | AL17: 204925 | AM17: 204925 | AN17: 204925 | AO17: 204925 | AP17: 204925 | AQ17: 204925 | AR17: 204925 | AS17: 204925 | AT17: 204925 | AU17: 204925 | AV17: 204925 | AW17: 204925 | AX17: 204925 | AY17: 204925 | AZ17: 204925 | BA17: 204925 | BB17: 204925 | BC17: 204925 | BD17: 204925 | BE17: 204925 | BF17: 204925 | BG17: 204925 | BH17: 204925 | BI17: 204925 | BJ17: 204925 | BK17: 204925 | BL17: 204925 | BM17: 204925 | BN17: 204925 | BO17: 204925 | BP17: 204925 | BQ17: 204925 | BR17: 204925 | BS17: 204925 | BT17: 204925 | BU17: 204925 | BV17: 204925 | BW17: 204925 | BX17: 204925 | BY17: 204925 | BZ17: 204925 | CA17: 204925 | CB17: 204925 | CC17: 204925 | CD17: 204925 | CE17: 204925 | CF17: 204925 | CG17: 204925 | CH17: 204925 | CI17: 204925 | CJ17: 204925 | CK17: 204925 | CL17: 204925 | CM17: 204925 | CN17: 204925 | CO17: 204925 | CP17: 204925 | CQ17: 204925 | CR17: 204925 | CS17: 204925 | CT17: 204925
B18: Actual | C18: =C10 -> -6835 | D18: =D10+C18 -> -9565 | E18: =E10+D18 -> -16224 | F18: =F10+E18 -> -17363 | G18: =G10+F18 -> -18387 | H18: =H10+G18 -> -16540 | I18: =I10+H18 -> -11194 | J18: =J10+I18 -> -7919 | K18: =K10+J18 -> -2570 | ... AL18: =AL10+AK18 -> 31011

Sheet Mapa Regiao
A1: ID | B1: Name
A2: 1 | B2: North
A3: 2 | B3: Northeast
A4: 3 | B4: Southeast
A5: 4 | B5: South
A6: 5 | B6: Central

Sheet forecasts (2)
A1: GVAR Forecasts
A2: Last in-sample estimation date: | B2: 2016M12
A3: Last forecast date: | B3: 2024M12
D5: 2017M1 | E5: 2017M2 | F5: 2017M3 | G5: 2017M4 | H5: 2017M5 | I5: 2017M6 | J5: 2017M7 | K5: 2017M8 | L5: 2017M9 | M5: 2017M10 | N5: 2017M11 | O5: 2017M12 | P5: 2018M1 | Q5: 2018M2 | R5: 2018M3 | S5: 2018M4 | T5: 2018M5 | U5: 2018M6 | V5: 2018M7 | W5: 2018M8 | X5: 2018M9 | Y5: 2018M10 | Z5: 2018M11 | AA5: 2018M12 | AB5: 2019M1 | AC5: 2019M2 | AD5: 2019M3 | AE5: 2019M4 | AF5: 2019M5 | AG5: 2019M6 | AH5: 2019M7 | AI5: 2019M8 | AJ5: 2019M9 | AK5: 2019M10 | AL5: 2019M11 | AM5: 2019M12 | AN5: 2020M1 | AO5: 2020M2 | AP5: 2020M3 | AQ5: 2020M4 | AR5: 2020M5 | AS5: 2020M6 | AT5: 2020M7 | AU5: 2020M8 | AV5: 2020M9 | AW5: 2020M10 | AX5: 2020M11 | AY5: 2020M12 | AZ5: 2021M1 | BA5: 2021M2 | BB5: 2021M3 | BC5: 2021M4 | BD5: 2021M5 | BE5: 2021M6 | BF5: 2021M7 | BG5: 2021M8 | BH5: 2021M9 | BI5: 2021M10 | BJ5: 2021M11 | BK5: 2021M12 | BL5: 2022M1 | BM5: 2022M2 | BN5: 2022M3 | BO5: 2022M4 | BP5: 2022M5 | BQ5: 2022M6 | BR5: 2022M7 | BS5: 2022M8 | BT5: 2022M9 | BU5: 2022M10 | BV5: 2022M11 | BW5: 2022M12 | BX5: 2023M1 | BY5: 2023M2 | BZ5: 2023M3 | CA5: 2023M4 | CB5: 2023M5 | CC5: 2023M6 | CD5: 2023M7 | CE5: 2023M8 | CF5: 2023M9 | CG5: 2023M10 | CH5: 2023M11 | CI5: 2023M12 | CJ5: 2024M1 | CK5: 2024M2 | CL5: 2024M3 | CM5: 2024M4 | CN5: 2024M5 | CO5: 2024M6 | CP5: 2024M7 | CQ5: 2024M8 | CR5: 2024M9 | CS5: 2024M10 | CT5: 2024M11 | CU5: 2024M12
A6: Ro1101 | B6: adm | C6: Forecast | D6: 2336.9808 | E6: 2312.3801 | F6: 2657.806 | G6: 2863.4845 | H6: 2929.8957 | I6: 2932.1209 | J6: 2722.6753 | K6: 2533.8324 | L6: 2267.0652 | M6: 2069.9615 | N6: 1943.9223 | O6: 1881.0981 | P6: 1905.1517 | Q6: 1947.7631 | R6: 2016.3741 | S6: 2065.4142 | T6: 2086.708 | U6: 2079.0643 | V6: 2038.9515 | W6: 1987.4013 | X6: 1929.4789 | Y6: 1881.6535 | Z6: 1850.2302 | AA6: 1837.4009 | AB6: 1843.2285 | AC6: 1859.8933 | AD6: 1882.0422 | AE6: 1901.8471 | AF6: 1914.9245 | AG6: 1919.5119 | AH6: 1915.9575 | AI6: 1907.6058 | AJ6: 1897.7589 | AK6: 1890.1217 | AL6: 1886.9702 | AM6: 1889.1262 | AN6: 1896.1482 | AO6: 1906.3751 | AP6: 1917.9433 | AQ6: 1928.9859 | AR6: 1938.2634 | AS6: 1945.2694 | AT6: 1950.1712 | AU6: 1953.7006 | AV6: 1956.7748 | AW6: 1960.3005 | AX6: 1964.9103 | AY6: 1970.8715 | AZ6: 1978.094 | BA6: 1986.2009 | BB6: 1994.6927 | BC6: 2003.0766 | BD6: 2010.9946 | BE6: 2018.2818 | BF6: 2024.9663 | BG6: 2031.2278 | BH6: 2037.3166 | BI6: 2043.4797 | BJ6: 2049.897 | BK6: 2056.6493 | BL6: 2063.7177 | BM6: 2071.007 | BN6: 2078.3845 | BO6: 2085.7193 | BP6: 2092.9142 | BQ6: 2099.9224 | BR6: 2106.7487 | BS6: 2113.4378 | BT6: 2120.0552 | BU6: 2126.6669 | BV6: 2133.3228 | BW6: 2140.0476 | BX6: 2146.8394 | BY6: 2153.6756 | BZ6: 2160.5221 | CA6: 2167.3444 | CB6: 2174.116 | CC6: 2180.8235 | CD6: 2187.4673 | CE6: 2194.0589 | CF6: 2200.6161 | CG6: 2207.1569 | CH6: 2213.6957 | CI6: 2220.2402 | CJ6: 2226.7906 | CK6: 2233.342 | CL6: 2239.8857 | CM6: 2246.4129 | CN6: 2252.9167 | CO6: 2259.3936 | CP6: 2265.8438 | CQ6: 2272.2704 | CR6: 2278.6783 | CS6: 2285.0727 | CT6: 2291.4578 | CU6: 2297.8361 | CV6: 1 | CW6: 1
C7: Actual | CV7: 0 | CW7: 0
A8: Ro1101 | B8: desl | C8: Forecast | D8: 3171.6865 | E8: 3043.8417 | F8: 3116.1931 | G8: 3065.1451 | H8: 3169.497 | I8: 3103.7389 | J8: 3063.4059 | K8: 2947.4825 | L8: 2780.9638 | M8: 2634.6895 | N8: 2467.2418 | O8: 2364.64 | P8: 2288.1828 | Q8: 2256.2625 | R8: 2252.0299 | S8: 2248.9762 | T8: 2248.137 | U8: 2226.0539 | V8: 2191.5499 | W8: 2143.0077 | X8: 2087.8574 | Y8: 2035.4439 | Z8: 1987.8242 | AA8: 1951.5844 | AB8: 1925.0338 | AC8: 1908.0051 | AD8: 1897.5939 | AE8: 1889.9574 | AF8: 1882.8145 | AG8: 1873.1463 | AH8: 1860.4555 | AI8: 1844.6843 | AJ8: 1827.0799 | AK8: 1809.5083 | AL8: 1793.4999 | AM8: 1780.4554 | AN8: 1770.7296 | AO8: 1764.1112 | AP8: 1759.7735 | AQ8: 1756.6334 | AR8: 1753.7581 | AS8: 1750.4382 | AT8: 1746.4344 | AU8: 1741.8373 | AV8: 1737.0084 | AW8: 1732.417 | AX8: 1728.4772 | AY8: 1725.4835 | AZ8: 1723.532 | BA8: 1722.5535 | BB8: 1722.3474 | BC8: 1722.6523 | BD8: 1723.2192 | BE8: 1723.8583 | BF8: 1724.4765 | BG8: 1725.0741 | BH8: 1725.7265 | BI8: 1726.5477 | BJ8: 1727.6505 | BK8: 1729.1169 | BL8: 1730.9787 | BM8: 1733.2179 | BN8: 1735.7777 | BO8: 1738.5823 | BP8: 1741.5578 | BQ8: 1744.6478 | BR8: 1747.8225 | BS8: 1751.0782 | BT8: 1754.4315 | BU8: 1757.9092 | BV8: 1761.5382 | BW8: 1765.3371 | BX8: 1769.3123 | BY8: 1773.4571 | BZ8: 1777.755 | CA8: 1782.1842 | CB8: 1786.7229 | CC8: 1791.3532 | CD8: 1796.0644 | CE8: 1800.8524 | CF8: 1805.719 | CG8: 1810.6691 | CH8: 1815.7081 | CI8: 1820.8396 | CJ8: 1826.0638 | CK8: 1831.3776 | CL8: 1836.7753 | CM8: 1842.2494 | CN8: 1847.7927 | CO8: 1853.3987 | CP8: 1859.063 | CQ8: 1864.7831 | CR8: 1870.5582 | CS8: 1876.3881 | CT8: 1882.2732 | CU8: 1888.2132 | CV8: -1 | CW8: 1
C9: Actual | CV9: 0 | CW9: 0
A10: Ro1102 | B10: adm | C10: Forecast | D10: 4137.5519 | E10: 4444.5537 | F10: 5010.4524 | G10: 5191.2041 | H10: 5154.9613 | I10: 5075.0248 | J10: 4758.7789 | K10: 4580.7946 | L10: 4351.9333 | M10: 4251.2794 | N10: 4238.3129 | O10: 4269.8338 | P10: 4372.4476 | Q10: 4442.5826 | R10: 4507.4578 | S10: 4517.8557 | T10: 4483.2062 | U10: 4419.6918 | V10: 4331.3627 | W10: 4252.5203 | X10: 4184.8822 | Y10: 4143.3702 | Z10: 4125.8544 | AA10: 4125.7486 | AB10: 4137.6964 | AC10: 4149.0379 | AD10: 4155.3258 | AE10: 4150.7121 | AF10: 4135.0917 | AG10: 4111.0759 | AH10: 4082.0784 | AI10: 4053.5659 | AJ10: 4028.8044 | AK10: 4010.5231 | AL10: 3999.0752 | AM10: 3993.216 | AN10: 3990.8947 | AO10: 3989.4078 | AP10: 3986.7774 | AQ10: 3981.636 | AR10: 3973.7276 | AS10: 3963.6517 | AT10: 3952.492 | AU10: 3941.5596 | AV10: 3931.8848 | AW10: 3924.1209 | AX10: 3918.3927 | AY10: 3914.3907 | AZ10: 3911.5419 | BA10: 3909.1731 | BB10: 3906.7224 | BC10: 3903.8274 | BD10: 3900.3855 | BE10: 3896.5214 | BF10: 3892.5063 | BG10: 3888.6668 | BH10: 3885.2843 | BI10: 3882.5373 | BJ10: 3880.4715 | BK10: 3879.0132 | BL10: 3878.0092 | BM10: 3877.2768 | BN10: 3876.6547 | BO10: 3876.036 | BP10: 3875.3823 | BQ10: 3874.7183 | BR10: 3874.1109 | BS10: 3873.6432 | BT10: 3873.3883 | BU10: 3873.3924 | BV10: 3873.6669 | BW10: 3874.1912 | BX10: 3874.9229 | BY10: 3875.8111 | BZ10: 3876.8093 | CA10: 3877.8852 | CB10: 3879.0243 | CC10: 3880.2289 | CD10: 3881.5134 | CE10: 3882.897 | CF10: 3884.3974 | CG10: 3886.0252 | CH10: 3887.7824 | CI10: 3889.6621 | CJ10: 3891.6515 | CK10: 3893.7352 | CL10: 3895.8988 | CM10: 3898.1315 | CN10: 3900.4272 | CO10: 3902.7845 | CP10: 3905.2054 | CQ10: 3907.6934 | CR10: 3910.2518 | CS10: 3912.8823 | CT10: 3915.584 | CU10: 3918.354 | CV10: 1 | CW10: 1
C11: Actual | CV11: 0 | CW11: 0
A12: Ro1102 | B12: desl | C12: Forecast | D12: 5184.4937 | E12: 5069.5182 | F12: 5288.3821 | G12: 5045.6956 | H12: 5145.1068 | I12: 4969.0827 | J12: 4867.0074 | K12: 4829.8545 | L12: 4688.2598 | M12: 4682.2469 | N12: 4608.8389 | O12: 4611.118 | P12: 4607.9062 | Q12: 4589.6876 | R12: 4581.2162 | S12: 4527.0458 | T12: 4478.1086 | U12: 4409.0183 | V12: 4345.4879 | W12: 4294.0142 | X12: 4249.7012 | Y12: 4223.2032 | Z12: 4199.7286 | AA12: 4182.3558 | AB12: 4163.8526 | AC12: 4142.3055 | AD12: 4118.9745 | AE12: 4091.6344 | AF12: 4063.8673 | AG12: 4035.2449 | AH12: 4007.8111 | AI12: 3982.5532 | AJ12: 3959.7141 | AK12: 3940.1412 | AL12: 3922.9989 | AM12: 3907.994 | AN12: 3894.0468 | AO12: 3880.3084 | AP12: 3866.2975 | AQ12: 3851.6823 | AR12: 3836.7818 | AS12: 3821.9481 | AT12: 3807.7321 | AU12: 3794.5459 | AV12: 3782.5806 | AW12: 3771.8658 | AX12: 3762.1985 | AY12: 3753.3371 | AZ12: 3745.0056 | BA12: 3736.9946 | BB12: 3729.1884 | BC12: 3721.5492 | BD12: 3714.1261 | BE12: 3707.0007 | BF12: 3700.2734 | BG12: 3694.027 | BH12: 3688.3083 | BI12: 3683.1239 | BJ12: 3678.436 | BK12: 3674.1811 | BL12: 3670.283 | BM12: 3666.6725 | BN12: 3663.3011 | BO12: 3660.1458 | BP12: 3657.2087 | BQ12: 3654.5077 | BR12: 3652.0671 | BS12: 3649.9068 | BT12: 3648.0358 | BU12: 3646.4499 | BV12: 3645.1334 | BW12: 3644.063 | BX12: 3643.2136 | BY12: 3642.5625 | BZ12: 3642.093 | CA12: 3641.795 | CB12: 3641.6644 | CC12: 3641.7017 | CD12: 3641.9087 | CE12: 3642.2868 | CF12: 3642.835 | CG12: 3643.5494 | CH12: 3644.423 | CI12: 3645.4468 | CJ12: 3646.6113 | CK12: 3647.9072 | CL12: 3649.327 | CM12: 3650.8649 | CN12: 3652.5172 | CO12: 3654.2813 | CP12: 3656.1554 | CQ12: 3658.1376 | CR12: 3660.2254 | CS12: 3662.4157 | CT12: 3664.7045 | CU12: 3667.0874 | CV12: -1 | CW12: 1
C13: Actual | CV13: 0 | CW13: 0
A14: Ac1201 | B14: adm | C14: Forecast | D14: 115.87824 | E14: 122.22568 | F14: 159.99944 | G14: 189.92608 | H14: 210.50288 | I14: 226.23131 | J14: 218.50408 | K14: 205.81668 | L14: 181.40742 | M14: 158.0026 | N14: 138.97397 | O14: 125.71312 | P14: 122.84775 | Q14: 125.51348 | R14: 133.57703 | S14: 141.99013 | T14: 148.14426 | U14: 150.63869 | V14: 148.30071 | W14: 142.84803 | X14: 135.28814 | Y14: 127.7757 | Z14: 121.66734 | AA14: 117.66068 | AB14: 116.03535 | AC14: 116.13942 | AD14: 117.33725 | AE14: 118.70458 | AF14: 119.56194 | AG14: 119.50974 | AH14: 118.40103 | AI14: 116.45363 | AJ14: 113.99433 | AK14: 111.46699 | AL14: 109.24536 | AM14: 107.57015 | AN14: 106.52701 | AO14: 106.02251 | AP14: 105.87051 | AQ14: 105.83219 | AR14: 105.69973 | AS14: 105.33967 | AT14: 104.70869 | AU14: 103.85308 | AV14: 102.87155 | AW14: 101.8845 | AX14: 100.99608 | AY14: 100.27196 | AZ14: 99.731655 | BA14: 99.351461 | BB14: 99.08057 | BC14: 98.857533 | BD14: 98.627801 | BE14: 98.355183 | BF14: 98.026585 | BG14: 97.650811 | BH14: 97.251603 | BI14: 96.859044 | BJ14: 96.500626 | BK14: 96.194829 | BL14: 95.948143 | BM14: 95.755511 | BN14: 95.603725 | BO14: 95.476077 | BP14: 95.357097 | BQ14: 95.236017 | BR14: 95.108388 | BS14: 94.975818 | BT14: 94.844219 | BU14: 94.721368 | BV14: 94.61447 | BW14: 94.52838 | BX14: 94.464764 | BY14: 94.422213 | BZ14: 94.397113 | CA14: 94.384868 | CB14: 94.381135 | CC14: 94.38275 | CD14: 94.388186 | CE14: 94.397522 | CF14: 94.412026 | CG14: 94.43353 | CH14: 94.463796 | CI14: 94.504015 | CJ14: 94.554559 | CK14: 94.614978 | CL14: 94.684206 | CM14: 94.760887 | CN14: 94.843704 | CO14: 94.931637 | CP14: 95.024109 | CQ14: 95.120976 | CR14: 95.222433 | CS14: 95.328844 | CT14: 95.44057 | CU14: 95.557835 | CV14: 1 | CW14: 1
C15: Actual | CV15: 0 | CW15: 0
A16: Ac1201 | B16: desl | C16: Forecast | D16: 204.3715 | E16: 170.28649 | F16: 161.97532 | G16: 145.91385 | H16: 145.94902 | I16: 145.11911 | J16: 150.91298 | K16: 157.89436 | L16: 159.75952 | M16: 161.99066 | N16: 157.72249 | O16: 152.39984 | P16: 145.0417 | Q16: 137.75736 | R16: 132.59744 | S16: 128.57336 | T16: 126.9994 | U16: 126.21613 | V16: 126.07451 | W16: 125.82973 | X16: 124.87459 | Y16: 123.39798 | Z16: 121.13125 | AA16: 118.52404 | AB16: 115.71102 | AC16: 112.97752 | AD16: 110.58109 | AE16: 108.5705 | AF16: 107.04709 | AG16: 105.88467 | AH16: 104.97474 | AI16: 104.14976 | AJ16: 103.25629 | AK16: 102.22397 | AL16: 101.01646 | AM16: 99.689833 | AN16: 98.319508 | AO16: 96.996808 | AP16: 95.79619 | AQ16: 94.751355 | AR16: 93.867019 | AS16: 93.111718 | AT16: 92.442649 | AU16: 91.81393 | AV16: 91.189101 | AW16: 90.549071 | AX16: 89.889629 | AY16: 89.221697 | AZ16: 88.563275 | BA16: 87.934657 | BB16: 87.352776 | BC16: 86.827188 | BD16: 86.359531 | BE16: 85.943634 | BF16: 85.568631 | BG16: 85.221994 | BH16: 84.892769 | BI16: 84.573915 | BJ16: 84.262989 | BK16: 83.961829 | BL16: 83.674941 | BM16: 83.407677 | BN16: 83.164502 | BO16: 82.947833 | BP16: 82.757708 | BQ16: 82.592062 | BR16: 82.447536 | BS16: 82.320412 | BT16: 82.207447 | BU16: 82.106432 | BV16: 82.016374 | BW16: 81.937365 | BX16: 81.87021 | BY16: 81.815967 | BZ16: 81.775525 | CA16: 81.749298 | CB16: 81.73711 | CC16: 81.738238 | CD16: 81.751592 | CE16: 81.775957 | CF16: 81.810217 | CG16: 81.853521 | CH16: 81.905353 | CI16: 81.965505 | CJ16: 82.033989 | CK16: 82.110902 | CL16: 82.196313 | CM16: 82.29017 | CN16: 82.39227 | CO16: 82.502265 | CP16: 82.619712 | CQ16: 82.744138 | CR16: 82.875096 | CS16: 83.012217 | CT16: 83.155221 | CU16: 83.303916 | CV16: -1 | CW16: 1
C17: Actual | CV17: 0 | CW17: 0
A18: Ac1202 | B18: adm | C18: Forecast | D18: 1346.32 | E18: 1379.2961 | F18: 1523.3626 | G18: 1628.7088 | H18: 1634.9611 | I18: 1628.978 | J18: 1538.0996 | K18: 1470.9891 | L18: 1388.7794 | M18: 1335.1077 | N18: 1314.4614 | O18: 1308.902 | P18: 1330.1977 | Q18: 1349.1277 | R18: 1370.5834 | S18: 1381.8493 | T18: 1380.4775 | U18: 1370.1813 | V18: 1349.2702 | W18: 1326.6261 | X18: 1303.7347 | Y18: 1285.6809 | Z18: 1274.3994 | AA18: 1269.3067 | AB18: 1270.0246 | AC18: 1273.0605 | AD18: 1276.4329 | AE18: 1277.6826 | AF18: 1275.6965 | AG18: 1270.6203 | AH18: 1263.0616 | AI18: 1254.591 | AJ18: 1246.4259 | AK18: 1239.6864 | AL18: 1234.8911 | AM18: 1231.9775 | AN18: 1230.5615 | AO18: 1229.9264 | AP18: 1229.4268 | AQ18: 1228.5131 | AR18: 1226.8964 | AS18: 1224.5594 | AT18: 1221.6776 | AU18: 1218.5796 | AV18: 1215.6 | AW18: 1213.022 | AX18: 1211.0043 | AY18: 1209.5644 | AZ18: 1208.6059 | BA18: 1207.9539 | BB18: 1207.4207 | BC18: 1206.8493 | BD18: 1206.1481 | BE18: 1205.3008 | BF18: 1204.3526 | BG18: 1203.3883 | BH18: 1202.5001 | BI18: 1201.7634 | BJ18: 1201.2207 | BK18: 1200.8765 | BL18: 1200.7039 | BM18: 1200.6563 | BN18: 1200.6827 | BO18: 1200.7402 | BP18: 1200.8022 | BQ18: 1200.8614 | BR18: 1200.927 | BS18: 1201.0188 | BT18: 1201.1598 | BU18: 1201.3693 | BV18: 1201.6585 | BW18: 1202.0288 | BX18: 1202.4729 | BY18: 1202.978 | BZ18: 1203.5294 | CA18: 1204.1143 | CB18: 1204.7243 | CC18: 1205.356 | CD18: 1206.0108 | CE18: 1206.693 | CF18: 1207.4081 | CG18: 1208.1605 | CH18: 1208.9527 | CI18: 1209.7847 | CJ18: 1210.6539 | CK18: 1211.5565 | CL18: 1212.4879 | CM18: 1213.4442 | CN18: 1214.4223 | CO18: 1215.4208 | CP18: 1216.4394 | CQ18: 1217.4787 | CR18: 1218.5396 | CS18: 1219.6228 | CT18: 1220.7286 | CU18: 1221.8566 | CV18: 1 | CW18: 1
C19: Actual | CV19: 0 | CW19: 0
A20: Ac1202 | B20: desl | C20: Forecast | D20: 1851.9404 | E20: 1770.2276 | F20: 1801.1693 | G20: 1630.3924 | H20: 1670.5878 | I20: 1596.3179 | J20: 1585.1338 | K20: 1583.7567 | L20: 1538.2506 | M20: 1542.7769 | N20: 1503.8192 | O20: 1497.6911 | P20: 1483.9862 | Q20: 1471.3549 | R20: 1466.9974 | S20: 1447.9043 | T20: 1435.3893 | U20: 1414.0148 | V20: 1395.5055 | W20: 1379.4823 | X20: 1364.6289 | Y20: 1355.4971 | Z20: 1346.0305 | AA20: 1338.7289 | AB20: 1330.4955 | AC20: 1321.4853 | AD20: 1312.3682 | AE20: 1302.4208 | AF20: 1293.1615 | AG20: 1283.984 | AH20: 1275.4874 | AI20: 1267.5831 | AJ20: 1260.1413 | AK20: 1253.409 | AL20: 1247.1025 | AM20: 1241.3499 | AN20: 1235.925 | AO20: 1230.7126 | AP20: 1225.6237 | AQ20: 1220.5406 | AR20: 1215.5376 | AS20: 1210.6451 | AT20: 1205.986 | AU20: 1201.6371 | AV20: 1197.6308 | AW20: 1193.9708 | AX20: 1190.597 | AY20: 1187.4572 | AZ20: 1184.4887 | BA20: 1181.6535 | BB20: 1178.9357 | BC20: 1176.3321 | BD20: 1173.8567 | BE20: 1171.5212 | BF20: 1169.3398 | BG20: 1167.3202 | BH20: 1165.4645 | BI20: 1163.7693 | BJ20: 1162.2247 | BK20: 1160.818 | BL20: 1159.5341 | BM20: 1158.3593 | BN20: 1157.2833 | BO20: 1156.3002 | BP20: 1155.4088 | BQ20: 1154.6105 | BR20: 1153.9081 | BS20: 1153.3036 | BT20: 1152.7966 | BU20: 1152.3842 | BV20: 1152.0616 | BW20: 1151.8227 | BX20: 1151.6613 | BY20: 1151.5723 | BZ20: 1151.5515 | CA20: 1151.5961 | CB20: 1151.7046 | CC20: 1151.8758 | CD20: 1152.109 | CE20: 1152.403 | CF20: 1152.7565 | CG20: 1153.1676 | CH20: 1153.6339 | CI20: 1154.1528 | CJ20: 1154.7216 | CK20: 1155.338 | CL20: 1155.9996 | CM20: 1156.7048 | CN20: 1157.4519 | CO20: 1158.24 | CP20: 1159.0678 | CQ20: 1159.9343 | CR20: 1160.8384 | CS20: 1161.7787 | CT20: 1162.7539 | CU20: 1163.7625 | CV20: -1 | CW20: 1
C21: Actual | CV21: 0 | CW21: 0
A22: Am1301 | B22: adm | C22: Forecast | D22: 20.57114 | E22: 27.653351 | F22: 33.591843 | G22: 30.158634 | H22: 26.779868 | I22: 28.438469 | J22: 24.279521 | K22: 26.136799 | L22: 25.028429 | M22: 25.367057 | N22: 25.860524 | O22: 24.953484 | P22: 25.352419 | Q22: 24.520757 | R22: 24.51491 | S22: 24.217185 | T22: 23.85015 | U22: 23.717568 | V22: 23.221395 | W22: 22.999849 | X22: 22.634648 | Y22: 22.408494 | Z22: 22.271379 | AA22: 22.122016 | AB22: 22.057999 | AC22: 21.905742 | AD22: 21.754442 | AE22: 21.552719 | AF22: 21.330705 | AG22: 21.127338 | AH22: 20.926516 | AI22: 20.766072 | AJ22: 20.61969 | AK22: 20.492911 | AL22: 20.375691 | AM22: 20.258607 | AN22: 20.146251 | AO22: 20.030415 | AP22: 19.916331 | AQ22: 19.801317 | AR22: 19.686505 | AS22: 19.574055 | AT22: 19.464066 | AU22: 19.360134 | AV22: 19.262492 | AW22: 19.172208 | AX22: 19.088399 | AY22: 19.009192 | AZ22: 18.933055 | BA22: 18.858051 | BB22: 18.783666 | BC22: 18.709793 | BD22: 18.637095 | BE22: 18.566502 | BF22: 18.498686 | BG22: 18.434169 | BH22: 18.372949 | BI22: 18.31482 | BJ22: 18.259367 | BK22: 18.206127 | BL22: 18.154724 | BM22: 18.104844 | BN22: 18.056328 | BO22: 18.009115 | BP22: 17.963247 | BQ22: 17.91883 | BR22: 17.87598 | BS22: 17.834797 | BT22: 17.795311 | BU22: 17.757484 | BV22: 17.721209 | BW22: 17.686334 | BX22: 17.652704 | BY22: 17.620186 | BZ22: 17.588691 | CA22: 17.558179 | CB22: 17.528646 | CC22: 17.500108 | CD22: 17.472582 | CE22: 17.446074 | CF22: 17.420567 | CG22: 17.396027 | CH22: 17.372402 | CI22: 17.349636 | CJ22: 17.327672 | CK22: 17.306462 | CL22: 17.285965 | CM22: 17.266155 | CN22: 17.247012 | CO22: 17.228524 | CP22: 17.21068 | CQ22: 17.193469 | CR22: 17.176874 | CS22: 17.160874 | CT22: 17.145446 | CU22: 17.130562 | CV22: 1 | CW22: 1
C23: Actual | CV23: 0 | CW23: 0
A24: Am1301 | B24: desl | C24: Forecast | D24: 36.580924 | E24: 38.527885 | F24: 32.243856 | G24: 30.42985 | H24: 31.397536 | I24: 28.674524 | J24: 31.353747 | K24: 30.590702 | L24: 31.637135 | M24: 31.903292 | N24: 31.258334 | O24: 31.427053 | P24: 30.382727 | Q24: 30.094884 | R24: 29.342084 | S24: 28.759256 | T24: 28.413671 | U24: 27.962448 | V24: 27.890834 | W24: 27.730514 | X24: 27.721589 | Y24: 27.676499 | Z24: 27.540386 | AA24: 27.375396 | AB24: 27.077842 | AC24: 26.778955 | AD24: 26.452761 | AE24: 26.162644 | AF24: 25.93048 | AG24: 25.739803 | AH24: 25.605761 | AI24: 25.487779 | AJ24: 25.382414 | AK24: 25.269152 | AL24: 25.1399 | AM24: 24.997934 | AN24: 24.840939 | AO24: 24.68054 | AP24: 24.520715 | AQ24: 24.369493 | AR24: 24.231548 | AS24: 24.107618 | AT24: 23.998037 | AU24: 23.898398 | AV24: 23.805088 | AW24: 23.713499 | AX24: 23.620475 | AY24: 23.524914 | AZ24: 23.426961 | BA24: 23.328653 | BB24: 23.232145 | BC24: 23.139637 | BD24: 23.052509 | BE24: 22.971104 | BF24: 22.894999 | BG24: 22.823053 | BH24: 22.754017 | BI24: 22.686718 | BJ24: 22.620366 | BK24: 22.554635 | BL24: 22.489591 | BM24: 22.425623 | BN24: 22.36323 | BO24: 22.302889 | BP24: 22.244924 | BQ24: 22.189436 | BR24: 22.136314 | BS24: 22.085276 | BT24: 22.035963 | BU24: 21.988024 | BV24: 21.94119 | BW24: 21.895314 | BX24: 21.850372 | BY24: 21.806434 | BZ24: 21.763614 | CA24: 21.722024 | CB24: 21.681731 | CC24: 21.642744 | CD24: 21.605009 | CE24: 21.568429 | CF24: 21.532885 | CG24: 21.498263 | CH24: 21.464472 | CI24: 21.431454 | CJ24: 21.399181 | CK24: 21.367651 | CL24: 21.336876 | CM24: 21.306867 | CN24: 21.277628 | CO24: 21.249147 | CP24: 21.221397 | CQ24: 21.194338 | CR24: 21.167928 | CS24: 21.14212 | CT24: 21.116878 | CU24: 21.092172 | CV24: -1 | CW24: 1
C25: Actual | CV25: 0 | CW25: 0
