Workbook

Sheet conditional forecasts_6
A1: GVAR Conditional Forecasts
A2: Last in-sample estimation date: | B2: 2016M12
A3: Last forecast date: | B3: 2024M12
D4: =DATE(LEFT(D5,4),SUBSTITUTE(RIGHT(D5,2),"M",""),1) -> 42736 | E4: =DATE(LEFT(E5,4),SUBSTITUTE(RIGHT(E5,2),"M",""),1) -> 42767 | F4: =DATE(LEFT(F5,4),SUBSTITUTE(RIGHT(F5,2),"M",""),1) -> 42795 | G4: =DATE(LEFT(G5,4),SUBSTITUTE(RIGHT(G5,2),"M",""),1) -> 42826 | H4: =DATE(LEFT(H5,4),SUBSTITUTE(RIGHT(H5,2),"M",""),1) -> 42856 | I4: =DATE(LEFT(I5,4),SUBSTITUTE(RIGHT(I5,2),"M",""),1) -> 42887 | J4: =DATE(LEFT(J5,4),SUBSTITUTE(RIGHT(J5,2),"M",""),1) -> 42917 | K4: =DATE(LEFT(K5,4),SUBSTITUTE(RIGHT(K5,2),"M",""),1) -> 42948 | ... CU4: =DATE(LEFT(CU5,4),SUBSTITUTE(RIGHT(CU5,2),"M",""),1) -> 45627
D5: 2017M1 | E5: 2017M2 | F5: 2017M3 | G5: 2017M4 | H5: 2017M5 | I5: 2017M6 | J5: 2017M7 | K5: 2017M8 | L5: 2017M9 | M5: 2017M10 | N5: 2017M11 | O5: 2017M12 | P5: 2018M1 | Q5: 2018M2 | R5: 2018M3 | S5: 2018M4 | T5: 2018M5 | U5: 2018M6 | V5: 2018M7 | W5: 2018M8 | X5: 2018M9 | Y5: 2018M10 | Z5: 2018M11 | AA5: 2018M12 | AB5: 2019M1 | AC5: 2019M2 | AD5: 2019M3 | AE5: 2019M4 | AF5: 2019M5 | AG5: 2019M6 | AH5: 2019M7 | AI5: 2019M8 | AJ5: 2019M9 | AK5: 2019M10 | AL5: 2019M11 | AM5: 2019M12 | AN5: 2020M1 | AO5: 2020M2 | AP5: 2020M3 | AQ5: 2020M4 | AR5: 2020M5 | AS5: 2020M6 | AT5: 2020M7 | AU5: 2020M8 | AV5: 2020M9 | AW5: 2020M10 | AX5: 2020M11 | AY5: 2020M12 | AZ5: 2021M1 | BA5: 2021M2 | BB5: 2021M3 | BC5: 2021M4 | BD5: 2021M5 | BE5: 2021M6 | BF5: 2021M7 | BG5: 2021M8 | BH5: 2021M9 | BI5: 2021M10 | BJ5: 2021M11 | BK5: 2021M12 | BL5: 2022M1 | BM5: 2022M2 | BN5: 2022M3 | BO5: 2022M4 | BP5: 2022M5 | BQ5: 2022M6 | BR5: 2022M7 | BS5: 2022M8 | BT5: 2022M9 | BU5: 2022M10 | BV5: 2022M11 | BW5: 2022M12 | BX5: 2023M1 | BY5: 2023M2 | BZ5: 2023M3 | CA5: 2023M4 | CB5: 2023M5 | CC5: 2023M6 | CD5: 2023M7 | CE5: 2023M8 | CF5: 2023M9 | CG5: 2023M10 | CH5: 2023M11 | CI5: 2023M12 | CJ5: 2024M1 | CK5: 2024M2 | CL5: 2024M3 | CM5: 2024M4 | CN5: 2024M5 | CO5: 2024M6 | CP5: 2024M7 | CQ5: 2024M8 | CR5: 2024M9 | CS5: 2024M10 | CT5: 2024M11 | CU5: 2024M12 | CV5: Serie | CW5: Regiao
A6: Ro1101 | B6: adm | C6: Forecast | D6: 2971.9712 | E6: 3235.3591 | F6: 3789.7455 | G6: 3905.7828 | H6: 4027.6398 | I6: 4239.4372 | J6: 4167.6035 | K6: 4195.5061 | L6: 4015.1358 | M6: 3552.2437 | N6: 3320.0997 | O6: 2765.7109 | P6: 3490.422 | Q6: 3815.1162 | R6: 4479.8551 | S6: 4616.0834 | T6: 4760.9932 | U6: 4951.8967 | V6: 4846.4715 | W6: 4846.2891 | X6: 4652.9903 | Y6: 4206.2382 | Z6: 4014.1244 | AA6: 3512.0586 | AB6: 4289.2772 | AC6: 4655.8892 | AD6: 5346.9741 | AE6: 5495.1962 | AF6: 5642.6933 | AG6: 5832.7547 | AH6: 5727.9427 | AI6: 5732.5766 | AJ6: 5549.0162 | AK6: 5116.3102 | AL6: 4941.3122 | AM6: 4458.0667 | AN6: 5254.5596 | AO6: 5639.8337 | AP6: 6348.1358 | AQ6: 6511.6199 | AR6: 6672.3245 | AS6: 6873.8669 | AT6: 6779.4674 | AU6: 6794.2364 | AV6: 6621.2305 | AW6: 6199.9259 | AX6: 6037.2658 | AY6: 5567.0906 | AZ6: 6377.0122 | BA6: 6775.673 | BB6: 7497.0065 | BC6: 7672.9968 | BD6: 7845.6524 | BE6: 8058.6588 | BF6: 7975.3479 | BG6: 8000.9386 | BH6: 7838.5673 | BI6: 7427.7571 | BJ6: 7275.4773 | BK6: 6815.5924 | BL6: 7635.7526 | BM6: 8044.6588 | BN6: 8776.3167 | BO6: 8962.774 | BP6: 9146.0645 | BQ6: 9369.8291 | BR6: 9297.2662 | BS6: 9333.375 | BT6: 9181.0205 | BU6: 8779.4664 | BV6: 8635.5171 | BW6: 8183.0494 | BX6: 9009.9562 | BY6: 9425.4113 | BZ6: 10164.055 | CA6: 10358.596 | CB6: 10551.565 | CC6: 10786.752 | CD6: 10727.007 | CE6: 10776.452 | CF6: 10636.631 | CG6: 10245.324 | CH6: 10108.039 | CI6: 9657.9205 | CJ6: 10483.309 | CK6: 10894.953 | CL6: 11629.669 | CM6: 11824.675 | CN6: 12024.394 | CO6: 12273.43 | CP6: 12242.867 | CQ6: 12313.065 | CR6: 12212.742 | CS6: 11876.903 | CT6: 11669.003 | CU6: 11348.252 | CV6: 1 | CW6: =CY6 -> 1101 | CY6: =IFERROR(CZ6,0) -> 1101 | CZ6: =RIGHT(A6,4)*1 -> 1101
C7: Actual | CV7: 0 | CW7: =CY7 -> 0 | CY7: =IFERROR(CZ7,0) -> 0 | CZ7: =RIGHT(A7,4)*1 -> #VALUE!
A8: Ro1101 | B8: desl | C8: Forecast | D8: 3215.2547 | E8: 3259.8696 | F8: 3597.8894 | G8: 3676.9513 | H8: 3990.5602 | I8: 3934.672 | J8: 4116.0651 | K8: 4169.8579 | L8: 4058.2588 | M8: 4259.9603 | N8: 4129.0323 | O8: 3993.6849 | P8: 3960.4714 | Q8: 3922.5585 | R8: 4282.2772 | S8: 4316.5015 | T8: 4633.4332 | U8: 4557.3443 | V8: 4716.5201 | W8: 4747.2084 | X8: 4622.2009 | Y8: 4827.4226 | Z8: 4719.0212 | AA8: 4620.6773 | AB8: 4631.0492 | AC8: 4635.1065 | AD8: 5029.5937 | AE8: 5089.3528 | AF8: 5423.8998 | AG8: 5360.6578 | AH8: 5531.3184 | AI8: 5574.7037 | AJ8: 5464.9346 | AK8: 5688.1755 | AL8: 5600.1427 | AM8: 5523.788 | AN8: 5556.9724 | AO8: 5583.9082 | AP8: 6000.6782 | AQ8: 6081.6172 | AR8: 6435.9609 | AS8: 6391.1293 | AT8: 6579.0773 | AU8: 6639.0722 | AV8: 6545.7257 | AW8: 6785.6016 | AX8: 6714.6311 | AY8: 6655.7748 | AZ8: 6706.7387 | BA8: 6751.4974 | BB8: 7185.8975 | BC8: 7284.0999 | BD8: 7655.2528 | BE8: 7626.7686 | BF8: 7830.6483 | BG8: 7906.2277 | BH8: 7828.1858 | BI8: 8083.1394 | BJ8: 8027.0575 | BK8: 7982.9285 | BL8: 8048.4842 | BM8: 8107.7292 | BN8: 8556.5433 | BO8: 8669.1174 | BP8: 9054.6145 | BQ8: 9040.4306 | BR8: 9258.508 | BS8: 9348.0785 | BT8: 9283.6845 | BU8: 9551.8006 | BV8: 9508.2892 | BW8: 9476.1119 | BX8: 9553.089 | BY8: 9623.4399 | BZ8: 10083.363 | CA8: 10207.409 | CB8: 10605.051 | CC8: 10603.842 | CD8: 10835.636 | CE8: 10939.289 | CF8: 10888.708 | CG8: 11169.576 | CH8: 11136.987 | CI8: 11113.426 | CJ8: 11196.639 | CK8: 11271.381 | CL8: 11735.367 | CM8: 11864.141 | CN8: 12269.943 | CO8: 12281.653 | CP8: 12527.854 | CQ8: 12656.665 | CR8: 12627.947 | CS8: 12907.852 | CT8: 12945.375 | CU8: 12851.316 | CV8: -1 | CW8: =CY8 -> 1101 | CY8: =IFERROR(CZ8,0) -> 1101 | CZ8: =RIGHT(A8,4)*1 -> 1101
C9: Actual | CV9: 0 | CW9: =CY9 -> 0 | CY9: =IFERROR(CZ9,0) -> 0 | CZ9: =RIGHT(A9,4)*1 -> #VALUE!
A10: Ro1102 | B10: adm | C10: Forecast | D10: 4805.1099 | E10: 5226.4448 | F10: 5926.0425 | G10: 5890.6612 | H10: 5836.4349 | I10: 5866.0396 | J10: 5539.6805 | K10: 5519.2345 | L10: 5284.6769 | M10: 4895.1884 | N10: 5017.3536 | O10: 4537.0284 | P10: 5521.8318 | Q10: 5723.1581 | R10: 6346.2211 | S10: 6239.7884 | T10: 6136.2739 | U10: 6106.8973 | V10: 5740.0336 | W10: 5699.7651 | X10: 5472.9904 | Y10: 5124.2777 | Z10: 5305.2913 | AA10: 4884.4028 | AB10: 5915.0157 | AC10: 6140.313 | AD10: 6766.7024 | AE10: 6651.0407 | AF10: 6535.6384 | AG10: 6499.564 | AH10: 6135.0453 | AI10: 6106.0689 | AJ10: 5896.974 | AK10: 5569.0608 | AL10: 5771.2311 | AM10: 5370.098 | AN10: 6418.2252 | AO10: 6658.5447 | AP10: 7297.5455 | AQ10: 7192.4112 | AR10: 7086.0193 | AS10: 7058.2103 | AT10: 6702.0591 | AU10: 6682.2711 | AV10: 6483.5886 | AW10: 6167.3107 | AX10: 6381.9834 | AY10: 5993.6669 | AZ10: 7054.3712 | BA10: 7306.6327 | BB10: 7956.776 | BC10: 7862.0341 | BD10: 7765.4689 | BE10: 7747.1444 | BF10: 7400.3203 | BG10: 7389.8127 | BH10: 7200.4013 | BI10: 6893.3785 | BJ10: 7117.2743 | BK10: 6738.1523 | BL10: 7808.0557 | BM10: 8069.5754 | BN10: 8729.088 | BO10: 8643.8422 | BP10: 8556.8484 | BQ10: 8548.0338 | BR10: 8210.4434 | BS10: 8208.6361 | BT10: 8027.1585 | BU10: 7727.1755 | BV10: 7957.2733 | BW10: 7583.8016 | BX10: 8659.3079 | BY10: 8927.0225 | BZ10: 9593.946 | CA10: 9517.747 | CB10: 9441.4663 | CC10: 9444.5551 | CD10: 9119.0698 | CE10: 9128.2225 | CF10: 8955.1219 | CG10: 8659.8139 | CH10: 8890.4278 | CI10: 8513.8551 | CJ10: 9584.4154 | CK10: 9848.0906 | CL10: 10514.539 | CM10: 10445.906 | CN10: 10384.904 | CO10: 10411.366 | CP10: 10118.325 | CQ10: 10148.966 | CR10: 9999.0898 | CS10: 9739.1502 | CT10: 9849.7217 | CU10: 9621.6472 | CV10: 1 | CW10: =CY10 -> 1102 | CY10: =IFERROR(CZ10,0) -> 1102 | CZ10: =RIGHT(A10,4)*1 -> 1102
C11: Actual | CV11: 0 | CW11: =CY11 -> 0 | CY11: =IFERROR(CZ11,0) -> 0 | CZ11: =RIGHT(A11,4)*1 -> #VALUE!
A12: Ro1102 | B12: desl | C12: Forecast | D12: 5153.9883 | E12: 5161.9421 | F12: 5710.6596 | G12: 5353.6937 | H12: 5632.6775 | I12: 5169.5156 | J12: 5243.7174 | K12: 5452.2012 | L12: 4976.2455 | M12: 5726.3922 | N12: 5768.5325 | O12: 5503.6416 | P12: 5610.1213 | Q12: 5361.3351 | R12: 5937.2812 | S12: 5532.6326 | T12: 5772.6057 | U12: 5306.6065 | V12: 5366.2506 | W12: 5577.277 | X12: 5122.3419 | Y12: 5905.541 | Z12: 5987.1629 | AA12: 5757.5482 | AB12: 5888.2536 | AC12: 5652.1109 | AD12: 6233.012 | AE12: 5831.2264 | AF12: 6076.7376 | AG12: 5621.3266 | AH12: 5696.4875 | AI12: 5926.3123 | AJ12: 5491.4214 | AK12: 6294.3165 | AL12: 6394.4835 | AM12: 6182.1018 | AN12: 6328.8583 | AO12: 6107.7539 | AP12: 6702.8128 | AQ12: 6314.4496 | AR12: 6572.8778 | AS12: 6130.2002 | AT12: 6218.2505 | AU12: 6461.3679 | AV12: 6040.244 | AW12: 6857.2622 | AX12: 6971.6598 | AY12: 6773.3365 | AZ12: 6933.7622 | BA12: 6725.8344 | BB12: 7333.5879 | BC12: 6957.5238 | BD12: 7227.9664 | BE12: 6797.1129 | BF12: 6896.8552 | BG12: 7151.5577 | BH12: 6741.9199 | BI12: 7570.3327 | BJ12: 7696.0505 | BK12: 7508.9997 | BL12: 7680.6755 | BM12: 7483.9846 | BN12: 8102.9399 | BO12: 7737.981 | BP12: 8019.332 | BQ12: 7599.066 | BR12: 7708.9543 | BS12: 7973.281 | BT12: 7572.7431 | BU12: 8409.8357 | BV12: 8544.0289 | BW12: 8365.5499 | BX12: 8546.2178 | BY12: 8359.1972 | BZ12: 8988.597 | CA12: 8634.7131 | CB12: 8927.362 | CC12: 8517.9882 | CD12: 8637.646 | CE12: 8909.9779 | CF12: 8515.3499 | CG12: 9356.362 | CH12: 9493.1256 | CI12: 9317.0958 | CJ12: 9501.5759 | CK12: 9320.8394 | CL12: 9961.2821 | CM12: 9621.4676 | CN12: 9932.1616 | CO12: 9544.6145 | CP12: 9674.271 | CQ12: 9964.4908 | CR12: 9584.0866 | CS12: 10321.215 | CT12: 10626.735 | CU12: 10208.612 | CV12: -1 | CW12: =CY12 -> 1102 | CY12: =IFERROR(CZ12,0) -> 1102 | CZ12: =RIGHT(A12,4)*1 -> 1102
C13: Actual | CV13: 0 | CW13: =CY13 -> 0 | CY13: =IFERROR(CZ13,0) -> 0 | CZ13: =RIGHT(A13,4)*1 -> #VALUE!
A14: Ac1201 | B14: adm | C14: Forecast | D14: 126.35637 | E14: 126.8376 | F14: 174.4873 | G14: 206.26166 | H14: 227.6565 | I14: 244.19842 | J14: 228.24291 | K14: 218.46386 | L14: 199.47221 | M14: 168.6912 | N14: 160.43161 | O14: 133.97148 | P14: 160.55887 | Q14: 163.79856 | R14: 199.35335 | S14: 226.80552 | T14: 245.67973 | U14: 257.88541 | V14: 236.94444 | W14: 221.54728 | X14: 198.01528 | Y14: 165.44346 | Z14: 158.64175 | AA14: 136.55949 | AB14: 169.07561 | AC14: 178.11491 | AD14: 218.03992 | AE14: 247.8088 | AF14: 267.06434 | AG14: 278.3689 | AH14: 256.07273 | AI14: 239.56592 | AJ14: 215.58084 | AK14: 183.32062 | AL14: 177.48435 | AM14: 156.80461 | AN14: 190.9267 | AO14: 201.57486 | AP14: 242.96316 | AQ14: 273.95672 | AR14: 294.16028 | AS14: 306.15166 | AT14: 284.3436 | AU14: 268.22018 | AV14: 244.61581 | AW14: 212.81825 | AX14: 207.57471 | AY14: 187.62266 | AZ14: 222.57563 | BA14: 234.10529 | BB14: 276.37101 | BC14: 308.19593 | BD14: 329.163 | BE14: 341.84806 | BF14: 320.67595 | BG14: 305.14904 | BH14: 282.1194 | BI14: 250.88774 | BJ14: 246.20864 | BK14: 226.82287 | BL14: 262.34571 | BM14: 274.45142 | BN14: 317.30386 | BO14: 349.73194 | BP14: 371.32335 | BQ14: 384.65432 | BR14: 364.14255 | BS14: 349.27388 | BT14: 326.87542 | BU14: 296.21878 | BV14: 292.03274 | BW14: 273.04463 | BX14: 308.87708 | BY14: 321.23725 | BZ14: 364.3458 | CA14: 397.10299 | CB14: 419.16568 | CC14: 433.15646 | CD14: 413.49596 | CE14: 399.61704 | CF14: 378.23619 | CG14: 348.47422 | CH14: 344.89658 | CI14: 326.10388 | CJ14: 361.6695 | CK14: 373.37667 | CL14: 415.61836 | CM14: 447.66737 | CN14: 469.44476 | CO14: 483.99429 | CP14: 465.87953 | CQ14: 454.34912 | CR14: 435.76564 | CS14: 410.94035 | CT14: 405.02428 | CU14: 396.1282 | CV14: 1 | CW14: =CY14 -> 1201 | CY14: =IFERROR(CZ14,0) -> 1201 | CZ14: =RIGHT(A14,4)*1 -> 1201
C15: Actual | CV15: 0 | CW15: =CY15 -> 0 | CY15: =IFERROR(CZ15,0) -> 0 | CZ15: =RIGHT(A15,4)*1 -> #VALUE!
A16: Ac1201 | B16: desl | C16: Forecast | D16: 194.03054 | E16: 159.49159 | F16: 159.89575 | G16: 150.59441 | H16: 167.71427 | I16: 164.89237 | J16: 182.71523 | K16: 194.46726 | L16: 188.17507 | M16: 223.65862 | N16: 224.61693 | O16: 220.86935 | P16: 211.90235 | Q16: 185.37527 | R16: 181.7285 | S16: 165.73266 | T16: 182.17851 | U16: 179.61644 | V16: 198.22178 | W16: 211.02415 | X16: 204.62754 | Y16: 239.05045 | Z16: 238.65345 | AA16: 233.97383 | AB16: 224.95317 | AC16: 199.29642 | AD16: 197.19059 | AE16: 183.01269 | AF16: 201.20278 | AG16: 200.1141 | AH16: 219.88655 | AI16: 233.62179 | AJ16: 228.02875 | AK16: 263.21067 | AL16: 263.57587 | AM16: 259.68183 | AN16: 251.48006 | AO16: 226.68531 | AP16: 225.49321 | AQ16: 212.28088 | AR16: 231.47444 | AS16: 231.4002 | AT16: 252.16623 | AU16: 266.84809 | AV16: 262.14254 | AW16: 298.15674 | AX16: 299.31502 | AY16: 296.1955 | AZ16: 288.76742 | BA16: 264.75574 | BB16: 264.35777 | BC16: 251.94597 | BD16: 271.93886 | BE16: 272.65558 | BF16: 294.19936 | BG16: 309.64395 | BH16: 305.68674 | BI16: 342.43685 | BJ16: 344.32068 | BK16: 341.91755 | BL16: 335.19653 | BM16: 311.88089 | BN16: 312.16528 | BO16: 300.41947 | BP16: 321.06046 | BQ16: 322.40825 | BR16: 344.57012 | BS16: 360.6268 | BT16: 357.2844 | BU16: 394.66025 | BV16: 397.18559 | BW16: 395.4386 | BX16: 389.37973 | BY16: 366.71654 | BZ16: 367.62352 | CA16: 356.45051 | CB16: 377.6009 | CC16: 379.39316 | CD16: 401.949 | CE16: 418.37943 | CF16: 415.43348 | CG16: 453.27367 | CH16: 456.36804 | CI16: 455.31517 | CJ16: 450.04967 | CK16: 428.22198 | CL16: 429.95481 | CM16: 419.39457 | CN16: 440.97309 | CO16: 442.96115 | CP16: 464.95635 | CQ16: 481.76347 | CR16: 477.88741 | CS16: 513.47558 | CT16: 522.97315 | CU16: 513.29507 | CV16: -1 | CW16: =CY16 -> 1201 | CY16: =IFERROR(CZ16,0) -> 1201 | CZ16: =RIGHT(A16,4)*1 -> 1201
C17: Actual | CV17: 0 | CW17: =CY17 -> 0 | CY17: =IFERROR(CZ17,0) -> 0 | CZ17: =RIGHT(A17,4)*1 -> #VALUE!
A18: Ac1202 | B18: adm | C18: Forecast | D18: 1566.222 | E18: 1669.4399 | F18: 1861.3321 | G18: 1913.4152 | H18: 1907.3729 | I18: 1934.5405 | J18: 1872.7611 | K18: 1866.7247 | L18: 1791.1189 | M18: 1663.5907 | N18: 1672.1623 | O18: 1456.6262 | P18: 1732.4047 | Q18: 1828.2496 | R18: 2043.712 | S18: 2052.3821 | T18: 2038.8781 | U18: 2048.0319 | V18: 1972.9779 | W18: 1961.2568 | X18: 1884.3659 | Y18: 1764.9583 | Z18: 1787.6017 | AA18: 1588.7409 | AB18: 1880.76 | AC18: 1989.0463 | AD18: 2211.7292 | AE18: 2222.9307 | AF18: 2208.9843 | AG18: 2216.8891 | AH18: 2141.6155 | AI18: 2131.7225 | AJ18: 2058.8655 | AK18: 1945.2369 | AL18: 1974.6553 | AM18: 1782.8227 | AN18: 2081.5579 | AO18: 2195.9077 | AP18: 2423.8637 | AQ18: 2439.5701 | AR18: 2429.4989 | AS18: 2440.864 | AT18: 2368.8846 | AU18: 2362.3545 | AV18: 2293.1024 | AW18: 2183.4003 | AX18: 2217.0459 | AY18: 2029.6396 | AZ18: 2332.8587 | BA18: 2451.612 | BB18: 2683.7923 | BC18: 2703.4997 | BD18: 2697.2132 | BE18: 2712.1884 | BF18: 2643.6996 | BG18: 2640.5911 | BH18: 2574.7282 | BI18: 2468.4033 | BJ18: 2505.4239 | BK18: 2321.3952 | BL18: 2627.9997 | BM18: 2750.1529 | BN18: 2985.7531 | BO18: 3008.8979 | BP18: 3006.0505 | BQ18: 3024.4321 | BR18: 2959.2652 | BS18: 2959.3326 | BT18: 2896.4427 | BU18: 2792.8551 | BV18: 2832.3866 | BW18: 2650.7065 | BX18: 2959.6153 | BY18: 3084.1837 | BZ18: 3322.4674 | CA18: 3348.679 | CB18: 3349.3063 | CC18: 3371.4735 | CD18: 3310.1742 | CE18: 3313.8666 | CF18: 3253.9968 | CG18: 3152.5287 | CH18: 3193.1275 | CI18: 3011.5768 | CJ18: 3320.0453 | CK18: 3444.3085 | CL18: 3682.9749 | CM18: 3711.4475 | CN18: 3716.1656 | CO18: 3744.5213 | CP18: 3690.982 | CQ18: 3702.8147 | CR18: 3645.273 | CS18: 3560.3747 | CT18: 3566.2493 | CU18: 3427.0386 | CV18: 1 | CW18: =CY18 -> 1202 | CY18: =IFERROR(CZ18,0) -> 1202 | CZ18: =RIGHT(A18,4)*1 -> 1202
C19: Actual | CV19: 0 | CW19: =CY19 -> 0 | CY19: =IFERROR(CZ19,0) -> 0 | CZ19: =RIGHT(A19,4)*1 -> #VALUE!
A20: Ac1202 | B20: desl | C20: Forecast | D20: 1767.9933 | E20: 1693.4829 | F20: 1854.6893 | G20: 1692.1342 | H20: 1866.3436 | I20: 1692.8518 | J20: 1735.6664 | K20: 1813.4487 | L20: 1663.1243 | M20: 1996.5782 | N20: 2006.406 | O20: 2024.8715 | P20: 1998.8287 | Q20: 1803.505 | R20: 1949.4918 | S20: 1778.709 | T20: 1933.0603 | U20: 1759.1829 | V20: 1797.4949 | W20: 1876.1613 | X20: 1733.2868 | Y20: 2077.0986 | Z20: 2099.8808 | AA20: 2130.691 | AB20: 2114.0692 | AC20: 1925.0254 | AD20: 2074.9628 | AE20: 1907.1671 | AF20: 2064.8445 | AG20: 1895.3563 | AH20: 1939.2211 | AI20: 2024.3157 | AJ20: 1888.3209 | AK20: 2239.0942 | AL20: 2268.6995 | AM20: 2306.0994 | AN20: 2295.7949 | AO20: 2112.7708 | AP20: 2268.4139 | AQ20: 2106.023 | AR20: 2268.865 | AS20: 2104.405 | AT20: 2153.2792 | AU20: 2243.4594 | AV20: 2112.6696 | AW20: 2468.7525 | AX20: 2503.713 | AY20: 2546.4376 | AZ20: 2541.3614 | BA20: 2363.4295 | BB20: 2524.0185 | BC20: 2366.4383 | BD20: 2533.9772 | BE20: 2374.1213 | BF20: 2427.5227 | BG20: 2522.164 | BH20: 2395.7785 | BI20: 2756.2201 | BJ20: 2795.5086 | BK20: 2842.5474 | BL20: 2841.7861 | BM20: 2668.1761 | BN20: 2833.0864 | BO20: 2679.802 | BP20: 2851.5696 | BQ20: 2695.8226 | BR20: 2753.1609 | BS20: 2851.5296 | BT20: 2728.6558 | BU20: 3092.4301 | BV20: 3134.9553 | BW20: 3185.2544 | BX20: 3187.9098 | BY20: 3017.9834 | BZ20: 3186.8935 | CA20: 3037.8812 | CB20: 3214.0419 | CC20: 3062.565 | CD20: 3123.7624 | CE20: 3225.3094 | CF20: 3104.7771 | CG20: 3470.0707 | CH20: 3513.5207 | CI20: 3564.6139 | CJ20: 3568.5553 | CK20: 3400.8244 | CL20: 3573.8407 | CM20: 3430.2532 | CN20: 3613.303 | CO20: 3470.7362 | CP20: 3536.3694 | CQ20: 3643.3136 | CR20: 3534.0666 | CS20: 3851.6641 | CT20: 3970.0539 | CU20: 3919.4065 | CV20: -1 | CW20: =CY20 -> 1202 | CY20: =IFERROR(CZ20,0) -> 1202 | CZ20: =RIGHT(A20,4)*1 -> 1202
C21: Actual | CV21: 0 | CW21: =CY21 -> 0 | CY21: =IFERROR(CZ21,0) -> 0 | CZ21: =RIGHT(A21,4)*1 -> #VALUE!
A22: Am1301 | B22: adm | C22: Forecast | D22: 25.814872 | E22: 18.651279 | F22: 24.87336 | G22: 18.922578 | H22: 16.609989 | I22: 23.657241 | J22: 12.215635 | K22: 15.478621 | L22: 18.581932 | M22: 6.2223467 | N22: 19.842993 | O22: 16.124996 | P22: 35.240894 | Q22: 21.545165 | R22: 22.184914 | S22: 17.432187 | T22: 14.056681 | U22: 20.669562 | V22: 9.7130523 | W22: 12.669597 | X22: 15.740038 | Y22: 3.3959065 | Z22: 17.012713 | AA22: 13.404947 | AB22: 32.665915 | AC22: 19.088586 | AD22: 19.802556 | AE22: 15.074938 | AF22: 11.687472 | AG22: 18.274656 | AH22: 7.2997059 | AI22: 10.25566 | AJ22: 13.345152 | AK22: 1.0348133 | AL22: 14.692283 | AM22: 11.125913 | AN22: 30.425872 | AO22: 16.88403 | AP22: 17.629865 | AQ22: 12.930516 | AR22: 9.5676619 | AS22: 16.176021 | AT22: 5.2196424 | AU22: 8.1929913 | AV22: 11.300362 | AW22: -0.99024624 | AX22: 12.689429 | AY22: 9.1474955 | AZ22: 28.473223 | BA22: 14.957345 | BB22: 15.728365 | BC22: 11.052865 | BD22: 7.7124041 | BE22: 14.34189 | BF22: 3.4056786 | BG22: 6.3984954 | BH22: 9.5247893 | BI22: -2.7473666 | BJ22: 10.950365 | BK22: 7.4262517 | BL22: 26.769848 | BM22: 13.272273 | BN22: 14.062429 | BO22: 9.4071653 | BP22: 6.0880374 | BQ22: 12.739567 | BR22: 1.8253144 | BS22: 4.8389007 | BT22: 7.9835896 | BU22: -4.2734819 | BV22: 9.4356927 | BW22: 5.9199362 | BX22: 25.270329 | BY22: 11.780311 | BZ22: 12.581437 | CA22: 7.942903 | CB22: 4.6475625 | CC22: 11.329592 | CD22: 0.45003705 | CE22: 3.4982565 | CF22: 6.6715056 | CG22: -5.5685907 | CH22: 8.1412665 | CI22: 4.6069137 | CJ22: 23.926485 | CK22: 10.402785 | CL22: 11.162094 | CM22: 6.5413768 | CN22: 3.2466053 | CO22: 9.9625569 | CP22: -0.68398783 | CQ22: 2.0244552 | CR22: 5.5258581 | CS22: -5.4149637 | CT22: 3.5487841 | CU22: 8.7033078 | CV22: 1 | CW22: =CY22 -> 1301 | CY22: =IFERROR(CZ22,0) -> 1301 | CZ22: =RIGHT(A22,4)*1 -> 1301
C23: Actual | CV23: 0 | CW23: =CY23 -> 0 | CY23: =IFERROR(CZ23,0) -> 0 | CZ23: =RIGHT(A23,4)*1 -> #VALUE!
A24: Am1301 | B24: desl | C24: Forecast | D24: 21.345085 | E24: 26.440844 | F24: 18.798829 | G24: 19.357964 | H24: 21.015534 | I24: 12.312313 | J24: 16.180924 | K24: 15.652415 | L24: 12.338055 | M24: 26.956862 | N24: 24.07691 | O24: 37.369202 | P24: 19.041492 | Q24: 21.90992 | R24: 15.073441 | S24: 15.09976 | T24: 16.422615 | U24: 8.1962576 | V24: 11.867604 | W24: 11.558669 | X24: 8.457051 | Y24: 23.114239 | Z24: 20.230787 | AA24: 33.441253 | AB24: 14.991421 | AC24: 17.772935 | AD24: 10.911186 | AE24: 10.968371 | AF24: 12.354833 | AG24: 4.1952159 | AH24: 7.9148581 | AI24: 7.6298669 | AJ24: 4.5331652 | AK24: 19.185985 | AL24: 16.297704 | AM24: 29.507203 | AN24: 11.06021 | AO24: 13.846573 | AP24: 6.9903419 | AQ24: 7.053708 | AR24: 8.4479875 | AS24: 0.29867914 | AT24: 4.0309797 | AU24: 3.7597557 | AV24: 0.67616343 | AW24: 15.339956 | AX24: 12.459928 | AY24: 25.675393 | AZ24: 7.2331877 | BA24: 10.024381 | BB24: 3.1738788 | BC24: 3.2441298 | BD24: 4.6461735 | BE24: -3.4950509 | BF24: 0.24510265 | BG24: -0.018827488 | BH24: -3.09571 | BI24: 11.574445 | BJ24: 8.7008163 | BK24: 21.9231 | BL24: 3.4883854 | BM24: 6.2877676 | BN24: -0.5541022 | BO24: -0.47529181 | BP24: 0.93454307 | BQ24: -7.200368 | BR24: -3.4558861 | BS24: -3.7175532 | BT24: -6.7937301 | BU24: 7.8766933 | BV24: 5.0044673 | BW24: 18.230961 | BX24: -0.19544261 | BY24: 2.6167562 | BZ24: -4.2086217 | CA24: -4.1118192 | CB24: -2.6856828 | CC24: -10.809617 | CD24: -7.062436 | CE24: -7.3315302 | CF24: -10.424244 | CG24: 4.2236156 | CH24: 1.3285187 | CI24: 14.54048 | CJ24: -3.8830047 | CK24: -1.0552923 | CL24: -7.8181964 | CM24: -7.6754559 | CN24: -6.1670032 | CO24: -14.189416 | CP24: -10.575022 | CQ24: -10.764821 | CR24: -13.43467 | CS24: -1.4446299 | CT24: 1.028274 | CU24: 6.7714174 | CV24: -1 | CW24: =CY24 -> 1301 | CY24: =IFERROR(CZ24,0) -> 1301 | CZ24: =RIGHT(A24,4)*1 -> 1301
C25: Actual | CV25: 0 | CW25: =CY25 -> 0 | CY25: =IFERROR(CZ25,0) -> 0 | CZ25: =RIGHT(A25,4)*1 -> #VALUE!
A26: Am1302 | B26: adm | C26: Forecast | D26: 26.835821 | E26: 24.956815 | F26: 29.292721 | G26: 29.008606 | H26: 28.675295 | I26: 31.060542 | J26: 27.750253 | K26: 28.93718 | L26: 29.05102 | M26: 23.944647 | N26: 27.118566 | O26: 23.307662 | P26: 29.846076 | Q26: 28.4649 | R26: 31.946567 | S26: 31.919541 | T26: 31.364823 | U26: 33.491969 | V26: 30.074745 | W26: 31.042483 | X26: 31.115314 | Y26: 26.175456 | Z26: 29.664404 | AA26: 26.244925 | AB26: 33.1361 | AC26: 31.985914 | AD26: 35.559415 | AE26: 35.520652 | AF26: 34.912228 | AG26: 37.001757 | AH26: 33.597134 | AI26: 34.633406 | AJ26: 34.816872 | AK26: 30.008874 | AL26: 33.63283 | AM26: 30.340827 | AN26: 37.34797 | AO26: 36.301858 | AP26: 39.968162 | AQ26: 40.011642 | AR26: 39.476162 | AS26: 41.631903 | AT26: 38.290711 | AU26: 39.392066 | AV26: 39.645809 | AW26: 34.914795 | AX26: 38.621603 | AY26: 35.415686 | AZ26: 42.508849 | BA26: 41.545877 | BB26: 45.290847 | BC26: 45.408307 | BD26: 44.942936 | BE26: 47.166194 | BF26: 43.89113 | BG26: 45.058042 | BH26: 45.377138 | BI26: 40.711312 | BJ26: 44.483053 | BK26: 41.341759 | BL26: 48.499303 | BM26: 47.600647 | BN26: 51.410068 | BO26: 51.592193 | BP26: 51.191533 | BQ26: 53.479033 | BR26: 50.266886 | BS26: 51.494305 | BT26: 51.870426 | BU26: 47.257428 | BV26: 51.077792 | BW26: 47.981889 | BX26: 55.183585 | BY26: 54.3306 | BZ26: 58.190145 | CA26: 58.429132 | CB26: 58.092817 | CC26: 60.450677 | CD26: 57.311001 | CE26: 58.607259 | CF26: 59.041956 | CG26: 54.47175 | CH26: 58.316307 | CI26: 55.226106 | CJ26: 62.423227 | CK26: 61.565317 | CL26: 65.426224 | CM26: 65.708037 | CN26: 65.43781 | CO26: 67.88886 | CP26: 64.985313 | CQ26: 66.228316 | CR26: 66.987613 | CS26: 62.755367 | CT26: 65.116712 | CU26: 64.581603 | CV26: 1 | CW26: =CY26 -> 1302 | CY26: =IFERROR(CZ26,0) -> 1302 | CZ26: =RIGHT(A26,4)*1 -> 1302
C27: Actual | CV27: 0 | CW27: =CY27 -> 0 | CY27: =IFERROR(CZ27,0) -> 0 | CZ27: =RIGHT(A27,4)*1 -> #VALUE!
A28: Am1302 | B28: desl | C28: Forecast | D28: 31.165148 | E28: 26.281526 | F28: 29.263085 | G28: 26.453364 | H28: 28.051662 | I28: 28.601001 | J28: 28.759106 | K28: 30.662117 | L28: 32.521294 | M28: 31.113244 | N28: 31.258658 | O28: 27.729643 | P28: 29.848562 | Q28: 25.932538 | R28: 29.171178 | S28: 26.656894 | T28: 28.328549 | U28: 29.200535 | V28: 29.407049 | W28: 31.228534 | X28: 33.037447 | Y28: 31.548778 | Z28: 31.632625 | AA28: 28.096443 | AB28: 30.251134 | AC28: 26.404304 | AD28: 29.734173 | AE28: 27.318076 | AF28: 29.084184 | AG28: 30.041228 | AH28: 30.320261 | AI28: 32.200405 | AJ28: 34.054724 | AK28: 32.600896 | AL28: 32.713776 | AM28: 29.206408 | AN28: 31.394427 | AO28: 27.588228 | AP28: 30.966431 | AQ28: 28.604546 | AR28: 30.427572 | AS28: 31.440875 | AT28: 31.772949 | AU28: 33.70166 | AV28: 35.600123 | AW28: 34.186987 | AX28: 34.338491 | AY28: 30.869012 | AZ28: 33.095165 | BA28: 29.327857 | BB28: 32.745791 | BC28: 30.424258 | BD28: 32.287884 | BE28: 33.341644 | BF28: 33.713716 | BG28: 35.681777 | BH28: 37.61887 | BI28: 36.243651 | BJ28: 36.432375 | BK28: 32.99938 | BL28: 35.261155 | BM28: 31.528415 | BN28: 34.979675 | BO28: 32.690158 | BP28: 34.584645 | BQ28: 35.668567 | BR28: 36.07082 | BS28: 38.069938 | BT28: 40.039725 | BU28: 38.699221 | BV28: 38.924447 | BW28: 35.528766 | BX28: 37.827041 | BY28: 34.127996 | BZ28: 37.608301 | CA28: 35.342019 | CB28: 37.254024 | CC28: 38.351332 | CD28: 38.765959 | CE28: 40.780463 | CF28: 42.773251 | CG28: 41.466604 | CH28: 41.738536 | CI28: 38.398924 | CJ28: 40.761072 | CK28: 37.119787 | CL28: 40.644999 | CM28: 38.399426 | CN28: 40.317195 | CO28: 41.342656 | CP28: 41.801316 | CQ28: 43.57369 | CR28: 45.728345 | CS28: 44.63621 | CT28: 44.129449 | CU28: 42.944443 | CV28: -1 | CW28: =CY28 -> 1302 | CY28: =IFERROR(CZ28,0) -> 1302 | CZ28: =RIGHT(A28,4)*1 -> 1302
C29: Actual | CV29: 0 | CW29: =CY29 -> 0 | CY29: =IFERROR(CZ29,0) -> 0 | CZ29: =RIGHT(A29,4)*1 -> #VALUE!
A30: Am1303 | B30: adm | C30: Forecast | D30: 10763.158 | E30: 11341.518 | F30: 13257.279 | G30: 13286.788 | H30: 13280.668 | I30: 13919.26 | J30: 13365.855 | K30: 13917.794 | L30: 13715.059 | M30: 12424.278 | N30: 12435.734 | O30: 9928.9604 | P30: 12334.864 | Q30: 12900.251 | R30: 15096.627 | S30: 15183.945 | T30: 15110.243 | U30: 15634.095 | V30: 14996.076 | W30: 15545.334 | X30: 15434.969 | Y30: 14318.221 | Z30: 14517.248 | AA30: 12149.212 | AB30: 14615.149 | AC30: 15161.908 | AD30: 17288.225 | AE30: 17293.281 | AF30: 17157.136 | AG30: 17653.92 | AH30: 17023.509 | AI30: 17604.077 | AJ30: 17535.182 | AK30: 16459.457 | AL30: 16693.192 | AM30: 14351.633 | AN30: 16836.069 | AO30: 17394.298 | AP30: 19526.196 | AQ30: 19532.462 | AR30: 19395.296 | AS30: 19891.418 | AT30: 19263.154 | AU30: 19850.243 | AV30: 19792.459 | AW30: 18731.33 | AX30: 18981.234 | AY30: 16655.405 | AZ30: 19153.656 | BA30: 19723.167 | BB30: 21864.018 | BC30: 21877.64 | BD30: 21747.112 | BE30: 22249.868 | BF30: 21628.626 | BG30: 22223.197 | BH30: 22173.219 | BI30: 21120.033 | BJ30: 21377.892 | BK30: 19060.046 | BL30: 21566.455 | BM30: 22144.519 | BN30: 24294.505 | BO30: 24317.883 | BP30: 24197.532 | BQ30: 24710.403 | BR30: 24098.5 | BS30: 24700.833 | BT30: 24656.388 | BU30: 23606.256 | BV30: 23865.073 | BW30: 21547.198 | BX30: 24054.321 | BY30: 24635.855 | BZ30: 26793.844 | CA30: 26830.69 | CB30: 26728.835 | CC30: 27263.174 | CD30: 26672.181 | CE30: 27290.519 | CF30: 27252.977 | CG30: 26197.906 | CH30: 26439.662 | CI30: 24095.393 | CJ30: 26573.68 | CK30: 27132.815 | CL30: 29282.66 | CM30: 29339.855 | CN30: 29282.618 | CO30: 29882.294 | CP30: 29393.432 | CQ30: 30045.47 | CR30: 30080.382 | CS30: 29124.079 | CT30: 28909.565 | CU30: 27080.588 | CV30: 1 | CW30: =CY30 -> 1303 | CY30: =IFERROR(CZ30,0) -> 1303 | CZ30: =RIGHT(A30,4)*1 -> 1303
C31: Actual | CV31: 0 | CW31: =CY31 -> 0 | CY31: =IFERROR(CZ31,0) -> 0 | CZ31: =RIGHT(A31,4)*1 -> #VALUE!
A32: Am1303 | B32: desl | C32: Forecast | D32: 12338.554 | E32: 12564.859 | F32: 13745.208 | G32: 13199.332 | H32: 14083.319 | I32: 12626.111 | J32: 12917.373 | K32: 13496.128 | L32: 12328.538 | M32: 14853.283 | N32: 15258.048 | O32: 15047.574 | P32: 14446.662 | Q32: 13615.794 | R32: 14819.37 | S32: 14020.108 | T32: 14802.742 | U32: 13332.071 | V32: 13549.301 | W32: 14124.14 | X32: 13026.181 | Y32: 15679.819 | Z32: 16244.453 | AA32: 16175.42 | AB32: 15663.806 | AC32: 14863.294 | AD32: 16053.928 | AE32: 15224.676 | AF32: 15984.913 | AG32: 14514.059 | AH32: 14755.873 | AI32: 15374.083 | AJ32: 14328.959 | AK32: 17036.594 | AL32: 17651.372 | AM32: 17626.763 | AN32: 17153.799 | AO32: 16386.729 | AP32: 17606.273 | AQ32: 16802.256 | AR32: 17585.321 | AS32: 16136.582 | AT32: 16401.584 | AU32: 17045.412 | AV32: 16028.845 | AW32: 18767.524 | AX32: 19414.666 | AY32: 19422.332 | AZ32: 18980.372 | BA32: 18242.387 | BB32: 19489.035 | BC32: 18710.512 | BD32: 19518.016 | BE32: 18093.184 | BF32: 18381.909 | BG32: 19049.435 | BH32: 18056.567 | BI32: 20818.922 | BJ32: 21489.72 | BK32: 21521.076 | BL32: 21102.931 | BM32: 20388.963 | BN32: 21659.825 | BO32: 20905.566 | BP32: 21737.072 | BQ32: 20335.515 | BR32: 20646.259 | BS32: 21334.084 | BT32: 20359.562 | BU32: 23138.471 | BV32: 23824.669 | BW32: 23871.368 | BX32: 23469.872 | BY32: 22775.174 | BZ32: 24068.779 | CA32: 23340.733 | CB32: 24200.82 | CC32: 22828.026 | CD32: 23164.807 | CE32: 23872.905 | CF32: 22910.654 | CG32: 25693.06 | CH32: 26375.28 | CI32: 26414.543 | CJ32: 26007.713 | CK32: 25315.1 | CL32: 26628.317 | CM32: 25934.468 | CN32: 26847.952 | CO32: 25550.58 | CP32: 25925.431 | CQ32: 26714.185 | CR32: 25803.233 | CS32: 28238.401 | CT32: 29502.905 | CU32: 28667.026 | CV32: -1 | CW32: =CY32 -> 1303 | CY32: =IFERROR(CZ32,0) -> 1303 | CZ32: =RIGHT(A32,4)*1 -> 1303
C33: Actual | CV33: 0 | CW33: =CY33 -> 0 | CY33: =IFERROR(CZ33,0) -> 0 | CZ33: =RIGHT(A33,4)*1 -> #VALUE!
A34: Am1304 | B34: adm | C34: Forecast | D34: 91.920675 | E34: 89.855785 | F34: 100.81865 | G34: 91.963398 | H34: 89.622268 | I34: 89.502999 | J34: 83.248093 | K34: 84.52792 | L34: 79.691006 | M34: 74.154167 | N34: 78.735903 | O34: 66.415709 | P34: 93.442955 | Q34: 92.614588 | R34: 105.55325 | S34: 96.781993 | T34: 93.842962 | U34: 92.741899 | V34: 86.014448 | W34: 87.117478 | X34: 82.478184 | Y34: 77.539941 | Z34: 82.82962 | AA34: 71.140911 | AB34: 98.620937 | AC34: 98.023412 | AD34: 111.02825 | AE34: 102.26719 | AF34: 99.378012 | AG34: 98.421383 | AH34: 91.943004 | AI34: 93.376779 | AJ34: 89.114562 | AK34: 84.567725 | AL34: 90.240904 | AM34: 78.915733 | AN34: 106.73434 | AO34: 106.44909 | AP34: 119.74094 | AQ34: 111.24553 | AR34: 108.6076 | AS34: 107.89691 | AT34: 101.66815 | AU34: 103.3616 | AV34: 99.371199 | AW34: 95.105982 | AX34: 101.0652 | AY34: 90.024207 | AZ34: 118.11997 | BA34: 118.10202 | BB34: 131.65097 | BC34: 123.40393 | BD34: 121.00787 | BE34: 120.53462 | BF34: 114.54027 | BG34: 116.46574 | BH34: 112.70506 | BI34: 108.6673 | BJ34: 114.85191 | BK34: 104.03481 | BL34: 132.3538 | BM34: 132.55921 | BN34: 146.33209 | BO34: 138.30909 | BP34: 136.13568 | BQ34: 135.88108 | BR34: 130.09807 | BS34: 132.22431 | BT34: 128.6517 | BU34: 124.78926 | BV34: 131.13927 | BW34: 120.48347 | BX34: 148.96756 | BY34: 149.35027 | BZ34: 163.31903 | CA34: 155.51265 | CB34: 153.57247 | CC34: 153.55694 | CD34: 148.00248 | CE34: 150.32828 | CF34: 146.90953 | CG34: 143.14642 | CH34: 149.54322 | CI34: 138.89921 | CJ34: 167.39072 | CK34: 167.82349 | CL34: 181.90789 | CM34: 174.34728 | CN34: 172.75104 | CO34: 173.14204 | CP34: 168.06001 | CQ34: 170.69712 | CR34: 167.185 | CS34: 164.38143 | CT34: 167.61115 | CU34: 160.99154 | CV34: 1 | CW34: =CY34 -> 1304 | CY34: =IFERROR(CZ34,0) -> 1304 | CZ34: =RIGHT(A34,4)*1 -> 1304
C35: Actual | CV35: 0 | CW35: =CY35 -> 0 | CY35: =IFERROR(CZ35,0) -> 0 | CZ35: =RIGHT(A35,4)*1 -> #VALUE!
A36: Am1304 | B36: desl | C36: Forecast | D36: 85.6858 | E36: 78.469634 | F36: 79.817082 | G36: 78.076182 | H36: 78.558502 | I36: 72.82668 | J36: 72.551353 | K36: 73.678966 | L36: 72.468283 | M36: 82.096229 | N36: 84.605333 | O36: 87.063275 | P36: 81.886287 | Q36: 81.166944 | R36: 82.835084 | S36: 80.972538 | T36: 80.194512 | U36: 74.144475 | V36: 73.476853 | W36: 74.509635 | X36: 73.574601 | Y36: 83.63712 | Z36: 86.70004 | AA36: 89.705057 | AB36: 84.957641 | AC36: 84.530049 | AD36: 86.380104 | AE36: 84.64832 | AF36: 84.012045 | AG36: 78.156979 | AH36: 77.752568 | AI36: 79.110084 | AJ36: 78.54195 | AK36: 88.990926 | AL36: 92.440852 | AM36: 95.820415 | AN36: 91.427557 | AO36: 91.331465 | AP36: 93.490539 | AQ36: 92.048969 | AR36: 91.69021 | AS36: 86.107293 | AT36: 85.976509 | AU36: 87.613876 | AV36: 87.333472 | AW36: 98.076593 | AX36: 101.8234 | AY36: 105.49809 | AZ36: 101.39468 | BA36: 101.5799 | BB36: 104.01146 | BC36: 102.83424 | BD36: 102.73326 | BE36: 97.403258 | BF36: 97.52199 | BG36: 99.406442 | BH36: 99.371199 | BI36: 110.35774 | BJ36: 114.34626 | BK36: 118.26093 | BL36: 114.39575 | BM36: 114.81736 | BN36: 117.48316 | BO36: 116.5375 | BP36: 116.66446 | BQ36: 111.55762 | BR36: 111.8935 | BS36: 113.98811 | BT36: 114.15579 | BU36: 125.33881 | BV36: 129.51935 | BW36: 133.62464 | BX36: 129.95222 | BY36: 130.57185 | BZ36: 133.44265 | CA36: 132.70828 | CB36: 133.04936 | CC36: 128.15338 | CD36: 128.68926 | CE36: 130.96541 | CF36: 131.29108 | CG36: 142.60726 | CH36: 146.90053 | CI36: 151.10942 | CJ36: 147.54645 | CK36: 148.29486 | CL36: 151.34588 | CM36: 150.81844 | CN36: 151.43059 | CO36: 146.8452 | CP36: 147.55756 | CQ36: 150.13239 | CR36: 150.5852 | CS36: 160.97972 | CT36: 167.19222 | CU36: 168.99004 | CV36: -1 | CW36: =CY36 -> 1304 | CY36: =IFERROR(CZ36,0) -> 1304 | CZ36: =RIGHT(A36,4)*1 -> 1304
C37: Actual | CV37: 0 | CW37: =CY37 -> 0 | CY37: =IFERROR(CZ37,0) -> 0 | CZ37: =RIGHT(A37,4)*1 -> #VALUE!
A38: Rr1401 | B38: adm | C38: Forecast | D38: 1592.4681 | E38: 1603.0724 | F38: 1725.4935 | G38: 1725.3831 | H38: 1715.2706 | I38: 1785.3086 | J38: 1726.6524 | K38: 1750.2421 | L38: 1758.6457 | M38: 1631.7138 | N38: 1682.2095 | O38: 1555.7662 | P38: 1760.3291 | Q38: 1773.9701 | R38: 1883.8635 | S38: 1885.6946 | T38: 1865.9145 | U38: 1927.0023 | V38: 1864.3651 | W38: 1887.9044 | X38: 1900.5184 | Y38: 1782.1472 | Z38: 1841.6871 | AA38: 1722.4075 | AB38: 1930.8362 | AC38: 1944.801 | AD38: 2052.4978 | AE38: 2051.3141 | AF38: 2029.1476 | AG38: 2089.2764 | AH38: 2027.2142 | AI38: 2052.4838 | AJ38: 2067.4358 | AK38: 1951.5343 | AL38: 2013.3625 | AM38: 1896.0374 | AN38: 2106.0436 | AO38: 2121.2195 | AP38: 2229.8022 | AQ38: 2229.2533 | AR38: 2207.5802 | AS38: 2268.1925 | AT38: 2206.7277 | AU38: 2232.79 | AV38: 2248.7482 | AW38: 2134.0221 | AX38: 2197.11 | AY38: 2081.0361 | AZ38: 2292.212 | BA38: 2308.4404 | BB38: 2417.9601 | BC38: 2418.2609 | BD38: 2397.3881 | BE38: 2458.7851 | BF38: 2398.1105 | BG38: 2424.9762 | BH38: 2441.7483 | BI38: 2327.8405 | BJ38: 2391.7466 | BK38: 2276.4911 | BL38: 2488.4919 | BM38: 2505.5605 | BN38: 2615.9431 | BO38: 2617.1303 | BP38: 2597.1572 | BQ38: 2659.4445 | BR38: 2599.6175 | BS38: 2627.251 | BT38: 2644.6814 | BU38: 2531.311 | BV38: 2595.652 | BW38: 2480.781 | BX38: 2693.197 | BY38: 2710.8063 | BZ38: 2821.939 | CA38: 2824.1299 | CB38: 2805.3942 | CC38: 2869.0561 | CD38: 2810.5739 | CE38: 2839.3182 | CF38: 2857.4258 | CG38: 2744.1742 | CH38: 2808.065 | CI38: 2692.3036 | CJ38: 2903.7187 | CK38: 2920.6736 | CL38: 3031.7072 | CM38: 3035.3071 | CN38: 3019.0437 | CO38: 3085.8491 | CP38: 3033.4284 | CQ38: 3063.2246 | CR38: 3084.2925 | CS38: 2985.7252 | CT38: 3003.3891 | CU38: 2947.4758 | CV38: 1 | CW38: =CY38 -> 1401 | CY38: =IFERROR(CZ38,0) -> 1401 | CZ38: =RIGHT(A38,4)*1 -> 1401
C39: Actual | CV39: 0 | CW39: =CY39 -> 0 | CY39: =IFERROR(CZ39,0) -> 0 | CZ39: =RIGHT(A39,4)*1 -> #VALUE!
A40: Rr1401 | B40: desl | C40: Forecast | D40: 1807.8106 | E40: 1645.0773 | F40: 1850.744 | G40: 1704.2146 | H40: 1806.6835 | I40: 1725.9295 | J40: 1719.9539 | K40: 1777.1626 | L40: 1664.9574 | M40: 1772.1163 | N40: 1783.1916 | O40: 1694.2531 | P40: 1882.8443 | Q40: 1763.9112 | R40: 1964.943 | S40: 1815.5113 | T40: 1910.4933 | U40: 1829.4039 | V40: 1817.2733 | W40: 1875.6333 | X40: 1768.4242 | Y40: 1884.7218 | Z40: 1905.3001 | AA40: 1823.9563 | AB40: 2016.4484 | AC40: 1897.844 | AD40: 2096.9076 | AE40: 1944.945 | AF40: 2038.1909 | AG40: 1956.8594 | AH40: 1945.9664 | AI40: 2006.6032 | AJ40: 1902.1528 | AK40: 2021.2412 | AL40: 2044.3816 | AM40: 1965.2696 | AN40: 2159.6449 | AO40: 2042.5889 | AP40: 2242.8995 | AQ40: 2091.9463 | AR40: 2186.0657 | AS40: 2105.5984 | AT40: 2095.6804 | AU40: 2157.4807 | AV40: 2054.3965 | AW40: 2175.0066 | AX40: 2199.7383 | AY40: 2122.1956 | AZ40: 2318.0497 | BA40: 2202.3507 | BB40: 2403.9017 | BC40: 2254.1017 | BD40: 2349.3245 | BE40: 2269.9427 | BF40: 2261.1122 | BG40: 2324.0094 | BH40: 2222.0301 | BI40: 2343.7489 | BJ40: 2369.5905 | BK40: 2293.1599 | BL40: 2490.1325 | BM40: 2375.5631 | BN40: 2578.257 | BO40: 2429.6079 | BP40: 2525.9752 | BQ40: 2447.7078 | BR40: 2439.932 | BS40: 2503.7963 | BT40: 2402.6797 | BU40: 2525.1605 | BV40: 2551.694 | BW40: 2475.9428 | BX40: 2673.6583 | BY40: 2559.9721 | BZ40: 2763.7446 | CA40: 2616.3806 | CB40: 2714.19 | CC40: 2637.4094 | CD40: 2631.0065 | CE40: 2695.9549 | CF40: 2595.4919 | CG40: 2718.1327 | CH40: 2744.3859 | CI40: 2668.1002 | CJ40: 2865.3775 | CK40: 2751.6184 | CL40: 2956.2355 | CM40: 2810.7561 | CN40: 2911.4358 | CO40: 2838.8447 | CP40: 2836.5998 | CQ40: 2903.2306 | CR40: 2811.4905 | CS40: 2916.9306 | CT40: 2959.4333 | CU40: 2867.8689 | CV40: -1 | CW40: =CY40 -> 1401 | CY40: =IFERROR(CZ40,0) -> 1401 | CZ40: =RIGHT(A40,4)*1 -> 1401
...

Sheet conditional forecasts_4
A1: GVAR Conditional Forecasts
A2: Last in-sample estimation date: | B2: 2016M12
A3: Last forecast date: | B3: 2024M12
D4: =DATE(LEFT(D5,4),SUBSTITUTE(RIGHT(D5,2),"M",""),1) -> 42736 | E4: =DATE(LEFT(E5,4),SUBSTITUTE(RIGHT(E5,2),"M",""),1) -> 42767 | F4: =DATE(LEFT(F5,4),SUBSTITUTE(RIGHT(F5,2),"M",""),1) -> 42795 | G4: =DATE(LEFT(G5,4),SUBSTITUTE(RIGHT(G5,2),"M",""),1) -> 42826 | H4: =DATE(LEFT(H5,4),SUBSTITUTE(RIGHT(H5,2),"M",""),1) -> 42856 | I4: =DATE(LEFT(I5,4),SUBSTITUTE(RIGHT(I5,2),"M",""),1) -> 42887 | J4: =DATE(LEFT(J5,4),SUBSTITUTE(RIGHT(J5,2),"M",""),1) -> 42917 | K4: =DATE(LEFT(K5,4),SUBSTITUTE(RIGHT(K5,2),"M",""),1) -> 42948 | ... CU4: =DATE(LEFT(CU5,4),SUBSTITUTE(RIGHT(CU5,2),"M",""),1) -> 45627
D5: 2017M1 | E5: 2017M2 | F5: 2017M3 | G5: 2017M4 | H5: 2017M5 | I5: 2017M6 | J5: 2017M7 | K5: 2017M8 | L5: 2017M9 | M5: 2017M10 | N5: 2017M11 | O5: 2017M12 | P5: 2018M1 | Q5: 2018M2 | R5: 2018M3 | S5: 2018M4 | T5: 2018M5 | U5: 2018M6 | V5: 2018M7 | W5: 2018M8 | X5: 2018M9 | Y5: 2018M10 | Z5: 2018M11 | AA5: 2018M12 | AB5: 2019M1 | AC5: 2019M2 | AD5: 2019M3 | AE5: 2019M4 | AF5: 2019M5 | AG5: 2019M6 | AH5: 2019M7 | AI5: 2019M8 | AJ5: 2019M9 | AK5: 2019M10 | AL5: 2019M11 | AM5: 2019M12 | AN5: 2020M1 | AO5: 2020M2 | AP5: 2020M3 | AQ5: 2020M4 | AR5: 2020M5 | AS5: 2020M6 | AT5: 2020M7 | AU5: 2020M8 | AV5: 2020M9 | AW5: 2020M10 | AX5: 2020M11 | AY5: 2020M12 | AZ5: 2021M1 | BA5: 2021M2 | BB5: 2021M3 | BC5: 2021M4 | BD5: 2021M5 | BE5: 2021M6 | BF5: 2021M7 | BG5: 2021M8 | BH5: 2021M9 | BI5: 2021M10 | BJ5: 2021M11 | BK5: 2021M12 | BL5: 2022M1 | BM5: 2022M2 | BN5: 2022M3 | BO5: 2022M4 | BP5: 2022M5 | BQ5: 2022M6 | BR5: 2022M7 | BS5: 2022M8 | BT5: 2022M9 | BU5: 2022M10 | BV5: 2022M11 | BW5: 2022M12 | BX5: 2023M1 | BY5: 2023M2 | BZ5: 2023M3 | CA5: 2023M4 | CB5: 2023M5 | CC5: 2023M6 | CD5: 2023M7 | CE5: 2023M8 | CF5: 2023M9 | CG5: 2023M10 | CH5: 2023M11 | CI5: 2023M12 | CJ5: 2024M1 | CK5: 2024M2 | CL5: 2024M3 | CM5: 2024M4 | CN5: 2024M5 | CO5: 2024M6 | CP5: 2024M7 | CQ5: 2024M8 | CR5: 2024M9 | CS5: 2024M10 | CT5: 2024M11 | CU5: 2024M12 | CV5: Serie | CW5: Regiao
A6: Ro1101 | B6: adm | C6: Forecast | D6: 2825.5893 | E6: 3101.2583 | F6: 3682.3295 | G6: 3778.1559 | H6: 3895.3444 | I6: 4095.0617 | J6: 4005.7696 | K6: 4011.3179 | L6: 3802.1037 | M6: 3349.4518 | N6: 3054.3983 | O6: 2447.4152 | P6: 3066.0483 | Q6: 3393.087 | R6: 4069.0224 | S6: 4196.3705 | T6: 4338.0658 | U6: 4516.986 | V6: 4391.6904 | W6: 4361.5762 | X6: 4129.0336 | Y6: 3680.227 | Z6: 3413.1122 | AA6: 2848.1789 | AB6: 3511.4962 | AC6: 3875.1506 | AD6: 4574.0663 | AE6: 4711.0598 | AF6: 4853.1414 | AG6: 5028.5274 | AH6: 4900.3381 | AI6: 4870.6907 | AJ6: 4642.8762 | AK6: 4202.7364 | AL6: 3947.3028 | AM6: 3395.9698 | AN6: 4073.7416 | AO6: 4451.7225 | AP6: 5163.9879 | AQ6: 5312.7487 | AR6: 5464.7726 | AS6: 5648.4528 | AT6: 5527.4426 | AU6: 5504.5761 | AV6: 5283.8245 | AW6: 4851.4893 | AX6: 4604.7537 | AY6: 4062.8784 | AZ6: 4750.5533 | BA6: 5138.5194 | BB6: 5860.552 | BC6: 6018.6842 | BD6: 6179.6336 | BE6: 6371.8363 | BF6: 6259.0333 | BG6: 6244.1471 | BH6: 6031.2137 | BI6: 5606.5701 | BJ6: 5367.4164 | BK6: 4833.0299 | BL6: 5528.1341 | BM6: 5923.5297 | BN6: 6653.0747 | BO6: 6818.8886 | BP6: 6987.749 | BQ6: 7188.0903 | BR6: 7083.5596 | BS6: 7076.8836 | BT6: 6871.8199 | BU6: 6454.4006 | BV6: 6221.5794 | BW6: 5692.5431 | BX6: 6392.1597 | BY6: 6791.6396 | BZ6: 7525.4723 | CA6: 7696.507 | CB6: 7872.157 | CC6: 8081.1849 | CD6: 7987.0813 | CE6: 7991.8584 | CF6: 7798.0582 | CG6: 7390.2163 | CH6: 7163.8009 | CI6: 6636.958 | CJ6: 7334.4744 | CK6: 7728.3331 | CL6: 8455.1889 | CM6: 8622.0901 | CN6: 8798.292 | CO6: 9016.7793 | CP6: 8944.4648 | CQ6: 8970.3811 | CR6: 8822.9592 | CS6: 8433.1566 | CT6: 8183.4914 | CU6: 7830.6053 | CV6: 1 | CW6: ='conditional forecasts_6'!CW6 -> 1101
C7: Actual | CV7: 0 | CW7: ='conditional forecasts_6'!CW7 -> 0
A8: Ro1101 | B8: desl | C8: Forecast | D8: 3176.4667 | E8: 3195.7408 | F8: 3504.4765 | G8: 3566.9715 | H8: 3860.0017 | I8: 3789.1297 | J8: 3947.532 | K8: 3980.7296 | L8: 3850.9945 | M8: 4010.8214 | N8: 3877.3752 | O8: 3732.2366 | P8: 3635.9394 | Q8: 3574.7262 | R8: 3893.81 | S8: 3914.7687 | T8: 4207.2865 | U8: 4115.2016 | V8: 4247.9128 | W8: 4251.8225 | X8: 4100.0046 | Y8: 4252.8423 | Z8: 4130.6517 | AA8: 4011.6913 | AB8: 3949.4054 | AC8: 3922.2221 | AD8: 4269.6578 | AE8: 4310.8405 | AF8: 4616.2167 | AG8: 4532.271 | AH8: 4671.4605 | AI8: 4682.6038 | AJ8: 4540.113 | AK8: 4704.7352 | AL8: 4596.5355 | AM8: 4493.2305 | AN8: 4447.6238 | AO8: 4437.4889 | AP8: 4801.7194 | AQ8: 4858.9149 | AR8: 5179.1734 | AS8: 5108.8848 | AT8: 5260.677 | AU8: 5283.742 | AV8: 5152.9443 | AW8: 5329.4266 | AX8: 5233.4934 | AY8: 5142.9102 | AZ8: 5110.3679 | BA8: 5113.4362 | BB8: 5490.7927 | BC8: 5560.8675 | BD8: 5893.6646 | BE8: 5835.5518 | BF8: 5999.1861 | BG8: 6033.8118 | BH8: 5914.3471 | BI8: 6101.9775 | BJ8: 6017.038 | BK8: 5937.3169 | BL8: 5915.5286 | BM8: 5929.2733 | BN8: 6317.2667 | BO8: 6397.9803 | BP8: 6741.4493 | BQ8: 6694.0474 | BR8: 6868.3951 | BS8: 6913.6491 | BT8: 6804.593 | BU8: 7002.2525 | BV8: 6926.8172 | BW8: 6855.9944 | BX8: 6842.5302 | BY8: 6864.1966 | BZ8: 7260.0145 | CA8: 7348.8403 | CB8: 7701.0836 | CC8: 7663.3662 | CD8: 7848.3246 | CE8: 7904.8314 | CF8: 7807.0975 | CG8: 8015.3672 | CH8: 7949.0206 | CI8: 7885.1332 | CJ8: 7876.1239 | CK8: 7900.0913 | CL8: 8297.0782 | CM8: 8387.0334 | CN8: 8743.2355 | CO8: 8712.8596 | CP8: 8909.6411 | CQ8: 8988.4242 | CR8: 8905.1556 | CS8: 9133.7397 | CT8: 9116.2113 | CU8: 8968.148 | CV8: -1 | CW8: ='conditional forecasts_6'!CW8 -> 1101
C9: Actual | CV9: 0 | CW9: ='conditional forecasts_6'!CW9 -> 0
A10: Ro1102 | B10: adm | C10: Forecast | D10: 4626.3708 | E10: 5091.6645 | F10: 5832.3454 | G10: 5783.8094 | H10: 5732.4579 | I10: 5752.2769 | J10: 5410.2786 | K10: 5368.0792 | L10: 5105.313 | M10: 4732.7277 | N10: 4790.4612 | O10: 4302.7018 | P10: 5199.8116 | Q10: 5433.2651 | R10: 6090.9441 | S10: 5986.1007 | T10: 5886.0864 | U10: 5843.3865 | V10: 5453.5291 | W10: 5380.4244 | X10: 5113.3021 | Y10: 4769.8295 | Z10: 4877.3912 | AA10: 4443.4925 | AB10: 5383.9137 | AC10: 5640.9853 | AD10: 6302.4239 | AE10: 6188.3118 | AF10: 6075.123 | AG10: 6022.9549 | AH10: 5631.3935 | AI10: 5564.7168 | AJ10: 5310.1225 | AK10: 4982.4587 | AL10: 5106.6479 | AM10: 4688.5739 | AN10: 5643.1729 | AO10: 5912.4155 | AP10: 6583.9293 | AQ10: 6477.9316 | AR10: 6371.2909 | AS10: 6324.7546 | AT10: 5938.7019 | AU10: 5878.1458 | AV10: 5630.757 | AW10: 5311.4798 | AX10: 5444.9763 | AY10: 5036.6483 | AZ10: 6000.9132 | BA10: 6279.3459 | BB10: 6959.3836 | BC10: 6861.2546 | BD10: 6761.9733 | BE10: 6722.4794 | BF10: 6343.3173 | BG10: 6289.6002 | BH10: 6049.0335 | BI10: 5736.5554 | BJ10: 5876.8142 | BK10: 5475.2176 | BL10: 6446.2213 | BM10: 6731.4647 | BN10: 7418.4554 | BO10: 7327.467 | BP10: 7235.5009 | BQ10: 7203.3992 | BR10: 6831.5165 | BS10: 6784.7033 | BT10: 6550.3809 | BU10: 6243.2653 | BV10: 6387.9415 | BW10: 5989.9956 | BX10: 6964.3339 | BY10: 7253.268 | BZ10: 7945.0545 | CA10: 7860.5743 | CB10: 7777.0549 | CC10: 7755.0075 | CD10: 7393.8611 | CE10: 7357.102 | CF10: 7130.6499 | CG10: 6827.9814 | CH10: 6973.0189 | CI10: 6571.596 | CJ10: 7539.8898 | CK10: 7822.2199 | CL10: 8509.6541 | CM10: 8427.1021 | CN10: 8352.1092 | CO10: 8349.0364 | CP10: 8017.0807 | CQ10: 8009.1716 | CR10: 7822.2017 | CS10: 7522.0378 | CT10: 7609.0297 | CU10: 7360.9872 | CV10: 1 | CW10: ='conditional forecasts_6'!CW10 -> 1102
C11: Actual | CV11: 0 | CW11: ='conditional forecasts_6'!CW11 -> 0
A12: Ro1102 | B12: desl | C12: Forecast | D12: 5091.5863 | E12: 5086.7267 | F12: 5628.7039 | G12: 5277.8379 | H12: 5535.1614 | I12: 5065.7142 | J12: 5120.8829 | K12: 5307.2963 | L12: 4837.4561 | M12: 5512.366 | N12: 5596.2241 | O12: 5400.4178 | P12: 5398.2953 | Q12: 5159.3899 | R12: 5722.5356 | S12: 5320.576 | T12: 5537.4502 | U12: 5056.3414 | V12: 5090.0909 | W12: 5270.7322 | X12: 4813.1606 | Y12: 5513.8184 | Z12: 5631.2875 | AA12: 5466.5102 | AB12: 5485.6045 | AC12: 5256.8267 | AD12: 5822.2572 | AE12: 5419.9088 | AF12: 5638.3525 | AG12: 5163.2614 | AH12: 5207.6034 | AI12: 5402.0348 | AJ12: 4959.6308 | AK12: 5675.3708 | AL12: 5807.082 | AM12: 5655.5313 | AN12: 5686.9153 | AO12: 5469.5863 | AP12: 6045.677 | AQ12: 5653.2711 | AR12: 5881.1127 | AS12: 5415.1678 | AT12: 5468.7449 | AU12: 5672.7748 | AV12: 5240.4476 | AW12: 5966.6698 | AX12: 6109.0555 | AY12: 5968.1116 | AZ12: 6009.8197 | BA12: 5802.4176 | BB12: 6388.0303 | BC12: 6004.8084 | BD12: 6241.5904 | BE12: 5784.4241 | BF12: 5846.6686 | BG12: 6059.2759 | BH12: 5635.4429 | BI12: 6370.0855 | BJ12: 6520.8395 | BK12: 6388.2454 | BL12: 6438.3202 | BM12: 6239.3237 | BN12: 6833.3743 | BO12: 6458.5774 | BP12: 6703.6857 | BQ12: 6254.628 | BR12: 6324.6319 | BS12: 6544.5359 | BT12: 6127.4801 | BU12: 6868.4202 | BV12: 7025.155 | BW12: 6898.5099 | BX12: 6954.8653 | BY12: 6762.8348 | BZ12: 7364.7618 | CA12: 6998.7263 | CB12: 7253.1346 | CC12: 6813.2689 | CD12: 6891.5474 | CE12: 7118.0454 | CF12: 6705.4525 | CG12: 7448.7372 | CH12: 7606.3034 | CI12: 7480.0853 | CJ12: 7537.6512 | CK12: 7348.9514 | CL12: 7958.0653 | CM12: 7601.9543 | CN12: 7871.5231 | CO12: 7449.352 | CP12: 7542.409 | CQ12: 7795.952 | CR12: 7377.4345 | CS12: 8090.7194 | CT12: 8363.1788 | CU12: 7901.6318 | CV12: -1 | CW12: ='conditional forecasts_6'!CW12 -> 1102
C13: Actual | CV13: 0 | CW13: ='conditional forecasts_6'!CW13 -> 0
A14: Ac1201 | B14: adm | C14: Forecast | D14: 123.37411 | E14: 126.37728 | F14: 171.90629 | G14: 202.49704 | H14: 225.21623 | I14: 241.6723 | J14: 225.40562 | K14: 214.64485 | L14: 193.80928 | M14: 163.04864 | N14: 151.27533 | O14: 123.84906 | P14: 147.76367 | Q14: 151.19886 | R14: 186.28378 | S14: 213.74445 | T14: 234.95663 | U14: 248.316 | V14: 227.731 | W14: 211.40802 | X14: 185.55259 | Y14: 152.06782 | Z14: 140.62934 | AA14: 116.50159 | AB14: 145.50132 | AC14: 154.22631 | AD14: 193.49282 | AE14: 223.31524 | AF14: 245.06318 | AG14: 257.66444 | AH14: 235.77011 | AI14: 218.24683 | AJ14: 191.71436 | AK14: 158.2168 | AL14: 147.36566 | AM14: 124.2554 | AN14: 154.50654 | AO14: 164.53933 | AP14: 205.02917 | AQ14: 235.89142 | AR14: 258.44195 | AS14: 271.60364 | AT14: 250.07013 | AU14: 232.78681 | AV14: 206.46747 | AW14: 173.2405 | AX14: 162.77144 | AY14: 140.16905 | AZ14: 171.03202 | BA14: 181.73614 | BB14: 222.90687 | BC14: 254.41882 | BD14: 277.56447 | BE14: 291.26144 | BF14: 270.21167 | BG14: 253.3754 | BH14: 227.48148 | BI14: 194.6696 | BJ14: 184.61172 | BK14: 162.41939 | BL14: 193.69288 | BM14: 204.81068 | BN14: 246.40341 | BO14: 278.35309 | BP14: 301.95974 | BQ14: 316.1454 | BR14: 295.60941 | BS14: 279.29951 | BT14: 253.92145 | BU14: 221.58404 | BV14: 211.92733 | BW14: 190.03957 | BX14: 221.51681 | BY14: 232.76029 | BZ14: 274.45222 | CA14: 306.54812 | CB14: 330.42751 | CC14: 345.07552 | CD14: 325.21475 | CE14: 309.75981 | CF14: 285.32168 | CG14: 253.86493 | CH14: 244.86075 | CI14: 223.24918 | CJ14: 254.53747 | CK14: 265.13932 | CL14: 305.86849 | CM14: 336.98564 | CN14: 360.13998 | CO14: 374.8073 | CP14: 355.93365 | CQ14: 342.53156 | CR14: 321.2322 | CS14: 292.93799 | CT14: 283.93196 | CU14: 272.11767 | CV14: 1 | CW14: ='conditional forecasts_6'!CW14 -> 1201
C15: Actual | CV15: 0 | CW15: ='conditional forecasts_6'!CW15 -> 0
A16: Ac1201 | B16: desl | C16: Forecast | D16: 193.47965 | E16: 158.79748 | F16: 157.11027 | G16: 145.79736 | H16: 161.55703 | I16: 158.13603 | J16: 175.12194 | K16: 186.71331 | L16: 180.56866 | M16: 213.13048 | N16: 216.10033 | O16: 213.94957 | P16: 202.15628 | Q16: 176.22767 | R16: 170.08492 | S16: 151.54993 | T16: 166.08329 | U16: 162.6293 | V16: 180.28743 | W16: 192.83278 | X16: 186.58095 | Y16: 218.03612 | Z16: 219.49356 | AA16: 216.14012 | AB16: 203.92904 | AC16: 178.45767 | AD16: 173.44063 | AE16: 156.34122 | AF16: 172.28633 | AG16: 170.02263 | AH16: 188.60308 | AI16: 201.85961 | AJ16: 196.19838 | AK16: 228.19736 | AL16: 230.19262 | AM16: 227.3881 | AN16: 215.7471 | AO16: 190.87964 | AP16: 186.5138 | AQ16: 170.11872 | AR16: 186.81261 | AS16: 185.31891 | AT16: 204.66008 | AU16: 218.64098 | AV16: 213.65298 | AW16: 246.27467 | AX16: 248.85519 | AY16: 246.61717 | AZ16: 235.54099 | BA16: 211.24726 | BB16: 207.46683 | BC16: 191.66538 | BD16: 208.95458 | BE16: 208.05129 | BF16: 227.97337 | BG16: 242.5238 | BH16: 238.09439 | BI16: 271.2655 | BJ16: 274.38834 | BK16: 272.68687 | BL16: 262.14145 | BM16: 238.37115 | BN16: 235.10398 | BO16: 219.80233 | BP16: 237.57531 | BQ16: 237.13935 | BR16: 257.51507 | BS16: 272.51174 | BT16: 268.53019 | BU16: 302.16057 | BV16: 305.76162 | BW16: 304.55934 | BX16: 294.52835 | BY16: 271.27349 | BZ16: 268.50209 | CA16: 253.65378 | CB16: 271.81944 | CC16: 271.7085 | CD16: 292.35069 | CE16: 307.58128 | CF16: 303.84104 | CG16: 337.76571 | CH16: 341.75824 | CI16: 341.07316 | CJ16: 331.67555 | CK16: 309.14646 | CL16: 307.12473 | CM16: 292.88348 | CN16: 311.54301 | CO16: 311.56229 | CP16: 331.86776 | CQ16: 347.13617 | CR16: 341.63675 | CS16: 375.97545 | CT16: 383.50523 | CU16: 371.34175 | CV16: -1 | CW16: ='conditional forecasts_6'!CW16 -> 1201
C17: Actual | CV17: 0 | CW17: ='conditional forecasts_6'!CW17 -> 0
A18: Ac1202 | B18: adm | C18: Forecast | D18: 1499.8732 | E18: 1616.3859 | F18: 1828.2258 | G18: 1869.129 | H18: 1864.3748 | I18: 1889.3188 | J18: 1819.8285 | K18: 1808.5062 | L18: 1722.6622 | M18: 1597.7641 | N18: 1589.3109 | O18: 1369.924 | P18: 1608.8938 | Q18: 1709.1285 | R18: 1937.5255 | S18: 1945.2645 | T18: 1932.4929 | U18: 1939.1126 | V18: 1855.6874 | W18: 1835.699 | X18: 1745.2245 | Y18: 1624.7047 | Z18: 1626.9086 | AA18: 1421.5646 | AB18: 1674.9756 | AC18: 1786.6588 | AD18: 2021.8228 | AE18: 2031.8261 | AF18: 2018.2344 | AG18: 2022.9174 | AH18: 1938.2033 | AI18: 1918.636 | AJ18: 1830.5652 | AK18: 1714.1108 | AL18: 1721.4184 | AM18: 1521.5613 | AN18: 1780.3199 | AO18: 1896.8699 | AP18: 2136.25 | AQ18: 2149.7895 | AR18: 2139.1376 | AS18: 2146.3304 | AT18: 2063.9134 | AU18: 2046.6525 | AV18: 1961.0776 | AW18: 1847.4083 | AX18: 1857.7956 | AY18: 1661.2368 | AZ18: 1923.3892 | BA18: 2043.3003 | BB18: 2285.9099 | BC18: 2302.4966 | BD18: 2294.7058 | BE18: 2304.6046 | BF18: 2224.7836 | BG18: 2210.0527 | BH18: 2126.9741 | BI18: 2015.7866 | BJ18: 2028.6511 | BK18: 1834.5717 | BL18: 2099.2137 | BM18: 2221.6359 | BN18: 2466.7893 | BO18: 2485.9579 | BP18: 2480.78 | BQ18: 2493.297 | BR18: 2416.0535 | BS18: 2403.7969 | BT18: 2323.0225 | BU18: 2213.9154 | BV18: 2228.6184 | BW18: 2036.1714 | BX18: 2302.34 | BY18: 2426.3381 | BZ18: 2673.2989 | CA18: 2694.6664 | CB18: 2692.1581 | CC18: 2707.7647 | CD18: 2633.8291 | CE18: 2624.7742 | CF18: 2546.7085 | CG18: 2439.4711 | CH18: 2454.9934 | CI18: 2262.3574 | CJ18: 2527.6168 | CK18: 2650.5248 | CL18: 2896.8377 | CM18: 2919.0928 | CN18: 2919.0079 | CO18: 2939.3902 | CP18: 2872.5743 | CQ18: 2871.611 | CR18: 2800.8439 | CS18: 2701.3921 | CT18: 2696.8242 | CU18: 2548.181 | CV18: 1 | CW18: ='conditional forecasts_6'!CW18 -> 1202
C19: Actual | CV19: 0 | CW19: ='conditional forecasts_6'!CW19 -> 0
A20: Ac1202 | B20: desl | C20: Forecast | D20: 1766.6444 | E20: 1683.7622 | F20: 1824.8577 | G20: 1663.9323 | H20: 1826.5158 | I20: 1649.6846 | J20: 1686.3847 | K20: 1753.6265 | L20: 1607.4582 | M20: 1911.1752 | N20: 1936.5825 | O20: 1979.194 | P20: 1928.8274 | Q20: 1740.5164 | R20: 1865.2027 | S20: 1691.2437 | T20: 1834.9729 | U20: 1654.8827 | V20: 1684.573 | W20: 1750.0804 | X20: 1608.2787 | Y20: 1919.6901 | Z20: 1955.726 | AA20: 2008.8099 | AB20: 1966.4138 | AC20: 1783.1374 | AD20: 1910.5636 | AE20: 1738.2846 | AF20: 1883.8677 | AG20: 1706.5345 | AH20: 1740.032 | AI20: 1810.1698 | AJ20: 1673.456 | AK20: 1990.0868 | AL20: 2031.2791 | AM20: 2089.3709 | AN20: 2051.7915 | AO20: 1873.1016 | AP20: 2004.8471 | AQ20: 1836.6104 | AR20: 1985.9992 | AS20: 1812.3249 | AT20: 1849.4476 | AU20: 1923.2755 | AV20: 1790.3701 | AW20: 2110.9253 | AX20: 2156.1103 | AY20: 2218.1951 | AZ20: 2184.5463 | BA20: 2009.6843 | BB20: 2145.1414 | BC20: 1980.5068 | BD20: 2133.4042 | BE20: 1963.1616 | BF20: 2003.6508 | BG20: 2080.7877 | BH20: 1951.1409 | BI20: 2274.9146 | BJ20: 2323.2937 | BK20: 2388.5671 | BL20: 2358.12 | BM20: 2186.4848 | BN20: 2325.1932 | BO20: 2163.8168 | BP20: 2319.9445 | BQ20: 2152.8543 | BR20: 2196.3618 | BS20: 2276.333 | BT20: 2149.3088 | BU20: 2475.5045 | BV20: 2526.1662 | BW20: 2593.6944 | BX20: 2565.6201 | BY20: 2396.6212 | BZ20: 2538.3277 | CA20: 2380.3143 | CB20: 2540.0471 | CC20: 2376.56 | CD20: 2423.351 | CE20: 2505.9726 | CF20: 2380.7626 | CG20: 2707.9073 | CH20: 2758.8524 | CI20: 2826.4144 | CJ20: 2798.6093 | CK20: 2630.6314 | CL20: 2774.9249 | CM20: 2620.6524 | CN20: 2786.2484 | CO20: 2630.077 | CP20: 2682.4394 | CQ20: 2775.5686 | CR20: 2651.6346 | CS20: 2959.9103 | CT20: 3065.1145 | CU20: 2997.6689 | CV20: -1 | CW20: ='conditional forecasts_6'!CW20 -> 1202
C21: Actual | CV21: 0 | CW21: ='conditional forecasts_6'!CW21 -> 0
A22: Am1301 | B22: adm | C22: Forecast | D22: 25.057669 | E22: 21.335398 | F22: 25.754117 | G22: 19.667795 | H22: 17.841272 | I22: 24.35841 | J22: 13.166062 | K22: 16.208252 | L22: 18.926433 | M22: 8.1661972 | N22: 19.416697 | O22: 16.384902 | P22: 36.35954 | Q22: 23.81884 | R22: 24.101609 | S22: 18.980245 | T22: 15.942087 | U22: 22.171723 | V22: 11.375473 | W22: 14.135985 | X22: 16.804332 | Y22: 6.0285622 | Z22: 17.257883 | AA22: 14.313449 | AB22: 34.41718 | AC22: 21.987815 | AD22: 22.342289 | AE22: 17.246346 | AF22: 14.196645 | AG22: 20.39893 | AH22: 9.5796831 | AI22: 12.332357 | AJ22: 15.010611 | AK22: 4.2586003 | AL22: 15.518583 | AM22: 12.606195 | AN22: 32.740538 | AO22: 20.339345 | AP22: 20.719341 | AQ22: 15.646069 | AR22: 12.615824 | AS22: 18.83424 | AT22: 8.0283474 | AU22: 10.792834 | AV22: 13.482961 | AW22: 2.7443124 | AX22: 14.019927 | AY22: 11.125385 | AZ22: 31.279065 | BA22: 18.897675 | BB22: 19.297019 | BC22: 14.242064 | BD22: 11.228933 | BE22: 17.463385 | BF22: 6.6726901 | BG22: 9.4517506 | BH22: 12.155944 | BI22: 1.4308911 | BJ22: 12.719655 | BK22: 9.8379135 | BL22: 30.004271 | BM22: 17.635807 | BN22: 18.048777 | BO22: 13.008579 | BP22: 10.011575 | BQ22: 16.263388 | BR22: 5.4906612 | BS22: 8.2871743 | BT22: 11.006879 | BU22: 0.29404925 | BV22: 11.590983 | BW22: 8.7136199 | BX22: 28.882045 | BY22: 16.51582 | BZ22: 16.934091 | CA22: 11.904772 | CB22: 8.9256097 | CC22: 15.201988 | CD22: 4.4585452 | CE22: 7.2858592 | CF22: 10.033563 | CG22: -0.65859123 | CH22: 10.645801 | CI22: 7.7585085 | CJ22: 27.901302 | CK22: 15.490368 | CL22: 15.854148 | CM22: 10.811971 | CN22: 7.8082477 | CO22: 14.168322 | CP22: 3.5492094 | CQ22: 6.2304414 | CR22: 9.6923501 | CS22: -1.553982 | CT22: 7.5747494 | CU22: 12.700656 | CV22: 1 | CW22: ='conditional forecasts_6'!CW22 -> 1301
C23: Actual | CV23: 0 | CW23: ='conditional forecasts_6'!CW23 -> 0
A24: Am1301 | B24: desl | C24: Forecast | D24: 24.918337 | E24: 27.485703 | F24: 19.805134 | G24: 20.962994 | H24: 22.155499 | I24: 13.652888 | J24: 17.448986 | K24: 16.743325 | L24: 14.110511 | M24: 27.183702 | N24: 25.946476 | O24: 39.776559 | P24: 22.479494 | Q24: 24.581742 | R24: 17.562879 | S24: 17.86794 | T24: 18.890987 | U24: 10.774709 | V24: 14.386685 | W24: 13.892124 | X24: 11.468032 | Y24: 24.597271 | Z24: 23.36656 | AA24: 37.122833 | AB24: 19.707699 | AC24: 21.718861 | AD24: 14.665884 | AE24: 14.991508 | AF24: 16.068853 | AG24: 8.0126208 | AH24: 11.669113 | AI24: 11.196941 | AJ24: 8.7774401 | AK24: 21.902331 | AL24: 20.66656 | AM24: 34.421097 | AN24: 17.007417 | AO24: 19.021427 | AP24: 11.971417 | AQ24: 12.300248 | AR24: 13.382209 | AS24: 5.3330924 | AT24: 8.9992866 | AU24: 8.5383159 | AV24: 6.1297851 | AW24: 19.263859 | AX24: 18.034753 | AY24: 31.793706 | AZ24: 14.383178 | BA24: 16.400247 | BB24: 9.3540657 | BC24: 9.6878068 | BD24: 10.775544 | BE24: 2.7325561 | BF24: 6.4046958 | BG24: 5.9491451 | BH24: 3.5454509 | BI24: 16.68398 | BJ24: 15.459309 | BK24: 29.22307 | BL24: 11.818031 | BM24: 13.841386 | BN24: 6.8021559 | BO24: 7.1431004 | BP24: 8.237638 | BQ24: 0.20026418 | BR24: 3.8761144 | BS24: 3.421982 | BT24: 1.0176052 | BU24: 14.15427 | BV24: 12.928149 | BW24: 26.692839 | BX24: 9.2928883 | BY24: 11.326433 | BZ24: 4.3020455 | CA24: 4.6604257 | CB24: 5.7716607 | CC24: -2.2535685 | CD24: 1.4266878 | CE24: 0.96723683 | CF24: -1.4517296 | CG24: 11.663121 | CH24: 10.413081 | CI24: 24.158718 | CJ24: 6.7483888 | CK24: 8.78495 | CL24: 1.8010952 | CM24: 2.1984129 | CN24: 3.4167241 | CO24: -4.5342414 | CP24: -0.88190829 | CQ24: -1.0963565 | CR24: -3.8422541 | CS24: 8.358681 | CT24: 10.686386 | CU24: 16.239154 | CV24: -1 | CW24: ='conditional forecasts_6'!CW24 -> 1301
C25: Actual | CV25: 0 | CW25: ='conditional forecasts_6'!CW25 -> 0
A26: Am1302 | B26: adm | C26: Forecast | D26: 25.708676 | E26: 24.315895 | F26: 28.478181 | G26: 28.092005 | H26: 27.775274 | I26: 29.978109 | J26: 26.643056 | K26: 27.643738 | L26: 27.534534 | M26: 22.82442 | N26: 25.130772 | O26: 21.391571 | P26: 27.652405 | Q26: 26.292618 | R26: 29.771124 | S26: 29.678163 | T26: 29.129445 | U26: 31.088573 | V26: 27.600481 | W26: 28.334356 | X26: 28.115702 | Y26: 23.498052 | Z26: 26.057385 | AA26: 22.663462 | AB26: 29.249918 | AC26: 28.109752 | AD26: 31.676607 | AE26: 31.56858 | AF26: 30.95726 | AG26: 32.86174 | AH26: 29.361504 | AI26: 30.133776 | AJ26: 29.993173 | AK26: 25.474971 | AL26: 28.138912 | AM26: 24.845019 | AN26: 31.523148 | AO26: 30.465567 | AP26: 34.10583 | AQ26: 34.061838 | AR26: 33.505513 | AS26: 35.457736 | AT26: 32.001452 | AU26: 32.818203 | AV26: 32.726375 | AW26: 28.263221 | AX26: 30.988185 | AY26: 27.759123 | AZ26: 34.50288 | BA26: 33.508991 | BB26: 37.209329 | BC26: 37.221386 | BD26: 36.717679 | BE26: 38.720175 | BF26: 35.312885 | BG26: 36.178092 | BH26: 36.134518 | BI26: 31.71946 | BJ26: 34.49229 | BK26: 31.310842 | BL26: 38.102073 | BM26: 37.155754 | BN26: 40.90403 | BO26: 40.96458 | BP26: 40.509885 | BQ26: 42.561552 | BR26: 39.202867 | BS26: 40.115069 | BT26: 40.115692 | BU26: 35.740986 | BV26: 38.549799 | BW26: 35.400361 | BX26: 42.221181 | BY26: 41.304713 | BZ26: 45.086473 | CA26: 45.187342 | CB26: 44.781686 | CC26: 46.890588 | CD26: 43.593864 | CE26: 44.566749 | CF26: 44.619438 | CG26: 40.281738 | CH26: 43.108508 | CI26: 39.958399 | CJ26: 46.767187 | CK26: 45.832843 | CL26: 49.602277 | CM26: 49.72108 | CN26: 49.343015 | CO26: 51.534956 | CP26: 48.387955 | CQ26: 49.390123 | CR26: 49.911254 | CS26: 45.363595 | CT26: 47.593547 | CU26: 46.906741 | CV26: 1 | CW26: ='conditional forecasts_6'!CW26 -> 1302
C27: Actual | CV27: 0 | CW27: ='conditional forecasts_6'!CW27 -> 0
